2021-09-09 20:33:06 WARNING (SyncWorker_0) [homeassistant.loader] We found a custom integration sun2 which has not been tested by Home Assistant. This component might cause stability problems, be sure to disable it if you experience issues with Home Assistant
2021-09-09 20:33:11 ERROR (MainThread) [homeassistant.components.websocket_api.http.connection] [22830812307712] Received invalid command: energy/info
2021-09-09 20:33:11 ERROR (MainThread) [homeassistant.components.websocket_api.http.connection] [22830812307712] Received invalid command: energy/info
2021-09-09 20:33:11 ERROR (MainThread) [homeassistant.components.websocket_api.http.connection] [22830812307712] Received invalid command: energy/info
2021-09-09 20:33:11 ERROR (MainThread) [homeassistant.components.websocket_api.http.connection] [22830812307712] Received invalid command: energy/info
2021-09-09 20:33:11 ERROR (MainThread) [homeassistant.components.websocket_api.http.connection] [22830812307712] Received invalid command: energy/info
2021-09-09 20:33:11 ERROR (MainThread) [homeassistant.components.websocket_api.http.connection] [22830812307712] Received invalid command: energy/info
2021-09-09 20:33:11 ERROR (MainThread) [homeassistant.components.websocket_api.http.connection] [22830812307712] Received invalid command: energy/info
2021-09-09 20:33:11 ERROR (MainThread) [homeassistant.components.websocket_api.http.connection] [22830812307712] Received invalid command: energy/info
2021-09-09 20:33:11 ERROR (MainThread) [homeassistant.components.websocket_api.http.connection] [22830812307712] Received invalid command: energy/info
2021-09-09 20:33:11 ERROR (MainThread) [homeassistant.components.websocket_api.http.connection] [22830812307712] Received invalid command: energy/info
2021-09-09 20:33:11 ERROR (MainThread) [homeassistant.components.websocket_api.http.connection] [22830812307712] Received invalid command: energy/info
2021-09-09 20:33:11 ERROR (MainThread) [homeassistant.components.websocket_api.http.connection] [22830812307712] Received invalid command: energy/info
2021-09-09 20:33:11 ERROR (MainThread) [homeassistant.components.websocket_api.http.connection] [22830812307712] Received invalid command: energy/info
2021-09-09 20:33:11 ERROR (MainThread) [homeassistant.components.websocket_api.http.connection] [22830812307712] Received invalid command: energy/info
2021-09-09 20:33:11 ERROR (MainThread) [homeassistant.components.websocket_api.http.connection] [22830812307712] Received invalid command: energy/info
2021-09-09 20:33:17 WARNING (MainThread) [homeassistant.components.sensor] Entity sensor.cpu_temp (<class 'homeassistant.components.command_line.sensor.CommandSensor'>) with device_class None reports a temperature in °C which will be converted to °F. Temperature conversion for entities without correct device_class is deprecated and will be removed from Home Assistant Core 2022.3. Please update your configuration if device_class is manually configured, otherwise create a bug report at https://github.com/home-assistant/core/issues?q=is%3Aopen+is%3Aissue+label%3A%22integration%3A+command_line%22
2021-09-09 20:33:19 WARNING (MainThread) [homeassistant.config_entries] Config entry 'Roku Smart Soundbar' for roku integration not ready yet: Invalid response from API: Error occurred while communicating with device; Retrying in background
2021-09-09 20:33:21 WARNING (MainThread) [homeassistant.components.sensor] Entity sensor.attictemp1_bme280_dewpoint (<class 'homeassistant.components.tasmota.sensor.TasmotaSensor'>) with device_class None reports a temperature in °C which will be converted to °F. Temperature conversion for entities without correct device_class is deprecated and will be removed from Home Assistant Core 2022.3. Please update your configuration if device_class is manually configured, otherwise create a bug report at https://github.com/home-assistant/core/issues?q=is%3Aopen+is%3Aissue+label%3A%22integration%3A+tasmota%22
2021-09-09 20:33:21 WARNING (MainThread) [homeassistant.components.sensor] Entity sensor.garagesidedoorsensor_bme280_dewpoint (<class 'homeassistant.components.tasmota.sensor.TasmotaSensor'>) with device_class None reports a temperature in °C which will be converted to °F. Temperature conversion for entities without correct device_class is deprecated and will be removed from Home Assistant Core 2022.3. Please update your configuration if device_class is manually configured, otherwise create a bug report at https://github.com/home-assistant/core/issues?q=is%3Aopen+is%3Aissue+label%3A%22integration%3A+tasmota%22
2021-09-09 20:33:25 WARNING (MainThread) [homeassistant.config_entries] Config entry '192.168.7.195' for wled integration not ready yet: Invalid response from API: Error occurred while communicating with WLED device at 192.168.7.195; Retrying in background
2021-09-09 20:34:01 ERROR (stream_worker) [libav.rtsp] method DESCRIBE failed: 404 Not Found
2021-09-09 20:34:01 ERROR (stream_worker) [homeassistant.components.stream.worker] Error opening stream rtsps://stream-uc2-delta.dropcam.com:443/sdm_live_stream/CiQA2vuxr3ACnS5aOb98j37KDKsoPQUygQ7bCkAmrdKmHMABGp4ScQAFjsOT7fgcc8k59nBnLGliiUrAS_LHOhqgEIPAlMoH8rbVf_2CCG_TjCvVBMlmC9gMMcCeifcgaMB2pUNNGHdfwIJ27rOQIZ_ZC9dBFbizvqM_nW7X5K4uVuZvYslOteS6h_zqkanwU_qaPlYRdRh2?auth=g.0.eyJraWQiOiIyMzhiNTUxZmMyM2EyM2Y4M2E2ZTE3MmJjZTg0YmU3ZjgxMzAzMmM4IiwiYWxnIjoiUlMyNTYifQ.eyJpc3MiOiJuZXN0LXNlY3VyaXR5LWF1dGhwcm94eSIsInN1YiI6Im5lc3RfaWQ6bmVzdC1waG9lbml4LXByb2Q6MjEyMTgxNDEiLCJwb2wiOiIzcC1vYXV0aC1zY29wZS1BUElfU0RNX1NFUlZJQ0UtY2xpZW50LTIwMjQyNzMxODczNS1qNXQ5bWMyMzZqaG85YXMycWY0dTZxY3NmYW1kaGJ0ci5hcHBzLmdvb2dsZXVzZXJjb250ZW50LmNvbSIsImV4cCI6MTYzMTI0NTEyN30.Wuxi03EPpiKsp1Q_CkU_gDhwiWCkmKN48noIzhkc1LTgUkPnoo2OjvNs1xxhHiAaZ8RXlCy3mMWeh7kceZCOXO8pOAD1_E8dpICnFF44Q3KbK11WEKdSha8-XaHkRUZiNvYGoL0ElpAyHFKYvR5knKpXSmWeQDhIB0jJEXSMKY2MOBAnhG0pdcFrG3H17hNXwjm-TBhOzdzLBzUKxX4TuOIYHt2ic0sb2ePG3_cGo-84A7vsWd-kKYePrKgYSRdGey0fMYcWTD2NBAPMcPSZ_QeF85Xv_aQ3Y-N0hJFMC6pqBQOPfaEGcj8kU419iTyQEw4vMpCzp9AqPbip3M2voQ
2021-09-09 20:34:25 ERROR (stream_worker) [libav.rtsp] method DESCRIBE failed: 404 Not Found
2021-09-09 20:34:25 ERROR (stream_worker) [homeassistant.components.stream.worker] Error opening stream rtsps://stream-uc2-delta.dropcam.com:443/sdm_live_stream/CiQA2vuxr3ACnS5aOb98j37KDKsoPQUygQ7bCkAmrdKmHMABGp4ScQAFjsOT7fgcc8k59nBnLGliiUrAS_LHOhqgEIPAlMoH8rbVf_2CCG_TjCvVBMlmC9gMMcCeifcgaMB2pUNNGHdfwIJ27rOQIZ_ZC9dBFbizvqM_nW7X5K4uVuZvYslOteS6h_zqkanwU_qaPlYRdRh2?auth=g.0.eyJraWQiOiIyMzhiNTUxZmMyM2EyM2Y4M2E2ZTE3MmJjZTg0YmU3ZjgxMzAzMmM4IiwiYWxnIjoiUlMyNTYifQ.eyJpc3MiOiJuZXN0LXNlY3VyaXR5LWF1dGhwcm94eSIsInN1YiI6Im5lc3RfaWQ6bmVzdC1waG9lbml4LXByb2Q6MjEyMTgxNDEiLCJwb2wiOiIzcC1vYXV0aC1zY29wZS1BUElfU0RNX1NFUlZJQ0UtY2xpZW50LTIwMjQyNzMxODczNS1qNXQ5bWMyMzZqaG85YXMycWY0dTZxY3NmYW1kaGJ0ci5hcHBzLmdvb2dsZXVzZXJjb250ZW50LmNvbSIsImV4cCI6MTYzMTI0NTEyN30.Wuxi03EPpiKsp1Q_CkU_gDhwiWCkmKN48noIzhkc1LTgUkPnoo2OjvNs1xxhHiAaZ8RXlCy3mMWeh7kceZCOXO8pOAD1_E8dpICnFF44Q3KbK11WEKdSha8-XaHkRUZiNvYGoL0ElpAyHFKYvR5knKpXSmWeQDhIB0jJEXSMKY2MOBAnhG0pdcFrG3H17hNXwjm-TBhOzdzLBzUKxX4TuOIYHt2ic0sb2ePG3_cGo-84A7vsWd-kKYePrKgYSRdGey0fMYcWTD2NBAPMcPSZ_QeF85Xv_aQ3Y-N0hJFMC6pqBQOPfaEGcj8kU419iTyQEw4vMpCzp9AqPbip3M2voQ
2021-09-09 20:34:58 ERROR (stream_worker) [libav.rtsp] method DESCRIBE failed: 404 Not Found
2021-09-09 20:34:58 ERROR (stream_worker) [homeassistant.components.stream.worker] Error opening stream rtsps://stream-uc2-delta.dropcam.com:443/sdm_live_stream/CiQA2vuxr3ACnS5aOb98j37KDKsoPQUygQ7bCkAmrdKmHMABGp4ScQAFjsOT7fgcc8k59nBnLGliiUrAS_LHOhqgEIPAlMoH8rbVf_2CCG_TjCvVBMlmC9gMMcCeifcgaMB2pUNNGHdfwIJ27rOQIZ_ZC9dBFbizvqM_nW7X5K4uVuZvYslOteS6h_zqkanwU_qaPlYRdRh2?auth=g.0.eyJraWQiOiIyMzhiNTUxZmMyM2EyM2Y4M2E2ZTE3MmJjZTg0YmU3ZjgxMzAzMmM4IiwiYWxnIjoiUlMyNTYifQ.eyJpc3MiOiJuZXN0LXNlY3VyaXR5LWF1dGhwcm94eSIsInN1YiI6Im5lc3RfaWQ6bmVzdC1waG9lbml4LXByb2Q6MjEyMTgxNDEiLCJwb2wiOiIzcC1vYXV0aC1zY29wZS1BUElfU0RNX1NFUlZJQ0UtY2xpZW50LTIwMjQyNzMxODczNS1qNXQ5bWMyMzZqaG85YXMycWY0dTZxY3NmYW1kaGJ0ci5hcHBzLmdvb2dsZXVzZXJjb250ZW50LmNvbSIsImV4cCI6MTYzMTI0NTEyN30.Wuxi03EPpiKsp1Q_CkU_gDhwiWCkmKN48noIzhkc1LTgUkPnoo2OjvNs1xxhHiAaZ8RXlCy3mMWeh7kceZCOXO8pOAD1_E8dpICnFF44Q3KbK11WEKdSha8-XaHkRUZiNvYGoL0ElpAyHFKYvR5knKpXSmWeQDhIB0jJEXSMKY2MOBAnhG0pdcFrG3H17hNXwjm-TBhOzdzLBzUKxX4TuOIYHt2ic0sb2ePG3_cGo-84A7vsWd-kKYePrKgYSRdGey0fMYcWTD2NBAPMcPSZ_QeF85Xv_aQ3Y-N0hJFMC6pqBQOPfaEGcj8kU419iTyQEw4vMpCzp9AqPbip3M2voQ
2021-09-09 20:35:40 ERROR (stream_worker) [libav.rtsp] method DESCRIBE failed: 404 Not Found
2021-09-09 20:35:40 ERROR (stream_worker) [homeassistant.components.stream.worker] Error opening stream rtsps://stream-uc2-delta.dropcam.com:443/sdm_live_stream/CiQA2vuxr3ACnS5aOb98j37KDKsoPQUygQ7bCkAmrdKmHMABGp4ScQAFjsOT7fgcc8k59nBnLGliiUrAS_LHOhqgEIPAlMoH8rbVf_2CCG_TjCvVBMlmC9gMMcCeifcgaMB2pUNNGHdfwIJ27rOQIZ_ZC9dBFbizvqM_nW7X5K4uVuZvYslOteS6h_zqkanwU_qaPlYRdRh2?auth=g.0.eyJraWQiOiIyMzhiNTUxZmMyM2EyM2Y4M2E2ZTE3MmJjZTg0YmU3ZjgxMzAzMmM4IiwiYWxnIjoiUlMyNTYifQ.eyJpc3MiOiJuZXN0LXNlY3VyaXR5LWF1dGhwcm94eSIsInN1YiI6Im5lc3RfaWQ6bmVzdC1waG9lbml4LXByb2Q6MjEyMTgxNDEiLCJwb2wiOiIzcC1vYXV0aC1zY29wZS1BUElfU0RNX1NFUlZJQ0UtY2xpZW50LTIwMjQyNzMxODczNS1qNXQ5bWMyMzZqaG85YXMycWY0dTZxY3NmYW1kaGJ0ci5hcHBzLmdvb2dsZXVzZXJjb250ZW50LmNvbSIsImV4cCI6MTYzMTI0NTEyN30.Wuxi03EPpiKsp1Q_CkU_gDhwiWCkmKN48noIzhkc1LTgUkPnoo2OjvNs1xxhHiAaZ8RXlCy3mMWeh7kceZCOXO8pOAD1_E8dpICnFF44Q3KbK11WEKdSha8-XaHkRUZiNvYGoL0ElpAyHFKYvR5knKpXSmWeQDhIB0jJEXSMKY2MOBAnhG0pdcFrG3H17hNXwjm-TBhOzdzLBzUKxX4TuOIYHt2ic0sb2ePG3_cGo-84A7vsWd-kKYePrKgYSRdGey0fMYcWTD2NBAPMcPSZ_QeF85Xv_aQ3Y-N0hJFMC6pqBQOPfaEGcj8kU419iTyQEw4vMpCzp9AqPbip3M2voQ
2021-09-09 20:38:13 ERROR (MainThread) [homeassistant] Error doing job: Future exception was never retrieved
Traceback (most recent call last):
  File "/usr/local/lib/python3.9/concurrent/futures/thread.py", line 52, in run
    result = self.fn(*self.args, **self.kwargs)
TypeError: update() takes 1 positional argument but 2 were given
2021-09-09 20:42:59 ERROR (stream_worker) [libav.rtsp] method DESCRIBE failed: 404 Not Found
2021-09-09 20:42:59 ERROR (stream_worker) [homeassistant.components.stream.worker] Error opening stream rtsps://stream-uc2-bravo.dropcam.com:443/sdm_live_stream/CiQA2vuxr3zvsVH2gvoYeXMrwVTFF2hBjY5lIgUZhK8E2y2STk4ScQAFjsOTcrpVcbV6jH2vrriGOH1H9acInibLRSiquO1d_sjsGqC4m7-Ye1fX9buqhrpQ6lJ08d2E6cLLcecSIUSFTOf47WMwStwjDfpt316EQkuSQ4m4AxjvTTmfVdHQG4O9X3hGjsH8X2CVPVm_fFzM?auth=g.0.eyJraWQiOiIyMzhiNTUxZmMyM2EyM2Y4M2E2ZTE3MmJjZTg0YmU3ZjgxMzAzMmM4IiwiYWxnIjoiUlMyNTYifQ.eyJpc3MiOiJuZXN0LXNlY3VyaXR5LWF1dGhwcm94eSIsInN1YiI6Im5lc3RfaWQ6bmVzdC1waG9lbml4LXByb2Q6MjEyMTgxNDEiLCJwb2wiOiIzcC1vYXV0aC1zY29wZS1BUElfU0RNX1NFUlZJQ0UtY2xpZW50LTIwMjQyNzMxODczNS1qNXQ5bWMyMzZqaG85YXMycWY0dTZxY3NmYW1kaGJ0ci5hcHBzLmdvb2dsZXVzZXJjb250ZW50LmNvbSIsImV4cCI6MTYzMTI0NTY2OH0.JtWqyJimTSpF0nHPUXwlFttK_vxic_ovGWFUEL1a9hqSYQQZ-zmpxeoXGf6NW8U35t5ApxB5ih3tKoBiNn5BMS_deqPbRJ0Pt_0YRWklFi1KTS4aG3eNsxAQh1WT35drs0ED72hn6Y2_uV8Yu3Vi-qV69GbdieTsYaM9TK8j4zOqABcpTQvKmkWNdwbfUXGkwYmyG4oWGJ-BTxAJvfaVvdz9Iu_p9cCqcLYaX4aTDj2iRSm7sp5tqYI1wDlP2mjnrR6dWgO8iVd8Zi6xIM_Lr63ytt6imEL-aximz24DJ0HERnTW6teb1jik8akfAPzk3QCovq_rBZB2RHKQX4oAvA
2021-09-09 20:43:14 ERROR (MainThread) [homeassistant] Error doing job: Future exception was never retrieved
Traceback (most recent call last):
  File "/usr/local/lib/python3.9/concurrent/futures/thread.py", line 52, in run
    result = self.fn(*self.args, **self.kwargs)
TypeError: update() takes 1 positional argument but 2 were given
2021-09-09 20:48:15 ERROR (MainThread) [homeassistant] Error doing job: Future exception was never retrieved
Traceback (most recent call last):
  File "/usr/local/lib/python3.9/concurrent/futures/thread.py", line 52, in run
    result = self.fn(*self.args, **self.kwargs)
TypeError: update() takes 1 positional argument but 2 were given
2021-09-09 20:49:17 ERROR (SyncWorker_2) [homeassistant.components.co2signal] Unexpected exception
Traceback (most recent call last):
  File "/usr/src/homeassistant/homeassistant/components/co2signal/__init__.py", line 119, in get_data
    data = CO2Signal.get_latest(
  File "/usr/local/lib/python3.9/site-packages/CO2Signal/co2signal.py", line 34, in get_latest
    latest_data = (requests
  File "/usr/local/lib/python3.9/site-packages/requests/models.py", line 900, in json
    return complexjson.loads(self.text, **kwargs)
  File "/usr/local/lib/python3.9/site-packages/simplejson/__init__.py", line 525, in loads
    return _default_decoder.decode(s)
  File "/usr/local/lib/python3.9/site-packages/simplejson/decoder.py", line 370, in decode
    obj, end = self.raw_decode(s)
  File "/usr/local/lib/python3.9/site-packages/simplejson/decoder.py", line 400, in raw_decode
    return self.scan_once(s, idx=_w(s, idx).end())
simplejson.errors.JSONDecodeError: Expecting value: line 1 column 1 (char 0)
2021-09-09 20:49:17 ERROR (MainThread) [homeassistant.components.co2signal] Error fetching co2signal data: 
2021-09-09 20:50:36 WARNING (Thread-10) [pychromecast.socket_client] [Liam Home Mini(192.168.6.222):8009] Heartbeat timeout, resetting connection
2021-09-09 20:50:43 ERROR (Thread-10) [pychromecast.socket_client] [Liam Home Mini(192.168.6.222):8009] Failed to connect to service ServiceInfo(type='host', data=('192.168.6.222', 8009)), retrying in 5.0s
2021-09-09 20:51:44 WARNING (MainThread) [homeassistant.components.template.template_entity] Template loop detected while processing event: <Event state_changed[L]: entity_id=sensor.entities_count, old_state=<state sensor.entities_count=725; friendly_name=Number of Entities @ 2021-09-09T20:49:44.788148-07:00>, new_state=<state sensor.entities_count=724; friendly_name=Number of Entities @ 2021-09-09T20:50:44.794992-07:00>>, skipping template render for Template[{{ states | rejectattr('state', 'eq', 'unavailable') | list | count}}]
2021-09-09 20:52:41 ERROR (stream_worker) [libav.rtsp] method DESCRIBE failed: 404 Not Found
2021-09-09 20:52:41 ERROR (stream_worker) [homeassistant.components.stream.worker] Error opening stream rtsps://stream-uc2-delta.dropcam.com:443/sdm_live_stream/CiQA2vuxr3ACnS5aOb98j37KDKsoPQUygQ7bCkAmrdKmHMABGp4ScQAFjsOT7fgcc8k59nBnLGliiUrAS_LHOhqgEIPAlMoH8rbVf_2CCG_TjCvVBMlmC9gMMcCeifcgaMB2pUNNGHdfwIJ27rOQIZ_ZC9dBFbizvqM_nW7X5K4uVuZvYslOteS6h_zqkanwU_qaPlYRdRh2?auth=g.0.eyJraWQiOiIyMzhiNTUxZmMyM2EyM2Y4M2E2ZTE3MmJjZTg0YmU3ZjgxMzAzMmM4IiwiYWxnIjoiUlMyNTYifQ.eyJpc3MiOiJuZXN0LXNlY3VyaXR5LWF1dGhwcm94eSIsInN1YiI6Im5lc3RfaWQ6bmVzdC1waG9lbml4LXByb2Q6MjEyMTgxNDEiLCJwb2wiOiIzcC1vYXV0aC1zY29wZS1BUElfU0RNX1NFUlZJQ0UtY2xpZW50LTIwMjQyNzMxODczNS1qNXQ5bWMyMzZqaG85YXMycWY0dTZxY3NmYW1kaGJ0ci5hcHBzLmdvb2dsZXVzZXJjb250ZW50LmNvbSIsImV4cCI6MTYzMTI0NjIxMH0.Cg461pfb3piJDX-EHKcOlvEmDXmUnJh4z284VNEvetTZ-NvMwO7c5H_iOF9gJM-mVsUhbwybwVVO4vigelvNlQvBl8x69kbEq2R1dV8rlxmxbPeER8RX0c3plHnn0h31-ahoOke61p3rrlUPeGLaUEM-g094qaOMHaTEzV6x-IN4m5IzCJIeXB7U8LSQy5Kgi0Z_cxYPpHioPzhhqKWPRgGkjdThNtLy27yL0IsfueZ_nIL_UjC85etv-kQ1g3GFZhnzXPYJnmbPl5cuhyrnVwp66_5dhTdluKeRdeMRwa3yBjfUpFuWm55jorV_T6PeDvkovu_lXRTcHNVx9IQRpA
2021-09-09 20:53:16 ERROR (MainThread) [homeassistant] Error doing job: Future exception was never retrieved
Traceback (most recent call last):
  File "/usr/local/lib/python3.9/concurrent/futures/thread.py", line 52, in run
    result = self.fn(*self.args, **self.kwargs)
TypeError: update() takes 1 positional argument but 2 were given
2021-09-09 20:53:35 ERROR (MainThread) [homeassistant.components.nws] Error requesting NWS observation station SAUC1 data: 503, message='Service Unavailable', url=URL('https://api.weather.gov/stations/SAUC1/observations')
2021-09-09 20:53:42 ERROR (stream_worker) [libav.rtsp] method DESCRIBE failed: 404 Not Found
2021-09-09 20:53:42 ERROR (stream_worker) [homeassistant.components.stream.worker] Error opening stream rtsps://stream-uc2-delta.dropcam.com:443/sdm_live_stream/CiQA2vuxr3ACnS5aOb98j37KDKsoPQUygQ7bCkAmrdKmHMABGp4ScQAFjsOT7fgcc8k59nBnLGliiUrAS_LHOhqgEIPAlMoH8rbVf_2CCG_TjCvVBMlmC9gMMcCeifcgaMB2pUNNGHdfwIJ27rOQIZ_ZC9dBFbizvqM_nW7X5K4uVuZvYslOteS6h_zqkanwU_qaPlYRdRh2?auth=g.0.eyJraWQiOiIyMzhiNTUxZmMyM2EyM2Y4M2E2ZTE3MmJjZTg0YmU3ZjgxMzAzMmM4IiwiYWxnIjoiUlMyNTYifQ.eyJpc3MiOiJuZXN0LXNlY3VyaXR5LWF1dGhwcm94eSIsInN1YiI6Im5lc3RfaWQ6bmVzdC1waG9lbml4LXByb2Q6MjEyMTgxNDEiLCJwb2wiOiIzcC1vYXV0aC1zY29wZS1BUElfU0RNX1NFUlZJQ0UtY2xpZW50LTIwMjQyNzMxODczNS1qNXQ5bWMyMzZqaG85YXMycWY0dTZxY3NmYW1kaGJ0ci5hcHBzLmdvb2dsZXVzZXJjb250ZW50LmNvbSIsImV4cCI6MTYzMTI0NjIxMH0.Cg461pfb3piJDX-EHKcOlvEmDXmUnJh4z284VNEvetTZ-NvMwO7c5H_iOF9gJM-mVsUhbwybwVVO4vigelvNlQvBl8x69kbEq2R1dV8rlxmxbPeER8RX0c3plHnn0h31-ahoOke61p3rrlUPeGLaUEM-g094qaOMHaTEzV6x-IN4m5IzCJIeXB7U8LSQy5Kgi0Z_cxYPpHioPzhhqKWPRgGkjdThNtLy27yL0IsfueZ_nIL_UjC85etv-kQ1g3GFZhnzXPYJnmbPl5cuhyrnVwp66_5dhTdluKeRdeMRwa3yBjfUpFuWm55jorV_T6PeDvkovu_lXRTcHNVx9IQRpA
2021-09-09 20:56:41 ERROR (stream_worker) [libav.rtsp] method DESCRIBE failed: 404 Not Found
2021-09-09 20:56:41 ERROR (stream_worker) [homeassistant.components.stream.worker] Error opening stream rtsps://stream-uc2-bravo.dropcam.com:443/sdm_live_stream/CiQA2vuxr3zvsVH2gvoYeXMrwVTFF2hBjY5lIgUZhK8E2y2STk4ScQAFjsOTcrpVcbV6jH2vrriGOH1H9acInibLRSiquO1d_sjsGqC4m7-Ye1fX9buqhrpQ6lJ08d2E6cLLcecSIUSFTOf47WMwStwjDfpt316EQkuSQ4m4AxjvTTmfVdHQG4O9X3hGjsH8X2CVPVm_fFzM?auth=g.0.eyJraWQiOiIyMzhiNTUxZmMyM2EyM2Y4M2E2ZTE3MmJjZTg0YmU3ZjgxMzAzMmM4IiwiYWxnIjoiUlMyNTYifQ.eyJpc3MiOiJuZXN0LXNlY3VyaXR5LWF1dGhwcm94eSIsInN1YiI6Im5lc3RfaWQ6bmVzdC1waG9lbml4LXByb2Q6MjEyMTgxNDEiLCJwb2wiOiIzcC1vYXV0aC1zY29wZS1BUElfU0RNX1NFUlZJQ0UtY2xpZW50LTIwMjQyNzMxODczNS1qNXQ5bWMyMzZqaG85YXMycWY0dTZxY3NmYW1kaGJ0ci5hcHBzLmdvb2dsZXVzZXJjb250ZW50LmNvbSIsImV4cCI6MTYzMTI0NjQ4MH0.T_662xdQFxNRPAs-yqUQxCQKZ4ujqDVU0v18eDXdmFAD3L4yoNrmAoAF22PtvyV6ppjfpWz9fpL4CVQZ5GpVWbt4ho2UJfbLY1CKZCyV1AxeKckiivrojDdbIHT4HKm9cE0sDJnqyPV7xFbsDkNF4zGLiQJevJHzfw79eebcB-jlAaCMzc2yn_zMM74IEwGJfftoMIAZ0Dsmrlb-bjVjARqT_18qzGYvDfv0IfzB7BepUQQZe5tUZOIbJWLglSwTQVIrnLEBwtA8_BH_2hR4kyoD4d6l06hEyu8CJiY9YbNLhLwIiEfAAXRJmS1pVeK4EfL9A9qawELqyoFqEMoCiw
2021-09-09 20:58:17 ERROR (MainThread) [homeassistant] Error doing job: Future exception was never retrieved
Traceback (most recent call last):
  File "/usr/local/lib/python3.9/concurrent/futures/thread.py", line 52, in run
    result = self.fn(*self.args, **self.kwargs)
TypeError: update() takes 1 positional argument but 2 were given
2021-09-09 21:03:18 ERROR (MainThread) [homeassistant] Error doing job: Future exception was never retrieved
Traceback (most recent call last):
  File "/usr/local/lib/python3.9/concurrent/futures/thread.py", line 52, in run
    result = self.fn(*self.args, **self.kwargs)
TypeError: update() takes 1 positional argument but 2 were given
2021-09-09 21:04:17 ERROR (SyncWorker_1) [homeassistant.components.co2signal] Unexpected exception
Traceback (most recent call last):
  File "/usr/src/homeassistant/homeassistant/components/co2signal/__init__.py", line 119, in get_data
    data = CO2Signal.get_latest(
  File "/usr/local/lib/python3.9/site-packages/CO2Signal/co2signal.py", line 34, in get_latest
    latest_data = (requests
  File "/usr/local/lib/python3.9/site-packages/requests/models.py", line 900, in json
    return complexjson.loads(self.text, **kwargs)
  File "/usr/local/lib/python3.9/site-packages/simplejson/__init__.py", line 525, in loads
    return _default_decoder.decode(s)
  File "/usr/local/lib/python3.9/site-packages/simplejson/decoder.py", line 370, in decode
    obj, end = self.raw_decode(s)
  File "/usr/local/lib/python3.9/site-packages/simplejson/decoder.py", line 400, in raw_decode
    return self.scan_once(s, idx=_w(s, idx).end())
simplejson.errors.JSONDecodeError: Expecting value: line 1 column 1 (char 0)
2021-09-09 21:06:58 ERROR (MainThread) [iotawattpy.connection] Err: All connection attempts failed
2021-09-09 21:06:58 ERROR (MainThread) [homeassistant.components.iotawatt.coordinator] Unexpected error fetching 192.168.20.195 data: 'NoneType' object has no attribute 'text'
Traceback (most recent call last):
  File "/usr/src/homeassistant/homeassistant/helpers/update_coordinator.py", line 187, in _async_refresh
    self.data = await self._async_update_data()
  File "/usr/src/homeassistant/homeassistant/components/iotawatt/coordinator.py", line 55, in _async_update_data
    await self.api.update()
  File "/usr/local/lib/python3.9/site-packages/iotawattpy/iotawatt.py", line 66, in update
    await self._refreshSensors(timespan)
  File "/usr/local/lib/python3.9/site-packages/iotawattpy/iotawatt.py", line 100, in _refreshSensors
    results = response.text
AttributeError: 'NoneType' object has no attribute 'text'
2021-09-09 21:08:19 ERROR (MainThread) [homeassistant] Error doing job: Future exception was never retrieved
Traceback (most recent call last):
  File "/usr/local/lib/python3.9/concurrent/futures/thread.py", line 52, in run
    result = self.fn(*self.args, **self.kwargs)
TypeError: update() takes 1 positional argument but 2 were given
2021-09-09 21:08:45 WARNING (MainThread) [bellows.zigbee.application] Watchdog heartbeat timeout: 
2021-09-09 21:12:01 WARNING (Recorder) [homeassistant.components.sensor.recorder] sensor.iotawatt_simexport has unknown unit None
2021-09-09 21:13:20 ERROR (MainThread) [homeassistant] Error doing job: Future exception was never retrieved
Traceback (most recent call last):
  File "/usr/local/lib/python3.9/concurrent/futures/thread.py", line 52, in run
    result = self.fn(*self.args, **self.kwargs)
TypeError: update() takes 1 positional argument but 2 were given
2021-09-09 21:14:57 ERROR (MainThread) [homeassistant.components.nws] Error requesting NWS observation station SAUC1 data: 503, message='Service Unavailable', url=URL('https://api.weather.gov/stations/SAUC1/observations')
2021-09-09 21:18:21 ERROR (MainThread) [homeassistant] Error doing job: Future exception was never retrieved
Traceback (most recent call last):
  File "/usr/local/lib/python3.9/concurrent/futures/thread.py", line 52, in run
    result = self.fn(*self.args, **self.kwargs)
TypeError: update() takes 1 positional argument but 2 were given
2021-09-09 21:18:52 ERROR (stream_worker) [libav.tls] Error in the pull function.
2021-09-09 21:18:52 ERROR (stream_worker) [libav.tls] The specified session has been invalidated for some reason.
2021-09-09 21:18:52 ERROR (stream_worker) [homeassistant.components.stream.worker] Error demuxing stream: 
2021-09-09 21:18:53 ERROR (stream_worker) [libav.tls] The specified session has been invalidated for some reason.
2021-09-09 21:19:17 ERROR (SyncWorker_10) [homeassistant.components.co2signal] Unexpected exception
Traceback (most recent call last):
  File "/usr/src/homeassistant/homeassistant/components/co2signal/__init__.py", line 119, in get_data
    data = CO2Signal.get_latest(
  File "/usr/local/lib/python3.9/site-packages/CO2Signal/co2signal.py", line 34, in get_latest
    latest_data = (requests
  File "/usr/local/lib/python3.9/site-packages/requests/models.py", line 900, in json
    return complexjson.loads(self.text, **kwargs)
  File "/usr/local/lib/python3.9/site-packages/simplejson/__init__.py", line 525, in loads
    return _default_decoder.decode(s)
  File "/usr/local/lib/python3.9/site-packages/simplejson/decoder.py", line 370, in decode
    obj, end = self.raw_decode(s)
  File "/usr/local/lib/python3.9/site-packages/simplejson/decoder.py", line 400, in raw_decode
    return self.scan_once(s, idx=_w(s, idx).end())
simplejson.errors.JSONDecodeError: Expecting value: line 1 column 1 (char 0)
2021-09-09 21:23:22 ERROR (MainThread) [homeassistant] Error doing job: Future exception was never retrieved
Traceback (most recent call last):
  File "/usr/local/lib/python3.9/concurrent/futures/thread.py", line 52, in run
    result = self.fn(*self.args, **self.kwargs)
TypeError: update() takes 1 positional argument but 2 were given
2021-09-09 21:24:28 WARNING (MainThread) [bellows.zigbee.application] Watchdog heartbeat timeout: 
2021-09-09 21:24:43 WARNING (MainThread) [bellows.zigbee.application] Watchdog heartbeat timeout: 
2021-09-09 21:24:58 WARNING (MainThread) [bellows.zigbee.application] Watchdog heartbeat timeout: 
2021-09-09 21:25:13 WARNING (MainThread) [bellows.zigbee.application] Watchdog heartbeat timeout: 
2021-09-09 21:25:28 WARNING (MainThread) [bellows.zigbee.application] Watchdog heartbeat timeout: 
2021-09-09 21:27:29 WARNING (bellows.thread_0) [bellows.uart] Reset future is None
2021-09-09 21:27:30 WARNING (bellows.thread_0) [bellows.uart] Reset future is None
2021-09-09 21:28:23 ERROR (MainThread) [homeassistant] Error doing job: Future exception was never retrieved
Traceback (most recent call last):
  File "/usr/local/lib/python3.9/concurrent/futures/thread.py", line 52, in run
    result = self.fn(*self.args, **self.kwargs)
TypeError: update() takes 1 positional argument but 2 were given
2021-09-09 21:28:29 ERROR (MainThread) [homeassistant.components.nws] Error requesting NWS observation station SAUC1 data: 503, message='Service Unavailable', url=URL('https://api.weather.gov/stations/SAUC1/observations')
2021-09-09 21:33:24 ERROR (MainThread) [homeassistant] Error doing job: Future exception was never retrieved
Traceback (most recent call last):
  File "/usr/local/lib/python3.9/concurrent/futures/thread.py", line 52, in run
    result = self.fn(*self.args, **self.kwargs)
TypeError: update() takes 1 positional argument but 2 were given
2021-09-09 21:34:17 ERROR (SyncWorker_6) [homeassistant.components.co2signal] Unexpected exception
Traceback (most recent call last):
  File "/usr/src/homeassistant/homeassistant/components/co2signal/__init__.py", line 119, in get_data
    data = CO2Signal.get_latest(
  File "/usr/local/lib/python3.9/site-packages/CO2Signal/co2signal.py", line 34, in get_latest
    latest_data = (requests
  File "/usr/local/lib/python3.9/site-packages/requests/models.py", line 900, in json
    return complexjson.loads(self.text, **kwargs)
  File "/usr/local/lib/python3.9/site-packages/simplejson/__init__.py", line 525, in loads
    return _default_decoder.decode(s)
  File "/usr/local/lib/python3.9/site-packages/simplejson/decoder.py", line 370, in decode
    obj, end = self.raw_decode(s)
  File "/usr/local/lib/python3.9/site-packages/simplejson/decoder.py", line 400, in raw_decode
    return self.scan_once(s, idx=_w(s, idx).end())
simplejson.errors.JSONDecodeError: Expecting value: line 1 column 1 (char 0)
2021-09-09 21:37:53 ERROR (MainThread) [homeassistant] Error doing job: Task was destroyed but it is pending!
2021-09-09 21:38:25 ERROR (MainThread) [homeassistant] Error doing job: Future exception was never retrieved
Traceback (most recent call last):
  File "/usr/local/lib/python3.9/concurrent/futures/thread.py", line 52, in run
    result = self.fn(*self.args, **self.kwargs)
TypeError: update() takes 1 positional argument but 2 were given
2021-09-09 21:43:26 ERROR (MainThread) [homeassistant] Error doing job: Future exception was never retrieved
Traceback (most recent call last):
  File "/usr/local/lib/python3.9/concurrent/futures/thread.py", line 52, in run
    result = self.fn(*self.args, **self.kwargs)
TypeError: update() takes 1 positional argument but 2 were given
2021-09-09 21:48:27 ERROR (MainThread) [homeassistant] Error doing job: Future exception was never retrieved
Traceback (most recent call last):
  File "/usr/local/lib/python3.9/concurrent/futures/thread.py", line 52, in run
    result = self.fn(*self.args, **self.kwargs)
TypeError: update() takes 1 positional argument but 2 were given
2021-09-09 21:53:28 ERROR (MainThread) [homeassistant] Error doing job: Future exception was never retrieved
Traceback (most recent call last):
  File "/usr/local/lib/python3.9/concurrent/futures/thread.py", line 52, in run
    result = self.fn(*self.args, **self.kwargs)
TypeError: update() takes 1 positional argument but 2 were given
2021-09-09 21:58:29 ERROR (MainThread) [homeassistant] Error doing job: Future exception was never retrieved
Traceback (most recent call last):
  File "/usr/local/lib/python3.9/concurrent/futures/thread.py", line 52, in run
    result = self.fn(*self.args, **self.kwargs)
TypeError: update() takes 1 positional argument but 2 were given
2021-09-09 22:03:30 ERROR (MainThread) [homeassistant] Error doing job: Future exception was never retrieved
Traceback (most recent call last):
  File "/usr/local/lib/python3.9/concurrent/futures/thread.py", line 52, in run
    result = self.fn(*self.args, **self.kwargs)
TypeError: update() takes 1 positional argument but 2 were given
2021-09-09 22:08:31 ERROR (MainThread) [homeassistant] Error doing job: Future exception was never retrieved
Traceback (most recent call last):
  File "/usr/local/lib/python3.9/concurrent/futures/thread.py", line 52, in run
    result = self.fn(*self.args, **self.kwargs)
TypeError: update() takes 1 positional argument but 2 were given
2021-09-09 22:13:32 ERROR (MainThread) [homeassistant] Error doing job: Future exception was never retrieved
Traceback (most recent call last):
  File "/usr/local/lib/python3.9/concurrent/futures/thread.py", line 52, in run
    result = self.fn(*self.args, **self.kwargs)
TypeError: update() takes 1 positional argument but 2 were given
2021-09-09 22:13:47 WARNING (MainThread) [haffmpeg.tools] Timeout reading image.
2021-09-09 22:18:33 ERROR (MainThread) [homeassistant] Error doing job: Future exception was never retrieved
Traceback (most recent call last):
  File "/usr/local/lib/python3.9/concurrent/futures/thread.py", line 52, in run
    result = self.fn(*self.args, **self.kwargs)
TypeError: update() takes 1 positional argument but 2 were given
2021-09-09 22:23:34 ERROR (MainThread) [homeassistant] Error doing job: Future exception was never retrieved
Traceback (most recent call last):
  File "/usr/local/lib/python3.9/concurrent/futures/thread.py", line 52, in run
    result = self.fn(*self.args, **self.kwargs)
TypeError: update() takes 1 positional argument but 2 were given
2021-09-09 22:28:35 ERROR (MainThread) [homeassistant] Error doing job: Future exception was never retrieved
Traceback (most recent call last):
  File "/usr/local/lib/python3.9/concurrent/futures/thread.py", line 52, in run
    result = self.fn(*self.args, **self.kwargs)
TypeError: update() takes 1 positional argument but 2 were given
2021-09-09 22:33:36 ERROR (MainThread) [homeassistant] Error doing job: Future exception was never retrieved
Traceback (most recent call last):
  File "/usr/local/lib/python3.9/concurrent/futures/thread.py", line 52, in run
    result = self.fn(*self.args, **self.kwargs)
TypeError: update() takes 1 positional argument but 2 were given
2021-09-09 22:38:37 ERROR (MainThread) [homeassistant] Error doing job: Future exception was never retrieved
Traceback (most recent call last):
  File "/usr/local/lib/python3.9/concurrent/futures/thread.py", line 52, in run
    result = self.fn(*self.args, **self.kwargs)
TypeError: update() takes 1 positional argument but 2 were given
2021-09-09 22:43:38 ERROR (MainThread) [homeassistant] Error doing job: Future exception was never retrieved
Traceback (most recent call last):
  File "/usr/local/lib/python3.9/concurrent/futures/thread.py", line 52, in run
    result = self.fn(*self.args, **self.kwargs)
TypeError: update() takes 1 positional argument but 2 were given
2021-09-09 22:48:39 ERROR (MainThread) [homeassistant] Error doing job: Future exception was never retrieved
Traceback (most recent call last):
  File "/usr/local/lib/python3.9/concurrent/futures/thread.py", line 52, in run
    result = self.fn(*self.args, **self.kwargs)
TypeError: update() takes 1 positional argument but 2 were given
2021-09-09 22:53:40 ERROR (MainThread) [homeassistant] Error doing job: Future exception was never retrieved
Traceback (most recent call last):
  File "/usr/local/lib/python3.9/concurrent/futures/thread.py", line 52, in run
    result = self.fn(*self.args, **self.kwargs)
TypeError: update() takes 1 positional argument but 2 were given
2021-09-09 22:57:51 ERROR (stream_worker) [libav.tls] Error in the pull function.
2021-09-09 22:57:51 ERROR (stream_worker) [libav.tls] The specified session has been invalidated for some reason.
2021-09-09 22:57:51 ERROR (stream_worker) [homeassistant.components.stream.worker] Error demuxing stream: 
2021-09-09 22:58:41 ERROR (MainThread) [homeassistant] Error doing job: Future exception was never retrieved
Traceback (most recent call last):
  File "/usr/local/lib/python3.9/concurrent/futures/thread.py", line 52, in run
    result = self.fn(*self.args, **self.kwargs)
TypeError: update() takes 1 positional argument but 2 were given
2021-09-09 23:00:00 WARNING (MainThread) [homeassistant.helpers.service] Unable to find referenced entities light.sophia_wled
2021-09-09 23:03:42 ERROR (MainThread) [homeassistant] Error doing job: Future exception was never retrieved
Traceback (most recent call last):
  File "/usr/local/lib/python3.9/concurrent/futures/thread.py", line 52, in run
    result = self.fn(*self.args, **self.kwargs)
TypeError: update() takes 1 positional argument but 2 were given
2021-09-09 23:08:43 ERROR (MainThread) [homeassistant] Error doing job: Future exception was never retrieved
Traceback (most recent call last):
  File "/usr/local/lib/python3.9/concurrent/futures/thread.py", line 52, in run
    result = self.fn(*self.args, **self.kwargs)
TypeError: update() takes 1 positional argument but 2 were given
2021-09-09 23:13:44 ERROR (MainThread) [homeassistant] Error doing job: Future exception was never retrieved
Traceback (most recent call last):
  File "/usr/local/lib/python3.9/concurrent/futures/thread.py", line 52, in run
    result = self.fn(*self.args, **self.kwargs)
TypeError: update() takes 1 positional argument but 2 were given
2021-09-09 23:18:45 ERROR (MainThread) [homeassistant] Error doing job: Future exception was never retrieved
Traceback (most recent call last):
  File "/usr/local/lib/python3.9/concurrent/futures/thread.py", line 52, in run
    result = self.fn(*self.args, **self.kwargs)
TypeError: update() takes 1 positional argument but 2 were given
2021-09-09 23:23:46 ERROR (MainThread) [homeassistant] Error doing job: Future exception was never retrieved
Traceback (most recent call last):
  File "/usr/local/lib/python3.9/concurrent/futures/thread.py", line 52, in run
    result = self.fn(*self.args, **self.kwargs)
TypeError: update() takes 1 positional argument but 2 were given
2021-09-09 23:23:48 ERROR (MainThread) [iotawattpy.connection] Err: 
2021-09-09 23:23:48 ERROR (MainThread) [homeassistant.components.iotawatt.coordinator] Unexpected error fetching 192.168.20.195 data: 'NoneType' object has no attribute 'text'
Traceback (most recent call last):
  File "/usr/src/homeassistant/homeassistant/helpers/update_coordinator.py", line 187, in _async_refresh
    self.data = await self._async_update_data()
  File "/usr/src/homeassistant/homeassistant/components/iotawatt/coordinator.py", line 55, in _async_update_data
    await self.api.update()
  File "/usr/local/lib/python3.9/site-packages/iotawattpy/iotawatt.py", line 66, in update
    await self._refreshSensors(timespan)
  File "/usr/local/lib/python3.9/site-packages/iotawattpy/iotawatt.py", line 100, in _refreshSensors
    results = response.text
AttributeError: 'NoneType' object has no attribute 'text'
2021-09-09 23:28:47 ERROR (MainThread) [homeassistant] Error doing job: Future exception was never retrieved
Traceback (most recent call last):
  File "/usr/local/lib/python3.9/concurrent/futures/thread.py", line 52, in run
    result = self.fn(*self.args, **self.kwargs)
TypeError: update() takes 1 positional argument but 2 were given
2021-09-09 23:33:48 ERROR (MainThread) [homeassistant] Error doing job: Future exception was never retrieved
Traceback (most recent call last):
  File "/usr/local/lib/python3.9/concurrent/futures/thread.py", line 52, in run
    result = self.fn(*self.args, **self.kwargs)
TypeError: update() takes 1 positional argument but 2 were given
2021-09-09 23:38:49 ERROR (MainThread) [homeassistant] Error doing job: Future exception was never retrieved
Traceback (most recent call last):
  File "/usr/local/lib/python3.9/concurrent/futures/thread.py", line 52, in run
    result = self.fn(*self.args, **self.kwargs)
TypeError: update() takes 1 positional argument but 2 were given
2021-09-09 23:43:24 ERROR (MainThread) [homeassistant.components.nws] Error requesting NWS forecast station SAUC1 data: 500, message='Internal Server Error', url=URL('https://api.weather.gov/gridpoints/LOX/146,60/forecast')
2021-09-09 23:43:50 ERROR (MainThread) [homeassistant] Error doing job: Future exception was never retrieved
Traceback (most recent call last):
  File "/usr/local/lib/python3.9/concurrent/futures/thread.py", line 52, in run
    result = self.fn(*self.args, **self.kwargs)
TypeError: update() takes 1 positional argument but 2 were given
2021-09-09 23:48:51 ERROR (MainThread) [homeassistant] Error doing job: Future exception was never retrieved
Traceback (most recent call last):
  File "/usr/local/lib/python3.9/concurrent/futures/thread.py", line 52, in run
    result = self.fn(*self.args, **self.kwargs)
TypeError: update() takes 1 positional argument but 2 were given
2021-09-09 23:49:00 WARNING (MainThread) [homeassistant.helpers.service] Unable to find referenced entities light.hue_lightstrip_2
2021-09-09 23:53:52 ERROR (MainThread) [homeassistant] Error doing job: Future exception was never retrieved
Traceback (most recent call last):
  File "/usr/local/lib/python3.9/concurrent/futures/thread.py", line 52, in run
    result = self.fn(*self.args, **self.kwargs)
TypeError: update() takes 1 positional argument but 2 were given
2021-09-09 23:58:53 ERROR (MainThread) [homeassistant] Error doing job: Future exception was never retrieved
Traceback (most recent call last):
  File "/usr/local/lib/python3.9/concurrent/futures/thread.py", line 52, in run
    result = self.fn(*self.args, **self.kwargs)
TypeError: update() takes 1 positional argument but 2 were given
2021-09-10 00:03:54 ERROR (MainThread) [homeassistant] Error doing job: Future exception was never retrieved
Traceback (most recent call last):
  File "/usr/local/lib/python3.9/concurrent/futures/thread.py", line 52, in run
    result = self.fn(*self.args, **self.kwargs)
TypeError: update() takes 1 positional argument but 2 were given
2021-09-10 00:08:55 ERROR (MainThread) [homeassistant] Error doing job: Future exception was never retrieved
Traceback (most recent call last):
  File "/usr/local/lib/python3.9/concurrent/futures/thread.py", line 52, in run
    result = self.fn(*self.args, **self.kwargs)
TypeError: update() takes 1 positional argument but 2 were given
2021-09-10 00:13:56 ERROR (MainThread) [homeassistant] Error doing job: Future exception was never retrieved
Traceback (most recent call last):
  File "/usr/local/lib/python3.9/concurrent/futures/thread.py", line 52, in run
    result = self.fn(*self.args, **self.kwargs)
TypeError: update() takes 1 positional argument but 2 were given
2021-09-10 00:18:57 ERROR (MainThread) [homeassistant] Error doing job: Future exception was never retrieved
Traceback (most recent call last):
  File "/usr/local/lib/python3.9/concurrent/futures/thread.py", line 52, in run
    result = self.fn(*self.args, **self.kwargs)
TypeError: update() takes 1 positional argument but 2 were given
2021-09-10 00:23:58 ERROR (MainThread) [homeassistant] Error doing job: Future exception was never retrieved
Traceback (most recent call last):
  File "/usr/local/lib/python3.9/concurrent/futures/thread.py", line 52, in run
    result = self.fn(*self.args, **self.kwargs)
TypeError: update() takes 1 positional argument but 2 were given
2021-09-10 00:28:59 ERROR (MainThread) [homeassistant] Error doing job: Future exception was never retrieved
Traceback (most recent call last):
  File "/usr/local/lib/python3.9/concurrent/futures/thread.py", line 52, in run
    result = self.fn(*self.args, **self.kwargs)
TypeError: update() takes 1 positional argument but 2 were given
2021-09-10 00:34:00 ERROR (MainThread) [homeassistant] Error doing job: Future exception was never retrieved
Traceback (most recent call last):
  File "/usr/local/lib/python3.9/concurrent/futures/thread.py", line 52, in run
    result = self.fn(*self.args, **self.kwargs)
TypeError: update() takes 1 positional argument but 2 were given
2021-09-10 00:36:52 WARNING (MainThread) [homeassistant.components.rest.sensor] REST result could not be parsed as JSON
2021-09-10 00:36:52 ERROR (MainThread) [homeassistant.helpers.template] Template variable error: 'mappingproxy object' has no attribute 'iss_position' when rendering '{"longitude": "{{ states.sensor.iss_coordinates.attributes.iss_position.longitude | float }}","latitude": "{{ states.sensor.iss_coordinates.attributes.iss_position.latitude | float }}"}'
2021-09-10 00:36:52 ERROR (MainThread) [homeassistant.components.automation.iss_location_update] ISS Location Update: Error executing script. Error for call_service at pos 1: Error rendering data template: UndefinedError: 'mappingproxy object' has no attribute 'iss_position'
2021-09-10 00:36:52 ERROR (MainThread) [homeassistant.components.automation.iss_location_update] Error while executing automation automation.iss_location_update: Error rendering data template: UndefinedError: 'mappingproxy object' has no attribute 'iss_position'
2021-09-10 00:38:51 WARNING (MainThread) [homeassistant.components.rest.sensor] REST result could not be parsed as JSON
2021-09-10 00:38:52 WARNING (MainThread) [homeassistant.components.rest.sensor] REST result could not be parsed as JSON
2021-09-10 00:38:52 ERROR (MainThread) [homeassistant.helpers.template] Template variable error: 'mappingproxy object' has no attribute 'iss_position' when rendering '{"longitude": "{{ states.sensor.iss_coordinates.attributes.iss_position.longitude | float }}","latitude": "{{ states.sensor.iss_coordinates.attributes.iss_position.latitude | float }}"}'
2021-09-10 00:38:52 ERROR (MainThread) [homeassistant.components.automation.iss_location_update] ISS Location Update: Error executing script. Error for call_service at pos 1: Error rendering data template: UndefinedError: 'mappingproxy object' has no attribute 'iss_position'
2021-09-10 00:38:52 ERROR (MainThread) [homeassistant.components.automation.iss_location_update] Error while executing automation automation.iss_location_update: Error rendering data template: UndefinedError: 'mappingproxy object' has no attribute 'iss_position'
2021-09-10 00:39:01 ERROR (MainThread) [homeassistant] Error doing job: Future exception was never retrieved
Traceback (most recent call last):
  File "/usr/local/lib/python3.9/concurrent/futures/thread.py", line 52, in run
    result = self.fn(*self.args, **self.kwargs)
TypeError: update() takes 1 positional argument but 2 were given
2021-09-10 00:39:05 WARNING (MainThread) [homeassistant.components.rest.sensor] REST result could not be parsed as JSON
2021-09-10 00:39:20 WARNING (MainThread) [homeassistant.components.rest.sensor] REST result could not be parsed as JSON
2021-09-10 00:39:26 WARNING (MainThread) [homeassistant.components.rest.sensor] REST result could not be parsed as JSON
2021-09-10 00:44:02 ERROR (MainThread) [homeassistant] Error doing job: Future exception was never retrieved
Traceback (most recent call last):
  File "/usr/local/lib/python3.9/concurrent/futures/thread.py", line 52, in run
    result = self.fn(*self.args, **self.kwargs)
TypeError: update() takes 1 positional argument but 2 were given
2021-09-10 00:49:03 ERROR (MainThread) [homeassistant] Error doing job: Future exception was never retrieved
Traceback (most recent call last):
  File "/usr/local/lib/python3.9/concurrent/futures/thread.py", line 52, in run
    result = self.fn(*self.args, **self.kwargs)
TypeError: update() takes 1 positional argument but 2 were given
2021-09-10 00:54:04 ERROR (MainThread) [homeassistant] Error doing job: Future exception was never retrieved
Traceback (most recent call last):
  File "/usr/local/lib/python3.9/concurrent/futures/thread.py", line 52, in run
    result = self.fn(*self.args, **self.kwargs)
TypeError: update() takes 1 positional argument but 2 were given
2021-09-10 00:59:05 ERROR (MainThread) [homeassistant] Error doing job: Future exception was never retrieved
Traceback (most recent call last):
  File "/usr/local/lib/python3.9/concurrent/futures/thread.py", line 52, in run
    result = self.fn(*self.args, **self.kwargs)
TypeError: update() takes 1 positional argument but 2 were given
2021-09-10 01:04:06 ERROR (MainThread) [homeassistant] Error doing job: Future exception was never retrieved
Traceback (most recent call last):
  File "/usr/local/lib/python3.9/concurrent/futures/thread.py", line 52, in run
    result = self.fn(*self.args, **self.kwargs)
TypeError: update() takes 1 positional argument but 2 were given
2021-09-10 01:09:07 ERROR (MainThread) [homeassistant] Error doing job: Future exception was never retrieved
Traceback (most recent call last):
  File "/usr/local/lib/python3.9/concurrent/futures/thread.py", line 52, in run
    result = self.fn(*self.args, **self.kwargs)
TypeError: update() takes 1 positional argument but 2 were given
2021-09-10 01:14:08 ERROR (MainThread) [homeassistant] Error doing job: Future exception was never retrieved
Traceback (most recent call last):
  File "/usr/local/lib/python3.9/concurrent/futures/thread.py", line 52, in run
    result = self.fn(*self.args, **self.kwargs)
TypeError: update() takes 1 positional argument but 2 were given
2021-09-10 01:19:09 ERROR (MainThread) [homeassistant] Error doing job: Future exception was never retrieved
Traceback (most recent call last):
  File "/usr/local/lib/python3.9/concurrent/futures/thread.py", line 52, in run
    result = self.fn(*self.args, **self.kwargs)
TypeError: update() takes 1 positional argument but 2 were given
2021-09-10 01:24:10 ERROR (MainThread) [homeassistant] Error doing job: Future exception was never retrieved
Traceback (most recent call last):
  File "/usr/local/lib/python3.9/concurrent/futures/thread.py", line 52, in run
    result = self.fn(*self.args, **self.kwargs)
TypeError: update() takes 1 positional argument but 2 were given
2021-09-10 01:29:11 ERROR (MainThread) [homeassistant] Error doing job: Future exception was never retrieved
Traceback (most recent call last):
  File "/usr/local/lib/python3.9/concurrent/futures/thread.py", line 52, in run
    result = self.fn(*self.args, **self.kwargs)
TypeError: update() takes 1 positional argument but 2 were given
2021-09-10 01:34:12 ERROR (MainThread) [homeassistant] Error doing job: Future exception was never retrieved
Traceback (most recent call last):
  File "/usr/local/lib/python3.9/concurrent/futures/thread.py", line 52, in run
    result = self.fn(*self.args, **self.kwargs)
TypeError: update() takes 1 positional argument but 2 were given
2021-09-10 01:39:13 ERROR (MainThread) [homeassistant] Error doing job: Future exception was never retrieved
Traceback (most recent call last):
  File "/usr/local/lib/python3.9/concurrent/futures/thread.py", line 52, in run
    result = self.fn(*self.args, **self.kwargs)
TypeError: update() takes 1 positional argument but 2 were given
2021-09-10 01:44:14 ERROR (MainThread) [homeassistant] Error doing job: Future exception was never retrieved
Traceback (most recent call last):
  File "/usr/local/lib/python3.9/concurrent/futures/thread.py", line 52, in run
    result = self.fn(*self.args, **self.kwargs)
TypeError: update() takes 1 positional argument but 2 were given
2021-09-10 01:49:15 ERROR (MainThread) [homeassistant] Error doing job: Future exception was never retrieved
Traceback (most recent call last):
  File "/usr/local/lib/python3.9/concurrent/futures/thread.py", line 52, in run
    result = self.fn(*self.args, **self.kwargs)
TypeError: update() takes 1 positional argument but 2 were given
2021-09-10 01:54:16 ERROR (MainThread) [homeassistant] Error doing job: Future exception was never retrieved
Traceback (most recent call last):
  File "/usr/local/lib/python3.9/concurrent/futures/thread.py", line 52, in run
    result = self.fn(*self.args, **self.kwargs)
TypeError: update() takes 1 positional argument but 2 were given
2021-09-10 01:59:17 ERROR (MainThread) [homeassistant] Error doing job: Future exception was never retrieved
Traceback (most recent call last):
  File "/usr/local/lib/python3.9/concurrent/futures/thread.py", line 52, in run
    result = self.fn(*self.args, **self.kwargs)
TypeError: update() takes 1 positional argument but 2 were given
2021-09-10 02:04:18 ERROR (MainThread) [homeassistant] Error doing job: Future exception was never retrieved
Traceback (most recent call last):
  File "/usr/local/lib/python3.9/concurrent/futures/thread.py", line 52, in run
    result = self.fn(*self.args, **self.kwargs)
TypeError: update() takes 1 positional argument but 2 were given
2021-09-10 02:09:19 ERROR (MainThread) [homeassistant] Error doing job: Future exception was never retrieved
Traceback (most recent call last):
  File "/usr/local/lib/python3.9/concurrent/futures/thread.py", line 52, in run
    result = self.fn(*self.args, **self.kwargs)
TypeError: update() takes 1 positional argument but 2 were given
2021-09-10 02:14:20 ERROR (MainThread) [homeassistant] Error doing job: Future exception was never retrieved
Traceback (most recent call last):
  File "/usr/local/lib/python3.9/concurrent/futures/thread.py", line 52, in run
    result = self.fn(*self.args, **self.kwargs)
TypeError: update() takes 1 positional argument but 2 were given
2021-09-10 02:19:21 ERROR (MainThread) [homeassistant] Error doing job: Future exception was never retrieved
Traceback (most recent call last):
  File "/usr/local/lib/python3.9/concurrent/futures/thread.py", line 52, in run
    result = self.fn(*self.args, **self.kwargs)
TypeError: update() takes 1 positional argument but 2 were given
2021-09-10 02:24:22 ERROR (MainThread) [homeassistant] Error doing job: Future exception was never retrieved
Traceback (most recent call last):
  File "/usr/local/lib/python3.9/concurrent/futures/thread.py", line 52, in run
    result = self.fn(*self.args, **self.kwargs)
TypeError: update() takes 1 positional argument but 2 were given
2021-09-10 02:29:23 ERROR (MainThread) [homeassistant] Error doing job: Future exception was never retrieved
Traceback (most recent call last):
  File "/usr/local/lib/python3.9/concurrent/futures/thread.py", line 52, in run
    result = self.fn(*self.args, **self.kwargs)
TypeError: update() takes 1 positional argument but 2 were given
2021-09-10 02:34:24 ERROR (MainThread) [homeassistant] Error doing job: Future exception was never retrieved
Traceback (most recent call last):
  File "/usr/local/lib/python3.9/concurrent/futures/thread.py", line 52, in run
    result = self.fn(*self.args, **self.kwargs)
TypeError: update() takes 1 positional argument but 2 were given
2021-09-10 02:39:25 ERROR (MainThread) [homeassistant] Error doing job: Future exception was never retrieved
Traceback (most recent call last):
  File "/usr/local/lib/python3.9/concurrent/futures/thread.py", line 52, in run
    result = self.fn(*self.args, **self.kwargs)
TypeError: update() takes 1 positional argument but 2 were given
2021-09-10 02:44:26 ERROR (MainThread) [homeassistant] Error doing job: Future exception was never retrieved
Traceback (most recent call last):
  File "/usr/local/lib/python3.9/concurrent/futures/thread.py", line 52, in run
    result = self.fn(*self.args, **self.kwargs)
TypeError: update() takes 1 positional argument but 2 were given
2021-09-10 02:49:27 ERROR (MainThread) [homeassistant] Error doing job: Future exception was never retrieved
Traceback (most recent call last):
  File "/usr/local/lib/python3.9/concurrent/futures/thread.py", line 52, in run
    result = self.fn(*self.args, **self.kwargs)
TypeError: update() takes 1 positional argument but 2 were given
2021-09-10 02:53:29 ERROR (MainThread) [iotawattpy.connection] Err: 
2021-09-10 02:53:29 ERROR (MainThread) [homeassistant.components.iotawatt.coordinator] Unexpected error fetching 192.168.20.195 data: 'NoneType' object has no attribute 'text'
Traceback (most recent call last):
  File "/usr/src/homeassistant/homeassistant/helpers/update_coordinator.py", line 187, in _async_refresh
    self.data = await self._async_update_data()
  File "/usr/src/homeassistant/homeassistant/components/iotawatt/coordinator.py", line 55, in _async_update_data
    await self.api.update()
  File "/usr/local/lib/python3.9/site-packages/iotawattpy/iotawatt.py", line 66, in update
    await self._refreshSensors(timespan)
  File "/usr/local/lib/python3.9/site-packages/iotawattpy/iotawatt.py", line 100, in _refreshSensors
    results = response.text
AttributeError: 'NoneType' object has no attribute 'text'
2021-09-10 02:54:28 ERROR (MainThread) [homeassistant] Error doing job: Future exception was never retrieved
Traceback (most recent call last):
  File "/usr/local/lib/python3.9/concurrent/futures/thread.py", line 52, in run
    result = self.fn(*self.args, **self.kwargs)
TypeError: update() takes 1 positional argument but 2 were given
2021-09-10 02:59:29 ERROR (MainThread) [homeassistant] Error doing job: Future exception was never retrieved
Traceback (most recent call last):
  File "/usr/local/lib/python3.9/concurrent/futures/thread.py", line 52, in run
    result = self.fn(*self.args, **self.kwargs)
TypeError: update() takes 1 positional argument but 2 were given
