2021-09-12 12:49:15 WARNING (SyncWorker_0) [homeassistant.loader] We found a custom integration sun2 which has not been tested by Home Assistant. This component might cause stability problems, be sure to disable it if you experience issues with Home Assistant
2021-09-12 12:49:24 WARNING (MainThread) [homeassistant.components.sensor] Entity sensor.cpu_temp (<class 'homeassistant.components.command_line.sensor.CommandSensor'>) with device_class None reports a temperature in °C which will be converted to °F. Temperature conversion for entities without correct device_class is deprecated and will be removed from Home Assistant Core 2022.3. Please update your configuration if device_class is manually configured, otherwise create a bug report at https://github.com/home-assistant/core/issues?q=is%3Aopen+is%3Aissue+label%3A%22integration%3A+command_line%22
2021-09-12 12:49:24 WARNING (MainThread) [homeassistant.components.sensor] Entity sensor.iotawatt_total_sce_kwh_cost (<class 'homeassistant.components.energy.sensor.EnergyCostSensor'>) with state_class measurement has set last_reset. Setting last_reset is deprecated and will be unsupported from Home Assistant Core 2021.11. Please update your configuration if state_class is manually configured, otherwise create a bug report at https://github.com/home-assistant/core/issues?q=is%3Aopen+is%3Aissue+label%3A%22integration%3A+energy%22
2021-09-12 12:49:24 WARNING (MainThread) [homeassistant.components.sensor] Entity sensor.iotawatt_gridexport_compensation (<class 'homeassistant.components.energy.sensor.EnergyCostSensor'>) with state_class measurement has set last_reset. Setting last_reset is deprecated and will be unsupported from Home Assistant Core 2021.11. Please update your configuration if state_class is manually configured, otherwise create a bug report at https://github.com/home-assistant/core/issues?q=is%3Aopen+is%3Aissue+label%3A%22integration%3A+energy%22
2021-09-12 12:49:25 ERROR (MainThread) [snitun.client.client_peer] Challenge/Response error with SniTun server
2021-09-12 12:49:25 ERROR (MainThread) [hass_nabucasa.remote] Connection problem to snitun server
2021-09-12 12:49:28 WARNING (MainThread) [homeassistant.config_entries] Config entry 'Roku Smart Soundbar' for roku integration not ready yet: Invalid response from API: Error occurred while communicating with device; Retrying in background
2021-09-12 12:49:30 WARNING (MainThread) [homeassistant.components.sensor] Entity sensor.attictemp1_bme280_dewpoint (<class 'homeassistant.components.tasmota.sensor.TasmotaSensor'>) with device_class None reports a temperature in °C which will be converted to °F. Temperature conversion for entities without correct device_class is deprecated and will be removed from Home Assistant Core 2022.3. Please update your configuration if device_class is manually configured, otherwise create a bug report at https://github.com/home-assistant/core/issues?q=is%3Aopen+is%3Aissue+label%3A%22integration%3A+tasmota%22
2021-09-12 12:49:30 WARNING (MainThread) [homeassistant.components.sensor] Entity sensor.garagesidedoorsensor_bme280_dewpoint (<class 'homeassistant.components.tasmota.sensor.TasmotaSensor'>) with device_class None reports a temperature in °C which will be converted to °F. Temperature conversion for entities without correct device_class is deprecated and will be removed from Home Assistant Core 2022.3. Please update your configuration if device_class is manually configured, otherwise create a bug report at https://github.com/home-assistant/core/issues?q=is%3Aopen+is%3Aissue+label%3A%22integration%3A+tasmota%22
2021-09-12 12:49:33 WARNING (MainThread) [homeassistant.config_entries] Config entry '192.168.7.195' for wled integration not ready yet: Invalid response from API: Error occurred while communicating with WLED device at 192.168.7.195; Retrying in background
2021-09-12 12:54:21 ERROR (MainThread) [homeassistant] Error doing job: Future exception was never retrieved
Traceback (most recent call last):
  File "/usr/local/lib/python3.9/concurrent/futures/thread.py", line 52, in run
    result = self.fn(*self.args, **self.kwargs)
TypeError: update() takes 1 positional argument but 2 were given
2021-09-12 12:59:01 ERROR (stream_worker) [homeassistant.components.stream.worker] Stream has no video
2021-09-12 12:59:22 ERROR (MainThread) [homeassistant] Error doing job: Future exception was never retrieved
Traceback (most recent call last):
  File "/usr/local/lib/python3.9/concurrent/futures/thread.py", line 52, in run
    result = self.fn(*self.args, **self.kwargs)
TypeError: update() takes 1 positional argument but 2 were given
2021-09-12 13:00:09 WARNING (MainThread) [bellows.zigbee.application] Watchdog heartbeat timeout: 
2021-09-12 13:00:24 WARNING (MainThread) [bellows.zigbee.application] Watchdog heartbeat timeout: 
2021-09-12 13:00:39 WARNING (MainThread) [bellows.zigbee.application] Watchdog heartbeat timeout: 
2021-09-12 13:00:54 WARNING (MainThread) [bellows.zigbee.application] Watchdog heartbeat timeout: 
2021-09-12 13:01:09 WARNING (MainThread) [bellows.zigbee.application] Watchdog heartbeat timeout: 
2021-09-12 13:02:35 WARNING (bellows.thread_0) [bellows.uart] Reset future is None
2021-09-12 13:02:36 ERROR (bellows.thread_0) [bellows.uart] Lost serial connection: read failed: socket disconnected
2021-09-12 13:02:36 ERROR (MainThread) [bellows.ezsp] NCP entered failed state. Requesting APP controller restart
2021-09-12 13:02:42 WARNING (bellows.thread_0) [bellows.uart] Reset future is None
2021-09-12 13:02:48 WARNING (bellows.thread_0) [bellows.uart] Reset future is None
2021-09-12 13:04:23 ERROR (MainThread) [homeassistant] Error doing job: Future exception was never retrieved
Traceback (most recent call last):
  File "/usr/local/lib/python3.9/concurrent/futures/thread.py", line 52, in run
    result = self.fn(*self.args, **self.kwargs)
TypeError: update() takes 1 positional argument but 2 were given
2021-09-12 13:08:21 ERROR (stream_worker) [homeassistant.components.stream.worker] Error opening stream rtsps://stream-uc2-delta.dropcam.com:443/sdm_live_stream/CiQA2vuxr2T1DqLTUax62v6siS6EajQNW96emz-R0JXW-B9XlPYScQAFjsOTYtoQ3z706HgMB1z8nPJ7hGr54blSbZPAzHzVxcoJzJxey-UaQx5wprpQ3XSQon9brSe5woP1xluRbuqk_MdGf1MGhpDJEvQli0kfpS7IGYeFIaULKDE2SVTESgqpShTXFBytxhdnoRD6VJVw?auth=g.0.eyJraWQiOiIyMzhiNTUxZmMyM2EyM2Y4M2E2ZTE3MmJjZTg0YmU3ZjgxMzAzMmM4IiwiYWxnIjoiUlMyNTYifQ.eyJpc3MiOiJuZXN0LXNlY3VyaXR5LWF1dGhwcm94eSIsInN1YiI6Im5lc3RfaWQ6bmVzdC1waG9lbml4LXByb2Q6MjEyMTgxNDEiLCJwb2wiOiIzcC1vYXV0aC1zY29wZS1BUElfU0RNX1NFUlZJQ0UtY2xpZW50LTIwMjQyNzMxODczNS1qNXQ5bWMyMzZqaG85YXMycWY0dTZxY3NmYW1kaGJ0ci5hcHBzLmdvb2dsZXVzZXJjb250ZW50LmNvbSIsImV4cCI6MTYzMTQ3NzU3MX0.O3hLihDuzStmuNN6a6spQD2UF7rveX7Vfb7dTv9wcZaLK0BcUXRnHLtKjPCXlG6ttsfNsC0tMQ0d1oaYDETA7pvyv2kgojfhcTooDGOF9hFUpyVbPn_UoalpjNwKlrH8tQAUZENYawk9eRHpBVOcyPL6m5fRb_WMgpfr_fL1ZDdr4YyjB5L26uo6C2J3otvvoCgbtwA2EfPC3QyE7F8u2p99V-iyXgZcIU7p0QWWlaXMyX916L_gD2EYVnMGOZUsdge1OQj8MUvxkr4g7--xWP95I0lZd5JnJwdyS4hpXtCpR5b3XYxJvT8mWfLGxac7GkWHMIR2U8c9rjfjMKlGLQ
2021-09-12 13:09:24 ERROR (MainThread) [homeassistant] Error doing job: Future exception was never retrieved
Traceback (most recent call last):
  File "/usr/local/lib/python3.9/concurrent/futures/thread.py", line 52, in run
    result = self.fn(*self.args, **self.kwargs)
TypeError: update() takes 1 positional argument but 2 were given
2021-09-12 13:12:00 ERROR (MainThread) [homeassistant] Error doing job: Task was destroyed but it is pending!
2021-09-12 13:14:25 ERROR (MainThread) [homeassistant] Error doing job: Future exception was never retrieved
Traceback (most recent call last):
  File "/usr/local/lib/python3.9/concurrent/futures/thread.py", line 52, in run
    result = self.fn(*self.args, **self.kwargs)
TypeError: update() takes 1 positional argument but 2 were given
2021-09-12 13:19:26 ERROR (MainThread) [homeassistant] Error doing job: Future exception was never retrieved
Traceback (most recent call last):
  File "/usr/local/lib/python3.9/concurrent/futures/thread.py", line 52, in run
    result = self.fn(*self.args, **self.kwargs)
TypeError: update() takes 1 positional argument but 2 were given
2021-09-12 13:24:27 ERROR (MainThread) [homeassistant] Error doing job: Future exception was never retrieved
Traceback (most recent call last):
  File "/usr/local/lib/python3.9/concurrent/futures/thread.py", line 52, in run
    result = self.fn(*self.args, **self.kwargs)
TypeError: update() takes 1 positional argument but 2 were given
2021-09-12 13:26:18 ERROR (stream_worker) [libav.rtsp] method DESCRIBE failed: 404 Not Found
2021-09-12 13:26:18 ERROR (stream_worker) [homeassistant.components.stream.worker] Error opening stream rtsps://stream-uc2-delta.dropcam.com:443/sdm_live_stream/CiQA2vuxr2T1DqLTUax62v6siS6EajQNW96emz-R0JXW-B9XlPYScQAFjsOTYtoQ3z706HgMB1z8nPJ7hGr54blSbZPAzHzVxcoJzJxey-UaQx5wprpQ3XSQon9brSe5woP1xluRbuqk_MdGf1MGhpDJEvQli0kfpS7IGYeFIaULKDE2SVTESgqpShTXFBytxhdnoRD6VJVw?auth=g.0.eyJraWQiOiIyMzhiNTUxZmMyM2EyM2Y4M2E2ZTE3MmJjZTg0YmU3ZjgxMzAzMmM4IiwiYWxnIjoiUlMyNTYifQ.eyJpc3MiOiJuZXN0LXNlY3VyaXR5LWF1dGhwcm94eSIsInN1YiI6Im5lc3RfaWQ6bmVzdC1waG9lbml4LXByb2Q6MjEyMTgxNDEiLCJwb2wiOiIzcC1vYXV0aC1zY29wZS1BUElfU0RNX1NFUlZJQ0UtY2xpZW50LTIwMjQyNzMxODczNS1qNXQ5bWMyMzZqaG85YXMycWY0dTZxY3NmYW1kaGJ0ci5hcHBzLmdvb2dsZXVzZXJjb250ZW50LmNvbSIsImV4cCI6MTYzMTQ3ODY1M30.gN-47LfD7y_jS8Dt6ndu-e11YEbKl5TvRPEie7lcr9p5xdw0wWKyCJyR7yhGddsQH6HrlLBjengHa_AZ5ZUDUyh59zZ_FInPczFVLOnF7z09ObDB4FsyplKZ_zE50q5xm2LW8Ghuy65OUZ8ANQxlUaPFefAmC0Au1ACUcR050UeIv3v781cGlKQKOmeDQ1p2egQT4vTNMK91paRnxeQHZg3i6HGMo3vkZ0JNGaFDZMDXiB3OMSFEOIfLgGyo9r521H21FSYdaECkh6hOnt1S0FQrWocLuuYyh5vc9mmvStGuvJxTj9pywskfgujxzxWnG7TO-G1jB_49os-7NnuTZA
2021-09-12 13:29:28 ERROR (MainThread) [homeassistant] Error doing job: Future exception was never retrieved
Traceback (most recent call last):
  File "/usr/local/lib/python3.9/concurrent/futures/thread.py", line 52, in run
    result = self.fn(*self.args, **self.kwargs)
TypeError: update() takes 1 positional argument but 2 were given
2021-09-12 13:34:29 ERROR (MainThread) [homeassistant] Error doing job: Future exception was never retrieved
Traceback (most recent call last):
  File "/usr/local/lib/python3.9/concurrent/futures/thread.py", line 52, in run
    result = self.fn(*self.args, **self.kwargs)
TypeError: update() takes 1 positional argument but 2 were given
2021-09-12 13:39:30 ERROR (MainThread) [homeassistant] Error doing job: Future exception was never retrieved
Traceback (most recent call last):
  File "/usr/local/lib/python3.9/concurrent/futures/thread.py", line 52, in run
    result = self.fn(*self.args, **self.kwargs)
TypeError: update() takes 1 positional argument but 2 were given
2021-09-12 13:39:46 ERROR (stream_worker) [libav.rtsp] method DESCRIBE failed: 404 Not Found
2021-09-12 13:39:46 ERROR (stream_worker) [homeassistant.components.stream.worker] Error opening stream rtsps://stream-uc2-bravo.dropcam.com:443/sdm_live_stream/CiQA2vuxrx9EG79DDcei0gACOWGyinh-igsl0UbV_gDND2CAebsScQAFjsOTiY7o_biPCRfMQoZpfeCAtyMe61SS87cmtnGaims3FaLYvMtP6jIjm4h3HGWQ4_GmB_LShPBK6kHlLRBq9RlbSVjT97pPLTwbRARRWi14D45rys6WD1r8iLd2XCoQpSiMZ6TcleONEotB4KB2?auth=g.0.eyJraWQiOiIyMzhiNTUxZmMyM2EyM2Y4M2E2ZTE3MmJjZTg0YmU3ZjgxMzAzMmM4IiwiYWxnIjoiUlMyNTYifQ.eyJpc3MiOiJuZXN0LXNlY3VyaXR5LWF1dGhwcm94eSIsInN1YiI6Im5lc3RfaWQ6bmVzdC1waG9lbml4LXByb2Q6MjEyMTgxNDEiLCJwb2wiOiIzcC1vYXV0aC1zY29wZS1BUElfU0RNX1NFUlZJQ0UtY2xpZW50LTIwMjQyNzMxODczNS1qNXQ5bWMyMzZqaG85YXMycWY0dTZxY3NmYW1kaGJ0ci5hcHBzLmdvb2dsZXVzZXJjb250ZW50LmNvbSIsImV4cCI6MTYzMTQ3OTQ2NX0.Cg9YJILRjQCGU3EENeSNHNRoI_PXh_dcrk1zk9s2KwawT55CCvseLb1_Kl0rSDvVyv3z4wwi5lqH8MvF4a6nLRQkDISRq_RdBzaa8tgE7PbL8CIDbQi8dvm6eylqpBD4LkGzRa36EzP5P7E1XiSsNv7wzZb7DycO6dNgjbcuvfIGtk_ETQnNRN0YxCuNIbM3oFAA2mapF7YG6P25wo_qrPTpjWkdiNbxzKzUsfxg71Da-RBAtY2pTu2tIwemNmA5TUDPXWeJkpo-cB_-PD0hOftuZr63yz3brFuEyQDJIPPzEBfDYZpo8Fm254aRS9yMPseAhs5aL86VUhjmgBK7kA
2021-09-12 13:44:31 ERROR (MainThread) [homeassistant] Error doing job: Future exception was never retrieved
Traceback (most recent call last):
  File "/usr/local/lib/python3.9/concurrent/futures/thread.py", line 52, in run
    result = self.fn(*self.args, **self.kwargs)
TypeError: update() takes 1 positional argument but 2 were given
2021-09-12 13:49:00 ERROR (stream_worker) [homeassistant.components.stream.worker] Stream has no video
2021-09-12 13:49:32 ERROR (MainThread) [homeassistant] Error doing job: Future exception was never retrieved
Traceback (most recent call last):
  File "/usr/local/lib/python3.9/concurrent/futures/thread.py", line 52, in run
    result = self.fn(*self.args, **self.kwargs)
TypeError: update() takes 1 positional argument but 2 were given
2021-09-12 13:49:42 ERROR (stream_worker) [libav.rtsp] method DESCRIBE failed: 404 Not Found
2021-09-12 13:49:42 ERROR (stream_worker) [homeassistant.components.stream.worker] Error opening stream rtsps://stream-uc2-delta.dropcam.com:443/sdm_live_stream/CiQA2vuxr2T1DqLTUax62v6siS6EajQNW96emz-R0JXW-B9XlPYScQAFjsOTYtoQ3z706HgMB1z8nPJ7hGr54blSbZPAzHzVxcoJzJxey-UaQx5wprpQ3XSQon9brSe5woP1xluRbuqk_MdGf1MGhpDJEvQli0kfpS7IGYeFIaULKDE2SVTESgqpShTXFBytxhdnoRD6VJVw?auth=g.0.eyJraWQiOiIyMzhiNTUxZmMyM2EyM2Y4M2E2ZTE3MmJjZTg0YmU3ZjgxMzAzMmM4IiwiYWxnIjoiUlMyNTYifQ.eyJpc3MiOiJuZXN0LXNlY3VyaXR5LWF1dGhwcm94eSIsInN1YiI6Im5lc3RfaWQ6bmVzdC1waG9lbml4LXByb2Q6MjEyMTgxNDEiLCJwb2wiOiIzcC1vYXV0aC1zY29wZS1BUElfU0RNX1NFUlZJQ0UtY2xpZW50LTIwMjQyNzMxODczNS1qNXQ5bWMyMzZqaG85YXMycWY0dTZxY3NmYW1kaGJ0ci5hcHBzLmdvb2dsZXVzZXJjb250ZW50LmNvbSIsImV4cCI6MTYzMTQ4MDAwNn0.WFcov1RQmbOuD-ByVhbYudZCXUUfnOOaOWx56FB4STYcqMBCDPCnRyjb5WzWTNabHiJDMrwzGHGo9jSHaP17mqYyCjzqFnHIJMt4bJaPqd_djjx1ysbRH1dto1PqSODCYWuLLqy_6vTLItpxd4kl04gSD3LLvgOprNdcHcE2RBemps78uTRh6yZqxwy7xOUbz-Zu9BkkDSs8Y7o2rD6ueWBQOfAHlCY4L6Sw1FbA5tlOlL1zE2uJes4cxexQ6ezuFNx3SzMlEuDXNzG7DGpV9oVMTgHuT73ToIPt1biSUEBxQm1ybfPQNWKaWAYyjB4nrygVpWEOsMrWeL7Nh8aU7Q
2021-09-12 13:53:49 ERROR (stream_worker) [libav.rtsp] method DESCRIBE failed: 404 Not Found
2021-09-12 13:53:49 ERROR (stream_worker) [homeassistant.components.stream.worker] Error opening stream rtsps://stream-uc2-delta.dropcam.com:443/sdm_live_stream/CiQA2vuxr2T1DqLTUax62v6siS6EajQNW96emz-R0JXW-B9XlPYScQAFjsOTYtoQ3z706HgMB1z8nPJ7hGr54blSbZPAzHzVxcoJzJxey-UaQx5wprpQ3XSQon9brSe5woP1xluRbuqk_MdGf1MGhpDJEvQli0kfpS7IGYeFIaULKDE2SVTESgqpShTXFBytxhdnoRD6VJVw?auth=g.0.eyJraWQiOiIyMzhiNTUxZmMyM2EyM2Y4M2E2ZTE3MmJjZTg0YmU3ZjgxMzAzMmM4IiwiYWxnIjoiUlMyNTYifQ.eyJpc3MiOiJuZXN0LXNlY3VyaXR5LWF1dGhwcm94eSIsInN1YiI6Im5lc3RfaWQ6bmVzdC1waG9lbml4LXByb2Q6MjEyMTgxNDEiLCJwb2wiOiIzcC1vYXV0aC1zY29wZS1BUElfU0RNX1NFUlZJQ0UtY2xpZW50LTIwMjQyNzMxODczNS1qNXQ5bWMyMzZqaG85YXMycWY0dTZxY3NmYW1kaGJ0ci5hcHBzLmdvb2dsZXVzZXJjb250ZW50LmNvbSIsImV4cCI6MTYzMTQ4MDI3N30.q0rg1R-y6hTDInnefjmmufdCy6qKpPHnlHC3J79-P3GfG3nFLdiPxLRwlLKP6rplHQm-VwLemnl4HQLTeZrxkgEoHp1rmFWDKNMXT4QuAWxLu1y-BBAE4LxrT1-ju5grbJ1f9b35xTbbLYcgiztXQVQQUZMAd7rw67zsnqcTWR1LAyeEGpNRJFSXbrcDZolLpSJolBby7Jwzh9ebhg-xwuvPDlugz-l6RrcZAvzKB3BMoY-ZS6h3yVXQYL1d3fMQruOvQwsRPbiQu2p3C4t-XkpPA1mjavG0UL1ugH0CdVLsnl2zDb2lShnRy6HWvm8QqqGAZ-nV6hqIL7KMF94w2A
2021-09-12 13:54:33 ERROR (MainThread) [homeassistant] Error doing job: Future exception was never retrieved
Traceback (most recent call last):
  File "/usr/local/lib/python3.9/concurrent/futures/thread.py", line 52, in run
    result = self.fn(*self.args, **self.kwargs)
TypeError: update() takes 1 positional argument but 2 were given
2021-09-12 13:58:03 ERROR (stream_worker) [libav.rtsp] method DESCRIBE failed: 404 Not Found
2021-09-12 13:58:03 ERROR (stream_worker) [homeassistant.components.stream.worker] Error opening stream rtsps://stream-uc2-bravo.dropcam.com:443/sdm_live_stream/CiQA2vuxrx9EG79DDcei0gACOWGyinh-igsl0UbV_gDND2CAebsScQAFjsOTiY7o_biPCRfMQoZpfeCAtyMe61SS87cmtnGaims3FaLYvMtP6jIjm4h3HGWQ4_GmB_LShPBK6kHlLRBq9RlbSVjT97pPLTwbRARRWi14D45rys6WD1r8iLd2XCoQpSiMZ6TcleONEotB4KB2?auth=g.0.eyJraWQiOiIyMzhiNTUxZmMyM2EyM2Y4M2E2ZTE3MmJjZTg0YmU3ZjgxMzAzMmM4IiwiYWxnIjoiUlMyNTYifQ.eyJpc3MiOiJuZXN0LXNlY3VyaXR5LWF1dGhwcm94eSIsInN1YiI6Im5lc3RfaWQ6bmVzdC1waG9lbml4LXByb2Q6MjEyMTgxNDEiLCJwb2wiOiIzcC1vYXV0aC1zY29wZS1BUElfU0RNX1NFUlZJQ0UtY2xpZW50LTIwMjQyNzMxODczNS1qNXQ5bWMyMzZqaG85YXMycWY0dTZxY3NmYW1kaGJ0ci5hcHBzLmdvb2dsZXVzZXJjb250ZW50LmNvbSIsImV4cCI6MTYzMTQ4MDU0N30.czu107RaOT8k_wyfZF6GWbTJxGuMpadkwiiEDIj0-w1BO-4oVmIhAXQZhz4ToY5GUHb162cqG3-WYzd5iklUtXl05i0-vbmIWpuv0y_WkGgjnS2nQsszGwAif7R8wsGOpmetTa6Glf6EhRJ2w7oOhMiXB_XJD3ulcwyZLEq54HVwj0g8GQ33g007ljPpWy_Y3lg-MxyLmCCQYv45OHyKZqUYNKx6xhimpJtjSbm202K9Pd5IhYMwOZPXPxv8lnUD3WX6ESRKKd5_EtRijwGABBZ7Aa628k2INLXSme49yd9q08rYzNiCUGdfBB9H91qOpmCvLTaIskBbK9oBnSaQeA
2021-09-12 13:58:12 WARNING (MainThread) [bellows.zigbee.application] Watchdog heartbeat timeout: 
2021-09-12 13:58:35 ERROR (stream_worker) [libav.rtsp] method DESCRIBE failed: 404 Not Found
2021-09-12 13:58:35 ERROR (stream_worker) [homeassistant.components.stream.worker] Error opening stream rtsps://stream-uc2-delta.dropcam.com:443/sdm_live_stream/CiQA2vuxr2T1DqLTUax62v6siS6EajQNW96emz-R0JXW-B9XlPYScQAFjsOTYtoQ3z706HgMB1z8nPJ7hGr54blSbZPAzHzVxcoJzJxey-UaQx5wprpQ3XSQon9brSe5woP1xluRbuqk_MdGf1MGhpDJEvQli0kfpS7IGYeFIaULKDE2SVTESgqpShTXFBytxhdnoRD6VJVw?auth=g.0.eyJraWQiOiIyMzhiNTUxZmMyM2EyM2Y4M2E2ZTE3MmJjZTg0YmU3ZjgxMzAzMmM4IiwiYWxnIjoiUlMyNTYifQ.eyJpc3MiOiJuZXN0LXNlY3VyaXR5LWF1dGhwcm94eSIsInN1YiI6Im5lc3RfaWQ6bmVzdC1waG9lbml4LXByb2Q6MjEyMTgxNDEiLCJwb2wiOiIzcC1vYXV0aC1zY29wZS1BUElfU0RNX1NFUlZJQ0UtY2xpZW50LTIwMjQyNzMxODczNS1qNXQ5bWMyMzZqaG85YXMycWY0dTZxY3NmYW1kaGJ0ci5hcHBzLmdvb2dsZXVzZXJjb250ZW50LmNvbSIsImV4cCI6MTYzMTQ4MDU0N30.czu107RaOT8k_wyfZF6GWbTJxGuMpadkwiiEDIj0-w1BO-4oVmIhAXQZhz4ToY5GUHb162cqG3-WYzd5iklUtXl05i0-vbmIWpuv0y_WkGgjnS2nQsszGwAif7R8wsGOpmetTa6Glf6EhRJ2w7oOhMiXB_XJD3ulcwyZLEq54HVwj0g8GQ33g007ljPpWy_Y3lg-MxyLmCCQYv45OHyKZqUYNKx6xhimpJtjSbm202K9Pd5IhYMwOZPXPxv8lnUD3WX6ESRKKd5_EtRijwGABBZ7Aa628k2INLXSme49yd9q08rYzNiCUGdfBB9H91qOpmCvLTaIskBbK9oBnSaQeA
2021-09-12 13:59:34 ERROR (MainThread) [homeassistant] Error doing job: Future exception was never retrieved
Traceback (most recent call last):
  File "/usr/local/lib/python3.9/concurrent/futures/thread.py", line 52, in run
    result = self.fn(*self.args, **self.kwargs)
TypeError: update() takes 1 positional argument but 2 were given
2021-09-12 13:59:45 ERROR (stream_worker) [libav.rtsp] method DESCRIBE failed: 404 Not Found
2021-09-12 13:59:45 ERROR (stream_worker) [homeassistant.components.stream.worker] Error opening stream rtsps://stream-uc2-delta.dropcam.com:443/sdm_live_stream/CiQA2vuxr2T1DqLTUax62v6siS6EajQNW96emz-R0JXW-B9XlPYScQAFjsOTYtoQ3z706HgMB1z8nPJ7hGr54blSbZPAzHzVxcoJzJxey-UaQx5wprpQ3XSQon9brSe5woP1xluRbuqk_MdGf1MGhpDJEvQli0kfpS7IGYeFIaULKDE2SVTESgqpShTXFBytxhdnoRD6VJVw?auth=g.0.eyJraWQiOiIyMzhiNTUxZmMyM2EyM2Y4M2E2ZTE3MmJjZTg0YmU3ZjgxMzAzMmM4IiwiYWxnIjoiUlMyNTYifQ.eyJpc3MiOiJuZXN0LXNlY3VyaXR5LWF1dGhwcm94eSIsInN1YiI6Im5lc3RfaWQ6bmVzdC1waG9lbml4LXByb2Q6MjEyMTgxNDEiLCJwb2wiOiIzcC1vYXV0aC1zY29wZS1BUElfU0RNX1NFUlZJQ0UtY2xpZW50LTIwMjQyNzMxODczNS1qNXQ5bWMyMzZqaG85YXMycWY0dTZxY3NmYW1kaGJ0ci5hcHBzLmdvb2dsZXVzZXJjb250ZW50LmNvbSIsImV4cCI6MTYzMTQ4MDU0N30.czu107RaOT8k_wyfZF6GWbTJxGuMpadkwiiEDIj0-w1BO-4oVmIhAXQZhz4ToY5GUHb162cqG3-WYzd5iklUtXl05i0-vbmIWpuv0y_WkGgjnS2nQsszGwAif7R8wsGOpmetTa6Glf6EhRJ2w7oOhMiXB_XJD3ulcwyZLEq54HVwj0g8GQ33g007ljPpWy_Y3lg-MxyLmCCQYv45OHyKZqUYNKx6xhimpJtjSbm202K9Pd5IhYMwOZPXPxv8lnUD3WX6ESRKKd5_EtRijwGABBZ7Aa628k2INLXSme49yd9q08rYzNiCUGdfBB9H91qOpmCvLTaIskBbK9oBnSaQeA
2021-09-12 14:00:33 ERROR (MainThread) [iotawattpy.connection] Err: 
2021-09-12 14:00:33 ERROR (MainThread) [homeassistant.components.iotawatt.coordinator] Unexpected error fetching 192.168.20.195 data: 'NoneType' object has no attribute 'text'
Traceback (most recent call last):
  File "/usr/src/homeassistant/homeassistant/helpers/update_coordinator.py", line 187, in _async_refresh
    self.data = await self._async_update_data()
  File "/usr/src/homeassistant/homeassistant/components/iotawatt/coordinator.py", line 55, in _async_update_data
    await self.api.update()
  File "/usr/local/lib/python3.9/site-packages/iotawattpy/iotawatt.py", line 66, in update
    await self._refreshSensors(timespan)
  File "/usr/local/lib/python3.9/site-packages/iotawattpy/iotawatt.py", line 100, in _refreshSensors
    results = response.text
AttributeError: 'NoneType' object has no attribute 'text'
2021-09-12 14:03:27 WARNING (MainThread) [haffmpeg.tools] Timeout reading image.
2021-09-12 14:04:35 ERROR (MainThread) [homeassistant] Error doing job: Future exception was never retrieved
Traceback (most recent call last):
  File "/usr/local/lib/python3.9/concurrent/futures/thread.py", line 52, in run
    result = self.fn(*self.args, **self.kwargs)
TypeError: update() takes 1 positional argument but 2 were given
2021-09-12 14:04:37 WARNING (MainThread) [haffmpeg.tools] Timeout reading image.
2021-09-12 14:04:47 WARNING (MainThread) [haffmpeg.tools] Timeout reading image.
2021-09-12 14:04:47 WARNING (MainThread) [haffmpeg.tools] Timeout reading image.
2021-09-12 14:05:47 WARNING (MainThread) [haffmpeg.tools] Timeout reading image.
2021-09-12 14:05:47 WARNING (MainThread) [haffmpeg.tools] Timeout reading image.
2021-09-12 14:05:57 WARNING (MainThread) [haffmpeg.tools] Timeout reading image.
2021-09-12 14:06:27 WARNING (MainThread) [haffmpeg.tools] Timeout reading image.
2021-09-12 14:07:49 ERROR (stream_worker) [libav.rtsp] method DESCRIBE failed: 404 Not Found
2021-09-12 14:07:49 ERROR (stream_worker) [homeassistant.components.stream.worker] Error opening stream rtsps://stream-uc2-delta.dropcam.com:443/sdm_live_stream/CiQA2vuxr2T1DqLTUax62v6siS6EajQNW96emz-R0JXW-B9XlPYScQAFjsOTYtoQ3z706HgMB1z8nPJ7hGr54blSbZPAzHzVxcoJzJxey-UaQx5wprpQ3XSQon9brSe5woP1xluRbuqk_MdGf1MGhpDJEvQli0kfpS7IGYeFIaULKDE2SVTESgqpShTXFBytxhdnoRD6VJVw?auth=g.0.eyJraWQiOiIyMzhiNTUxZmMyM2EyM2Y4M2E2ZTE3MmJjZTg0YmU3ZjgxMzAzMmM4IiwiYWxnIjoiUlMyNTYifQ.eyJpc3MiOiJuZXN0LXNlY3VyaXR5LWF1dGhwcm94eSIsInN1YiI6Im5lc3RfaWQ6bmVzdC1waG9lbml4LXByb2Q6MjEyMTgxNDEiLCJwb2wiOiIzcC1vYXV0aC1zY29wZS1BUElfU0RNX1NFUlZJQ0UtY2xpZW50LTIwMjQyNzMxODczNS1qNXQ5bWMyMzZqaG85YXMycWY0dTZxY3NmYW1kaGJ0ci5hcHBzLmdvb2dsZXVzZXJjb250ZW50LmNvbSIsImV4cCI6MTYzMTQ4MTA4OH0.BU2saPyKHCrXGppgxjQVgBzjMih-EtYPYtn7BFAePRlCEBTEnco-IEWKhuR5m8TTscpiYJ-_2oYvFQE_Yq1n2yQuxQlzqTOEwsxMEXaKsNA7wuqiK9JKlhYgHenoc2L3KNwbU7z2f1u6ZOmECkB4AVrseFY8RZhEAueJLbAKQuCllbDY6eYDCRZAcLtMeyO42sWNPFkykDO_jsJtLpMQT9wtwiu4smbLnQ8MCmlKV_3CJ5EQaF1aTD2v68PZl5HqMI7rVdSpp-Xg4HeiLzLe5YyPG-KxBQYGjmNFcLnb3jNKsE6UMeojiLFbH0TF5Enp9480lIBYidML68hGGiQFnA
2021-09-12 14:07:57 WARNING (MainThread) [haffmpeg.tools] Timeout reading image.
2021-09-12 14:09:23 ERROR (stream_worker) [libav.rtsp] method DESCRIBE failed: 404 Not Found
2021-09-12 14:09:23 ERROR (stream_worker) [homeassistant.components.stream.worker] Error opening stream rtsps://stream-uc2-delta.dropcam.com:443/sdm_live_stream/CiQA2vuxr2T1DqLTUax62v6siS6EajQNW96emz-R0JXW-B9XlPYScQAFjsOTYtoQ3z706HgMB1z8nPJ7hGr54blSbZPAzHzVxcoJzJxey-UaQx5wprpQ3XSQon9brSe5woP1xluRbuqk_MdGf1MGhpDJEvQli0kfpS7IGYeFIaULKDE2SVTESgqpShTXFBytxhdnoRD6VJVw?auth=g.0.eyJraWQiOiIyMzhiNTUxZmMyM2EyM2Y4M2E2ZTE3MmJjZTg0YmU3ZjgxMzAzMmM4IiwiYWxnIjoiUlMyNTYifQ.eyJpc3MiOiJuZXN0LXNlY3VyaXR5LWF1dGhwcm94eSIsInN1YiI6Im5lc3RfaWQ6bmVzdC1waG9lbml4LXByb2Q6MjEyMTgxNDEiLCJwb2wiOiIzcC1vYXV0aC1zY29wZS1BUElfU0RNX1NFUlZJQ0UtY2xpZW50LTIwMjQyNzMxODczNS1qNXQ5bWMyMzZqaG85YXMycWY0dTZxY3NmYW1kaGJ0ci5hcHBzLmdvb2dsZXVzZXJjb250ZW50LmNvbSIsImV4cCI6MTYzMTQ4MTA4OH0.BU2saPyKHCrXGppgxjQVgBzjMih-EtYPYtn7BFAePRlCEBTEnco-IEWKhuR5m8TTscpiYJ-_2oYvFQE_Yq1n2yQuxQlzqTOEwsxMEXaKsNA7wuqiK9JKlhYgHenoc2L3KNwbU7z2f1u6ZOmECkB4AVrseFY8RZhEAueJLbAKQuCllbDY6eYDCRZAcLtMeyO42sWNPFkykDO_jsJtLpMQT9wtwiu4smbLnQ8MCmlKV_3CJ5EQaF1aTD2v68PZl5HqMI7rVdSpp-Xg4HeiLzLe5YyPG-KxBQYGjmNFcLnb3jNKsE6UMeojiLFbH0TF5Enp9480lIBYidML68hGGiQFnA
2021-09-12 14:09:36 ERROR (MainThread) [homeassistant] Error doing job: Future exception was never retrieved
Traceback (most recent call last):
  File "/usr/local/lib/python3.9/concurrent/futures/thread.py", line 52, in run
    result = self.fn(*self.args, **self.kwargs)
TypeError: update() takes 1 positional argument but 2 were given
2021-09-12 14:09:47 WARNING (MainThread) [haffmpeg.tools] Timeout reading image.
2021-09-12 14:11:23 ERROR (stream_worker) [homeassistant.components.stream.worker] Error opening stream rtsps://stream-uc2-delta.dropcam.com:443/sdm_live_stream/CiQA2vuxr2T1DqLTUax62v6siS6EajQNW96emz-R0JXW-B9XlPYScQAFjsOTYtoQ3z706HgMB1z8nPJ7hGr54blSbZPAzHzVxcoJzJxey-UaQx5wprpQ3XSQon9brSe5woP1xluRbuqk_MdGf1MGhpDJEvQli0kfpS7IGYeFIaULKDE2SVTESgqpShTXFBytxhdnoRD6VJVw?auth=g.0.eyJraWQiOiIyMzhiNTUxZmMyM2EyM2Y4M2E2ZTE3MmJjZTg0YmU3ZjgxMzAzMmM4IiwiYWxnIjoiUlMyNTYifQ.eyJpc3MiOiJuZXN0LXNlY3VyaXR5LWF1dGhwcm94eSIsInN1YiI6Im5lc3RfaWQ6bmVzdC1waG9lbml4LXByb2Q6MjEyMTgxNDEiLCJwb2wiOiIzcC1vYXV0aC1zY29wZS1BUElfU0RNX1NFUlZJQ0UtY2xpZW50LTIwMjQyNzMxODczNS1qNXQ5bWMyMzZqaG85YXMycWY0dTZxY3NmYW1kaGJ0ci5hcHBzLmdvb2dsZXVzZXJjb250ZW50LmNvbSIsImV4cCI6MTYzMTQ4MTA4OH0.BU2saPyKHCrXGppgxjQVgBzjMih-EtYPYtn7BFAePRlCEBTEnco-IEWKhuR5m8TTscpiYJ-_2oYvFQE_Yq1n2yQuxQlzqTOEwsxMEXaKsNA7wuqiK9JKlhYgHenoc2L3KNwbU7z2f1u6ZOmECkB4AVrseFY8RZhEAueJLbAKQuCllbDY6eYDCRZAcLtMeyO42sWNPFkykDO_jsJtLpMQT9wtwiu4smbLnQ8MCmlKV_3CJ5EQaF1aTD2v68PZl5HqMI7rVdSpp-Xg4HeiLzLe5YyPG-KxBQYGjmNFcLnb3jNKsE6UMeojiLFbH0TF5Enp9480lIBYidML68hGGiQFnA
2021-09-12 14:11:41 ERROR (stream_worker) [libav.rtsp] method DESCRIBE failed: 404 Not Found
2021-09-12 14:11:41 ERROR (stream_worker) [homeassistant.components.stream.worker] Error opening stream rtsps://stream-uc2-bravo.dropcam.com:443/sdm_live_stream/CiQA2vuxrx9EG79DDcei0gACOWGyinh-igsl0UbV_gDND2CAebsScQAFjsOTiY7o_biPCRfMQoZpfeCAtyMe61SS87cmtnGaims3FaLYvMtP6jIjm4h3HGWQ4_GmB_LShPBK6kHlLRBq9RlbSVjT97pPLTwbRARRWi14D45rys6WD1r8iLd2XCoQpSiMZ6TcleONEotB4KB2?auth=g.0.eyJraWQiOiIyMzhiNTUxZmMyM2EyM2Y4M2E2ZTE3MmJjZTg0YmU3ZjgxMzAzMmM4IiwiYWxnIjoiUlMyNTYifQ.eyJpc3MiOiJuZXN0LXNlY3VyaXR5LWF1dGhwcm94eSIsInN1YiI6Im5lc3RfaWQ6bmVzdC1waG9lbml4LXByb2Q6MjEyMTgxNDEiLCJwb2wiOiIzcC1vYXV0aC1zY29wZS1BUElfU0RNX1NFUlZJQ0UtY2xpZW50LTIwMjQyNzMxODczNS1qNXQ5bWMyMzZqaG85YXMycWY0dTZxY3NmYW1kaGJ0ci5hcHBzLmdvb2dsZXVzZXJjb250ZW50LmNvbSIsImV4cCI6MTYzMTQ4MTM1OX0.kKGQ_mhxmTh7Na6qaFpHNs0i87lBlqZnIPuNkPh6RyNfK5qvUdGSSAffZU302xXNU-j__-_IMBPuGhs0sa3Uc4pbztYjShL231sYY4tfpSIft1i_6HzLhrnsxk5UeF4dALYvOeJKjSfuqUzBSTd2Fmc05lXxtacP8vprH7tsA5xTp_hIlnMW0kCD4JC1-KM7iwMU07tLhQ2JH9iqAgc9kHYPvoKTVSWV8YI7UAsBttB4buiTUGVEZIgIrfzONlpGzkUNIku6tT7CR2t91JiExTtTl-uJ4Vwa1VjKMubwmhcrD5nj6PHtVPtWetq-ELoWriQ1rrr7GmPJfCGBrr-2Bg
2021-09-12 14:12:17 WARNING (MainThread) [haffmpeg.tools] Timeout reading image.
2021-09-12 14:12:23 WARNING (stream_worker) [homeassistant.components.stream.worker] Audio stream not found
2021-09-12 14:13:29 ERROR (stream_worker) [libav.tls] The specified session has been invalidated for some reason.
2021-09-12 14:13:29 ERROR (stream_worker) [homeassistant.components.stream.worker] Error demuxing stream: 
2021-09-12 14:13:29 ERROR (stream_worker) [libav.tls] The specified session has been invalidated for some reason.
2021-09-12 14:14:37 ERROR (MainThread) [homeassistant] Error doing job: Future exception was never retrieved
Traceback (most recent call last):
  File "/usr/local/lib/python3.9/concurrent/futures/thread.py", line 52, in run
    result = self.fn(*self.args, **self.kwargs)
TypeError: update() takes 1 positional argument but 2 were given
2021-09-12 14:15:37 WARNING (MainThread) [haffmpeg.tools] Timeout reading image.
2021-09-12 14:15:37 WARNING (MainThread) [haffmpeg.tools] Timeout reading image.
2021-09-12 14:16:07 WARNING (MainThread) [haffmpeg.tools] Timeout reading image.
2021-09-12 14:16:32 ERROR (stream_worker) [libav.rtsp] method DESCRIBE failed: 404 Not Found
2021-09-12 14:16:32 ERROR (stream_worker) [homeassistant.components.stream.worker] Error opening stream rtsps://stream-uc2-bravo.dropcam.com:443/sdm_live_stream/CiQA2vuxrx9EG79DDcei0gACOWGyinh-igsl0UbV_gDND2CAebsScQAFjsOTiY7o_biPCRfMQoZpfeCAtyMe61SS87cmtnGaims3FaLYvMtP6jIjm4h3HGWQ4_GmB_LShPBK6kHlLRBq9RlbSVjT97pPLTwbRARRWi14D45rys6WD1r8iLd2XCoQpSiMZ6TcleONEotB4KB2?auth=g.0.eyJraWQiOiIyMzhiNTUxZmMyM2EyM2Y4M2E2ZTE3MmJjZTg0YmU3ZjgxMzAzMmM4IiwiYWxnIjoiUlMyNTYifQ.eyJpc3MiOiJuZXN0LXNlY3VyaXR5LWF1dGhwcm94eSIsInN1YiI6Im5lc3RfaWQ6bmVzdC1waG9lbml4LXByb2Q6MjEyMTgxNDEiLCJwb2wiOiIzcC1vYXV0aC1zY29wZS1BUElfU0RNX1NFUlZJQ0UtY2xpZW50LTIwMjQyNzMxODczNS1qNXQ5bWMyMzZqaG85YXMycWY0dTZxY3NmYW1kaGJ0ci5hcHBzLmdvb2dsZXVzZXJjb250ZW50LmNvbSIsImV4cCI6MTYzMTQ4MTYyOX0.hClTbK5-jihM2ml6qannoYb8bZFWEJge9NELQtsO-XNtfNs_s3wFSg9IopB6-_9JJz32TCESzkpSr799zqOpUox46EF6JYHh2OjvoVkmR9PWagu9uzWZtcqqhMBsDBhNH-DDmWcg9f8X4JD04F6TEaZuctgd009XYNofDcsFUo9IlNwwebV6KmJOgb_i2BPwZr4dKdlrmS-NeeD1ZKy9r0eM4rM9zKBC9S-PVqwg7Z4UlGz1Y3PUlmPftog7cakPeMqCgwO_xawY6faBq4RdWVeTm6FnKCvMkutmUbDbPDkSe6kSnZ-4sLMC8tl0iacbCZpmrQAEty0oHiCwWRU2-w
2021-09-12 14:19:38 ERROR (MainThread) [homeassistant] Error doing job: Future exception was never retrieved
Traceback (most recent call last):
  File "/usr/local/lib/python3.9/concurrent/futures/thread.py", line 52, in run
    result = self.fn(*self.args, **self.kwargs)
TypeError: update() takes 1 positional argument but 2 were given
2021-09-12 14:21:11 ERROR (stream_worker) [libav.rtsp] method DESCRIBE failed: 404 Not Found
2021-09-12 14:21:11 ERROR (stream_worker) [homeassistant.components.stream.worker] Error opening stream rtsps://stream-uc2-bravo.dropcam.com:443/sdm_live_stream/CiQA2vuxrx9EG79DDcei0gACOWGyinh-igsl0UbV_gDND2CAebsScQAFjsOTiY7o_biPCRfMQoZpfeCAtyMe61SS87cmtnGaims3FaLYvMtP6jIjm4h3HGWQ4_GmB_LShPBK6kHlLRBq9RlbSVjT97pPLTwbRARRWi14D45rys6WD1r8iLd2XCoQpSiMZ6TcleONEotB4KB2?auth=g.0.eyJraWQiOiIyMzhiNTUxZmMyM2EyM2Y4M2E2ZTE3MmJjZTg0YmU3ZjgxMzAzMmM4IiwiYWxnIjoiUlMyNTYifQ.eyJpc3MiOiJuZXN0LXNlY3VyaXR5LWF1dGhwcm94eSIsInN1YiI6Im5lc3RfaWQ6bmVzdC1waG9lbml4LXByb2Q6MjEyMTgxNDEiLCJwb2wiOiIzcC1vYXV0aC1zY29wZS1BUElfU0RNX1NFUlZJQ0UtY2xpZW50LTIwMjQyNzMxODczNS1qNXQ5bWMyMzZqaG85YXMycWY0dTZxY3NmYW1kaGJ0ci5hcHBzLmdvb2dsZXVzZXJjb250ZW50LmNvbSIsImV4cCI6MTYzMTQ4MTkwMH0.hV_dOnUndxRgsYlr-wvuqAh3hS3WiEInReETVgJcl4CvKqZ6q7qAy7K4VrT-ZlOjBqvq-jhc-pEHnEtLg2FR0MhLc_E-rSC08kXCjuDu8OBGkArhBv72dyS8J1olhejVuH6vOEpAU2AOWxB3pnrXqHzmik2hVbTG2fO9AwNTPgPKTGi8BA8xPPOSd4fCN9-RHPE7K4zcP1wqJHuucK9SehNuG08fjan1_QZ_v5CqaXrWkVjC2i2sl_Ta5pyI9SQthU-mLLKcR0J3S29MaUBgaf8YpfqJOIaURGqtwu1M2yGKZaBiD9ZSS7-kHevGDNLvKV79jnXmGtQQZTwXPKD3Bg
2021-09-12 14:24:39 ERROR (MainThread) [homeassistant] Error doing job: Future exception was never retrieved
Traceback (most recent call last):
  File "/usr/local/lib/python3.9/concurrent/futures/thread.py", line 52, in run
    result = self.fn(*self.args, **self.kwargs)
TypeError: update() takes 1 positional argument but 2 were given
2021-09-12 14:28:38 WARNING (MainThread) [haffmpeg.tools] Timeout reading image.
2021-09-12 14:29:40 ERROR (MainThread) [homeassistant] Error doing job: Future exception was never retrieved
Traceback (most recent call last):
  File "/usr/local/lib/python3.9/concurrent/futures/thread.py", line 52, in run
    result = self.fn(*self.args, **self.kwargs)
TypeError: update() takes 1 positional argument but 2 were given
2021-09-12 14:34:41 ERROR (MainThread) [homeassistant] Error doing job: Future exception was never retrieved
Traceback (most recent call last):
  File "/usr/local/lib/python3.9/concurrent/futures/thread.py", line 52, in run
    result = self.fn(*self.args, **self.kwargs)
TypeError: update() takes 1 positional argument but 2 were given
2021-09-12 14:34:55 WARNING (MainThread) [haffmpeg.tools] Timeout reading image.
2021-09-12 14:35:56 WARNING (MainThread) [haffmpeg.tools] Timeout reading image.
2021-09-12 14:39:42 ERROR (MainThread) [homeassistant] Error doing job: Future exception was never retrieved
Traceback (most recent call last):
  File "/usr/local/lib/python3.9/concurrent/futures/thread.py", line 52, in run
    result = self.fn(*self.args, **self.kwargs)
TypeError: update() takes 1 positional argument but 2 were given
2021-09-12 14:42:10 ERROR (MainThread) [iotawattpy.connection] Err: 
2021-09-12 14:42:10 ERROR (MainThread) [homeassistant.components.iotawatt.coordinator] Unexpected error fetching 192.168.20.195 data: 'NoneType' object has no attribute 'text'
Traceback (most recent call last):
  File "/usr/src/homeassistant/homeassistant/helpers/update_coordinator.py", line 187, in _async_refresh
    self.data = await self._async_update_data()
  File "/usr/src/homeassistant/homeassistant/components/iotawatt/coordinator.py", line 55, in _async_update_data
    await self.api.update()
  File "/usr/local/lib/python3.9/site-packages/iotawattpy/iotawatt.py", line 66, in update
    await self._refreshSensors(timespan)
  File "/usr/local/lib/python3.9/site-packages/iotawattpy/iotawatt.py", line 100, in _refreshSensors
    results = response.text
AttributeError: 'NoneType' object has no attribute 'text'
2021-09-12 14:42:45 ERROR (MainThread) [iotawattpy.connection] Err: 
2021-09-12 14:42:45 ERROR (MainThread) [homeassistant.components.iotawatt.coordinator] Unexpected error fetching 192.168.20.195 data: 'NoneType' object has no attribute 'text'
Traceback (most recent call last):
  File "/usr/src/homeassistant/homeassistant/helpers/update_coordinator.py", line 187, in _async_refresh
    self.data = await self._async_update_data()
  File "/usr/src/homeassistant/homeassistant/components/iotawatt/coordinator.py", line 55, in _async_update_data
    await self.api.update()
  File "/usr/local/lib/python3.9/site-packages/iotawattpy/iotawatt.py", line 66, in update
    await self._refreshSensors(timespan)
  File "/usr/local/lib/python3.9/site-packages/iotawattpy/iotawatt.py", line 100, in _refreshSensors
    results = response.text
AttributeError: 'NoneType' object has no attribute 'text'
2021-09-12 14:43:20 ERROR (MainThread) [iotawattpy.connection] Err: 
2021-09-12 14:43:20 ERROR (MainThread) [homeassistant.components.iotawatt.coordinator] Unexpected error fetching 192.168.20.195 data: 'NoneType' object has no attribute 'text'
Traceback (most recent call last):
  File "/usr/src/homeassistant/homeassistant/helpers/update_coordinator.py", line 187, in _async_refresh
    self.data = await self._async_update_data()
  File "/usr/src/homeassistant/homeassistant/components/iotawatt/coordinator.py", line 55, in _async_update_data
    await self.api.update()
  File "/usr/local/lib/python3.9/site-packages/iotawattpy/iotawatt.py", line 66, in update
    await self._refreshSensors(timespan)
  File "/usr/local/lib/python3.9/site-packages/iotawattpy/iotawatt.py", line 100, in _refreshSensors
    results = response.text
AttributeError: 'NoneType' object has no attribute 'text'
2021-09-12 14:44:25 ERROR (MainThread) [iotawattpy.connection] Err: 
2021-09-12 14:44:25 ERROR (MainThread) [homeassistant.components.iotawatt.coordinator] Unexpected error fetching 192.168.20.195 data: 'NoneType' object has no attribute 'text'
Traceback (most recent call last):
  File "/usr/src/homeassistant/homeassistant/helpers/update_coordinator.py", line 187, in _async_refresh
    self.data = await self._async_update_data()
  File "/usr/src/homeassistant/homeassistant/components/iotawatt/coordinator.py", line 55, in _async_update_data
    await self.api.update()
  File "/usr/local/lib/python3.9/site-packages/iotawattpy/iotawatt.py", line 66, in update
    await self._refreshSensors(timespan)
  File "/usr/local/lib/python3.9/site-packages/iotawattpy/iotawatt.py", line 100, in _refreshSensors
    results = response.text
AttributeError: 'NoneType' object has no attribute 'text'
2021-09-12 14:44:43 ERROR (MainThread) [homeassistant] Error doing job: Future exception was never retrieved
Traceback (most recent call last):
  File "/usr/local/lib/python3.9/concurrent/futures/thread.py", line 52, in run
    result = self.fn(*self.args, **self.kwargs)
TypeError: update() takes 1 positional argument but 2 were given
2021-09-12 14:49:44 ERROR (MainThread) [homeassistant] Error doing job: Future exception was never retrieved
Traceback (most recent call last):
  File "/usr/local/lib/python3.9/concurrent/futures/thread.py", line 52, in run
    result = self.fn(*self.args, **self.kwargs)
TypeError: update() takes 1 positional argument but 2 were given
2021-09-12 14:53:21 ERROR (stream_worker) [libav.rtsp] method DESCRIBE failed: 404 Not Found
2021-09-12 14:53:21 ERROR (stream_worker) [homeassistant.components.stream.worker] Error opening stream rtsps://stream-uc2-delta.dropcam.com:443/sdm_live_stream/CiQA2vuxr2T1DqLTUax62v6siS6EajQNW96emz-R0JXW-B9XlPYScQAFjsOTYtoQ3z706HgMB1z8nPJ7hGr54blSbZPAzHzVxcoJzJxey-UaQx5wprpQ3XSQon9brSe5woP1xluRbuqk_MdGf1MGhpDJEvQli0kfpS7IGYeFIaULKDE2SVTESgqpShTXFBytxhdnoRD6VJVw?auth=g.0.eyJraWQiOiIyMzhiNTUxZmMyM2EyM2Y4M2E2ZTE3MmJjZTg0YmU3ZjgxMzAzMmM4IiwiYWxnIjoiUlMyNTYifQ.eyJpc3MiOiJuZXN0LXNlY3VyaXR5LWF1dGhwcm94eSIsInN1YiI6Im5lc3RfaWQ6bmVzdC1waG9lbml4LXByb2Q6MjEyMTgxNDEiLCJwb2wiOiIzcC1vYXV0aC1zY29wZS1BUElfU0RNX1NFUlZJQ0UtY2xpZW50LTIwMjQyNzMxODczNS1qNXQ5bWMyMzZqaG85YXMycWY0dTZxY3NmYW1kaGJ0ci5hcHBzLmdvb2dsZXVzZXJjb250ZW50LmNvbSIsImV4cCI6MTYzMTQ4Mzc5NH0.Jn5YvKetjCIo0ZxP-pdYhEPexrP2opNx9qK8twOATEeuitHbfd3LtuD2o3b5PYeN7AFsuzhU5D-y5tiA5Na-70WWtxEJtutqXYH8zv0sVIyDRa6l-Y-bO4byTCVa4FkMG1yL4x0rK_dNjULmwyWVXvhIh2qrsG3vuVVRWTDSOKNhwNMV__s7zpBLs5hlVRLeEJw6_HaDOag1Pd6MShI8HgXWDmoGQb0g0N8pK2Fi7kVsGFS3_UvqUUfp0yrlGQo5M1tvy-v4BEx74-dd8sRBXdOsOZ1rPO98iz2-OyFFfd_GUwPNXHQvirenW_cfcPi09fhEgJdjUwguxCHz00iX6Q
2021-09-12 14:54:45 ERROR (MainThread) [homeassistant] Error doing job: Future exception was never retrieved
Traceback (most recent call last):
  File "/usr/local/lib/python3.9/concurrent/futures/thread.py", line 52, in run
    result = self.fn(*self.args, **self.kwargs)
TypeError: update() takes 1 positional argument but 2 were given
2021-09-12 14:55:12 ERROR (stream_worker) [libav.rtsp] method DESCRIBE failed: 404 Not Found
2021-09-12 14:55:12 ERROR (stream_worker) [homeassistant.components.stream.worker] Error opening stream rtsps://stream-uc2-delta.dropcam.com:443/sdm_live_stream/CiQA2vuxr2T1DqLTUax62v6siS6EajQNW96emz-R0JXW-B9XlPYScQAFjsOTYtoQ3z706HgMB1z8nPJ7hGr54blSbZPAzHzVxcoJzJxey-UaQx5wprpQ3XSQon9brSe5woP1xluRbuqk_MdGf1MGhpDJEvQli0kfpS7IGYeFIaULKDE2SVTESgqpShTXFBytxhdnoRD6VJVw?auth=g.0.eyJraWQiOiIyMzhiNTUxZmMyM2EyM2Y4M2E2ZTE3MmJjZTg0YmU3ZjgxMzAzMmM4IiwiYWxnIjoiUlMyNTYifQ.eyJpc3MiOiJuZXN0LXNlY3VyaXR5LWF1dGhwcm94eSIsInN1YiI6Im5lc3RfaWQ6bmVzdC1waG9lbml4LXByb2Q6MjEyMTgxNDEiLCJwb2wiOiIzcC1vYXV0aC1zY29wZS1BUElfU0RNX1NFUlZJQ0UtY2xpZW50LTIwMjQyNzMxODczNS1qNXQ5bWMyMzZqaG85YXMycWY0dTZxY3NmYW1kaGJ0ci5hcHBzLmdvb2dsZXVzZXJjb250ZW50LmNvbSIsImV4cCI6MTYzMTQ4Mzc5NH0.Jn5YvKetjCIo0ZxP-pdYhEPexrP2opNx9qK8twOATEeuitHbfd3LtuD2o3b5PYeN7AFsuzhU5D-y5tiA5Na-70WWtxEJtutqXYH8zv0sVIyDRa6l-Y-bO4byTCVa4FkMG1yL4x0rK_dNjULmwyWVXvhIh2qrsG3vuVVRWTDSOKNhwNMV__s7zpBLs5hlVRLeEJw6_HaDOag1Pd6MShI8HgXWDmoGQb0g0N8pK2Fi7kVsGFS3_UvqUUfp0yrlGQo5M1tvy-v4BEx74-dd8sRBXdOsOZ1rPO98iz2-OyFFfd_GUwPNXHQvirenW_cfcPi09fhEgJdjUwguxCHz00iX6Q
2021-09-12 14:59:46 ERROR (MainThread) [homeassistant] Error doing job: Future exception was never retrieved
Traceback (most recent call last):
  File "/usr/local/lib/python3.9/concurrent/futures/thread.py", line 52, in run
    result = self.fn(*self.args, **self.kwargs)
TypeError: update() takes 1 positional argument but 2 were given
2021-09-12 15:04:47 ERROR (MainThread) [homeassistant] Error doing job: Future exception was never retrieved
Traceback (most recent call last):
  File "/usr/local/lib/python3.9/concurrent/futures/thread.py", line 52, in run
    result = self.fn(*self.args, **self.kwargs)
TypeError: update() takes 1 positional argument but 2 were given
2021-09-12 15:09:48 ERROR (MainThread) [homeassistant] Error doing job: Future exception was never retrieved
Traceback (most recent call last):
  File "/usr/local/lib/python3.9/concurrent/futures/thread.py", line 52, in run
    result = self.fn(*self.args, **self.kwargs)
TypeError: update() takes 1 positional argument but 2 were given
2021-09-12 15:14:49 ERROR (MainThread) [homeassistant] Error doing job: Future exception was never retrieved
Traceback (most recent call last):
  File "/usr/local/lib/python3.9/concurrent/futures/thread.py", line 52, in run
    result = self.fn(*self.args, **self.kwargs)
TypeError: update() takes 1 positional argument but 2 were given
2021-09-12 15:19:50 ERROR (MainThread) [homeassistant] Error doing job: Future exception was never retrieved
Traceback (most recent call last):
  File "/usr/local/lib/python3.9/concurrent/futures/thread.py", line 52, in run
    result = self.fn(*self.args, **self.kwargs)
TypeError: update() takes 1 positional argument but 2 were given
2021-09-12 15:19:54 ERROR (MainThread) [homeassistant.components.nws] Error requesting NWS observation station SAUC1 data: 503, message='Service Unavailable', url=URL('https://api.weather.gov/stations/SAUC1/observations')
2021-09-12 15:24:51 ERROR (MainThread) [homeassistant] Error doing job: Future exception was never retrieved
Traceback (most recent call last):
  File "/usr/local/lib/python3.9/concurrent/futures/thread.py", line 52, in run
    result = self.fn(*self.args, **self.kwargs)
TypeError: update() takes 1 positional argument but 2 were given
2021-09-12 15:29:52 ERROR (MainThread) [homeassistant] Error doing job: Future exception was never retrieved
Traceback (most recent call last):
  File "/usr/local/lib/python3.9/concurrent/futures/thread.py", line 52, in run
    result = self.fn(*self.args, **self.kwargs)
TypeError: update() takes 1 positional argument but 2 were given
2021-09-12 15:31:04 ERROR (MainThread) [homeassistant.components.nws] Error requesting NWS observation station SAUC1 data: 503, message='Service Unavailable', url=URL('https://api.weather.gov/stations/SAUC1/observations')
2021-09-12 15:34:53 ERROR (MainThread) [homeassistant] Error doing job: Future exception was never retrieved
Traceback (most recent call last):
  File "/usr/local/lib/python3.9/concurrent/futures/thread.py", line 52, in run
    result = self.fn(*self.args, **self.kwargs)
TypeError: update() takes 1 positional argument but 2 were given
2021-09-12 15:39:54 ERROR (MainThread) [homeassistant] Error doing job: Future exception was never retrieved
Traceback (most recent call last):
  File "/usr/local/lib/python3.9/concurrent/futures/thread.py", line 52, in run
    result = self.fn(*self.args, **self.kwargs)
TypeError: update() takes 1 positional argument but 2 were given
2021-09-12 15:44:55 ERROR (MainThread) [homeassistant] Error doing job: Future exception was never retrieved
Traceback (most recent call last):
  File "/usr/local/lib/python3.9/concurrent/futures/thread.py", line 52, in run
    result = self.fn(*self.args, **self.kwargs)
TypeError: update() takes 1 positional argument but 2 were given
2021-09-12 15:49:29 ERROR (MainThread) [homeassistant.components.forecast_solar] Error requesting forecast_solar data: 500, message='Internal Server Error', url=URL('https://91.228.53.233/estimate/34.3769732/-118.5435177/35/-20/7.458?time=iso8601&damping=0.0')
2021-09-12 15:49:56 ERROR (MainThread) [homeassistant] Error doing job: Future exception was never retrieved
Traceback (most recent call last):
  File "/usr/local/lib/python3.9/concurrent/futures/thread.py", line 52, in run
    result = self.fn(*self.args, **self.kwargs)
TypeError: update() takes 1 positional argument but 2 were given
2021-09-12 15:50:13 ERROR (stream_worker) [libav.tls] The specified session has been invalidated for some reason.
2021-09-12 15:50:13 ERROR (stream_worker) [homeassistant.components.stream.worker] Error demuxing stream: 
2021-09-12 15:54:57 ERROR (MainThread) [homeassistant] Error doing job: Future exception was never retrieved
Traceback (most recent call last):
  File "/usr/local/lib/python3.9/concurrent/futures/thread.py", line 52, in run
    result = self.fn(*self.args, **self.kwargs)
TypeError: update() takes 1 positional argument but 2 were given
2021-09-12 15:59:58 ERROR (MainThread) [homeassistant] Error doing job: Future exception was never retrieved
Traceback (most recent call last):
  File "/usr/local/lib/python3.9/concurrent/futures/thread.py", line 52, in run
    result = self.fn(*self.args, **self.kwargs)
TypeError: update() takes 1 positional argument but 2 were given
2021-09-12 16:04:58 ERROR (MainThread) [homeassistant.components.nws] Error requesting NWS observation station SAUC1 data: 503, message='Service Unavailable', url=URL('https://api.weather.gov/stations/SAUC1/observations')
2021-09-12 16:04:59 ERROR (MainThread) [homeassistant] Error doing job: Future exception was never retrieved
Traceback (most recent call last):
  File "/usr/local/lib/python3.9/concurrent/futures/thread.py", line 52, in run
    result = self.fn(*self.args, **self.kwargs)
TypeError: update() takes 1 positional argument but 2 were given
2021-09-12 16:10:00 ERROR (MainThread) [homeassistant] Error doing job: Future exception was never retrieved
Traceback (most recent call last):
  File "/usr/local/lib/python3.9/concurrent/futures/thread.py", line 52, in run
    result = self.fn(*self.args, **self.kwargs)
TypeError: update() takes 1 positional argument but 2 were given
2021-09-12 16:15:01 ERROR (MainThread) [homeassistant] Error doing job: Future exception was never retrieved
Traceback (most recent call last):
  File "/usr/local/lib/python3.9/concurrent/futures/thread.py", line 52, in run
    result = self.fn(*self.args, **self.kwargs)
TypeError: update() takes 1 positional argument but 2 were given
2021-09-12 16:20:02 ERROR (MainThread) [homeassistant] Error doing job: Future exception was never retrieved
Traceback (most recent call last):
  File "/usr/local/lib/python3.9/concurrent/futures/thread.py", line 52, in run
    result = self.fn(*self.args, **self.kwargs)
TypeError: update() takes 1 positional argument but 2 were given
2021-09-12 16:25:03 ERROR (MainThread) [homeassistant] Error doing job: Future exception was never retrieved
Traceback (most recent call last):
  File "/usr/local/lib/python3.9/concurrent/futures/thread.py", line 52, in run
    result = self.fn(*self.args, **self.kwargs)
TypeError: update() takes 1 positional argument but 2 were given
2021-09-12 16:30:04 ERROR (MainThread) [homeassistant] Error doing job: Future exception was never retrieved
Traceback (most recent call last):
  File "/usr/local/lib/python3.9/concurrent/futures/thread.py", line 52, in run
    result = self.fn(*self.args, **self.kwargs)
TypeError: update() takes 1 positional argument but 2 were given
