2021-09-09 13:53:01 WARNING (SyncWorker_0) [homeassistant.loader] We found a custom integration sun2 which has not been tested by Home Assistant. This component might cause stability problems, be sure to disable it if you experience issues with Home Assistant
2021-09-09 13:53:10 ERROR (MainThread) [snitun.client.client_peer] Challenge/Response error with SniTun server
2021-09-09 13:53:10 ERROR (MainThread) [hass_nabucasa.remote] Connection problem to snitun server
2021-09-09 13:53:11 WARNING (MainThread) [homeassistant.components.sensor] Entity sensor.cpu_temp (<class 'homeassistant.components.command_line.sensor.CommandSensor'>) with device_class None reports a temperature in °C which will be converted to °F. Temperature conversion for entities without correct device_class is deprecated and will be removed from Home Assistant Core 2022.3. Please update your configuration if device_class is manually configured, otherwise create a bug report at https://github.com/home-assistant/core/issues?q=is%3Aopen+is%3Aissue+label%3A%22integration%3A+command_line%22
2021-09-09 13:53:13 WARNING (MainThread) [homeassistant.config_entries] Config entry 'Roku Smart Soundbar' for roku integration not ready yet: Invalid response from API: Error occurred while communicating with device; Retrying in background
2021-09-09 13:53:14 WARNING (MainThread) [homeassistant.components.sensor] Entity sensor.garagesidedoorsensor_bme280_dewpoint (<class 'homeassistant.components.tasmota.sensor.TasmotaSensor'>) with device_class None reports a temperature in °C which will be converted to °F. Temperature conversion for entities without correct device_class is deprecated and will be removed from Home Assistant Core 2022.3. Please update your configuration if device_class is manually configured, otherwise create a bug report at https://github.com/home-assistant/core/issues?q=is%3Aopen+is%3Aissue+label%3A%22integration%3A+tasmota%22
2021-09-09 13:53:14 WARNING (MainThread) [homeassistant.components.sensor] Entity sensor.attictemp1_bme280_dewpoint (<class 'homeassistant.components.tasmota.sensor.TasmotaSensor'>) with device_class None reports a temperature in °C which will be converted to °F. Temperature conversion for entities without correct device_class is deprecated and will be removed from Home Assistant Core 2022.3. Please update your configuration if device_class is manually configured, otherwise create a bug report at https://github.com/home-assistant/core/issues?q=is%3Aopen+is%3Aissue+label%3A%22integration%3A+tasmota%22
2021-09-09 13:53:19 WARNING (MainThread) [homeassistant.config_entries] Config entry '192.168.7.195' for wled integration not ready yet: Invalid response from API: Error occurred while communicating with WLED device at 192.168.7.195; Retrying in background
2021-09-09 13:58:07 ERROR (MainThread) [homeassistant] Error doing job: Future exception was never retrieved
Traceback (most recent call last):
  File "/usr/local/lib/python3.9/concurrent/futures/thread.py", line 52, in run
    result = self.fn(*self.args, **self.kwargs)
TypeError: update() takes 1 positional argument but 2 were given
2021-09-09 13:58:24 ERROR (stream_worker) [libav.rtsp] method DESCRIBE failed: 404 Not Found
2021-09-09 13:58:24 ERROR (stream_worker) [homeassistant.components.stream.worker] Error opening stream rtsps://stream-uc2-bravo.dropcam.com:443/sdm_live_stream/CiQA2vuxr8jGGfnfk5q5GVRsM74SK2KmU3qwcpZn3kT03bEXZh4ScQAFjsOTNIY1JNym9ZUFznFxLMNrng7Lkyj8K5L1XiZfx0ODU0ATIDT7KdSkxXssW_aNhR1UBrulQc5uYbRWL5ftxNDNwMzFGNAuFly_oW2EoRlXdeO7So_g_hYlO3tAa_ScJ03wAGtujjoaZiAgI6ev?auth=g.0.eyJraWQiOiIyMzhiNTUxZmMyM2EyM2Y4M2E2ZTE3MmJjZTg0YmU3ZjgxMzAzMmM4IiwiYWxnIjoiUlMyNTYifQ.eyJpc3MiOiJuZXN0LXNlY3VyaXR5LWF1dGhwcm94eSIsInN1YiI6Im5lc3RfaWQ6bmVzdC1waG9lbml4LXByb2Q6MjEyMTgxNDEiLCJwb2wiOiIzcC1vYXV0aC1zY29wZS1BUElfU0RNX1NFUlZJQ0UtY2xpZW50LTIwMjQyNzMxODczNS1qNXQ5bWMyMzZqaG85YXMycWY0dTZxY3NmYW1kaGJ0ci5hcHBzLmdvb2dsZXVzZXJjb250ZW50LmNvbSIsImV4cCI6MTYzMTIyMTM5MX0.pe2uqDzkX7GveAoYupz9_D7pkzVTYmiTQ9RPOxQBX8E3oO6ohrJLPA4ucH6gA30uolShBTiA-YzZJvCcS4irvGt6VlbAlDr229RzD3Jr1i5ydWd2N2LcpuSUBkGyvI79LfyCXy_9QRkN6oZLMT906qNum3Z7GehYEGwi0uT8F5SzhxBK4Nhgz_HapXvIH2KC6N9jViYbdXyONe96CA19j43wA-NPRd9jPgDo_w1vv7WH4eumwQX0VmA3zLXU56__yHuyCfbzQMCbqLc5hai4zSshT_c7bcNppK4tE6xzi_z-2ZQTI1x3ZtsFhngFuzy4tmtx-Wi-dAcyfWIiqGotTg
2021-09-09 13:58:26 ERROR (stream_worker) [homeassistant.components.stream.worker] Error opening stream rtsps://stream-uc2-delta.dropcam.com:443/sdm_live_stream/CiQA2vuxr4wlat_oNQpHNeZ87fQ06np3JhBIi5GYSUmXwoUViGkScAAFjsOTJ8K6nsvCJBJBsNqOFFeRMM2XFPHrVukeF3cKSIc0dXSJSeBxQFmnhvyQisqH2ioNWN5allBv6mqGBsywMr29yZJvn1IVMMvUW7uYZxwN6Kqa7kC6wzr6GFdF0DfEqvqWwQckMzZhXKHEz3s?auth=g.0.eyJraWQiOiIyMzhiNTUxZmMyM2EyM2Y4M2E2ZTE3MmJjZTg0YmU3ZjgxMzAzMmM4IiwiYWxnIjoiUlMyNTYifQ.eyJpc3MiOiJuZXN0LXNlY3VyaXR5LWF1dGhwcm94eSIsInN1YiI6Im5lc3RfaWQ6bmVzdC1waG9lbml4LXByb2Q6MjEyMTgxNDEiLCJwb2wiOiIzcC1vYXV0aC1zY29wZS1BUElfU0RNX1NFUlZJQ0UtY2xpZW50LTIwMjQyNzMxODczNS1qNXQ5bWMyMzZqaG85YXMycWY0dTZxY3NmYW1kaGJ0ci5hcHBzLmdvb2dsZXVzZXJjb250ZW50LmNvbSIsImV4cCI6MTYzMTIyMTM5Mn0.ITvfvu1SVA8x38wNoNmiVatCVDikXcS4UhDRVtb8yrSiL4NHJz48VJY67lfBx8U8rr-pzHm35VY_4a80si-LxKtsexbFiJJvtnZ4CAzmM074r1-nX8HLIYr_82XAVf7Rb-QmjMSW81XBr0uqIWhIpjg6khazRRoG_VIGTxkWznAlB46kbjm1Z0QC87EvF3xK0WG9MMomiN3wsWem0lwVshzarbcjpTWWURC6zxGncD0wmvG1ON2Qijze5b2Xxl5R_vBquKNffDIsXeGpIRr9J1tB7CU-df-yE5lIzwiYH0RqmfF7k7io79VJz9ziQb-ULxTYdd80jM2gJAweehg6mg
2021-09-09 13:58:34 ERROR (stream_worker) [libav.rtsp] method DESCRIBE failed: 404 Not Found
2021-09-09 13:58:44 ERROR (stream_worker) [libav.rtsp] method DESCRIBE failed: 404 Not Found
2021-09-09 13:58:44 ERROR (stream_worker) [homeassistant.components.stream.worker] Error opening stream rtsps://stream-uc2-bravo.dropcam.com:443/sdm_live_stream/CiQA2vuxr8jGGfnfk5q5GVRsM74SK2KmU3qwcpZn3kT03bEXZh4ScQAFjsOTNIY1JNym9ZUFznFxLMNrng7Lkyj8K5L1XiZfx0ODU0ATIDT7KdSkxXssW_aNhR1UBrulQc5uYbRWL5ftxNDNwMzFGNAuFly_oW2EoRlXdeO7So_g_hYlO3tAa_ScJ03wAGtujjoaZiAgI6ev?auth=g.0.eyJraWQiOiIyMzhiNTUxZmMyM2EyM2Y4M2E2ZTE3MmJjZTg0YmU3ZjgxMzAzMmM4IiwiYWxnIjoiUlMyNTYifQ.eyJpc3MiOiJuZXN0LXNlY3VyaXR5LWF1dGhwcm94eSIsInN1YiI6Im5lc3RfaWQ6bmVzdC1waG9lbml4LXByb2Q6MjEyMTgxNDEiLCJwb2wiOiIzcC1vYXV0aC1zY29wZS1BUElfU0RNX1NFUlZJQ0UtY2xpZW50LTIwMjQyNzMxODczNS1qNXQ5bWMyMzZqaG85YXMycWY0dTZxY3NmYW1kaGJ0ci5hcHBzLmdvb2dsZXVzZXJjb250ZW50LmNvbSIsImV4cCI6MTYzMTIyMTM5MX0.pe2uqDzkX7GveAoYupz9_D7pkzVTYmiTQ9RPOxQBX8E3oO6ohrJLPA4ucH6gA30uolShBTiA-YzZJvCcS4irvGt6VlbAlDr229RzD3Jr1i5ydWd2N2LcpuSUBkGyvI79LfyCXy_9QRkN6oZLMT906qNum3Z7GehYEGwi0uT8F5SzhxBK4Nhgz_HapXvIH2KC6N9jViYbdXyONe96CA19j43wA-NPRd9jPgDo_w1vv7WH4eumwQX0VmA3zLXU56__yHuyCfbzQMCbqLc5hai4zSshT_c7bcNppK4tE6xzi_z-2ZQTI1x3ZtsFhngFuzy4tmtx-Wi-dAcyfWIiqGotTg
2021-09-09 13:58:48 ERROR (stream_worker) [homeassistant.components.stream.worker] Error opening stream rtsps://stream-uc2-delta.dropcam.com:443/sdm_live_stream/CiQA2vuxr4wlat_oNQpHNeZ87fQ06np3JhBIi5GYSUmXwoUViGkScAAFjsOTJ8K6nsvCJBJBsNqOFFeRMM2XFPHrVukeF3cKSIc0dXSJSeBxQFmnhvyQisqH2ioNWN5allBv6mqGBsywMr29yZJvn1IVMMvUW7uYZxwN6Kqa7kC6wzr6GFdF0DfEqvqWwQckMzZhXKHEz3s?auth=g.0.eyJraWQiOiIyMzhiNTUxZmMyM2EyM2Y4M2E2ZTE3MmJjZTg0YmU3ZjgxMzAzMmM4IiwiYWxnIjoiUlMyNTYifQ.eyJpc3MiOiJuZXN0LXNlY3VyaXR5LWF1dGhwcm94eSIsInN1YiI6Im5lc3RfaWQ6bmVzdC1waG9lbml4LXByb2Q6MjEyMTgxNDEiLCJwb2wiOiIzcC1vYXV0aC1zY29wZS1BUElfU0RNX1NFUlZJQ0UtY2xpZW50LTIwMjQyNzMxODczNS1qNXQ5bWMyMzZqaG85YXMycWY0dTZxY3NmYW1kaGJ0ci5hcHBzLmdvb2dsZXVzZXJjb250ZW50LmNvbSIsImV4cCI6MTYzMTIyMTM5Mn0.ITvfvu1SVA8x38wNoNmiVatCVDikXcS4UhDRVtb8yrSiL4NHJz48VJY67lfBx8U8rr-pzHm35VY_4a80si-LxKtsexbFiJJvtnZ4CAzmM074r1-nX8HLIYr_82XAVf7Rb-QmjMSW81XBr0uqIWhIpjg6khazRRoG_VIGTxkWznAlB46kbjm1Z0QC87EvF3xK0WG9MMomiN3wsWem0lwVshzarbcjpTWWURC6zxGncD0wmvG1ON2Qijze5b2Xxl5R_vBquKNffDIsXeGpIRr9J1tB7CU-df-yE5lIzwiYH0RqmfF7k7io79VJz9ziQb-ULxTYdd80jM2gJAweehg6mg
2021-09-09 13:59:04 ERROR (stream_worker) [libav.rtsp] method DESCRIBE failed: 404 Not Found
2021-09-09 14:03:08 ERROR (MainThread) [homeassistant] Error doing job: Future exception was never retrieved
Traceback (most recent call last):
  File "/usr/local/lib/python3.9/concurrent/futures/thread.py", line 52, in run
    result = self.fn(*self.args, **self.kwargs)
TypeError: update() takes 1 positional argument but 2 were given
2021-09-09 14:03:14 ERROR (stream_worker) [libav.rtsp] method DESCRIBE failed: 404 Not Found
2021-09-09 14:03:14 ERROR (stream_worker) [homeassistant.components.stream.worker] Error opening stream rtsps://stream-uc2-bravo.dropcam.com:443/sdm_live_stream/CiQA2vuxr8jGGfnfk5q5GVRsM74SK2KmU3qwcpZn3kT03bEXZh4ScQAFjsOTNIY1JNym9ZUFznFxLMNrng7Lkyj8K5L1XiZfx0ODU0ATIDT7KdSkxXssW_aNhR1UBrulQc5uYbRWL5ftxNDNwMzFGNAuFly_oW2EoRlXdeO7So_g_hYlO3tAa_ScJ03wAGtujjoaZiAgI6ev?auth=g.0.eyJraWQiOiIyMzhiNTUxZmMyM2EyM2Y4M2E2ZTE3MmJjZTg0YmU3ZjgxMzAzMmM4IiwiYWxnIjoiUlMyNTYifQ.eyJpc3MiOiJuZXN0LXNlY3VyaXR5LWF1dGhwcm94eSIsInN1YiI6Im5lc3RfaWQ6bmVzdC1waG9lbml4LXByb2Q6MjEyMTgxNDEiLCJwb2wiOiIzcC1vYXV0aC1zY29wZS1BUElfU0RNX1NFUlZJQ0UtY2xpZW50LTIwMjQyNzMxODczNS1qNXQ5bWMyMzZqaG85YXMycWY0dTZxY3NmYW1kaGJ0ci5hcHBzLmdvb2dsZXVzZXJjb250ZW50LmNvbSIsImV4cCI6MTYzMTIyMTY2MX0.sHJdWaiqF_bG9GEqw6ZWaFPJgSSEjtk9fMW69iw4vf2yny5m0vJ-6pcn4gUXOxhhrUz8LhvAPCm5eGyMEel-IBjZRZ_MGAFcKF0lDf4bQFkegMp0chQ1jilv6aJ3GckoYFiBCSbq04NNlgi2URD5lSWE7BTovpUh8HI-a7oBdJYKa5XCBE6ig6-N5V8O8Lhcibpu8a2LZnZM2bercCXz6Do8MCvg8lFAeql1-Jjwp16uAp-wbhH--AY23omDfGentD2ehLky7VMuQzZGVw2z0BAYy6nYg100-2Oi1yZJzhy_HRoEbOKZ4wKv7spyUW_gVCFg-HstNGnEOZ-rtpATlg
2021-09-09 14:03:23 ERROR (MainThread) [homeassistant.components.nws] Error requesting NWS observation station SAUC1 data: 503, message='Service Unavailable', url=URL('https://api.weather.gov/stations/SAUC1/observations')
2021-09-09 14:07:45 ERROR (stream_worker) [libav.rtsp] method DESCRIBE failed: 404 Not Found
2021-09-09 14:07:45 ERROR (stream_worker) [homeassistant.components.stream.worker] Error opening stream rtsps://stream-uc2-delta.dropcam.com:443/sdm_live_stream/CiQA2vuxr4wlat_oNQpHNeZ87fQ06np3JhBIi5GYSUmXwoUViGkScAAFjsOTJ8K6nsvCJBJBsNqOFFeRMM2XFPHrVukeF3cKSIc0dXSJSeBxQFmnhvyQisqH2ioNWN5allBv6mqGBsywMr29yZJvn1IVMMvUW7uYZxwN6Kqa7kC6wzr6GFdF0DfEqvqWwQckMzZhXKHEz3s?auth=g.0.eyJraWQiOiIyMzhiNTUxZmMyM2EyM2Y4M2E2ZTE3MmJjZTg0YmU3ZjgxMzAzMmM4IiwiYWxnIjoiUlMyNTYifQ.eyJpc3MiOiJuZXN0LXNlY3VyaXR5LWF1dGhwcm94eSIsInN1YiI6Im5lc3RfaWQ6bmVzdC1waG9lbml4LXByb2Q6MjEyMTgxNDEiLCJwb2wiOiIzcC1vYXV0aC1zY29wZS1BUElfU0RNX1NFUlZJQ0UtY2xpZW50LTIwMjQyNzMxODczNS1qNXQ5bWMyMzZqaG85YXMycWY0dTZxY3NmYW1kaGJ0ci5hcHBzLmdvb2dsZXVzZXJjb250ZW50LmNvbSIsImV4cCI6MTYzMTIyMTkzM30.m1Q_ja7bzRNdz6841OM6I2DiYrwGj68dj4_FJsf--sfrwaCzTdZ3o-8_OGtW96tW571kofiSI3TtaV0DvXHg423Yucu_EV15OzNENEl-OEt-QOUQB8UrSwi5EfieXct42GqQaD1Nw2GwOzRBjjvjuY_l0DGGs2Q3M0EDSyNV9CFYHVe8PLNbzL8_ADk6EWlhvTmvy4hV6CruIeGEyJc5kpUAIKybE3s5SpOLSv4hDLtN7ci78aJT0Fzx9FUsDV2aAkiHSrB_vQySByRQNAAmICILmIzjoP0v1MjZ2dS5zrTNMJMpgctkXmhWI487okBRdND6B0xeVf2SNQM1g-X4yQ
2021-09-09 14:08:09 ERROR (MainThread) [homeassistant] Error doing job: Future exception was never retrieved
Traceback (most recent call last):
  File "/usr/local/lib/python3.9/concurrent/futures/thread.py", line 52, in run
    result = self.fn(*self.args, **self.kwargs)
TypeError: update() takes 1 positional argument but 2 were given
2021-09-09 14:08:13 ERROR (stream_worker) [homeassistant.components.stream.worker] Error opening stream rtsps://stream-uc2-bravo.dropcam.com:443/sdm_live_stream/CiQA2vuxr8jGGfnfk5q5GVRsM74SK2KmU3qwcpZn3kT03bEXZh4ScQAFjsOTNIY1JNym9ZUFznFxLMNrng7Lkyj8K5L1XiZfx0ODU0ATIDT7KdSkxXssW_aNhR1UBrulQc5uYbRWL5ftxNDNwMzFGNAuFly_oW2EoRlXdeO7So_g_hYlO3tAa_ScJ03wAGtujjoaZiAgI6ev?auth=g.0.eyJraWQiOiIyMzhiNTUxZmMyM2EyM2Y4M2E2ZTE3MmJjZTg0YmU3ZjgxMzAzMmM4IiwiYWxnIjoiUlMyNTYifQ.eyJpc3MiOiJuZXN0LXNlY3VyaXR5LWF1dGhwcm94eSIsInN1YiI6Im5lc3RfaWQ6bmVzdC1waG9lbml4LXByb2Q6MjEyMTgxNDEiLCJwb2wiOiIzcC1vYXV0aC1zY29wZS1BUElfU0RNX1NFUlZJQ0UtY2xpZW50LTIwMjQyNzMxODczNS1qNXQ5bWMyMzZqaG85YXMycWY0dTZxY3NmYW1kaGJ0ci5hcHBzLmdvb2dsZXVzZXJjb250ZW50LmNvbSIsImV4cCI6MTYzMTIyMTkzMn0.ac_p7OOYsu8HYP-ixJZ1ID6EUUce4frCXR6YwEWc7uxL58Xn7jpaTkqyedky0WVsSehaWjJJacPOM3rYTOUSUV1istHKAf0z3yy9fK3uoYPZGT3-slUOXk7KwJ6qeAPsY4o_Ab-XCeA2eGZgr5iXs4_Tq-xsJvnQK-26ZYwOVbtd7fm5lU0uV0vt-PtrxfTo_b6wOCfXKxXjSamSB4ZwL_XkaXYRMWDma7tc5m9YmmO9giF_9aLxggPOsQJgUU4RrKH3duklFNo8iwDbo6Jiu9g-qXakUaU_1dckPnEGGT8E2lPXcbZM7-PhtwySNmfhe-iQZ-m0dhaV92-iYLDd3w
2021-09-09 14:12:02 WARNING (Recorder) [homeassistant.components.sensor.recorder] sensor.iotawatt_exporttogrid_kwh has unknown unit None
2021-09-09 14:13:10 ERROR (MainThread) [homeassistant] Error doing job: Future exception was never retrieved
Traceback (most recent call last):
  File "/usr/local/lib/python3.9/concurrent/futures/thread.py", line 52, in run
    result = self.fn(*self.args, **self.kwargs)
TypeError: update() takes 1 positional argument but 2 were given
2021-09-09 14:18:11 ERROR (MainThread) [homeassistant] Error doing job: Future exception was never retrieved
Traceback (most recent call last):
  File "/usr/local/lib/python3.9/concurrent/futures/thread.py", line 52, in run
    result = self.fn(*self.args, **self.kwargs)
TypeError: update() takes 1 positional argument but 2 were given
2021-09-09 14:23:12 ERROR (MainThread) [homeassistant] Error doing job: Future exception was never retrieved
Traceback (most recent call last):
  File "/usr/local/lib/python3.9/concurrent/futures/thread.py", line 52, in run
    result = self.fn(*self.args, **self.kwargs)
TypeError: update() takes 1 positional argument but 2 were given
2021-09-09 14:28:13 ERROR (MainThread) [homeassistant] Error doing job: Future exception was never retrieved
Traceback (most recent call last):
  File "/usr/local/lib/python3.9/concurrent/futures/thread.py", line 52, in run
    result = self.fn(*self.args, **self.kwargs)
TypeError: update() takes 1 positional argument but 2 were given
2021-09-09 14:33:14 ERROR (MainThread) [homeassistant.components.nws] Error requesting NWS forecast station SAUC1 data: 500, message='Internal Server Error', url=URL('https://api.weather.gov/gridpoints/LOX/146,60/forecast')
2021-09-09 14:33:14 ERROR (MainThread) [homeassistant] Error doing job: Future exception was never retrieved
Traceback (most recent call last):
  File "/usr/local/lib/python3.9/concurrent/futures/thread.py", line 52, in run
    result = self.fn(*self.args, **self.kwargs)
TypeError: update() takes 1 positional argument but 2 were given
2021-09-09 14:38:15 ERROR (MainThread) [homeassistant] Error doing job: Future exception was never retrieved
Traceback (most recent call last):
  File "/usr/local/lib/python3.9/concurrent/futures/thread.py", line 52, in run
    result = self.fn(*self.args, **self.kwargs)
TypeError: update() takes 1 positional argument but 2 were given
2021-09-09 14:43:16 ERROR (MainThread) [homeassistant] Error doing job: Future exception was never retrieved
Traceback (most recent call last):
  File "/usr/local/lib/python3.9/concurrent/futures/thread.py", line 52, in run
    result = self.fn(*self.args, **self.kwargs)
TypeError: update() takes 1 positional argument but 2 were given
2021-09-09 14:46:03 ERROR (MainThread) [iotawattpy.connection] Err: 
2021-09-09 14:46:03 ERROR (MainThread) [homeassistant.components.iotawatt.coordinator] Unexpected error fetching 192.168.20.195 data: 'NoneType' object has no attribute 'text'
Traceback (most recent call last):
  File "/usr/src/homeassistant/homeassistant/helpers/update_coordinator.py", line 187, in _async_refresh
    self.data = await self._async_update_data()
  File "/usr/src/homeassistant/homeassistant/components/iotawatt/coordinator.py", line 55, in _async_update_data
    await self.api.update()
  File "/usr/local/lib/python3.9/site-packages/iotawattpy/iotawatt.py", line 66, in update
    await self._refreshSensors(timespan)
  File "/usr/local/lib/python3.9/site-packages/iotawattpy/iotawatt.py", line 100, in _refreshSensors
    results = response.text
AttributeError: 'NoneType' object has no attribute 'text'
2021-09-09 14:46:38 ERROR (MainThread) [iotawattpy.connection] Err: 
2021-09-09 14:46:38 ERROR (MainThread) [homeassistant.components.iotawatt.coordinator] Unexpected error fetching 192.168.20.195 data: 'NoneType' object has no attribute 'text'
Traceback (most recent call last):
  File "/usr/src/homeassistant/homeassistant/helpers/update_coordinator.py", line 187, in _async_refresh
    self.data = await self._async_update_data()
  File "/usr/src/homeassistant/homeassistant/components/iotawatt/coordinator.py", line 55, in _async_update_data
    await self.api.update()
  File "/usr/local/lib/python3.9/site-packages/iotawattpy/iotawatt.py", line 66, in update
    await self._refreshSensors(timespan)
  File "/usr/local/lib/python3.9/site-packages/iotawattpy/iotawatt.py", line 100, in _refreshSensors
    results = response.text
AttributeError: 'NoneType' object has no attribute 'text'
2021-09-09 14:47:13 ERROR (MainThread) [iotawattpy.connection] Err: 
2021-09-09 14:47:13 ERROR (MainThread) [homeassistant.components.iotawatt.coordinator] Unexpected error fetching 192.168.20.195 data: 'NoneType' object has no attribute 'text'
Traceback (most recent call last):
  File "/usr/src/homeassistant/homeassistant/helpers/update_coordinator.py", line 187, in _async_refresh
    self.data = await self._async_update_data()
  File "/usr/src/homeassistant/homeassistant/components/iotawatt/coordinator.py", line 55, in _async_update_data
    await self.api.update()
  File "/usr/local/lib/python3.9/site-packages/iotawattpy/iotawatt.py", line 66, in update
    await self._refreshSensors(timespan)
  File "/usr/local/lib/python3.9/site-packages/iotawattpy/iotawatt.py", line 100, in _refreshSensors
    results = response.text
AttributeError: 'NoneType' object has no attribute 'text'
2021-09-09 14:48:17 ERROR (MainThread) [homeassistant] Error doing job: Future exception was never retrieved
Traceback (most recent call last):
  File "/usr/local/lib/python3.9/concurrent/futures/thread.py", line 52, in run
    result = self.fn(*self.args, **self.kwargs)
TypeError: update() takes 1 positional argument but 2 were given
2021-09-09 14:48:49 ERROR (stream_worker) [homeassistant.components.stream.worker] Error opening stream rtsps://stream-uc2-delta.dropcam.com:443/sdm_live_stream/CiQA2vuxr4wlat_oNQpHNeZ87fQ06np3JhBIi5GYSUmXwoUViGkScAAFjsOTJ8K6nsvCJBJBsNqOFFeRMM2XFPHrVukeF3cKSIc0dXSJSeBxQFmnhvyQisqH2ioNWN5allBv6mqGBsywMr29yZJvn1IVMMvUW7uYZxwN6Kqa7kC6wzr6GFdF0DfEqvqWwQckMzZhXKHEz3s?auth=g.0.eyJraWQiOiIyMzhiNTUxZmMyM2EyM2Y4M2E2ZTE3MmJjZTg0YmU3ZjgxMzAzMmM4IiwiYWxnIjoiUlMyNTYifQ.eyJpc3MiOiJuZXN0LXNlY3VyaXR5LWF1dGhwcm94eSIsInN1YiI6Im5lc3RfaWQ6bmVzdC1waG9lbml4LXByb2Q6MjEyMTgxNDEiLCJwb2wiOiIzcC1vYXV0aC1zY29wZS1BUElfU0RNX1NFUlZJQ0UtY2xpZW50LTIwMjQyNzMxODczNS1qNXQ5bWMyMzZqaG85YXMycWY0dTZxY3NmYW1kaGJ0ci5hcHBzLmdvb2dsZXVzZXJjb250ZW50LmNvbSIsImV4cCI6MTYzMTIyNDM2OX0.hksIn4PohmxU3-0734ExEy0d9LqIq9yEIUO2OCg60ZPUII4M7jfHt86YjysfMi2NBjITwjREgxO_xyFMJ8FMes1DkebuhVCIsxQrZVmSS8cHgv7KTNOfY0q7qjFkjW7LmVqZIXb6Zp2-vDrnO_ezV_w52IrssWkXtg6xJ4iysN4wBthAee5LEY0yl3lSl8kGzFa1dPwuXaLwPJbi7Ukz13Ti2yBzkrKfKVKxvEFcVHHO4wZCXUm23R8m2m4nAoJdDdYt97tafh9T0ZnTfT9oDCGVx3LF4-7l2DMZpZUMfSz5oI3kfcy7ab773oE9Xehs-_KFuP-OGyZP9Zz_6vGsyA
2021-09-09 14:53:18 ERROR (MainThread) [homeassistant] Error doing job: Future exception was never retrieved
Traceback (most recent call last):
  File "/usr/local/lib/python3.9/concurrent/futures/thread.py", line 52, in run
    result = self.fn(*self.args, **self.kwargs)
TypeError: update() takes 1 positional argument but 2 were given
2021-09-09 14:58:19 ERROR (MainThread) [homeassistant] Error doing job: Future exception was never retrieved
Traceback (most recent call last):
  File "/usr/local/lib/python3.9/concurrent/futures/thread.py", line 52, in run
    result = self.fn(*self.args, **self.kwargs)
TypeError: update() takes 1 positional argument but 2 were given
2021-09-09 15:03:20 ERROR (MainThread) [homeassistant] Error doing job: Future exception was never retrieved
Traceback (most recent call last):
  File "/usr/local/lib/python3.9/concurrent/futures/thread.py", line 52, in run
    result = self.fn(*self.args, **self.kwargs)
TypeError: update() takes 1 positional argument but 2 were given
2021-09-09 15:05:09 ERROR (MainThread) [homeassistant.components.nws] Error requesting NWS observation station SAUC1 data: 503, message='Service Unavailable', url=URL('https://api.weather.gov/stations/SAUC1/observations')
2021-09-09 15:08:21 ERROR (MainThread) [homeassistant] Error doing job: Future exception was never retrieved
Traceback (most recent call last):
  File "/usr/local/lib/python3.9/concurrent/futures/thread.py", line 52, in run
    result = self.fn(*self.args, **self.kwargs)
TypeError: update() takes 1 positional argument but 2 were given
2021-09-09 15:13:22 ERROR (MainThread) [homeassistant] Error doing job: Future exception was never retrieved
Traceback (most recent call last):
  File "/usr/local/lib/python3.9/concurrent/futures/thread.py", line 52, in run
    result = self.fn(*self.args, **self.kwargs)
TypeError: update() takes 1 positional argument but 2 were given
2021-09-09 15:18:23 ERROR (MainThread) [homeassistant] Error doing job: Future exception was never retrieved
Traceback (most recent call last):
  File "/usr/local/lib/python3.9/concurrent/futures/thread.py", line 52, in run
    result = self.fn(*self.args, **self.kwargs)
TypeError: update() takes 1 positional argument but 2 were given
2021-09-09 15:18:37 ERROR (MainThread) [homeassistant.components.template.cover] Received invalid cover is_on state: unavailable. Expected: open, opening, closed, closing, true, false
2021-09-09 15:18:38 WARNING (MainThread) [homeassistant.components.sensor] Entity sensor.cpu_temp (<class 'homeassistant.components.command_line.sensor.CommandSensor'>) with device_class None reports a temperature in °C which will be converted to °F. Temperature conversion for entities without correct device_class is deprecated and will be removed from Home Assistant Core 2022.3. Please update your configuration if device_class is manually configured, otherwise create a bug report at https://github.com/home-assistant/core/issues?q=is%3Aopen+is%3Aissue+label%3A%22integration%3A+command_line%22
2021-09-09 15:18:39 WARNING (MainThread) [homeassistant.components.template.template_entity] Template loop detected while processing event: <Event state_changed[L]: entity_id=sensor.sensor_count, old_state=<state sensor.sensor_count=435; friendly_name=Number of Sensors @ 2021-09-09T15:18:37.759712-07:00>, new_state=<state sensor.sensor_count=458; friendly_name=Number of Sensors @ 2021-09-09T15:18:38.855151-07:00>>, skipping template render for Template[{{ states.sensor | rejectattr('state', 'eq', 'unavailable') | list | count }}]
2021-09-09 15:18:53 ERROR (MainThread) [homeassistant.components.nws] Error requesting NWS observation station SAUC1 data: 503, message='Service Unavailable', url=URL('https://api.weather.gov/stations/SAUC1/observations')
