2021-09-11 03:17:36 WARNING (SyncWorker_0) [homeassistant.loader] We found a custom integration sun2 which has not been tested by Home Assistant. This component might cause stability problems, be sure to disable it if you experience issues with Home Assistant
2021-09-11 03:17:44 WARNING (Recorder) [homeassistant.components.recorder.util] The system could not validate that the sqlite3 database at //config/home-assistant_v2.db was shutdown cleanly
2021-09-11 03:17:52 WARNING (MainThread) [homeassistant.components.sensor] Entity sensor.iotawatt_total_sce_kwh_cost (<class 'homeassistant.components.energy.sensor.EnergyCostSensor'>) with state_class measurement has set last_reset. Setting last_reset is deprecated and will be unsupported from Home Assistant Core 2021.11. Please update your configuration if state_class is manually configured, otherwise create a bug report at https://github.com/home-assistant/core/issues?q=is%3Aopen+is%3Aissue+label%3A%22integration%3A+energy%22
2021-09-11 03:17:52 WARNING (MainThread) [homeassistant.components.sensor] Entity sensor.iotawatt_gridexport_compensation (<class 'homeassistant.components.energy.sensor.EnergyCostSensor'>) with state_class measurement has set last_reset. Setting last_reset is deprecated and will be unsupported from Home Assistant Core 2021.11. Please update your configuration if state_class is manually configured, otherwise create a bug report at https://github.com/home-assistant/core/issues?q=is%3Aopen+is%3Aissue+label%3A%22integration%3A+energy%22
2021-09-11 03:17:52 WARNING (MainThread) [homeassistant.components.sensor] Entity sensor.cpu_temp (<class 'homeassistant.components.command_line.sensor.CommandSensor'>) with device_class None reports a temperature in °C which will be converted to °F. Temperature conversion for entities without correct device_class is deprecated and will be removed from Home Assistant Core 2022.3. Please update your configuration if device_class is manually configured, otherwise create a bug report at https://github.com/home-assistant/core/issues?q=is%3Aopen+is%3Aissue+label%3A%22integration%3A+command_line%22
2021-09-11 03:17:54 WARNING (MainThread) [homeassistant.config_entries] Config entry 'Roku Smart Soundbar' for roku integration not ready yet: Invalid response from API: Error occurred while communicating with device; Retrying in background
2021-09-11 03:18:00 WARNING (MainThread) [homeassistant.config_entries] Config entry '192.168.7.195' for wled integration not ready yet: Invalid response from API: Error occurred while communicating with WLED device at 192.168.7.195; Retrying in background
2021-09-11 03:18:44 WARNING (MainThread) [homeassistant.components.sensor] Entity sensor.garagesidedoorsensor_bme280_dewpoint (<class 'homeassistant.components.tasmota.sensor.TasmotaSensor'>) with device_class None reports a temperature in °C which will be converted to °F. Temperature conversion for entities without correct device_class is deprecated and will be removed from Home Assistant Core 2022.3. Please update your configuration if device_class is manually configured, otherwise create a bug report at https://github.com/home-assistant/core/issues?q=is%3Aopen+is%3Aissue+label%3A%22integration%3A+tasmota%22
2021-09-11 03:18:44 WARNING (MainThread) [homeassistant.components.template.template_entity] Template loop detected while processing event: <Event state_changed[L]: entity_id=sensor.sensor_count, old_state=<state sensor.sensor_count=339; friendly_name=Number of Sensors @ 2021-09-11T03:18:42.367610-07:00>, new_state=<state sensor.sensor_count=358; friendly_name=Number of Sensors @ 2021-09-11T03:18:43.367882-07:00>>, skipping template render for Template[{{ states.sensor | rejectattr('state', 'eq', 'unavailable') | list | count }}]
2021-09-11 03:20:46 WARNING (MainThread) [homeassistant.components.sensor] Entity sensor.attictemp1_bme280_dewpoint (<class 'homeassistant.components.tasmota.sensor.TasmotaSensor'>) with device_class None reports a temperature in °C which will be converted to °F. Temperature conversion for entities without correct device_class is deprecated and will be removed from Home Assistant Core 2022.3. Please update your configuration if device_class is manually configured, otherwise create a bug report at https://github.com/home-assistant/core/issues?q=is%3Aopen+is%3Aissue+label%3A%22integration%3A+tasmota%22
2021-09-11 03:22:49 ERROR (MainThread) [homeassistant] Error doing job: Future exception was never retrieved
Traceback (most recent call last):
  File "/usr/local/lib/python3.9/concurrent/futures/thread.py", line 52, in run
    result = self.fn(*self.args, **self.kwargs)
TypeError: update() takes 1 positional argument but 2 were given
2021-09-11 03:22:49 WARNING (MainThread) [homeassistant.components.template.template_entity] Template loop detected while processing event: <Event state_changed[L]: entity_id=sensor.sensor_count, old_state=<state sensor.sensor_count=414; friendly_name=Number of Sensors @ 2021-09-11T03:22:47.994028-07:00>, new_state=<state sensor.sensor_count=426; friendly_name=Number of Sensors @ 2021-09-11T03:22:48.994111-07:00>>, skipping template render for Template[{{ states.sensor | rejectattr('state', 'eq', 'unavailable') | list | count }}]
2021-09-11 03:24:54 WARNING (MainThread) [homeassistant.components.template.template_entity] Template loop detected while processing event: <Event state_changed[L]: entity_id=sensor.sensor_count, old_state=<state sensor.sensor_count=461; friendly_name=Number of Sensors @ 2021-09-11T03:24:52.102524-07:00>, new_state=<state sensor.sensor_count=467; friendly_name=Number of Sensors @ 2021-09-11T03:24:53.103614-07:00>>, skipping template render for Template[{{ states.sensor | rejectattr('state', 'eq', 'unavailable') | list | count }}]
2021-09-11 03:26:54 WARNING (MainThread) [homeassistant.helpers.service] Unable to find referenced entities light.hue_lightstrip_2
2021-09-11 03:27:50 ERROR (MainThread) [homeassistant] Error doing job: Future exception was never retrieved
Traceback (most recent call last):
  File "/usr/local/lib/python3.9/concurrent/futures/thread.py", line 52, in run
    result = self.fn(*self.args, **self.kwargs)
TypeError: update() takes 1 positional argument but 2 were given
2021-09-11 03:32:51 ERROR (MainThread) [homeassistant] Error doing job: Future exception was never retrieved
Traceback (most recent call last):
  File "/usr/local/lib/python3.9/concurrent/futures/thread.py", line 52, in run
    result = self.fn(*self.args, **self.kwargs)
TypeError: update() takes 1 positional argument but 2 were given
2021-09-11 03:37:52 ERROR (MainThread) [homeassistant] Error doing job: Future exception was never retrieved
Traceback (most recent call last):
  File "/usr/local/lib/python3.9/concurrent/futures/thread.py", line 52, in run
    result = self.fn(*self.args, **self.kwargs)
TypeError: update() takes 1 positional argument but 2 were given
2021-09-11 03:42:53 ERROR (MainThread) [homeassistant] Error doing job: Future exception was never retrieved
Traceback (most recent call last):
  File "/usr/local/lib/python3.9/concurrent/futures/thread.py", line 52, in run
    result = self.fn(*self.args, **self.kwargs)
TypeError: update() takes 1 positional argument but 2 were given
2021-09-11 03:47:54 ERROR (MainThread) [homeassistant] Error doing job: Future exception was never retrieved
Traceback (most recent call last):
  File "/usr/local/lib/python3.9/concurrent/futures/thread.py", line 52, in run
    result = self.fn(*self.args, **self.kwargs)
TypeError: update() takes 1 positional argument but 2 were given
2021-09-11 03:52:55 ERROR (MainThread) [homeassistant] Error doing job: Future exception was never retrieved
Traceback (most recent call last):
  File "/usr/local/lib/python3.9/concurrent/futures/thread.py", line 52, in run
    result = self.fn(*self.args, **self.kwargs)
TypeError: update() takes 1 positional argument but 2 were given
2021-09-11 03:57:56 ERROR (MainThread) [homeassistant] Error doing job: Future exception was never retrieved
Traceback (most recent call last):
  File "/usr/local/lib/python3.9/concurrent/futures/thread.py", line 52, in run
    result = self.fn(*self.args, **self.kwargs)
TypeError: update() takes 1 positional argument but 2 were given
2021-09-11 04:02:57 ERROR (MainThread) [homeassistant] Error doing job: Future exception was never retrieved
Traceback (most recent call last):
  File "/usr/local/lib/python3.9/concurrent/futures/thread.py", line 52, in run
    result = self.fn(*self.args, **self.kwargs)
TypeError: update() takes 1 positional argument but 2 were given
2021-09-11 04:07:58 ERROR (MainThread) [homeassistant] Error doing job: Future exception was never retrieved
Traceback (most recent call last):
  File "/usr/local/lib/python3.9/concurrent/futures/thread.py", line 52, in run
    result = self.fn(*self.args, **self.kwargs)
TypeError: update() takes 1 positional argument but 2 were given
2021-09-11 04:08:43 ERROR (MainThread) [homeassistant.components.nws] Error requesting NWS observation station SAUC1 data: 503, message='Service Unavailable', url=URL('https://api.weather.gov/stations/SAUC1/observations')
2021-09-11 04:12:59 ERROR (MainThread) [homeassistant] Error doing job: Future exception was never retrieved
Traceback (most recent call last):
  File "/usr/local/lib/python3.9/concurrent/futures/thread.py", line 52, in run
    result = self.fn(*self.args, **self.kwargs)
TypeError: update() takes 1 positional argument but 2 were given
2021-09-11 04:18:00 ERROR (MainThread) [homeassistant] Error doing job: Future exception was never retrieved
Traceback (most recent call last):
  File "/usr/local/lib/python3.9/concurrent/futures/thread.py", line 52, in run
    result = self.fn(*self.args, **self.kwargs)
TypeError: update() takes 1 positional argument but 2 were given
2021-09-11 04:23:01 ERROR (MainThread) [homeassistant] Error doing job: Future exception was never retrieved
Traceback (most recent call last):
  File "/usr/local/lib/python3.9/concurrent/futures/thread.py", line 52, in run
    result = self.fn(*self.args, **self.kwargs)
TypeError: update() takes 1 positional argument but 2 were given
2021-09-11 04:28:02 ERROR (MainThread) [homeassistant] Error doing job: Future exception was never retrieved
Traceback (most recent call last):
  File "/usr/local/lib/python3.9/concurrent/futures/thread.py", line 52, in run
    result = self.fn(*self.args, **self.kwargs)
TypeError: update() takes 1 positional argument but 2 were given
2021-09-11 04:33:03 ERROR (MainThread) [homeassistant] Error doing job: Future exception was never retrieved
Traceback (most recent call last):
  File "/usr/local/lib/python3.9/concurrent/futures/thread.py", line 52, in run
    result = self.fn(*self.args, **self.kwargs)
TypeError: update() takes 1 positional argument but 2 were given
2021-09-11 04:38:04 ERROR (MainThread) [homeassistant] Error doing job: Future exception was never retrieved
Traceback (most recent call last):
  File "/usr/local/lib/python3.9/concurrent/futures/thread.py", line 52, in run
    result = self.fn(*self.args, **self.kwargs)
TypeError: update() takes 1 positional argument but 2 were given
2021-09-11 04:40:10 WARNING (Thread-15) [pychromecast.socket_client] [Bedroom_Sophia speaker(192.168.20.60):8009] Heartbeat timeout, resetting connection
2021-09-11 04:40:18 ERROR (Thread-15) [pychromecast.socket_client] [Bedroom_Sophia speaker(192.168.20.60):8009] Failed to connect to service ServiceInfo(type='host', data=('192.168.20.60', 8009)), retrying in 5.0s
2021-09-11 04:43:05 ERROR (MainThread) [homeassistant] Error doing job: Future exception was never retrieved
Traceback (most recent call last):
  File "/usr/local/lib/python3.9/concurrent/futures/thread.py", line 52, in run
    result = self.fn(*self.args, **self.kwargs)
TypeError: update() takes 1 positional argument but 2 were given
2021-09-11 04:48:06 ERROR (MainThread) [homeassistant] Error doing job: Future exception was never retrieved
Traceback (most recent call last):
  File "/usr/local/lib/python3.9/concurrent/futures/thread.py", line 52, in run
    result = self.fn(*self.args, **self.kwargs)
TypeError: update() takes 1 positional argument but 2 were given
2021-09-11 04:53:07 ERROR (MainThread) [homeassistant] Error doing job: Future exception was never retrieved
Traceback (most recent call last):
  File "/usr/local/lib/python3.9/concurrent/futures/thread.py", line 52, in run
    result = self.fn(*self.args, **self.kwargs)
TypeError: update() takes 1 positional argument but 2 were given
2021-09-11 04:57:53 ERROR (stream_worker) [libav.rtsp] method DESCRIBE failed: 404 Not Found
2021-09-11 04:57:53 ERROR (stream_worker) [homeassistant.components.stream.worker] Error opening stream rtsps://stream-uc2-bravo.dropcam.com:443/sdm_live_stream/CiQA2vuxr27_sLMvoT3EEnvrU1pnbO1VaGHfkZ-X46xM_qZuuR0ScQAFjsOTT9-1IyTNchrOtDlFoQma0mll5EFJzjpM75_OlO7v5_W9P9Q8tHgk3YW7T8y0rPqrUvFPBV1YJmUUYtFShzz5DQbd7BJ0xQnC04XNfTsSkwJdkxmXYSprYOhYmoPEJh6Wz5jWZQ8Msql5JIBC?auth=g.0.eyJraWQiOiIyMzhiNTUxZmMyM2EyM2Y4M2E2ZTE3MmJjZTg0YmU3ZjgxMzAzMmM4IiwiYWxnIjoiUlMyNTYifQ.eyJpc3MiOiJuZXN0LXNlY3VyaXR5LWF1dGhwcm94eSIsInN1YiI6Im5lc3RfaWQ6bmVzdC1waG9lbml4LXByb2Q6MjEyMTgxNDEiLCJwb2wiOiIzcC1vYXV0aC1zY29wZS1BUElfU0RNX1NFUlZJQ0UtY2xpZW50LTIwMjQyNzMxODczNS1qNXQ5bWMyMzZqaG85YXMycWY0dTZxY3NmYW1kaGJ0ci5hcHBzLmdvb2dsZXVzZXJjb250ZW50LmNvbSIsImV4cCI6MTYzMTM2MTc1NH0.DBoo9HfBTUKKf2osN6zMQERFwkkFeP3OGRaJCb6fAStZ8ynKMZG0ljaR9EhLJEFVZxXsQOfmNuEfp59x62uJAM6OJvzUy21CWcCvl9B42Vp_4TMrpO6kCZIApFbp0yiUpwVRyPY7aaCWVwokAJnq16Hl7Uow_-LNZrrd-6yEGxJLNGjJuKqpXLC6N04oTHZUmmjHUuRc2bjQlB2nJMm5K9fnQaFo2W7pbB8LZjVvA4F15Y14JUO4S4Gz9TJghxYhCuEfriH3wIWZcU6QgS9Fr2sxxVHzIVGeemPSTfd6DyJwFLgr1pg1zDdjan5qvFT9y1aZZ0BZ51xS5XkJWS-oAw
2021-09-11 04:58:08 ERROR (MainThread) [homeassistant] Error doing job: Future exception was never retrieved
Traceback (most recent call last):
  File "/usr/local/lib/python3.9/concurrent/futures/thread.py", line 52, in run
    result = self.fn(*self.args, **self.kwargs)
TypeError: update() takes 1 positional argument but 2 were given
2021-09-11 04:58:13 ERROR (stream_worker) [libav.rtsp] method DESCRIBE failed: 404 Not Found
2021-09-11 04:58:13 ERROR (stream_worker) [homeassistant.components.stream.worker] Error opening stream rtsps://stream-uc2-bravo.dropcam.com:443/sdm_live_stream/CiQA2vuxr27_sLMvoT3EEnvrU1pnbO1VaGHfkZ-X46xM_qZuuR0ScQAFjsOTT9-1IyTNchrOtDlFoQma0mll5EFJzjpM75_OlO7v5_W9P9Q8tHgk3YW7T8y0rPqrUvFPBV1YJmUUYtFShzz5DQbd7BJ0xQnC04XNfTsSkwJdkxmXYSprYOhYmoPEJh6Wz5jWZQ8Msql5JIBC?auth=g.0.eyJraWQiOiIyMzhiNTUxZmMyM2EyM2Y4M2E2ZTE3MmJjZTg0YmU3ZjgxMzAzMmM4IiwiYWxnIjoiUlMyNTYifQ.eyJpc3MiOiJuZXN0LXNlY3VyaXR5LWF1dGhwcm94eSIsInN1YiI6Im5lc3RfaWQ6bmVzdC1waG9lbml4LXByb2Q6MjEyMTgxNDEiLCJwb2wiOiIzcC1vYXV0aC1zY29wZS1BUElfU0RNX1NFUlZJQ0UtY2xpZW50LTIwMjQyNzMxODczNS1qNXQ5bWMyMzZqaG85YXMycWY0dTZxY3NmYW1kaGJ0ci5hcHBzLmdvb2dsZXVzZXJjb250ZW50LmNvbSIsImV4cCI6MTYzMTM2MTc1NH0.DBoo9HfBTUKKf2osN6zMQERFwkkFeP3OGRaJCb6fAStZ8ynKMZG0ljaR9EhLJEFVZxXsQOfmNuEfp59x62uJAM6OJvzUy21CWcCvl9B42Vp_4TMrpO6kCZIApFbp0yiUpwVRyPY7aaCWVwokAJnq16Hl7Uow_-LNZrrd-6yEGxJLNGjJuKqpXLC6N04oTHZUmmjHUuRc2bjQlB2nJMm5K9fnQaFo2W7pbB8LZjVvA4F15Y14JUO4S4Gz9TJghxYhCuEfriH3wIWZcU6QgS9Fr2sxxVHzIVGeemPSTfd6DyJwFLgr1pg1zDdjan5qvFT9y1aZZ0BZ51xS5XkJWS-oAw
2021-09-11 05:02:36 ERROR (stream_worker) [libav.rtsp] method DESCRIBE failed: 404 Not Found
2021-09-11 05:02:36 ERROR (stream_worker) [homeassistant.components.stream.worker] Error opening stream rtsps://stream-uc2-bravo.dropcam.com:443/sdm_live_stream/CiQA2vuxr27_sLMvoT3EEnvrU1pnbO1VaGHfkZ-X46xM_qZuuR0ScQAFjsOTT9-1IyTNchrOtDlFoQma0mll5EFJzjpM75_OlO7v5_W9P9Q8tHgk3YW7T8y0rPqrUvFPBV1YJmUUYtFShzz5DQbd7BJ0xQnC04XNfTsSkwJdkxmXYSprYOhYmoPEJh6Wz5jWZQ8Msql5JIBC?auth=g.0.eyJraWQiOiIyMzhiNTUxZmMyM2EyM2Y4M2E2ZTE3MmJjZTg0YmU3ZjgxMzAzMmM4IiwiYWxnIjoiUlMyNTYifQ.eyJpc3MiOiJuZXN0LXNlY3VyaXR5LWF1dGhwcm94eSIsInN1YiI6Im5lc3RfaWQ6bmVzdC1waG9lbml4LXByb2Q6MjEyMTgxNDEiLCJwb2wiOiIzcC1vYXV0aC1zY29wZS1BUElfU0RNX1NFUlZJQ0UtY2xpZW50LTIwMjQyNzMxODczNS1qNXQ5bWMyMzZqaG85YXMycWY0dTZxY3NmYW1kaGJ0ci5hcHBzLmdvb2dsZXVzZXJjb250ZW50LmNvbSIsImV4cCI6MTYzMTM2MjAyNX0.OAsEb3hAwY-H9ATuDnSzDYe9jAbyj7JjLchEv6UEe2KUIgkKKyQ-K6foR2GHLHXBTsvSP3-wah74tbYk6LttgZikW7f8UXLMEkZFh6PC3fg5RHMhPhtXFVF3CC7poZqYnuVFCbrZb6gGMpMUTCqFFecVB07Yn5Oy1rt3Y8a7NN7tyk2Bgi9i4URN337Qqzgu1XNXLmscVmU5sDN4zZxGNcYtuDzP6SQjqU77c_NPnVV0N-sN0fIWgKk3BkAjdtFnVnvdKY5gRGvhm1Zm1Rebi1Bo21B4u4kWfcfKK8Vb_VF_WYrxH7Lm5Ms-sDWQ_n3j4wbWpdS7fk3dVhui06OoIQ
2021-09-11 05:03:09 ERROR (MainThread) [homeassistant] Error doing job: Future exception was never retrieved
Traceback (most recent call last):
  File "/usr/local/lib/python3.9/concurrent/futures/thread.py", line 52, in run
    result = self.fn(*self.args, **self.kwargs)
TypeError: update() takes 1 positional argument but 2 were given
2021-09-11 05:07:21 ERROR (stream_worker) [libav.rtsp] method DESCRIBE failed: 404 Not Found
2021-09-11 05:07:21 ERROR (stream_worker) [homeassistant.components.stream.worker] Error opening stream rtsps://stream-uc2-bravo.dropcam.com:443/sdm_live_stream/CiQA2vuxr27_sLMvoT3EEnvrU1pnbO1VaGHfkZ-X46xM_qZuuR0ScQAFjsOTT9-1IyTNchrOtDlFoQma0mll5EFJzjpM75_OlO7v5_W9P9Q8tHgk3YW7T8y0rPqrUvFPBV1YJmUUYtFShzz5DQbd7BJ0xQnC04XNfTsSkwJdkxmXYSprYOhYmoPEJh6Wz5jWZQ8Msql5JIBC?auth=g.0.eyJraWQiOiIyMzhiNTUxZmMyM2EyM2Y4M2E2ZTE3MmJjZTg0YmU3ZjgxMzAzMmM4IiwiYWxnIjoiUlMyNTYifQ.eyJpc3MiOiJuZXN0LXNlY3VyaXR5LWF1dGhwcm94eSIsInN1YiI6Im5lc3RfaWQ6bmVzdC1waG9lbml4LXByb2Q6MjEyMTgxNDEiLCJwb2wiOiIzcC1vYXV0aC1zY29wZS1BUElfU0RNX1NFUlZJQ0UtY2xpZW50LTIwMjQyNzMxODczNS1qNXQ5bWMyMzZqaG85YXMycWY0dTZxY3NmYW1kaGJ0ci5hcHBzLmdvb2dsZXVzZXJjb250ZW50LmNvbSIsImV4cCI6MTYzMTM2MjI5NX0.fJPmuD5Q4j1AqgicddnxtgnlwfjfMQi2MFSleuVjnaK5lpqGpyEVjG5phPTq7sq0NC8YekdUPAIQGUpaG8gwQC_5az_BGoMHumhy2vtPyx2uQBBa9zvmTqcqTWMkSmPMBD7SPaScL314XeM_JXV3ECgvFjSnza0ygLdJVHSPJ1Lb5_aIQAPf2cPHo6BRBX0kL289VX9UL_6iht0w_9x9bd7rrJrhlCKRuKUdrEeFVBNGo-89OQ2mOEzVvNQkRuN4lQanbCeMf0stufzkr9OSNeB8Nb1J24vjw48Kz5gM_LlPn2lHtk7jfT6JHydq6m31SDVHwWhxic6UeJXs41fd5A
2021-09-11 05:08:10 ERROR (MainThread) [homeassistant] Error doing job: Future exception was never retrieved
Traceback (most recent call last):
  File "/usr/local/lib/python3.9/concurrent/futures/thread.py", line 52, in run
    result = self.fn(*self.args, **self.kwargs)
TypeError: update() takes 1 positional argument but 2 were given
2021-09-11 05:11:57 ERROR (stream_worker) [homeassistant.components.stream.worker] Stream has no video
2021-09-11 05:13:11 ERROR (MainThread) [homeassistant] Error doing job: Future exception was never retrieved
Traceback (most recent call last):
  File "/usr/local/lib/python3.9/concurrent/futures/thread.py", line 52, in run
    result = self.fn(*self.args, **self.kwargs)
TypeError: update() takes 1 positional argument but 2 were given
2021-09-11 05:14:34 ERROR (MainThread) [iotawattpy.connection] Err: 
2021-09-11 05:14:34 ERROR (MainThread) [homeassistant.components.iotawatt.coordinator] Unexpected error fetching 192.168.20.195 data: 'NoneType' object has no attribute 'text'
Traceback (most recent call last):
  File "/usr/src/homeassistant/homeassistant/helpers/update_coordinator.py", line 187, in _async_refresh
    self.data = await self._async_update_data()
  File "/usr/src/homeassistant/homeassistant/components/iotawatt/coordinator.py", line 55, in _async_update_data
    await self.api.update()
  File "/usr/local/lib/python3.9/site-packages/iotawattpy/iotawatt.py", line 66, in update
    await self._refreshSensors(timespan)
  File "/usr/local/lib/python3.9/site-packages/iotawattpy/iotawatt.py", line 100, in _refreshSensors
    results = response.text
AttributeError: 'NoneType' object has no attribute 'text'
2021-09-11 05:15:31 WARNING (MainThread) [bellows.zigbee.application] Watchdog heartbeat timeout: 
2021-09-11 05:18:12 ERROR (MainThread) [homeassistant] Error doing job: Future exception was never retrieved
Traceback (most recent call last):
  File "/usr/local/lib/python3.9/concurrent/futures/thread.py", line 52, in run
    result = self.fn(*self.args, **self.kwargs)
TypeError: update() takes 1 positional argument but 2 were given
2021-09-11 05:23:13 ERROR (MainThread) [homeassistant] Error doing job: Future exception was never retrieved
Traceback (most recent call last):
  File "/usr/local/lib/python3.9/concurrent/futures/thread.py", line 52, in run
    result = self.fn(*self.args, **self.kwargs)
TypeError: update() takes 1 positional argument but 2 were given
2021-09-11 05:28:14 ERROR (MainThread) [homeassistant] Error doing job: Future exception was never retrieved
Traceback (most recent call last):
  File "/usr/local/lib/python3.9/concurrent/futures/thread.py", line 52, in run
    result = self.fn(*self.args, **self.kwargs)
TypeError: update() takes 1 positional argument but 2 were given
2021-09-11 05:30:12 ERROR (stream_worker) [libav.rtsp] method DESCRIBE failed: 404 Not Found
2021-09-11 05:30:12 ERROR (stream_worker) [homeassistant.components.stream.worker] Error opening stream rtsps://stream-uc2-bravo.dropcam.com:443/sdm_live_stream/CiQA2vuxr27_sLMvoT3EEnvrU1pnbO1VaGHfkZ-X46xM_qZuuR0ScQAFjsOTT9-1IyTNchrOtDlFoQma0mll5EFJzjpM75_OlO7v5_W9P9Q8tHgk3YW7T8y0rPqrUvFPBV1YJmUUYtFShzz5DQbd7BJ0xQnC04XNfTsSkwJdkxmXYSprYOhYmoPEJh6Wz5jWZQ8Msql5JIBC?auth=g.0.eyJraWQiOiIyMzhiNTUxZmMyM2EyM2Y4M2E2ZTE3MmJjZTg0YmU3ZjgxMzAzMmM4IiwiYWxnIjoiUlMyNTYifQ.eyJpc3MiOiJuZXN0LXNlY3VyaXR5LWF1dGhwcm94eSIsInN1YiI6Im5lc3RfaWQ6bmVzdC1waG9lbml4LXByb2Q6MjEyMTgxNDEiLCJwb2wiOiIzcC1vYXV0aC1zY29wZS1BUElfU0RNX1NFUlZJQ0UtY2xpZW50LTIwMjQyNzMxODczNS1qNXQ5bWMyMzZqaG85YXMycWY0dTZxY3NmYW1kaGJ0ci5hcHBzLmdvb2dsZXVzZXJjb250ZW50LmNvbSIsImV4cCI6MTYzMTM2MzY0OH0.D8ygyzhwcyoH8ujwaXtYTEDXLzR2DNkxCTgCFs9DuY1CBrUWuKtiGW-J8aSRs1CnT810EzZ2YY-7s567F-lTPIk1OKeYptp4sDF_5Krhxsvx8jADHmDZvsgcd_w2Ejuu7_yi7B8p3ePxJWA6NwvPpYv__uLKnKVVWVvA2y7uvH2U6HsMNKjcH837U2aRx_PmglxySDL1d66WIEIDuOLNtboduhLNsdkJw6sSr6l1uimWlDiGYeAxQIFssHblTW6IdxHRUq5TcAvv3m3_C6rvNVBrL4zKZP_pCYWE-C7iy2OisvNH0Yx5T3yU5R9ezQEK7McjAbZh1EG5-Xg3cqDjqg
2021-09-11 05:31:26 ERROR (stream_worker) [libav.rtsp] method DESCRIBE failed: 404 Not Found
2021-09-11 05:31:26 ERROR (stream_worker) [homeassistant.components.stream.worker] Error opening stream rtsps://stream-uc2-bravo.dropcam.com:443/sdm_live_stream/CiQA2vuxr27_sLMvoT3EEnvrU1pnbO1VaGHfkZ-X46xM_qZuuR0ScQAFjsOTT9-1IyTNchrOtDlFoQma0mll5EFJzjpM75_OlO7v5_W9P9Q8tHgk3YW7T8y0rPqrUvFPBV1YJmUUYtFShzz5DQbd7BJ0xQnC04XNfTsSkwJdkxmXYSprYOhYmoPEJh6Wz5jWZQ8Msql5JIBC?auth=g.0.eyJraWQiOiIyMzhiNTUxZmMyM2EyM2Y4M2E2ZTE3MmJjZTg0YmU3ZjgxMzAzMmM4IiwiYWxnIjoiUlMyNTYifQ.eyJpc3MiOiJuZXN0LXNlY3VyaXR5LWF1dGhwcm94eSIsInN1YiI6Im5lc3RfaWQ6bmVzdC1waG9lbml4LXByb2Q6MjEyMTgxNDEiLCJwb2wiOiIzcC1vYXV0aC1zY29wZS1BUElfU0RNX1NFUlZJQ0UtY2xpZW50LTIwMjQyNzMxODczNS1qNXQ5bWMyMzZqaG85YXMycWY0dTZxY3NmYW1kaGJ0ci5hcHBzLmdvb2dsZXVzZXJjb250ZW50LmNvbSIsImV4cCI6MTYzMTM2MzY0OH0.D8ygyzhwcyoH8ujwaXtYTEDXLzR2DNkxCTgCFs9DuY1CBrUWuKtiGW-J8aSRs1CnT810EzZ2YY-7s567F-lTPIk1OKeYptp4sDF_5Krhxsvx8jADHmDZvsgcd_w2Ejuu7_yi7B8p3ePxJWA6NwvPpYv__uLKnKVVWVvA2y7uvH2U6HsMNKjcH837U2aRx_PmglxySDL1d66WIEIDuOLNtboduhLNsdkJw6sSr6l1uimWlDiGYeAxQIFssHblTW6IdxHRUq5TcAvv3m3_C6rvNVBrL4zKZP_pCYWE-C7iy2OisvNH0Yx5T3yU5R9ezQEK7McjAbZh1EG5-Xg3cqDjqg
2021-09-11 05:32:17 WARNING (MainThread) [homeassistant.components.mqtt] Can't decode payload b'{"Time":"2021-09-11T05:32:12","ENERGY":{"TotalStartTime":"2021-08-10T18:02:19","Total":83.340,"Yesterday":3.367,"Today":0.284,"Power":3806\x00\x17tele/S31_temp01/MARGINS{"MARGINS":{"PowerDelta":-5}}0\xf4\x01\x00\x16tele/S31_temp01/SENSOR{' on tele/S31_temp01/SENSOR with encoding utf-8 (for <Job HassJobType.Callback <function TasmotaSensor.subscribe_topics.<locals>.state_message_received at 0x14f450cb9d30>>)
2021-09-11 05:32:17 WARNING (MainThread) [homeassistant.components.mqtt] Can't decode payload b'{"Time":"2021-09-11T05:32:12","ENERGY":{"TotalStartTime":"2021-08-10T18:02:19","Total":83.340,"Yesterday":3.367,"Today":0.284,"Power":3806\x00\x17tele/S31_temp01/MARGINS{"MARGINS":{"PowerDelta":-5}}0\xf4\x01\x00\x16tele/S31_temp01/SENSOR{' on tele/S31_temp01/SENSOR with encoding utf-8 (for <Job HassJobType.Callback <function TasmotaSensor.subscribe_topics.<locals>.state_message_received at 0x14f450c76040>>)
2021-09-11 05:32:17 WARNING (MainThread) [homeassistant.components.mqtt] Can't decode payload b'{"Time":"2021-09-11T05:32:12","ENERGY":{"TotalStartTime":"2021-08-10T18:02:19","Total":83.340,"Yesterday":3.367,"Today":0.284,"Power":3806\x00\x17tele/S31_temp01/MARGINS{"MARGINS":{"PowerDelta":-5}}0\xf4\x01\x00\x16tele/S31_temp01/SENSOR{' on tele/S31_temp01/SENSOR with encoding utf-8 (for <Job HassJobType.Callback <function TasmotaSensor.subscribe_topics.<locals>.state_message_received at 0x14f450c76940>>)
2021-09-11 05:32:17 WARNING (MainThread) [homeassistant.components.mqtt] Can't decode payload b'{"Time":"2021-09-11T05:32:12","ENERGY":{"TotalStartTime":"2021-08-10T18:02:19","Total":83.340,"Yesterday":3.367,"Today":0.284,"Power":3806\x00\x17tele/S31_temp01/MARGINS{"MARGINS":{"PowerDelta":-5}}0\xf4\x01\x00\x16tele/S31_temp01/SENSOR{' on tele/S31_temp01/SENSOR with encoding utf-8 (for <Job HassJobType.Callback <function TasmotaSensor.subscribe_topics.<locals>.state_message_received at 0x14f4506c11f0>>)
2021-09-11 05:32:17 WARNING (MainThread) [homeassistant.components.mqtt] Can't decode payload b'{"Time":"2021-09-11T05:32:12","ENERGY":{"TotalStartTime":"2021-08-10T18:02:19","Total":83.340,"Yesterday":3.367,"Today":0.284,"Power":3806\x00\x17tele/S31_temp01/MARGINS{"MARGINS":{"PowerDelta":-5}}0\xf4\x01\x00\x16tele/S31_temp01/SENSOR{' on tele/S31_temp01/SENSOR with encoding utf-8 (for <Job HassJobType.Callback <function TasmotaSensor.subscribe_topics.<locals>.state_message_received at 0x14f4506c1af0>>)
2021-09-11 05:32:17 WARNING (MainThread) [homeassistant.components.mqtt] Can't decode payload b'{"Time":"2021-09-11T05:32:12","ENERGY":{"TotalStartTime":"2021-08-10T18:02:19","Total":83.340,"Yesterday":3.367,"Today":0.284,"Power":3806\x00\x17tele/S31_temp01/MARGINS{"MARGINS":{"PowerDelta":-5}}0\xf4\x01\x00\x16tele/S31_temp01/SENSOR{' on tele/S31_temp01/SENSOR with encoding utf-8 (for <Job HassJobType.Callback <function TasmotaSensor.subscribe_topics.<locals>.state_message_received at 0x14f4506ca430>>)
2021-09-11 05:32:17 WARNING (MainThread) [homeassistant.components.mqtt] Can't decode payload b'{"Time":"2021-09-11T05:32:12","ENERGY":{"TotalStartTime":"2021-08-10T18:02:19","Total":83.340,"Yesterday":3.367,"Today":0.284,"Power":3806\x00\x17tele/S31_temp01/MARGINS{"MARGINS":{"PowerDelta":-5}}0\xf4\x01\x00\x16tele/S31_temp01/SENSOR{' on tele/S31_temp01/SENSOR with encoding utf-8 (for <Job HassJobType.Callback <function TasmotaSensor.subscribe_topics.<locals>.state_message_received at 0x14f4506cad30>>)
2021-09-11 05:32:17 WARNING (MainThread) [homeassistant.components.mqtt] Can't decode payload b'{"Time":"2021-09-11T05:32:12","ENERGY":{"TotalStartTime":"2021-08-10T18:02:19","Total":83.340,"Yesterday":3.367,"Today":0.284,"Power":3806\x00\x17tele/S31_temp01/MARGINS{"MARGINS":{"PowerDelta":-5}}0\xf4\x01\x00\x16tele/S31_temp01/SENSOR{' on tele/S31_temp01/SENSOR with encoding utf-8 (for <Job HassJobType.Callback <function TasmotaSensor.subscribe_topics.<locals>.state_message_received at 0x14f4506d5670>>)
2021-09-11 05:32:17 WARNING (MainThread) [homeassistant.components.mqtt] Can't decode payload b'{"Time":"2021-09-11T05:32:12","ENERGY":{"TotalStartTime":"2021-08-10T18:02:19","Total":83.340,"Yesterday":3.367,"Today":0.284,"Power":3806\x00\x17tele/S31_temp01/MARGINS{"MARGINS":{"PowerDelta":-5}}0\xf4\x01\x00\x16tele/S31_temp01/SENSOR{' on tele/S31_temp01/SENSOR with encoding utf-8 (for <Job HassJobType.Callback <function TasmotaSensor.subscribe_topics.<locals>.state_message_received at 0x14f4506d5f70>>)
2021-09-11 05:32:17 WARNING (MainThread) [homeassistant.components.mqtt] Can't decode payload b'{"Time":"2021-09-11T05:32:12","ENERGY":{"TotalStartTime":"2021-08-10T18:02:19","Total":83.340,"Yesterday":3.367,"Today":0.284,"Power":3806\x00\x17tele/S31_temp01/MARGINS{"MARGINS":{"PowerDelta":-5}}0\xf4\x01\x00\x16tele/S31_temp01/SENSOR{' on tele/S31_temp01/SENSOR with encoding utf-8 (for <Job HassJobType.Callback <function TasmotaSensor.subscribe_topics.<locals>.state_message_received at 0x14f4506dc8b0>>)
2021-09-11 05:33:15 ERROR (MainThread) [homeassistant] Error doing job: Future exception was never retrieved
Traceback (most recent call last):
  File "/usr/local/lib/python3.9/concurrent/futures/thread.py", line 52, in run
    result = self.fn(*self.args, **self.kwargs)
TypeError: update() takes 1 positional argument but 2 were given
2021-09-11 05:38:16 ERROR (MainThread) [homeassistant] Error doing job: Future exception was never retrieved
Traceback (most recent call last):
  File "/usr/local/lib/python3.9/concurrent/futures/thread.py", line 52, in run
    result = self.fn(*self.args, **self.kwargs)
TypeError: update() takes 1 positional argument but 2 were given
2021-09-11 05:43:17 ERROR (MainThread) [homeassistant] Error doing job: Future exception was never retrieved
Traceback (most recent call last):
  File "/usr/local/lib/python3.9/concurrent/futures/thread.py", line 52, in run
    result = self.fn(*self.args, **self.kwargs)
TypeError: update() takes 1 positional argument but 2 were given
2021-09-11 05:48:18 ERROR (MainThread) [homeassistant] Error doing job: Future exception was never retrieved
Traceback (most recent call last):
  File "/usr/local/lib/python3.9/concurrent/futures/thread.py", line 52, in run
    result = self.fn(*self.args, **self.kwargs)
TypeError: update() takes 1 positional argument but 2 were given
2021-09-11 05:53:19 ERROR (MainThread) [homeassistant] Error doing job: Future exception was never retrieved
Traceback (most recent call last):
  File "/usr/local/lib/python3.9/concurrent/futures/thread.py", line 52, in run
    result = self.fn(*self.args, **self.kwargs)
TypeError: update() takes 1 positional argument but 2 were given
2021-09-11 05:58:20 ERROR (MainThread) [homeassistant] Error doing job: Future exception was never retrieved
Traceback (most recent call last):
  File "/usr/local/lib/python3.9/concurrent/futures/thread.py", line 52, in run
    result = self.fn(*self.args, **self.kwargs)
TypeError: update() takes 1 positional argument but 2 were given
2021-09-11 06:03:21 ERROR (MainThread) [homeassistant] Error doing job: Future exception was never retrieved
Traceback (most recent call last):
  File "/usr/local/lib/python3.9/concurrent/futures/thread.py", line 52, in run
    result = self.fn(*self.args, **self.kwargs)
TypeError: update() takes 1 positional argument but 2 were given
2021-09-11 06:05:40 WARNING (MainThread) [bellows.zigbee.application] Watchdog heartbeat timeout: 
2021-09-11 06:05:55 WARNING (MainThread) [bellows.zigbee.application] Watchdog heartbeat timeout: 
2021-09-11 06:08:22 ERROR (MainThread) [homeassistant] Error doing job: Future exception was never retrieved
Traceback (most recent call last):
  File "/usr/local/lib/python3.9/concurrent/futures/thread.py", line 52, in run
    result = self.fn(*self.args, **self.kwargs)
TypeError: update() takes 1 positional argument but 2 were given
2021-09-11 06:13:23 ERROR (MainThread) [homeassistant] Error doing job: Future exception was never retrieved
Traceback (most recent call last):
  File "/usr/local/lib/python3.9/concurrent/futures/thread.py", line 52, in run
    result = self.fn(*self.args, **self.kwargs)
TypeError: update() takes 1 positional argument but 2 were given
2021-09-11 06:18:24 ERROR (MainThread) [homeassistant] Error doing job: Future exception was never retrieved
Traceback (most recent call last):
  File "/usr/local/lib/python3.9/concurrent/futures/thread.py", line 52, in run
    result = self.fn(*self.args, **self.kwargs)
TypeError: update() takes 1 positional argument but 2 were given
2021-09-11 06:23:25 ERROR (MainThread) [homeassistant] Error doing job: Future exception was never retrieved
Traceback (most recent call last):
  File "/usr/local/lib/python3.9/concurrent/futures/thread.py", line 52, in run
    result = self.fn(*self.args, **self.kwargs)
TypeError: update() takes 1 positional argument but 2 were given
2021-09-11 06:23:26 ERROR (stream_worker) [libav.rtsp] method DESCRIBE failed: 404 Not Found
2021-09-11 06:23:26 ERROR (stream_worker) [homeassistant.components.stream.worker] Error opening stream rtsps://stream-uc2-delta.dropcam.com:443/sdm_live_stream/CiQA2vuxrzkcUOGJE2JDLFJAnQLTlN1AC4hVvPiSkveUMQSHylwScQAFjsOTmmq3cK5qwz7nYlT8j2qyNbpmk91SnJlCdgLAgg-QP-aB43FR_5SJI12xHa_Cerp9CJ-Y0pajjqAsuQD8O1SY0Gy4QX0sP7dIvV2wap12AicA3R8Ke47gYl6M8CVTeWQNWInJgnUyGKRzltux?auth=g.0.eyJraWQiOiIyMzhiNTUxZmMyM2EyM2Y4M2E2ZTE3MmJjZTg0YmU3ZjgxMzAzMmM4IiwiYWxnIjoiUlMyNTYifQ.eyJpc3MiOiJuZXN0LXNlY3VyaXR5LWF1dGhwcm94eSIsInN1YiI6Im5lc3RfaWQ6bmVzdC1waG9lbml4LXByb2Q6MjEyMTgxNDEiLCJwb2wiOiIzcC1vYXV0aC1zY29wZS1BUElfU0RNX1NFUlZJQ0UtY2xpZW50LTIwMjQyNzMxODczNS1qNXQ5bWMyMzZqaG85YXMycWY0dTZxY3NmYW1kaGJ0ci5hcHBzLmdvb2dsZXVzZXJjb250ZW50LmNvbSIsImV4cCI6MTYzMTM2Njg5NX0.Ria_otCys_BNA4poEvgaKGaVuuAFJxx_TdrvidzcT9KPEqPcM7XHPVFgLGWIv2ErjFQC1fnPfnOj69cZ3wyS6nyhMCIZuflm4zu1u5kBIxZj7-bxMdA6wK_pj8hHk4KpKEXpQY9hzel-JI7ZsqRvzC7875cqwrRnGF1zPlWXaq4VaPey7LS-CqhGb46xXvk-4EQ_U3t1NtApCVxNO-G1fluFnM-uLOXs1C8aMBDCZ5FgIZvqCqcIkkM2JXAjWdE8u4NiELkU_XA_wNDShQTz9J4ppQo5PeV3x6YT29HDSHcdC5iHUHLoPKQw4JPOm7toebO6vUzw2sWMw7D3yDfU8Q
2021-09-11 06:28:09 ERROR (stream_worker) [libav.rtsp] method DESCRIBE failed: 404 Not Found
2021-09-11 06:28:09 ERROR (stream_worker) [homeassistant.components.stream.worker] Error opening stream rtsps://stream-uc2-delta.dropcam.com:443/sdm_live_stream/CiQA2vuxrzkcUOGJE2JDLFJAnQLTlN1AC4hVvPiSkveUMQSHylwScQAFjsOTmmq3cK5qwz7nYlT8j2qyNbpmk91SnJlCdgLAgg-QP-aB43FR_5SJI12xHa_Cerp9CJ-Y0pajjqAsuQD8O1SY0Gy4QX0sP7dIvV2wap12AicA3R8Ke47gYl6M8CVTeWQNWInJgnUyGKRzltux?auth=g.0.eyJraWQiOiIyMzhiNTUxZmMyM2EyM2Y4M2E2ZTE3MmJjZTg0YmU3ZjgxMzAzMmM4IiwiYWxnIjoiUlMyNTYifQ.eyJpc3MiOiJuZXN0LXNlY3VyaXR5LWF1dGhwcm94eSIsInN1YiI6Im5lc3RfaWQ6bmVzdC1waG9lbml4LXByb2Q6MjEyMTgxNDEiLCJwb2wiOiIzcC1vYXV0aC1zY29wZS1BUElfU0RNX1NFUlZJQ0UtY2xpZW50LTIwMjQyNzMxODczNS1qNXQ5bWMyMzZqaG85YXMycWY0dTZxY3NmYW1kaGJ0ci5hcHBzLmdvb2dsZXVzZXJjb250ZW50LmNvbSIsImV4cCI6MTYzMTM2NzE2NX0.QNP7lyAEMuMIVrxVU_DI2BSjJ2byNP6spBScddKoAu2-q1RbMM0pDCAMTjmObWMWASr3j-Fu_8uKwAZldfFi0WiczSgHKXhh8Dnug3tyHximAt-gOpeUcQ9yhtlEab1fayGVmT1DH8fWMR_RC8_vk41R-k9vq_ElyH5_pQgZyurj5Hhbd41BI0iie4YEQm3YLJujbQipg8CUGMQM7lI5ZRj5O69kM0t14VB7vBntcisN1ue38Kq8Bwz_BxvKj4jRAdarsAJ1-WiaSyLf0IlVXbHyt6yZDIMW_Cj-BDCmaQASatMM7b_RlLPxbSLA4E5tAtfsyJ6YkhFf7npyNXDXLQ
2021-09-11 06:28:26 ERROR (MainThread) [homeassistant] Error doing job: Future exception was never retrieved
Traceback (most recent call last):
  File "/usr/local/lib/python3.9/concurrent/futures/thread.py", line 52, in run
    result = self.fn(*self.args, **self.kwargs)
TypeError: update() takes 1 positional argument but 2 were given
2021-09-11 06:30:03 ERROR (MainThread) [homeassistant.components.nws] Error requesting NWS observation station SAUC1 data: 503, message='Service Unavailable', url=URL('https://api.weather.gov/stations/SAUC1/observations')
2021-09-11 06:33:27 ERROR (MainThread) [homeassistant] Error doing job: Future exception was never retrieved
Traceback (most recent call last):
  File "/usr/local/lib/python3.9/concurrent/futures/thread.py", line 52, in run
    result = self.fn(*self.args, **self.kwargs)
TypeError: update() takes 1 positional argument but 2 were given
2021-09-11 06:34:59 WARNING (MainThread) [homeassistant.helpers.service] Unable to find referenced entities scene.kitchen_sink_off
2021-09-11 06:38:28 ERROR (MainThread) [homeassistant] Error doing job: Future exception was never retrieved
Traceback (most recent call last):
  File "/usr/local/lib/python3.9/concurrent/futures/thread.py", line 52, in run
    result = self.fn(*self.args, **self.kwargs)
TypeError: update() takes 1 positional argument but 2 were given
2021-09-11 06:43:29 ERROR (MainThread) [homeassistant] Error doing job: Future exception was never retrieved
Traceback (most recent call last):
  File "/usr/local/lib/python3.9/concurrent/futures/thread.py", line 52, in run
    result = self.fn(*self.args, **self.kwargs)
TypeError: update() takes 1 positional argument but 2 were given
2021-09-11 06:48:30 ERROR (MainThread) [homeassistant] Error doing job: Future exception was never retrieved
Traceback (most recent call last):
  File "/usr/local/lib/python3.9/concurrent/futures/thread.py", line 52, in run
    result = self.fn(*self.args, **self.kwargs)
TypeError: update() takes 1 positional argument but 2 were given
2021-09-11 06:50:50 ERROR (stream_worker) [libav.rtsp] method DESCRIBE failed: 404 Not Found
2021-09-11 06:50:50 ERROR (stream_worker) [homeassistant.components.stream.worker] Error opening stream rtsps://stream-uc2-delta.dropcam.com:443/sdm_live_stream/CiQA2vuxrzkcUOGJE2JDLFJAnQLTlN1AC4hVvPiSkveUMQSHylwScQAFjsOTmmq3cK5qwz7nYlT8j2qyNbpmk91SnJlCdgLAgg-QP-aB43FR_5SJI12xHa_Cerp9CJ-Y0pajjqAsuQD8O1SY0Gy4QX0sP7dIvV2wap12AicA3R8Ke47gYl6M8CVTeWQNWInJgnUyGKRzltux?auth=g.0.eyJraWQiOiIyMzhiNTUxZmMyM2EyM2Y4M2E2ZTE3MmJjZTg0YmU3ZjgxMzAzMmM4IiwiYWxnIjoiUlMyNTYifQ.eyJpc3MiOiJuZXN0LXNlY3VyaXR5LWF1dGhwcm94eSIsInN1YiI6Im5lc3RfaWQ6bmVzdC1waG9lbml4LXByb2Q6MjEyMTgxNDEiLCJwb2wiOiIzcC1vYXV0aC1zY29wZS1BUElfU0RNX1NFUlZJQ0UtY2xpZW50LTIwMjQyNzMxODczNS1qNXQ5bWMyMzZqaG85YXMycWY0dTZxY3NmYW1kaGJ0ci5hcHBzLmdvb2dsZXVzZXJjb250ZW50LmNvbSIsImV4cCI6MTYzMTM2ODUxOH0.eB98ibd3Bz2giTeK5kFDsq8T88mDK6vu3TdaTwAx8rPz4o1yUg8L_xqGeaoiOrdO5N1-CY-E_ZsbhlayB9CZlTvIXP3yuwjGqYlBfXf_nRVH3LNSndDbIcJxK_GF8U_rcuNtzhNZpGuyfnkR2LIK90BoZaBL91TdUGOjMqRJEN7VFf03O_DuUv8eF0iIO8UldwFrUoti4PiHu9tp3ZfOSW85pLeSg-F9C_Fv7Qe4HNGTMQ9CXeAHWUfvGZ4MWZ_CTVwqxOcGaPng7I_Dr30PAG1oyUj_BmOGthNlyNsJ9VDLsBjdjOKiISixhUpvE-oM9efUp_K9gWs8COsxd3gurQ
2021-09-11 06:53:31 ERROR (MainThread) [homeassistant] Error doing job: Future exception was never retrieved
Traceback (most recent call last):
  File "/usr/local/lib/python3.9/concurrent/futures/thread.py", line 52, in run
    result = self.fn(*self.args, **self.kwargs)
TypeError: update() takes 1 positional argument but 2 were given
2021-09-11 06:55:29 ERROR (stream_worker) [homeassistant.components.stream.worker] Stream has no video
2021-09-11 06:56:23 ERROR (stream_worker) [libav.rtsp] method DESCRIBE failed: 404 Not Found
2021-09-11 06:56:23 ERROR (stream_worker) [homeassistant.components.stream.worker] Error opening stream rtsps://stream-uc2-delta.dropcam.com:443/sdm_live_stream/CiQA2vuxrzkcUOGJE2JDLFJAnQLTlN1AC4hVvPiSkveUMQSHylwScQAFjsOTmmq3cK5qwz7nYlT8j2qyNbpmk91SnJlCdgLAgg-QP-aB43FR_5SJI12xHa_Cerp9CJ-Y0pajjqAsuQD8O1SY0Gy4QX0sP7dIvV2wap12AicA3R8Ke47gYl6M8CVTeWQNWInJgnUyGKRzltux?auth=g.0.eyJraWQiOiIyMzhiNTUxZmMyM2EyM2Y4M2E2ZTE3MmJjZTg0YmU3ZjgxMzAzMmM4IiwiYWxnIjoiUlMyNTYifQ.eyJpc3MiOiJuZXN0LXNlY3VyaXR5LWF1dGhwcm94eSIsInN1YiI6Im5lc3RfaWQ6bmVzdC1waG9lbml4LXByb2Q6MjEyMTgxNDEiLCJwb2wiOiIzcC1vYXV0aC1zY29wZS1BUElfU0RNX1NFUlZJQ0UtY2xpZW50LTIwMjQyNzMxODczNS1qNXQ5bWMyMzZqaG85YXMycWY0dTZxY3NmYW1kaGJ0ci5hcHBzLmdvb2dsZXVzZXJjb250ZW50LmNvbSIsImV4cCI6MTYzMTM2ODc4OH0.d0-RdoFaj92rSZOhRMwDh1uaS_5XbuV1c77lwDYchwAKhMtj319-EpVl0ynFtSZp2pt-uhqCM_K1RXuyBj9s7r-V-lqZYA-LMCOwijpbpP9Vib2X0ZA4IBbzS364WGsYG7TV_9_qMrvvIrNVbaBpT38VbaCNyNst3HiN2iGwDGsSCIj41T_8eao85N5j8WlRht_ropeGWrztEDd3N9NAofkKL6Nhrkq50OoGTH9fFRTNSG1UKuf3GpgrTvMpj-LaJg_aJijvAA8uc4ocQ1gl_xzLpk0KwdJeaJFre4Wvxo7OvWCyjJKjWZy8C17eMkJKQGW2rjAZy3vFdwR-u5Xo4w
2021-09-11 06:58:32 ERROR (MainThread) [homeassistant] Error doing job: Future exception was never retrieved
Traceback (most recent call last):
  File "/usr/local/lib/python3.9/concurrent/futures/thread.py", line 52, in run
    result = self.fn(*self.args, **self.kwargs)
TypeError: update() takes 1 positional argument but 2 were given
2021-09-11 07:00:40 ERROR (stream_worker) [homeassistant.components.stream.worker] Error opening stream rtsps://stream-uc2-delta.dropcam.com:443/sdm_live_stream/CiQA2vuxrzkcUOGJE2JDLFJAnQLTlN1AC4hVvPiSkveUMQSHylwScQAFjsOTmmq3cK5qwz7nYlT8j2qyNbpmk91SnJlCdgLAgg-QP-aB43FR_5SJI12xHa_Cerp9CJ-Y0pajjqAsuQD8O1SY0Gy4QX0sP7dIvV2wap12AicA3R8Ke47gYl6M8CVTeWQNWInJgnUyGKRzltux?auth=g.0.eyJraWQiOiIyMzhiNTUxZmMyM2EyM2Y4M2E2ZTE3MmJjZTg0YmU3ZjgxMzAzMmM4IiwiYWxnIjoiUlMyNTYifQ.eyJpc3MiOiJuZXN0LXNlY3VyaXR5LWF1dGhwcm94eSIsInN1YiI6Im5lc3RfaWQ6bmVzdC1waG9lbml4LXByb2Q6MjEyMTgxNDEiLCJwb2wiOiIzcC1vYXV0aC1zY29wZS1BUElfU0RNX1NFUlZJQ0UtY2xpZW50LTIwMjQyNzMxODczNS1qNXQ5bWMyMzZqaG85YXMycWY0dTZxY3NmYW1kaGJ0ci5hcHBzLmdvb2dsZXVzZXJjb250ZW50LmNvbSIsImV4cCI6MTYzMTM2OTA1OX0.r53cKx-h5bYTu0L5WJmPHjTCg0NaSh1LiKumCDeeQbsXbyXTs0i2Bxp0Y7wEBY31NQFf8dRnXXNEw65q4Dm2Sabrw3rZg3BaV2MuFjw8xyToyg3FH6My2qA0BsuB1BZVcmdBPtqZdpUXEnOn73aqUPxdRGkdIxJyLpj3-pVQWNtH5mSr9pXD4NzXfGiCdScexBlQ3FO97FlgZl6hbEJdtoCR5bb2Q0lgCBbrJWVW18OaGBTy8d_ZHZ-LvLWK8Dfl-AGDZ_4Y_Uh0oyfjAKVvHntiIh3KEexj2ePO3wCuGS0P_yFSa3RkePKXSEcbE6bzxD8mGgOGM9dTvr2g6KfoYg
2021-09-11 07:01:34 ERROR (MainThread) [homeassistant.components.nws] Error requesting NWS observation station SAUC1 data: 503, message='Service Unavailable', url=URL('https://api.weather.gov/stations/SAUC1/observations')
2021-09-11 07:03:33 ERROR (MainThread) [homeassistant] Error doing job: Future exception was never retrieved
Traceback (most recent call last):
  File "/usr/local/lib/python3.9/concurrent/futures/thread.py", line 52, in run
    result = self.fn(*self.args, **self.kwargs)
TypeError: update() takes 1 positional argument but 2 were given
2021-09-11 07:05:03 ERROR (stream_worker) [libav.rtsp] method DESCRIBE failed: 404 Not Found
2021-09-11 07:05:03 ERROR (stream_worker) [homeassistant.components.stream.worker] Error opening stream rtsps://stream-uc2-delta.dropcam.com:443/sdm_live_stream/CiQA2vuxrzkcUOGJE2JDLFJAnQLTlN1AC4hVvPiSkveUMQSHylwScQAFjsOTmmq3cK5qwz7nYlT8j2qyNbpmk91SnJlCdgLAgg-QP-aB43FR_5SJI12xHa_Cerp9CJ-Y0pajjqAsuQD8O1SY0Gy4QX0sP7dIvV2wap12AicA3R8Ke47gYl6M8CVTeWQNWInJgnUyGKRzltux?auth=g.0.eyJraWQiOiIyMzhiNTUxZmMyM2EyM2Y4M2E2ZTE3MmJjZTg0YmU3ZjgxMzAzMmM4IiwiYWxnIjoiUlMyNTYifQ.eyJpc3MiOiJuZXN0LXNlY3VyaXR5LWF1dGhwcm94eSIsInN1YiI6Im5lc3RfaWQ6bmVzdC1waG9lbml4LXByb2Q6MjEyMTgxNDEiLCJwb2wiOiIzcC1vYXV0aC1zY29wZS1BUElfU0RNX1NFUlZJQ0UtY2xpZW50LTIwMjQyNzMxODczNS1qNXQ5bWMyMzZqaG85YXMycWY0dTZxY3NmYW1kaGJ0ci5hcHBzLmdvb2dsZXVzZXJjb250ZW50LmNvbSIsImV4cCI6MTYzMTM2OTMyOX0.qVX1UU9pDtA7Ni7_WokvaBM6LCmxhoMGYeZG97XCbQj3FYxsMcEdV4v7TeFxiI8J-5D-8KbQBVPYe1LFVjnT_lUMWIiWVPSTFZnkgqp7PFsim45cUc9BIMD_GX2WiIXOvoMsUxx8kw89d_Fa8kG2xOWjTYx9ZUMIGHzzXaexJ7SaDyUPImk-Pudgl8GjvZ9-xjrygRCrlK3yTEd8V3GkhptcxGH6X_bCYABDSNwFXcL_QFQK3TILDlO0qTxRdkOJbcW_XN2003fNHyzG63xDRqH5EdSitPAlTT1RsHLHMZnY9Wfsgj0hPbuQIDTwIfdhbbVsAHkFQ5OJDM_gxbfkSA
2021-09-11 07:08:34 ERROR (MainThread) [homeassistant] Error doing job: Future exception was never retrieved
Traceback (most recent call last):
  File "/usr/local/lib/python3.9/concurrent/futures/thread.py", line 52, in run
    result = self.fn(*self.args, **self.kwargs)
TypeError: update() takes 1 positional argument but 2 were given
2021-09-11 07:09:42 ERROR (stream_worker) [libav.rtsp] method DESCRIBE failed: 404 Not Found
2021-09-11 07:09:42 ERROR (stream_worker) [homeassistant.components.stream.worker] Error opening stream rtsps://stream-uc2-delta.dropcam.com:443/sdm_live_stream/CiQA2vuxrzkcUOGJE2JDLFJAnQLTlN1AC4hVvPiSkveUMQSHylwScQAFjsOTmmq3cK5qwz7nYlT8j2qyNbpmk91SnJlCdgLAgg-QP-aB43FR_5SJI12xHa_Cerp9CJ-Y0pajjqAsuQD8O1SY0Gy4QX0sP7dIvV2wap12AicA3R8Ke47gYl6M8CVTeWQNWInJgnUyGKRzltux?auth=g.0.eyJraWQiOiIyMzhiNTUxZmMyM2EyM2Y4M2E2ZTE3MmJjZTg0YmU3ZjgxMzAzMmM4IiwiYWxnIjoiUlMyNTYifQ.eyJpc3MiOiJuZXN0LXNlY3VyaXR5LWF1dGhwcm94eSIsInN1YiI6Im5lc3RfaWQ6bmVzdC1waG9lbml4LXByb2Q6MjEyMTgxNDEiLCJwb2wiOiIzcC1vYXV0aC1zY29wZS1BUElfU0RNX1NFUlZJQ0UtY2xpZW50LTIwMjQyNzMxODczNS1qNXQ5bWMyMzZqaG85YXMycWY0dTZxY3NmYW1kaGJ0ci5hcHBzLmdvb2dsZXVzZXJjb250ZW50LmNvbSIsImV4cCI6MTYzMTM2OTYwMH0.KwCLDSDWc9uY-g7Q4vvmPIKuoiWLSCizHInk9xJBoyeysCbdawzkIGVrS0nIes3s7O92EduVejEJjHvMrYq9smJiS0LM5ocBW4xH5T3jnu8UAAKwYCyuSn16iXQnqXrSKRjkGbyEK1Ut16LpD0hGhYI74HgUzyAd-8z4ZTTJTxaY4jeGqM3HNmytttASf6GldoScJSlii8-TFffqRWNHcdONHVTR9IMnmFkINK_Sp-ykifN1NBEMvWedHm8kylO2nR3u6m-HhHRCAr2o2KM8cTTCPvrqCiJa2CQSFtb3xeX-l1FaOpN6EZKtWsEUK5Hfk8_Baps3vLmpB8gwqokCjw
2021-09-11 07:13:35 ERROR (MainThread) [homeassistant] Error doing job: Future exception was never retrieved
Traceback (most recent call last):
  File "/usr/local/lib/python3.9/concurrent/futures/thread.py", line 52, in run
    result = self.fn(*self.args, **self.kwargs)
TypeError: update() takes 1 positional argument but 2 were given
2021-09-11 07:18:36 ERROR (MainThread) [homeassistant] Error doing job: Future exception was never retrieved
Traceback (most recent call last):
  File "/usr/local/lib/python3.9/concurrent/futures/thread.py", line 52, in run
    result = self.fn(*self.args, **self.kwargs)
TypeError: update() takes 1 positional argument but 2 were given
2021-09-11 07:18:52 ERROR (stream_worker) [libav.rtsp] method DESCRIBE failed: 404 Not Found
2021-09-11 07:18:52 ERROR (stream_worker) [homeassistant.components.stream.worker] Error opening stream rtsps://stream-uc2-delta.dropcam.com:443/sdm_live_stream/CiQA2vuxrzkcUOGJE2JDLFJAnQLTlN1AC4hVvPiSkveUMQSHylwScQAFjsOTmmq3cK5qwz7nYlT8j2qyNbpmk91SnJlCdgLAgg-QP-aB43FR_5SJI12xHa_Cerp9CJ-Y0pajjqAsuQD8O1SY0Gy4QX0sP7dIvV2wap12AicA3R8Ke47gYl6M8CVTeWQNWInJgnUyGKRzltux?auth=g.0.eyJraWQiOiIyMzhiNTUxZmMyM2EyM2Y4M2E2ZTE3MmJjZTg0YmU3ZjgxMzAzMmM4IiwiYWxnIjoiUlMyNTYifQ.eyJpc3MiOiJuZXN0LXNlY3VyaXR5LWF1dGhwcm94eSIsInN1YiI6Im5lc3RfaWQ6bmVzdC1waG9lbml4LXByb2Q6MjEyMTgxNDEiLCJwb2wiOiIzcC1vYXV0aC1zY29wZS1BUElfU0RNX1NFUlZJQ0UtY2xpZW50LTIwMjQyNzMxODczNS1qNXQ5bWMyMzZqaG85YXMycWY0dTZxY3NmYW1kaGJ0ci5hcHBzLmdvb2dsZXVzZXJjb250ZW50LmNvbSIsImV4cCI6MTYzMTM3MDE0MX0.sXNxWhLtwews1bl21V1jM_ToLl-h5TSEvOD_VxBMwdlJAV7uwMALtgFrrKbWFeLQlZi7AhSelnsKLpNo-YP9qncHoB6pwDN1STKEf3091c1bpfBcNnRdz5nQ8maPIhwvFb6LTICm36yqWVNI-I_A4NZmCpfnXmOe4udn7NrZtYeG505JntUdIfUiBgibzfn5NDMGr2oGnCkKWU-VhJgx2vgoFSRRlspB5wwd7pzVCI9FHTkqzb_R-3YUZ35AJAKgrIE-TX6J4AjI5K5IuRaoFjjerL3APkSr6Nih5sEkISpxH--7BXtkKpMx8Q6Mh_lble9QdVTqoumPy_B6B00NeQ
2021-09-11 07:20:33 ERROR (stream_worker) [libav.rtsp] method DESCRIBE failed: 404 Not Found
2021-09-11 07:20:33 ERROR (stream_worker) [homeassistant.components.stream.worker] Error opening stream rtsps://stream-uc2-delta.dropcam.com:443/sdm_live_stream/CiQA2vuxrzkcUOGJE2JDLFJAnQLTlN1AC4hVvPiSkveUMQSHylwScQAFjsOTmmq3cK5qwz7nYlT8j2qyNbpmk91SnJlCdgLAgg-QP-aB43FR_5SJI12xHa_Cerp9CJ-Y0pajjqAsuQD8O1SY0Gy4QX0sP7dIvV2wap12AicA3R8Ke47gYl6M8CVTeWQNWInJgnUyGKRzltux?auth=g.0.eyJraWQiOiIyMzhiNTUxZmMyM2EyM2Y4M2E2ZTE3MmJjZTg0YmU3ZjgxMzAzMmM4IiwiYWxnIjoiUlMyNTYifQ.eyJpc3MiOiJuZXN0LXNlY3VyaXR5LWF1dGhwcm94eSIsInN1YiI6Im5lc3RfaWQ6bmVzdC1waG9lbml4LXByb2Q6MjEyMTgxNDEiLCJwb2wiOiIzcC1vYXV0aC1zY29wZS1BUElfU0RNX1NFUlZJQ0UtY2xpZW50LTIwMjQyNzMxODczNS1qNXQ5bWMyMzZqaG85YXMycWY0dTZxY3NmYW1kaGJ0ci5hcHBzLmdvb2dsZXVzZXJjb250ZW50LmNvbSIsImV4cCI6MTYzMTM3MDE0MX0.sXNxWhLtwews1bl21V1jM_ToLl-h5TSEvOD_VxBMwdlJAV7uwMALtgFrrKbWFeLQlZi7AhSelnsKLpNo-YP9qncHoB6pwDN1STKEf3091c1bpfBcNnRdz5nQ8maPIhwvFb6LTICm36yqWVNI-I_A4NZmCpfnXmOe4udn7NrZtYeG505JntUdIfUiBgibzfn5NDMGr2oGnCkKWU-VhJgx2vgoFSRRlspB5wwd7pzVCI9FHTkqzb_R-3YUZ35AJAKgrIE-TX6J4AjI5K5IuRaoFjjerL3APkSr6Nih5sEkISpxH--7BXtkKpMx8Q6Mh_lble9QdVTqoumPy_B6B00NeQ
2021-09-11 07:23:37 ERROR (MainThread) [homeassistant] Error doing job: Future exception was never retrieved
Traceback (most recent call last):
  File "/usr/local/lib/python3.9/concurrent/futures/thread.py", line 52, in run
    result = self.fn(*self.args, **self.kwargs)
TypeError: update() takes 1 positional argument but 2 were given
2021-09-11 07:28:38 ERROR (MainThread) [homeassistant] Error doing job: Future exception was never retrieved
Traceback (most recent call last):
  File "/usr/local/lib/python3.9/concurrent/futures/thread.py", line 52, in run
    result = self.fn(*self.args, **self.kwargs)
TypeError: update() takes 1 positional argument but 2 were given
2021-09-11 07:33:39 ERROR (MainThread) [homeassistant] Error doing job: Future exception was never retrieved
Traceback (most recent call last):
  File "/usr/local/lib/python3.9/concurrent/futures/thread.py", line 52, in run
    result = self.fn(*self.args, **self.kwargs)
TypeError: update() takes 1 positional argument but 2 were given
2021-09-11 07:38:40 ERROR (MainThread) [homeassistant] Error doing job: Future exception was never retrieved
Traceback (most recent call last):
  File "/usr/local/lib/python3.9/concurrent/futures/thread.py", line 52, in run
    result = self.fn(*self.args, **self.kwargs)
TypeError: update() takes 1 positional argument but 2 were given
2021-09-11 07:40:45 ERROR (MainThread) [iotawattpy.connection] Err: 
2021-09-11 07:40:45 ERROR (MainThread) [homeassistant.components.iotawatt.coordinator] Unexpected error fetching 192.168.20.195 data: 'NoneType' object has no attribute 'text'
Traceback (most recent call last):
  File "/usr/src/homeassistant/homeassistant/helpers/update_coordinator.py", line 187, in _async_refresh
    self.data = await self._async_update_data()
  File "/usr/src/homeassistant/homeassistant/components/iotawatt/coordinator.py", line 55, in _async_update_data
    await self.api.update()
  File "/usr/local/lib/python3.9/site-packages/iotawattpy/iotawatt.py", line 66, in update
    await self._refreshSensors(timespan)
  File "/usr/local/lib/python3.9/site-packages/iotawattpy/iotawatt.py", line 100, in _refreshSensors
    results = response.text
AttributeError: 'NoneType' object has no attribute 'text'
2021-09-11 07:43:41 ERROR (MainThread) [homeassistant] Error doing job: Future exception was never retrieved
Traceback (most recent call last):
  File "/usr/local/lib/python3.9/concurrent/futures/thread.py", line 52, in run
    result = self.fn(*self.args, **self.kwargs)
TypeError: update() takes 1 positional argument but 2 were given
2021-09-11 07:48:35 WARNING (MainThread) [bellows.zigbee.application] Watchdog heartbeat timeout: 
2021-09-11 07:48:42 ERROR (MainThread) [homeassistant] Error doing job: Future exception was never retrieved
Traceback (most recent call last):
  File "/usr/local/lib/python3.9/concurrent/futures/thread.py", line 52, in run
    result = self.fn(*self.args, **self.kwargs)
TypeError: update() takes 1 positional argument but 2 were given
2021-09-11 07:53:43 ERROR (MainThread) [homeassistant] Error doing job: Future exception was never retrieved
Traceback (most recent call last):
  File "/usr/local/lib/python3.9/concurrent/futures/thread.py", line 52, in run
    result = self.fn(*self.args, **self.kwargs)
TypeError: update() takes 1 positional argument but 2 were given
2021-09-11 07:58:44 ERROR (MainThread) [homeassistant] Error doing job: Future exception was never retrieved
Traceback (most recent call last):
  File "/usr/local/lib/python3.9/concurrent/futures/thread.py", line 52, in run
    result = self.fn(*self.args, **self.kwargs)
TypeError: update() takes 1 positional argument but 2 were given
2021-09-11 08:03:45 ERROR (MainThread) [homeassistant] Error doing job: Future exception was never retrieved
Traceback (most recent call last):
  File "/usr/local/lib/python3.9/concurrent/futures/thread.py", line 52, in run
    result = self.fn(*self.args, **self.kwargs)
TypeError: update() takes 1 positional argument but 2 were given
2021-09-11 08:08:46 ERROR (MainThread) [homeassistant] Error doing job: Future exception was never retrieved
Traceback (most recent call last):
  File "/usr/local/lib/python3.9/concurrent/futures/thread.py", line 52, in run
    result = self.fn(*self.args, **self.kwargs)
TypeError: update() takes 1 positional argument but 2 were given
2021-09-11 08:10:53 ERROR (MainThread) [iotawattpy.connection] Err: 
2021-09-11 08:10:53 ERROR (MainThread) [homeassistant.components.iotawatt.coordinator] Unexpected error fetching 192.168.20.195 data: 'NoneType' object has no attribute 'text'
Traceback (most recent call last):
  File "/usr/src/homeassistant/homeassistant/helpers/update_coordinator.py", line 187, in _async_refresh
    self.data = await self._async_update_data()
  File "/usr/src/homeassistant/homeassistant/components/iotawatt/coordinator.py", line 55, in _async_update_data
    await self.api.update()
  File "/usr/local/lib/python3.9/site-packages/iotawattpy/iotawatt.py", line 66, in update
    await self._refreshSensors(timespan)
  File "/usr/local/lib/python3.9/site-packages/iotawattpy/iotawatt.py", line 107, in _refreshSensors
    query = query.text
AttributeError: 'NoneType' object has no attribute 'text'
2021-09-11 08:12:49 ERROR (stream_worker) [libav.rtsp] method DESCRIBE failed: 404 Not Found
2021-09-11 08:12:49 ERROR (stream_worker) [homeassistant.components.stream.worker] Error opening stream rtsps://stream-uc2-bravo.dropcam.com:443/sdm_live_stream/CiQA2vuxr27_sLMvoT3EEnvrU1pnbO1VaGHfkZ-X46xM_qZuuR0ScQAFjsOTT9-1IyTNchrOtDlFoQma0mll5EFJzjpM75_OlO7v5_W9P9Q8tHgk3YW7T8y0rPqrUvFPBV1YJmUUYtFShzz5DQbd7BJ0xQnC04XNfTsSkwJdkxmXYSprYOhYmoPEJh6Wz5jWZQ8Msql5JIBC?auth=g.0.eyJraWQiOiIyMzhiNTUxZmMyM2EyM2Y4M2E2ZTE3MmJjZTg0YmU3ZjgxMzAzMmM4IiwiYWxnIjoiUlMyNTYifQ.eyJpc3MiOiJuZXN0LXNlY3VyaXR5LWF1dGhwcm94eSIsInN1YiI6Im5lc3RfaWQ6bmVzdC1waG9lbml4LXByb2Q6MjEyMTgxNDEiLCJwb2wiOiIzcC1vYXV0aC1zY29wZS1BUElfU0RNX1NFUlZJQ0UtY2xpZW50LTIwMjQyNzMxODczNS1qNXQ5bWMyMzZqaG85YXMycWY0dTZxY3NmYW1kaGJ0ci5hcHBzLmdvb2dsZXVzZXJjb250ZW50LmNvbSIsImV4cCI6MTYzMTM3MzM4OH0.sI8-MYnZe6fglqAyA-bWZQfUh_YXpRqjpvldvUX1i6HeqTqbejp91L5hZPombAk8ExzbH-c_h-M4nS_4sBJoDY0SXL7x1nQWDNNWX4AbcMpaWxVbbzJ6UYjovD-M54FuZw5qh_CotdrIS66fTgNGMKgdlP7P5QjpowzUwUQ5uWNkM697IS5N61aDDin8IFBaSy5aNzkWDLSrTUtQtZ6wXVksXki_78Yyq4_975-Y6wUY3LcmSmSow0EA-fFcgHMHXzjEd9dxRnOf7iQtRY-Y7a0IHPgmZNFNzxWq6DOGONgbtwWu2mIC9NxSvimQmCF3AJkaz0CH1TVyxxebB7vCGw
2021-09-11 08:13:47 ERROR (MainThread) [homeassistant] Error doing job: Future exception was never retrieved
Traceback (most recent call last):
  File "/usr/local/lib/python3.9/concurrent/futures/thread.py", line 52, in run
    result = self.fn(*self.args, **self.kwargs)
TypeError: update() takes 1 positional argument but 2 were given
2021-09-11 08:18:48 ERROR (MainThread) [homeassistant] Error doing job: Future exception was never retrieved
Traceback (most recent call last):
  File "/usr/local/lib/python3.9/concurrent/futures/thread.py", line 52, in run
    result = self.fn(*self.args, **self.kwargs)
TypeError: update() takes 1 positional argument but 2 were given
2021-09-11 08:22:00 ERROR (stream_worker) [libav.rtsp] method DESCRIBE failed: 404 Not Found
2021-09-11 08:22:00 ERROR (stream_worker) [homeassistant.components.stream.worker] Error opening stream rtsps://stream-uc2-bravo.dropcam.com:443/sdm_live_stream/CiQA2vuxr27_sLMvoT3EEnvrU1pnbO1VaGHfkZ-X46xM_qZuuR0ScQAFjsOTT9-1IyTNchrOtDlFoQma0mll5EFJzjpM75_OlO7v5_W9P9Q8tHgk3YW7T8y0rPqrUvFPBV1YJmUUYtFShzz5DQbd7BJ0xQnC04XNfTsSkwJdkxmXYSprYOhYmoPEJh6Wz5jWZQ8Msql5JIBC?auth=g.0.eyJraWQiOiIyMzhiNTUxZmMyM2EyM2Y4M2E2ZTE3MmJjZTg0YmU3ZjgxMzAzMmM4IiwiYWxnIjoiUlMyNTYifQ.eyJpc3MiOiJuZXN0LXNlY3VyaXR5LWF1dGhwcm94eSIsInN1YiI6Im5lc3RfaWQ6bmVzdC1waG9lbml4LXByb2Q6MjEyMTgxNDEiLCJwb2wiOiIzcC1vYXV0aC1zY29wZS1BUElfU0RNX1NFUlZJQ0UtY2xpZW50LTIwMjQyNzMxODczNS1qNXQ5bWMyMzZqaG85YXMycWY0dTZxY3NmYW1kaGJ0ci5hcHBzLmdvb2dsZXVzZXJjb250ZW50LmNvbSIsImV4cCI6MTYzMTM3MzkyOH0.pv1dmgzv1p0O59LAhROietCX8F7nrYbsuaEMFc5n6vqge0cskLA34zPfFQp4Nbj7ImhXFtXew7dtmFWwdNkqKSRnSbYIeOmCtjmyIBzHKYltEF-qKHHjy8KtqAdAlhpfjuKP0YClKlo92wZXmxNezxOLH0m-10WwKAHG1nwOziRKivzAOu94BHxL4dn0Ts7XbIdlipz2c5XhVv3epKCRjBUzhF_BPYxTz4xFQn7Iizo8aJOhuNyzByQOIK5odFnUPAVPUGnr0QOsW81oNbopuZkdYtcuOWfYEMisVSUkL24tN3F49vXdvudOZolSESEq3L4fWW2DZ58CS3c_c9EOLQ
2021-09-11 08:23:49 ERROR (MainThread) [homeassistant] Error doing job: Future exception was never retrieved
Traceback (most recent call last):
  File "/usr/local/lib/python3.9/concurrent/futures/thread.py", line 52, in run
    result = self.fn(*self.args, **self.kwargs)
TypeError: update() takes 1 positional argument but 2 were given
2021-09-11 08:26:41 ERROR (stream_worker) [libav.rtsp] method DESCRIBE failed: 404 Not Found
2021-09-11 08:26:41 ERROR (stream_worker) [homeassistant.components.stream.worker] Error opening stream rtsps://stream-uc2-bravo.dropcam.com:443/sdm_live_stream/CiQA2vuxr27_sLMvoT3EEnvrU1pnbO1VaGHfkZ-X46xM_qZuuR0ScQAFjsOTT9-1IyTNchrOtDlFoQma0mll5EFJzjpM75_OlO7v5_W9P9Q8tHgk3YW7T8y0rPqrUvFPBV1YJmUUYtFShzz5DQbd7BJ0xQnC04XNfTsSkwJdkxmXYSprYOhYmoPEJh6Wz5jWZQ8Msql5JIBC?auth=g.0.eyJraWQiOiIyMzhiNTUxZmMyM2EyM2Y4M2E2ZTE3MmJjZTg0YmU3ZjgxMzAzMmM4IiwiYWxnIjoiUlMyNTYifQ.eyJpc3MiOiJuZXN0LXNlY3VyaXR5LWF1dGhwcm94eSIsInN1YiI6Im5lc3RfaWQ6bmVzdC1waG9lbml4LXByb2Q6MjEyMTgxNDEiLCJwb2wiOiIzcC1vYXV0aC1zY29wZS1BUElfU0RNX1NFUlZJQ0UtY2xpZW50LTIwMjQyNzMxODczNS1qNXQ5bWMyMzZqaG85YXMycWY0dTZxY3NmYW1kaGJ0ci5hcHBzLmdvb2dsZXVzZXJjb250ZW50LmNvbSIsImV4cCI6MTYzMTM3NDE5OX0.YTJa9n49nMXCTwsCJ7ds9L3zqOBNwkV2IYgrS22JIgkPzqEHQR6SmFic6N95Y5lH_O_UhPjOcDOqwPHHURBy9WBZtXCAYUykxBEdVelL0ADhxAepet1yzi2LBiyHmiEIQQ8r7LeRfl9Rki_PUYOrLn9zp2iDr5j1Z8Xrb2GEcRSP-lKh9aXZic9cK5_yokLC7viYELe73Xx83oz8MdstXM6cV2xHDPaxrBPi94oRM_zGbybh1ntn6XmMlpPara7Iv6VGZ0qnT6_qI9MWOHlvqPjvOwCrZGdXuWiQv91pJZclX9hoqnCumChmUBEhUPnnSerwNf0AI4cIP6ZDDCMwiw
2021-09-11 08:28:50 ERROR (MainThread) [homeassistant] Error doing job: Future exception was never retrieved
Traceback (most recent call last):
  File "/usr/local/lib/python3.9/concurrent/futures/thread.py", line 52, in run
    result = self.fn(*self.args, **self.kwargs)
TypeError: update() takes 1 positional argument but 2 were given
2021-09-11 08:31:24 ERROR (stream_worker) [libav.rtsp] method DESCRIBE failed: 404 Not Found
2021-09-11 08:31:24 ERROR (stream_worker) [homeassistant.components.stream.worker] Error opening stream rtsps://stream-uc2-bravo.dropcam.com:443/sdm_live_stream/CiQA2vuxr27_sLMvoT3EEnvrU1pnbO1VaGHfkZ-X46xM_qZuuR0ScQAFjsOTT9-1IyTNchrOtDlFoQma0mll5EFJzjpM75_OlO7v5_W9P9Q8tHgk3YW7T8y0rPqrUvFPBV1YJmUUYtFShzz5DQbd7BJ0xQnC04XNfTsSkwJdkxmXYSprYOhYmoPEJh6Wz5jWZQ8Msql5JIBC?auth=g.0.eyJraWQiOiIyMzhiNTUxZmMyM2EyM2Y4M2E2ZTE3MmJjZTg0YmU3ZjgxMzAzMmM4IiwiYWxnIjoiUlMyNTYifQ.eyJpc3MiOiJuZXN0LXNlY3VyaXR5LWF1dGhwcm94eSIsInN1YiI6Im5lc3RfaWQ6bmVzdC1waG9lbml4LXByb2Q6MjEyMTgxNDEiLCJwb2wiOiIzcC1vYXV0aC1zY29wZS1BUElfU0RNX1NFUlZJQ0UtY2xpZW50LTIwMjQyNzMxODczNS1qNXQ5bWMyMzZqaG85YXMycWY0dTZxY3NmYW1kaGJ0ci5hcHBzLmdvb2dsZXVzZXJjb250ZW50LmNvbSIsImV4cCI6MTYzMTM3NDQ3MH0.m5IzM16FhDVpnRmPWYoyYv6i5owCI_quh4lheKjz_u6ZtmNnPDNklYqrhpbxPE1Ns7Y79tUnT9xQNgZkVvTZwCfI-m45MjuFHcDCap-9Asnwidf0O1gncIvx7vNykXOt5OoDcspPfzXLJwp51jom-uGtpG2LEgpohVAIgXyid9SojCdOZx1nP0beDBBBFepN2mWf5Kcbnhmgrl17i3PObc7IX3ymhzSqFFng2OTqlb9zZpcxt7lQKJEABOjMXx7ybg1LHpb5yee--IPx9XwKoszM-S4bk5CEWGWvMzBsQ-yb4SrnEmWPPNzQe-LYo6wwJf7EwjesT3NpsRPFi-BSwQ
2021-09-11 08:33:44 ERROR (stream_worker) [homeassistant.components.stream.worker] Error opening stream rtsps://stream-uc2-bravo.dropcam.com:443/sdm_live_stream/CiQA2vuxr27_sLMvoT3EEnvrU1pnbO1VaGHfkZ-X46xM_qZuuR0ScQAFjsOTT9-1IyTNchrOtDlFoQma0mll5EFJzjpM75_OlO7v5_W9P9Q8tHgk3YW7T8y0rPqrUvFPBV1YJmUUYtFShzz5DQbd7BJ0xQnC04XNfTsSkwJdkxmXYSprYOhYmoPEJh6Wz5jWZQ8Msql5JIBC?auth=g.0.eyJraWQiOiIyMzhiNTUxZmMyM2EyM2Y4M2E2ZTE3MmJjZTg0YmU3ZjgxMzAzMmM4IiwiYWxnIjoiUlMyNTYifQ.eyJpc3MiOiJuZXN0LXNlY3VyaXR5LWF1dGhwcm94eSIsInN1YiI6Im5lc3RfaWQ6bmVzdC1waG9lbml4LXByb2Q6MjEyMTgxNDEiLCJwb2wiOiIzcC1vYXV0aC1zY29wZS1BUElfU0RNX1NFUlZJQ0UtY2xpZW50LTIwMjQyNzMxODczNS1qNXQ5bWMyMzZqaG85YXMycWY0dTZxY3NmYW1kaGJ0ci5hcHBzLmdvb2dsZXVzZXJjb250ZW50LmNvbSIsImV4cCI6MTYzMTM3NDQ3MH0.m5IzM16FhDVpnRmPWYoyYv6i5owCI_quh4lheKjz_u6ZtmNnPDNklYqrhpbxPE1Ns7Y79tUnT9xQNgZkVvTZwCfI-m45MjuFHcDCap-9Asnwidf0O1gncIvx7vNykXOt5OoDcspPfzXLJwp51jom-uGtpG2LEgpohVAIgXyid9SojCdOZx1nP0beDBBBFepN2mWf5Kcbnhmgrl17i3PObc7IX3ymhzSqFFng2OTqlb9zZpcxt7lQKJEABOjMXx7ybg1LHpb5yee--IPx9XwKoszM-S4bk5CEWGWvMzBsQ-yb4SrnEmWPPNzQe-LYo6wwJf7EwjesT3NpsRPFi-BSwQ
2021-09-11 08:33:51 ERROR (MainThread) [homeassistant] Error doing job: Future exception was never retrieved
Traceback (most recent call last):
  File "/usr/local/lib/python3.9/concurrent/futures/thread.py", line 52, in run
    result = self.fn(*self.args, **self.kwargs)
TypeError: update() takes 1 positional argument but 2 were given
2021-09-11 08:38:52 ERROR (MainThread) [homeassistant] Error doing job: Future exception was never retrieved
Traceback (most recent call last):
  File "/usr/local/lib/python3.9/concurrent/futures/thread.py", line 52, in run
    result = self.fn(*self.args, **self.kwargs)
TypeError: update() takes 1 positional argument but 2 were given
2021-09-11 08:43:53 ERROR (MainThread) [homeassistant] Error doing job: Future exception was never retrieved
Traceback (most recent call last):
  File "/usr/local/lib/python3.9/concurrent/futures/thread.py", line 52, in run
    result = self.fn(*self.args, **self.kwargs)
TypeError: update() takes 1 positional argument but 2 were given
2021-09-11 08:44:08 ERROR (MainThread) [homeassistant.components.nws] Error requesting NWS observation station SAUC1 data: 503, message='Service Unavailable', url=URL('https://api.weather.gov/stations/SAUC1/observations')
2021-09-11 08:48:54 ERROR (MainThread) [homeassistant] Error doing job: Future exception was never retrieved
Traceback (most recent call last):
  File "/usr/local/lib/python3.9/concurrent/futures/thread.py", line 52, in run
    result = self.fn(*self.args, **self.kwargs)
TypeError: update() takes 1 positional argument but 2 were given
2021-09-11 08:53:55 ERROR (MainThread) [homeassistant] Error doing job: Future exception was never retrieved
Traceback (most recent call last):
  File "/usr/local/lib/python3.9/concurrent/futures/thread.py", line 52, in run
    result = self.fn(*self.args, **self.kwargs)
TypeError: update() takes 1 positional argument but 2 were given
2021-09-11 08:58:56 ERROR (MainThread) [homeassistant] Error doing job: Future exception was never retrieved
Traceback (most recent call last):
  File "/usr/local/lib/python3.9/concurrent/futures/thread.py", line 52, in run
    result = self.fn(*self.args, **self.kwargs)
TypeError: update() takes 1 positional argument but 2 were given
2021-09-11 09:03:57 ERROR (MainThread) [homeassistant] Error doing job: Future exception was never retrieved
Traceback (most recent call last):
  File "/usr/local/lib/python3.9/concurrent/futures/thread.py", line 52, in run
    result = self.fn(*self.args, **self.kwargs)
TypeError: update() takes 1 positional argument but 2 were given
2021-09-11 09:05:18 ERROR (MainThread) [homeassistant.components.nws] Error requesting NWS observation station SAUC1 data: 503, message='Service Unavailable', url=URL('https://api.weather.gov/stations/SAUC1/observations')
2021-09-11 09:08:58 ERROR (MainThread) [homeassistant] Error doing job: Future exception was never retrieved
Traceback (most recent call last):
  File "/usr/local/lib/python3.9/concurrent/futures/thread.py", line 52, in run
    result = self.fn(*self.args, **self.kwargs)
TypeError: update() takes 1 positional argument but 2 were given
2021-09-11 09:13:59 ERROR (MainThread) [homeassistant] Error doing job: Future exception was never retrieved
Traceback (most recent call last):
  File "/usr/local/lib/python3.9/concurrent/futures/thread.py", line 52, in run
    result = self.fn(*self.args, **self.kwargs)
TypeError: update() takes 1 positional argument but 2 were given
2021-09-11 09:19:00 ERROR (MainThread) [homeassistant] Error doing job: Future exception was never retrieved
Traceback (most recent call last):
  File "/usr/local/lib/python3.9/concurrent/futures/thread.py", line 52, in run
    result = self.fn(*self.args, **self.kwargs)
TypeError: update() takes 1 positional argument but 2 were given
2021-09-11 09:24:01 ERROR (MainThread) [homeassistant] Error doing job: Future exception was never retrieved
Traceback (most recent call last):
  File "/usr/local/lib/python3.9/concurrent/futures/thread.py", line 52, in run
    result = self.fn(*self.args, **self.kwargs)
TypeError: update() takes 1 positional argument but 2 were given
2021-09-11 09:27:38 ERROR (MainThread) [homeassistant.components.nws] Error requesting NWS observation station SAUC1 data: 503, message='Service Unavailable', url=URL('https://api.weather.gov/stations/SAUC1/observations')
2021-09-11 09:29:02 ERROR (MainThread) [homeassistant] Error doing job: Future exception was never retrieved
Traceback (most recent call last):
  File "/usr/local/lib/python3.9/concurrent/futures/thread.py", line 52, in run
    result = self.fn(*self.args, **self.kwargs)
TypeError: update() takes 1 positional argument but 2 were given
2021-09-11 09:34:03 ERROR (MainThread) [homeassistant] Error doing job: Future exception was never retrieved
Traceback (most recent call last):
  File "/usr/local/lib/python3.9/concurrent/futures/thread.py", line 52, in run
    result = self.fn(*self.args, **self.kwargs)
TypeError: update() takes 1 positional argument but 2 were given
2021-09-11 09:39:04 ERROR (MainThread) [homeassistant] Error doing job: Future exception was never retrieved
Traceback (most recent call last):
  File "/usr/local/lib/python3.9/concurrent/futures/thread.py", line 52, in run
    result = self.fn(*self.args, **self.kwargs)
TypeError: update() takes 1 positional argument but 2 were given
2021-09-11 09:44:05 ERROR (MainThread) [homeassistant] Error doing job: Future exception was never retrieved
Traceback (most recent call last):
  File "/usr/local/lib/python3.9/concurrent/futures/thread.py", line 52, in run
    result = self.fn(*self.args, **self.kwargs)
TypeError: update() takes 1 positional argument but 2 were given
2021-09-11 09:49:06 ERROR (MainThread) [homeassistant] Error doing job: Future exception was never retrieved
Traceback (most recent call last):
  File "/usr/local/lib/python3.9/concurrent/futures/thread.py", line 52, in run
    result = self.fn(*self.args, **self.kwargs)
TypeError: update() takes 1 positional argument but 2 were given
2021-09-11 09:54:07 ERROR (MainThread) [homeassistant] Error doing job: Future exception was never retrieved
Traceback (most recent call last):
  File "/usr/local/lib/python3.9/concurrent/futures/thread.py", line 52, in run
    result = self.fn(*self.args, **self.kwargs)
TypeError: update() takes 1 positional argument but 2 were given
2021-09-11 09:59:08 ERROR (MainThread) [homeassistant] Error doing job: Future exception was never retrieved
Traceback (most recent call last):
  File "/usr/local/lib/python3.9/concurrent/futures/thread.py", line 52, in run
    result = self.fn(*self.args, **self.kwargs)
TypeError: update() takes 1 positional argument but 2 were given
2021-09-11 10:04:09 ERROR (MainThread) [homeassistant] Error doing job: Future exception was never retrieved
Traceback (most recent call last):
  File "/usr/local/lib/python3.9/concurrent/futures/thread.py", line 52, in run
    result = self.fn(*self.args, **self.kwargs)
TypeError: update() takes 1 positional argument but 2 were given
2021-09-11 10:09:10 ERROR (MainThread) [homeassistant] Error doing job: Future exception was never retrieved
Traceback (most recent call last):
  File "/usr/local/lib/python3.9/concurrent/futures/thread.py", line 52, in run
    result = self.fn(*self.args, **self.kwargs)
TypeError: update() takes 1 positional argument but 2 were given
2021-09-11 10:09:12 ERROR (MainThread) [homeassistant.components.nws] Error requesting NWS observation station SAUC1 data: 503, message='Service Unavailable', url=URL('https://api.weather.gov/stations/SAUC1/observations')
2021-09-11 10:14:11 ERROR (MainThread) [homeassistant] Error doing job: Future exception was never retrieved
Traceback (most recent call last):
  File "/usr/local/lib/python3.9/concurrent/futures/thread.py", line 52, in run
    result = self.fn(*self.args, **self.kwargs)
TypeError: update() takes 1 positional argument but 2 were given
2021-09-11 10:19:12 ERROR (MainThread) [homeassistant] Error doing job: Future exception was never retrieved
Traceback (most recent call last):
  File "/usr/local/lib/python3.9/concurrent/futures/thread.py", line 52, in run
    result = self.fn(*self.args, **self.kwargs)
TypeError: update() takes 1 positional argument but 2 were given
2021-09-11 10:24:13 ERROR (MainThread) [homeassistant] Error doing job: Future exception was never retrieved
Traceback (most recent call last):
  File "/usr/local/lib/python3.9/concurrent/futures/thread.py", line 52, in run
    result = self.fn(*self.args, **self.kwargs)
TypeError: update() takes 1 positional argument but 2 were given
2021-09-11 10:29:14 ERROR (MainThread) [homeassistant] Error doing job: Future exception was never retrieved
Traceback (most recent call last):
  File "/usr/local/lib/python3.9/concurrent/futures/thread.py", line 52, in run
    result = self.fn(*self.args, **self.kwargs)
TypeError: update() takes 1 positional argument but 2 were given
2021-09-11 10:34:15 ERROR (MainThread) [homeassistant] Error doing job: Future exception was never retrieved
Traceback (most recent call last):
  File "/usr/local/lib/python3.9/concurrent/futures/thread.py", line 52, in run
    result = self.fn(*self.args, **self.kwargs)
TypeError: update() takes 1 positional argument but 2 were given
2021-09-11 10:39:16 ERROR (MainThread) [homeassistant] Error doing job: Future exception was never retrieved
Traceback (most recent call last):
  File "/usr/local/lib/python3.9/concurrent/futures/thread.py", line 52, in run
    result = self.fn(*self.args, **self.kwargs)
TypeError: update() takes 1 positional argument but 2 were given
2021-09-11 10:44:17 ERROR (MainThread) [homeassistant] Error doing job: Future exception was never retrieved
Traceback (most recent call last):
  File "/usr/local/lib/python3.9/concurrent/futures/thread.py", line 52, in run
    result = self.fn(*self.args, **self.kwargs)
TypeError: update() takes 1 positional argument but 2 were given
2021-09-11 10:49:18 ERROR (MainThread) [homeassistant] Error doing job: Future exception was never retrieved
Traceback (most recent call last):
  File "/usr/local/lib/python3.9/concurrent/futures/thread.py", line 52, in run
    result = self.fn(*self.args, **self.kwargs)
TypeError: update() takes 1 positional argument but 2 were given
2021-09-11 10:54:19 ERROR (MainThread) [homeassistant] Error doing job: Future exception was never retrieved
Traceback (most recent call last):
  File "/usr/local/lib/python3.9/concurrent/futures/thread.py", line 52, in run
    result = self.fn(*self.args, **self.kwargs)
TypeError: update() takes 1 positional argument but 2 were given
2021-09-11 10:59:20 ERROR (MainThread) [homeassistant] Error doing job: Future exception was never retrieved
Traceback (most recent call last):
  File "/usr/local/lib/python3.9/concurrent/futures/thread.py", line 52, in run
    result = self.fn(*self.args, **self.kwargs)
TypeError: update() takes 1 positional argument but 2 were given
2021-09-11 11:04:21 ERROR (MainThread) [homeassistant] Error doing job: Future exception was never retrieved
Traceback (most recent call last):
  File "/usr/local/lib/python3.9/concurrent/futures/thread.py", line 52, in run
    result = self.fn(*self.args, **self.kwargs)
TypeError: update() takes 1 positional argument but 2 were given
2021-09-11 11:09:22 ERROR (MainThread) [homeassistant] Error doing job: Future exception was never retrieved
Traceback (most recent call last):
  File "/usr/local/lib/python3.9/concurrent/futures/thread.py", line 52, in run
    result = self.fn(*self.args, **self.kwargs)
TypeError: update() takes 1 positional argument but 2 were given
2021-09-11 11:14:23 ERROR (MainThread) [homeassistant] Error doing job: Future exception was never retrieved
Traceback (most recent call last):
  File "/usr/local/lib/python3.9/concurrent/futures/thread.py", line 52, in run
    result = self.fn(*self.args, **self.kwargs)
TypeError: update() takes 1 positional argument but 2 were given
2021-09-11 11:19:24 ERROR (MainThread) [homeassistant] Error doing job: Future exception was never retrieved
Traceback (most recent call last):
  File "/usr/local/lib/python3.9/concurrent/futures/thread.py", line 52, in run
    result = self.fn(*self.args, **self.kwargs)
TypeError: update() takes 1 positional argument but 2 were given
2021-09-11 11:24:25 ERROR (MainThread) [homeassistant] Error doing job: Future exception was never retrieved
Traceback (most recent call last):
  File "/usr/local/lib/python3.9/concurrent/futures/thread.py", line 52, in run
    result = self.fn(*self.args, **self.kwargs)
TypeError: update() takes 1 positional argument but 2 were given
2021-09-11 11:29:26 ERROR (MainThread) [homeassistant] Error doing job: Future exception was never retrieved
Traceback (most recent call last):
  File "/usr/local/lib/python3.9/concurrent/futures/thread.py", line 52, in run
    result = self.fn(*self.args, **self.kwargs)
TypeError: update() takes 1 positional argument but 2 were given
2021-09-11 11:34:27 ERROR (MainThread) [homeassistant] Error doing job: Future exception was never retrieved
Traceback (most recent call last):
  File "/usr/local/lib/python3.9/concurrent/futures/thread.py", line 52, in run
    result = self.fn(*self.args, **self.kwargs)
TypeError: update() takes 1 positional argument but 2 were given
2021-09-11 11:39:28 ERROR (MainThread) [homeassistant] Error doing job: Future exception was never retrieved
Traceback (most recent call last):
  File "/usr/local/lib/python3.9/concurrent/futures/thread.py", line 52, in run
    result = self.fn(*self.args, **self.kwargs)
TypeError: update() takes 1 positional argument but 2 were given
2021-09-11 11:44:29 ERROR (MainThread) [homeassistant] Error doing job: Future exception was never retrieved
Traceback (most recent call last):
  File "/usr/local/lib/python3.9/concurrent/futures/thread.py", line 52, in run
    result = self.fn(*self.args, **self.kwargs)
TypeError: update() takes 1 positional argument but 2 were given
2021-09-11 11:49:30 ERROR (MainThread) [homeassistant] Error doing job: Future exception was never retrieved
Traceback (most recent call last):
  File "/usr/local/lib/python3.9/concurrent/futures/thread.py", line 52, in run
    result = self.fn(*self.args, **self.kwargs)
TypeError: update() takes 1 positional argument but 2 were given
2021-09-11 11:50:45 ERROR (MainThread) [homeassistant.components.nws] Error requesting NWS observation station SAUC1 data: 503, message='Service Unavailable', url=URL('https://api.weather.gov/stations/SAUC1/observations')
2021-09-11 11:54:31 ERROR (MainThread) [homeassistant] Error doing job: Future exception was never retrieved
Traceback (most recent call last):
  File "/usr/local/lib/python3.9/concurrent/futures/thread.py", line 52, in run
    result = self.fn(*self.args, **self.kwargs)
TypeError: update() takes 1 positional argument but 2 were given
2021-09-11 11:59:32 ERROR (MainThread) [homeassistant] Error doing job: Future exception was never retrieved
Traceback (most recent call last):
  File "/usr/local/lib/python3.9/concurrent/futures/thread.py", line 52, in run
    result = self.fn(*self.args, **self.kwargs)
TypeError: update() takes 1 positional argument but 2 were given
2021-09-11 12:01:58 ERROR (MainThread) [homeassistant.components.nws] Error requesting NWS observation station SAUC1 data: 503, message='Service Unavailable', url=URL('https://api.weather.gov/stations/SAUC1/observations')
2021-09-11 12:04:33 ERROR (MainThread) [homeassistant] Error doing job: Future exception was never retrieved
Traceback (most recent call last):
  File "/usr/local/lib/python3.9/concurrent/futures/thread.py", line 52, in run
    result = self.fn(*self.args, **self.kwargs)
TypeError: update() takes 1 positional argument but 2 were given
2021-09-11 12:09:34 ERROR (MainThread) [homeassistant] Error doing job: Future exception was never retrieved
Traceback (most recent call last):
  File "/usr/local/lib/python3.9/concurrent/futures/thread.py", line 52, in run
    result = self.fn(*self.args, **self.kwargs)
TypeError: update() takes 1 positional argument but 2 were given
2021-09-11 12:14:35 ERROR (MainThread) [homeassistant] Error doing job: Future exception was never retrieved
Traceback (most recent call last):
  File "/usr/local/lib/python3.9/concurrent/futures/thread.py", line 52, in run
    result = self.fn(*self.args, **self.kwargs)
TypeError: update() takes 1 positional argument but 2 were given
2021-09-11 12:19:36 ERROR (SyncWorker_1) [homeassistant] Error doing job: Future exception was never retrieved
Traceback (most recent call last):
  File "/usr/local/lib/python3.9/concurrent/futures/thread.py", line 52, in run
    result = self.fn(*self.args, **self.kwargs)
TypeError: update() takes 1 positional argument but 2 were given
2021-09-11 12:20:24 ERROR (MainThread) [homeassistant.components.nws] Error requesting NWS forecast station SAUC1 data: Cannot connect to host api.weather.gov:443 ssl:default [Network unreachable]
2021-09-11 12:24:37 ERROR (MainThread) [homeassistant] Error doing job: Future exception was never retrieved
Traceback (most recent call last):
  File "/usr/local/lib/python3.9/concurrent/futures/thread.py", line 52, in run
    result = self.fn(*self.args, **self.kwargs)
TypeError: update() takes 1 positional argument but 2 were given
2021-09-11 12:29:38 ERROR (MainThread) [homeassistant] Error doing job: Future exception was never retrieved
Traceback (most recent call last):
  File "/usr/local/lib/python3.9/concurrent/futures/thread.py", line 52, in run
    result = self.fn(*self.args, **self.kwargs)
TypeError: update() takes 1 positional argument but 2 were given
2021-09-11 12:33:34 ERROR (MainThread) [homeassistant.components.nws] Error requesting NWS forecast station SAUC1 data: Cannot connect to host api.weather.gov:443 ssl:default [Network unreachable]
2021-09-11 12:34:39 ERROR (MainThread) [homeassistant] Error doing job: Future exception was never retrieved
Traceback (most recent call last):
  File "/usr/local/lib/python3.9/concurrent/futures/thread.py", line 52, in run
    result = self.fn(*self.args, **self.kwargs)
TypeError: update() takes 1 positional argument but 2 were given
2021-09-11 12:39:40 ERROR (MainThread) [homeassistant] Error doing job: Future exception was never retrieved
Traceback (most recent call last):
  File "/usr/local/lib/python3.9/concurrent/futures/thread.py", line 52, in run
    result = self.fn(*self.args, **self.kwargs)
TypeError: update() takes 1 positional argument but 2 were given
2021-09-11 12:44:41 ERROR (MainThread) [homeassistant] Error doing job: Future exception was never retrieved
Traceback (most recent call last):
  File "/usr/local/lib/python3.9/concurrent/futures/thread.py", line 52, in run
    result = self.fn(*self.args, **self.kwargs)
TypeError: update() takes 1 positional argument but 2 were given
2021-09-11 12:45:07 ERROR (MainThread) [homeassistant.components.nws] Error requesting NWS observation station SAUC1 data: Cannot connect to host api.weather.gov:443 ssl:default [Network unreachable]
2021-09-11 12:49:42 ERROR (MainThread) [homeassistant] Error doing job: Future exception was never retrieved
Traceback (most recent call last):
  File "/usr/local/lib/python3.9/concurrent/futures/thread.py", line 52, in run
    result = self.fn(*self.args, **self.kwargs)
TypeError: update() takes 1 positional argument but 2 were given
2021-09-11 12:54:43 ERROR (MainThread) [homeassistant] Error doing job: Future exception was never retrieved
Traceback (most recent call last):
  File "/usr/local/lib/python3.9/concurrent/futures/thread.py", line 52, in run
    result = self.fn(*self.args, **self.kwargs)
TypeError: update() takes 1 positional argument but 2 were given
2021-09-11 12:59:44 ERROR (MainThread) [homeassistant] Error doing job: Future exception was never retrieved
Traceback (most recent call last):
  File "/usr/local/lib/python3.9/concurrent/futures/thread.py", line 52, in run
    result = self.fn(*self.args, **self.kwargs)
TypeError: update() takes 1 positional argument but 2 were given
2021-09-11 13:04:45 ERROR (MainThread) [homeassistant] Error doing job: Future exception was never retrieved
Traceback (most recent call last):
  File "/usr/local/lib/python3.9/concurrent/futures/thread.py", line 52, in run
    result = self.fn(*self.args, **self.kwargs)
TypeError: update() takes 1 positional argument but 2 were given
2021-09-11 13:09:46 ERROR (MainThread) [homeassistant] Error doing job: Future exception was never retrieved
Traceback (most recent call last):
  File "/usr/local/lib/python3.9/concurrent/futures/thread.py", line 52, in run
    result = self.fn(*self.args, **self.kwargs)
TypeError: update() takes 1 positional argument but 2 were given
2021-09-11 13:14:47 ERROR (MainThread) [homeassistant] Error doing job: Future exception was never retrieved
Traceback (most recent call last):
  File "/usr/local/lib/python3.9/concurrent/futures/thread.py", line 52, in run
    result = self.fn(*self.args, **self.kwargs)
TypeError: update() takes 1 positional argument but 2 were given
2021-09-11 13:19:48 ERROR (MainThread) [homeassistant] Error doing job: Future exception was never retrieved
Traceback (most recent call last):
  File "/usr/local/lib/python3.9/concurrent/futures/thread.py", line 52, in run
    result = self.fn(*self.args, **self.kwargs)
TypeError: update() takes 1 positional argument but 2 were given
2021-09-11 13:24:49 ERROR (MainThread) [homeassistant] Error doing job: Future exception was never retrieved
Traceback (most recent call last):
  File "/usr/local/lib/python3.9/concurrent/futures/thread.py", line 52, in run
    result = self.fn(*self.args, **self.kwargs)
TypeError: update() takes 1 positional argument but 2 were given
2021-09-11 13:29:50 ERROR (MainThread) [homeassistant] Error doing job: Future exception was never retrieved
Traceback (most recent call last):
  File "/usr/local/lib/python3.9/concurrent/futures/thread.py", line 52, in run
    result = self.fn(*self.args, **self.kwargs)
TypeError: update() takes 1 positional argument but 2 were given
2021-09-11 13:34:51 ERROR (MainThread) [homeassistant] Error doing job: Future exception was never retrieved
Traceback (most recent call last):
  File "/usr/local/lib/python3.9/concurrent/futures/thread.py", line 52, in run
    result = self.fn(*self.args, **self.kwargs)
TypeError: update() takes 1 positional argument but 2 were given
2021-09-11 13:39:52 ERROR (MainThread) [homeassistant] Error doing job: Future exception was never retrieved
Traceback (most recent call last):
  File "/usr/local/lib/python3.9/concurrent/futures/thread.py", line 52, in run
    result = self.fn(*self.args, **self.kwargs)
TypeError: update() takes 1 positional argument but 2 were given
2021-09-11 13:44:53 ERROR (MainThread) [homeassistant] Error doing job: Future exception was never retrieved
Traceback (most recent call last):
  File "/usr/local/lib/python3.9/concurrent/futures/thread.py", line 52, in run
    result = self.fn(*self.args, **self.kwargs)
TypeError: update() takes 1 positional argument but 2 were given
2021-09-11 13:49:54 ERROR (MainThread) [homeassistant] Error doing job: Future exception was never retrieved
Traceback (most recent call last):
  File "/usr/local/lib/python3.9/concurrent/futures/thread.py", line 52, in run
    result = self.fn(*self.args, **self.kwargs)
TypeError: update() takes 1 positional argument but 2 were given
2021-09-11 13:54:55 ERROR (MainThread) [homeassistant] Error doing job: Future exception was never retrieved
Traceback (most recent call last):
  File "/usr/local/lib/python3.9/concurrent/futures/thread.py", line 52, in run
    result = self.fn(*self.args, **self.kwargs)
TypeError: update() takes 1 positional argument but 2 were given
2021-09-11 13:59:56 ERROR (MainThread) [homeassistant] Error doing job: Future exception was never retrieved
Traceback (most recent call last):
  File "/usr/local/lib/python3.9/concurrent/futures/thread.py", line 52, in run
    result = self.fn(*self.args, **self.kwargs)
TypeError: update() takes 1 positional argument but 2 were given
2021-09-11 14:04:57 ERROR (MainThread) [homeassistant] Error doing job: Future exception was never retrieved
Traceback (most recent call last):
  File "/usr/local/lib/python3.9/concurrent/futures/thread.py", line 52, in run
    result = self.fn(*self.args, **self.kwargs)
TypeError: update() takes 1 positional argument but 2 were given
2021-09-11 14:09:58 ERROR (MainThread) [homeassistant] Error doing job: Future exception was never retrieved
Traceback (most recent call last):
  File "/usr/local/lib/python3.9/concurrent/futures/thread.py", line 52, in run
    result = self.fn(*self.args, **self.kwargs)
TypeError: update() takes 1 positional argument but 2 were given
2021-09-11 14:14:59 ERROR (MainThread) [homeassistant] Error doing job: Future exception was never retrieved
Traceback (most recent call last):
  File "/usr/local/lib/python3.9/concurrent/futures/thread.py", line 52, in run
    result = self.fn(*self.args, **self.kwargs)
TypeError: update() takes 1 positional argument but 2 were given
2021-09-11 14:17:47 ERROR (MainThread) [bellows.ezsp] NCP entered failed state. Requesting APP controller restart
2021-09-11 14:20:00 ERROR (MainThread) [homeassistant] Error doing job: Future exception was never retrieved
Traceback (most recent call last):
  File "/usr/local/lib/python3.9/concurrent/futures/thread.py", line 52, in run
    result = self.fn(*self.args, **self.kwargs)
TypeError: update() takes 1 positional argument but 2 were given
2021-09-11 14:25:01 ERROR (MainThread) [homeassistant] Error doing job: Future exception was never retrieved
Traceback (most recent call last):
  File "/usr/local/lib/python3.9/concurrent/futures/thread.py", line 52, in run
    result = self.fn(*self.args, **self.kwargs)
TypeError: update() takes 1 positional argument but 2 were given
2021-09-11 14:28:04 ERROR (MainThread) [iotawattpy.connection] Err: 
2021-09-11 14:28:04 ERROR (MainThread) [homeassistant.components.iotawatt.coordinator] Unexpected error fetching 192.168.20.195 data: 'NoneType' object has no attribute 'text'
Traceback (most recent call last):
  File "/usr/src/homeassistant/homeassistant/helpers/update_coordinator.py", line 187, in _async_refresh
    self.data = await self._async_update_data()
  File "/usr/src/homeassistant/homeassistant/components/iotawatt/coordinator.py", line 55, in _async_update_data
    await self.api.update()
  File "/usr/local/lib/python3.9/site-packages/iotawattpy/iotawatt.py", line 66, in update
    await self._refreshSensors(timespan)
  File "/usr/local/lib/python3.9/site-packages/iotawattpy/iotawatt.py", line 100, in _refreshSensors
    results = response.text
AttributeError: 'NoneType' object has no attribute 'text'
2021-09-11 14:30:02 ERROR (MainThread) [homeassistant] Error doing job: Future exception was never retrieved
Traceback (most recent call last):
  File "/usr/local/lib/python3.9/concurrent/futures/thread.py", line 52, in run
    result = self.fn(*self.args, **self.kwargs)
TypeError: update() takes 1 positional argument but 2 were given
2021-09-11 14:35:03 ERROR (MainThread) [homeassistant] Error doing job: Future exception was never retrieved
Traceback (most recent call last):
  File "/usr/local/lib/python3.9/concurrent/futures/thread.py", line 52, in run
    result = self.fn(*self.args, **self.kwargs)
TypeError: update() takes 1 positional argument but 2 were given
2021-09-11 14:40:04 ERROR (MainThread) [homeassistant] Error doing job: Future exception was never retrieved
Traceback (most recent call last):
  File "/usr/local/lib/python3.9/concurrent/futures/thread.py", line 52, in run
    result = self.fn(*self.args, **self.kwargs)
TypeError: update() takes 1 positional argument but 2 were given
2021-09-11 14:42:17 ERROR (MainThread) [iotawattpy.connection] Err: 
2021-09-11 14:42:17 ERROR (MainThread) [homeassistant.components.iotawatt.coordinator] Unexpected error fetching 192.168.20.195 data: 'NoneType' object has no attribute 'text'
Traceback (most recent call last):
  File "/usr/src/homeassistant/homeassistant/helpers/update_coordinator.py", line 187, in _async_refresh
    self.data = await self._async_update_data()
  File "/usr/src/homeassistant/homeassistant/components/iotawatt/coordinator.py", line 55, in _async_update_data
    await self.api.update()
  File "/usr/local/lib/python3.9/site-packages/iotawattpy/iotawatt.py", line 66, in update
    await self._refreshSensors(timespan)
  File "/usr/local/lib/python3.9/site-packages/iotawattpy/iotawatt.py", line 100, in _refreshSensors
    results = response.text
AttributeError: 'NoneType' object has no attribute 'text'
2021-09-11 14:42:55 ERROR (MainThread) [iotawattpy.connection] Err: 
2021-09-11 14:42:55 ERROR (MainThread) [homeassistant.components.iotawatt.coordinator] Unexpected error fetching 192.168.20.195 data: 'NoneType' object has no attribute 'text'
Traceback (most recent call last):
  File "/usr/src/homeassistant/homeassistant/helpers/update_coordinator.py", line 187, in _async_refresh
    self.data = await self._async_update_data()
  File "/usr/src/homeassistant/homeassistant/components/iotawatt/coordinator.py", line 55, in _async_update_data
    await self.api.update()
  File "/usr/local/lib/python3.9/site-packages/iotawattpy/iotawatt.py", line 66, in update
    await self._refreshSensors(timespan)
  File "/usr/local/lib/python3.9/site-packages/iotawattpy/iotawatt.py", line 100, in _refreshSensors
    results = response.text
AttributeError: 'NoneType' object has no attribute 'text'
2021-09-11 14:45:05 ERROR (MainThread) [homeassistant] Error doing job: Future exception was never retrieved
Traceback (most recent call last):
  File "/usr/local/lib/python3.9/concurrent/futures/thread.py", line 52, in run
    result = self.fn(*self.args, **self.kwargs)
TypeError: update() takes 1 positional argument but 2 were given
2021-09-11 14:50:06 ERROR (MainThread) [homeassistant] Error doing job: Future exception was never retrieved
Traceback (most recent call last):
  File "/usr/local/lib/python3.9/concurrent/futures/thread.py", line 52, in run
    result = self.fn(*self.args, **self.kwargs)
TypeError: update() takes 1 positional argument but 2 were given
2021-09-11 14:55:07 ERROR (MainThread) [homeassistant] Error doing job: Future exception was never retrieved
Traceback (most recent call last):
  File "/usr/local/lib/python3.9/concurrent/futures/thread.py", line 52, in run
    result = self.fn(*self.args, **self.kwargs)
TypeError: update() takes 1 positional argument but 2 were given
2021-09-11 14:56:17 ERROR (MainThread) [homeassistant.components.nws] Error requesting NWS observation station SAUC1 data: 503, message='Service Unavailable', url=URL('https://api.weather.gov/stations/SAUC1/observations')
2021-09-11 14:56:31 ERROR (MainThread) [bellows.ezsp] NCP entered failed state. Requesting APP controller restart
2021-09-11 14:58:13 ERROR (MainThread) [iotawattpy.connection] Err: 
2021-09-11 14:58:13 ERROR (MainThread) [homeassistant.components.iotawatt.coordinator] Unexpected error fetching 192.168.20.195 data: 'NoneType' object has no attribute 'text'
Traceback (most recent call last):
  File "/usr/src/homeassistant/homeassistant/helpers/update_coordinator.py", line 187, in _async_refresh
    self.data = await self._async_update_data()
  File "/usr/src/homeassistant/homeassistant/components/iotawatt/coordinator.py", line 55, in _async_update_data
    await self.api.update()
  File "/usr/local/lib/python3.9/site-packages/iotawattpy/iotawatt.py", line 66, in update
    await self._refreshSensors(timespan)
  File "/usr/local/lib/python3.9/site-packages/iotawattpy/iotawatt.py", line 100, in _refreshSensors
    results = response.text
AttributeError: 'NoneType' object has no attribute 'text'
2021-09-11 15:00:08 ERROR (MainThread) [homeassistant] Error doing job: Future exception was never retrieved
Traceback (most recent call last):
  File "/usr/local/lib/python3.9/concurrent/futures/thread.py", line 52, in run
    result = self.fn(*self.args, **self.kwargs)
TypeError: update() takes 1 positional argument but 2 were given
2021-09-11 15:05:09 ERROR (MainThread) [homeassistant] Error doing job: Future exception was never retrieved
Traceback (most recent call last):
  File "/usr/local/lib/python3.9/concurrent/futures/thread.py", line 52, in run
    result = self.fn(*self.args, **self.kwargs)
TypeError: update() takes 1 positional argument but 2 were given
2021-09-11 15:07:32 ERROR (MainThread) [homeassistant.components.nws] Error requesting NWS observation station SAUC1 data: 503, message='Service Unavailable', url=URL('https://api.weather.gov/stations/SAUC1/observations')
2021-09-11 15:10:10 ERROR (MainThread) [homeassistant] Error doing job: Future exception was never retrieved
Traceback (most recent call last):
  File "/usr/local/lib/python3.9/concurrent/futures/thread.py", line 52, in run
    result = self.fn(*self.args, **self.kwargs)
TypeError: update() takes 1 positional argument but 2 were given
2021-09-11 15:15:11 ERROR (MainThread) [homeassistant] Error doing job: Future exception was never retrieved
Traceback (most recent call last):
  File "/usr/local/lib/python3.9/concurrent/futures/thread.py", line 52, in run
    result = self.fn(*self.args, **self.kwargs)
TypeError: update() takes 1 positional argument but 2 were given
2021-09-11 15:20:12 ERROR (MainThread) [homeassistant] Error doing job: Future exception was never retrieved
Traceback (most recent call last):
  File "/usr/local/lib/python3.9/concurrent/futures/thread.py", line 52, in run
    result = self.fn(*self.args, **self.kwargs)
TypeError: update() takes 1 positional argument but 2 were given
2021-09-11 15:25:13 ERROR (MainThread) [homeassistant] Error doing job: Future exception was never retrieved
Traceback (most recent call last):
  File "/usr/local/lib/python3.9/concurrent/futures/thread.py", line 52, in run
    result = self.fn(*self.args, **self.kwargs)
TypeError: update() takes 1 positional argument but 2 were given
2021-09-11 15:25:37 WARNING (MainThread) [bellows.zigbee.application] Watchdog heartbeat timeout: 
2021-09-11 15:25:52 WARNING (MainThread) [bellows.zigbee.application] Watchdog heartbeat timeout: 
2021-09-11 15:26:07 WARNING (MainThread) [bellows.zigbee.application] Watchdog heartbeat timeout: 
2021-09-11 15:26:22 WARNING (MainThread) [bellows.zigbee.application] Watchdog heartbeat timeout: 
2021-09-11 15:26:37 WARNING (MainThread) [bellows.zigbee.application] Watchdog heartbeat timeout: 
2021-09-11 15:27:41 WARNING (bellows.thread_0) [bellows.uart] Reset future is None
2021-09-11 15:27:41 ERROR (bellows.thread_0) [bellows.uart] Lost serial connection: read failed: socket disconnected
2021-09-11 15:27:41 ERROR (MainThread) [bellows.ezsp] NCP entered failed state. Requesting APP controller restart
2021-09-11 15:27:47 WARNING (bellows.thread_0) [bellows.uart] Reset future is None
2021-09-11 15:27:53 WARNING (bellows.thread_0) [bellows.uart] Reset future is None
2021-09-11 15:29:01 ERROR (MainThread) [homeassistant.components.nws] Error requesting NWS observation station SAUC1 data: 503, message='Service Unavailable', url=URL('https://api.weather.gov/stations/SAUC1/observations')
2021-09-11 15:30:14 ERROR (MainThread) [homeassistant] Error doing job: Future exception was never retrieved
Traceback (most recent call last):
  File "/usr/local/lib/python3.9/concurrent/futures/thread.py", line 52, in run
    result = self.fn(*self.args, **self.kwargs)
TypeError: update() takes 1 positional argument but 2 were given
2021-09-11 15:35:15 ERROR (MainThread) [homeassistant] Error doing job: Future exception was never retrieved
Traceback (most recent call last):
  File "/usr/local/lib/python3.9/concurrent/futures/thread.py", line 52, in run
    result = self.fn(*self.args, **self.kwargs)
TypeError: update() takes 1 positional argument but 2 were given
2021-09-11 15:39:02 ERROR (MainThread) [homeassistant] Error doing job: Task was destroyed but it is pending!
2021-09-11 15:40:16 ERROR (MainThread) [homeassistant] Error doing job: Future exception was never retrieved
Traceback (most recent call last):
  File "/usr/local/lib/python3.9/concurrent/futures/thread.py", line 52, in run
    result = self.fn(*self.args, **self.kwargs)
TypeError: update() takes 1 positional argument but 2 were given
2021-09-11 15:45:17 ERROR (MainThread) [homeassistant] Error doing job: Future exception was never retrieved
Traceback (most recent call last):
  File "/usr/local/lib/python3.9/concurrent/futures/thread.py", line 52, in run
    result = self.fn(*self.args, **self.kwargs)
TypeError: update() takes 1 positional argument but 2 were given
2021-09-11 15:50:18 ERROR (MainThread) [homeassistant] Error doing job: Future exception was never retrieved
Traceback (most recent call last):
  File "/usr/local/lib/python3.9/concurrent/futures/thread.py", line 52, in run
    result = self.fn(*self.args, **self.kwargs)
TypeError: update() takes 1 positional argument but 2 were given
2021-09-11 15:55:19 ERROR (MainThread) [homeassistant] Error doing job: Future exception was never retrieved
Traceback (most recent call last):
  File "/usr/local/lib/python3.9/concurrent/futures/thread.py", line 52, in run
    result = self.fn(*self.args, **self.kwargs)
TypeError: update() takes 1 positional argument but 2 were given
2021-09-11 16:00:11 ERROR (MainThread) [homeassistant.components.nws] Error requesting NWS observation station SAUC1 data: 503, message='Service Unavailable', url=URL('https://api.weather.gov/stations/SAUC1/observations')
2021-09-11 16:00:20 ERROR (MainThread) [homeassistant] Error doing job: Future exception was never retrieved
Traceback (most recent call last):
  File "/usr/local/lib/python3.9/concurrent/futures/thread.py", line 52, in run
    result = self.fn(*self.args, **self.kwargs)
TypeError: update() takes 1 positional argument but 2 were given
2021-09-11 16:05:21 ERROR (MainThread) [homeassistant] Error doing job: Future exception was never retrieved
Traceback (most recent call last):
  File "/usr/local/lib/python3.9/concurrent/futures/thread.py", line 52, in run
    result = self.fn(*self.args, **self.kwargs)
TypeError: update() takes 1 positional argument but 2 were given
2021-09-11 16:10:22 ERROR (MainThread) [homeassistant] Error doing job: Future exception was never retrieved
Traceback (most recent call last):
  File "/usr/local/lib/python3.9/concurrent/futures/thread.py", line 52, in run
    result = self.fn(*self.args, **self.kwargs)
TypeError: update() takes 1 positional argument but 2 were given
2021-09-11 16:11:17 ERROR (MainThread) [iotawattpy.connection] Err: 
2021-09-11 16:11:17 ERROR (MainThread) [homeassistant.components.iotawatt.coordinator] Unexpected error fetching 192.168.20.195 data: 'NoneType' object has no attribute 'text'
Traceback (most recent call last):
  File "/usr/src/homeassistant/homeassistant/helpers/update_coordinator.py", line 187, in _async_refresh
    self.data = await self._async_update_data()
  File "/usr/src/homeassistant/homeassistant/components/iotawatt/coordinator.py", line 55, in _async_update_data
    await self.api.update()
  File "/usr/local/lib/python3.9/site-packages/iotawattpy/iotawatt.py", line 66, in update
    await self._refreshSensors(timespan)
  File "/usr/local/lib/python3.9/site-packages/iotawattpy/iotawatt.py", line 100, in _refreshSensors
    results = response.text
AttributeError: 'NoneType' object has no attribute 'text'
2021-09-11 16:15:23 ERROR (MainThread) [homeassistant] Error doing job: Future exception was never retrieved
Traceback (most recent call last):
  File "/usr/local/lib/python3.9/concurrent/futures/thread.py", line 52, in run
    result = self.fn(*self.args, **self.kwargs)
TypeError: update() takes 1 positional argument but 2 were given
2021-09-11 16:20:24 ERROR (MainThread) [homeassistant] Error doing job: Future exception was never retrieved
Traceback (most recent call last):
  File "/usr/local/lib/python3.9/concurrent/futures/thread.py", line 52, in run
    result = self.fn(*self.args, **self.kwargs)
TypeError: update() takes 1 positional argument but 2 were given
2021-09-11 16:24:27 ERROR (MainThread) [iotawattpy.connection] Err: 
2021-09-11 16:24:27 ERROR (MainThread) [homeassistant.components.iotawatt.coordinator] Unexpected error fetching 192.168.20.195 data: 'NoneType' object has no attribute 'text'
Traceback (most recent call last):
  File "/usr/src/homeassistant/homeassistant/helpers/update_coordinator.py", line 187, in _async_refresh
    self.data = await self._async_update_data()
  File "/usr/src/homeassistant/homeassistant/components/iotawatt/coordinator.py", line 55, in _async_update_data
    await self.api.update()
  File "/usr/local/lib/python3.9/site-packages/iotawattpy/iotawatt.py", line 66, in update
    await self._refreshSensors(timespan)
  File "/usr/local/lib/python3.9/site-packages/iotawattpy/iotawatt.py", line 100, in _refreshSensors
    results = response.text
AttributeError: 'NoneType' object has no attribute 'text'
2021-09-11 16:25:25 ERROR (MainThread) [homeassistant] Error doing job: Future exception was never retrieved
Traceback (most recent call last):
  File "/usr/local/lib/python3.9/concurrent/futures/thread.py", line 52, in run
    result = self.fn(*self.args, **self.kwargs)
TypeError: update() takes 1 positional argument but 2 were given
2021-09-11 16:30:26 ERROR (MainThread) [homeassistant] Error doing job: Future exception was never retrieved
Traceback (most recent call last):
  File "/usr/local/lib/python3.9/concurrent/futures/thread.py", line 52, in run
    result = self.fn(*self.args, **self.kwargs)
TypeError: update() takes 1 positional argument but 2 were given
2021-09-11 16:35:27 ERROR (MainThread) [homeassistant] Error doing job: Future exception was never retrieved
Traceback (most recent call last):
  File "/usr/local/lib/python3.9/concurrent/futures/thread.py", line 52, in run
    result = self.fn(*self.args, **self.kwargs)
TypeError: update() takes 1 positional argument but 2 were given
2021-09-11 16:40:28 ERROR (MainThread) [homeassistant] Error doing job: Future exception was never retrieved
Traceback (most recent call last):
  File "/usr/local/lib/python3.9/concurrent/futures/thread.py", line 52, in run
    result = self.fn(*self.args, **self.kwargs)
TypeError: update() takes 1 positional argument but 2 were given
2021-09-11 16:45:29 ERROR (MainThread) [homeassistant] Error doing job: Future exception was never retrieved
Traceback (most recent call last):
  File "/usr/local/lib/python3.9/concurrent/futures/thread.py", line 52, in run
    result = self.fn(*self.args, **self.kwargs)
TypeError: update() takes 1 positional argument but 2 were given
2021-09-11 16:50:30 ERROR (MainThread) [homeassistant] Error doing job: Future exception was never retrieved
Traceback (most recent call last):
  File "/usr/local/lib/python3.9/concurrent/futures/thread.py", line 52, in run
    result = self.fn(*self.args, **self.kwargs)
TypeError: update() takes 1 positional argument but 2 were given
2021-09-11 16:55:31 ERROR (MainThread) [homeassistant] Error doing job: Future exception was never retrieved
Traceback (most recent call last):
  File "/usr/local/lib/python3.9/concurrent/futures/thread.py", line 52, in run
    result = self.fn(*self.args, **self.kwargs)
TypeError: update() takes 1 positional argument but 2 were given
2021-09-11 17:00:32 ERROR (MainThread) [homeassistant] Error doing job: Future exception was never retrieved
Traceback (most recent call last):
  File "/usr/local/lib/python3.9/concurrent/futures/thread.py", line 52, in run
    result = self.fn(*self.args, **self.kwargs)
TypeError: update() takes 1 positional argument but 2 were given
2021-09-11 17:05:33 ERROR (MainThread) [homeassistant] Error doing job: Future exception was never retrieved
Traceback (most recent call last):
  File "/usr/local/lib/python3.9/concurrent/futures/thread.py", line 52, in run
    result = self.fn(*self.args, **self.kwargs)
TypeError: update() takes 1 positional argument but 2 were given
2021-09-11 17:06:43 WARNING (MainThread) [bellows.zigbee.application] Watchdog heartbeat timeout: 
2021-09-11 17:10:34 ERROR (MainThread) [homeassistant] Error doing job: Future exception was never retrieved
Traceback (most recent call last):
  File "/usr/local/lib/python3.9/concurrent/futures/thread.py", line 52, in run
    result = self.fn(*self.args, **self.kwargs)
TypeError: update() takes 1 positional argument but 2 were given
2021-09-11 17:15:35 ERROR (MainThread) [homeassistant] Error doing job: Future exception was never retrieved
Traceback (most recent call last):
  File "/usr/local/lib/python3.9/concurrent/futures/thread.py", line 52, in run
    result = self.fn(*self.args, **self.kwargs)
TypeError: update() takes 1 positional argument but 2 were given
2021-09-11 17:20:36 ERROR (MainThread) [homeassistant] Error doing job: Future exception was never retrieved
Traceback (most recent call last):
  File "/usr/local/lib/python3.9/concurrent/futures/thread.py", line 52, in run
    result = self.fn(*self.args, **self.kwargs)
TypeError: update() takes 1 positional argument but 2 were given
2021-09-11 17:25:37 ERROR (MainThread) [homeassistant] Error doing job: Future exception was never retrieved
Traceback (most recent call last):
  File "/usr/local/lib/python3.9/concurrent/futures/thread.py", line 52, in run
    result = self.fn(*self.args, **self.kwargs)
TypeError: update() takes 1 positional argument but 2 were given
2021-09-11 17:30:38 ERROR (MainThread) [homeassistant] Error doing job: Future exception was never retrieved
Traceback (most recent call last):
  File "/usr/local/lib/python3.9/concurrent/futures/thread.py", line 52, in run
    result = self.fn(*self.args, **self.kwargs)
TypeError: update() takes 1 positional argument but 2 were given
2021-09-11 17:35:39 ERROR (MainThread) [homeassistant] Error doing job: Future exception was never retrieved
Traceback (most recent call last):
  File "/usr/local/lib/python3.9/concurrent/futures/thread.py", line 52, in run
    result = self.fn(*self.args, **self.kwargs)
TypeError: update() takes 1 positional argument but 2 were given
2021-09-11 17:40:40 ERROR (MainThread) [homeassistant] Error doing job: Future exception was never retrieved
Traceback (most recent call last):
  File "/usr/local/lib/python3.9/concurrent/futures/thread.py", line 52, in run
    result = self.fn(*self.args, **self.kwargs)
TypeError: update() takes 1 positional argument but 2 were given
2021-09-11 17:45:41 ERROR (MainThread) [homeassistant] Error doing job: Future exception was never retrieved
Traceback (most recent call last):
  File "/usr/local/lib/python3.9/concurrent/futures/thread.py", line 52, in run
    result = self.fn(*self.args, **self.kwargs)
TypeError: update() takes 1 positional argument but 2 were given
2021-09-11 17:47:02 WARNING (MainThread) [homeassistant.helpers.service] Unable to find referenced entities light.hue_lightstrip_2
2021-09-11 17:50:42 ERROR (MainThread) [homeassistant] Error doing job: Future exception was never retrieved
Traceback (most recent call last):
  File "/usr/local/lib/python3.9/concurrent/futures/thread.py", line 52, in run
    result = self.fn(*self.args, **self.kwargs)
TypeError: update() takes 1 positional argument but 2 were given
2021-09-11 17:55:43 ERROR (MainThread) [homeassistant] Error doing job: Future exception was never retrieved
Traceback (most recent call last):
  File "/usr/local/lib/python3.9/concurrent/futures/thread.py", line 52, in run
    result = self.fn(*self.args, **self.kwargs)
TypeError: update() takes 1 positional argument but 2 were given
2021-09-11 18:00:44 ERROR (MainThread) [homeassistant] Error doing job: Future exception was never retrieved
Traceback (most recent call last):
  File "/usr/local/lib/python3.9/concurrent/futures/thread.py", line 52, in run
    result = self.fn(*self.args, **self.kwargs)
TypeError: update() takes 1 positional argument but 2 were given
2021-09-11 18:05:45 ERROR (MainThread) [homeassistant] Error doing job: Future exception was never retrieved
Traceback (most recent call last):
  File "/usr/local/lib/python3.9/concurrent/futures/thread.py", line 52, in run
    result = self.fn(*self.args, **self.kwargs)
TypeError: update() takes 1 positional argument but 2 were given
2021-09-11 18:10:46 ERROR (MainThread) [homeassistant] Error doing job: Future exception was never retrieved
Traceback (most recent call last):
  File "/usr/local/lib/python3.9/concurrent/futures/thread.py", line 52, in run
    result = self.fn(*self.args, **self.kwargs)
TypeError: update() takes 1 positional argument but 2 were given
2021-09-11 18:14:54 ERROR (MainThread) [iotawattpy.connection] Err: 
2021-09-11 18:14:54 ERROR (MainThread) [homeassistant.components.iotawatt.coordinator] Unexpected error fetching 192.168.20.195 data: 'NoneType' object has no attribute 'text'
Traceback (most recent call last):
  File "/usr/src/homeassistant/homeassistant/helpers/update_coordinator.py", line 187, in _async_refresh
    self.data = await self._async_update_data()
  File "/usr/src/homeassistant/homeassistant/components/iotawatt/coordinator.py", line 55, in _async_update_data
    await self.api.update()
  File "/usr/local/lib/python3.9/site-packages/iotawattpy/iotawatt.py", line 66, in update
    await self._refreshSensors(timespan)
  File "/usr/local/lib/python3.9/site-packages/iotawattpy/iotawatt.py", line 100, in _refreshSensors
    results = response.text
AttributeError: 'NoneType' object has no attribute 'text'
2021-09-11 18:15:47 ERROR (MainThread) [homeassistant] Error doing job: Future exception was never retrieved
Traceback (most recent call last):
  File "/usr/local/lib/python3.9/concurrent/futures/thread.py", line 52, in run
    result = self.fn(*self.args, **self.kwargs)
TypeError: update() takes 1 positional argument but 2 were given
2021-09-11 18:20:48 ERROR (MainThread) [homeassistant] Error doing job: Future exception was never retrieved
Traceback (most recent call last):
  File "/usr/local/lib/python3.9/concurrent/futures/thread.py", line 52, in run
    result = self.fn(*self.args, **self.kwargs)
TypeError: update() takes 1 positional argument but 2 were given
2021-09-11 18:25:49 ERROR (MainThread) [homeassistant] Error doing job: Future exception was never retrieved
Traceback (most recent call last):
  File "/usr/local/lib/python3.9/concurrent/futures/thread.py", line 52, in run
    result = self.fn(*self.args, **self.kwargs)
TypeError: update() takes 1 positional argument but 2 were given
2021-09-11 18:30:50 ERROR (MainThread) [homeassistant] Error doing job: Future exception was never retrieved
Traceback (most recent call last):
  File "/usr/local/lib/python3.9/concurrent/futures/thread.py", line 52, in run
    result = self.fn(*self.args, **self.kwargs)
TypeError: update() takes 1 positional argument but 2 were given
2021-09-11 18:35:51 ERROR (MainThread) [homeassistant] Error doing job: Future exception was never retrieved
Traceback (most recent call last):
  File "/usr/local/lib/python3.9/concurrent/futures/thread.py", line 52, in run
    result = self.fn(*self.args, **self.kwargs)
TypeError: update() takes 1 positional argument but 2 were given
2021-09-11 18:40:52 ERROR (MainThread) [homeassistant] Error doing job: Future exception was never retrieved
Traceback (most recent call last):
  File "/usr/local/lib/python3.9/concurrent/futures/thread.py", line 52, in run
    result = self.fn(*self.args, **self.kwargs)
TypeError: update() takes 1 positional argument but 2 were given
2021-09-11 18:45:53 ERROR (MainThread) [homeassistant] Error doing job: Future exception was never retrieved
Traceback (most recent call last):
  File "/usr/local/lib/python3.9/concurrent/futures/thread.py", line 52, in run
    result = self.fn(*self.args, **self.kwargs)
TypeError: update() takes 1 positional argument but 2 were given
2021-09-11 18:50:54 ERROR (MainThread) [homeassistant] Error doing job: Future exception was never retrieved
Traceback (most recent call last):
  File "/usr/local/lib/python3.9/concurrent/futures/thread.py", line 52, in run
    result = self.fn(*self.args, **self.kwargs)
TypeError: update() takes 1 positional argument but 2 were given
2021-09-11 18:55:55 ERROR (MainThread) [homeassistant] Error doing job: Future exception was never retrieved
Traceback (most recent call last):
  File "/usr/local/lib/python3.9/concurrent/futures/thread.py", line 52, in run
    result = self.fn(*self.args, **self.kwargs)
TypeError: update() takes 1 positional argument but 2 were given
2021-09-11 19:00:56 ERROR (MainThread) [homeassistant] Error doing job: Future exception was never retrieved
Traceback (most recent call last):
  File "/usr/local/lib/python3.9/concurrent/futures/thread.py", line 52, in run
    result = self.fn(*self.args, **self.kwargs)
TypeError: update() takes 1 positional argument but 2 were given
2021-09-11 19:05:44 WARNING (MainThread) [homeassistant.helpers.service] Unable to find referenced entities scene.kitchen_sink_on
2021-09-11 19:05:45 WARNING (MainThread) [homeassistant.helpers.service] Unable to find referenced entities light.hue_lightstrip_2
2021-09-11 19:05:57 ERROR (MainThread) [homeassistant] Error doing job: Future exception was never retrieved
Traceback (most recent call last):
  File "/usr/local/lib/python3.9/concurrent/futures/thread.py", line 52, in run
    result = self.fn(*self.args, **self.kwargs)
TypeError: update() takes 1 positional argument but 2 were given
2021-09-11 19:10:58 ERROR (MainThread) [homeassistant] Error doing job: Future exception was never retrieved
Traceback (most recent call last):
  File "/usr/local/lib/python3.9/concurrent/futures/thread.py", line 52, in run
    result = self.fn(*self.args, **self.kwargs)
TypeError: update() takes 1 positional argument but 2 were given
2021-09-11 19:15:59 ERROR (MainThread) [homeassistant] Error doing job: Future exception was never retrieved
Traceback (most recent call last):
  File "/usr/local/lib/python3.9/concurrent/futures/thread.py", line 52, in run
    result = self.fn(*self.args, **self.kwargs)
TypeError: update() takes 1 positional argument but 2 were given
2021-09-11 19:21:00 ERROR (MainThread) [homeassistant] Error doing job: Future exception was never retrieved
Traceback (most recent call last):
  File "/usr/local/lib/python3.9/concurrent/futures/thread.py", line 52, in run
    result = self.fn(*self.args, **self.kwargs)
TypeError: update() takes 1 positional argument but 2 were given
2021-09-11 19:26:01 ERROR (MainThread) [homeassistant] Error doing job: Future exception was never retrieved
Traceback (most recent call last):
  File "/usr/local/lib/python3.9/concurrent/futures/thread.py", line 52, in run
    result = self.fn(*self.args, **self.kwargs)
TypeError: update() takes 1 positional argument but 2 were given
2021-09-11 19:31:02 ERROR (MainThread) [homeassistant] Error doing job: Future exception was never retrieved
Traceback (most recent call last):
  File "/usr/local/lib/python3.9/concurrent/futures/thread.py", line 52, in run
    result = self.fn(*self.args, **self.kwargs)
TypeError: update() takes 1 positional argument but 2 were given
2021-09-11 19:36:03 ERROR (MainThread) [homeassistant] Error doing job: Future exception was never retrieved
Traceback (most recent call last):
  File "/usr/local/lib/python3.9/concurrent/futures/thread.py", line 52, in run
    result = self.fn(*self.args, **self.kwargs)
TypeError: update() takes 1 positional argument but 2 were given
2021-09-11 19:39:14 WARNING (MainThread) [bellows.zigbee.application] Watchdog heartbeat timeout: 
2021-09-11 19:39:29 WARNING (MainThread) [bellows.zigbee.application] Watchdog heartbeat timeout: 
2021-09-11 19:39:44 WARNING (MainThread) [bellows.zigbee.application] Watchdog heartbeat timeout: 
2021-09-11 19:39:59 WARNING (MainThread) [bellows.zigbee.application] Watchdog heartbeat timeout: 
2021-09-11 19:40:14 WARNING (MainThread) [bellows.zigbee.application] Watchdog heartbeat timeout: 
2021-09-11 19:41:00 WARNING (bellows.thread_0) [bellows.uart] Reset future is None
2021-09-11 19:41:04 ERROR (MainThread) [homeassistant] Error doing job: Future exception was never retrieved
Traceback (most recent call last):
  File "/usr/local/lib/python3.9/concurrent/futures/thread.py", line 52, in run
    result = self.fn(*self.args, **self.kwargs)
TypeError: update() takes 1 positional argument but 2 were given
2021-09-11 19:43:30 ERROR (Thread-5) [homeassistant] Error doing job: Task was destroyed but it is pending!
2021-09-11 19:46:05 ERROR (MainThread) [homeassistant] Error doing job: Future exception was never retrieved
Traceback (most recent call last):
  File "/usr/local/lib/python3.9/concurrent/futures/thread.py", line 52, in run
    result = self.fn(*self.args, **self.kwargs)
TypeError: update() takes 1 positional argument but 2 were given
2021-09-11 19:51:06 ERROR (MainThread) [homeassistant] Error doing job: Future exception was never retrieved
Traceback (most recent call last):
  File "/usr/local/lib/python3.9/concurrent/futures/thread.py", line 52, in run
    result = self.fn(*self.args, **self.kwargs)
TypeError: update() takes 1 positional argument but 2 were given
2021-09-11 19:56:07 ERROR (MainThread) [homeassistant] Error doing job: Future exception was never retrieved
Traceback (most recent call last):
  File "/usr/local/lib/python3.9/concurrent/futures/thread.py", line 52, in run
    result = self.fn(*self.args, **self.kwargs)
TypeError: update() takes 1 positional argument but 2 were given
2021-09-11 20:01:08 ERROR (MainThread) [homeassistant] Error doing job: Future exception was never retrieved
Traceback (most recent call last):
  File "/usr/local/lib/python3.9/concurrent/futures/thread.py", line 52, in run
    result = self.fn(*self.args, **self.kwargs)
TypeError: update() takes 1 positional argument but 2 were given
2021-09-11 20:06:09 ERROR (MainThread) [homeassistant] Error doing job: Future exception was never retrieved
Traceback (most recent call last):
  File "/usr/local/lib/python3.9/concurrent/futures/thread.py", line 52, in run
    result = self.fn(*self.args, **self.kwargs)
TypeError: update() takes 1 positional argument but 2 were given
2021-09-11 20:11:10 ERROR (MainThread) [homeassistant] Error doing job: Future exception was never retrieved
Traceback (most recent call last):
  File "/usr/local/lib/python3.9/concurrent/futures/thread.py", line 52, in run
    result = self.fn(*self.args, **self.kwargs)
TypeError: update() takes 1 positional argument but 2 were given
2021-09-11 20:16:11 ERROR (MainThread) [homeassistant] Error doing job: Future exception was never retrieved
Traceback (most recent call last):
  File "/usr/local/lib/python3.9/concurrent/futures/thread.py", line 52, in run
    result = self.fn(*self.args, **self.kwargs)
TypeError: update() takes 1 positional argument but 2 were given
2021-09-11 20:21:12 ERROR (MainThread) [homeassistant] Error doing job: Future exception was never retrieved
Traceback (most recent call last):
  File "/usr/local/lib/python3.9/concurrent/futures/thread.py", line 52, in run
    result = self.fn(*self.args, **self.kwargs)
TypeError: update() takes 1 positional argument but 2 were given
2021-09-11 20:22:10 ERROR (MainThread) [homeassistant.components.nws] Error requesting NWS observation station SAUC1 data: 503, message='Service Unavailable', url=URL('https://api.weather.gov/stations/SAUC1/observations')
2021-09-11 20:26:13 ERROR (MainThread) [homeassistant] Error doing job: Future exception was never retrieved
Traceback (most recent call last):
  File "/usr/local/lib/python3.9/concurrent/futures/thread.py", line 52, in run
    result = self.fn(*self.args, **self.kwargs)
TypeError: update() takes 1 positional argument but 2 were given
2021-09-11 20:31:14 ERROR (MainThread) [homeassistant] Error doing job: Future exception was never retrieved
Traceback (most recent call last):
  File "/usr/local/lib/python3.9/concurrent/futures/thread.py", line 52, in run
    result = self.fn(*self.args, **self.kwargs)
TypeError: update() takes 1 positional argument but 2 were given
2021-09-11 20:36:15 ERROR (MainThread) [homeassistant] Error doing job: Future exception was never retrieved
Traceback (most recent call last):
  File "/usr/local/lib/python3.9/concurrent/futures/thread.py", line 52, in run
    result = self.fn(*self.args, **self.kwargs)
TypeError: update() takes 1 positional argument but 2 were given
2021-09-11 20:41:16 ERROR (MainThread) [homeassistant] Error doing job: Future exception was never retrieved
Traceback (most recent call last):
  File "/usr/local/lib/python3.9/concurrent/futures/thread.py", line 52, in run
    result = self.fn(*self.args, **self.kwargs)
TypeError: update() takes 1 positional argument but 2 were given
2021-09-11 20:46:17 ERROR (MainThread) [homeassistant] Error doing job: Future exception was never retrieved
Traceback (most recent call last):
  File "/usr/local/lib/python3.9/concurrent/futures/thread.py", line 52, in run
    result = self.fn(*self.args, **self.kwargs)
TypeError: update() takes 1 positional argument but 2 were given
2021-09-11 20:51:18 ERROR (MainThread) [homeassistant] Error doing job: Future exception was never retrieved
Traceback (most recent call last):
  File "/usr/local/lib/python3.9/concurrent/futures/thread.py", line 52, in run
    result = self.fn(*self.args, **self.kwargs)
TypeError: update() takes 1 positional argument but 2 were given
2021-09-11 20:53:20 ERROR (MainThread) [homeassistant.components.nws] Error requesting NWS observation station SAUC1 data: 503, message='Service Unavailable', url=URL('https://api.weather.gov/stations/SAUC1/observations')
2021-09-11 20:56:19 ERROR (MainThread) [homeassistant] Error doing job: Future exception was never retrieved
Traceback (most recent call last):
  File "/usr/local/lib/python3.9/concurrent/futures/thread.py", line 52, in run
    result = self.fn(*self.args, **self.kwargs)
TypeError: update() takes 1 positional argument but 2 were given
2021-09-11 21:01:20 ERROR (MainThread) [homeassistant] Error doing job: Future exception was never retrieved
Traceback (most recent call last):
  File "/usr/local/lib/python3.9/concurrent/futures/thread.py", line 52, in run
    result = self.fn(*self.args, **self.kwargs)
TypeError: update() takes 1 positional argument but 2 were given
2021-09-11 21:06:21 ERROR (MainThread) [homeassistant] Error doing job: Future exception was never retrieved
Traceback (most recent call last):
  File "/usr/local/lib/python3.9/concurrent/futures/thread.py", line 52, in run
    result = self.fn(*self.args, **self.kwargs)
TypeError: update() takes 1 positional argument but 2 were given
2021-09-11 21:11:22 ERROR (MainThread) [homeassistant] Error doing job: Future exception was never retrieved
Traceback (most recent call last):
  File "/usr/local/lib/python3.9/concurrent/futures/thread.py", line 52, in run
    result = self.fn(*self.args, **self.kwargs)
TypeError: update() takes 1 positional argument but 2 were given
2021-09-11 21:16:23 ERROR (MainThread) [homeassistant] Error doing job: Future exception was never retrieved
Traceback (most recent call last):
  File "/usr/local/lib/python3.9/concurrent/futures/thread.py", line 52, in run
    result = self.fn(*self.args, **self.kwargs)
TypeError: update() takes 1 positional argument but 2 were given
2021-09-11 21:21:24 ERROR (MainThread) [homeassistant] Error doing job: Future exception was never retrieved
Traceback (most recent call last):
  File "/usr/local/lib/python3.9/concurrent/futures/thread.py", line 52, in run
    result = self.fn(*self.args, **self.kwargs)
TypeError: update() takes 1 positional argument but 2 were given
2021-09-11 21:24:47 ERROR (MainThread) [homeassistant.components.nws] Error requesting NWS observation station SAUC1 data: 503, message='Service Unavailable', url=URL('https://api.weather.gov/stations/SAUC1/observations')
2021-09-11 21:26:25 ERROR (MainThread) [homeassistant] Error doing job: Future exception was never retrieved
Traceback (most recent call last):
  File "/usr/local/lib/python3.9/concurrent/futures/thread.py", line 52, in run
    result = self.fn(*self.args, **self.kwargs)
TypeError: update() takes 1 positional argument but 2 were given
2021-09-11 21:31:26 ERROR (MainThread) [homeassistant] Error doing job: Future exception was never retrieved
Traceback (most recent call last):
  File "/usr/local/lib/python3.9/concurrent/futures/thread.py", line 52, in run
    result = self.fn(*self.args, **self.kwargs)
TypeError: update() takes 1 positional argument but 2 were given
2021-09-11 21:36:27 ERROR (MainThread) [homeassistant] Error doing job: Future exception was never retrieved
Traceback (most recent call last):
  File "/usr/local/lib/python3.9/concurrent/futures/thread.py", line 52, in run
    result = self.fn(*self.args, **self.kwargs)
TypeError: update() takes 1 positional argument but 2 were given
2021-09-11 21:38:30 WARNING (MainThread) [bellows.zigbee.application] Watchdog heartbeat timeout: 
2021-09-11 21:41:28 ERROR (MainThread) [homeassistant] Error doing job: Future exception was never retrieved
Traceback (most recent call last):
  File "/usr/local/lib/python3.9/concurrent/futures/thread.py", line 52, in run
    result = self.fn(*self.args, **self.kwargs)
TypeError: update() takes 1 positional argument but 2 were given
2021-09-11 21:46:08 ERROR (MainThread) [homeassistant.components.nws] Error requesting NWS observation station SAUC1 data: 503, message='Service Unavailable', url=URL('https://api.weather.gov/stations/SAUC1/observations')
2021-09-11 21:46:29 ERROR (MainThread) [homeassistant] Error doing job: Future exception was never retrieved
Traceback (most recent call last):
  File "/usr/local/lib/python3.9/concurrent/futures/thread.py", line 52, in run
    result = self.fn(*self.args, **self.kwargs)
TypeError: update() takes 1 positional argument but 2 were given
2021-09-11 21:51:30 ERROR (MainThread) [homeassistant] Error doing job: Future exception was never retrieved
Traceback (most recent call last):
  File "/usr/local/lib/python3.9/concurrent/futures/thread.py", line 52, in run
    result = self.fn(*self.args, **self.kwargs)
TypeError: update() takes 1 positional argument but 2 were given
2021-09-11 21:56:31 ERROR (MainThread) [homeassistant] Error doing job: Future exception was never retrieved
Traceback (most recent call last):
  File "/usr/local/lib/python3.9/concurrent/futures/thread.py", line 52, in run
    result = self.fn(*self.args, **self.kwargs)
TypeError: update() takes 1 positional argument but 2 were given
2021-09-11 22:01:32 ERROR (MainThread) [homeassistant] Error doing job: Future exception was never retrieved
Traceback (most recent call last):
  File "/usr/local/lib/python3.9/concurrent/futures/thread.py", line 52, in run
    result = self.fn(*self.args, **self.kwargs)
TypeError: update() takes 1 positional argument but 2 were given
2021-09-11 22:06:33 ERROR (MainThread) [homeassistant] Error doing job: Future exception was never retrieved
Traceback (most recent call last):
  File "/usr/local/lib/python3.9/concurrent/futures/thread.py", line 52, in run
    result = self.fn(*self.args, **self.kwargs)
TypeError: update() takes 1 positional argument but 2 were given
2021-09-11 22:11:34 ERROR (MainThread) [homeassistant] Error doing job: Future exception was never retrieved
Traceback (most recent call last):
  File "/usr/local/lib/python3.9/concurrent/futures/thread.py", line 52, in run
    result = self.fn(*self.args, **self.kwargs)
TypeError: update() takes 1 positional argument but 2 were given
2021-09-11 22:16:35 ERROR (MainThread) [homeassistant] Error doing job: Future exception was never retrieved
Traceback (most recent call last):
  File "/usr/local/lib/python3.9/concurrent/futures/thread.py", line 52, in run
    result = self.fn(*self.args, **self.kwargs)
TypeError: update() takes 1 positional argument but 2 were given
2021-09-11 22:21:36 ERROR (MainThread) [homeassistant] Error doing job: Future exception was never retrieved
Traceback (most recent call last):
  File "/usr/local/lib/python3.9/concurrent/futures/thread.py", line 52, in run
    result = self.fn(*self.args, **self.kwargs)
TypeError: update() takes 1 positional argument but 2 were given
2021-09-11 22:26:37 ERROR (MainThread) [homeassistant] Error doing job: Future exception was never retrieved
Traceback (most recent call last):
  File "/usr/local/lib/python3.9/concurrent/futures/thread.py", line 52, in run
    result = self.fn(*self.args, **self.kwargs)
TypeError: update() takes 1 positional argument but 2 were given
2021-09-11 22:31:38 ERROR (MainThread) [homeassistant] Error doing job: Future exception was never retrieved
Traceback (most recent call last):
  File "/usr/local/lib/python3.9/concurrent/futures/thread.py", line 52, in run
    result = self.fn(*self.args, **self.kwargs)
TypeError: update() takes 1 positional argument but 2 were given
2021-09-11 22:36:39 ERROR (MainThread) [homeassistant] Error doing job: Future exception was never retrieved
Traceback (most recent call last):
  File "/usr/local/lib/python3.9/concurrent/futures/thread.py", line 52, in run
    result = self.fn(*self.args, **self.kwargs)
TypeError: update() takes 1 positional argument but 2 were given
2021-09-11 22:40:22 WARNING (MainThread) [homeassistant.helpers.service] Unable to find referenced entities light.hue_lightstrip_2
2021-09-11 22:41:40 ERROR (MainThread) [homeassistant] Error doing job: Future exception was never retrieved
Traceback (most recent call last):
  File "/usr/local/lib/python3.9/concurrent/futures/thread.py", line 52, in run
    result = self.fn(*self.args, **self.kwargs)
TypeError: update() takes 1 positional argument but 2 were given
2021-09-11 22:46:41 ERROR (MainThread) [homeassistant] Error doing job: Future exception was never retrieved
Traceback (most recent call last):
  File "/usr/local/lib/python3.9/concurrent/futures/thread.py", line 52, in run
    result = self.fn(*self.args, **self.kwargs)
TypeError: update() takes 1 positional argument but 2 were given
2021-09-11 22:51:42 ERROR (MainThread) [homeassistant] Error doing job: Future exception was never retrieved
Traceback (most recent call last):
  File "/usr/local/lib/python3.9/concurrent/futures/thread.py", line 52, in run
    result = self.fn(*self.args, **self.kwargs)
TypeError: update() takes 1 positional argument but 2 were given
2021-09-11 22:56:43 ERROR (MainThread) [homeassistant] Error doing job: Future exception was never retrieved
Traceback (most recent call last):
  File "/usr/local/lib/python3.9/concurrent/futures/thread.py", line 52, in run
    result = self.fn(*self.args, **self.kwargs)
TypeError: update() takes 1 positional argument but 2 were given
2021-09-11 23:00:00 WARNING (MainThread) [homeassistant.helpers.service] Unable to find referenced entities light.sophia_wled
2021-09-11 23:01:44 ERROR (MainThread) [homeassistant] Error doing job: Future exception was never retrieved
Traceback (most recent call last):
  File "/usr/local/lib/python3.9/concurrent/futures/thread.py", line 52, in run
    result = self.fn(*self.args, **self.kwargs)
TypeError: update() takes 1 positional argument but 2 were given
2021-09-11 23:06:45 ERROR (MainThread) [homeassistant] Error doing job: Future exception was never retrieved
Traceback (most recent call last):
  File "/usr/local/lib/python3.9/concurrent/futures/thread.py", line 52, in run
    result = self.fn(*self.args, **self.kwargs)
TypeError: update() takes 1 positional argument but 2 were given
2021-09-11 23:07:19 ERROR (MainThread) [homeassistant.components.nws] Error requesting NWS observation station SAUC1 data: 503, message='Service Unavailable', url=URL('https://api.weather.gov/stations/SAUC1/observations')
2021-09-11 23:11:46 ERROR (MainThread) [homeassistant] Error doing job: Future exception was never retrieved
Traceback (most recent call last):
  File "/usr/local/lib/python3.9/concurrent/futures/thread.py", line 52, in run
    result = self.fn(*self.args, **self.kwargs)
TypeError: update() takes 1 positional argument but 2 were given
2021-09-11 23:16:47 ERROR (MainThread) [homeassistant] Error doing job: Future exception was never retrieved
Traceback (most recent call last):
  File "/usr/local/lib/python3.9/concurrent/futures/thread.py", line 52, in run
    result = self.fn(*self.args, **self.kwargs)
TypeError: update() takes 1 positional argument but 2 were given
2021-09-11 23:17:46 ERROR (MainThread) [homeassistant.components.nws] Error requesting NWS forecast station SAUC1 data: 500, message='Internal Server Error', url=URL('https://api.weather.gov/gridpoints/LOX/146,60/forecast')
2021-09-11 23:21:48 ERROR (MainThread) [homeassistant] Error doing job: Future exception was never retrieved
Traceback (most recent call last):
  File "/usr/local/lib/python3.9/concurrent/futures/thread.py", line 52, in run
    result = self.fn(*self.args, **self.kwargs)
TypeError: update() takes 1 positional argument but 2 were given
2021-09-11 23:26:49 ERROR (MainThread) [homeassistant] Error doing job: Future exception was never retrieved
Traceback (most recent call last):
  File "/usr/local/lib/python3.9/concurrent/futures/thread.py", line 52, in run
    result = self.fn(*self.args, **self.kwargs)
TypeError: update() takes 1 positional argument but 2 were given
2021-09-11 23:31:50 ERROR (MainThread) [homeassistant] Error doing job: Future exception was never retrieved
Traceback (most recent call last):
  File "/usr/local/lib/python3.9/concurrent/futures/thread.py", line 52, in run
    result = self.fn(*self.args, **self.kwargs)
TypeError: update() takes 1 positional argument but 2 were given
2021-09-11 23:36:51 ERROR (MainThread) [homeassistant] Error doing job: Future exception was never retrieved
Traceback (most recent call last):
  File "/usr/local/lib/python3.9/concurrent/futures/thread.py", line 52, in run
    result = self.fn(*self.args, **self.kwargs)
TypeError: update() takes 1 positional argument but 2 were given
2021-09-11 23:41:52 ERROR (MainThread) [homeassistant] Error doing job: Future exception was never retrieved
Traceback (most recent call last):
  File "/usr/local/lib/python3.9/concurrent/futures/thread.py", line 52, in run
    result = self.fn(*self.args, **self.kwargs)
TypeError: update() takes 1 positional argument but 2 were given
2021-09-11 23:46:53 ERROR (MainThread) [homeassistant] Error doing job: Future exception was never retrieved
Traceback (most recent call last):
  File "/usr/local/lib/python3.9/concurrent/futures/thread.py", line 52, in run
    result = self.fn(*self.args, **self.kwargs)
TypeError: update() takes 1 positional argument but 2 were given
2021-09-11 23:51:54 ERROR (MainThread) [homeassistant] Error doing job: Future exception was never retrieved
Traceback (most recent call last):
  File "/usr/local/lib/python3.9/concurrent/futures/thread.py", line 52, in run
    result = self.fn(*self.args, **self.kwargs)
TypeError: update() takes 1 positional argument but 2 were given
2021-09-11 23:56:55 ERROR (MainThread) [homeassistant] Error doing job: Future exception was never retrieved
Traceback (most recent call last):
  File "/usr/local/lib/python3.9/concurrent/futures/thread.py", line 52, in run
    result = self.fn(*self.args, **self.kwargs)
TypeError: update() takes 1 positional argument but 2 were given
2021-09-12 00:00:36 ERROR (MainThread) [iotawattpy.connection] Err: 
2021-09-12 00:00:36 ERROR (MainThread) [homeassistant.components.iotawatt.coordinator] Unexpected error fetching 192.168.20.195 data: 'NoneType' object has no attribute 'text'
Traceback (most recent call last):
  File "/usr/src/homeassistant/homeassistant/helpers/update_coordinator.py", line 187, in _async_refresh
    self.data = await self._async_update_data()
  File "/usr/src/homeassistant/homeassistant/components/iotawatt/coordinator.py", line 55, in _async_update_data
    await self.api.update()
  File "/usr/local/lib/python3.9/site-packages/iotawattpy/iotawatt.py", line 66, in update
    await self._refreshSensors(timespan)
  File "/usr/local/lib/python3.9/site-packages/iotawattpy/iotawatt.py", line 100, in _refreshSensors
    results = response.text
AttributeError: 'NoneType' object has no attribute 'text'
2021-09-12 00:01:56 ERROR (MainThread) [homeassistant] Error doing job: Future exception was never retrieved
Traceback (most recent call last):
  File "/usr/local/lib/python3.9/concurrent/futures/thread.py", line 52, in run
    result = self.fn(*self.args, **self.kwargs)
TypeError: update() takes 1 positional argument but 2 were given
2021-09-12 00:06:57 ERROR (MainThread) [homeassistant] Error doing job: Future exception was never retrieved
Traceback (most recent call last):
  File "/usr/local/lib/python3.9/concurrent/futures/thread.py", line 52, in run
    result = self.fn(*self.args, **self.kwargs)
TypeError: update() takes 1 positional argument but 2 were given
2021-09-12 00:11:58 ERROR (MainThread) [homeassistant] Error doing job: Future exception was never retrieved
Traceback (most recent call last):
  File "/usr/local/lib/python3.9/concurrent/futures/thread.py", line 52, in run
    result = self.fn(*self.args, **self.kwargs)
TypeError: update() takes 1 positional argument but 2 were given
2021-09-12 00:16:59 ERROR (MainThread) [homeassistant] Error doing job: Future exception was never retrieved
Traceback (most recent call last):
  File "/usr/local/lib/python3.9/concurrent/futures/thread.py", line 52, in run
    result = self.fn(*self.args, **self.kwargs)
TypeError: update() takes 1 positional argument but 2 were given
2021-09-12 00:21:25 ERROR (MainThread) [bellows.ezsp] NCP entered failed state. Requesting APP controller restart
2021-09-12 00:21:25 ERROR (MainThread) [bellows.ezsp] NCP entered failed state. Requesting APP controller restart
2021-09-12 00:22:00 ERROR (MainThread) [homeassistant] Error doing job: Future exception was never retrieved
Traceback (most recent call last):
  File "/usr/local/lib/python3.9/concurrent/futures/thread.py", line 52, in run
    result = self.fn(*self.args, **self.kwargs)
TypeError: update() takes 1 positional argument but 2 were given
2021-09-12 00:22:04 WARNING (bellows.thread_0) [bellows.uart] Reset future is None
2021-09-12 00:22:11 WARNING (bellows.thread_0) [bellows.uart] Reset future is None
2021-09-12 00:27:01 ERROR (MainThread) [homeassistant] Error doing job: Future exception was never retrieved
Traceback (most recent call last):
  File "/usr/local/lib/python3.9/concurrent/futures/thread.py", line 52, in run
    result = self.fn(*self.args, **self.kwargs)
TypeError: update() takes 1 positional argument but 2 were given
2021-09-12 00:32:02 ERROR (MainThread) [homeassistant] Error doing job: Future exception was never retrieved
Traceback (most recent call last):
  File "/usr/local/lib/python3.9/concurrent/futures/thread.py", line 52, in run
    result = self.fn(*self.args, **self.kwargs)
TypeError: update() takes 1 positional argument but 2 were given
2021-09-12 00:37:03 ERROR (MainThread) [homeassistant] Error doing job: Future exception was never retrieved
Traceback (most recent call last):
  File "/usr/local/lib/python3.9/concurrent/futures/thread.py", line 52, in run
    result = self.fn(*self.args, **self.kwargs)
TypeError: update() takes 1 positional argument but 2 were given
2021-09-12 00:42:04 ERROR (MainThread) [homeassistant] Error doing job: Future exception was never retrieved
Traceback (most recent call last):
  File "/usr/local/lib/python3.9/concurrent/futures/thread.py", line 52, in run
    result = self.fn(*self.args, **self.kwargs)
TypeError: update() takes 1 positional argument but 2 were given
2021-09-12 00:47:05 ERROR (MainThread) [homeassistant] Error doing job: Future exception was never retrieved
Traceback (most recent call last):
  File "/usr/local/lib/python3.9/concurrent/futures/thread.py", line 52, in run
    result = self.fn(*self.args, **self.kwargs)
TypeError: update() takes 1 positional argument but 2 were given
2021-09-12 00:52:06 ERROR (MainThread) [homeassistant] Error doing job: Future exception was never retrieved
Traceback (most recent call last):
  File "/usr/local/lib/python3.9/concurrent/futures/thread.py", line 52, in run
    result = self.fn(*self.args, **self.kwargs)
TypeError: update() takes 1 positional argument but 2 were given
2021-09-12 00:57:07 ERROR (MainThread) [homeassistant] Error doing job: Future exception was never retrieved
Traceback (most recent call last):
  File "/usr/local/lib/python3.9/concurrent/futures/thread.py", line 52, in run
    result = self.fn(*self.args, **self.kwargs)
TypeError: update() takes 1 positional argument but 2 were given
2021-09-12 01:02:08 ERROR (MainThread) [homeassistant] Error doing job: Future exception was never retrieved
Traceback (most recent call last):
  File "/usr/local/lib/python3.9/concurrent/futures/thread.py", line 52, in run
    result = self.fn(*self.args, **self.kwargs)
TypeError: update() takes 1 positional argument but 2 were given
2021-09-12 01:07:09 ERROR (MainThread) [homeassistant] Error doing job: Future exception was never retrieved
Traceback (most recent call last):
  File "/usr/local/lib/python3.9/concurrent/futures/thread.py", line 52, in run
    result = self.fn(*self.args, **self.kwargs)
TypeError: update() takes 1 positional argument but 2 were given
2021-09-12 01:12:10 ERROR (MainThread) [homeassistant] Error doing job: Future exception was never retrieved
Traceback (most recent call last):
  File "/usr/local/lib/python3.9/concurrent/futures/thread.py", line 52, in run
    result = self.fn(*self.args, **self.kwargs)
TypeError: update() takes 1 positional argument but 2 were given
2021-09-12 01:17:11 ERROR (MainThread) [homeassistant] Error doing job: Future exception was never retrieved
Traceback (most recent call last):
  File "/usr/local/lib/python3.9/concurrent/futures/thread.py", line 52, in run
    result = self.fn(*self.args, **self.kwargs)
TypeError: update() takes 1 positional argument but 2 were given
2021-09-12 01:22:12 ERROR (MainThread) [homeassistant] Error doing job: Future exception was never retrieved
Traceback (most recent call last):
  File "/usr/local/lib/python3.9/concurrent/futures/thread.py", line 52, in run
    result = self.fn(*self.args, **self.kwargs)
TypeError: update() takes 1 positional argument but 2 were given
2021-09-12 01:27:13 ERROR (MainThread) [homeassistant] Error doing job: Future exception was never retrieved
Traceback (most recent call last):
  File "/usr/local/lib/python3.9/concurrent/futures/thread.py", line 52, in run
    result = self.fn(*self.args, **self.kwargs)
TypeError: update() takes 1 positional argument but 2 were given
2021-09-12 01:32:14 ERROR (MainThread) [homeassistant] Error doing job: Future exception was never retrieved
Traceback (most recent call last):
  File "/usr/local/lib/python3.9/concurrent/futures/thread.py", line 52, in run
    result = self.fn(*self.args, **self.kwargs)
TypeError: update() takes 1 positional argument but 2 were given
2021-09-12 01:37:15 ERROR (MainThread) [homeassistant] Error doing job: Future exception was never retrieved
Traceback (most recent call last):
  File "/usr/local/lib/python3.9/concurrent/futures/thread.py", line 52, in run
    result = self.fn(*self.args, **self.kwargs)
TypeError: update() takes 1 positional argument but 2 were given
2021-09-12 01:42:16 ERROR (MainThread) [homeassistant] Error doing job: Future exception was never retrieved
Traceback (most recent call last):
  File "/usr/local/lib/python3.9/concurrent/futures/thread.py", line 52, in run
    result = self.fn(*self.args, **self.kwargs)
TypeError: update() takes 1 positional argument but 2 were given
2021-09-12 01:47:17 ERROR (MainThread) [homeassistant] Error doing job: Future exception was never retrieved
Traceback (most recent call last):
  File "/usr/local/lib/python3.9/concurrent/futures/thread.py", line 52, in run
    result = self.fn(*self.args, **self.kwargs)
TypeError: update() takes 1 positional argument but 2 were given
2021-09-12 01:52:18 ERROR (MainThread) [homeassistant] Error doing job: Future exception was never retrieved
Traceback (most recent call last):
  File "/usr/local/lib/python3.9/concurrent/futures/thread.py", line 52, in run
    result = self.fn(*self.args, **self.kwargs)
TypeError: update() takes 1 positional argument but 2 were given
2021-09-12 01:57:19 ERROR (MainThread) [homeassistant] Error doing job: Future exception was never retrieved
Traceback (most recent call last):
  File "/usr/local/lib/python3.9/concurrent/futures/thread.py", line 52, in run
    result = self.fn(*self.args, **self.kwargs)
TypeError: update() takes 1 positional argument but 2 were given
2021-09-12 02:02:20 ERROR (MainThread) [homeassistant] Error doing job: Future exception was never retrieved
Traceback (most recent call last):
  File "/usr/local/lib/python3.9/concurrent/futures/thread.py", line 52, in run
    result = self.fn(*self.args, **self.kwargs)
TypeError: update() takes 1 positional argument but 2 were given
2021-09-12 02:07:21 ERROR (MainThread) [homeassistant] Error doing job: Future exception was never retrieved
Traceback (most recent call last):
  File "/usr/local/lib/python3.9/concurrent/futures/thread.py", line 52, in run
    result = self.fn(*self.args, **self.kwargs)
TypeError: update() takes 1 positional argument but 2 were given
2021-09-12 02:12:22 ERROR (MainThread) [homeassistant] Error doing job: Future exception was never retrieved
Traceback (most recent call last):
  File "/usr/local/lib/python3.9/concurrent/futures/thread.py", line 52, in run
    result = self.fn(*self.args, **self.kwargs)
TypeError: update() takes 1 positional argument but 2 were given
2021-09-12 02:17:23 ERROR (MainThread) [homeassistant] Error doing job: Future exception was never retrieved
Traceback (most recent call last):
  File "/usr/local/lib/python3.9/concurrent/futures/thread.py", line 52, in run
    result = self.fn(*self.args, **self.kwargs)
TypeError: update() takes 1 positional argument but 2 were given
2021-09-12 02:22:24 ERROR (MainThread) [homeassistant] Error doing job: Future exception was never retrieved
Traceback (most recent call last):
  File "/usr/local/lib/python3.9/concurrent/futures/thread.py", line 52, in run
    result = self.fn(*self.args, **self.kwargs)
TypeError: update() takes 1 positional argument but 2 were given
2021-09-12 02:24:41 WARNING (Thread-9) [pychromecast.socket_client] [Kitchen speaker(192.168.20.124):8009] Heartbeat timeout, resetting connection
2021-09-12 02:27:25 ERROR (MainThread) [homeassistant] Error doing job: Future exception was never retrieved
Traceback (most recent call last):
  File "/usr/local/lib/python3.9/concurrent/futures/thread.py", line 52, in run
    result = self.fn(*self.args, **self.kwargs)
TypeError: update() takes 1 positional argument but 2 were given
2021-09-12 02:32:26 ERROR (MainThread) [homeassistant] Error doing job: Future exception was never retrieved
Traceback (most recent call last):
  File "/usr/local/lib/python3.9/concurrent/futures/thread.py", line 52, in run
    result = self.fn(*self.args, **self.kwargs)
TypeError: update() takes 1 positional argument but 2 were given
2021-09-12 02:37:27 ERROR (MainThread) [homeassistant] Error doing job: Future exception was never retrieved
Traceback (most recent call last):
  File "/usr/local/lib/python3.9/concurrent/futures/thread.py", line 52, in run
    result = self.fn(*self.args, **self.kwargs)
TypeError: update() takes 1 positional argument but 2 were given
2021-09-12 02:42:28 ERROR (MainThread) [homeassistant] Error doing job: Future exception was never retrieved
Traceback (most recent call last):
  File "/usr/local/lib/python3.9/concurrent/futures/thread.py", line 52, in run
    result = self.fn(*self.args, **self.kwargs)
TypeError: update() takes 1 positional argument but 2 were given
2021-09-12 02:47:29 ERROR (MainThread) [homeassistant] Error doing job: Future exception was never retrieved
Traceback (most recent call last):
  File "/usr/local/lib/python3.9/concurrent/futures/thread.py", line 52, in run
    result = self.fn(*self.args, **self.kwargs)
TypeError: update() takes 1 positional argument but 2 were given
2021-09-12 02:52:30 ERROR (MainThread) [homeassistant] Error doing job: Future exception was never retrieved
Traceback (most recent call last):
  File "/usr/local/lib/python3.9/concurrent/futures/thread.py", line 52, in run
    result = self.fn(*self.args, **self.kwargs)
TypeError: update() takes 1 positional argument but 2 were given
2021-09-12 02:57:31 ERROR (MainThread) [homeassistant] Error doing job: Future exception was never retrieved
Traceback (most recent call last):
  File "/usr/local/lib/python3.9/concurrent/futures/thread.py", line 52, in run
    result = self.fn(*self.args, **self.kwargs)
TypeError: update() takes 1 positional argument but 2 were given
