2021-09-04 03:16:53 WARNING (SyncWorker_0) [homeassistant.loader] We found a custom integration sun2 which has not been tested by Home Assistant. This component might cause stability problems, be sure to disable it if you experience issues with Home Assistant
2021-09-04 03:17:00 WARNING (Recorder) [homeassistant.components.recorder.util] The system could not validate that the sqlite3 database at //config/home-assistant_v2.db was shutdown cleanly
2021-09-04 03:17:03 WARNING (MainThread) [homeassistant.components.webhook] Received message for unregistered webhook f06d1a61aa5c38a342b6db71f8743e282e529f663d9b996d12cd72ba7b7e2f35 from cloud
2021-09-04 03:17:03 WARNING (MainThread) [homeassistant.components.webhook] Received message for unregistered webhook f06d1a61aa5c38a342b6db71f8743e282e529f663d9b996d12cd72ba7b7e2f35 from cloud
2021-09-04 03:17:07 ERROR (MainThread) [snitun.client.client_peer] Challenge/Response error with SniTun server
2021-09-04 03:17:07 ERROR (MainThread) [hass_nabucasa.remote] Connection problem to snitun server
2021-09-04 03:17:09 WARNING (MainThread) [homeassistant.config_entries] Config entry 'Roku Smart Soundbar' for roku integration not ready yet: Invalid response from API: Error occurred while communicating with device; Retrying in background
2021-09-04 03:17:10 WARNING (MainThread) [homeassistant.components.sensor] Entity sensor.cpu_temp (<class 'homeassistant.components.command_line.sensor.CommandSensor'>) with device_class None reports a temperature in °C which will be converted to °F. Temperature conversion for entities without correct device_class is deprecated and will be removed from Home Assistant Core 2022.3. Please update your configuration if device_class is manually configured, otherwise create a bug report at https://github.com/home-assistant/core/issues?q=is%3Aopen+is%3Aissue+label%3A%22integration%3A+command_line%22
2021-09-04 03:17:15 WARNING (MainThread) [homeassistant.config_entries] Config entry '192.168.7.195' for wled integration not ready yet: Invalid response from API: Error occurred while communicating with WLED device at 192.168.7.195; Retrying in background
2021-09-04 03:17:17 ERROR (MainThread) [homeassistant.components.snmp.sensor] Please check the details in the configuration file
2021-09-04 03:17:17 ERROR (MainThread) [homeassistant.components.snmp.sensor] Please check the details in the configuration file
2021-09-04 03:17:17 ERROR (MainThread) [homeassistant.components.snmp.sensor] Please check the details in the configuration file
2021-09-04 03:17:17 ERROR (MainThread) [homeassistant.components.snmp.sensor] Please check the details in the configuration file
2021-09-04 03:17:17 ERROR (MainThread) [homeassistant.components.snmp.sensor] Please check the details in the configuration file
2021-09-04 03:18:06 WARNING (MainThread) [homeassistant.bootstrap] Waiting on integrations to complete setup: forecast_solar
2021-09-04 03:18:44 WARNING (MainThread) [homeassistant.components.sensor] Entity sensor.garagesidedoorsensor_bme280_dewpoint (<class 'homeassistant.components.tasmota.sensor.TasmotaSensor'>) with device_class None reports a temperature in °C which will be converted to °F. Temperature conversion for entities without correct device_class is deprecated and will be removed from Home Assistant Core 2022.3. Please update your configuration if device_class is manually configured, otherwise create a bug report at https://github.com/home-assistant/core/issues?q=is%3Aopen+is%3Aissue+label%3A%22integration%3A+tasmota%22
2021-09-04 03:18:45 WARNING (MainThread) [homeassistant.components.sensor] Entity sensor.attictemp1_bme280_dewpoint (<class 'homeassistant.components.tasmota.sensor.TasmotaSensor'>) with device_class None reports a temperature in °C which will be converted to °F. Temperature conversion for entities without correct device_class is deprecated and will be removed from Home Assistant Core 2022.3. Please update your configuration if device_class is manually configured, otherwise create a bug report at https://github.com/home-assistant/core/issues?q=is%3Aopen+is%3Aissue+label%3A%22integration%3A+tasmota%22
2021-09-04 03:19:06 WARNING (MainThread) [homeassistant.bootstrap] Waiting on integrations to complete setup: forecast_solar
2021-09-04 03:19:16 WARNING (MainThread) [homeassistant.config_entries] Config entry 'Cerezo House HA' for forecast_solar integration not ready yet: Cannot connect to host 91.228.53.233:443 ssl:False [Connect call failed ('91.228.53.233', 443)]; Retrying in background
2021-09-04 03:19:16 WARNING (MainThread) [homeassistant.config_entries] Config entry 'Cerezo House HA' for forecast_solar integration not ready yet: Cannot connect to host 91.228.53.233:443 ssl:False [Connect call failed ('91.228.53.233', 443)]; Retrying in background
2021-09-04 03:20:49 WARNING (MainThread) [homeassistant.components.template.template_entity] Template loop detected while processing event: <Event state_changed[L]: entity_id=sensor.sensor_count, old_state=<state sensor.sensor_count=400; friendly_name=Number of Sensors @ 2021-09-04T03:20:46.873140-07:00>, new_state=<state sensor.sensor_count=416; friendly_name=Number of Sensors @ 2021-09-04T03:20:47.873127-07:00>>, skipping template render for Template[{{ states.sensor | rejectattr('state', 'eq', 'unavailable') | list | count }}]
2021-09-04 03:21:16 WARNING (MainThread) [homeassistant.components.template.template_entity] Template loop detected while processing event: <Event state_changed[L]: entity_id=sensor.entities_count, old_state=<state sensor.entities_count=685; friendly_name=Number of Entities @ 2021-09-04T03:19:16.567828-07:00>, new_state=<state sensor.entities_count=731; friendly_name=Number of Entities @ 2021-09-04T03:20:16.623454-07:00>>, skipping template render for Template[{{ states | rejectattr('state', 'eq', 'unavailable') | list | count}}]
2021-09-04 03:22:03 ERROR (MainThread) [homeassistant] Error doing job: Future exception was never retrieved
Traceback (most recent call last):
  File "/usr/local/lib/python3.9/concurrent/futures/thread.py", line 52, in run
    result = self.fn(*self.args, **self.kwargs)
TypeError: update() takes 1 positional argument but 2 were given
2021-09-04 03:27:04 ERROR (MainThread) [homeassistant] Error doing job: Future exception was never retrieved
Traceback (most recent call last):
  File "/usr/local/lib/python3.9/concurrent/futures/thread.py", line 52, in run
    result = self.fn(*self.args, **self.kwargs)
TypeError: update() takes 1 positional argument but 2 were given
2021-09-04 03:32:05 ERROR (MainThread) [homeassistant] Error doing job: Future exception was never retrieved
Traceback (most recent call last):
  File "/usr/local/lib/python3.9/concurrent/futures/thread.py", line 52, in run
    result = self.fn(*self.args, **self.kwargs)
TypeError: update() takes 1 positional argument but 2 were given
2021-09-04 03:35:29 WARNING (Thread-15) [pychromecast.socket_client] [Bedroom_Sophia speaker(192.168.20.60):8009] Heartbeat timeout, resetting connection
2021-09-04 03:35:31 ERROR (Thread-15) [pychromecast.socket_client] [Bedroom_Sophia speaker(192.168.20.60):8009] Failed to connect to service ServiceInfo(type='host', data=('192.168.20.60', 8009)), retrying in 5.0s
2021-09-04 03:37:06 ERROR (MainThread) [homeassistant] Error doing job: Future exception was never retrieved
Traceback (most recent call last):
  File "/usr/local/lib/python3.9/concurrent/futures/thread.py", line 52, in run
    result = self.fn(*self.args, **self.kwargs)
TypeError: update() takes 1 positional argument but 2 were given
2021-09-04 03:42:07 ERROR (MainThread) [homeassistant] Error doing job: Future exception was never retrieved
Traceback (most recent call last):
  File "/usr/local/lib/python3.9/concurrent/futures/thread.py", line 52, in run
    result = self.fn(*self.args, **self.kwargs)
TypeError: update() takes 1 positional argument but 2 were given
2021-09-04 03:47:08 ERROR (MainThread) [homeassistant] Error doing job: Future exception was never retrieved
Traceback (most recent call last):
  File "/usr/local/lib/python3.9/concurrent/futures/thread.py", line 52, in run
    result = self.fn(*self.args, **self.kwargs)
TypeError: update() takes 1 positional argument but 2 were given
2021-09-04 03:52:09 ERROR (MainThread) [homeassistant] Error doing job: Future exception was never retrieved
Traceback (most recent call last):
  File "/usr/local/lib/python3.9/concurrent/futures/thread.py", line 52, in run
    result = self.fn(*self.args, **self.kwargs)
TypeError: update() takes 1 positional argument but 2 were given
2021-09-04 03:57:10 ERROR (MainThread) [homeassistant] Error doing job: Future exception was never retrieved
Traceback (most recent call last):
  File "/usr/local/lib/python3.9/concurrent/futures/thread.py", line 52, in run
    result = self.fn(*self.args, **self.kwargs)
TypeError: update() takes 1 positional argument but 2 were given
2021-09-04 04:02:11 ERROR (MainThread) [homeassistant] Error doing job: Future exception was never retrieved
Traceback (most recent call last):
  File "/usr/local/lib/python3.9/concurrent/futures/thread.py", line 52, in run
    result = self.fn(*self.args, **self.kwargs)
TypeError: update() takes 1 positional argument but 2 were given
2021-09-04 04:07:12 ERROR (MainThread) [homeassistant] Error doing job: Future exception was never retrieved
Traceback (most recent call last):
  File "/usr/local/lib/python3.9/concurrent/futures/thread.py", line 52, in run
    result = self.fn(*self.args, **self.kwargs)
TypeError: update() takes 1 positional argument but 2 were given
2021-09-04 04:12:13 ERROR (MainThread) [homeassistant] Error doing job: Future exception was never retrieved
Traceback (most recent call last):
  File "/usr/local/lib/python3.9/concurrent/futures/thread.py", line 52, in run
    result = self.fn(*self.args, **self.kwargs)
TypeError: update() takes 1 positional argument but 2 were given
2021-09-04 04:17:14 ERROR (MainThread) [homeassistant] Error doing job: Future exception was never retrieved
Traceback (most recent call last):
  File "/usr/local/lib/python3.9/concurrent/futures/thread.py", line 52, in run
    result = self.fn(*self.args, **self.kwargs)
TypeError: update() takes 1 positional argument but 2 were given
2021-09-04 04:22:15 ERROR (MainThread) [homeassistant] Error doing job: Future exception was never retrieved
Traceback (most recent call last):
  File "/usr/local/lib/python3.9/concurrent/futures/thread.py", line 52, in run
    result = self.fn(*self.args, **self.kwargs)
TypeError: update() takes 1 positional argument but 2 were given
2021-09-04 04:22:51 WARNING (Thread-10) [pychromecast.socket_client] [Kitchen speaker(192.168.20.124):8009] Heartbeat timeout, resetting connection
2021-09-04 04:23:21 ERROR (Thread-10) [pychromecast.socket_client] [Kitchen speaker(192.168.20.124):8009] Failed to connect to service ServiceInfo(type='host', data=('192.168.20.124', 8009)), retrying in 5.0s
2021-09-04 04:27:16 ERROR (MainThread) [homeassistant] Error doing job: Future exception was never retrieved
Traceback (most recent call last):
  File "/usr/local/lib/python3.9/concurrent/futures/thread.py", line 52, in run
    result = self.fn(*self.args, **self.kwargs)
TypeError: update() takes 1 positional argument but 2 were given
2021-09-04 04:32:17 ERROR (MainThread) [homeassistant] Error doing job: Future exception was never retrieved
Traceback (most recent call last):
  File "/usr/local/lib/python3.9/concurrent/futures/thread.py", line 52, in run
    result = self.fn(*self.args, **self.kwargs)
TypeError: update() takes 1 positional argument but 2 were given
2021-09-04 04:37:18 ERROR (MainThread) [homeassistant] Error doing job: Future exception was never retrieved
Traceback (most recent call last):
  File "/usr/local/lib/python3.9/concurrent/futures/thread.py", line 52, in run
    result = self.fn(*self.args, **self.kwargs)
TypeError: update() takes 1 positional argument but 2 were given
2021-09-04 04:42:19 ERROR (MainThread) [homeassistant] Error doing job: Future exception was never retrieved
Traceback (most recent call last):
  File "/usr/local/lib/python3.9/concurrent/futures/thread.py", line 52, in run
    result = self.fn(*self.args, **self.kwargs)
TypeError: update() takes 1 positional argument but 2 were given
2021-09-04 04:42:20 WARNING (Thread-14) [pychromecast.socket_client] [Office_Brian speaker(192.168.20.247):8009] Heartbeat timeout, resetting connection
2021-09-04 04:42:36 ERROR (Thread-14) [pychromecast.socket_client] [Office_Brian speaker(192.168.20.247):8009] Failed to connect to service ServiceInfo(type='host', data=('192.168.20.247', 8009)), retrying in 5.0s
2021-09-04 04:47:20 ERROR (MainThread) [homeassistant] Error doing job: Future exception was never retrieved
Traceback (most recent call last):
  File "/usr/local/lib/python3.9/concurrent/futures/thread.py", line 52, in run
    result = self.fn(*self.args, **self.kwargs)
TypeError: update() takes 1 positional argument but 2 were given
2021-09-04 04:52:21 ERROR (MainThread) [homeassistant] Error doing job: Future exception was never retrieved
Traceback (most recent call last):
  File "/usr/local/lib/python3.9/concurrent/futures/thread.py", line 52, in run
    result = self.fn(*self.args, **self.kwargs)
TypeError: update() takes 1 positional argument but 2 were given
2021-09-04 04:57:22 ERROR (MainThread) [homeassistant] Error doing job: Future exception was never retrieved
Traceback (most recent call last):
  File "/usr/local/lib/python3.9/concurrent/futures/thread.py", line 52, in run
    result = self.fn(*self.args, **self.kwargs)
TypeError: update() takes 1 positional argument but 2 were given
2021-09-04 05:02:23 ERROR (MainThread) [homeassistant] Error doing job: Future exception was never retrieved
Traceback (most recent call last):
  File "/usr/local/lib/python3.9/concurrent/futures/thread.py", line 52, in run
    result = self.fn(*self.args, **self.kwargs)
TypeError: update() takes 1 positional argument but 2 were given
2021-09-04 05:07:24 ERROR (MainThread) [homeassistant] Error doing job: Future exception was never retrieved
Traceback (most recent call last):
  File "/usr/local/lib/python3.9/concurrent/futures/thread.py", line 52, in run
    result = self.fn(*self.args, **self.kwargs)
TypeError: update() takes 1 positional argument but 2 were given
2021-09-04 05:07:25 ERROR (MainThread) [homeassistant.components.nws] Error requesting NWS observation station SAUC1 data: 503, message='Service Unavailable', url=URL('https://api.weather.gov/stations/SAUC1/observations')
2021-09-04 05:12:25 ERROR (MainThread) [homeassistant] Error doing job: Future exception was never retrieved
Traceback (most recent call last):
  File "/usr/local/lib/python3.9/concurrent/futures/thread.py", line 52, in run
    result = self.fn(*self.args, **self.kwargs)
TypeError: update() takes 1 positional argument but 2 were given
2021-09-04 05:17:26 ERROR (MainThread) [homeassistant] Error doing job: Future exception was never retrieved
Traceback (most recent call last):
  File "/usr/local/lib/python3.9/concurrent/futures/thread.py", line 52, in run
    result = self.fn(*self.args, **self.kwargs)
TypeError: update() takes 1 positional argument but 2 were given
2021-09-04 05:21:27 ERROR (stream_worker) [libav.rtsp] method DESCRIBE failed: 404 Not Found
2021-09-04 05:21:27 ERROR (stream_worker) [homeassistant.components.stream.worker] Error opening stream rtsps://stream-uc2-bravo.dropcam.com:443/sdm_live_stream/CiQA2vuxr7lokMie-K08g-QCWPm8feXufXtZDbWaBEV2w2bpT0kScQBQBG8tcd6RJCCSx63sLVahEhg5kqmwsAudRkZdRBYfX2lQt8torI-AmpJoCjDWNvP8iCDRYNu04Yl4RfELOeTk3ld5Y1c8l_Emm20aba_QWUaTUUC5xIaZRryPHgvfdt2ODS7dZ5fWh_j0txJhft3e?auth=g.0.eyJraWQiOiIyMzhiNTUxZmMyM2EyM2Y4M2E2ZTE3MmJjZTg0YmU3ZjgxMzAzMmM4IiwiYWxnIjoiUlMyNTYifQ.eyJpc3MiOiJuZXN0LXNlY3VyaXR5LWF1dGhwcm94eSIsInN1YiI6Im5lc3RfaWQ6bmVzdC1waG9lbml4LXByb2Q6MjEyMTgxNDEiLCJwb2wiOiIzcC1vYXV0aC1zY29wZS1BUElfU0RNX1NFUlZJQ0UtY2xpZW50LTIwMjQyNzMxODczNS1qNXQ5bWMyMzZqaG85YXMycWY0dTZxY3NmYW1kaGJ0ci5hcHBzLmdvb2dsZXVzZXJjb250ZW50LmNvbSIsImV4cCI6MTYzMDc1ODM2NX0.kf-NfwDM-72711GbLaWP5vf-mQTFYmGfJ1ZbTiaYyu1byyeHrktZocSB0D2A-W2-fI2bf4zUTplJvfO0I3czjTSkaq-l6Y4Eg6bSBOoLzkSEEdUASsEO7-53uK5MnLpGXgyR-jPhpr7O6mfr0_axEioegBxPjFe6gKlopCOrFTwwtRjh55oKuoGIllyD2EQIV8sVRouVeqO3i-sCCE1Ax36eVlNQt2m8o_nQeNaOzy9MAYym-5nH1NLJIuDf0dzbuqMORtZKD8w9FvnkP0HPwxFX02CyzKCYbrIdJzvw2YzNPuObLfFtU2O7S0Srs7K4gZjOCNrLJO6pvISXrZ_2oA
2021-09-04 05:21:53 ERROR (stream_worker) [libav.rtsp] method DESCRIBE failed: 404 Not Found
2021-09-04 05:21:53 ERROR (stream_worker) [homeassistant.components.stream.worker] Error opening stream rtsps://stream-uc2-bravo.dropcam.com:443/sdm_live_stream/CiQA2vuxr7lokMie-K08g-QCWPm8feXufXtZDbWaBEV2w2bpT0kScQBQBG8tcd6RJCCSx63sLVahEhg5kqmwsAudRkZdRBYfX2lQt8torI-AmpJoCjDWNvP8iCDRYNu04Yl4RfELOeTk3ld5Y1c8l_Emm20aba_QWUaTUUC5xIaZRryPHgvfdt2ODS7dZ5fWh_j0txJhft3e?auth=g.0.eyJraWQiOiIyMzhiNTUxZmMyM2EyM2Y4M2E2ZTE3MmJjZTg0YmU3ZjgxMzAzMmM4IiwiYWxnIjoiUlMyNTYifQ.eyJpc3MiOiJuZXN0LXNlY3VyaXR5LWF1dGhwcm94eSIsInN1YiI6Im5lc3RfaWQ6bmVzdC1waG9lbml4LXByb2Q6MjEyMTgxNDEiLCJwb2wiOiIzcC1vYXV0aC1zY29wZS1BUElfU0RNX1NFUlZJQ0UtY2xpZW50LTIwMjQyNzMxODczNS1qNXQ5bWMyMzZqaG85YXMycWY0dTZxY3NmYW1kaGJ0ci5hcHBzLmdvb2dsZXVzZXJjb250ZW50LmNvbSIsImV4cCI6MTYzMDc1ODM2NX0.kf-NfwDM-72711GbLaWP5vf-mQTFYmGfJ1ZbTiaYyu1byyeHrktZocSB0D2A-W2-fI2bf4zUTplJvfO0I3czjTSkaq-l6Y4Eg6bSBOoLzkSEEdUASsEO7-53uK5MnLpGXgyR-jPhpr7O6mfr0_axEioegBxPjFe6gKlopCOrFTwwtRjh55oKuoGIllyD2EQIV8sVRouVeqO3i-sCCE1Ax36eVlNQt2m8o_nQeNaOzy9MAYym-5nH1NLJIuDf0dzbuqMORtZKD8w9FvnkP0HPwxFX02CyzKCYbrIdJzvw2YzNPuObLfFtU2O7S0Srs7K4gZjOCNrLJO6pvISXrZ_2oA
2021-09-04 05:22:27 ERROR (MainThread) [homeassistant] Error doing job: Future exception was never retrieved
Traceback (most recent call last):
  File "/usr/local/lib/python3.9/concurrent/futures/thread.py", line 52, in run
    result = self.fn(*self.args, **self.kwargs)
TypeError: update() takes 1 positional argument but 2 were given
2021-09-04 05:25:43 WARNING (stream_worker) [homeassistant.components.stream.worker] Audio stream not found
2021-09-04 05:27:28 ERROR (MainThread) [homeassistant] Error doing job: Future exception was never retrieved
Traceback (most recent call last):
  File "/usr/local/lib/python3.9/concurrent/futures/thread.py", line 52, in run
    result = self.fn(*self.args, **self.kwargs)
TypeError: update() takes 1 positional argument but 2 were given
2021-09-04 05:32:29 ERROR (MainThread) [homeassistant] Error doing job: Future exception was never retrieved
Traceback (most recent call last):
  File "/usr/local/lib/python3.9/concurrent/futures/thread.py", line 52, in run
    result = self.fn(*self.args, **self.kwargs)
TypeError: update() takes 1 positional argument but 2 were given
2021-09-04 05:37:30 ERROR (MainThread) [homeassistant] Error doing job: Future exception was never retrieved
Traceback (most recent call last):
  File "/usr/local/lib/python3.9/concurrent/futures/thread.py", line 52, in run
    result = self.fn(*self.args, **self.kwargs)
TypeError: update() takes 1 positional argument but 2 were given
2021-09-04 05:42:31 ERROR (MainThread) [homeassistant] Error doing job: Future exception was never retrieved
Traceback (most recent call last):
  File "/usr/local/lib/python3.9/concurrent/futures/thread.py", line 52, in run
    result = self.fn(*self.args, **self.kwargs)
TypeError: update() takes 1 positional argument but 2 were given
2021-09-04 05:47:32 ERROR (MainThread) [homeassistant] Error doing job: Future exception was never retrieved
Traceback (most recent call last):
  File "/usr/local/lib/python3.9/concurrent/futures/thread.py", line 52, in run
    result = self.fn(*self.args, **self.kwargs)
TypeError: update() takes 1 positional argument but 2 were given
2021-09-04 05:48:41 ERROR (stream_worker) [libav.rtsp] method DESCRIBE failed: 404 Not Found
2021-09-04 05:48:41 ERROR (stream_worker) [homeassistant.components.stream.worker] Error opening stream rtsps://stream-uc2-bravo.dropcam.com:443/sdm_live_stream/CiQA2vuxr7lokMie-K08g-QCWPm8feXufXtZDbWaBEV2w2bpT0kScQBQBG8tcd6RJCCSx63sLVahEhg5kqmwsAudRkZdRBYfX2lQt8torI-AmpJoCjDWNvP8iCDRYNu04Yl4RfELOeTk3ld5Y1c8l_Emm20aba_QWUaTUUC5xIaZRryPHgvfdt2ODS7dZ5fWh_j0txJhft3e?auth=g.0.eyJraWQiOiIyMzhiNTUxZmMyM2EyM2Y4M2E2ZTE3MmJjZTg0YmU3ZjgxMzAzMmM4IiwiYWxnIjoiUlMyNTYifQ.eyJpc3MiOiJuZXN0LXNlY3VyaXR5LWF1dGhwcm94eSIsInN1YiI6Im5lc3RfaWQ6bmVzdC1waG9lbml4LXByb2Q6MjEyMTgxNDEiLCJwb2wiOiIzcC1vYXV0aC1zY29wZS1BUElfU0RNX1NFUlZJQ0UtY2xpZW50LTIwMjQyNzMxODczNS1qNXQ5bWMyMzZqaG85YXMycWY0dTZxY3NmYW1kaGJ0ci5hcHBzLmdvb2dsZXVzZXJjb250ZW50LmNvbSIsImV4cCI6MTYzMDc1OTk4OH0.b7OiRV4yGBrWeK_hNe7FPPnt5JuFZP6JkTQt7E6OaDKsHasHz8EBzhuEmUghcA6Ryy70GrL6nQeHgDmZ9DBDcXFz5ih81Zlis-LbDJwB_gflwiYVJIJcKazqL4cGN8IrJHRECRLgoFVL1R3F_Z6wmSiUOb01imD5o0_wfFrhAfXPKQZ1wwjUIroFelHbAZKKo5Yc3_y_yhrIe6qNgEjkvC6nk1NChUykpR-lxPwosyM0L-8h6J_DBBFc9ndbI95K6_Txwwg8UELI5-09r7PLR_4g3td9BtUbfhauARHOYiNtZpYJ8VBBH_trvtAfjCxbaGwhysYIzjff_jiNHdyRog
2021-09-04 05:49:22 ERROR (stream_worker) [libav.rtsp] method DESCRIBE failed: 404 Not Found
2021-09-04 05:49:22 ERROR (stream_worker) [homeassistant.components.stream.worker] Error opening stream rtsps://stream-uc2-bravo.dropcam.com:443/sdm_live_stream/CiQA2vuxr7lokMie-K08g-QCWPm8feXufXtZDbWaBEV2w2bpT0kScQBQBG8tcd6RJCCSx63sLVahEhg5kqmwsAudRkZdRBYfX2lQt8torI-AmpJoCjDWNvP8iCDRYNu04Yl4RfELOeTk3ld5Y1c8l_Emm20aba_QWUaTUUC5xIaZRryPHgvfdt2ODS7dZ5fWh_j0txJhft3e?auth=g.0.eyJraWQiOiIyMzhiNTUxZmMyM2EyM2Y4M2E2ZTE3MmJjZTg0YmU3ZjgxMzAzMmM4IiwiYWxnIjoiUlMyNTYifQ.eyJpc3MiOiJuZXN0LXNlY3VyaXR5LWF1dGhwcm94eSIsInN1YiI6Im5lc3RfaWQ6bmVzdC1waG9lbml4LXByb2Q6MjEyMTgxNDEiLCJwb2wiOiIzcC1vYXV0aC1zY29wZS1BUElfU0RNX1NFUlZJQ0UtY2xpZW50LTIwMjQyNzMxODczNS1qNXQ5bWMyMzZqaG85YXMycWY0dTZxY3NmYW1kaGJ0ci5hcHBzLmdvb2dsZXVzZXJjb250ZW50LmNvbSIsImV4cCI6MTYzMDc1OTk4OH0.b7OiRV4yGBrWeK_hNe7FPPnt5JuFZP6JkTQt7E6OaDKsHasHz8EBzhuEmUghcA6Ryy70GrL6nQeHgDmZ9DBDcXFz5ih81Zlis-LbDJwB_gflwiYVJIJcKazqL4cGN8IrJHRECRLgoFVL1R3F_Z6wmSiUOb01imD5o0_wfFrhAfXPKQZ1wwjUIroFelHbAZKKo5Yc3_y_yhrIe6qNgEjkvC6nk1NChUykpR-lxPwosyM0L-8h6J_DBBFc9ndbI95K6_Txwwg8UELI5-09r7PLR_4g3td9BtUbfhauARHOYiNtZpYJ8VBBH_trvtAfjCxbaGwhysYIzjff_jiNHdyRog
2021-09-04 05:50:14 ERROR (stream_worker) [libav.rtsp] method DESCRIBE failed: 404 Not Found
2021-09-04 05:50:14 ERROR (stream_worker) [homeassistant.components.stream.worker] Error opening stream rtsps://stream-uc2-bravo.dropcam.com:443/sdm_live_stream/CiQA2vuxr7lokMie-K08g-QCWPm8feXufXtZDbWaBEV2w2bpT0kScQBQBG8tcd6RJCCSx63sLVahEhg5kqmwsAudRkZdRBYfX2lQt8torI-AmpJoCjDWNvP8iCDRYNu04Yl4RfELOeTk3ld5Y1c8l_Emm20aba_QWUaTUUC5xIaZRryPHgvfdt2ODS7dZ5fWh_j0txJhft3e?auth=g.0.eyJraWQiOiIyMzhiNTUxZmMyM2EyM2Y4M2E2ZTE3MmJjZTg0YmU3ZjgxMzAzMmM4IiwiYWxnIjoiUlMyNTYifQ.eyJpc3MiOiJuZXN0LXNlY3VyaXR5LWF1dGhwcm94eSIsInN1YiI6Im5lc3RfaWQ6bmVzdC1waG9lbml4LXByb2Q6MjEyMTgxNDEiLCJwb2wiOiIzcC1vYXV0aC1zY29wZS1BUElfU0RNX1NFUlZJQ0UtY2xpZW50LTIwMjQyNzMxODczNS1qNXQ5bWMyMzZqaG85YXMycWY0dTZxY3NmYW1kaGJ0ci5hcHBzLmdvb2dsZXVzZXJjb250ZW50LmNvbSIsImV4cCI6MTYzMDc1OTk4OH0.b7OiRV4yGBrWeK_hNe7FPPnt5JuFZP6JkTQt7E6OaDKsHasHz8EBzhuEmUghcA6Ryy70GrL6nQeHgDmZ9DBDcXFz5ih81Zlis-LbDJwB_gflwiYVJIJcKazqL4cGN8IrJHRECRLgoFVL1R3F_Z6wmSiUOb01imD5o0_wfFrhAfXPKQZ1wwjUIroFelHbAZKKo5Yc3_y_yhrIe6qNgEjkvC6nk1NChUykpR-lxPwosyM0L-8h6J_DBBFc9ndbI95K6_Txwwg8UELI5-09r7PLR_4g3td9BtUbfhauARHOYiNtZpYJ8VBBH_trvtAfjCxbaGwhysYIzjff_jiNHdyRog
2021-09-04 05:52:33 ERROR (MainThread) [homeassistant] Error doing job: Future exception was never retrieved
Traceback (most recent call last):
  File "/usr/local/lib/python3.9/concurrent/futures/thread.py", line 52, in run
    result = self.fn(*self.args, **self.kwargs)
TypeError: update() takes 1 positional argument but 2 were given
2021-09-04 05:54:01 ERROR (stream_worker) [homeassistant.components.stream.worker] Error opening stream rtsps://stream-uc2-bravo.dropcam.com:443/sdm_live_stream/CiQA2vuxr7lokMie-K08g-QCWPm8feXufXtZDbWaBEV2w2bpT0kScQBQBG8tcd6RJCCSx63sLVahEhg5kqmwsAudRkZdRBYfX2lQt8torI-AmpJoCjDWNvP8iCDRYNu04Yl4RfELOeTk3ld5Y1c8l_Emm20aba_QWUaTUUC5xIaZRryPHgvfdt2ODS7dZ5fWh_j0txJhft3e?auth=g.0.eyJraWQiOiIyMzhiNTUxZmMyM2EyM2Y4M2E2ZTE3MmJjZTg0YmU3ZjgxMzAzMmM4IiwiYWxnIjoiUlMyNTYifQ.eyJpc3MiOiJuZXN0LXNlY3VyaXR5LWF1dGhwcm94eSIsInN1YiI6Im5lc3RfaWQ6bmVzdC1waG9lbml4LXByb2Q6MjEyMTgxNDEiLCJwb2wiOiIzcC1vYXV0aC1zY29wZS1BUElfU0RNX1NFUlZJQ0UtY2xpZW50LTIwMjQyNzMxODczNS1qNXQ5bWMyMzZqaG85YXMycWY0dTZxY3NmYW1kaGJ0ci5hcHBzLmdvb2dsZXVzZXJjb250ZW50LmNvbSIsImV4cCI6MTYzMDc2MDI1OX0.hT9YedlYRhw0I3r0X_p0X9TUzk0JxVx1Tj7wccasscj2103_IlQonw80FxCfFU86GpJJCW847FgpWyDEbDR7i0hh-1aYbMgEiCbytAsKeC_t1OZh6xKL3TLxiUK62_pPV-D7K5Vka9y-aXqUcIPAjP5PVJBYP5K4H7EEdAzGI5gWZW8Ngtb_U8sIR_sXnIfF9D1SaRlt0vArOF5tgleb1lZleD3A_JoT-7MkyQnMjGTTa0yfU4zKLDUXamgJsjJp5tQH6j4KW4B6CR5Y-KEB1fiJtuvO6Z29jh0RPogI26DoOQ66ZRL4x_6Kw4v6Pg7Gk57w7_uFQ7k0eBYjtnh1OQ
2021-09-04 05:57:34 ERROR (MainThread) [homeassistant] Error doing job: Future exception was never retrieved
Traceback (most recent call last):
  File "/usr/local/lib/python3.9/concurrent/futures/thread.py", line 52, in run
    result = self.fn(*self.args, **self.kwargs)
TypeError: update() takes 1 positional argument but 2 were given
2021-09-04 06:02:35 ERROR (MainThread) [homeassistant] Error doing job: Future exception was never retrieved
Traceback (most recent call last):
  File "/usr/local/lib/python3.9/concurrent/futures/thread.py", line 52, in run
    result = self.fn(*self.args, **self.kwargs)
TypeError: update() takes 1 positional argument but 2 were given
2021-09-04 06:07:36 ERROR (MainThread) [homeassistant] Error doing job: Future exception was never retrieved
Traceback (most recent call last):
  File "/usr/local/lib/python3.9/concurrent/futures/thread.py", line 52, in run
    result = self.fn(*self.args, **self.kwargs)
TypeError: update() takes 1 positional argument but 2 were given
2021-09-04 06:12:37 ERROR (MainThread) [homeassistant] Error doing job: Future exception was never retrieved
Traceback (most recent call last):
  File "/usr/local/lib/python3.9/concurrent/futures/thread.py", line 52, in run
    result = self.fn(*self.args, **self.kwargs)
TypeError: update() takes 1 positional argument but 2 were given
2021-09-04 06:17:38 ERROR (MainThread) [homeassistant] Error doing job: Future exception was never retrieved
Traceback (most recent call last):
  File "/usr/local/lib/python3.9/concurrent/futures/thread.py", line 52, in run
    result = self.fn(*self.args, **self.kwargs)
TypeError: update() takes 1 positional argument but 2 were given
2021-09-04 06:22:39 ERROR (MainThread) [homeassistant] Error doing job: Future exception was never retrieved
Traceback (most recent call last):
  File "/usr/local/lib/python3.9/concurrent/futures/thread.py", line 52, in run
    result = self.fn(*self.args, **self.kwargs)
TypeError: update() takes 1 positional argument but 2 were given
2021-09-04 06:27:40 ERROR (MainThread) [homeassistant] Error doing job: Future exception was never retrieved
Traceback (most recent call last):
  File "/usr/local/lib/python3.9/concurrent/futures/thread.py", line 52, in run
    result = self.fn(*self.args, **self.kwargs)
TypeError: update() takes 1 positional argument but 2 were given
2021-09-04 06:28:02 ERROR (stream_worker) [libav.tls] The specified session has been invalidated for some reason.
2021-09-04 06:28:02 ERROR (stream_worker) [homeassistant.components.stream.worker] Error demuxing stream: 
2021-09-04 06:28:06 ERROR (stream_worker) [libav.tls] The specified session has been invalidated for some reason.
2021-09-04 06:29:55 ERROR (stream_worker) [libav.rtsp] method DESCRIBE failed: 404 Not Found
2021-09-04 06:29:55 ERROR (stream_worker) [homeassistant.components.stream.worker] Error opening stream rtsps://stream-uc2-bravo.dropcam.com:443/sdm_live_stream/CiQA2vuxr7lokMie-K08g-QCWPm8feXufXtZDbWaBEV2w2bpT0kScQBQBG8tcd6RJCCSx63sLVahEhg5kqmwsAudRkZdRBYfX2lQt8torI-AmpJoCjDWNvP8iCDRYNu04Yl4RfELOeTk3ld5Y1c8l_Emm20aba_QWUaTUUC5xIaZRryPHgvfdt2ODS7dZ5fWh_j0txJhft3e?auth=g.0.eyJraWQiOiIyMzhiNTUxZmMyM2EyM2Y4M2E2ZTE3MmJjZTg0YmU3ZjgxMzAzMmM4IiwiYWxnIjoiUlMyNTYifQ.eyJpc3MiOiJuZXN0LXNlY3VyaXR5LWF1dGhwcm94eSIsInN1YiI6Im5lc3RfaWQ6bmVzdC1waG9lbml4LXByb2Q6MjEyMTgxNDEiLCJwb2wiOiIzcC1vYXV0aC1zY29wZS1BUElfU0RNX1NFUlZJQ0UtY2xpZW50LTIwMjQyNzMxODczNS1qNXQ5bWMyMzZqaG85YXMycWY0dTZxY3NmYW1kaGJ0ci5hcHBzLmdvb2dsZXVzZXJjb250ZW50LmNvbSIsImV4cCI6MTYzMDc2MjQyNH0.KEg8jHgnDQjrxr3l7PO4bbKmiFDdYKvSRN3x583_xPMo3GelKC4-DjKWZ8KKPduEM5NAs8iDWl49Ku5UpQMPKgSb7XJXAvJjatTj8k744idZ6VwXTZK1QtDrR7v9SyhKi-0PJv9SZTAXQANFBk-8KSAP4rNwQBTuKPDUTf5rCz-TqE6dWAqu1CKGSnuYt6hzUxse5XwlnPMY4kehNxQEBqtSOOd2EPck9AGoUixu3eT4LtfZqueHgpn24M-omqpzl_2RHnHqecg2Ep4goY2yw5-PuLT8M4846S4NH6Gb18C5zoGG_fV1UMVcprxdUXeZdSbcrTcnTrYKWZ1QpQaJog
2021-09-04 06:30:04 WARNING (MainThread) [homeassistant.helpers.service] Unable to find referenced entities scene.kitchen_sink_off
2021-09-04 06:32:41 ERROR (MainThread) [homeassistant] Error doing job: Future exception was never retrieved
Traceback (most recent call last):
  File "/usr/local/lib/python3.9/concurrent/futures/thread.py", line 52, in run
    result = self.fn(*self.args, **self.kwargs)
TypeError: update() takes 1 positional argument but 2 were given
2021-09-04 06:33:36 ERROR (stream_worker) [libav.rtsp] method DESCRIBE failed: 404 Not Found
2021-09-04 06:33:36 ERROR (stream_worker) [homeassistant.components.stream.worker] Error opening stream rtsps://stream-uc2-delta.dropcam.com:443/sdm_live_stream/CiQA2vuxrxgUe66wV8PzCqYwd49FXyOZ1xkH8MXvQXcYv6j0Nl8ScQBQBG8tiSo9CBLjErdwWc3nFE6es0dCX7VcZ6mU9GkFjYuQ5S6t3GfIyBb1zd8txbwMqkuKLT4liYxofz1yKAf6J8mV0HYmnNbZaPNL9fkL9Q6Ahy9SNTifPW_1bhK3CZUPhDH79F0yossm0YkyhcxY?auth=g.0.eyJraWQiOiIyMzhiNTUxZmMyM2EyM2Y4M2E2ZTE3MmJjZTg0YmU3ZjgxMzAzMmM4IiwiYWxnIjoiUlMyNTYifQ.eyJpc3MiOiJuZXN0LXNlY3VyaXR5LWF1dGhwcm94eSIsInN1YiI6Im5lc3RfaWQ6bmVzdC1waG9lbml4LXByb2Q6MjEyMTgxNDEiLCJwb2wiOiIzcC1vYXV0aC1zY29wZS1BUElfU0RNX1NFUlZJQ0UtY2xpZW50LTIwMjQyNzMxODczNS1qNXQ5bWMyMzZqaG85YXMycWY0dTZxY3NmYW1kaGJ0ci5hcHBzLmdvb2dsZXVzZXJjb250ZW50LmNvbSIsImV4cCI6MTYzMDc2MjY5NH0.hmvFouWEIZ6GKd7rmZC5VTggZCFFlgRsPqUUuTniEXD6aZd3lt95aVwrspqvClsv9oClH6g673MN2SxMhk6f9W1WKu7-eRaM6IsZKw_kkPXrkWI6Vwohv2I5wAG9OkzK9e6OVyxiTStXofVmTZDFRiCNg8NveNFzUG2ZZ29LOZWry--ZI_Irqz8wRhRQ7PXs9Fi7lAZztdqh5rc97PnxAz9QBvS7mBvsJVYLsXk_Plv4L3dp0Ol_YriDv_kG9AUv3v4_W5dmpsJtc25MLa0l-hUBmIgsbs4jH-eHd0O6CLbWtQc0jvcwXwiwJthXUDuj6wi9eBXWHE8atvCWjLr1sQ
2021-09-04 06:34:07 ERROR (stream_worker) [libav.rtsp] method DESCRIBE failed: 404 Not Found
2021-09-04 06:34:07 ERROR (stream_worker) [homeassistant.components.stream.worker] Error opening stream rtsps://stream-uc2-delta.dropcam.com:443/sdm_live_stream/CiQA2vuxrxgUe66wV8PzCqYwd49FXyOZ1xkH8MXvQXcYv6j0Nl8ScQBQBG8tiSo9CBLjErdwWc3nFE6es0dCX7VcZ6mU9GkFjYuQ5S6t3GfIyBb1zd8txbwMqkuKLT4liYxofz1yKAf6J8mV0HYmnNbZaPNL9fkL9Q6Ahy9SNTifPW_1bhK3CZUPhDH79F0yossm0YkyhcxY?auth=g.0.eyJraWQiOiIyMzhiNTUxZmMyM2EyM2Y4M2E2ZTE3MmJjZTg0YmU3ZjgxMzAzMmM4IiwiYWxnIjoiUlMyNTYifQ.eyJpc3MiOiJuZXN0LXNlY3VyaXR5LWF1dGhwcm94eSIsInN1YiI6Im5lc3RfaWQ6bmVzdC1waG9lbml4LXByb2Q6MjEyMTgxNDEiLCJwb2wiOiIzcC1vYXV0aC1zY29wZS1BUElfU0RNX1NFUlZJQ0UtY2xpZW50LTIwMjQyNzMxODczNS1qNXQ5bWMyMzZqaG85YXMycWY0dTZxY3NmYW1kaGJ0ci5hcHBzLmdvb2dsZXVzZXJjb250ZW50LmNvbSIsImV4cCI6MTYzMDc2MjY5NH0.hmvFouWEIZ6GKd7rmZC5VTggZCFFlgRsPqUUuTniEXD6aZd3lt95aVwrspqvClsv9oClH6g673MN2SxMhk6f9W1WKu7-eRaM6IsZKw_kkPXrkWI6Vwohv2I5wAG9OkzK9e6OVyxiTStXofVmTZDFRiCNg8NveNFzUG2ZZ29LOZWry--ZI_Irqz8wRhRQ7PXs9Fi7lAZztdqh5rc97PnxAz9QBvS7mBvsJVYLsXk_Plv4L3dp0Ol_YriDv_kG9AUv3v4_W5dmpsJtc25MLa0l-hUBmIgsbs4jH-eHd0O6CLbWtQc0jvcwXwiwJthXUDuj6wi9eBXWHE8atvCWjLr1sQ
2021-09-04 06:34:49 ERROR (stream_worker) [libav.rtsp] method DESCRIBE failed: 404 Not Found
2021-09-04 06:34:49 ERROR (stream_worker) [homeassistant.components.stream.worker] Error opening stream rtsps://stream-uc2-delta.dropcam.com:443/sdm_live_stream/CiQA2vuxrxgUe66wV8PzCqYwd49FXyOZ1xkH8MXvQXcYv6j0Nl8ScQBQBG8tiSo9CBLjErdwWc3nFE6es0dCX7VcZ6mU9GkFjYuQ5S6t3GfIyBb1zd8txbwMqkuKLT4liYxofz1yKAf6J8mV0HYmnNbZaPNL9fkL9Q6Ahy9SNTifPW_1bhK3CZUPhDH79F0yossm0YkyhcxY?auth=g.0.eyJraWQiOiIyMzhiNTUxZmMyM2EyM2Y4M2E2ZTE3MmJjZTg0YmU3ZjgxMzAzMmM4IiwiYWxnIjoiUlMyNTYifQ.eyJpc3MiOiJuZXN0LXNlY3VyaXR5LWF1dGhwcm94eSIsInN1YiI6Im5lc3RfaWQ6bmVzdC1waG9lbml4LXByb2Q6MjEyMTgxNDEiLCJwb2wiOiIzcC1vYXV0aC1zY29wZS1BUElfU0RNX1NFUlZJQ0UtY2xpZW50LTIwMjQyNzMxODczNS1qNXQ5bWMyMzZqaG85YXMycWY0dTZxY3NmYW1kaGJ0ci5hcHBzLmdvb2dsZXVzZXJjb250ZW50LmNvbSIsImV4cCI6MTYzMDc2MjY5NH0.hmvFouWEIZ6GKd7rmZC5VTggZCFFlgRsPqUUuTniEXD6aZd3lt95aVwrspqvClsv9oClH6g673MN2SxMhk6f9W1WKu7-eRaM6IsZKw_kkPXrkWI6Vwohv2I5wAG9OkzK9e6OVyxiTStXofVmTZDFRiCNg8NveNFzUG2ZZ29LOZWry--ZI_Irqz8wRhRQ7PXs9Fi7lAZztdqh5rc97PnxAz9QBvS7mBvsJVYLsXk_Plv4L3dp0Ol_YriDv_kG9AUv3v4_W5dmpsJtc25MLa0l-hUBmIgsbs4jH-eHd0O6CLbWtQc0jvcwXwiwJthXUDuj6wi9eBXWHE8atvCWjLr1sQ
2021-09-04 06:35:42 ERROR (stream_worker) [libav.rtsp] method DESCRIBE failed: 404 Not Found
2021-09-04 06:35:42 ERROR (stream_worker) [homeassistant.components.stream.worker] Error opening stream rtsps://stream-uc2-delta.dropcam.com:443/sdm_live_stream/CiQA2vuxrxgUe66wV8PzCqYwd49FXyOZ1xkH8MXvQXcYv6j0Nl8ScQBQBG8tiSo9CBLjErdwWc3nFE6es0dCX7VcZ6mU9GkFjYuQ5S6t3GfIyBb1zd8txbwMqkuKLT4liYxofz1yKAf6J8mV0HYmnNbZaPNL9fkL9Q6Ahy9SNTifPW_1bhK3CZUPhDH79F0yossm0YkyhcxY?auth=g.0.eyJraWQiOiIyMzhiNTUxZmMyM2EyM2Y4M2E2ZTE3MmJjZTg0YmU3ZjgxMzAzMmM4IiwiYWxnIjoiUlMyNTYifQ.eyJpc3MiOiJuZXN0LXNlY3VyaXR5LWF1dGhwcm94eSIsInN1YiI6Im5lc3RfaWQ6bmVzdC1waG9lbml4LXByb2Q6MjEyMTgxNDEiLCJwb2wiOiIzcC1vYXV0aC1zY29wZS1BUElfU0RNX1NFUlZJQ0UtY2xpZW50LTIwMjQyNzMxODczNS1qNXQ5bWMyMzZqaG85YXMycWY0dTZxY3NmYW1kaGJ0ci5hcHBzLmdvb2dsZXVzZXJjb250ZW50LmNvbSIsImV4cCI6MTYzMDc2MjY5NH0.hmvFouWEIZ6GKd7rmZC5VTggZCFFlgRsPqUUuTniEXD6aZd3lt95aVwrspqvClsv9oClH6g673MN2SxMhk6f9W1WKu7-eRaM6IsZKw_kkPXrkWI6Vwohv2I5wAG9OkzK9e6OVyxiTStXofVmTZDFRiCNg8NveNFzUG2ZZ29LOZWry--ZI_Irqz8wRhRQ7PXs9Fi7lAZztdqh5rc97PnxAz9QBvS7mBvsJVYLsXk_Plv4L3dp0Ol_YriDv_kG9AUv3v4_W5dmpsJtc25MLa0l-hUBmIgsbs4jH-eHd0O6CLbWtQc0jvcwXwiwJthXUDuj6wi9eBXWHE8atvCWjLr1sQ
2021-09-04 06:36:44 ERROR (stream_worker) [homeassistant.components.stream.worker] Stream has no video
2021-09-04 06:37:42 ERROR (MainThread) [homeassistant] Error doing job: Future exception was never retrieved
Traceback (most recent call last):
  File "/usr/local/lib/python3.9/concurrent/futures/thread.py", line 52, in run
    result = self.fn(*self.args, **self.kwargs)
TypeError: update() takes 1 positional argument but 2 were given
2021-09-04 06:42:43 ERROR (MainThread) [homeassistant] Error doing job: Future exception was never retrieved
Traceback (most recent call last):
  File "/usr/local/lib/python3.9/concurrent/futures/thread.py", line 52, in run
    result = self.fn(*self.args, **self.kwargs)
TypeError: update() takes 1 positional argument but 2 were given
2021-09-04 06:43:37 ERROR (stream_worker) [libav.rtsp] method DESCRIBE failed: 404 Not Found
2021-09-04 06:43:37 ERROR (stream_worker) [homeassistant.components.stream.worker] Error opening stream rtsps://stream-uc2-bravo.dropcam.com:443/sdm_live_stream/CiQA2vuxr7lokMie-K08g-QCWPm8feXufXtZDbWaBEV2w2bpT0kScQBQBG8tcd6RJCCSx63sLVahEhg5kqmwsAudRkZdRBYfX2lQt8torI-AmpJoCjDWNvP8iCDRYNu04Yl4RfELOeTk3ld5Y1c8l_Emm20aba_QWUaTUUC5xIaZRryPHgvfdt2ODS7dZ5fWh_j0txJhft3e?auth=g.0.eyJraWQiOiIyMzhiNTUxZmMyM2EyM2Y4M2E2ZTE3MmJjZTg0YmU3ZjgxMzAzMmM4IiwiYWxnIjoiUlMyNTYifQ.eyJpc3MiOiJuZXN0LXNlY3VyaXR5LWF1dGhwcm94eSIsInN1YiI6Im5lc3RfaWQ6bmVzdC1waG9lbml4LXByb2Q6MjEyMTgxNDEiLCJwb2wiOiIzcC1vYXV0aC1zY29wZS1BUElfU0RNX1NFUlZJQ0UtY2xpZW50LTIwMjQyNzMxODczNS1qNXQ5bWMyMzZqaG85YXMycWY0dTZxY3NmYW1kaGJ0ci5hcHBzLmdvb2dsZXVzZXJjb250ZW50LmNvbSIsImV4cCI6MTYzMDc2MzIzNn0.hbdtBzyJT9VRoqkNbBFLUPKRcHbeL5IbWY2OuCuRtgsgUYE3pHIMKCLGfXL7nNcIeXh2FWOpEcJ1MPg55ND2JMT-YSFqZUmL9S-SWsh-cE7dnNoW6JyTKkAAu00Zqy4gKIT6DrG1lL1gswptUTkkxa_HRt3sAe46Er6mdZQaMTAX2Eqj5c-HjtDHkFQAxmeuxe7lLy7Cbabl_9ViTDhWQpCYtlOOXFvHrtpCreKu2FCJiFQRdQW0K9ScE-dRg02dpx8hKhVgmJm9oyjKGvBomr9f9PQnhushxSZiJI0h4HMilBAEM8n5MuRKxhcPqZBRkDJKVdCcFMJyqzwnzv3USw
2021-09-04 06:45:54 ERROR (stream_worker) [libav.tls] The specified session has been invalidated for some reason.
2021-09-04 06:45:54 ERROR (stream_worker) [homeassistant.components.stream.worker] Error demuxing stream: 
2021-09-04 06:45:56 ERROR (stream_worker) [libav.tls] The specified session has been invalidated for some reason.
2021-09-04 06:47:44 ERROR (MainThread) [homeassistant] Error doing job: Future exception was never retrieved
Traceback (most recent call last):
  File "/usr/local/lib/python3.9/concurrent/futures/thread.py", line 52, in run
    result = self.fn(*self.args, **self.kwargs)
TypeError: update() takes 1 positional argument but 2 were given
2021-09-04 06:52:45 ERROR (MainThread) [homeassistant] Error doing job: Future exception was never retrieved
Traceback (most recent call last):
  File "/usr/local/lib/python3.9/concurrent/futures/thread.py", line 52, in run
    result = self.fn(*self.args, **self.kwargs)
TypeError: update() takes 1 positional argument but 2 were given
2021-09-04 06:57:46 ERROR (MainThread) [homeassistant] Error doing job: Future exception was never retrieved
Traceback (most recent call last):
  File "/usr/local/lib/python3.9/concurrent/futures/thread.py", line 52, in run
    result = self.fn(*self.args, **self.kwargs)
TypeError: update() takes 1 positional argument but 2 were given
2021-09-04 07:02:47 ERROR (MainThread) [homeassistant] Error doing job: Future exception was never retrieved
Traceback (most recent call last):
  File "/usr/local/lib/python3.9/concurrent/futures/thread.py", line 52, in run
    result = self.fn(*self.args, **self.kwargs)
TypeError: update() takes 1 positional argument but 2 were given
2021-09-04 07:07:48 ERROR (MainThread) [homeassistant] Error doing job: Future exception was never retrieved
Traceback (most recent call last):
  File "/usr/local/lib/python3.9/concurrent/futures/thread.py", line 52, in run
    result = self.fn(*self.args, **self.kwargs)
TypeError: update() takes 1 positional argument but 2 were given
2021-09-04 07:12:49 ERROR (MainThread) [homeassistant] Error doing job: Future exception was never retrieved
Traceback (most recent call last):
  File "/usr/local/lib/python3.9/concurrent/futures/thread.py", line 52, in run
    result = self.fn(*self.args, **self.kwargs)
TypeError: update() takes 1 positional argument but 2 were given
2021-09-04 07:17:50 ERROR (MainThread) [homeassistant] Error doing job: Future exception was never retrieved
Traceback (most recent call last):
  File "/usr/local/lib/python3.9/concurrent/futures/thread.py", line 52, in run
    result = self.fn(*self.args, **self.kwargs)
TypeError: update() takes 1 positional argument but 2 were given
2021-09-04 07:22:51 ERROR (MainThread) [homeassistant] Error doing job: Future exception was never retrieved
Traceback (most recent call last):
  File "/usr/local/lib/python3.9/concurrent/futures/thread.py", line 52, in run
    result = self.fn(*self.args, **self.kwargs)
TypeError: update() takes 1 positional argument but 2 were given
2021-09-04 07:27:52 ERROR (MainThread) [homeassistant] Error doing job: Future exception was never retrieved
Traceback (most recent call last):
  File "/usr/local/lib/python3.9/concurrent/futures/thread.py", line 52, in run
    result = self.fn(*self.args, **self.kwargs)
TypeError: update() takes 1 positional argument but 2 were given
2021-09-04 07:32:53 ERROR (MainThread) [homeassistant] Error doing job: Future exception was never retrieved
Traceback (most recent call last):
  File "/usr/local/lib/python3.9/concurrent/futures/thread.py", line 52, in run
    result = self.fn(*self.args, **self.kwargs)
TypeError: update() takes 1 positional argument but 2 were given
2021-09-04 07:37:54 ERROR (MainThread) [homeassistant] Error doing job: Future exception was never retrieved
Traceback (most recent call last):
  File "/usr/local/lib/python3.9/concurrent/futures/thread.py", line 52, in run
    result = self.fn(*self.args, **self.kwargs)
TypeError: update() takes 1 positional argument but 2 were given
2021-09-04 07:42:28 ERROR (stream_worker) [libav.rtsp] method DESCRIBE failed: 404 Not Found
2021-09-04 07:42:28 ERROR (stream_worker) [homeassistant.components.stream.worker] Error opening stream rtsps://stream-uc2-bravo.dropcam.com:443/sdm_live_stream/CiQA2vuxr7lokMie-K08g-QCWPm8feXufXtZDbWaBEV2w2bpT0kScQBQBG8tcd6RJCCSx63sLVahEhg5kqmwsAudRkZdRBYfX2lQt8torI-AmpJoCjDWNvP8iCDRYNu04Yl4RfELOeTk3ld5Y1c8l_Emm20aba_QWUaTUUC5xIaZRryPHgvfdt2ODS7dZ5fWh_j0txJhft3e?auth=g.0.eyJraWQiOiIyMzhiNTUxZmMyM2EyM2Y4M2E2ZTE3MmJjZTg0YmU3ZjgxMzAzMmM4IiwiYWxnIjoiUlMyNTYifQ.eyJpc3MiOiJuZXN0LXNlY3VyaXR5LWF1dGhwcm94eSIsInN1YiI6Im5lc3RfaWQ6bmVzdC1waG9lbml4LXByb2Q6MjEyMTgxNDEiLCJwb2wiOiIzcC1vYXV0aC1zY29wZS1BUElfU0RNX1NFUlZJQ0UtY2xpZW50LTIwMjQyNzMxODczNS1qNXQ5bWMyMzZqaG85YXMycWY0dTZxY3NmYW1kaGJ0ci5hcHBzLmdvb2dsZXVzZXJjb250ZW50LmNvbSIsImV4cCI6MTYzMDc2Njc1Nn0.hlSwsFtPqqfQQJJC4LQ7cQXSK-9mI1w_IZaysnspxL8NKKn9WdLQ49gNR_QauifYUwXADcfrPf4UKbkgAYrOm2dPX4iRF8cMp7ZHAMv3jDfzbjppWoJV-PQ-oFAvTVrMRx4w5im4gcQ9CcmhRaXCRkvqgZZ01qaUwIWGCpOUjiLObLOa5He9RXYQXHA8SvUBVbN-_mcMm57D3MutCDyOvapUSdhM6SaWLOlMLH5eO3gr0UPsIKI1_Fk3V9tRzeAxodfqUTINPxUsycIJVqNdbRNGYMZPs-TtTjMVRQVIs3tD4f1_mnFDIpucvY0ncA9GmmPkce_FoCLCbl4AQzwuzw
2021-09-04 07:42:55 ERROR (MainThread) [homeassistant] Error doing job: Future exception was never retrieved
Traceback (most recent call last):
  File "/usr/local/lib/python3.9/concurrent/futures/thread.py", line 52, in run
    result = self.fn(*self.args, **self.kwargs)
TypeError: update() takes 1 positional argument but 2 were given
2021-09-04 07:47:56 ERROR (MainThread) [homeassistant] Error doing job: Future exception was never retrieved
Traceback (most recent call last):
  File "/usr/local/lib/python3.9/concurrent/futures/thread.py", line 52, in run
    result = self.fn(*self.args, **self.kwargs)
TypeError: update() takes 1 positional argument but 2 were given
2021-09-04 07:52:57 ERROR (MainThread) [homeassistant] Error doing job: Future exception was never retrieved
Traceback (most recent call last):
  File "/usr/local/lib/python3.9/concurrent/futures/thread.py", line 52, in run
    result = self.fn(*self.args, **self.kwargs)
TypeError: update() takes 1 positional argument but 2 were given
2021-09-04 07:57:12 ERROR (MainThread) [homeassistant.components.nws] Error requesting NWS forecast station SAUC1 data: 500, message='Internal Server Error', url=URL('https://api.weather.gov/gridpoints/LOX/146,60/forecast')
2021-09-04 07:57:58 ERROR (MainThread) [homeassistant] Error doing job: Future exception was never retrieved
Traceback (most recent call last):
  File "/usr/local/lib/python3.9/concurrent/futures/thread.py", line 52, in run
    result = self.fn(*self.args, **self.kwargs)
TypeError: update() takes 1 positional argument but 2 were given
2021-09-04 08:02:59 ERROR (MainThread) [homeassistant] Error doing job: Future exception was never retrieved
Traceback (most recent call last):
  File "/usr/local/lib/python3.9/concurrent/futures/thread.py", line 52, in run
    result = self.fn(*self.args, **self.kwargs)
TypeError: update() takes 1 positional argument but 2 were given
2021-09-04 08:08:00 ERROR (MainThread) [homeassistant] Error doing job: Future exception was never retrieved
Traceback (most recent call last):
  File "/usr/local/lib/python3.9/concurrent/futures/thread.py", line 52, in run
    result = self.fn(*self.args, **self.kwargs)
TypeError: update() takes 1 positional argument but 2 were given
2021-09-04 08:13:01 ERROR (MainThread) [homeassistant] Error doing job: Future exception was never retrieved
Traceback (most recent call last):
  File "/usr/local/lib/python3.9/concurrent/futures/thread.py", line 52, in run
    result = self.fn(*self.args, **self.kwargs)
TypeError: update() takes 1 positional argument but 2 were given
2021-09-04 08:18:02 ERROR (MainThread) [homeassistant] Error doing job: Future exception was never retrieved
Traceback (most recent call last):
  File "/usr/local/lib/python3.9/concurrent/futures/thread.py", line 52, in run
    result = self.fn(*self.args, **self.kwargs)
TypeError: update() takes 1 positional argument but 2 were given
2021-09-04 08:23:03 ERROR (MainThread) [homeassistant] Error doing job: Future exception was never retrieved
Traceback (most recent call last):
  File "/usr/local/lib/python3.9/concurrent/futures/thread.py", line 52, in run
    result = self.fn(*self.args, **self.kwargs)
TypeError: update() takes 1 positional argument but 2 were given
2021-09-04 08:28:04 ERROR (MainThread) [homeassistant] Error doing job: Future exception was never retrieved
Traceback (most recent call last):
  File "/usr/local/lib/python3.9/concurrent/futures/thread.py", line 52, in run
    result = self.fn(*self.args, **self.kwargs)
TypeError: update() takes 1 positional argument but 2 were given
2021-09-04 08:33:05 ERROR (MainThread) [homeassistant] Error doing job: Future exception was never retrieved
Traceback (most recent call last):
  File "/usr/local/lib/python3.9/concurrent/futures/thread.py", line 52, in run
    result = self.fn(*self.args, **self.kwargs)
TypeError: update() takes 1 positional argument but 2 were given
2021-09-04 08:38:06 ERROR (MainThread) [homeassistant] Error doing job: Future exception was never retrieved
Traceback (most recent call last):
  File "/usr/local/lib/python3.9/concurrent/futures/thread.py", line 52, in run
    result = self.fn(*self.args, **self.kwargs)
TypeError: update() takes 1 positional argument but 2 were given
2021-09-04 08:43:07 ERROR (MainThread) [homeassistant] Error doing job: Future exception was never retrieved
Traceback (most recent call last):
  File "/usr/local/lib/python3.9/concurrent/futures/thread.py", line 52, in run
    result = self.fn(*self.args, **self.kwargs)
TypeError: update() takes 1 positional argument but 2 were given
2021-09-04 08:48:08 ERROR (MainThread) [homeassistant] Error doing job: Future exception was never retrieved
Traceback (most recent call last):
  File "/usr/local/lib/python3.9/concurrent/futures/thread.py", line 52, in run
    result = self.fn(*self.args, **self.kwargs)
TypeError: update() takes 1 positional argument but 2 were given
2021-09-04 08:51:01 WARNING (Thread-10) [pychromecast.socket_client] [Kitchen speaker(192.168.20.124):8009] Heartbeat timeout, resetting connection
2021-09-04 08:51:01 ERROR (Thread-10) [pychromecast.socket_client] [Kitchen speaker(192.168.20.124):8009] Failed to connect to service ServiceInfo(type='mdns', data='Google-Home-94338647b4446a4635573050a795c7c2._googlecast._tcp.local.'), retrying in 5.0s
2021-09-04 08:53:09 ERROR (MainThread) [homeassistant] Error doing job: Future exception was never retrieved
Traceback (most recent call last):
  File "/usr/local/lib/python3.9/concurrent/futures/thread.py", line 52, in run
    result = self.fn(*self.args, **self.kwargs)
TypeError: update() takes 1 positional argument but 2 were given
2021-09-04 08:58:10 ERROR (MainThread) [homeassistant] Error doing job: Future exception was never retrieved
Traceback (most recent call last):
  File "/usr/local/lib/python3.9/concurrent/futures/thread.py", line 52, in run
    result = self.fn(*self.args, **self.kwargs)
TypeError: update() takes 1 positional argument but 2 were given
2021-09-04 08:59:07 ERROR (MainThread) [homeassistant.components.nws] Error requesting NWS observation station SAUC1 data: 503, message='Service Unavailable', url=URL('https://api.weather.gov/stations/SAUC1/observations')
2021-09-04 09:03:11 ERROR (MainThread) [homeassistant] Error doing job: Future exception was never retrieved
Traceback (most recent call last):
  File "/usr/local/lib/python3.9/concurrent/futures/thread.py", line 52, in run
    result = self.fn(*self.args, **self.kwargs)
TypeError: update() takes 1 positional argument but 2 were given
2021-09-04 09:08:12 ERROR (MainThread) [homeassistant] Error doing job: Future exception was never retrieved
Traceback (most recent call last):
  File "/usr/local/lib/python3.9/concurrent/futures/thread.py", line 52, in run
    result = self.fn(*self.args, **self.kwargs)
TypeError: update() takes 1 positional argument but 2 were given
2021-09-04 09:13:13 ERROR (MainThread) [homeassistant] Error doing job: Future exception was never retrieved
Traceback (most recent call last):
  File "/usr/local/lib/python3.9/concurrent/futures/thread.py", line 52, in run
    result = self.fn(*self.args, **self.kwargs)
TypeError: update() takes 1 positional argument but 2 were given
2021-09-04 09:18:14 ERROR (MainThread) [homeassistant] Error doing job: Future exception was never retrieved
Traceback (most recent call last):
  File "/usr/local/lib/python3.9/concurrent/futures/thread.py", line 52, in run
    result = self.fn(*self.args, **self.kwargs)
TypeError: update() takes 1 positional argument but 2 were given
2021-09-04 09:23:15 ERROR (MainThread) [homeassistant] Error doing job: Future exception was never retrieved
Traceback (most recent call last):
  File "/usr/local/lib/python3.9/concurrent/futures/thread.py", line 52, in run
    result = self.fn(*self.args, **self.kwargs)
TypeError: update() takes 1 positional argument but 2 were given
2021-09-04 09:28:16 ERROR (MainThread) [homeassistant] Error doing job: Future exception was never retrieved
Traceback (most recent call last):
  File "/usr/local/lib/python3.9/concurrent/futures/thread.py", line 52, in run
    result = self.fn(*self.args, **self.kwargs)
TypeError: update() takes 1 positional argument but 2 were given
2021-09-04 09:33:17 ERROR (MainThread) [homeassistant] Error doing job: Future exception was never retrieved
Traceback (most recent call last):
  File "/usr/local/lib/python3.9/concurrent/futures/thread.py", line 52, in run
    result = self.fn(*self.args, **self.kwargs)
TypeError: update() takes 1 positional argument but 2 were given
2021-09-04 09:38:18 ERROR (MainThread) [homeassistant] Error doing job: Future exception was never retrieved
Traceback (most recent call last):
  File "/usr/local/lib/python3.9/concurrent/futures/thread.py", line 52, in run
    result = self.fn(*self.args, **self.kwargs)
TypeError: update() takes 1 positional argument but 2 were given
2021-09-04 09:43:19 ERROR (MainThread) [homeassistant] Error doing job: Future exception was never retrieved
Traceback (most recent call last):
  File "/usr/local/lib/python3.9/concurrent/futures/thread.py", line 52, in run
    result = self.fn(*self.args, **self.kwargs)
TypeError: update() takes 1 positional argument but 2 were given
2021-09-04 09:48:20 ERROR (MainThread) [homeassistant] Error doing job: Future exception was never retrieved
Traceback (most recent call last):
  File "/usr/local/lib/python3.9/concurrent/futures/thread.py", line 52, in run
    result = self.fn(*self.args, **self.kwargs)
TypeError: update() takes 1 positional argument but 2 were given
2021-09-04 09:53:21 ERROR (MainThread) [homeassistant] Error doing job: Future exception was never retrieved
Traceback (most recent call last):
  File "/usr/local/lib/python3.9/concurrent/futures/thread.py", line 52, in run
    result = self.fn(*self.args, **self.kwargs)
TypeError: update() takes 1 positional argument but 2 were given
2021-09-04 09:58:22 ERROR (MainThread) [homeassistant] Error doing job: Future exception was never retrieved
Traceback (most recent call last):
  File "/usr/local/lib/python3.9/concurrent/futures/thread.py", line 52, in run
    result = self.fn(*self.args, **self.kwargs)
TypeError: update() takes 1 positional argument but 2 were given
2021-09-04 10:03:23 ERROR (MainThread) [homeassistant] Error doing job: Future exception was never retrieved
Traceback (most recent call last):
  File "/usr/local/lib/python3.9/concurrent/futures/thread.py", line 52, in run
    result = self.fn(*self.args, **self.kwargs)
TypeError: update() takes 1 positional argument but 2 were given
2021-09-04 10:08:24 ERROR (MainThread) [homeassistant] Error doing job: Future exception was never retrieved
Traceback (most recent call last):
  File "/usr/local/lib/python3.9/concurrent/futures/thread.py", line 52, in run
    result = self.fn(*self.args, **self.kwargs)
TypeError: update() takes 1 positional argument but 2 were given
2021-09-04 10:13:25 ERROR (MainThread) [homeassistant] Error doing job: Future exception was never retrieved
Traceback (most recent call last):
  File "/usr/local/lib/python3.9/concurrent/futures/thread.py", line 52, in run
    result = self.fn(*self.args, **self.kwargs)
TypeError: update() takes 1 positional argument but 2 were given
2021-09-04 10:18:26 ERROR (MainThread) [homeassistant] Error doing job: Future exception was never retrieved
Traceback (most recent call last):
  File "/usr/local/lib/python3.9/concurrent/futures/thread.py", line 52, in run
    result = self.fn(*self.args, **self.kwargs)
TypeError: update() takes 1 positional argument but 2 were given
2021-09-04 10:20:32 ERROR (stream_worker) [libav.rtsp] method DESCRIBE failed: 404 Not Found
2021-09-04 10:20:32 ERROR (stream_worker) [homeassistant.components.stream.worker] Error opening stream rtsps://stream-uc2-bravo.dropcam.com:443/sdm_live_stream/CiQA2vuxr7lokMie-K08g-QCWPm8feXufXtZDbWaBEV2w2bpT0kScQBQBG8tcd6RJCCSx63sLVahEhg5kqmwsAudRkZdRBYfX2lQt8torI-AmpJoCjDWNvP8iCDRYNu04Yl4RfELOeTk3ld5Y1c8l_Emm20aba_QWUaTUUC5xIaZRryPHgvfdt2ODS7dZ5fWh_j0txJhft3e?auth=g.0.eyJraWQiOiIyMzhiNTUxZmMyM2EyM2Y4M2E2ZTE3MmJjZTg0YmU3ZjgxMzAzMmM4IiwiYWxnIjoiUlMyNTYifQ.eyJpc3MiOiJuZXN0LXNlY3VyaXR5LWF1dGhwcm94eSIsInN1YiI6Im5lc3RfaWQ6bmVzdC1waG9lbml4LXByb2Q6MjEyMTgxNDEiLCJwb2wiOiIzcC1vYXV0aC1zY29wZS1BUElfU0RNX1NFUlZJQ0UtY2xpZW50LTIwMjQyNzMxODczNS1qNXQ5bWMyMzZqaG85YXMycWY0dTZxY3NmYW1kaGJ0ci5hcHBzLmdvb2dsZXVzZXJjb250ZW50LmNvbSIsImV4cCI6MTYzMDc3NjIzMH0.OB3tCh5ztYib9242ZC-M6jy5WxbPd4lLWlblnXetLCkKrYmksC5K07g9jGQ3_1O9V3Pswtdo8_dytrWgDLhEjHPr8IIvH2K0LjGlupRFqhLdmLBsS_eY6Ca6nYVee0sGyeBeywOC-mMj__HL1geU-h5P59WS7TN2JeewftdTNjePUYntJ5h-fobg9mw6Rj6VWahoNsY9GBT4nvsKQfF2HrC5a_0EZD_mscb6MhtdS94gQcr-prGSs3E39-I0gDscYWC__mYh60TK6Sf3pjDY0q5Gw-e5fX-Wf6yyPRvgqnlyYTXXaiIbesDY9EhAxBQf7cyKekcXxdAMmTWJRpJ3mw
2021-09-04 10:23:27 ERROR (MainThread) [homeassistant] Error doing job: Future exception was never retrieved
Traceback (most recent call last):
  File "/usr/local/lib/python3.9/concurrent/futures/thread.py", line 52, in run
    result = self.fn(*self.args, **self.kwargs)
TypeError: update() takes 1 positional argument but 2 were given
2021-09-04 10:28:28 ERROR (MainThread) [homeassistant] Error doing job: Future exception was never retrieved
Traceback (most recent call last):
  File "/usr/local/lib/python3.9/concurrent/futures/thread.py", line 52, in run
    result = self.fn(*self.args, **self.kwargs)
TypeError: update() takes 1 positional argument but 2 were given
2021-09-04 10:33:29 ERROR (MainThread) [homeassistant] Error doing job: Future exception was never retrieved
Traceback (most recent call last):
  File "/usr/local/lib/python3.9/concurrent/futures/thread.py", line 52, in run
    result = self.fn(*self.args, **self.kwargs)
TypeError: update() takes 1 positional argument but 2 were given
2021-09-04 10:34:19 ERROR (stream_worker) [libav.rtsp] method DESCRIBE failed: 404 Not Found
2021-09-04 10:34:19 ERROR (stream_worker) [homeassistant.components.stream.worker] Error opening stream rtsps://stream-uc2-bravo.dropcam.com:443/sdm_live_stream/CiQA2vuxr7lokMie-K08g-QCWPm8feXufXtZDbWaBEV2w2bpT0kScQBQBG8tcd6RJCCSx63sLVahEhg5kqmwsAudRkZdRBYfX2lQt8torI-AmpJoCjDWNvP8iCDRYNu04Yl4RfELOeTk3ld5Y1c8l_Emm20aba_QWUaTUUC5xIaZRryPHgvfdt2ODS7dZ5fWh_j0txJhft3e?auth=g.0.eyJraWQiOiIyMzhiNTUxZmMyM2EyM2Y4M2E2ZTE3MmJjZTg0YmU3ZjgxMzAzMmM4IiwiYWxnIjoiUlMyNTYifQ.eyJpc3MiOiJuZXN0LXNlY3VyaXR5LWF1dGhwcm94eSIsInN1YiI6Im5lc3RfaWQ6bmVzdC1waG9lbml4LXByb2Q6MjEyMTgxNDEiLCJwb2wiOiIzcC1vYXV0aC1zY29wZS1BUElfU0RNX1NFUlZJQ0UtY2xpZW50LTIwMjQyNzMxODczNS1qNXQ5bWMyMzZqaG85YXMycWY0dTZxY3NmYW1kaGJ0ci5hcHBzLmdvb2dsZXVzZXJjb250ZW50LmNvbSIsImV4cCI6MTYzMDc3NzA0Mn0.hksDZ3QNJKEfitVsyXUERODOE0Rr-XEAOK0YSL82WcYiaOH3Lx-mpLHzA5mhT_mVed3iYN6cVN27NKanW-YPZP0EvfO4bxUK5yyY1LMqlNpl5WcJ-2tgTGYdOQ6fTFiEPlOIobMnOlbJsEeMpCLN3dPOz7wI_A6rVrSgJVwmkXP7xZynKsDGyP3z06QQ6u-9OOm1ueIh8fcsGtBR2drYV1kd92I1Ss104EuJRawJrh-DgY_ZaZdUGR2Sp9EUI7Fud0IAe9YZvq-VufKU20Es2bJOM_8wC7pbUaPl1goMv76KHXhMW836SekmK4HsM7atfY1Y2X7z5uQ8hZYgNosXnQ
2021-09-04 10:36:30 WARNING (MainThread) [bellows.zigbee.application] Watchdog heartbeat timeout: 
2021-09-04 10:38:30 ERROR (MainThread) [homeassistant] Error doing job: Future exception was never retrieved
Traceback (most recent call last):
  File "/usr/local/lib/python3.9/concurrent/futures/thread.py", line 52, in run
    result = self.fn(*self.args, **self.kwargs)
TypeError: update() takes 1 positional argument but 2 were given
2021-09-04 10:43:31 ERROR (MainThread) [homeassistant] Error doing job: Future exception was never retrieved
Traceback (most recent call last):
  File "/usr/local/lib/python3.9/concurrent/futures/thread.py", line 52, in run
    result = self.fn(*self.args, **self.kwargs)
TypeError: update() takes 1 positional argument but 2 were given
2021-09-04 10:48:32 ERROR (MainThread) [homeassistant] Error doing job: Future exception was never retrieved
Traceback (most recent call last):
  File "/usr/local/lib/python3.9/concurrent/futures/thread.py", line 52, in run
    result = self.fn(*self.args, **self.kwargs)
TypeError: update() takes 1 positional argument but 2 were given
2021-09-04 10:53:33 ERROR (MainThread) [homeassistant] Error doing job: Future exception was never retrieved
Traceback (most recent call last):
  File "/usr/local/lib/python3.9/concurrent/futures/thread.py", line 52, in run
    result = self.fn(*self.args, **self.kwargs)
TypeError: update() takes 1 positional argument but 2 were given
2021-09-04 10:58:34 ERROR (MainThread) [homeassistant] Error doing job: Future exception was never retrieved
Traceback (most recent call last):
  File "/usr/local/lib/python3.9/concurrent/futures/thread.py", line 52, in run
    result = self.fn(*self.args, **self.kwargs)
TypeError: update() takes 1 positional argument but 2 were given
2021-09-04 11:01:13 ERROR (MainThread) [homeassistant.components.nws] Error requesting NWS observation station SAUC1 data: 503, message='Service Unavailable', url=URL('https://api.weather.gov/stations/SAUC1/observations')
2021-09-04 11:03:35 ERROR (MainThread) [homeassistant] Error doing job: Future exception was never retrieved
Traceback (most recent call last):
  File "/usr/local/lib/python3.9/concurrent/futures/thread.py", line 52, in run
    result = self.fn(*self.args, **self.kwargs)
TypeError: update() takes 1 positional argument but 2 were given
2021-09-04 11:08:36 ERROR (MainThread) [homeassistant] Error doing job: Future exception was never retrieved
Traceback (most recent call last):
  File "/usr/local/lib/python3.9/concurrent/futures/thread.py", line 52, in run
    result = self.fn(*self.args, **self.kwargs)
TypeError: update() takes 1 positional argument but 2 were given
2021-09-04 11:13:37 ERROR (MainThread) [homeassistant] Error doing job: Future exception was never retrieved
Traceback (most recent call last):
  File "/usr/local/lib/python3.9/concurrent/futures/thread.py", line 52, in run
    result = self.fn(*self.args, **self.kwargs)
TypeError: update() takes 1 positional argument but 2 were given
2021-09-04 11:18:38 ERROR (MainThread) [homeassistant] Error doing job: Future exception was never retrieved
Traceback (most recent call last):
  File "/usr/local/lib/python3.9/concurrent/futures/thread.py", line 52, in run
    result = self.fn(*self.args, **self.kwargs)
TypeError: update() takes 1 positional argument but 2 were given
2021-09-04 11:23:39 ERROR (MainThread) [homeassistant] Error doing job: Future exception was never retrieved
Traceback (most recent call last):
  File "/usr/local/lib/python3.9/concurrent/futures/thread.py", line 52, in run
    result = self.fn(*self.args, **self.kwargs)
TypeError: update() takes 1 positional argument but 2 were given
2021-09-04 11:24:01 ERROR (stream_worker) [libav.rtsp] method DESCRIBE failed: 404 Not Found
2021-09-04 11:24:01 ERROR (stream_worker) [homeassistant.components.stream.worker] Error opening stream rtsps://stream-uc2-bravo.dropcam.com:443/sdm_live_stream/CiQA2vuxr7lokMie-K08g-QCWPm8feXufXtZDbWaBEV2w2bpT0kScQBQBG8tcd6RJCCSx63sLVahEhg5kqmwsAudRkZdRBYfX2lQt8torI-AmpJoCjDWNvP8iCDRYNu04Yl4RfELOeTk3ld5Y1c8l_Emm20aba_QWUaTUUC5xIaZRryPHgvfdt2ODS7dZ5fWh_j0txJhft3e?auth=g.0.eyJraWQiOiIyMzhiNTUxZmMyM2EyM2Y4M2E2ZTE3MmJjZTg0YmU3ZjgxMzAzMmM4IiwiYWxnIjoiUlMyNTYifQ.eyJpc3MiOiJuZXN0LXNlY3VyaXR5LWF1dGhwcm94eSIsInN1YiI6Im5lc3RfaWQ6bmVzdC1waG9lbml4LXByb2Q6MjEyMTgxNDEiLCJwb2wiOiIzcC1vYXV0aC1zY29wZS1BUElfU0RNX1NFUlZJQ0UtY2xpZW50LTIwMjQyNzMxODczNS1qNXQ5bWMyMzZqaG85YXMycWY0dTZxY3NmYW1kaGJ0ci5hcHBzLmdvb2dsZXVzZXJjb250ZW50LmNvbSIsImV4cCI6MTYzMDc4MDAxOX0.MMHfXvBuNWz4ZxJ0Iwggg30zAQdZE2vTOSYWADSwpB-cmUoNpXESDk-z33HbPzYYtVnJQnSwxBQsVfeR7eyAwJdCyEGf6Lje-3kt1LkgD7_3u_I8Sbvm6gDXThESfEmM39UulI5VR-CxPe4ktbVHGJfzTcHDwCtc0ilcoxXvfl8c8mHQhAMPmTno_PnTtJIM7zDOyI5Pz9Km9ogzgvnLXgXTeR20ZSg0BoY-KNWpzzUEOwd2MDFqwn4fei73tUdxuypuPwEdEFgw3ik8swtMnK2M-GJk0dCIxfXk7Hj3XbYDNpWBNRmcM66AlSGCdzmi6jSaeBREkiyWo_2pmQvIpA
2021-09-04 11:28:40 ERROR (MainThread) [homeassistant] Error doing job: Future exception was never retrieved
Traceback (most recent call last):
  File "/usr/local/lib/python3.9/concurrent/futures/thread.py", line 52, in run
    result = self.fn(*self.args, **self.kwargs)
TypeError: update() takes 1 positional argument but 2 were given
2021-09-04 11:33:12 ERROR (stream_worker) [libav.rtsp] method DESCRIBE failed: 404 Not Found
2021-09-04 11:33:12 ERROR (stream_worker) [homeassistant.components.stream.worker] Error opening stream rtsps://stream-uc2-bravo.dropcam.com:443/sdm_live_stream/CiQA2vuxr7lokMie-K08g-QCWPm8feXufXtZDbWaBEV2w2bpT0kScQBQBG8tcd6RJCCSx63sLVahEhg5kqmwsAudRkZdRBYfX2lQt8torI-AmpJoCjDWNvP8iCDRYNu04Yl4RfELOeTk3ld5Y1c8l_Emm20aba_QWUaTUUC5xIaZRryPHgvfdt2ODS7dZ5fWh_j0txJhft3e?auth=g.0.eyJraWQiOiIyMzhiNTUxZmMyM2EyM2Y4M2E2ZTE3MmJjZTg0YmU3ZjgxMzAzMmM4IiwiYWxnIjoiUlMyNTYifQ.eyJpc3MiOiJuZXN0LXNlY3VyaXR5LWF1dGhwcm94eSIsInN1YiI6Im5lc3RfaWQ6bmVzdC1waG9lbml4LXByb2Q6MjEyMTgxNDEiLCJwb2wiOiIzcC1vYXV0aC1zY29wZS1BUElfU0RNX1NFUlZJQ0UtY2xpZW50LTIwMjQyNzMxODczNS1qNXQ5bWMyMzZqaG85YXMycWY0dTZxY3NmYW1kaGJ0ci5hcHBzLmdvb2dsZXVzZXJjb250ZW50LmNvbSIsImV4cCI6MTYzMDc4MDU2MH0.PpqU-oq-vZmQwUxm2TrpAoRGzGd73YH-NZ4dHoICccoTbu3sSdweBWey6R_bR4U4CwQcngUFDJ0Kh8mlgsILhaMsvpp9faWGiOnERmLZwUt6FtDxY6o7VcQDLX_Gz82ckx59Qge5-eX8ZdAU3jPXLexx7wrEMopqT2eNKmX_HoZchBA1tRODZa1mYeFQ222R2eM-C_S3zGPXGNRGHUUPB4FDSKvlAWC4COqFNnrA8fvuF5TFb_iI420XsWIAGm843msv4Uw-r4TpwDp6AVffSDEfrF4Y5BD2c6-oNQm3i_LcG_lUXOA--dGTFkK2y-OGr-lYlW8z4resednak12-1A
2021-09-04 11:33:41 ERROR (MainThread) [homeassistant] Error doing job: Future exception was never retrieved
Traceback (most recent call last):
  File "/usr/local/lib/python3.9/concurrent/futures/thread.py", line 52, in run
    result = self.fn(*self.args, **self.kwargs)
TypeError: update() takes 1 positional argument but 2 were given
2021-09-04 11:37:52 ERROR (stream_worker) [libav.rtsp] method DESCRIBE failed: 404 Not Found
2021-09-04 11:37:52 ERROR (stream_worker) [homeassistant.components.stream.worker] Error opening stream rtsps://stream-uc2-bravo.dropcam.com:443/sdm_live_stream/CiQA2vuxr7lokMie-K08g-QCWPm8feXufXtZDbWaBEV2w2bpT0kScQBQBG8tcd6RJCCSx63sLVahEhg5kqmwsAudRkZdRBYfX2lQt8torI-AmpJoCjDWNvP8iCDRYNu04Yl4RfELOeTk3ld5Y1c8l_Emm20aba_QWUaTUUC5xIaZRryPHgvfdt2ODS7dZ5fWh_j0txJhft3e?auth=g.0.eyJraWQiOiIyMzhiNTUxZmMyM2EyM2Y4M2E2ZTE3MmJjZTg0YmU3ZjgxMzAzMmM4IiwiYWxnIjoiUlMyNTYifQ.eyJpc3MiOiJuZXN0LXNlY3VyaXR5LWF1dGhwcm94eSIsInN1YiI6Im5lc3RfaWQ6bmVzdC1waG9lbml4LXByb2Q6MjEyMTgxNDEiLCJwb2wiOiIzcC1vYXV0aC1zY29wZS1BUElfU0RNX1NFUlZJQ0UtY2xpZW50LTIwMjQyNzMxODczNS1qNXQ5bWMyMzZqaG85YXMycWY0dTZxY3NmYW1kaGJ0ci5hcHBzLmdvb2dsZXVzZXJjb250ZW50LmNvbSIsImV4cCI6MTYzMDc4MDgzMX0.sC-QOmaFxFRWwTAJzA-LJ-3T9e_91bZUHRNyw2arsGUtESmGWRVh6aXr_FoYUvq7x7TiLSlxwLNjsPIvyQTI_GwJ4lXt6yNEAzKiDwGQpZ6PGp2_tDTjANr2HEY3QrexHQ4Gd_5qKPYG9HkfFzKyzhbNPcGzvVN-OHJO26XX7A4twhZBb8Z8obPTtJV4Q7EC30Dhr37wcSl61LVpQA0l4VkH_RkyyoMeCcCK_tIxAFigw-Cv_nZ6-8TjbTLgFwy5MoJLaBsvAiuhd3f-shmi915kP8AyoDTlGVC-aGD4eHHS_bWNJ-lEptykBS3XbcqUW_w9WazMw41UUhaa78CrRg
2021-09-04 11:38:42 ERROR (MainThread) [homeassistant] Error doing job: Future exception was never retrieved
Traceback (most recent call last):
  File "/usr/local/lib/python3.9/concurrent/futures/thread.py", line 52, in run
    result = self.fn(*self.args, **self.kwargs)
TypeError: update() takes 1 positional argument but 2 were given
2021-09-04 11:43:43 ERROR (MainThread) [homeassistant] Error doing job: Future exception was never retrieved
Traceback (most recent call last):
  File "/usr/local/lib/python3.9/concurrent/futures/thread.py", line 52, in run
    result = self.fn(*self.args, **self.kwargs)
TypeError: update() takes 1 positional argument but 2 were given
2021-09-04 11:48:44 ERROR (MainThread) [homeassistant] Error doing job: Future exception was never retrieved
Traceback (most recent call last):
  File "/usr/local/lib/python3.9/concurrent/futures/thread.py", line 52, in run
    result = self.fn(*self.args, **self.kwargs)
TypeError: update() takes 1 positional argument but 2 were given
2021-09-04 11:53:45 ERROR (MainThread) [homeassistant] Error doing job: Future exception was never retrieved
Traceback (most recent call last):
  File "/usr/local/lib/python3.9/concurrent/futures/thread.py", line 52, in run
    result = self.fn(*self.args, **self.kwargs)
TypeError: update() takes 1 positional argument but 2 were given
2021-09-04 11:58:46 ERROR (MainThread) [homeassistant] Error doing job: Future exception was never retrieved
Traceback (most recent call last):
  File "/usr/local/lib/python3.9/concurrent/futures/thread.py", line 52, in run
    result = self.fn(*self.args, **self.kwargs)
TypeError: update() takes 1 positional argument but 2 were given
2021-09-04 12:03:47 ERROR (MainThread) [homeassistant] Error doing job: Future exception was never retrieved
Traceback (most recent call last):
  File "/usr/local/lib/python3.9/concurrent/futures/thread.py", line 52, in run
    result = self.fn(*self.args, **self.kwargs)
TypeError: update() takes 1 positional argument but 2 were given
2021-09-04 12:05:27 WARNING (MainThread) [bellows.zigbee.application] Watchdog heartbeat timeout: 
2021-09-04 12:08:48 ERROR (MainThread) [homeassistant] Error doing job: Future exception was never retrieved
Traceback (most recent call last):
  File "/usr/local/lib/python3.9/concurrent/futures/thread.py", line 52, in run
    result = self.fn(*self.args, **self.kwargs)
TypeError: update() takes 1 positional argument but 2 were given
2021-09-04 12:13:49 ERROR (MainThread) [homeassistant] Error doing job: Future exception was never retrieved
Traceback (most recent call last):
  File "/usr/local/lib/python3.9/concurrent/futures/thread.py", line 52, in run
    result = self.fn(*self.args, **self.kwargs)
TypeError: update() takes 1 positional argument but 2 were given
2021-09-04 12:18:50 ERROR (MainThread) [homeassistant] Error doing job: Future exception was never retrieved
Traceback (most recent call last):
  File "/usr/local/lib/python3.9/concurrent/futures/thread.py", line 52, in run
    result = self.fn(*self.args, **self.kwargs)
TypeError: update() takes 1 positional argument but 2 were given
2021-09-04 12:23:51 ERROR (MainThread) [homeassistant] Error doing job: Future exception was never retrieved
Traceback (most recent call last):
  File "/usr/local/lib/python3.9/concurrent/futures/thread.py", line 52, in run
    result = self.fn(*self.args, **self.kwargs)
TypeError: update() takes 1 positional argument but 2 were given
2021-09-04 12:28:52 ERROR (MainThread) [homeassistant] Error doing job: Future exception was never retrieved
Traceback (most recent call last):
  File "/usr/local/lib/python3.9/concurrent/futures/thread.py", line 52, in run
    result = self.fn(*self.args, **self.kwargs)
TypeError: update() takes 1 positional argument but 2 were given
2021-09-04 12:33:53 ERROR (MainThread) [homeassistant] Error doing job: Future exception was never retrieved
Traceback (most recent call last):
  File "/usr/local/lib/python3.9/concurrent/futures/thread.py", line 52, in run
    result = self.fn(*self.args, **self.kwargs)
TypeError: update() takes 1 positional argument but 2 were given
2021-09-04 12:38:54 ERROR (MainThread) [homeassistant] Error doing job: Future exception was never retrieved
Traceback (most recent call last):
  File "/usr/local/lib/python3.9/concurrent/futures/thread.py", line 52, in run
    result = self.fn(*self.args, **self.kwargs)
TypeError: update() takes 1 positional argument but 2 were given
2021-09-04 12:43:55 ERROR (MainThread) [homeassistant] Error doing job: Future exception was never retrieved
Traceback (most recent call last):
  File "/usr/local/lib/python3.9/concurrent/futures/thread.py", line 52, in run
    result = self.fn(*self.args, **self.kwargs)
TypeError: update() takes 1 positional argument but 2 were given
2021-09-04 12:48:56 ERROR (MainThread) [homeassistant] Error doing job: Future exception was never retrieved
Traceback (most recent call last):
  File "/usr/local/lib/python3.9/concurrent/futures/thread.py", line 52, in run
    result = self.fn(*self.args, **self.kwargs)
TypeError: update() takes 1 positional argument but 2 were given
2021-09-04 12:53:57 ERROR (MainThread) [homeassistant] Error doing job: Future exception was never retrieved
Traceback (most recent call last):
  File "/usr/local/lib/python3.9/concurrent/futures/thread.py", line 52, in run
    result = self.fn(*self.args, **self.kwargs)
TypeError: update() takes 1 positional argument but 2 were given
2021-09-04 12:58:58 ERROR (MainThread) [homeassistant] Error doing job: Future exception was never retrieved
Traceback (most recent call last):
  File "/usr/local/lib/python3.9/concurrent/futures/thread.py", line 52, in run
    result = self.fn(*self.args, **self.kwargs)
TypeError: update() takes 1 positional argument but 2 were given
2021-09-04 13:03:59 ERROR (MainThread) [homeassistant] Error doing job: Future exception was never retrieved
Traceback (most recent call last):
  File "/usr/local/lib/python3.9/concurrent/futures/thread.py", line 52, in run
    result = self.fn(*self.args, **self.kwargs)
TypeError: update() takes 1 positional argument but 2 were given
2021-09-04 13:09:00 ERROR (MainThread) [homeassistant] Error doing job: Future exception was never retrieved
Traceback (most recent call last):
  File "/usr/local/lib/python3.9/concurrent/futures/thread.py", line 52, in run
    result = self.fn(*self.args, **self.kwargs)
TypeError: update() takes 1 positional argument but 2 were given
2021-09-04 13:14:01 ERROR (MainThread) [homeassistant] Error doing job: Future exception was never retrieved
Traceback (most recent call last):
  File "/usr/local/lib/python3.9/concurrent/futures/thread.py", line 52, in run
    result = self.fn(*self.args, **self.kwargs)
TypeError: update() takes 1 positional argument but 2 were given
2021-09-04 13:19:02 ERROR (MainThread) [homeassistant] Error doing job: Future exception was never retrieved
Traceback (most recent call last):
  File "/usr/local/lib/python3.9/concurrent/futures/thread.py", line 52, in run
    result = self.fn(*self.args, **self.kwargs)
TypeError: update() takes 1 positional argument but 2 were given
2021-09-04 13:24:03 ERROR (MainThread) [homeassistant] Error doing job: Future exception was never retrieved
Traceback (most recent call last):
  File "/usr/local/lib/python3.9/concurrent/futures/thread.py", line 52, in run
    result = self.fn(*self.args, **self.kwargs)
TypeError: update() takes 1 positional argument but 2 were given
2021-09-04 13:29:04 ERROR (MainThread) [homeassistant] Error doing job: Future exception was never retrieved
Traceback (most recent call last):
  File "/usr/local/lib/python3.9/concurrent/futures/thread.py", line 52, in run
    result = self.fn(*self.args, **self.kwargs)
TypeError: update() takes 1 positional argument but 2 were given
2021-09-04 13:34:05 ERROR (MainThread) [homeassistant] Error doing job: Future exception was never retrieved
Traceback (most recent call last):
  File "/usr/local/lib/python3.9/concurrent/futures/thread.py", line 52, in run
    result = self.fn(*self.args, **self.kwargs)
TypeError: update() takes 1 positional argument but 2 were given
2021-09-04 13:39:06 ERROR (MainThread) [homeassistant] Error doing job: Future exception was never retrieved
Traceback (most recent call last):
  File "/usr/local/lib/python3.9/concurrent/futures/thread.py", line 52, in run
    result = self.fn(*self.args, **self.kwargs)
TypeError: update() takes 1 positional argument but 2 were given
2021-09-04 13:44:07 ERROR (MainThread) [homeassistant] Error doing job: Future exception was never retrieved
Traceback (most recent call last):
  File "/usr/local/lib/python3.9/concurrent/futures/thread.py", line 52, in run
    result = self.fn(*self.args, **self.kwargs)
TypeError: update() takes 1 positional argument but 2 were given
2021-09-04 13:49:08 ERROR (MainThread) [homeassistant] Error doing job: Future exception was never retrieved
Traceback (most recent call last):
  File "/usr/local/lib/python3.9/concurrent/futures/thread.py", line 52, in run
    result = self.fn(*self.args, **self.kwargs)
TypeError: update() takes 1 positional argument but 2 were given
2021-09-04 13:54:09 ERROR (MainThread) [homeassistant] Error doing job: Future exception was never retrieved
Traceback (most recent call last):
  File "/usr/local/lib/python3.9/concurrent/futures/thread.py", line 52, in run
    result = self.fn(*self.args, **self.kwargs)
TypeError: update() takes 1 positional argument but 2 were given
2021-09-04 13:59:10 ERROR (MainThread) [homeassistant] Error doing job: Future exception was never retrieved
Traceback (most recent call last):
  File "/usr/local/lib/python3.9/concurrent/futures/thread.py", line 52, in run
    result = self.fn(*self.args, **self.kwargs)
TypeError: update() takes 1 positional argument but 2 were given
2021-09-04 14:04:11 ERROR (MainThread) [homeassistant] Error doing job: Future exception was never retrieved
Traceback (most recent call last):
  File "/usr/local/lib/python3.9/concurrent/futures/thread.py", line 52, in run
    result = self.fn(*self.args, **self.kwargs)
TypeError: update() takes 1 positional argument but 2 were given
2021-09-04 14:09:12 ERROR (MainThread) [homeassistant] Error doing job: Future exception was never retrieved
Traceback (most recent call last):
  File "/usr/local/lib/python3.9/concurrent/futures/thread.py", line 52, in run
    result = self.fn(*self.args, **self.kwargs)
TypeError: update() takes 1 positional argument but 2 were given
2021-09-04 14:14:13 ERROR (MainThread) [homeassistant] Error doing job: Future exception was never retrieved
Traceback (most recent call last):
  File "/usr/local/lib/python3.9/concurrent/futures/thread.py", line 52, in run
    result = self.fn(*self.args, **self.kwargs)
TypeError: update() takes 1 positional argument but 2 were given
2021-09-04 14:19:14 ERROR (MainThread) [homeassistant] Error doing job: Future exception was never retrieved
Traceback (most recent call last):
  File "/usr/local/lib/python3.9/concurrent/futures/thread.py", line 52, in run
    result = self.fn(*self.args, **self.kwargs)
TypeError: update() takes 1 positional argument but 2 were given
2021-09-04 14:20:07 WARNING (MainThread) [bellows.zigbee.application] Watchdog heartbeat timeout: 
2021-09-04 14:20:22 WARNING (MainThread) [bellows.zigbee.application] Watchdog heartbeat timeout: 
2021-09-04 14:24:15 ERROR (MainThread) [homeassistant] Error doing job: Future exception was never retrieved
Traceback (most recent call last):
  File "/usr/local/lib/python3.9/concurrent/futures/thread.py", line 52, in run
    result = self.fn(*self.args, **self.kwargs)
TypeError: update() takes 1 positional argument but 2 were given
2021-09-04 14:29:16 ERROR (MainThread) [homeassistant] Error doing job: Future exception was never retrieved
Traceback (most recent call last):
  File "/usr/local/lib/python3.9/concurrent/futures/thread.py", line 52, in run
    result = self.fn(*self.args, **self.kwargs)
TypeError: update() takes 1 positional argument but 2 were given
2021-09-04 14:31:39 WARNING (MainThread) [homeassistant.components.unifi] Lost connection to UniFi controller
2021-09-04 14:34:17 ERROR (MainThread) [homeassistant] Error doing job: Future exception was never retrieved
Traceback (most recent call last):
  File "/usr/local/lib/python3.9/concurrent/futures/thread.py", line 52, in run
    result = self.fn(*self.args, **self.kwargs)
TypeError: update() takes 1 positional argument but 2 were given
2021-09-04 14:39:18 ERROR (MainThread) [homeassistant] Error doing job: Future exception was never retrieved
Traceback (most recent call last):
  File "/usr/local/lib/python3.9/concurrent/futures/thread.py", line 52, in run
    result = self.fn(*self.args, **self.kwargs)
TypeError: update() takes 1 positional argument but 2 were given
2021-09-04 14:44:19 ERROR (MainThread) [homeassistant] Error doing job: Future exception was never retrieved
Traceback (most recent call last):
  File "/usr/local/lib/python3.9/concurrent/futures/thread.py", line 52, in run
    result = self.fn(*self.args, **self.kwargs)
TypeError: update() takes 1 positional argument but 2 were given
2021-09-04 14:49:20 ERROR (MainThread) [homeassistant] Error doing job: Future exception was never retrieved
Traceback (most recent call last):
  File "/usr/local/lib/python3.9/concurrent/futures/thread.py", line 52, in run
    result = self.fn(*self.args, **self.kwargs)
TypeError: update() takes 1 positional argument but 2 were given
2021-09-04 14:54:21 ERROR (MainThread) [homeassistant] Error doing job: Future exception was never retrieved
Traceback (most recent call last):
  File "/usr/local/lib/python3.9/concurrent/futures/thread.py", line 52, in run
    result = self.fn(*self.args, **self.kwargs)
TypeError: update() takes 1 positional argument but 2 were given
2021-09-04 14:59:22 ERROR (MainThread) [homeassistant] Error doing job: Future exception was never retrieved
Traceback (most recent call last):
  File "/usr/local/lib/python3.9/concurrent/futures/thread.py", line 52, in run
    result = self.fn(*self.args, **self.kwargs)
TypeError: update() takes 1 positional argument but 2 were given
2021-09-04 15:04:18 ERROR (MainThread) [homeassistant.components.nws] Error requesting NWS observation station SAUC1 data: 503, message='Service Unavailable', url=URL('https://api.weather.gov/stations/SAUC1/observations')
2021-09-04 15:04:23 ERROR (MainThread) [homeassistant] Error doing job: Future exception was never retrieved
Traceback (most recent call last):
  File "/usr/local/lib/python3.9/concurrent/futures/thread.py", line 52, in run
    result = self.fn(*self.args, **self.kwargs)
TypeError: update() takes 1 positional argument but 2 were given
2021-09-04 15:09:24 ERROR (MainThread) [homeassistant] Error doing job: Future exception was never retrieved
Traceback (most recent call last):
  File "/usr/local/lib/python3.9/concurrent/futures/thread.py", line 52, in run
    result = self.fn(*self.args, **self.kwargs)
TypeError: update() takes 1 positional argument but 2 were given
2021-09-04 15:14:25 ERROR (MainThread) [homeassistant] Error doing job: Future exception was never retrieved
Traceback (most recent call last):
  File "/usr/local/lib/python3.9/concurrent/futures/thread.py", line 52, in run
    result = self.fn(*self.args, **self.kwargs)
TypeError: update() takes 1 positional argument but 2 were given
2021-09-04 15:19:26 ERROR (MainThread) [homeassistant] Error doing job: Future exception was never retrieved
Traceback (most recent call last):
  File "/usr/local/lib/python3.9/concurrent/futures/thread.py", line 52, in run
    result = self.fn(*self.args, **self.kwargs)
TypeError: update() takes 1 positional argument but 2 were given
2021-09-04 15:24:27 ERROR (MainThread) [homeassistant] Error doing job: Future exception was never retrieved
Traceback (most recent call last):
  File "/usr/local/lib/python3.9/concurrent/futures/thread.py", line 52, in run
    result = self.fn(*self.args, **self.kwargs)
TypeError: update() takes 1 positional argument but 2 were given
2021-09-04 15:25:40 ERROR (MainThread) [homeassistant.components.nws] Error requesting NWS observation station SAUC1 data: 503, message='Service Unavailable', url=URL('https://api.weather.gov/stations/SAUC1/observations')
2021-09-04 15:29:28 ERROR (MainThread) [homeassistant] Error doing job: Future exception was never retrieved
Traceback (most recent call last):
  File "/usr/local/lib/python3.9/concurrent/futures/thread.py", line 52, in run
    result = self.fn(*self.args, **self.kwargs)
TypeError: update() takes 1 positional argument but 2 were given
2021-09-04 15:34:29 ERROR (MainThread) [homeassistant] Error doing job: Future exception was never retrieved
Traceback (most recent call last):
  File "/usr/local/lib/python3.9/concurrent/futures/thread.py", line 52, in run
    result = self.fn(*self.args, **self.kwargs)
TypeError: update() takes 1 positional argument but 2 were given
2021-09-04 15:39:30 ERROR (MainThread) [homeassistant] Error doing job: Future exception was never retrieved
Traceback (most recent call last):
  File "/usr/local/lib/python3.9/concurrent/futures/thread.py", line 52, in run
    result = self.fn(*self.args, **self.kwargs)
TypeError: update() takes 1 positional argument but 2 were given
2021-09-04 15:44:31 ERROR (MainThread) [homeassistant] Error doing job: Future exception was never retrieved
Traceback (most recent call last):
  File "/usr/local/lib/python3.9/concurrent/futures/thread.py", line 52, in run
    result = self.fn(*self.args, **self.kwargs)
TypeError: update() takes 1 positional argument but 2 were given
2021-09-04 15:49:32 ERROR (MainThread) [homeassistant] Error doing job: Future exception was never retrieved
Traceback (most recent call last):
  File "/usr/local/lib/python3.9/concurrent/futures/thread.py", line 52, in run
    result = self.fn(*self.args, **self.kwargs)
TypeError: update() takes 1 positional argument but 2 were given
2021-09-04 15:54:33 ERROR (MainThread) [homeassistant] Error doing job: Future exception was never retrieved
Traceback (most recent call last):
  File "/usr/local/lib/python3.9/concurrent/futures/thread.py", line 52, in run
    result = self.fn(*self.args, **self.kwargs)
TypeError: update() takes 1 positional argument but 2 were given
2021-09-04 15:59:34 ERROR (MainThread) [homeassistant] Error doing job: Future exception was never retrieved
Traceback (most recent call last):
  File "/usr/local/lib/python3.9/concurrent/futures/thread.py", line 52, in run
    result = self.fn(*self.args, **self.kwargs)
TypeError: update() takes 1 positional argument but 2 were given
2021-09-04 16:04:35 ERROR (MainThread) [homeassistant] Error doing job: Future exception was never retrieved
Traceback (most recent call last):
  File "/usr/local/lib/python3.9/concurrent/futures/thread.py", line 52, in run
    result = self.fn(*self.args, **self.kwargs)
TypeError: update() takes 1 positional argument but 2 were given
2021-09-04 16:09:36 ERROR (MainThread) [homeassistant] Error doing job: Future exception was never retrieved
Traceback (most recent call last):
  File "/usr/local/lib/python3.9/concurrent/futures/thread.py", line 52, in run
    result = self.fn(*self.args, **self.kwargs)
TypeError: update() takes 1 positional argument but 2 were given
2021-09-04 16:14:37 ERROR (MainThread) [homeassistant] Error doing job: Future exception was never retrieved
Traceback (most recent call last):
  File "/usr/local/lib/python3.9/concurrent/futures/thread.py", line 52, in run
    result = self.fn(*self.args, **self.kwargs)
TypeError: update() takes 1 positional argument but 2 were given
2021-09-04 16:19:38 ERROR (MainThread) [homeassistant] Error doing job: Future exception was never retrieved
Traceback (most recent call last):
  File "/usr/local/lib/python3.9/concurrent/futures/thread.py", line 52, in run
    result = self.fn(*self.args, **self.kwargs)
TypeError: update() takes 1 positional argument but 2 were given
2021-09-04 16:24:39 ERROR (MainThread) [homeassistant] Error doing job: Future exception was never retrieved
Traceback (most recent call last):
  File "/usr/local/lib/python3.9/concurrent/futures/thread.py", line 52, in run
    result = self.fn(*self.args, **self.kwargs)
TypeError: update() takes 1 positional argument but 2 were given
2021-09-04 16:27:15 ERROR (MainThread) [homeassistant.components.nws] Error requesting NWS observation station SAUC1 data: 503, message='Service Unavailable', url=URL('https://api.weather.gov/stations/SAUC1/observations')
2021-09-04 16:29:40 ERROR (MainThread) [homeassistant] Error doing job: Future exception was never retrieved
Traceback (most recent call last):
  File "/usr/local/lib/python3.9/concurrent/futures/thread.py", line 52, in run
    result = self.fn(*self.args, **self.kwargs)
TypeError: update() takes 1 positional argument but 2 were given
2021-09-04 16:34:41 ERROR (MainThread) [homeassistant] Error doing job: Future exception was never retrieved
Traceback (most recent call last):
  File "/usr/local/lib/python3.9/concurrent/futures/thread.py", line 52, in run
    result = self.fn(*self.args, **self.kwargs)
TypeError: update() takes 1 positional argument but 2 were given
2021-09-04 16:39:42 ERROR (MainThread) [homeassistant] Error doing job: Future exception was never retrieved
Traceback (most recent call last):
  File "/usr/local/lib/python3.9/concurrent/futures/thread.py", line 52, in run
    result = self.fn(*self.args, **self.kwargs)
TypeError: update() takes 1 positional argument but 2 were given
2021-09-04 16:44:43 ERROR (MainThread) [homeassistant] Error doing job: Future exception was never retrieved
Traceback (most recent call last):
  File "/usr/local/lib/python3.9/concurrent/futures/thread.py", line 52, in run
    result = self.fn(*self.args, **self.kwargs)
TypeError: update() takes 1 positional argument but 2 were given
2021-09-04 16:49:44 ERROR (MainThread) [homeassistant] Error doing job: Future exception was never retrieved
Traceback (most recent call last):
  File "/usr/local/lib/python3.9/concurrent/futures/thread.py", line 52, in run
    result = self.fn(*self.args, **self.kwargs)
TypeError: update() takes 1 positional argument but 2 were given
2021-09-04 16:54:45 ERROR (MainThread) [homeassistant] Error doing job: Future exception was never retrieved
Traceback (most recent call last):
  File "/usr/local/lib/python3.9/concurrent/futures/thread.py", line 52, in run
    result = self.fn(*self.args, **self.kwargs)
TypeError: update() takes 1 positional argument but 2 were given
2021-09-04 16:59:46 ERROR (MainThread) [homeassistant] Error doing job: Future exception was never retrieved
Traceback (most recent call last):
  File "/usr/local/lib/python3.9/concurrent/futures/thread.py", line 52, in run
    result = self.fn(*self.args, **self.kwargs)
TypeError: update() takes 1 positional argument but 2 were given
2021-09-04 17:04:47 ERROR (MainThread) [homeassistant] Error doing job: Future exception was never retrieved
Traceback (most recent call last):
  File "/usr/local/lib/python3.9/concurrent/futures/thread.py", line 52, in run
    result = self.fn(*self.args, **self.kwargs)
TypeError: update() takes 1 positional argument but 2 were given
2021-09-04 17:09:48 ERROR (MainThread) [homeassistant] Error doing job: Future exception was never retrieved
Traceback (most recent call last):
  File "/usr/local/lib/python3.9/concurrent/futures/thread.py", line 52, in run
    result = self.fn(*self.args, **self.kwargs)
TypeError: update() takes 1 positional argument but 2 were given
2021-09-04 17:14:49 ERROR (MainThread) [homeassistant] Error doing job: Future exception was never retrieved
Traceback (most recent call last):
  File "/usr/local/lib/python3.9/concurrent/futures/thread.py", line 52, in run
    result = self.fn(*self.args, **self.kwargs)
TypeError: update() takes 1 positional argument but 2 were given
2021-09-04 17:19:50 ERROR (MainThread) [homeassistant] Error doing job: Future exception was never retrieved
Traceback (most recent call last):
  File "/usr/local/lib/python3.9/concurrent/futures/thread.py", line 52, in run
    result = self.fn(*self.args, **self.kwargs)
TypeError: update() takes 1 positional argument but 2 were given
2021-09-04 17:24:51 ERROR (MainThread) [homeassistant] Error doing job: Future exception was never retrieved
Traceback (most recent call last):
  File "/usr/local/lib/python3.9/concurrent/futures/thread.py", line 52, in run
    result = self.fn(*self.args, **self.kwargs)
TypeError: update() takes 1 positional argument but 2 were given
2021-09-04 17:29:52 ERROR (MainThread) [homeassistant] Error doing job: Future exception was never retrieved
Traceback (most recent call last):
  File "/usr/local/lib/python3.9/concurrent/futures/thread.py", line 52, in run
    result = self.fn(*self.args, **self.kwargs)
TypeError: update() takes 1 positional argument but 2 were given
2021-09-04 17:34:53 ERROR (MainThread) [homeassistant] Error doing job: Future exception was never retrieved
Traceback (most recent call last):
  File "/usr/local/lib/python3.9/concurrent/futures/thread.py", line 52, in run
    result = self.fn(*self.args, **self.kwargs)
TypeError: update() takes 1 positional argument but 2 were given
2021-09-04 17:39:54 ERROR (MainThread) [homeassistant] Error doing job: Future exception was never retrieved
Traceback (most recent call last):
  File "/usr/local/lib/python3.9/concurrent/futures/thread.py", line 52, in run
    result = self.fn(*self.args, **self.kwargs)
TypeError: update() takes 1 positional argument but 2 were given
2021-09-04 17:44:55 ERROR (MainThread) [homeassistant] Error doing job: Future exception was never retrieved
Traceback (most recent call last):
  File "/usr/local/lib/python3.9/concurrent/futures/thread.py", line 52, in run
    result = self.fn(*self.args, **self.kwargs)
TypeError: update() takes 1 positional argument but 2 were given
2021-09-04 17:49:56 ERROR (MainThread) [homeassistant] Error doing job: Future exception was never retrieved
Traceback (most recent call last):
  File "/usr/local/lib/python3.9/concurrent/futures/thread.py", line 52, in run
    result = self.fn(*self.args, **self.kwargs)
TypeError: update() takes 1 positional argument but 2 were given
2021-09-04 17:52:48 WARNING (MainThread) [bellows.zigbee.application] Watchdog heartbeat timeout: 
2021-09-04 17:53:03 ERROR (bellows.thread_0) [bellows.uart] CRC error in frame b'5e86b1a9112a15b658924a24c20251a8bd7e' (b'a8bd' != b'5d2e')
2021-09-04 17:53:03 ERROR (MainThread) [bellows.ezsp] NCP entered failed state. Requesting APP controller restart
2021-09-04 17:53:20 ERROR (Recorder) [homeassistant] Error doing job: Task was destroyed but it is pending!
2021-09-04 17:54:57 ERROR (MainThread) [homeassistant] Error doing job: Future exception was never retrieved
Traceback (most recent call last):
  File "/usr/local/lib/python3.9/concurrent/futures/thread.py", line 52, in run
    result = self.fn(*self.args, **self.kwargs)
TypeError: update() takes 1 positional argument but 2 were given
2021-09-04 17:59:58 ERROR (MainThread) [homeassistant] Error doing job: Future exception was never retrieved
Traceback (most recent call last):
  File "/usr/local/lib/python3.9/concurrent/futures/thread.py", line 52, in run
    result = self.fn(*self.args, **self.kwargs)
TypeError: update() takes 1 positional argument but 2 were given
2021-09-04 18:04:59 ERROR (MainThread) [homeassistant] Error doing job: Future exception was never retrieved
Traceback (most recent call last):
  File "/usr/local/lib/python3.9/concurrent/futures/thread.py", line 52, in run
    result = self.fn(*self.args, **self.kwargs)
TypeError: update() takes 1 positional argument but 2 were given
2021-09-04 18:10:00 ERROR (MainThread) [homeassistant] Error doing job: Future exception was never retrieved
Traceback (most recent call last):
  File "/usr/local/lib/python3.9/concurrent/futures/thread.py", line 52, in run
    result = self.fn(*self.args, **self.kwargs)
TypeError: update() takes 1 positional argument but 2 were given
2021-09-04 18:15:01 ERROR (MainThread) [homeassistant] Error doing job: Future exception was never retrieved
Traceback (most recent call last):
  File "/usr/local/lib/python3.9/concurrent/futures/thread.py", line 52, in run
    result = self.fn(*self.args, **self.kwargs)
TypeError: update() takes 1 positional argument but 2 were given
2021-09-04 18:20:02 ERROR (MainThread) [homeassistant] Error doing job: Future exception was never retrieved
Traceback (most recent call last):
  File "/usr/local/lib/python3.9/concurrent/futures/thread.py", line 52, in run
    result = self.fn(*self.args, **self.kwargs)
TypeError: update() takes 1 positional argument but 2 were given
2021-09-04 18:25:03 ERROR (MainThread) [homeassistant] Error doing job: Future exception was never retrieved
Traceback (most recent call last):
  File "/usr/local/lib/python3.9/concurrent/futures/thread.py", line 52, in run
    result = self.fn(*self.args, **self.kwargs)
TypeError: update() takes 1 positional argument but 2 were given
2021-09-04 18:30:04 ERROR (MainThread) [homeassistant] Error doing job: Future exception was never retrieved
Traceback (most recent call last):
  File "/usr/local/lib/python3.9/concurrent/futures/thread.py", line 52, in run
    result = self.fn(*self.args, **self.kwargs)
TypeError: update() takes 1 positional argument but 2 were given
2021-09-04 18:35:05 ERROR (MainThread) [homeassistant] Error doing job: Future exception was never retrieved
Traceback (most recent call last):
  File "/usr/local/lib/python3.9/concurrent/futures/thread.py", line 52, in run
    result = self.fn(*self.args, **self.kwargs)
TypeError: update() takes 1 positional argument but 2 were given
2021-09-04 18:40:06 ERROR (MainThread) [homeassistant] Error doing job: Future exception was never retrieved
Traceback (most recent call last):
  File "/usr/local/lib/python3.9/concurrent/futures/thread.py", line 52, in run
    result = self.fn(*self.args, **self.kwargs)
TypeError: update() takes 1 positional argument but 2 were given
2021-09-04 18:45:07 ERROR (MainThread) [homeassistant] Error doing job: Future exception was never retrieved
Traceback (most recent call last):
  File "/usr/local/lib/python3.9/concurrent/futures/thread.py", line 52, in run
    result = self.fn(*self.args, **self.kwargs)
TypeError: update() takes 1 positional argument but 2 were given
2021-09-04 18:50:08 ERROR (MainThread) [homeassistant] Error doing job: Future exception was never retrieved
Traceback (most recent call last):
  File "/usr/local/lib/python3.9/concurrent/futures/thread.py", line 52, in run
    result = self.fn(*self.args, **self.kwargs)
TypeError: update() takes 1 positional argument but 2 were given
2021-09-04 18:55:09 ERROR (MainThread) [homeassistant] Error doing job: Future exception was never retrieved
Traceback (most recent call last):
  File "/usr/local/lib/python3.9/concurrent/futures/thread.py", line 52, in run
    result = self.fn(*self.args, **self.kwargs)
TypeError: update() takes 1 positional argument but 2 were given
2021-09-04 19:00:10 ERROR (MainThread) [homeassistant] Error doing job: Future exception was never retrieved
Traceback (most recent call last):
  File "/usr/local/lib/python3.9/concurrent/futures/thread.py", line 52, in run
    result = self.fn(*self.args, **self.kwargs)
TypeError: update() takes 1 positional argument but 2 were given
2021-09-04 19:05:11 ERROR (MainThread) [homeassistant] Error doing job: Future exception was never retrieved
Traceback (most recent call last):
  File "/usr/local/lib/python3.9/concurrent/futures/thread.py", line 52, in run
    result = self.fn(*self.args, **self.kwargs)
TypeError: update() takes 1 positional argument but 2 were given
2021-09-04 19:09:06 WARNING (MainThread) [homeassistant.helpers.service] Unable to find referenced entities light.hue_lightstrip_2
2021-09-04 19:09:15 WARNING (MainThread) [haffmpeg.tools] Timeout reading image.
2021-09-04 19:10:12 ERROR (MainThread) [homeassistant] Error doing job: Future exception was never retrieved
Traceback (most recent call last):
  File "/usr/local/lib/python3.9/concurrent/futures/thread.py", line 52, in run
    result = self.fn(*self.args, **self.kwargs)
TypeError: update() takes 1 positional argument but 2 were given
2021-09-04 19:11:06 WARNING (MainThread) [homeassistant.components.mqtt] Can't decode payload b'{"GPIOs1":{"0":"None","32":"Button","64":"Button_n","96":"Button_i","128":"Button_in","160":"Switch","192":"Switch_n","224":"Relay","256":"Relay_i","288":"Led","320":"Led_i","352":"Counter","384":"Counter_n","416":"PWM","448":"PWM_i","480":"Buzzer","512":"Buzzer_i","544":"LedLink","576":"LedLink_i","608":"I2C SCL","640":"I2C SDA","672":"SPI MISO","704":"SPI MOSI","736":"SPI CLK","768":"SPI CS","800":"SPI DC","832":"SSPI MISO","864":"SSPI MOSI","896":"SSPI SCLK","928":"SSPI CS","960":"SSPI DC","992":"Backlight","1024":"Display Rst","1056":"IRsend","1088":"IRrecv","1120":"RFSend","1152":"RFrecv","1184":"DHT11","1216":"AM2301","1248":"SI7021","1280":"DHT11_o","1312":"DS18x20","1344":"DS18x20_o","1376":"WS2812","1408":"MHZ Tx","1440":"MHZ Rx","1472":"PZEM0XX Tx","1504":"PZEM004 Rx","1536":"PZEM016 Rx","1568":"PZEM017 Rx","1600":"SAir Tx","1632":"SAir Rx","1664":"PMS5003 Tx","1696":"PMS5003 Rx","1728":"SDS0X1 Tx","1760":"SDS0X1 Rx","1792":"SerBr Tx","1824":"SerBr Rx","1856":"SR04 Tri/TX","1888":"SR04 Ech/RX","1920":"SDMx20 Tx","1952":"SDMx20 Rx","1984":"SDM630 Tx","2016":"SDM630 Rx","2048":"TM1638 CLK","2080":"TM1638 DIO","2112":"TM1638 STB","2144":"MP3 Player","2176":"HX711 SCK","2208":"HX711 DAT","2240":"TX2x","2272":"Tuya Tx","2304":"Tuya Rx","2336":"MGC3130 Xfr","2368":"MGC3130 Rst","2400":"RF Sensor","2432":"AZ Tx","2464":"AZ Rx","2496":"MX31855 CS","2528":"MX31855 CLK","2560":"MX31855 DO","2592":"HLWBL SEL","2624":"HLWBL SEL_i","2656":"HLWBL CF1","2688":"HLW8012 CF","2720":"BL0937 CF","2752":"MCP39F5 Tx","2784":"MCP39F5 Rx","2816":"MCP39F5 Rst","2848":"PN532 Tx","2880":"PN532 Rx","2912":"SM16716 CLK","2944":"SM16716 DAT","2976":"SM16716 PWR","3008":"MY92x1 DI","3040":"MY92x1 DCKI","3072":"CSE7766 Tx","3104":"CSE7766 Rx","3136":"ALux IrRcv","3168":"ALux IrSel","3200":"Serial Tx","3232":"Serial Rx","3264":"Rotary A","3296":"Rotary B","3328":"ADC Joystick","3360":"MX31865 CS","3392":"HRE Clock","3424":"HRE Data","3456":"ADE7953 IRQ","3488":"SolaxX1 Tx","3520":"SolaxX1 Rx","3552":"Zigbee Tx","3584":"Zigbee Rx","3616":"RDM6300 RX","3648":"iBeacon TX","3680":"iBeacon RX","3712":"A4988 DIR","3744":"A4988 STP","3776":"A4988 ENA","3808":"A4988 MS1","3840":"Output Hi","3872":"Output Lo","3904":"DDS238-2 Tx","3936":"DDS238-2 Rx","3968":"DDSU666 Tx","4000":"DDSU666 Rx","4032":"SM2135 Clk","4064":"SM2135 Dat","4096":"DeepSleep","4128":"EXS Enable","4160":"Client TX","4192":"Client RX","4224":"Client RST","4256":"Client RST_i","4288":"HPMA Rx","4320":"HPMA Tx","4352":"GPS RX","4384":"GPS TX","4416":"HM10 RX","4448":"HM10 TX","4480":"LE-01MR Rx","4512":"LE-01MR Tx","4544":"CC1101 GDO0","4576":"CC1101 GDO2","4608":"HRXL Rx","4640":"MOODL Tx","4672":"AS3935","4704":"ADC Input","4736":"ADC Temp","4768":"ADC Light","4800":"ADC Button","4832":"ADC Button_i","4864":"ADC Range","4896":"ADC CT Power","4928":"OpenTherm RX","4960":"OpenTherm TX","4992":"WindMeter0\xda\x03\x00\x18stat/KitchenLight/RESULT{"GPIOs2":{"6656":"TM1637 DIO","6688":"DLP Tx","6720":"DLP Rx","6752":"SSD1351 DC","6784":"XPT2046 CS","6816":"CSE7761 Tx","6848":"CSE7761 Rx","6880":"VL53L0X XSHUT","6912":"MAX7219 CLK","6944":"MAX7219 DIN","6976":"MAX7219 CS","7008":"TFmini+ TX","7040":"TFmini+ RX","7072":"ZC Pulse","7104":"Input","7136":"I2S Out Data","7168":"I2S Out Clk","7200":"I2S Out Slct","7232":"I2S In Data","7264":"I2S In Clk","7296":"I2S In Slct","7328":"Interrupt"}}0@\x00\x18stat/KitchenLight/RESULT{"PulseTime2":{"Set":0,"Remaining":0}}0\xfd\x02\x00\x18stat/KitchenLight/STATUS{"Status":{"Module":0,"DeviceName":"KitchenLight","FriendlyName":["KitchenLight"],"Topic":"KitchenLight","ButtonTopic":"0","Power":1,"PowerOnState":3,"LedState":1,"LedMask":"FFFF","SaveData":1,"SaveState":1,"SwitchTopic":"0","SwitchMode":[0,0,0,0,0,0,0,0],"ButtonRetain":0,"SwitchRetain":0,"SensorRetain":0,"PowerRetain":1,"InfoRetain":0,"StateRetain":0}}0\xf2\x02\x00\x19stat/KitchenLight/STATUS1{"StatusPRM":{"Baudra' on stat/KitchenLight/RESULT with encoding utf-8 (for <Job HassJobType.Callback <function TasmotaLight.subscribe_topics.<locals>.state_message_received at 0x14941a0084c0>>)
2021-09-04 19:15:13 ERROR (MainThread) [homeassistant] Error doing job: Future exception was never retrieved
Traceback (most recent call last):
  File "/usr/local/lib/python3.9/concurrent/futures/thread.py", line 52, in run
    result = self.fn(*self.args, **self.kwargs)
TypeError: update() takes 1 positional argument but 2 were given
2021-09-04 19:15:27 WARNING (MainThread) [homeassistant.helpers.service] Unable to find referenced entities scene.kitchen_sink_on
2021-09-04 19:15:27 WARNING (MainThread) [homeassistant.helpers.service] Unable to find referenced entities light.hue_lightstrip_2
2021-09-04 19:20:14 ERROR (MainThread) [homeassistant] Error doing job: Future exception was never retrieved
Traceback (most recent call last):
  File "/usr/local/lib/python3.9/concurrent/futures/thread.py", line 52, in run
    result = self.fn(*self.args, **self.kwargs)
TypeError: update() takes 1 positional argument but 2 were given
2021-09-04 19:25:15 ERROR (MainThread) [homeassistant] Error doing job: Future exception was never retrieved
Traceback (most recent call last):
  File "/usr/local/lib/python3.9/concurrent/futures/thread.py", line 52, in run
    result = self.fn(*self.args, **self.kwargs)
TypeError: update() takes 1 positional argument but 2 were given
2021-09-04 19:30:16 ERROR (MainThread) [homeassistant] Error doing job: Future exception was never retrieved
Traceback (most recent call last):
  File "/usr/local/lib/python3.9/concurrent/futures/thread.py", line 52, in run
    result = self.fn(*self.args, **self.kwargs)
TypeError: update() takes 1 positional argument but 2 were given
2021-09-04 19:35:17 ERROR (MainThread) [homeassistant] Error doing job: Future exception was never retrieved
Traceback (most recent call last):
  File "/usr/local/lib/python3.9/concurrent/futures/thread.py", line 52, in run
    result = self.fn(*self.args, **self.kwargs)
TypeError: update() takes 1 positional argument but 2 were given
2021-09-04 19:40:18 ERROR (MainThread) [homeassistant] Error doing job: Future exception was never retrieved
Traceback (most recent call last):
  File "/usr/local/lib/python3.9/concurrent/futures/thread.py", line 52, in run
    result = self.fn(*self.args, **self.kwargs)
TypeError: update() takes 1 positional argument but 2 were given
2021-09-04 19:45:19 ERROR (MainThread) [homeassistant] Error doing job: Future exception was never retrieved
Traceback (most recent call last):
  File "/usr/local/lib/python3.9/concurrent/futures/thread.py", line 52, in run
    result = self.fn(*self.args, **self.kwargs)
TypeError: update() takes 1 positional argument but 2 were given
2021-09-04 19:50:20 ERROR (MainThread) [homeassistant] Error doing job: Future exception was never retrieved
Traceback (most recent call last):
  File "/usr/local/lib/python3.9/concurrent/futures/thread.py", line 52, in run
    result = self.fn(*self.args, **self.kwargs)
TypeError: update() takes 1 positional argument but 2 were given
2021-09-04 19:55:21 ERROR (MainThread) [homeassistant] Error doing job: Future exception was never retrieved
Traceback (most recent call last):
  File "/usr/local/lib/python3.9/concurrent/futures/thread.py", line 52, in run
    result = self.fn(*self.args, **self.kwargs)
TypeError: update() takes 1 positional argument but 2 were given
2021-09-04 20:00:22 ERROR (MainThread) [homeassistant] Error doing job: Future exception was never retrieved
Traceback (most recent call last):
  File "/usr/local/lib/python3.9/concurrent/futures/thread.py", line 52, in run
    result = self.fn(*self.args, **self.kwargs)
TypeError: update() takes 1 positional argument but 2 were given
2021-09-04 20:05:23 ERROR (MainThread) [homeassistant] Error doing job: Future exception was never retrieved
Traceback (most recent call last):
  File "/usr/local/lib/python3.9/concurrent/futures/thread.py", line 52, in run
    result = self.fn(*self.args, **self.kwargs)
TypeError: update() takes 1 positional argument but 2 were given
2021-09-04 20:10:24 ERROR (MainThread) [homeassistant] Error doing job: Future exception was never retrieved
Traceback (most recent call last):
  File "/usr/local/lib/python3.9/concurrent/futures/thread.py", line 52, in run
    result = self.fn(*self.args, **self.kwargs)
TypeError: update() takes 1 positional argument but 2 were given
2021-09-04 20:15:25 ERROR (SyncWorker_0) [homeassistant] Error doing job: Future exception was never retrieved
Traceback (most recent call last):
  File "/usr/local/lib/python3.9/concurrent/futures/thread.py", line 52, in run
    result = self.fn(*self.args, **self.kwargs)
TypeError: update() takes 1 positional argument but 2 were given
2021-09-04 20:20:26 ERROR (MainThread) [homeassistant] Error doing job: Future exception was never retrieved
Traceback (most recent call last):
  File "/usr/local/lib/python3.9/concurrent/futures/thread.py", line 52, in run
    result = self.fn(*self.args, **self.kwargs)
TypeError: update() takes 1 positional argument but 2 were given
2021-09-04 20:25:27 ERROR (MainThread) [homeassistant] Error doing job: Future exception was never retrieved
Traceback (most recent call last):
  File "/usr/local/lib/python3.9/concurrent/futures/thread.py", line 52, in run
    result = self.fn(*self.args, **self.kwargs)
TypeError: update() takes 1 positional argument but 2 were given
2021-09-04 20:30:28 ERROR (MainThread) [homeassistant] Error doing job: Future exception was never retrieved
Traceback (most recent call last):
  File "/usr/local/lib/python3.9/concurrent/futures/thread.py", line 52, in run
    result = self.fn(*self.args, **self.kwargs)
TypeError: update() takes 1 positional argument but 2 were given
2021-09-04 20:35:29 ERROR (MainThread) [homeassistant] Error doing job: Future exception was never retrieved
Traceback (most recent call last):
  File "/usr/local/lib/python3.9/concurrent/futures/thread.py", line 52, in run
    result = self.fn(*self.args, **self.kwargs)
TypeError: update() takes 1 positional argument but 2 were given
2021-09-04 20:40:30 ERROR (MainThread) [homeassistant] Error doing job: Future exception was never retrieved
Traceback (most recent call last):
  File "/usr/local/lib/python3.9/concurrent/futures/thread.py", line 52, in run
    result = self.fn(*self.args, **self.kwargs)
TypeError: update() takes 1 positional argument but 2 were given
2021-09-04 20:45:31 ERROR (MainThread) [homeassistant] Error doing job: Future exception was never retrieved
Traceback (most recent call last):
  File "/usr/local/lib/python3.9/concurrent/futures/thread.py", line 52, in run
    result = self.fn(*self.args, **self.kwargs)
TypeError: update() takes 1 positional argument but 2 were given
2021-09-04 20:50:32 ERROR (MainThread) [homeassistant] Error doing job: Future exception was never retrieved
Traceback (most recent call last):
  File "/usr/local/lib/python3.9/concurrent/futures/thread.py", line 52, in run
    result = self.fn(*self.args, **self.kwargs)
TypeError: update() takes 1 positional argument but 2 were given
2021-09-04 20:55:33 ERROR (MainThread) [homeassistant] Error doing job: Future exception was never retrieved
Traceback (most recent call last):
  File "/usr/local/lib/python3.9/concurrent/futures/thread.py", line 52, in run
    result = self.fn(*self.args, **self.kwargs)
TypeError: update() takes 1 positional argument but 2 were given
2021-09-04 20:59:08 ERROR (MainThread) [homeassistant.components.nws] Error requesting NWS observation station SAUC1 data: 503, message='Service Unavailable', url=URL('https://api.weather.gov/stations/SAUC1/observations')
2021-09-04 21:00:34 ERROR (MainThread) [homeassistant] Error doing job: Task exception was never retrieved
Traceback (most recent call last):
  File "/usr/local/lib/python3.9/site-packages/zigpy/device.py", line 287, in request
    raise zigpy.exceptions.DeliveryError(
zigpy.exceptions.DeliveryError: [0x82b0:1:0x0500]: Message send failure
2021-09-04 21:00:34 ERROR (MainThread) [homeassistant] Error doing job: Future exception was never retrieved
Traceback (most recent call last):
  File "/usr/local/lib/python3.9/concurrent/futures/thread.py", line 52, in run
    result = self.fn(*self.args, **self.kwargs)
TypeError: update() takes 1 positional argument but 2 were given
2021-09-04 21:00:34 ERROR (MainThread) [homeassistant] Error doing job: Task exception was never retrieved
Traceback (most recent call last):
  File "/usr/local/lib/python3.9/site-packages/zigpy/device.py", line 287, in request
    raise zigpy.exceptions.DeliveryError(
zigpy.exceptions.DeliveryError: [0x82b0:1:0x0500]: Message send failure
2021-09-04 21:05:35 ERROR (MainThread) [homeassistant] Error doing job: Future exception was never retrieved
Traceback (most recent call last):
  File "/usr/local/lib/python3.9/concurrent/futures/thread.py", line 52, in run
    result = self.fn(*self.args, **self.kwargs)
TypeError: update() takes 1 positional argument but 2 were given
2021-09-04 21:10:36 ERROR (MainThread) [homeassistant] Error doing job: Future exception was never retrieved
Traceback (most recent call last):
  File "/usr/local/lib/python3.9/concurrent/futures/thread.py", line 52, in run
    result = self.fn(*self.args, **self.kwargs)
TypeError: update() takes 1 positional argument but 2 were given
2021-09-04 21:15:37 ERROR (MainThread) [homeassistant] Error doing job: Future exception was never retrieved
Traceback (most recent call last):
  File "/usr/local/lib/python3.9/concurrent/futures/thread.py", line 52, in run
    result = self.fn(*self.args, **self.kwargs)
TypeError: update() takes 1 positional argument but 2 were given
2021-09-04 21:20:38 ERROR (MainThread) [homeassistant] Error doing job: Future exception was never retrieved
Traceback (most recent call last):
  File "/usr/local/lib/python3.9/concurrent/futures/thread.py", line 52, in run
    result = self.fn(*self.args, **self.kwargs)
TypeError: update() takes 1 positional argument but 2 were given
2021-09-04 21:25:39 ERROR (MainThread) [homeassistant] Error doing job: Future exception was never retrieved
Traceback (most recent call last):
  File "/usr/local/lib/python3.9/concurrent/futures/thread.py", line 52, in run
    result = self.fn(*self.args, **self.kwargs)
TypeError: update() takes 1 positional argument but 2 were given
2021-09-04 21:30:40 ERROR (MainThread) [homeassistant] Error doing job: Future exception was never retrieved
Traceback (most recent call last):
  File "/usr/local/lib/python3.9/concurrent/futures/thread.py", line 52, in run
    result = self.fn(*self.args, **self.kwargs)
TypeError: update() takes 1 positional argument but 2 were given
2021-09-04 21:35:41 ERROR (MainThread) [homeassistant] Error doing job: Future exception was never retrieved
Traceback (most recent call last):
  File "/usr/local/lib/python3.9/concurrent/futures/thread.py", line 52, in run
    result = self.fn(*self.args, **self.kwargs)
TypeError: update() takes 1 positional argument but 2 were given
2021-09-04 21:40:42 ERROR (MainThread) [homeassistant] Error doing job: Future exception was never retrieved
Traceback (most recent call last):
  File "/usr/local/lib/python3.9/concurrent/futures/thread.py", line 52, in run
    result = self.fn(*self.args, **self.kwargs)
TypeError: update() takes 1 positional argument but 2 were given
2021-09-04 21:45:43 ERROR (MainThread) [homeassistant] Error doing job: Future exception was never retrieved
Traceback (most recent call last):
  File "/usr/local/lib/python3.9/concurrent/futures/thread.py", line 52, in run
    result = self.fn(*self.args, **self.kwargs)
TypeError: update() takes 1 positional argument but 2 were given
2021-09-04 21:50:44 ERROR (MainThread) [homeassistant] Error doing job: Future exception was never retrieved
Traceback (most recent call last):
  File "/usr/local/lib/python3.9/concurrent/futures/thread.py", line 52, in run
    result = self.fn(*self.args, **self.kwargs)
TypeError: update() takes 1 positional argument but 2 were given
2021-09-04 21:55:45 ERROR (MainThread) [homeassistant] Error doing job: Future exception was never retrieved
Traceback (most recent call last):
  File "/usr/local/lib/python3.9/concurrent/futures/thread.py", line 52, in run
    result = self.fn(*self.args, **self.kwargs)
TypeError: update() takes 1 positional argument but 2 were given
2021-09-04 22:00:46 ERROR (MainThread) [homeassistant] Error doing job: Future exception was never retrieved
Traceback (most recent call last):
  File "/usr/local/lib/python3.9/concurrent/futures/thread.py", line 52, in run
    result = self.fn(*self.args, **self.kwargs)
TypeError: update() takes 1 positional argument but 2 were given
2021-09-04 22:05:47 ERROR (MainThread) [homeassistant] Error doing job: Future exception was never retrieved
Traceback (most recent call last):
  File "/usr/local/lib/python3.9/concurrent/futures/thread.py", line 52, in run
    result = self.fn(*self.args, **self.kwargs)
TypeError: update() takes 1 positional argument but 2 were given
2021-09-04 22:10:48 ERROR (MainThread) [homeassistant] Error doing job: Future exception was never retrieved
Traceback (most recent call last):
  File "/usr/local/lib/python3.9/concurrent/futures/thread.py", line 52, in run
    result = self.fn(*self.args, **self.kwargs)
TypeError: update() takes 1 positional argument but 2 were given
2021-09-04 22:12:02 WARNING (Recorder) [homeassistant.components.sensor.recorder] Entity sensor.solar_energy from integration integration has state class total_increasing, but its state is not strictly increasing. Please create a bug report at https://github.com/home-assistant/core/issues?q=is%3Aopen+is%3Aissue+label%3A%22integration%3A+recorder%22
2021-09-04 22:15:49 ERROR (MainThread) [homeassistant] Error doing job: Future exception was never retrieved
Traceback (most recent call last):
  File "/usr/local/lib/python3.9/concurrent/futures/thread.py", line 52, in run
    result = self.fn(*self.args, **self.kwargs)
TypeError: update() takes 1 positional argument but 2 were given
2021-09-04 22:15:54 WARNING (MainThread) [haffmpeg.tools] Timeout reading image.
2021-09-04 22:16:02 WARNING (MainThread) [haffmpeg.tools] Timeout reading image.
2021-09-04 22:16:53 WARNING (MainThread) [haffmpeg.tools] Timeout reading image.
2021-09-04 22:17:22 WARNING (MainThread) [haffmpeg.tools] Timeout reading image.
2021-09-04 22:20:50 ERROR (MainThread) [homeassistant] Error doing job: Future exception was never retrieved
Traceback (most recent call last):
  File "/usr/local/lib/python3.9/concurrent/futures/thread.py", line 52, in run
    result = self.fn(*self.args, **self.kwargs)
TypeError: update() takes 1 positional argument but 2 were given
2021-09-04 22:25:51 ERROR (MainThread) [homeassistant] Error doing job: Future exception was never retrieved
Traceback (most recent call last):
  File "/usr/local/lib/python3.9/concurrent/futures/thread.py", line 52, in run
    result = self.fn(*self.args, **self.kwargs)
TypeError: update() takes 1 positional argument but 2 were given
2021-09-04 22:30:52 ERROR (MainThread) [homeassistant] Error doing job: Future exception was never retrieved
Traceback (most recent call last):
  File "/usr/local/lib/python3.9/concurrent/futures/thread.py", line 52, in run
    result = self.fn(*self.args, **self.kwargs)
TypeError: update() takes 1 positional argument but 2 were given
2021-09-04 22:35:53 ERROR (MainThread) [homeassistant] Error doing job: Future exception was never retrieved
Traceback (most recent call last):
  File "/usr/local/lib/python3.9/concurrent/futures/thread.py", line 52, in run
    result = self.fn(*self.args, **self.kwargs)
TypeError: update() takes 1 positional argument but 2 were given
2021-09-04 22:40:54 ERROR (MainThread) [homeassistant] Error doing job: Future exception was never retrieved
Traceback (most recent call last):
  File "/usr/local/lib/python3.9/concurrent/futures/thread.py", line 52, in run
    result = self.fn(*self.args, **self.kwargs)
TypeError: update() takes 1 positional argument but 2 were given
2021-09-04 22:45:55 ERROR (MainThread) [homeassistant] Error doing job: Future exception was never retrieved
Traceback (most recent call last):
  File "/usr/local/lib/python3.9/concurrent/futures/thread.py", line 52, in run
    result = self.fn(*self.args, **self.kwargs)
TypeError: update() takes 1 positional argument but 2 were given
2021-09-04 22:47:08 ERROR (MainThread) [homeassistant] Error doing job: Task exception was never retrieved
Traceback (most recent call last):
  File "/usr/local/lib/python3.9/site-packages/zigpy/device.py", line 287, in request
    raise zigpy.exceptions.DeliveryError(
zigpy.exceptions.DeliveryError: [0xa8ad:1:0x0500]: Message send failure
2021-09-04 22:47:08 ERROR (MainThread) [homeassistant] Error doing job: Task exception was never retrieved
Traceback (most recent call last):
  File "/usr/local/lib/python3.9/site-packages/zigpy/device.py", line 287, in request
    raise zigpy.exceptions.DeliveryError(
zigpy.exceptions.DeliveryError: [0xa8ad:1:0x0500]: Message send failure
2021-09-04 22:50:56 ERROR (MainThread) [homeassistant] Error doing job: Future exception was never retrieved
Traceback (most recent call last):
  File "/usr/local/lib/python3.9/concurrent/futures/thread.py", line 52, in run
    result = self.fn(*self.args, **self.kwargs)
TypeError: update() takes 1 positional argument but 2 were given
2021-09-04 22:55:57 ERROR (MainThread) [homeassistant] Error doing job: Future exception was never retrieved
Traceback (most recent call last):
  File "/usr/local/lib/python3.9/concurrent/futures/thread.py", line 52, in run
    result = self.fn(*self.args, **self.kwargs)
TypeError: update() takes 1 positional argument but 2 were given
2021-09-04 23:00:00 WARNING (MainThread) [homeassistant.helpers.service] Unable to find referenced entities light.sophia_wled
2021-09-04 23:00:58 ERROR (MainThread) [homeassistant] Error doing job: Future exception was never retrieved
Traceback (most recent call last):
  File "/usr/local/lib/python3.9/concurrent/futures/thread.py", line 52, in run
    result = self.fn(*self.args, **self.kwargs)
TypeError: update() takes 1 positional argument but 2 were given
2021-09-04 23:05:59 ERROR (MainThread) [homeassistant] Error doing job: Future exception was never retrieved
Traceback (most recent call last):
  File "/usr/local/lib/python3.9/concurrent/futures/thread.py", line 52, in run
    result = self.fn(*self.args, **self.kwargs)
TypeError: update() takes 1 positional argument but 2 were given
2021-09-04 23:11:00 ERROR (MainThread) [homeassistant] Error doing job: Future exception was never retrieved
Traceback (most recent call last):
  File "/usr/local/lib/python3.9/concurrent/futures/thread.py", line 52, in run
    result = self.fn(*self.args, **self.kwargs)
TypeError: update() takes 1 positional argument but 2 were given
2021-09-04 23:16:01 ERROR (MainThread) [homeassistant] Error doing job: Future exception was never retrieved
Traceback (most recent call last):
  File "/usr/local/lib/python3.9/concurrent/futures/thread.py", line 52, in run
    result = self.fn(*self.args, **self.kwargs)
TypeError: update() takes 1 positional argument but 2 were given
2021-09-04 23:21:02 ERROR (MainThread) [homeassistant] Error doing job: Future exception was never retrieved
Traceback (most recent call last):
  File "/usr/local/lib/python3.9/concurrent/futures/thread.py", line 52, in run
    result = self.fn(*self.args, **self.kwargs)
TypeError: update() takes 1 positional argument but 2 were given
2021-09-04 23:26:03 ERROR (MainThread) [homeassistant] Error doing job: Future exception was never retrieved
Traceback (most recent call last):
  File "/usr/local/lib/python3.9/concurrent/futures/thread.py", line 52, in run
    result = self.fn(*self.args, **self.kwargs)
TypeError: update() takes 1 positional argument but 2 were given
2021-09-04 23:31:04 ERROR (MainThread) [homeassistant] Error doing job: Future exception was never retrieved
Traceback (most recent call last):
  File "/usr/local/lib/python3.9/concurrent/futures/thread.py", line 52, in run
    result = self.fn(*self.args, **self.kwargs)
TypeError: update() takes 1 positional argument but 2 were given
2021-09-04 23:36:05 ERROR (MainThread) [homeassistant] Error doing job: Future exception was never retrieved
Traceback (most recent call last):
  File "/usr/local/lib/python3.9/concurrent/futures/thread.py", line 52, in run
    result = self.fn(*self.args, **self.kwargs)
TypeError: update() takes 1 positional argument but 2 were given
2021-09-04 23:40:34 WARNING (MainThread) [homeassistant.components.mqtt] Can't decode payload b'{"GPIOs1":{"0":"None","32":"Button","64":"Button_n","96":"Button_i","128":"Button_in","160":"Switch","192":"Switch_n","224":"Relay","256":"Relay_i","288":"Led","320":"Led_i","352":"Counter","384":"Counter_n","416":"PWM","448":"PWM_i","480":"Buzzer","512":"Buzzer_i","544":"LedLink","576":"LedLink_i","608":"I2C SCL","640":"I2C SDA","672":"SPI MISO","704":"SPI MOSI","736":"SPI CLK","768":"SPI CS","800":"SPI DC","832":"SSPI MISO","864":"SSPI MOSI","896":"SSPI SCLK","928":"SSPI CS","960":"SSPI DC","992":"Backlight","1024":"Display Rst","1056":"IRsend","1088":"IRrecv","1120":"RFSend","1152":"RFrecv","1184":"DHT11","1216":"AM2301","1248":"SI7021","1280":"DHT11_o","1312":"DS18x20","1344":"DS18x20_o","1376":"WS2812","1408":"MHZ Tx","1440":"MHZ Rx","1472":"PZEM0XX Tx","1504":"PZEM004 Rx","1536":"PZEM016 Rx","1568":"PZEM017 Rx","1600":"SAir Tx","1632":"SAir Rx","1664":"PMS5003 Tx","1696":"PMS5003 Rx","1728":"SDS0X1 Tx","1760":"SDS0X1 Rx","1792":"SerBr Tx","1824":"SerBr Rx","1856":"SR04 Tri/TX","1888":"SR04 Ech/RX","1920":"SDMx20 Tx","1952":"SDMx20 Rx","1984":"SDM630 Tx","2016":"SDM630 Rx","2048":"TM1638 CLK","2080":"TM1638 DIO","2112":"TM1638 STB","2144":"MP3 Player","2176":"HX711 SCK","2208":"HX711 DAT","2240":"TX2x","2272":"Tuya Tx","2304":"Tuya Rx","2336":"MGC3130 Xfr","2368":"MGC3130 Rst","2400":"RF Sensor","2432":"AZ Tx","2464":"AZ Rx","2496":"MX31855 CS","2528":"MX31855 CLK","2560":"MX31855 DO","2592":"HLWBL SEL","2624":"HLWBL SEL_i","2656":"HLWBL CF1","2688":"HLW8012 CF","2720":"BL0937 CF","2752":"MCP39F5 Tx","2784":"MCP39F5 Rx","2816":"MCP39F5 Rst","2848":"PN532 Tx","2880":"PN532 Rx","2912":"SM16716 CLK","2944":"SM16716 DAT","2976":"SM16716 PWR","3008":"MY92x1 DI","3040":"MY92x1 DCKI","3072":"CSE7766 Tx","3104":"CSE7766 Rx","3136":"ALux IrRcv","3168":"ALux IrSel","3200":"Serial Tx","3232":"Serial Rx","3264":"Rotary A","3296":"Rotary B","3328":"ADC Joystick","3360":"MX31865 CS","3392":"HRE Clock","3424":"HRE Data","3456":"ADE7953 IRQ","3488":"SolaxX1 Tx","3520":"SolaxX1 Rx","3552":"Zigbee Tx","3584":"Zigbee Rx","3616":"RDM6300 RX","3648":"iBeacon TX","3680":"iBeacon RX","3712":"A4988 DIR","3744":"A4988 STP","3776":"A4988 ENA","3808":"A4988 MS1","3840":"Output Hi","3872":"Output Lo","3904":"DDS238-2 Tx","3936":"DDS238-2 Rx","3968":"DDSU666 Tx","4000":"DDSU666 Rx","4032":"SM2135 Clk","4064":"SM2135 Dat","4096":"DeepSleep","4128":"EXS Enable","4160":"Client TX","4192":"Client RX","4224":"Client RST","4256":"Client RST_i","4288":"HPMA Rx","4320":"HPMA Tx","4352":"GPS RX","4384":"GPS TX","4416":"HM10 RX","4448":"HM10 TX","4480":"LE-01MR Rx","4512":"LE-01MR Tx","4544":"CC1101 GDO0","4576":"CC1101 GDO2","4608":"HRXL Rx","4640":"MOODL Tx","4672":"AS3935","4704":"ADC Input","4736":"ADC Temp","4768":"ADC Light","4800":"ADC Button","4832":"ADC Button_i","4864":"ADC Range","4896":"ADC CT Power","4928":"OpenTherm RX","4960":"OpenTherm TX","4992":"0\xe3\x03\x00!stat/WaterHeaterPumpSwitch/RESULT{"GPIOs2":{"6656":"TM1637 DIO","6688":"DLP Tx","6720":"DLP Rx","6752":"SSD1351 DC","6784":"XPT2046 CS","6816":"CSE7761 Tx","6848":"CSE7761 Rx","6880":"VL53L0X XSHUT","6912":"MAX7219 CLK","6944":"MAX7219 DIN","6976":"MAX7219 CS","7008":"TFmini+ TX","7040":"TFmini+ RX","7072":"ZC Pulse","7104":"Input","7136":"I2S Out Data","7168":"I2S Out Clk","7200":"I2S Out Slct","7232":"I2S In Data","7264":"I2S In Clk","7296":"I2S In Slct","7328":"Interrupt"}}03\x00!stat/WaterHeaterPumpSwitch/RESULT{"BlinkTime":10}0I\x00!stat/WaterHeaterPumpSwitch/RESULT{"PulseTime2":{"Set":0,"Remaining":0}}0I\x00!stat/WaterHeaterPumpSwitch/RESULT{"PulseTime6":{"Set":0,"Remaining":0}}08\x00!stat/WaterHeaterPumpSwitch/RESULT{"SwitchDebounce":50}0I\x00!stat/WaterHeaterPumpSwitch/RESULT{"PulseTime4":{"Set":0,"Remaining":0}}00\x00!stat/WaterHeaterPumpSwitch/RESULT{"MqttLog":0}0I\x00!stat/WaterHeaterPumpSwitch/RESULT{"PulseTime8":{"Set":0,"Remaining":0}}0\x89\x0b\x00!stat/WaterHeaterPumpSwitch/RESULT{"' on stat/WaterHeaterPumpSwitch/RESULT with encoding utf-8 (for <Job HassJobType.Callback <function TasmotaRelay.subscribe_topics.<locals>.state_message_received at 0x149419fefee0>>)
2021-09-04 23:41:06 ERROR (MainThread) [homeassistant] Error doing job: Future exception was never retrieved
Traceback (most recent call last):
  File "/usr/local/lib/python3.9/concurrent/futures/thread.py", line 52, in run
    result = self.fn(*self.args, **self.kwargs)
TypeError: update() takes 1 positional argument but 2 were given
2021-09-04 23:41:15 WARNING (MainThread) [homeassistant.helpers.service] Unable to find referenced entities light.hue_lightstrip_2
2021-09-04 23:46:07 ERROR (MainThread) [homeassistant] Error doing job: Future exception was never retrieved
Traceback (most recent call last):
  File "/usr/local/lib/python3.9/concurrent/futures/thread.py", line 52, in run
    result = self.fn(*self.args, **self.kwargs)
TypeError: update() takes 1 positional argument but 2 were given
2021-09-04 23:51:08 ERROR (MainThread) [homeassistant] Error doing job: Future exception was never retrieved
Traceback (most recent call last):
  File "/usr/local/lib/python3.9/concurrent/futures/thread.py", line 52, in run
    result = self.fn(*self.args, **self.kwargs)
TypeError: update() takes 1 positional argument but 2 were given
2021-09-04 23:56:09 ERROR (MainThread) [homeassistant] Error doing job: Future exception was never retrieved
Traceback (most recent call last):
  File "/usr/local/lib/python3.9/concurrent/futures/thread.py", line 52, in run
    result = self.fn(*self.args, **self.kwargs)
TypeError: update() takes 1 positional argument but 2 were given
2021-09-05 00:01:10 ERROR (MainThread) [homeassistant] Error doing job: Future exception was never retrieved
Traceback (most recent call last):
  File "/usr/local/lib/python3.9/concurrent/futures/thread.py", line 52, in run
    result = self.fn(*self.args, **self.kwargs)
TypeError: update() takes 1 positional argument but 2 were given
2021-09-05 00:06:11 ERROR (MainThread) [homeassistant] Error doing job: Future exception was never retrieved
Traceback (most recent call last):
  File "/usr/local/lib/python3.9/concurrent/futures/thread.py", line 52, in run
    result = self.fn(*self.args, **self.kwargs)
TypeError: update() takes 1 positional argument but 2 were given
2021-09-05 00:11:12 ERROR (MainThread) [homeassistant] Error doing job: Future exception was never retrieved
Traceback (most recent call last):
  File "/usr/local/lib/python3.9/concurrent/futures/thread.py", line 52, in run
    result = self.fn(*self.args, **self.kwargs)
TypeError: update() takes 1 positional argument but 2 were given
2021-09-05 00:16:13 ERROR (MainThread) [homeassistant] Error doing job: Future exception was never retrieved
Traceback (most recent call last):
  File "/usr/local/lib/python3.9/concurrent/futures/thread.py", line 52, in run
    result = self.fn(*self.args, **self.kwargs)
TypeError: update() takes 1 positional argument but 2 were given
2021-09-05 00:21:14 ERROR (MainThread) [homeassistant] Error doing job: Future exception was never retrieved
Traceback (most recent call last):
  File "/usr/local/lib/python3.9/concurrent/futures/thread.py", line 52, in run
    result = self.fn(*self.args, **self.kwargs)
TypeError: update() takes 1 positional argument but 2 were given
2021-09-05 00:26:15 ERROR (MainThread) [homeassistant] Error doing job: Future exception was never retrieved
Traceback (most recent call last):
  File "/usr/local/lib/python3.9/concurrent/futures/thread.py", line 52, in run
    result = self.fn(*self.args, **self.kwargs)
TypeError: update() takes 1 positional argument but 2 were given
2021-09-05 00:31:16 ERROR (MainThread) [homeassistant] Error doing job: Future exception was never retrieved
Traceback (most recent call last):
  File "/usr/local/lib/python3.9/concurrent/futures/thread.py", line 52, in run
    result = self.fn(*self.args, **self.kwargs)
TypeError: update() takes 1 positional argument but 2 were given
2021-09-05 00:36:17 ERROR (MainThread) [homeassistant] Error doing job: Future exception was never retrieved
Traceback (most recent call last):
  File "/usr/local/lib/python3.9/concurrent/futures/thread.py", line 52, in run
    result = self.fn(*self.args, **self.kwargs)
TypeError: update() takes 1 positional argument but 2 were given
2021-09-05 00:41:18 ERROR (MainThread) [homeassistant] Error doing job: Future exception was never retrieved
Traceback (most recent call last):
  File "/usr/local/lib/python3.9/concurrent/futures/thread.py", line 52, in run
    result = self.fn(*self.args, **self.kwargs)
TypeError: update() takes 1 positional argument but 2 were given
2021-09-05 00:46:19 ERROR (MainThread) [homeassistant] Error doing job: Future exception was never retrieved
Traceback (most recent call last):
  File "/usr/local/lib/python3.9/concurrent/futures/thread.py", line 52, in run
    result = self.fn(*self.args, **self.kwargs)
TypeError: update() takes 1 positional argument but 2 were given
2021-09-05 00:51:20 ERROR (MainThread) [homeassistant] Error doing job: Future exception was never retrieved
Traceback (most recent call last):
  File "/usr/local/lib/python3.9/concurrent/futures/thread.py", line 52, in run
    result = self.fn(*self.args, **self.kwargs)
TypeError: update() takes 1 positional argument but 2 were given
2021-09-05 00:56:21 ERROR (MainThread) [homeassistant] Error doing job: Future exception was never retrieved
Traceback (most recent call last):
  File "/usr/local/lib/python3.9/concurrent/futures/thread.py", line 52, in run
    result = self.fn(*self.args, **self.kwargs)
TypeError: update() takes 1 positional argument but 2 were given
2021-09-05 01:01:22 ERROR (MainThread) [homeassistant] Error doing job: Future exception was never retrieved
Traceback (most recent call last):
  File "/usr/local/lib/python3.9/concurrent/futures/thread.py", line 52, in run
    result = self.fn(*self.args, **self.kwargs)
TypeError: update() takes 1 positional argument but 2 were given
2021-09-05 01:06:23 ERROR (MainThread) [homeassistant] Error doing job: Future exception was never retrieved
Traceback (most recent call last):
  File "/usr/local/lib/python3.9/concurrent/futures/thread.py", line 52, in run
    result = self.fn(*self.args, **self.kwargs)
TypeError: update() takes 1 positional argument but 2 were given
2021-09-05 01:11:24 ERROR (MainThread) [homeassistant] Error doing job: Future exception was never retrieved
Traceback (most recent call last):
  File "/usr/local/lib/python3.9/concurrent/futures/thread.py", line 52, in run
    result = self.fn(*self.args, **self.kwargs)
TypeError: update() takes 1 positional argument but 2 were given
2021-09-05 01:16:25 ERROR (MainThread) [homeassistant] Error doing job: Future exception was never retrieved
Traceback (most recent call last):
  File "/usr/local/lib/python3.9/concurrent/futures/thread.py", line 52, in run
    result = self.fn(*self.args, **self.kwargs)
TypeError: update() takes 1 positional argument but 2 were given
2021-09-05 01:17:24 WARNING (MainThread) [homeassistant.helpers.entity] Update of sensor.seventeentrack_package_420913219274890249338700531464 is taking over 10 seconds
2021-09-05 01:21:26 ERROR (MainThread) [homeassistant] Error doing job: Future exception was never retrieved
Traceback (most recent call last):
  File "/usr/local/lib/python3.9/concurrent/futures/thread.py", line 52, in run
    result = self.fn(*self.args, **self.kwargs)
TypeError: update() takes 1 positional argument but 2 were given
2021-09-05 01:26:27 ERROR (MainThread) [homeassistant] Error doing job: Future exception was never retrieved
Traceback (most recent call last):
  File "/usr/local/lib/python3.9/concurrent/futures/thread.py", line 52, in run
    result = self.fn(*self.args, **self.kwargs)
TypeError: update() takes 1 positional argument but 2 were given
2021-09-05 01:31:28 ERROR (MainThread) [homeassistant] Error doing job: Future exception was never retrieved
Traceback (most recent call last):
  File "/usr/local/lib/python3.9/concurrent/futures/thread.py", line 52, in run
    result = self.fn(*self.args, **self.kwargs)
TypeError: update() takes 1 positional argument but 2 were given
2021-09-05 01:36:29 ERROR (MainThread) [homeassistant] Error doing job: Future exception was never retrieved
Traceback (most recent call last):
  File "/usr/local/lib/python3.9/concurrent/futures/thread.py", line 52, in run
    result = self.fn(*self.args, **self.kwargs)
TypeError: update() takes 1 positional argument but 2 were given
2021-09-05 01:41:30 ERROR (MainThread) [homeassistant] Error doing job: Future exception was never retrieved
Traceback (most recent call last):
  File "/usr/local/lib/python3.9/concurrent/futures/thread.py", line 52, in run
    result = self.fn(*self.args, **self.kwargs)
TypeError: update() takes 1 positional argument but 2 were given
2021-09-05 01:46:31 ERROR (MainThread) [homeassistant] Error doing job: Future exception was never retrieved
Traceback (most recent call last):
  File "/usr/local/lib/python3.9/concurrent/futures/thread.py", line 52, in run
    result = self.fn(*self.args, **self.kwargs)
TypeError: update() takes 1 positional argument but 2 were given
2021-09-05 01:51:32 ERROR (MainThread) [homeassistant] Error doing job: Future exception was never retrieved
Traceback (most recent call last):
  File "/usr/local/lib/python3.9/concurrent/futures/thread.py", line 52, in run
    result = self.fn(*self.args, **self.kwargs)
TypeError: update() takes 1 positional argument but 2 were given
2021-09-05 01:56:33 ERROR (MainThread) [homeassistant] Error doing job: Future exception was never retrieved
Traceback (most recent call last):
  File "/usr/local/lib/python3.9/concurrent/futures/thread.py", line 52, in run
    result = self.fn(*self.args, **self.kwargs)
TypeError: update() takes 1 positional argument but 2 were given
2021-09-05 02:01:34 ERROR (MainThread) [homeassistant] Error doing job: Future exception was never retrieved
Traceback (most recent call last):
  File "/usr/local/lib/python3.9/concurrent/futures/thread.py", line 52, in run
    result = self.fn(*self.args, **self.kwargs)
TypeError: update() takes 1 positional argument but 2 were given
2021-09-05 02:06:35 ERROR (MainThread) [homeassistant] Error doing job: Future exception was never retrieved
Traceback (most recent call last):
  File "/usr/local/lib/python3.9/concurrent/futures/thread.py", line 52, in run
    result = self.fn(*self.args, **self.kwargs)
TypeError: update() takes 1 positional argument but 2 were given
2021-09-05 02:11:36 ERROR (MainThread) [homeassistant] Error doing job: Future exception was never retrieved
Traceback (most recent call last):
  File "/usr/local/lib/python3.9/concurrent/futures/thread.py", line 52, in run
    result = self.fn(*self.args, **self.kwargs)
TypeError: update() takes 1 positional argument but 2 were given
2021-09-05 02:16:37 ERROR (MainThread) [homeassistant] Error doing job: Future exception was never retrieved
Traceback (most recent call last):
  File "/usr/local/lib/python3.9/concurrent/futures/thread.py", line 52, in run
    result = self.fn(*self.args, **self.kwargs)
TypeError: update() takes 1 positional argument but 2 were given
2021-09-05 02:21:38 ERROR (MainThread) [homeassistant] Error doing job: Future exception was never retrieved
Traceback (most recent call last):
  File "/usr/local/lib/python3.9/concurrent/futures/thread.py", line 52, in run
    result = self.fn(*self.args, **self.kwargs)
TypeError: update() takes 1 positional argument but 2 were given
2021-09-05 02:26:39 ERROR (MainThread) [homeassistant] Error doing job: Future exception was never retrieved
Traceback (most recent call last):
  File "/usr/local/lib/python3.9/concurrent/futures/thread.py", line 52, in run
    result = self.fn(*self.args, **self.kwargs)
TypeError: update() takes 1 positional argument but 2 were given
2021-09-05 02:31:40 ERROR (MainThread) [homeassistant] Error doing job: Future exception was never retrieved
Traceback (most recent call last):
  File "/usr/local/lib/python3.9/concurrent/futures/thread.py", line 52, in run
    result = self.fn(*self.args, **self.kwargs)
TypeError: update() takes 1 positional argument but 2 were given
2021-09-05 02:36:41 ERROR (MainThread) [homeassistant] Error doing job: Future exception was never retrieved
Traceback (most recent call last):
  File "/usr/local/lib/python3.9/concurrent/futures/thread.py", line 52, in run
    result = self.fn(*self.args, **self.kwargs)
TypeError: update() takes 1 positional argument but 2 were given
2021-09-05 02:38:59 WARNING (Thread-8) [pychromecast.socket_client] [Bedroom_Master speaker(192.168.20.77):8009] Heartbeat timeout, resetting connection
2021-09-05 02:41:42 ERROR (MainThread) [homeassistant] Error doing job: Future exception was never retrieved
Traceback (most recent call last):
  File "/usr/local/lib/python3.9/concurrent/futures/thread.py", line 52, in run
    result = self.fn(*self.args, **self.kwargs)
TypeError: update() takes 1 positional argument but 2 were given
2021-09-05 02:46:43 ERROR (MainThread) [homeassistant] Error doing job: Future exception was never retrieved
Traceback (most recent call last):
  File "/usr/local/lib/python3.9/concurrent/futures/thread.py", line 52, in run
    result = self.fn(*self.args, **self.kwargs)
TypeError: update() takes 1 positional argument but 2 were given
2021-09-05 02:47:28 WARNING (Thread-15) [pychromecast.socket_client] [Bedroom_Sophia speaker(192.168.20.60):8009] Heartbeat timeout, resetting connection
2021-09-05 02:47:44 ERROR (Thread-15) [pychromecast.socket_client] [Bedroom_Sophia speaker(192.168.20.60):8009] Failed to connect to service ServiceInfo(type='host', data=('192.168.20.60', 8009)), retrying in 5.0s
2021-09-05 02:51:44 ERROR (MainThread) [homeassistant] Error doing job: Future exception was never retrieved
Traceback (most recent call last):
  File "/usr/local/lib/python3.9/concurrent/futures/thread.py", line 52, in run
    result = self.fn(*self.args, **self.kwargs)
TypeError: update() takes 1 positional argument but 2 were given
2021-09-05 02:56:45 ERROR (MainThread) [homeassistant] Error doing job: Future exception was never retrieved
Traceback (most recent call last):
  File "/usr/local/lib/python3.9/concurrent/futures/thread.py", line 52, in run
    result = self.fn(*self.args, **self.kwargs)
TypeError: update() takes 1 positional argument but 2 were given
