2021-09-23 22:35:26 WARNING (SyncWorker_0) [homeassistant.loader] We found a custom integration sun2 which has not been tested by Home Assistant. This component might cause stability problems, be sure to disable it if you experience issues with Home Assistant
2021-09-23 22:35:36 WARNING (MainThread) [homeassistant.components.sensor] Entity sensor.cpu_temp (<class 'homeassistant.components.command_line.sensor.CommandSensor'>) with device_class None reports a temperature in °C which will be converted to °F. Temperature conversion for entities without correct device_class is deprecated and will be removed from Home Assistant Core 2022.3. Please update your configuration if device_class is manually configured, otherwise create a bug report at https://github.com/home-assistant/core/issues?q=is%3Aopen+is%3Aissue+label%3A%22integration%3A+command_line%22
2021-09-23 22:35:39 WARNING (MainThread) [homeassistant.config_entries] Config entry 'Roku Smart Soundbar' for roku integration not ready yet: Invalid response from API: Error occurred while communicating with device; Retrying in background
2021-09-23 22:35:41 WARNING (MainThread) [homeassistant.components.sensor] Entity sensor.attictemp1_bme280_dewpoint (<class 'homeassistant.components.tasmota.sensor.TasmotaSensor'>) with device_class None reports a temperature in °C which will be converted to °F. Temperature conversion for entities without correct device_class is deprecated and will be removed from Home Assistant Core 2022.3. Please update your configuration if device_class is manually configured, otherwise create a bug report at https://github.com/home-assistant/core/issues?q=is%3Aopen+is%3Aissue+label%3A%22integration%3A+tasmota%22
2021-09-23 22:35:41 WARNING (MainThread) [homeassistant.components.sensor] Entity sensor.garagesidedoorsensor_bme280_dewpoint (<class 'homeassistant.components.tasmota.sensor.TasmotaSensor'>) with device_class None reports a temperature in °C which will be converted to °F. Temperature conversion for entities without correct device_class is deprecated and will be removed from Home Assistant Core 2022.3. Please update your configuration if device_class is manually configured, otherwise create a bug report at https://github.com/home-assistant/core/issues?q=is%3Aopen+is%3Aissue+label%3A%22integration%3A+tasmota%22
2021-09-23 22:35:45 WARNING (MainThread) [homeassistant.config_entries] Config entry '192.168.7.195' for wled integration not ready yet: Invalid response from API: Error occurred while communicating with WLED device at 192.168.7.195; Retrying in background
2021-09-23 22:35:46 ERROR (MainThread) [homeassistant.components.automation.liam_lamp_power_on_from_tradfri] Unknown error while setting up trigger (empty result) Liam - Lamp: "Turn on" button pressed Tradfri
2021-09-23 22:35:46 ERROR (MainThread) [homeassistant.components.automation.liam_lamp_dim_up_button_pressed_tradfri] Unknown error while setting up trigger (empty result) Liam - Lamp: "Dim Up" button pressed Tradfri
2021-09-23 22:35:46 ERROR (MainThread) [homeassistant.components.automation.liam_lamp_dim_down_button_pressed_tradfri] Unknown error while setting up trigger (empty result) Liam - Lamp: "Dim Down" button pressed Tradfri
2021-09-23 22:35:46 ERROR (MainThread) [homeassistant.components.automation.liam_lamp_left_button_pressed_tradfri] Unknown error while setting up trigger (empty result) Liam - Lamp: "Left" button pressed Tradfri
2021-09-23 22:35:46 ERROR (MainThread) [homeassistant.components.automation.liam_lamp_right_button_pressed_tradfri] Unknown error while setting up trigger (empty result) Liam - Lamp: "Right" button pressed Tradfri
2021-09-23 22:36:00 ERROR (Thread-13) [homeassistant.components.cast.media_player] Failed to cast media https://3hn0pigkolfj5459ps2gnq0jwb6qgqmq.ui.nabu.casa/media/local/1-second-of-silence.mp3?authSig=eyJ0eXAiOiJKV1QiLCJhbGciOiJIUzI1NiJ9.eyJpc3MiOiIzZWI2Mjg3Y2YzMjI0ZDgzYTBjY2FjZjRjYzgzYTJlNyIsInBhdGgiOiIvbWVkaWEvbG9jYWwvMS1zZWNvbmQtb2Ytc2lsZW5jZS5tcDMiLCJpYXQiOjE2MzI0NjE3NjAsImV4cCI6MTYzMjU0ODE2MH0.cIFFTOjqoz5dmn8Na-Clu4e1jrZUk8pfBKW0B1ISs10 from external_url (https://3hn0pigkolfj5459ps2gnq0jwb6qgqmq.ui.nabu.casa). Please make sure the URL is: Reachable from the cast device and either a publicly resolvable hostname or an IP address
2021-09-23 22:36:23 ERROR (MainThread) [zigpy.application] Couldn't start application
2021-09-23 22:36:23 ERROR (MainThread) [homeassistant.config_entries] Error setting up entry socket://192.168.7.217:6638 for zha
Traceback (most recent call last):
  File "/usr/src/homeassistant/homeassistant/config_entries.py", line 304, in async_setup
    result = await component.async_setup_entry(hass, self)  # type: ignore
  File "/usr/src/homeassistant/homeassistant/components/zha/__init__.py", line 102, in async_setup_entry
    await zha_gateway.async_initialize()
  File "/usr/src/homeassistant/homeassistant/components/zha/core/gateway.py", line 152, in async_initialize
    self.application_controller = await app_controller_cls.new(
  File "/usr/local/lib/python3.9/site-packages/zigpy/application.py", line 69, in new
    await app.startup(auto_form)
  File "/usr/local/lib/python3.9/site-packages/zigpy_znp/zigbee/application.py", line 196, in startup
    return await self._startup(
  File "/usr/local/lib/python3.9/site-packages/zigpy_znp/zigbee/application.py", line 313, in _startup
    await self._load_network_info()
  File "/usr/local/lib/python3.9/site-packages/zigpy_znp/zigbee/application.py", line 1283, in _load_network_info
    await self._znp.load_network_info()
  File "/usr/local/lib/python3.9/site-packages/zigpy_znp/api.py", line 52, in load_network_info
    self.network_info = await load_network_info(self)
  File "/usr/local/lib/python3.9/site-packages/zigpy_znp/znp/utils.py", line 49, in load_network_info
    raise ValueError("Device is not a part of a network")
ValueError: Device is not a part of a network
2021-09-23 22:38:00 ERROR (Thread-13) [homeassistant.components.cast.media_player] Failed to cast media https://3hn0pigkolfj5459ps2gnq0jwb6qgqmq.ui.nabu.casa/media/local/1-second-of-silence.mp3?authSig=eyJ0eXAiOiJKV1QiLCJhbGciOiJIUzI1NiJ9.eyJpc3MiOiIzZWI2Mjg3Y2YzMjI0ZDgzYTBjY2FjZjRjYzgzYTJlNyIsInBhdGgiOiIvbWVkaWEvbG9jYWwvMS1zZWNvbmQtb2Ytc2lsZW5jZS5tcDMiLCJpYXQiOjE2MzI0NjE4ODAsImV4cCI6MTYzMjU0ODI4MH0.drdQgGYIpwPhmVPGuHwbkNR3r9DmyF0L-wWCW_d-OuU from external_url (https://3hn0pigkolfj5459ps2gnq0jwb6qgqmq.ui.nabu.casa). Please make sure the URL is: Reachable from the cast device and either a publicly resolvable hostname or an IP address
2021-09-23 22:38:00 ERROR (Thread-13) [homeassistant.components.cast.media_player] Failed to cast media https://3hn0pigkolfj5459ps2gnq0jwb6qgqmq.ui.nabu.casa/media/local/1-second-of-silence.mp3?authSig=eyJ0eXAiOiJKV1QiLCJhbGciOiJIUzI1NiJ9.eyJpc3MiOiIzZWI2Mjg3Y2YzMjI0ZDgzYTBjY2FjZjRjYzgzYTJlNyIsInBhdGgiOiIvbWVkaWEvbG9jYWwvMS1zZWNvbmQtb2Ytc2lsZW5jZS5tcDMiLCJpYXQiOjE2MzI0NjE4ODAsImV4cCI6MTYzMjU0ODI4MH0.drdQgGYIpwPhmVPGuHwbkNR3r9DmyF0L-wWCW_d-OuU from external_url (https://3hn0pigkolfj5459ps2gnq0jwb6qgqmq.ui.nabu.casa). Please make sure the URL is: Reachable from the cast device and either a publicly resolvable hostname or an IP address
2021-09-23 22:38:00 ERROR (Thread-13) [homeassistant.components.cast.media_player] Failed to cast media https://3hn0pigkolfj5459ps2gnq0jwb6qgqmq.ui.nabu.casa/media/local/1-second-of-silence.mp3?authSig=eyJ0eXAiOiJKV1QiLCJhbGciOiJIUzI1NiJ9.eyJpc3MiOiIzZWI2Mjg3Y2YzMjI0ZDgzYTBjY2FjZjRjYzgzYTJlNyIsInBhdGgiOiIvbWVkaWEvbG9jYWwvMS1zZWNvbmQtb2Ytc2lsZW5jZS5tcDMiLCJpYXQiOjE2MzI0NjE4ODAsImV4cCI6MTYzMjU0ODI4MH0.drdQgGYIpwPhmVPGuHwbkNR3r9DmyF0L-wWCW_d-OuU from external_url (https://3hn0pigkolfj5459ps2gnq0jwb6qgqmq.ui.nabu.casa). Please make sure the URL is: Reachable from the cast device and either a publicly resolvable hostname or an IP address
2021-09-23 22:38:00 ERROR (Thread-13) [homeassistant.components.cast.media_player] Failed to cast media https://3hn0pigkolfj5459ps2gnq0jwb6qgqmq.ui.nabu.casa/media/local/1-second-of-silence.mp3?authSig=eyJ0eXAiOiJKV1QiLCJhbGciOiJIUzI1NiJ9.eyJpc3MiOiIzZWI2Mjg3Y2YzMjI0ZDgzYTBjY2FjZjRjYzgzYTJlNyIsInBhdGgiOiIvbWVkaWEvbG9jYWwvMS1zZWNvbmQtb2Ytc2lsZW5jZS5tcDMiLCJpYXQiOjE2MzI0NjE4ODAsImV4cCI6MTYzMjU0ODI4MH0.drdQgGYIpwPhmVPGuHwbkNR3r9DmyF0L-wWCW_d-OuU from external_url (https://3hn0pigkolfj5459ps2gnq0jwb6qgqmq.ui.nabu.casa). Please make sure the URL is: Reachable from the cast device and either a publicly resolvable hostname or an IP address
2021-09-23 22:40:00 ERROR (Thread-13) [homeassistant.components.cast.media_player] Failed to cast media https://3hn0pigkolfj5459ps2gnq0jwb6qgqmq.ui.nabu.casa/media/local/1-second-of-silence.mp3?authSig=eyJ0eXAiOiJKV1QiLCJhbGciOiJIUzI1NiJ9.eyJpc3MiOiIzZWI2Mjg3Y2YzMjI0ZDgzYTBjY2FjZjRjYzgzYTJlNyIsInBhdGgiOiIvbWVkaWEvbG9jYWwvMS1zZWNvbmQtb2Ytc2lsZW5jZS5tcDMiLCJpYXQiOjE2MzI0NjIwMDAsImV4cCI6MTYzMjU0ODQwMH0.4pGKj_2OxTsunTKCyr9YT-fo586X4VTthNr-FyphHic from external_url (https://3hn0pigkolfj5459ps2gnq0jwb6qgqmq.ui.nabu.casa). Please make sure the URL is: Reachable from the cast device and either a publicly resolvable hostname or an IP address
2021-09-23 22:40:00 ERROR (Thread-13) [homeassistant.components.cast.media_player] Failed to cast media https://3hn0pigkolfj5459ps2gnq0jwb6qgqmq.ui.nabu.casa/media/local/1-second-of-silence.mp3?authSig=eyJ0eXAiOiJKV1QiLCJhbGciOiJIUzI1NiJ9.eyJpc3MiOiIzZWI2Mjg3Y2YzMjI0ZDgzYTBjY2FjZjRjYzgzYTJlNyIsInBhdGgiOiIvbWVkaWEvbG9jYWwvMS1zZWNvbmQtb2Ytc2lsZW5jZS5tcDMiLCJpYXQiOjE2MzI0NjIwMDAsImV4cCI6MTYzMjU0ODQwMH0.4pGKj_2OxTsunTKCyr9YT-fo586X4VTthNr-FyphHic from external_url (https://3hn0pigkolfj5459ps2gnq0jwb6qgqmq.ui.nabu.casa). Please make sure the URL is: Reachable from the cast device and either a publicly resolvable hostname or an IP address
2021-09-23 22:40:00 ERROR (Thread-13) [homeassistant.components.cast.media_player] Failed to cast media https://3hn0pigkolfj5459ps2gnq0jwb6qgqmq.ui.nabu.casa/media/local/1-second-of-silence.mp3?authSig=eyJ0eXAiOiJKV1QiLCJhbGciOiJIUzI1NiJ9.eyJpc3MiOiIzZWI2Mjg3Y2YzMjI0ZDgzYTBjY2FjZjRjYzgzYTJlNyIsInBhdGgiOiIvbWVkaWEvbG9jYWwvMS1zZWNvbmQtb2Ytc2lsZW5jZS5tcDMiLCJpYXQiOjE2MzI0NjIwMDAsImV4cCI6MTYzMjU0ODQwMH0.4pGKj_2OxTsunTKCyr9YT-fo586X4VTthNr-FyphHic from external_url (https://3hn0pigkolfj5459ps2gnq0jwb6qgqmq.ui.nabu.casa). Please make sure the URL is: Reachable from the cast device and either a publicly resolvable hostname or an IP address
2021-09-23 22:40:00 ERROR (Thread-13) [homeassistant.components.cast.media_player] Failed to cast media https://3hn0pigkolfj5459ps2gnq0jwb6qgqmq.ui.nabu.casa/media/local/1-second-of-silence.mp3?authSig=eyJ0eXAiOiJKV1QiLCJhbGciOiJIUzI1NiJ9.eyJpc3MiOiIzZWI2Mjg3Y2YzMjI0ZDgzYTBjY2FjZjRjYzgzYTJlNyIsInBhdGgiOiIvbWVkaWEvbG9jYWwvMS1zZWNvbmQtb2Ytc2lsZW5jZS5tcDMiLCJpYXQiOjE2MzI0NjIwMDAsImV4cCI6MTYzMjU0ODQwMH0.4pGKj_2OxTsunTKCyr9YT-fo586X4VTthNr-FyphHic from external_url (https://3hn0pigkolfj5459ps2gnq0jwb6qgqmq.ui.nabu.casa). Please make sure the URL is: Reachable from the cast device and either a publicly resolvable hostname or an IP address
2021-09-23 22:40:35 ERROR (MainThread) [homeassistant] Error doing job: Future exception was never retrieved
Traceback (most recent call last):
  File "/usr/local/lib/python3.9/concurrent/futures/thread.py", line 52, in run
    result = self.fn(*self.args, **self.kwargs)
TypeError: update() takes 1 positional argument but 2 were given
2021-09-23 22:41:17 ERROR (MainThread) [homeassistant.components.websocket_api.http.connection] [23371906921184] Received invalid command: zha/configuration
2021-09-23 22:41:21 ERROR (MainThread) [homeassistant.components.websocket_api.http.connection] [23371906921184] Received invalid command: zha/devices/permit
2021-09-23 22:42:00 ERROR (Thread-13) [homeassistant.components.cast.media_player] Failed to cast media https://3hn0pigkolfj5459ps2gnq0jwb6qgqmq.ui.nabu.casa/media/local/1-second-of-silence.mp3?authSig=eyJ0eXAiOiJKV1QiLCJhbGciOiJIUzI1NiJ9.eyJpc3MiOiIzZWI2Mjg3Y2YzMjI0ZDgzYTBjY2FjZjRjYzgzYTJlNyIsInBhdGgiOiIvbWVkaWEvbG9jYWwvMS1zZWNvbmQtb2Ytc2lsZW5jZS5tcDMiLCJpYXQiOjE2MzI0NjIxMjAsImV4cCI6MTYzMjU0ODUyMH0.QciMnGha7WBRv6f1FIbfiaj46msv22MdTVcZaKdXmq8 from external_url (https://3hn0pigkolfj5459ps2gnq0jwb6qgqmq.ui.nabu.casa). Please make sure the URL is: Reachable from the cast device and either a publicly resolvable hostname or an IP address
2021-09-23 22:42:00 ERROR (Thread-13) [homeassistant.components.cast.media_player] Failed to cast media https://3hn0pigkolfj5459ps2gnq0jwb6qgqmq.ui.nabu.casa/media/local/1-second-of-silence.mp3?authSig=eyJ0eXAiOiJKV1QiLCJhbGciOiJIUzI1NiJ9.eyJpc3MiOiIzZWI2Mjg3Y2YzMjI0ZDgzYTBjY2FjZjRjYzgzYTJlNyIsInBhdGgiOiIvbWVkaWEvbG9jYWwvMS1zZWNvbmQtb2Ytc2lsZW5jZS5tcDMiLCJpYXQiOjE2MzI0NjIxMjAsImV4cCI6MTYzMjU0ODUyMH0.QciMnGha7WBRv6f1FIbfiaj46msv22MdTVcZaKdXmq8 from external_url (https://3hn0pigkolfj5459ps2gnq0jwb6qgqmq.ui.nabu.casa). Please make sure the URL is: Reachable from the cast device and either a publicly resolvable hostname or an IP address
2021-09-23 22:42:00 ERROR (Thread-13) [homeassistant.components.cast.media_player] Failed to cast media https://3hn0pigkolfj5459ps2gnq0jwb6qgqmq.ui.nabu.casa/media/local/1-second-of-silence.mp3?authSig=eyJ0eXAiOiJKV1QiLCJhbGciOiJIUzI1NiJ9.eyJpc3MiOiIzZWI2Mjg3Y2YzMjI0ZDgzYTBjY2FjZjRjYzgzYTJlNyIsInBhdGgiOiIvbWVkaWEvbG9jYWwvMS1zZWNvbmQtb2Ytc2lsZW5jZS5tcDMiLCJpYXQiOjE2MzI0NjIxMjAsImV4cCI6MTYzMjU0ODUyMH0.QciMnGha7WBRv6f1FIbfiaj46msv22MdTVcZaKdXmq8 from external_url (https://3hn0pigkolfj5459ps2gnq0jwb6qgqmq.ui.nabu.casa). Please make sure the URL is: Reachable from the cast device and either a publicly resolvable hostname or an IP address
2021-09-23 22:42:00 ERROR (Thread-13) [homeassistant.components.cast.media_player] Failed to cast media https://3hn0pigkolfj5459ps2gnq0jwb6qgqmq.ui.nabu.casa/media/local/1-second-of-silence.mp3?authSig=eyJ0eXAiOiJKV1QiLCJhbGciOiJIUzI1NiJ9.eyJpc3MiOiIzZWI2Mjg3Y2YzMjI0ZDgzYTBjY2FjZjRjYzgzYTJlNyIsInBhdGgiOiIvbWVkaWEvbG9jYWwvMS1zZWNvbmQtb2Ytc2lsZW5jZS5tcDMiLCJpYXQiOjE2MzI0NjIxMjAsImV4cCI6MTYzMjU0ODUyMH0.QciMnGha7WBRv6f1FIbfiaj46msv22MdTVcZaKdXmq8 from external_url (https://3hn0pigkolfj5459ps2gnq0jwb6qgqmq.ui.nabu.casa). Please make sure the URL is: Reachable from the cast device and either a publicly resolvable hostname or an IP address
2021-09-23 22:42:33 ERROR (MainThread) [homeassistant.components.websocket_api.http.connection] [23371906921184] Received invalid command: zha/configuration
2021-09-23 22:42:37 ERROR (MainThread) [homeassistant.components.websocket_api.http.connection] [23371906921184] Received invalid command: zha/devices
2021-09-23 22:42:38 ERROR (MainThread) [homeassistant.components.websocket_api.http.connection] [23371906921184] Received invalid command: zha/groups
2021-09-23 22:42:39 ERROR (MainThread) [homeassistant.components.websocket_api.http.connection] [23371906921184] Received invalid command: zha/devices
2021-09-23 22:42:40 ERROR (MainThread) [homeassistant.components.websocket_api.http.connection] [23371906921184] Received invalid command: zha/configuration
2021-09-23 22:44:00 ERROR (Thread-13) [homeassistant.components.cast.media_player] Failed to cast media https://3hn0pigkolfj5459ps2gnq0jwb6qgqmq.ui.nabu.casa/media/local/1-second-of-silence.mp3?authSig=eyJ0eXAiOiJKV1QiLCJhbGciOiJIUzI1NiJ9.eyJpc3MiOiIzZWI2Mjg3Y2YzMjI0ZDgzYTBjY2FjZjRjYzgzYTJlNyIsInBhdGgiOiIvbWVkaWEvbG9jYWwvMS1zZWNvbmQtb2Ytc2lsZW5jZS5tcDMiLCJpYXQiOjE2MzI0NjIyNDAsImV4cCI6MTYzMjU0ODY0MH0.NR5H_ueJFGb2QaJih74U6PwJxFsDvMVCsk51b2hij0Q from external_url (https://3hn0pigkolfj5459ps2gnq0jwb6qgqmq.ui.nabu.casa). Please make sure the URL is: Reachable from the cast device and either a publicly resolvable hostname or an IP address
2021-09-23 22:44:00 ERROR (Thread-13) [homeassistant.components.cast.media_player] Failed to cast media https://3hn0pigkolfj5459ps2gnq0jwb6qgqmq.ui.nabu.casa/media/local/1-second-of-silence.mp3?authSig=eyJ0eXAiOiJKV1QiLCJhbGciOiJIUzI1NiJ9.eyJpc3MiOiIzZWI2Mjg3Y2YzMjI0ZDgzYTBjY2FjZjRjYzgzYTJlNyIsInBhdGgiOiIvbWVkaWEvbG9jYWwvMS1zZWNvbmQtb2Ytc2lsZW5jZS5tcDMiLCJpYXQiOjE2MzI0NjIyNDAsImV4cCI6MTYzMjU0ODY0MH0.NR5H_ueJFGb2QaJih74U6PwJxFsDvMVCsk51b2hij0Q from external_url (https://3hn0pigkolfj5459ps2gnq0jwb6qgqmq.ui.nabu.casa). Please make sure the URL is: Reachable from the cast device and either a publicly resolvable hostname or an IP address
2021-09-23 22:44:00 ERROR (Thread-13) [homeassistant.components.cast.media_player] Failed to cast media https://3hn0pigkolfj5459ps2gnq0jwb6qgqmq.ui.nabu.casa/media/local/1-second-of-silence.mp3?authSig=eyJ0eXAiOiJKV1QiLCJhbGciOiJIUzI1NiJ9.eyJpc3MiOiIzZWI2Mjg3Y2YzMjI0ZDgzYTBjY2FjZjRjYzgzYTJlNyIsInBhdGgiOiIvbWVkaWEvbG9jYWwvMS1zZWNvbmQtb2Ytc2lsZW5jZS5tcDMiLCJpYXQiOjE2MzI0NjIyNDAsImV4cCI6MTYzMjU0ODY0MH0.NR5H_ueJFGb2QaJih74U6PwJxFsDvMVCsk51b2hij0Q from external_url (https://3hn0pigkolfj5459ps2gnq0jwb6qgqmq.ui.nabu.casa). Please make sure the URL is: Reachable from the cast device and either a publicly resolvable hostname or an IP address
2021-09-23 22:44:00 ERROR (Thread-13) [homeassistant.components.cast.media_player] Failed to cast media https://3hn0pigkolfj5459ps2gnq0jwb6qgqmq.ui.nabu.casa/media/local/1-second-of-silence.mp3?authSig=eyJ0eXAiOiJKV1QiLCJhbGciOiJIUzI1NiJ9.eyJpc3MiOiIzZWI2Mjg3Y2YzMjI0ZDgzYTBjY2FjZjRjYzgzYTJlNyIsInBhdGgiOiIvbWVkaWEvbG9jYWwvMS1zZWNvbmQtb2Ytc2lsZW5jZS5tcDMiLCJpYXQiOjE2MzI0NjIyNDAsImV4cCI6MTYzMjU0ODY0MH0.NR5H_ueJFGb2QaJih74U6PwJxFsDvMVCsk51b2hij0Q from external_url (https://3hn0pigkolfj5459ps2gnq0jwb6qgqmq.ui.nabu.casa). Please make sure the URL is: Reachable from the cast device and either a publicly resolvable hostname or an IP address
2021-09-23 22:45:36 ERROR (MainThread) [homeassistant] Error doing job: Future exception was never retrieved
Traceback (most recent call last):
  File "/usr/local/lib/python3.9/concurrent/futures/thread.py", line 52, in run
    result = self.fn(*self.args, **self.kwargs)
TypeError: update() takes 1 positional argument but 2 were given
2021-09-23 22:45:57 ERROR (MainThread) [zigpy.application] Couldn't start application
2021-09-23 22:45:57 ERROR (MainThread) [homeassistant.config_entries] Error setting up entry socket://192.168.7.217:6638 for zha
Traceback (most recent call last):
  File "/usr/src/homeassistant/homeassistant/config_entries.py", line 304, in async_setup
    result = await component.async_setup_entry(hass, self)  # type: ignore
  File "/usr/src/homeassistant/homeassistant/components/zha/__init__.py", line 102, in async_setup_entry
    await zha_gateway.async_initialize()
  File "/usr/src/homeassistant/homeassistant/components/zha/core/gateway.py", line 152, in async_initialize
    self.application_controller = await app_controller_cls.new(
  File "/usr/local/lib/python3.9/site-packages/zigpy/application.py", line 69, in new
    await app.startup(auto_form)
  File "/usr/local/lib/python3.9/site-packages/zigpy_znp/zigbee/application.py", line 196, in startup
    return await self._startup(
  File "/usr/local/lib/python3.9/site-packages/zigpy_znp/zigbee/application.py", line 313, in _startup
    await self._load_network_info()
  File "/usr/local/lib/python3.9/site-packages/zigpy_znp/zigbee/application.py", line 1283, in _load_network_info
    await self._znp.load_network_info()
  File "/usr/local/lib/python3.9/site-packages/zigpy_znp/api.py", line 52, in load_network_info
    self.network_info = await load_network_info(self)
  File "/usr/local/lib/python3.9/site-packages/zigpy_znp/znp/utils.py", line 49, in load_network_info
    raise ValueError("Device is not a part of a network")
ValueError: Device is not a part of a network
2021-09-23 22:46:00 ERROR (Thread-13) [homeassistant.components.cast.media_player] Failed to cast media https://3hn0pigkolfj5459ps2gnq0jwb6qgqmq.ui.nabu.casa/media/local/1-second-of-silence.mp3?authSig=eyJ0eXAiOiJKV1QiLCJhbGciOiJIUzI1NiJ9.eyJpc3MiOiIzZWI2Mjg3Y2YzMjI0ZDgzYTBjY2FjZjRjYzgzYTJlNyIsInBhdGgiOiIvbWVkaWEvbG9jYWwvMS1zZWNvbmQtb2Ytc2lsZW5jZS5tcDMiLCJpYXQiOjE2MzI0NjIzNjAsImV4cCI6MTYzMjU0ODc2MH0.YVKfqFQZBoggQh1Z873LdfKvyDmzOJSy6wOSWHGR85s from external_url (https://3hn0pigkolfj5459ps2gnq0jwb6qgqmq.ui.nabu.casa). Please make sure the URL is: Reachable from the cast device and either a publicly resolvable hostname or an IP address
2021-09-23 22:46:00 ERROR (Thread-13) [homeassistant.components.cast.media_player] Failed to cast media https://3hn0pigkolfj5459ps2gnq0jwb6qgqmq.ui.nabu.casa/media/local/1-second-of-silence.mp3?authSig=eyJ0eXAiOiJKV1QiLCJhbGciOiJIUzI1NiJ9.eyJpc3MiOiIzZWI2Mjg3Y2YzMjI0ZDgzYTBjY2FjZjRjYzgzYTJlNyIsInBhdGgiOiIvbWVkaWEvbG9jYWwvMS1zZWNvbmQtb2Ytc2lsZW5jZS5tcDMiLCJpYXQiOjE2MzI0NjIzNjAsImV4cCI6MTYzMjU0ODc2MH0.YVKfqFQZBoggQh1Z873LdfKvyDmzOJSy6wOSWHGR85s from external_url (https://3hn0pigkolfj5459ps2gnq0jwb6qgqmq.ui.nabu.casa). Please make sure the URL is: Reachable from the cast device and either a publicly resolvable hostname or an IP address
2021-09-23 22:46:00 ERROR (Thread-13) [homeassistant.components.cast.media_player] Failed to cast media https://3hn0pigkolfj5459ps2gnq0jwb6qgqmq.ui.nabu.casa/media/local/1-second-of-silence.mp3?authSig=eyJ0eXAiOiJKV1QiLCJhbGciOiJIUzI1NiJ9.eyJpc3MiOiIzZWI2Mjg3Y2YzMjI0ZDgzYTBjY2FjZjRjYzgzYTJlNyIsInBhdGgiOiIvbWVkaWEvbG9jYWwvMS1zZWNvbmQtb2Ytc2lsZW5jZS5tcDMiLCJpYXQiOjE2MzI0NjIzNjAsImV4cCI6MTYzMjU0ODc2MH0.YVKfqFQZBoggQh1Z873LdfKvyDmzOJSy6wOSWHGR85s from external_url (https://3hn0pigkolfj5459ps2gnq0jwb6qgqmq.ui.nabu.casa). Please make sure the URL is: Reachable from the cast device and either a publicly resolvable hostname or an IP address
2021-09-23 22:46:00 ERROR (Thread-13) [homeassistant.components.cast.media_player] Failed to cast media https://3hn0pigkolfj5459ps2gnq0jwb6qgqmq.ui.nabu.casa/media/local/1-second-of-silence.mp3?authSig=eyJ0eXAiOiJKV1QiLCJhbGciOiJIUzI1NiJ9.eyJpc3MiOiIzZWI2Mjg3Y2YzMjI0ZDgzYTBjY2FjZjRjYzgzYTJlNyIsInBhdGgiOiIvbWVkaWEvbG9jYWwvMS1zZWNvbmQtb2Ytc2lsZW5jZS5tcDMiLCJpYXQiOjE2MzI0NjIzNjAsImV4cCI6MTYzMjU0ODc2MH0.YVKfqFQZBoggQh1Z873LdfKvyDmzOJSy6wOSWHGR85s from external_url (https://3hn0pigkolfj5459ps2gnq0jwb6qgqmq.ui.nabu.casa). Please make sure the URL is: Reachable from the cast device and either a publicly resolvable hostname or an IP address
2021-09-23 22:47:46 ERROR (MainThread) [homeassistant.components.websocket_api.http.connection] [23371906921184] Received invalid command: zha/configuration
2021-09-23 22:47:50 ERROR (MainThread) [homeassistant.components.nws] Error requesting NWS observation station SAUC1 data: Cannot connect to host api.weather.gov:443 ssl:default [Connect call failed ('96.7.232.15', 443)]
2021-09-23 22:48:00 ERROR (Thread-13) [homeassistant.components.cast.media_player] Failed to cast media https://3hn0pigkolfj5459ps2gnq0jwb6qgqmq.ui.nabu.casa/media/local/1-second-of-silence.mp3?authSig=eyJ0eXAiOiJKV1QiLCJhbGciOiJIUzI1NiJ9.eyJpc3MiOiIzZWI2Mjg3Y2YzMjI0ZDgzYTBjY2FjZjRjYzgzYTJlNyIsInBhdGgiOiIvbWVkaWEvbG9jYWwvMS1zZWNvbmQtb2Ytc2lsZW5jZS5tcDMiLCJpYXQiOjE2MzI0NjI0ODAsImV4cCI6MTYzMjU0ODg4MH0.vJ9ASCXU5KUXuoAZWvrX3wWau0AU5QAx0Cj3f215pjY from external_url (https://3hn0pigkolfj5459ps2gnq0jwb6qgqmq.ui.nabu.casa). Please make sure the URL is: Reachable from the cast device and either a publicly resolvable hostname or an IP address
2021-09-23 22:48:00 ERROR (Thread-13) [homeassistant.components.cast.media_player] Failed to cast media https://3hn0pigkolfj5459ps2gnq0jwb6qgqmq.ui.nabu.casa/media/local/1-second-of-silence.mp3?authSig=eyJ0eXAiOiJKV1QiLCJhbGciOiJIUzI1NiJ9.eyJpc3MiOiIzZWI2Mjg3Y2YzMjI0ZDgzYTBjY2FjZjRjYzgzYTJlNyIsInBhdGgiOiIvbWVkaWEvbG9jYWwvMS1zZWNvbmQtb2Ytc2lsZW5jZS5tcDMiLCJpYXQiOjE2MzI0NjI0ODAsImV4cCI6MTYzMjU0ODg4MH0.vJ9ASCXU5KUXuoAZWvrX3wWau0AU5QAx0Cj3f215pjY from external_url (https://3hn0pigkolfj5459ps2gnq0jwb6qgqmq.ui.nabu.casa). Please make sure the URL is: Reachable from the cast device and either a publicly resolvable hostname or an IP address
2021-09-23 22:48:00 ERROR (Thread-13) [homeassistant.components.cast.media_player] Failed to cast media https://3hn0pigkolfj5459ps2gnq0jwb6qgqmq.ui.nabu.casa/media/local/1-second-of-silence.mp3?authSig=eyJ0eXAiOiJKV1QiLCJhbGciOiJIUzI1NiJ9.eyJpc3MiOiIzZWI2Mjg3Y2YzMjI0ZDgzYTBjY2FjZjRjYzgzYTJlNyIsInBhdGgiOiIvbWVkaWEvbG9jYWwvMS1zZWNvbmQtb2Ytc2lsZW5jZS5tcDMiLCJpYXQiOjE2MzI0NjI0ODAsImV4cCI6MTYzMjU0ODg4MH0.vJ9ASCXU5KUXuoAZWvrX3wWau0AU5QAx0Cj3f215pjY from external_url (https://3hn0pigkolfj5459ps2gnq0jwb6qgqmq.ui.nabu.casa). Please make sure the URL is: Reachable from the cast device and either a publicly resolvable hostname or an IP address
2021-09-23 22:48:00 ERROR (Thread-13) [homeassistant.components.cast.media_player] Failed to cast media https://3hn0pigkolfj5459ps2gnq0jwb6qgqmq.ui.nabu.casa/media/local/1-second-of-silence.mp3?authSig=eyJ0eXAiOiJKV1QiLCJhbGciOiJIUzI1NiJ9.eyJpc3MiOiIzZWI2Mjg3Y2YzMjI0ZDgzYTBjY2FjZjRjYzgzYTJlNyIsInBhdGgiOiIvbWVkaWEvbG9jYWwvMS1zZWNvbmQtb2Ytc2lsZW5jZS5tcDMiLCJpYXQiOjE2MzI0NjI0ODAsImV4cCI6MTYzMjU0ODg4MH0.vJ9ASCXU5KUXuoAZWvrX3wWau0AU5QAx0Cj3f215pjY from external_url (https://3hn0pigkolfj5459ps2gnq0jwb6qgqmq.ui.nabu.casa). Please make sure the URL is: Reachable from the cast device and either a publicly resolvable hostname or an IP address
2021-09-23 22:50:00 ERROR (Thread-13) [homeassistant.components.cast.media_player] Failed to cast media https://3hn0pigkolfj5459ps2gnq0jwb6qgqmq.ui.nabu.casa/media/local/1-second-of-silence.mp3?authSig=eyJ0eXAiOiJKV1QiLCJhbGciOiJIUzI1NiJ9.eyJpc3MiOiIzZWI2Mjg3Y2YzMjI0ZDgzYTBjY2FjZjRjYzgzYTJlNyIsInBhdGgiOiIvbWVkaWEvbG9jYWwvMS1zZWNvbmQtb2Ytc2lsZW5jZS5tcDMiLCJpYXQiOjE2MzI0NjI2MDAsImV4cCI6MTYzMjU0OTAwMH0.s38ANDFGJqO1ufS5m0zNtoFhRP_-cnJ58rbPxIz6G8Y from external_url (https://3hn0pigkolfj5459ps2gnq0jwb6qgqmq.ui.nabu.casa). Please make sure the URL is: Reachable from the cast device and either a publicly resolvable hostname or an IP address
2021-09-23 22:50:00 ERROR (Thread-13) [homeassistant.components.cast.media_player] Failed to cast media https://3hn0pigkolfj5459ps2gnq0jwb6qgqmq.ui.nabu.casa/media/local/1-second-of-silence.mp3?authSig=eyJ0eXAiOiJKV1QiLCJhbGciOiJIUzI1NiJ9.eyJpc3MiOiIzZWI2Mjg3Y2YzMjI0ZDgzYTBjY2FjZjRjYzgzYTJlNyIsInBhdGgiOiIvbWVkaWEvbG9jYWwvMS1zZWNvbmQtb2Ytc2lsZW5jZS5tcDMiLCJpYXQiOjE2MzI0NjI2MDAsImV4cCI6MTYzMjU0OTAwMH0.s38ANDFGJqO1ufS5m0zNtoFhRP_-cnJ58rbPxIz6G8Y from external_url (https://3hn0pigkolfj5459ps2gnq0jwb6qgqmq.ui.nabu.casa). Please make sure the URL is: Reachable from the cast device and either a publicly resolvable hostname or an IP address
2021-09-23 22:50:00 ERROR (Thread-13) [homeassistant.components.cast.media_player] Failed to cast media https://3hn0pigkolfj5459ps2gnq0jwb6qgqmq.ui.nabu.casa/media/local/1-second-of-silence.mp3?authSig=eyJ0eXAiOiJKV1QiLCJhbGciOiJIUzI1NiJ9.eyJpc3MiOiIzZWI2Mjg3Y2YzMjI0ZDgzYTBjY2FjZjRjYzgzYTJlNyIsInBhdGgiOiIvbWVkaWEvbG9jYWwvMS1zZWNvbmQtb2Ytc2lsZW5jZS5tcDMiLCJpYXQiOjE2MzI0NjI2MDAsImV4cCI6MTYzMjU0OTAwMH0.s38ANDFGJqO1ufS5m0zNtoFhRP_-cnJ58rbPxIz6G8Y from external_url (https://3hn0pigkolfj5459ps2gnq0jwb6qgqmq.ui.nabu.casa). Please make sure the URL is: Reachable from the cast device and either a publicly resolvable hostname or an IP address
2021-09-23 22:50:00 ERROR (Thread-13) [homeassistant.components.cast.media_player] Failed to cast media https://3hn0pigkolfj5459ps2gnq0jwb6qgqmq.ui.nabu.casa/media/local/1-second-of-silence.mp3?authSig=eyJ0eXAiOiJKV1QiLCJhbGciOiJIUzI1NiJ9.eyJpc3MiOiIzZWI2Mjg3Y2YzMjI0ZDgzYTBjY2FjZjRjYzgzYTJlNyIsInBhdGgiOiIvbWVkaWEvbG9jYWwvMS1zZWNvbmQtb2Ytc2lsZW5jZS5tcDMiLCJpYXQiOjE2MzI0NjI2MDAsImV4cCI6MTYzMjU0OTAwMH0.s38ANDFGJqO1ufS5m0zNtoFhRP_-cnJ58rbPxIz6G8Y from external_url (https://3hn0pigkolfj5459ps2gnq0jwb6qgqmq.ui.nabu.casa). Please make sure the URL is: Reachable from the cast device and either a publicly resolvable hostname or an IP address
2021-09-23 22:50:37 ERROR (MainThread) [homeassistant] Error doing job: Future exception was never retrieved
Traceback (most recent call last):
  File "/usr/local/lib/python3.9/concurrent/futures/thread.py", line 52, in run
    result = self.fn(*self.args, **self.kwargs)
TypeError: update() takes 1 positional argument but 2 were given
2021-09-23 22:52:00 ERROR (Thread-13) [homeassistant.components.cast.media_player] Failed to cast media https://3hn0pigkolfj5459ps2gnq0jwb6qgqmq.ui.nabu.casa/media/local/1-second-of-silence.mp3?authSig=eyJ0eXAiOiJKV1QiLCJhbGciOiJIUzI1NiJ9.eyJpc3MiOiIzZWI2Mjg3Y2YzMjI0ZDgzYTBjY2FjZjRjYzgzYTJlNyIsInBhdGgiOiIvbWVkaWEvbG9jYWwvMS1zZWNvbmQtb2Ytc2lsZW5jZS5tcDMiLCJpYXQiOjE2MzI0NjI3MjAsImV4cCI6MTYzMjU0OTEyMH0.6Llf8ZKJFUf7PHjNt3OmqV5U_JBZ1Yq7bWznOlMiMr8 from external_url (https://3hn0pigkolfj5459ps2gnq0jwb6qgqmq.ui.nabu.casa). Please make sure the URL is: Reachable from the cast device and either a publicly resolvable hostname or an IP address
2021-09-23 22:52:00 ERROR (Thread-13) [homeassistant.components.cast.media_player] Failed to cast media https://3hn0pigkolfj5459ps2gnq0jwb6qgqmq.ui.nabu.casa/media/local/1-second-of-silence.mp3?authSig=eyJ0eXAiOiJKV1QiLCJhbGciOiJIUzI1NiJ9.eyJpc3MiOiIzZWI2Mjg3Y2YzMjI0ZDgzYTBjY2FjZjRjYzgzYTJlNyIsInBhdGgiOiIvbWVkaWEvbG9jYWwvMS1zZWNvbmQtb2Ytc2lsZW5jZS5tcDMiLCJpYXQiOjE2MzI0NjI3MjAsImV4cCI6MTYzMjU0OTEyMH0.6Llf8ZKJFUf7PHjNt3OmqV5U_JBZ1Yq7bWznOlMiMr8 from external_url (https://3hn0pigkolfj5459ps2gnq0jwb6qgqmq.ui.nabu.casa). Please make sure the URL is: Reachable from the cast device and either a publicly resolvable hostname or an IP address
2021-09-23 22:52:00 ERROR (Thread-13) [homeassistant.components.cast.media_player] Failed to cast media https://3hn0pigkolfj5459ps2gnq0jwb6qgqmq.ui.nabu.casa/media/local/1-second-of-silence.mp3?authSig=eyJ0eXAiOiJKV1QiLCJhbGciOiJIUzI1NiJ9.eyJpc3MiOiIzZWI2Mjg3Y2YzMjI0ZDgzYTBjY2FjZjRjYzgzYTJlNyIsInBhdGgiOiIvbWVkaWEvbG9jYWwvMS1zZWNvbmQtb2Ytc2lsZW5jZS5tcDMiLCJpYXQiOjE2MzI0NjI3MjAsImV4cCI6MTYzMjU0OTEyMH0.6Llf8ZKJFUf7PHjNt3OmqV5U_JBZ1Yq7bWznOlMiMr8 from external_url (https://3hn0pigkolfj5459ps2gnq0jwb6qgqmq.ui.nabu.casa). Please make sure the URL is: Reachable from the cast device and either a publicly resolvable hostname or an IP address
2021-09-23 22:52:00 ERROR (Thread-13) [homeassistant.components.cast.media_player] Failed to cast media https://3hn0pigkolfj5459ps2gnq0jwb6qgqmq.ui.nabu.casa/media/local/1-second-of-silence.mp3?authSig=eyJ0eXAiOiJKV1QiLCJhbGciOiJIUzI1NiJ9.eyJpc3MiOiIzZWI2Mjg3Y2YzMjI0ZDgzYTBjY2FjZjRjYzgzYTJlNyIsInBhdGgiOiIvbWVkaWEvbG9jYWwvMS1zZWNvbmQtb2Ytc2lsZW5jZS5tcDMiLCJpYXQiOjE2MzI0NjI3MjAsImV4cCI6MTYzMjU0OTEyMH0.6Llf8ZKJFUf7PHjNt3OmqV5U_JBZ1Yq7bWznOlMiMr8 from external_url (https://3hn0pigkolfj5459ps2gnq0jwb6qgqmq.ui.nabu.casa). Please make sure the URL is: Reachable from the cast device and either a publicly resolvable hostname or an IP address
2021-09-23 22:54:00 ERROR (Thread-13) [homeassistant.components.cast.media_player] Failed to cast media https://3hn0pigkolfj5459ps2gnq0jwb6qgqmq.ui.nabu.casa/media/local/1-second-of-silence.mp3?authSig=eyJ0eXAiOiJKV1QiLCJhbGciOiJIUzI1NiJ9.eyJpc3MiOiIzZWI2Mjg3Y2YzMjI0ZDgzYTBjY2FjZjRjYzgzYTJlNyIsInBhdGgiOiIvbWVkaWEvbG9jYWwvMS1zZWNvbmQtb2Ytc2lsZW5jZS5tcDMiLCJpYXQiOjE2MzI0NjI4NDAsImV4cCI6MTYzMjU0OTI0MH0.hls1PlyNKwJw-oUYgsbpNnK5sLEZ_B8D1JN-5VF1ri0 from external_url (https://3hn0pigkolfj5459ps2gnq0jwb6qgqmq.ui.nabu.casa). Please make sure the URL is: Reachable from the cast device and either a publicly resolvable hostname or an IP address
2021-09-23 22:54:00 ERROR (Thread-13) [homeassistant.components.cast.media_player] Failed to cast media https://3hn0pigkolfj5459ps2gnq0jwb6qgqmq.ui.nabu.casa/media/local/1-second-of-silence.mp3?authSig=eyJ0eXAiOiJKV1QiLCJhbGciOiJIUzI1NiJ9.eyJpc3MiOiIzZWI2Mjg3Y2YzMjI0ZDgzYTBjY2FjZjRjYzgzYTJlNyIsInBhdGgiOiIvbWVkaWEvbG9jYWwvMS1zZWNvbmQtb2Ytc2lsZW5jZS5tcDMiLCJpYXQiOjE2MzI0NjI4NDAsImV4cCI6MTYzMjU0OTI0MH0.hls1PlyNKwJw-oUYgsbpNnK5sLEZ_B8D1JN-5VF1ri0 from external_url (https://3hn0pigkolfj5459ps2gnq0jwb6qgqmq.ui.nabu.casa). Please make sure the URL is: Reachable from the cast device and either a publicly resolvable hostname or an IP address
2021-09-23 22:54:00 ERROR (Thread-13) [homeassistant.components.cast.media_player] Failed to cast media https://3hn0pigkolfj5459ps2gnq0jwb6qgqmq.ui.nabu.casa/media/local/1-second-of-silence.mp3?authSig=eyJ0eXAiOiJKV1QiLCJhbGciOiJIUzI1NiJ9.eyJpc3MiOiIzZWI2Mjg3Y2YzMjI0ZDgzYTBjY2FjZjRjYzgzYTJlNyIsInBhdGgiOiIvbWVkaWEvbG9jYWwvMS1zZWNvbmQtb2Ytc2lsZW5jZS5tcDMiLCJpYXQiOjE2MzI0NjI4NDAsImV4cCI6MTYzMjU0OTI0MH0.hls1PlyNKwJw-oUYgsbpNnK5sLEZ_B8D1JN-5VF1ri0 from external_url (https://3hn0pigkolfj5459ps2gnq0jwb6qgqmq.ui.nabu.casa). Please make sure the URL is: Reachable from the cast device and either a publicly resolvable hostname or an IP address
2021-09-23 22:54:00 ERROR (Thread-13) [homeassistant.components.cast.media_player] Failed to cast media https://3hn0pigkolfj5459ps2gnq0jwb6qgqmq.ui.nabu.casa/media/local/1-second-of-silence.mp3?authSig=eyJ0eXAiOiJKV1QiLCJhbGciOiJIUzI1NiJ9.eyJpc3MiOiIzZWI2Mjg3Y2YzMjI0ZDgzYTBjY2FjZjRjYzgzYTJlNyIsInBhdGgiOiIvbWVkaWEvbG9jYWwvMS1zZWNvbmQtb2Ytc2lsZW5jZS5tcDMiLCJpYXQiOjE2MzI0NjI4NDAsImV4cCI6MTYzMjU0OTI0MH0.hls1PlyNKwJw-oUYgsbpNnK5sLEZ_B8D1JN-5VF1ri0 from external_url (https://3hn0pigkolfj5459ps2gnq0jwb6qgqmq.ui.nabu.casa). Please make sure the URL is: Reachable from the cast device and either a publicly resolvable hostname or an IP address
2021-09-23 22:54:00 ERROR (stream_worker) [libav.rtsp] method DESCRIBE failed: 404 Not Found
2021-09-23 22:54:00 ERROR (stream_worker) [homeassistant.components.stream.worker] Error opening stream rtsps://stream-uc2-bravo.dropcam.com:443/sdm_live_stream/CiQA2vuxrxOTI9I8W8IKLDUvMPN5fAtPq_zu5jTmzSoA94ZCFLAScQAFjsOTHvWJCrqFqy9fnfN5VTI7_F3_7Sn41SM5hipBYxTVi3Yai4BBLNNa1XtwMSRxhPHLpX43JwKPb20I1wPB2FnkiOEo5edbO2C6yR2BrWNsh79QJuUHUA_YPR8GNr05Dyz9JKfwRN4bT1QlL62z?auth=g.0.eyJraWQiOiIyMzhiNTUxZmMyM2EyM2Y4M2E2ZTE3MmJjZTg0YmU3ZjgxMzAzMmM4IiwiYWxnIjoiUlMyNTYifQ.eyJpc3MiOiJuZXN0LXNlY3VyaXR5LWF1dGhwcm94eSIsInN1YiI6Im5lc3RfaWQ6bmVzdC1waG9lbml4LXByb2Q6MjEyMTgxNDEiLCJwb2wiOiIzcC1vYXV0aC1zY29wZS1BUElfU0RNX1NFUlZJQ0UtY2xpZW50LTIwMjQyNzMxODczNS1qNXQ5bWMyMzZqaG85YXMycWY0dTZxY3NmYW1kaGJ0ci5hcHBzLmdvb2dsZXVzZXJjb250ZW50LmNvbSIsImV4cCI6MTYzMjQ2MzEyOX0.ePD9b-TyXs1q-anZdELkPJJUDPxilKyqPyMlYiGFEuYStKIwlgOGPQ57j7xTmyEgL2HzzdTcAvfJ0ufa4kdlYKoF-G5oV3zBKQIxw6Kg86sCTuOhNrj5DAXhUJjQCEbp1YCIqMjDQMFbAuZz13kkamHTEEl6q8-D3s8YpGPVytqiBVegKDHKzFIJUhCoLAwKeWPwdLwpzJT1fhI4yffpK09pejChi06Nfl0lrpoy-JLj3-bxtD8MLgps00E8urjRS3Zl5q_5yA3XSTWO8dGcoF6KY4LtdKnFZJdSJxV8DKOvNbntnBGO-UCvpNDujLRJYTbRWssHtxCC8gsl-_PSBg
2021-09-23 22:54:21 ERROR (stream_worker) [libav.rtsp] method DESCRIBE failed: 404 Not Found
2021-09-23 22:54:21 ERROR (stream_worker) [homeassistant.components.stream.worker] Error opening stream rtsps://stream-uc2-bravo.dropcam.com:443/sdm_live_stream/CiQA2vuxrxOTI9I8W8IKLDUvMPN5fAtPq_zu5jTmzSoA94ZCFLAScQAFjsOTHvWJCrqFqy9fnfN5VTI7_F3_7Sn41SM5hipBYxTVi3Yai4BBLNNa1XtwMSRxhPHLpX43JwKPb20I1wPB2FnkiOEo5edbO2C6yR2BrWNsh79QJuUHUA_YPR8GNr05Dyz9JKfwRN4bT1QlL62z?auth=g.0.eyJraWQiOiIyMzhiNTUxZmMyM2EyM2Y4M2E2ZTE3MmJjZTg0YmU3ZjgxMzAzMmM4IiwiYWxnIjoiUlMyNTYifQ.eyJpc3MiOiJuZXN0LXNlY3VyaXR5LWF1dGhwcm94eSIsInN1YiI6Im5lc3RfaWQ6bmVzdC1waG9lbml4LXByb2Q6MjEyMTgxNDEiLCJwb2wiOiIzcC1vYXV0aC1zY29wZS1BUElfU0RNX1NFUlZJQ0UtY2xpZW50LTIwMjQyNzMxODczNS1qNXQ5bWMyMzZqaG85YXMycWY0dTZxY3NmYW1kaGJ0ci5hcHBzLmdvb2dsZXVzZXJjb250ZW50LmNvbSIsImV4cCI6MTYzMjQ2MzEyOX0.ePD9b-TyXs1q-anZdELkPJJUDPxilKyqPyMlYiGFEuYStKIwlgOGPQ57j7xTmyEgL2HzzdTcAvfJ0ufa4kdlYKoF-G5oV3zBKQIxw6Kg86sCTuOhNrj5DAXhUJjQCEbp1YCIqMjDQMFbAuZz13kkamHTEEl6q8-D3s8YpGPVytqiBVegKDHKzFIJUhCoLAwKeWPwdLwpzJT1fhI4yffpK09pejChi06Nfl0lrpoy-JLj3-bxtD8MLgps00E8urjRS3Zl5q_5yA3XSTWO8dGcoF6KY4LtdKnFZJdSJxV8DKOvNbntnBGO-UCvpNDujLRJYTbRWssHtxCC8gsl-_PSBg
2021-09-23 22:55:38 ERROR (MainThread) [homeassistant] Error doing job: Future exception was never retrieved
Traceback (most recent call last):
  File "/usr/local/lib/python3.9/concurrent/futures/thread.py", line 52, in run
    result = self.fn(*self.args, **self.kwargs)
TypeError: update() takes 1 positional argument but 2 were given
2021-09-23 22:56:00 ERROR (Thread-13) [homeassistant.components.cast.media_player] Failed to cast media https://3hn0pigkolfj5459ps2gnq0jwb6qgqmq.ui.nabu.casa/media/local/1-second-of-silence.mp3?authSig=eyJ0eXAiOiJKV1QiLCJhbGciOiJIUzI1NiJ9.eyJpc3MiOiIzZWI2Mjg3Y2YzMjI0ZDgzYTBjY2FjZjRjYzgzYTJlNyIsInBhdGgiOiIvbWVkaWEvbG9jYWwvMS1zZWNvbmQtb2Ytc2lsZW5jZS5tcDMiLCJpYXQiOjE2MzI0NjI5NjAsImV4cCI6MTYzMjU0OTM2MH0.RaKGfJUH2gZo79GnsoUCjoZlwdw5_9KdNi2mKvAPRFs from external_url (https://3hn0pigkolfj5459ps2gnq0jwb6qgqmq.ui.nabu.casa). Please make sure the URL is: Reachable from the cast device and either a publicly resolvable hostname or an IP address
2021-09-23 22:56:00 ERROR (Thread-13) [homeassistant.components.cast.media_player] Failed to cast media https://3hn0pigkolfj5459ps2gnq0jwb6qgqmq.ui.nabu.casa/media/local/1-second-of-silence.mp3?authSig=eyJ0eXAiOiJKV1QiLCJhbGciOiJIUzI1NiJ9.eyJpc3MiOiIzZWI2Mjg3Y2YzMjI0ZDgzYTBjY2FjZjRjYzgzYTJlNyIsInBhdGgiOiIvbWVkaWEvbG9jYWwvMS1zZWNvbmQtb2Ytc2lsZW5jZS5tcDMiLCJpYXQiOjE2MzI0NjI5NjAsImV4cCI6MTYzMjU0OTM2MH0.RaKGfJUH2gZo79GnsoUCjoZlwdw5_9KdNi2mKvAPRFs from external_url (https://3hn0pigkolfj5459ps2gnq0jwb6qgqmq.ui.nabu.casa). Please make sure the URL is: Reachable from the cast device and either a publicly resolvable hostname or an IP address
2021-09-23 22:56:00 ERROR (Thread-13) [homeassistant.components.cast.media_player] Failed to cast media https://3hn0pigkolfj5459ps2gnq0jwb6qgqmq.ui.nabu.casa/media/local/1-second-of-silence.mp3?authSig=eyJ0eXAiOiJKV1QiLCJhbGciOiJIUzI1NiJ9.eyJpc3MiOiIzZWI2Mjg3Y2YzMjI0ZDgzYTBjY2FjZjRjYzgzYTJlNyIsInBhdGgiOiIvbWVkaWEvbG9jYWwvMS1zZWNvbmQtb2Ytc2lsZW5jZS5tcDMiLCJpYXQiOjE2MzI0NjI5NjAsImV4cCI6MTYzMjU0OTM2MH0.RaKGfJUH2gZo79GnsoUCjoZlwdw5_9KdNi2mKvAPRFs from external_url (https://3hn0pigkolfj5459ps2gnq0jwb6qgqmq.ui.nabu.casa). Please make sure the URL is: Reachable from the cast device and either a publicly resolvable hostname or an IP address
2021-09-23 22:56:00 ERROR (Thread-13) [homeassistant.components.cast.media_player] Failed to cast media https://3hn0pigkolfj5459ps2gnq0jwb6qgqmq.ui.nabu.casa/media/local/1-second-of-silence.mp3?authSig=eyJ0eXAiOiJKV1QiLCJhbGciOiJIUzI1NiJ9.eyJpc3MiOiIzZWI2Mjg3Y2YzMjI0ZDgzYTBjY2FjZjRjYzgzYTJlNyIsInBhdGgiOiIvbWVkaWEvbG9jYWwvMS1zZWNvbmQtb2Ytc2lsZW5jZS5tcDMiLCJpYXQiOjE2MzI0NjI5NjAsImV4cCI6MTYzMjU0OTM2MH0.RaKGfJUH2gZo79GnsoUCjoZlwdw5_9KdNi2mKvAPRFs from external_url (https://3hn0pigkolfj5459ps2gnq0jwb6qgqmq.ui.nabu.casa). Please make sure the URL is: Reachable from the cast device and either a publicly resolvable hostname or an IP address
2021-09-23 22:57:21 ERROR (MainThread) [homeassistant.config] Invalid config for [automation]: Invalid trigger configuration. Got OrderedDict([('default_config', {}), ('frontend', OrderedDict([('themes', OrderedDict())])), ('mobile_app', {}), ('discovery', {'ignore': [], 'enable': []}), ('python_script', {}), ('sun', {}), ('recorder', {'db_max_retries': 10, 'purge_keep_days': 10, 'auto_purge': True, 'exclude': {'entities': [], 'entity_globs': [], 'domains': []}, 'db_retry_wait': 3, 'purge_interval': 1, 'db_integrity_check': True, 'include': {'entities': [], 'entity_globs': [], 'domains': []}, 'commit_interval': 1}), ('a.... (See /config/configuration.yaml, line 29). 
2021-09-23 22:57:21 ERROR (MainThread) [homeassistant.config] Invalid config for [automation]: Invalid trigger configuration. Got OrderedDict([('default_config', {}), ('frontend', OrderedDict([('themes', OrderedDict())])), ('mobile_app', {}), ('discovery', {'ignore': [], 'enable': []}), ('python_script', {}), ('sun', {}), ('recorder', {'db_max_retries': 10, 'purge_keep_days': 10, 'auto_purge': True, 'exclude': {'entities': [], 'entity_globs': [], 'domains': []}, 'db_retry_wait': 3, 'purge_interval': 1, 'db_integrity_check': True, 'include': {'entities': [], 'entity_globs': [], 'domains': []}, 'commit_interval': 1}), ('a.... (See /config/configuration.yaml, line 29). 
2021-09-23 22:57:21 ERROR (MainThread) [homeassistant.config] Invalid config for [automation]: Invalid trigger configuration. Got OrderedDict([('default_config', {}), ('frontend', OrderedDict([('themes', OrderedDict())])), ('mobile_app', {}), ('discovery', {'ignore': [], 'enable': []}), ('python_script', {}), ('sun', {}), ('recorder', {'db_max_retries': 10, 'purge_keep_days': 10, 'auto_purge': True, 'exclude': {'entities': [], 'entity_globs': [], 'domains': []}, 'db_retry_wait': 3, 'purge_interval': 1, 'db_integrity_check': True, 'include': {'entities': [], 'entity_globs': [], 'domains': []}, 'commit_interval': 1}), ('a.... (See /config/configuration.yaml, line 29). 
2021-09-23 22:57:21 ERROR (MainThread) [homeassistant.config] Invalid config for [automation]: Invalid trigger configuration. Got OrderedDict([('default_config', {}), ('frontend', OrderedDict([('themes', OrderedDict())])), ('mobile_app', {}), ('discovery', {'ignore': [], 'enable': []}), ('python_script', {}), ('sun', {}), ('recorder', {'db_max_retries': 10, 'purge_keep_days': 10, 'auto_purge': True, 'exclude': {'entities': [], 'entity_globs': [], 'domains': []}, 'db_retry_wait': 3, 'purge_interval': 1, 'db_integrity_check': True, 'include': {'entities': [], 'entity_globs': [], 'domains': []}, 'commit_interval': 1}), ('a.... (See /config/configuration.yaml, line 29). 
2021-09-23 22:57:21 ERROR (MainThread) [homeassistant.config] Invalid config for [automation]: Invalid trigger configuration. Got OrderedDict([('default_config', {}), ('frontend', OrderedDict([('themes', OrderedDict())])), ('mobile_app', {}), ('discovery', {'ignore': [], 'enable': []}), ('python_script', {}), ('sun', {}), ('recorder', {'db_max_retries': 10, 'purge_keep_days': 10, 'auto_purge': True, 'exclude': {'entities': [], 'entity_globs': [], 'domains': []}, 'db_retry_wait': 3, 'purge_interval': 1, 'db_integrity_check': True, 'include': {'entities': [], 'entity_globs': [], 'domains': []}, 'commit_interval': 1}), ('a.... (See /config/configuration.yaml, line 29). 
2021-09-23 22:57:32 ERROR (MainThread) [homeassistant.components.websocket_api.http.connection] [23371906921184] Received invalid command: zha/configuration
2021-09-23 22:58:00 ERROR (Thread-13) [homeassistant.components.cast.media_player] Failed to cast media https://3hn0pigkolfj5459ps2gnq0jwb6qgqmq.ui.nabu.casa/media/local/1-second-of-silence.mp3?authSig=eyJ0eXAiOiJKV1QiLCJhbGciOiJIUzI1NiJ9.eyJpc3MiOiIzZWI2Mjg3Y2YzMjI0ZDgzYTBjY2FjZjRjYzgzYTJlNyIsInBhdGgiOiIvbWVkaWEvbG9jYWwvMS1zZWNvbmQtb2Ytc2lsZW5jZS5tcDMiLCJpYXQiOjE2MzI0NjMwODAsImV4cCI6MTYzMjU0OTQ4MH0.9U-BovNMzrhreaM6E--WwOg6NX3mKA-cn0G8_LOxYbE from external_url (https://3hn0pigkolfj5459ps2gnq0jwb6qgqmq.ui.nabu.casa). Please make sure the URL is: Reachable from the cast device and either a publicly resolvable hostname or an IP address
2021-09-23 22:58:00 ERROR (Thread-13) [homeassistant.components.cast.media_player] Failed to cast media https://3hn0pigkolfj5459ps2gnq0jwb6qgqmq.ui.nabu.casa/media/local/1-second-of-silence.mp3?authSig=eyJ0eXAiOiJKV1QiLCJhbGciOiJIUzI1NiJ9.eyJpc3MiOiIzZWI2Mjg3Y2YzMjI0ZDgzYTBjY2FjZjRjYzgzYTJlNyIsInBhdGgiOiIvbWVkaWEvbG9jYWwvMS1zZWNvbmQtb2Ytc2lsZW5jZS5tcDMiLCJpYXQiOjE2MzI0NjMwODAsImV4cCI6MTYzMjU0OTQ4MH0.9U-BovNMzrhreaM6E--WwOg6NX3mKA-cn0G8_LOxYbE from external_url (https://3hn0pigkolfj5459ps2gnq0jwb6qgqmq.ui.nabu.casa). Please make sure the URL is: Reachable from the cast device and either a publicly resolvable hostname or an IP address
2021-09-23 22:58:00 ERROR (Thread-13) [homeassistant.components.cast.media_player] Failed to cast media https://3hn0pigkolfj5459ps2gnq0jwb6qgqmq.ui.nabu.casa/media/local/1-second-of-silence.mp3?authSig=eyJ0eXAiOiJKV1QiLCJhbGciOiJIUzI1NiJ9.eyJpc3MiOiIzZWI2Mjg3Y2YzMjI0ZDgzYTBjY2FjZjRjYzgzYTJlNyIsInBhdGgiOiIvbWVkaWEvbG9jYWwvMS1zZWNvbmQtb2Ytc2lsZW5jZS5tcDMiLCJpYXQiOjE2MzI0NjMwODAsImV4cCI6MTYzMjU0OTQ4MH0.9U-BovNMzrhreaM6E--WwOg6NX3mKA-cn0G8_LOxYbE from external_url (https://3hn0pigkolfj5459ps2gnq0jwb6qgqmq.ui.nabu.casa). Please make sure the URL is: Reachable from the cast device and either a publicly resolvable hostname or an IP address
2021-09-23 22:58:00 ERROR (Thread-13) [homeassistant.components.cast.media_player] Failed to cast media https://3hn0pigkolfj5459ps2gnq0jwb6qgqmq.ui.nabu.casa/media/local/1-second-of-silence.mp3?authSig=eyJ0eXAiOiJKV1QiLCJhbGciOiJIUzI1NiJ9.eyJpc3MiOiIzZWI2Mjg3Y2YzMjI0ZDgzYTBjY2FjZjRjYzgzYTJlNyIsInBhdGgiOiIvbWVkaWEvbG9jYWwvMS1zZWNvbmQtb2Ytc2lsZW5jZS5tcDMiLCJpYXQiOjE2MzI0NjMwODAsImV4cCI6MTYzMjU0OTQ4MH0.9U-BovNMzrhreaM6E--WwOg6NX3mKA-cn0G8_LOxYbE from external_url (https://3hn0pigkolfj5459ps2gnq0jwb6qgqmq.ui.nabu.casa). Please make sure the URL is: Reachable from the cast device and either a publicly resolvable hostname or an IP address
2021-09-23 22:58:20 ERROR (MainThread) [homeassistant.components.websocket_api.http.connection] [23371906921184] Received invalid command: zha/configuration
2021-09-23 22:58:22 ERROR (MainThread) [homeassistant.components.websocket_api.http.connection] [23371906921184] Received invalid command: zha/configuration
2021-09-23 22:59:11 ERROR (MainThread) [homeassistant.config] Invalid config for [automation]: Invalid trigger configuration. Got OrderedDict([('default_config', {}), ('frontend', OrderedDict([('themes', OrderedDict())])), ('mobile_app', {}), ('discovery', {'ignore': [], 'enable': []}), ('python_script', {}), ('sun', {}), ('recorder', {'db_max_retries': 10, 'purge_keep_days': 10, 'auto_purge': True, 'exclude': {'entities': [], 'entity_globs': [], 'domains': []}, 'db_retry_wait': 3, 'purge_interval': 1, 'db_integrity_check': True, 'include': {'entities': [], 'entity_globs': [], 'domains': []}, 'commit_interval': 1}), ('a.... (See /config/configuration.yaml, line 29). 
2021-09-23 22:59:11 ERROR (MainThread) [homeassistant.config] Invalid config for [automation]: Invalid trigger configuration. Got OrderedDict([('default_config', {}), ('frontend', OrderedDict([('themes', OrderedDict())])), ('mobile_app', {}), ('discovery', {'ignore': [], 'enable': []}), ('python_script', {}), ('sun', {}), ('recorder', {'db_max_retries': 10, 'purge_keep_days': 10, 'auto_purge': True, 'exclude': {'entities': [], 'entity_globs': [], 'domains': []}, 'db_retry_wait': 3, 'purge_interval': 1, 'db_integrity_check': True, 'include': {'entities': [], 'entity_globs': [], 'domains': []}, 'commit_interval': 1}), ('a.... (See /config/configuration.yaml, line 29). 
2021-09-23 22:59:11 ERROR (MainThread) [homeassistant.config] Invalid config for [automation]: Invalid trigger configuration. Got OrderedDict([('default_config', {}), ('frontend', OrderedDict([('themes', OrderedDict())])), ('mobile_app', {}), ('discovery', {'ignore': [], 'enable': []}), ('python_script', {}), ('sun', {}), ('recorder', {'db_max_retries': 10, 'purge_keep_days': 10, 'auto_purge': True, 'exclude': {'entities': [], 'entity_globs': [], 'domains': []}, 'db_retry_wait': 3, 'purge_interval': 1, 'db_integrity_check': True, 'include': {'entities': [], 'entity_globs': [], 'domains': []}, 'commit_interval': 1}), ('a.... (See /config/configuration.yaml, line 29). 
2021-09-23 22:59:11 ERROR (MainThread) [homeassistant.config] Invalid config for [automation]: Invalid trigger configuration. Got OrderedDict([('default_config', {}), ('frontend', OrderedDict([('themes', OrderedDict())])), ('mobile_app', {}), ('discovery', {'ignore': [], 'enable': []}), ('python_script', {}), ('sun', {}), ('recorder', {'db_max_retries': 10, 'purge_keep_days': 10, 'auto_purge': True, 'exclude': {'entities': [], 'entity_globs': [], 'domains': []}, 'db_retry_wait': 3, 'purge_interval': 1, 'db_integrity_check': True, 'include': {'entities': [], 'entity_globs': [], 'domains': []}, 'commit_interval': 1}), ('a.... (See /config/configuration.yaml, line 29). 
2021-09-23 22:59:11 ERROR (MainThread) [homeassistant.config] Invalid config for [automation]: Invalid trigger configuration. Got OrderedDict([('default_config', {}), ('frontend', OrderedDict([('themes', OrderedDict())])), ('mobile_app', {}), ('discovery', {'ignore': [], 'enable': []}), ('python_script', {}), ('sun', {}), ('recorder', {'db_max_retries': 10, 'purge_keep_days': 10, 'auto_purge': True, 'exclude': {'entities': [], 'entity_globs': [], 'domains': []}, 'db_retry_wait': 3, 'purge_interval': 1, 'db_integrity_check': True, 'include': {'entities': [], 'entity_globs': [], 'domains': []}, 'commit_interval': 1}), ('a.... (See /config/configuration.yaml, line 29). 
