2021-09-12 16:35:10 WARNING (SyncWorker_0) [homeassistant.loader] We found a custom integration sun2 which has not been tested by Home Assistant. This component might cause stability problems, be sure to disable it if you experience issues with Home Assistant
2021-09-12 16:35:23 WARNING (MainThread) [homeassistant.components.sensor] Entity sensor.cpu_temp (<class 'homeassistant.components.command_line.sensor.CommandSensor'>) with device_class None reports a temperature in °C which will be converted to °F. Temperature conversion for entities without correct device_class is deprecated and will be removed from Home Assistant Core 2022.3. Please update your configuration if device_class is manually configured, otherwise create a bug report at https://github.com/home-assistant/core/issues?q=is%3Aopen+is%3Aissue+label%3A%22integration%3A+command_line%22
2021-09-12 16:35:23 WARNING (MainThread) [homeassistant.config_entries] Config entry 'Cerezo House HA' for forecast_solar integration not ready yet: 500, message='Internal Server Error', url=URL('https://91.228.53.233/estimate/34.3769732/-118.5435177/35/-20/7.458?time=iso8601&damping=0.0'); Retrying in background
2021-09-12 16:35:25 WARNING (MainThread) [homeassistant.config_entries] Config entry 'Roku Smart Soundbar' for roku integration not ready yet: Invalid response from API: Error occurred while communicating with device; Retrying in background
2021-09-12 16:35:27 WARNING (MainThread) [homeassistant.components.sensor] Entity sensor.attictemp1_bme280_dewpoint (<class 'homeassistant.components.tasmota.sensor.TasmotaSensor'>) with device_class None reports a temperature in °C which will be converted to °F. Temperature conversion for entities without correct device_class is deprecated and will be removed from Home Assistant Core 2022.3. Please update your configuration if device_class is manually configured, otherwise create a bug report at https://github.com/home-assistant/core/issues?q=is%3Aopen+is%3Aissue+label%3A%22integration%3A+tasmota%22
2021-09-12 16:35:27 WARNING (MainThread) [homeassistant.components.sensor] Entity sensor.garagesidedoorsensor_bme280_dewpoint (<class 'homeassistant.components.tasmota.sensor.TasmotaSensor'>) with device_class None reports a temperature in °C which will be converted to °F. Temperature conversion for entities without correct device_class is deprecated and will be removed from Home Assistant Core 2022.3. Please update your configuration if device_class is manually configured, otherwise create a bug report at https://github.com/home-assistant/core/issues?q=is%3Aopen+is%3Aissue+label%3A%22integration%3A+tasmota%22
2021-09-12 16:35:31 WARNING (MainThread) [homeassistant.config_entries] Config entry '192.168.7.195' for wled integration not ready yet: Invalid response from API: Error occurred while communicating with WLED device at 192.168.7.195; Retrying in background
2021-09-12 16:40:19 ERROR (MainThread) [homeassistant] Error doing job: Future exception was never retrieved
Traceback (most recent call last):
  File "/usr/local/lib/python3.9/concurrent/futures/thread.py", line 52, in run
    result = self.fn(*self.args, **self.kwargs)
TypeError: update() takes 1 positional argument but 2 were given
2021-09-12 16:44:59 ERROR (MainThread) [iotawattpy.connection] Err: 
2021-09-12 16:44:59 ERROR (MainThread) [homeassistant.components.iotawatt.coordinator] Unexpected error fetching 192.168.20.195 data: 'NoneType' object has no attribute 'text'
Traceback (most recent call last):
  File "/usr/src/homeassistant/homeassistant/helpers/update_coordinator.py", line 187, in _async_refresh
    self.data = await self._async_update_data()
  File "/usr/src/homeassistant/homeassistant/components/iotawatt/coordinator.py", line 55, in _async_update_data
    await self.api.update()
  File "/usr/local/lib/python3.9/site-packages/iotawattpy/iotawatt.py", line 66, in update
    await self._refreshSensors(timespan)
  File "/usr/local/lib/python3.9/site-packages/iotawattpy/iotawatt.py", line 100, in _refreshSensors
    results = response.text
AttributeError: 'NoneType' object has no attribute 'text'
2021-09-12 16:45:20 ERROR (MainThread) [homeassistant] Error doing job: Future exception was never retrieved
Traceback (most recent call last):
  File "/usr/local/lib/python3.9/concurrent/futures/thread.py", line 52, in run
    result = self.fn(*self.args, **self.kwargs)
TypeError: update() takes 1 positional argument but 2 were given
2021-09-12 16:49:54 ERROR (stream_worker) [libav.rtsp] method DESCRIBE failed: 404 Not Found
2021-09-12 16:49:54 ERROR (stream_worker) [homeassistant.components.stream.worker] Error opening stream rtsps://stream-uc2-delta.dropcam.com:443/sdm_live_stream/CiQA2vuxr70CRx2gK8IRmLITNFF032c4dkVUVFEPjSiot_nPtdkScQAFjsOTeLoFyxqJAyv7itMSpamqPm-sOSWbJVUkhKBpkVf4At5KSgRU8_keohbk6Jv-nN1YcRTUbAE8QIYS29993MKo34mCnPbDtaeqsMOxElEcJuWTAQlGp9HPqHLiZJ5JwthadbQD0aS-ZW5Ae7Gv?auth=g.0.eyJraWQiOiIyMzhiNTUxZmMyM2EyM2Y4M2E2ZTE3MmJjZTg0YmU3ZjgxMzAzMmM4IiwiYWxnIjoiUlMyNTYifQ.eyJpc3MiOiJuZXN0LXNlY3VyaXR5LWF1dGhwcm94eSIsInN1YiI6Im5lc3RfaWQ6bmVzdC1waG9lbml4LXByb2Q6MjEyMTgxNDEiLCJwb2wiOiIzcC1vYXV0aC1zY29wZS1BUElfU0RNX1NFUlZJQ0UtY2xpZW50LTIwMjQyNzMxODczNS1qNXQ5bWMyMzZqaG85YXMycWY0dTZxY3NmYW1kaGJ0ci5hcHBzLmdvb2dsZXVzZXJjb250ZW50LmNvbSIsImV4cCI6MTYzMTQ5MDg3NX0.dtAntGs4knzvqlIKlZD6iG86n83oF7hyKAyCJnnk6HzqV1tKFFa1C-8VTdaL2_oux2gRXarwtWCFVHaXogRXkrEJfjLlIghcAV9M5Eisyas4N8zRXV3wJgGyEJFGbOLMX2hl6ToBbzYZQw5XNjaSmrrqaZEUwPu7ffdzXKN61jWMJpil31drxJuDlDczFBI3iRqUzRzpAfuzBXRnC6BsIfJfN-r9N5b85Ua4T9OMhvNx4nC4kduAy2cn4e7-c0c-HTKGm31zlnMKi_ttb62jNUcul8ENqOkOi-r6Qg6uRyNME1n_KUd62_0_G0bx_sz4aiS--WoSMTvHUV3Qb6evOw
2021-09-12 16:50:15 ERROR (stream_worker) [libav.rtsp] method DESCRIBE failed: 404 Not Found
2021-09-12 16:50:15 ERROR (stream_worker) [homeassistant.components.stream.worker] Error opening stream rtsps://stream-uc2-delta.dropcam.com:443/sdm_live_stream/CiQA2vuxr70CRx2gK8IRmLITNFF032c4dkVUVFEPjSiot_nPtdkScQAFjsOTeLoFyxqJAyv7itMSpamqPm-sOSWbJVUkhKBpkVf4At5KSgRU8_keohbk6Jv-nN1YcRTUbAE8QIYS29993MKo34mCnPbDtaeqsMOxElEcJuWTAQlGp9HPqHLiZJ5JwthadbQD0aS-ZW5Ae7Gv?auth=g.0.eyJraWQiOiIyMzhiNTUxZmMyM2EyM2Y4M2E2ZTE3MmJjZTg0YmU3ZjgxMzAzMmM4IiwiYWxnIjoiUlMyNTYifQ.eyJpc3MiOiJuZXN0LXNlY3VyaXR5LWF1dGhwcm94eSIsInN1YiI6Im5lc3RfaWQ6bmVzdC1waG9lbml4LXByb2Q6MjEyMTgxNDEiLCJwb2wiOiIzcC1vYXV0aC1zY29wZS1BUElfU0RNX1NFUlZJQ0UtY2xpZW50LTIwMjQyNzMxODczNS1qNXQ5bWMyMzZqaG85YXMycWY0dTZxY3NmYW1kaGJ0ci5hcHBzLmdvb2dsZXVzZXJjb250ZW50LmNvbSIsImV4cCI6MTYzMTQ5MDg3NX0.dtAntGs4knzvqlIKlZD6iG86n83oF7hyKAyCJnnk6HzqV1tKFFa1C-8VTdaL2_oux2gRXarwtWCFVHaXogRXkrEJfjLlIghcAV9M5Eisyas4N8zRXV3wJgGyEJFGbOLMX2hl6ToBbzYZQw5XNjaSmrrqaZEUwPu7ffdzXKN61jWMJpil31drxJuDlDczFBI3iRqUzRzpAfuzBXRnC6BsIfJfN-r9N5b85Ua4T9OMhvNx4nC4kduAy2cn4e7-c0c-HTKGm31zlnMKi_ttb62jNUcul8ENqOkOi-r6Qg6uRyNME1n_KUd62_0_G0bx_sz4aiS--WoSMTvHUV3Qb6evOw
2021-09-12 16:50:21 ERROR (MainThread) [homeassistant] Error doing job: Future exception was never retrieved
Traceback (most recent call last):
  File "/usr/local/lib/python3.9/concurrent/futures/thread.py", line 52, in run
    result = self.fn(*self.args, **self.kwargs)
TypeError: update() takes 1 positional argument but 2 were given
2021-09-12 16:50:46 ERROR (stream_worker) [libav.rtsp] method DESCRIBE failed: 404 Not Found
2021-09-12 16:50:46 ERROR (stream_worker) [homeassistant.components.stream.worker] Error opening stream rtsps://stream-uc2-delta.dropcam.com:443/sdm_live_stream/CiQA2vuxr70CRx2gK8IRmLITNFF032c4dkVUVFEPjSiot_nPtdkScQAFjsOTeLoFyxqJAyv7itMSpamqPm-sOSWbJVUkhKBpkVf4At5KSgRU8_keohbk6Jv-nN1YcRTUbAE8QIYS29993MKo34mCnPbDtaeqsMOxElEcJuWTAQlGp9HPqHLiZJ5JwthadbQD0aS-ZW5Ae7Gv?auth=g.0.eyJraWQiOiIyMzhiNTUxZmMyM2EyM2Y4M2E2ZTE3MmJjZTg0YmU3ZjgxMzAzMmM4IiwiYWxnIjoiUlMyNTYifQ.eyJpc3MiOiJuZXN0LXNlY3VyaXR5LWF1dGhwcm94eSIsInN1YiI6Im5lc3RfaWQ6bmVzdC1waG9lbml4LXByb2Q6MjEyMTgxNDEiLCJwb2wiOiIzcC1vYXV0aC1zY29wZS1BUElfU0RNX1NFUlZJQ0UtY2xpZW50LTIwMjQyNzMxODczNS1qNXQ5bWMyMzZqaG85YXMycWY0dTZxY3NmYW1kaGJ0ci5hcHBzLmdvb2dsZXVzZXJjb250ZW50LmNvbSIsImV4cCI6MTYzMTQ5MDg3NX0.dtAntGs4knzvqlIKlZD6iG86n83oF7hyKAyCJnnk6HzqV1tKFFa1C-8VTdaL2_oux2gRXarwtWCFVHaXogRXkrEJfjLlIghcAV9M5Eisyas4N8zRXV3wJgGyEJFGbOLMX2hl6ToBbzYZQw5XNjaSmrrqaZEUwPu7ffdzXKN61jWMJpil31drxJuDlDczFBI3iRqUzRzpAfuzBXRnC6BsIfJfN-r9N5b85Ua4T9OMhvNx4nC4kduAy2cn4e7-c0c-HTKGm31zlnMKi_ttb62jNUcul8ENqOkOi-r6Qg6uRyNME1n_KUd62_0_G0bx_sz4aiS--WoSMTvHUV3Qb6evOw
2021-09-12 16:55:22 ERROR (MainThread) [homeassistant] Error doing job: Future exception was never retrieved
Traceback (most recent call last):
  File "/usr/local/lib/python3.9/concurrent/futures/thread.py", line 52, in run
    result = self.fn(*self.args, **self.kwargs)
TypeError: update() takes 1 positional argument but 2 were given
2021-09-12 16:55:45 ERROR (stream_worker) [libav.tls] Error in the pull function.
2021-09-12 16:55:45 ERROR (stream_worker) [libav.tls] The specified session has been invalidated for some reason.
2021-09-12 16:55:45 ERROR (stream_worker) [homeassistant.components.stream.worker] Error demuxing stream: 
2021-09-12 16:55:47 ERROR (stream_worker) [libav.tls] The specified session has been invalidated for some reason.
2021-09-12 17:00:23 ERROR (MainThread) [homeassistant] Error doing job: Future exception was never retrieved
Traceback (most recent call last):
  File "/usr/local/lib/python3.9/concurrent/futures/thread.py", line 52, in run
    result = self.fn(*self.args, **self.kwargs)
TypeError: update() takes 1 positional argument but 2 were given
2021-09-12 17:05:24 ERROR (MainThread) [homeassistant] Error doing job: Future exception was never retrieved
Traceback (most recent call last):
  File "/usr/local/lib/python3.9/concurrent/futures/thread.py", line 52, in run
    result = self.fn(*self.args, **self.kwargs)
TypeError: update() takes 1 positional argument but 2 were given
2021-09-12 17:05:38 ERROR (MainThread) [iotawattpy.connection] Err: 
2021-09-12 17:05:38 ERROR (MainThread) [homeassistant.components.iotawatt.coordinator] Unexpected error fetching 192.168.20.195 data: 'NoneType' object has no attribute 'text'
Traceback (most recent call last):
  File "/usr/src/homeassistant/homeassistant/helpers/update_coordinator.py", line 187, in _async_refresh
    self.data = await self._async_update_data()
  File "/usr/src/homeassistant/homeassistant/components/iotawatt/coordinator.py", line 55, in _async_update_data
    await self.api.update()
  File "/usr/local/lib/python3.9/site-packages/iotawattpy/iotawatt.py", line 66, in update
    await self._refreshSensors(timespan)
  File "/usr/local/lib/python3.9/site-packages/iotawattpy/iotawatt.py", line 100, in _refreshSensors
    results = response.text
AttributeError: 'NoneType' object has no attribute 'text'
2021-09-12 17:07:00 ERROR (MainThread) [homeassistant.components.websocket_api.http.connection] [23232373314752] Error handling message: Unknown error
Traceback (most recent call last):
  File "/usr/src/homeassistant/homeassistant/components/websocket_api/decorators.py", line 25, in _handle_async_response
    await func(hass, connection, msg)
  File "/usr/src/homeassistant/homeassistant/components/energy/websocket_api.py", line 85, in with_manager
    await result
  File "/usr/src/homeassistant/homeassistant/components/energy/websocket_api.py", line 215, in ws_solar_forecast
    forecast = await forecast_platforms[config_entry.domain](hass, config_entry_id)
  File "/usr/src/homeassistant/homeassistant/components/forecast_solar/energy.py", line 13, in async_get_solar_forecast
    coordinator = hass.data[DOMAIN].get(config_entry_id)
KeyError: 'forecast_solar'
2021-09-12 17:07:02 ERROR (MainThread) [homeassistant.components.websocket_api.http.connection] [23232407970480] Error handling message: Unknown error
Traceback (most recent call last):
  File "/usr/src/homeassistant/homeassistant/components/websocket_api/decorators.py", line 25, in _handle_async_response
    await func(hass, connection, msg)
  File "/usr/src/homeassistant/homeassistant/components/energy/websocket_api.py", line 85, in with_manager
    await result
  File "/usr/src/homeassistant/homeassistant/components/energy/websocket_api.py", line 215, in ws_solar_forecast
    forecast = await forecast_platforms[config_entry.domain](hass, config_entry_id)
  File "/usr/src/homeassistant/homeassistant/components/forecast_solar/energy.py", line 13, in async_get_solar_forecast
    coordinator = hass.data[DOMAIN].get(config_entry_id)
KeyError: 'forecast_solar'
2021-09-12 17:07:06 ERROR (MainThread) [homeassistant.components.websocket_api.http.connection] [23232407970480] Error handling message: Unknown error
Traceback (most recent call last):
  File "/usr/src/homeassistant/homeassistant/components/websocket_api/decorators.py", line 25, in _handle_async_response
    await func(hass, connection, msg)
  File "/usr/src/homeassistant/homeassistant/components/energy/websocket_api.py", line 85, in with_manager
    await result
  File "/usr/src/homeassistant/homeassistant/components/energy/websocket_api.py", line 215, in ws_solar_forecast
    forecast = await forecast_platforms[config_entry.domain](hass, config_entry_id)
  File "/usr/src/homeassistant/homeassistant/components/forecast_solar/energy.py", line 13, in async_get_solar_forecast
    coordinator = hass.data[DOMAIN].get(config_entry_id)
KeyError: 'forecast_solar'
2021-09-12 17:07:06 ERROR (MainThread) [homeassistant.components.websocket_api.http.connection] [23232407970480] Error handling message: Unknown error
Traceback (most recent call last):
  File "/usr/src/homeassistant/homeassistant/components/websocket_api/decorators.py", line 25, in _handle_async_response
    await func(hass, connection, msg)
  File "/usr/src/homeassistant/homeassistant/components/energy/websocket_api.py", line 85, in with_manager
    await result
  File "/usr/src/homeassistant/homeassistant/components/energy/websocket_api.py", line 215, in ws_solar_forecast
    forecast = await forecast_platforms[config_entry.domain](hass, config_entry_id)
  File "/usr/src/homeassistant/homeassistant/components/forecast_solar/energy.py", line 13, in async_get_solar_forecast
    coordinator = hass.data[DOMAIN].get(config_entry_id)
KeyError: 'forecast_solar'
2021-09-12 17:07:15 ERROR (MainThread) [homeassistant.components.websocket_api.http.connection] [23232407970480] Error handling message: Unknown error
Traceback (most recent call last):
  File "/usr/src/homeassistant/homeassistant/components/websocket_api/decorators.py", line 25, in _handle_async_response
    await func(hass, connection, msg)
  File "/usr/src/homeassistant/homeassistant/components/energy/websocket_api.py", line 85, in with_manager
    await result
  File "/usr/src/homeassistant/homeassistant/components/energy/websocket_api.py", line 215, in ws_solar_forecast
    forecast = await forecast_platforms[config_entry.domain](hass, config_entry_id)
  File "/usr/src/homeassistant/homeassistant/components/forecast_solar/energy.py", line 13, in async_get_solar_forecast
    coordinator = hass.data[DOMAIN].get(config_entry_id)
KeyError: 'forecast_solar'
2021-09-12 17:07:15 ERROR (MainThread) [homeassistant.components.websocket_api.http.connection] [23232407970480] Error handling message: Unknown error
Traceback (most recent call last):
  File "/usr/src/homeassistant/homeassistant/components/websocket_api/decorators.py", line 25, in _handle_async_response
    await func(hass, connection, msg)
  File "/usr/src/homeassistant/homeassistant/components/energy/websocket_api.py", line 85, in with_manager
    await result
  File "/usr/src/homeassistant/homeassistant/components/energy/websocket_api.py", line 215, in ws_solar_forecast
    forecast = await forecast_platforms[config_entry.domain](hass, config_entry_id)
  File "/usr/src/homeassistant/homeassistant/components/forecast_solar/energy.py", line 13, in async_get_solar_forecast
    coordinator = hass.data[DOMAIN].get(config_entry_id)
KeyError: 'forecast_solar'
2021-09-12 17:10:25 ERROR (MainThread) [homeassistant] Error doing job: Future exception was never retrieved
Traceback (most recent call last):
  File "/usr/local/lib/python3.9/concurrent/futures/thread.py", line 52, in run
    result = self.fn(*self.args, **self.kwargs)
TypeError: update() takes 1 positional argument but 2 were given
2021-09-12 17:11:53 ERROR (MainThread) [homeassistant.components.websocket_api.http.connection] [23232407970480] Error handling message: Unknown error
Traceback (most recent call last):
  File "/usr/src/homeassistant/homeassistant/components/websocket_api/decorators.py", line 25, in _handle_async_response
    await func(hass, connection, msg)
  File "/usr/src/homeassistant/homeassistant/components/energy/websocket_api.py", line 85, in with_manager
    await result
  File "/usr/src/homeassistant/homeassistant/components/energy/websocket_api.py", line 215, in ws_solar_forecast
    forecast = await forecast_platforms[config_entry.domain](hass, config_entry_id)
  File "/usr/src/homeassistant/homeassistant/components/forecast_solar/energy.py", line 13, in async_get_solar_forecast
    coordinator = hass.data[DOMAIN].get(config_entry_id)
KeyError: 'forecast_solar'
2021-09-12 17:11:53 ERROR (MainThread) [homeassistant.components.websocket_api.http.connection] [23232407970480] Error handling message: Unknown error
Traceback (most recent call last):
  File "/usr/src/homeassistant/homeassistant/components/websocket_api/decorators.py", line 25, in _handle_async_response
    await func(hass, connection, msg)
  File "/usr/src/homeassistant/homeassistant/components/energy/websocket_api.py", line 85, in with_manager
    await result
  File "/usr/src/homeassistant/homeassistant/components/energy/websocket_api.py", line 215, in ws_solar_forecast
    forecast = await forecast_platforms[config_entry.domain](hass, config_entry_id)
  File "/usr/src/homeassistant/homeassistant/components/forecast_solar/energy.py", line 13, in async_get_solar_forecast
    coordinator = hass.data[DOMAIN].get(config_entry_id)
KeyError: 'forecast_solar'
2021-09-12 17:12:28 ERROR (stream_worker) [libav.rtsp] method DESCRIBE failed: 404 Not Found
2021-09-12 17:12:28 ERROR (stream_worker) [homeassistant.components.stream.worker] Error opening stream rtsps://stream-uc2-bravo.dropcam.com:443/sdm_live_stream/CiQA2vuxr1SLu8rlYbOHo16R-04X0NNEKfeupmXLad7ICSMu8s8ScQAFjsOTS4_b71We2VG7vYgLakwq7JUxt6NJI0n_4qGM-a8nYLnRqRt-bpKX5HVk56GBFLsegX_YCrq7qGjicjVDCJLw6ikxOmGMNn5FOIzSK0Ae_WFyJ5hjvdjABw-qslkW0czaUaWbWG6Bc1HqAVEU?auth=g.0.eyJraWQiOiIyMzhiNTUxZmMyM2EyM2Y4M2E2ZTE3MmJjZTg0YmU3ZjgxMzAzMmM4IiwiYWxnIjoiUlMyNTYifQ.eyJpc3MiOiJuZXN0LXNlY3VyaXR5LWF1dGhwcm94eSIsInN1YiI6Im5lc3RfaWQ6bmVzdC1waG9lbml4LXByb2Q6MjEyMTgxNDEiLCJwb2wiOiIzcC1vYXV0aC1zY29wZS1BUElfU0RNX1NFUlZJQ0UtY2xpZW50LTIwMjQyNzMxODczNS1qNXQ5bWMyMzZqaG85YXMycWY0dTZxY3NmYW1kaGJ0ci5hcHBzLmdvb2dsZXVzZXJjb250ZW50LmNvbSIsImV4cCI6MTYzMTQ5MjIyNn0.qAuCqWKqJlipFjJz_CoWqRQP99nsCixi5JKWcoeoUqkI8zH-MOTf6DzytHTpUXeW69yjqpOkt_4HoMi-VtSwaN84Tjzy-FFVMRcV43i9ilkuwKWrvtTJIpNJivw4m9E6m_rlrToSAjvsO7D_f3qS4D_PKuW_Wr6-cZd67U-g3yd_m0a0rJJOAPtmMZ8r_Sorw1_ZswNOFQnDeCzbbExz302oBCNhUlfpChzSwSgvW_Ric8YwLHh5MRUTZGtbCdoD2KPn91MezQOXx2mLMpKw0JYCOomjRrrBsiamNX5TEXoWAqPHC8Aqi9n-Yy7X9ydFBAfgJ0wR_lYsIudF2Oqt2A
2021-09-12 17:12:49 ERROR (stream_worker) [libav.rtsp] method DESCRIBE failed: 404 Not Found
2021-09-12 17:12:49 ERROR (stream_worker) [homeassistant.components.stream.worker] Error opening stream rtsps://stream-uc2-delta.dropcam.com:443/sdm_live_stream/CiQA2vuxr70CRx2gK8IRmLITNFF032c4dkVUVFEPjSiot_nPtdkScQAFjsOTeLoFyxqJAyv7itMSpamqPm-sOSWbJVUkhKBpkVf4At5KSgRU8_keohbk6Jv-nN1YcRTUbAE8QIYS29993MKo34mCnPbDtaeqsMOxElEcJuWTAQlGp9HPqHLiZJ5JwthadbQD0aS-ZW5Ae7Gv?auth=g.0.eyJraWQiOiIyMzhiNTUxZmMyM2EyM2Y4M2E2ZTE3MmJjZTg0YmU3ZjgxMzAzMmM4IiwiYWxnIjoiUlMyNTYifQ.eyJpc3MiOiJuZXN0LXNlY3VyaXR5LWF1dGhwcm94eSIsInN1YiI6Im5lc3RfaWQ6bmVzdC1waG9lbml4LXByb2Q6MjEyMTgxNDEiLCJwb2wiOiIzcC1vYXV0aC1zY29wZS1BUElfU0RNX1NFUlZJQ0UtY2xpZW50LTIwMjQyNzMxODczNS1qNXQ5bWMyMzZqaG85YXMycWY0dTZxY3NmYW1kaGJ0ci5hcHBzLmdvb2dsZXVzZXJjb250ZW50LmNvbSIsImV4cCI6MTYzMTQ5MjIyN30.cxvbh5QOy3lzXjmCTLEdgzk39Sfbg6e_p7ZKLKraY0kjUH8R5COiafMV0CwiKLequIuR-00YFPIL-ZXYZ4bMrJeuBxFukuxgZn1P8jq550SBfH-55-UlTdf5ocKOP4_aVoFHLTRFVCcefsWHHUUr9XVyFmhBKFqGX2EgFCPi0xBkllLRJMuMHb1buccnywZ0ybBMGkVne14Jh6tWe7xTjsJesQAhTc2H65ztML9SJ0oefbyIRPzUVE0bpQO-x4rhohVjT50rSnpz_vENNx4t8GUroWADCjJelpvtne1xOQJGtOTi4YT8GOT5OeTKu-DIdbiruW4nSW3XlbXrr28iTQ
2021-09-12 17:15:26 ERROR (MainThread) [homeassistant] Error doing job: Future exception was never retrieved
Traceback (most recent call last):
  File "/usr/local/lib/python3.9/concurrent/futures/thread.py", line 52, in run
    result = self.fn(*self.args, **self.kwargs)
TypeError: update() takes 1 positional argument but 2 were given
2021-09-12 17:18:47 WARNING (MainThread) [bellows.zigbee.application] Watchdog heartbeat timeout: 
2021-09-12 17:19:02 WARNING (MainThread) [bellows.zigbee.application] Watchdog heartbeat timeout: 
2021-09-12 17:20:27 ERROR (MainThread) [homeassistant] Error doing job: Future exception was never retrieved
Traceback (most recent call last):
  File "/usr/local/lib/python3.9/concurrent/futures/thread.py", line 52, in run
    result = self.fn(*self.args, **self.kwargs)
TypeError: update() takes 1 positional argument but 2 were given
2021-09-12 17:25:28 ERROR (MainThread) [homeassistant] Error doing job: Future exception was never retrieved
Traceback (most recent call last):
  File "/usr/local/lib/python3.9/concurrent/futures/thread.py", line 52, in run
    result = self.fn(*self.args, **self.kwargs)
TypeError: update() takes 1 positional argument but 2 were given
2021-09-12 17:30:29 ERROR (MainThread) [homeassistant] Error doing job: Future exception was never retrieved
Traceback (most recent call last):
  File "/usr/local/lib/python3.9/concurrent/futures/thread.py", line 52, in run
    result = self.fn(*self.args, **self.kwargs)
TypeError: update() takes 1 positional argument but 2 were given
2021-09-12 17:35:30 ERROR (MainThread) [homeassistant] Error doing job: Future exception was never retrieved
Traceback (most recent call last):
  File "/usr/local/lib/python3.9/concurrent/futures/thread.py", line 52, in run
    result = self.fn(*self.args, **self.kwargs)
TypeError: update() takes 1 positional argument but 2 were given
2021-09-12 17:37:58 ERROR (MainThread) [iotawattpy.connection] Err: 
2021-09-12 17:37:58 ERROR (MainThread) [homeassistant.components.iotawatt.coordinator] Unexpected error fetching 192.168.20.195 data: 'NoneType' object has no attribute 'text'
Traceback (most recent call last):
  File "/usr/src/homeassistant/homeassistant/helpers/update_coordinator.py", line 187, in _async_refresh
    self.data = await self._async_update_data()
  File "/usr/src/homeassistant/homeassistant/components/iotawatt/coordinator.py", line 55, in _async_update_data
    await self.api.update()
  File "/usr/local/lib/python3.9/site-packages/iotawattpy/iotawatt.py", line 66, in update
    await self._refreshSensors(timespan)
  File "/usr/local/lib/python3.9/site-packages/iotawattpy/iotawatt.py", line 100, in _refreshSensors
    results = response.text
AttributeError: 'NoneType' object has no attribute 'text'
2021-09-12 17:40:31 ERROR (MainThread) [homeassistant] Error doing job: Future exception was never retrieved
Traceback (most recent call last):
  File "/usr/local/lib/python3.9/concurrent/futures/thread.py", line 52, in run
    result = self.fn(*self.args, **self.kwargs)
TypeError: update() takes 1 positional argument but 2 were given
2021-09-12 17:45:32 ERROR (MainThread) [homeassistant] Error doing job: Future exception was never retrieved
Traceback (most recent call last):
  File "/usr/local/lib/python3.9/concurrent/futures/thread.py", line 52, in run
    result = self.fn(*self.args, **self.kwargs)
TypeError: update() takes 1 positional argument but 2 were given
2021-09-12 17:50:33 ERROR (MainThread) [homeassistant] Error doing job: Future exception was never retrieved
Traceback (most recent call last):
  File "/usr/local/lib/python3.9/concurrent/futures/thread.py", line 52, in run
    result = self.fn(*self.args, **self.kwargs)
TypeError: update() takes 1 positional argument but 2 were given
2021-09-12 17:53:34 ERROR (stream_worker) [libav.rtsp] method DESCRIBE failed: 404 Not Found
2021-09-12 17:53:34 ERROR (stream_worker) [homeassistant.components.stream.worker] Error opening stream rtsps://stream-uc2-delta.dropcam.com:443/sdm_live_stream/CiQA2vuxr70CRx2gK8IRmLITNFF032c4dkVUVFEPjSiot_nPtdkScQAFjsOTeLoFyxqJAyv7itMSpamqPm-sOSWbJVUkhKBpkVf4At5KSgRU8_keohbk6Jv-nN1YcRTUbAE8QIYS29993MKo34mCnPbDtaeqsMOxElEcJuWTAQlGp9HPqHLiZJ5JwthadbQD0aS-ZW5Ae7Gv?auth=g.0.eyJraWQiOiIyMzhiNTUxZmMyM2EyM2Y4M2E2ZTE3MmJjZTg0YmU3ZjgxMzAzMmM4IiwiYWxnIjoiUlMyNTYifQ.eyJpc3MiOiJuZXN0LXNlY3VyaXR5LWF1dGhwcm94eSIsInN1YiI6Im5lc3RfaWQ6bmVzdC1waG9lbml4LXByb2Q6MjEyMTgxNDEiLCJwb2wiOiIzcC1vYXV0aC1zY29wZS1BUElfU0RNX1NFUlZJQ0UtY2xpZW50LTIwMjQyNzMxODczNS1qNXQ5bWMyMzZqaG85YXMycWY0dTZxY3NmYW1kaGJ0ci5hcHBzLmdvb2dsZXVzZXJjb250ZW50LmNvbSIsImV4cCI6MTYzMTQ5NDY2MX0.J1VNin8C6PpeD1f1h2Uy9vg97NpF31rmJOTH5xWFiqwr00eK8Uaia4ADI6kiBYBBnP8oTzt_9V59ri2fbGBqKuo2QZFORHCXqOCbWSkP3wM3wHsVJH9mg3JvmwGoi3vAOJk3Lri_CJ6KO9QIqbtvlECOxbjzJPmsenTZhbAal5EOwL-NYVAnz5wfRZdak-ZyEScoTDZqzi2AnJuZVhpgVxE2wIJGIxZ3_z-gdvuQAT0lP_uTEItWk_JNsb0XgHvveJYPcSt-kyfYGw2C9xe4TCqtBS5Ml4tckvXwbRj5iPK3v520ElEvoqz5kJKznWINvyM-RQPihFAYnXzg1D6PCw
2021-09-12 17:55:34 ERROR (MainThread) [homeassistant] Error doing job: Future exception was never retrieved
Traceback (most recent call last):
  File "/usr/local/lib/python3.9/concurrent/futures/thread.py", line 52, in run
    result = self.fn(*self.args, **self.kwargs)
TypeError: update() takes 1 positional argument but 2 were given
2021-09-12 17:56:14 ERROR (MainThread) [homeassistant.components.nws] Error requesting NWS observation station SAUC1 data: 503, message='Service Unavailable', url=URL('https://api.weather.gov/stations/SAUC1/observations')
2021-09-12 17:57:43 ERROR (stream_worker) [libav.rtsp] method DESCRIBE failed: 404 Not Found
2021-09-12 17:57:43 ERROR (stream_worker) [homeassistant.components.stream.worker] Error opening stream rtsps://stream-uc2-bravo.dropcam.com:443/sdm_live_stream/CiQA2vuxr1SLu8rlYbOHo16R-04X0NNEKfeupmXLad7ICSMu8s8ScQAFjsOTS4_b71We2VG7vYgLakwq7JUxt6NJI0n_4qGM-a8nYLnRqRt-bpKX5HVk56GBFLsegX_YCrq7qGjicjVDCJLw6ikxOmGMNn5FOIzSK0Ae_WFyJ5hjvdjABw-qslkW0czaUaWbWG6Bc1HqAVEU?auth=g.0.eyJraWQiOiIyMzhiNTUxZmMyM2EyM2Y4M2E2ZTE3MmJjZTg0YmU3ZjgxMzAzMmM4IiwiYWxnIjoiUlMyNTYifQ.eyJpc3MiOiJuZXN0LXNlY3VyaXR5LWF1dGhwcm94eSIsInN1YiI6Im5lc3RfaWQ6bmVzdC1waG9lbml4LXByb2Q6MjEyMTgxNDEiLCJwb2wiOiIzcC1vYXV0aC1zY29wZS1BUElfU0RNX1NFUlZJQ0UtY2xpZW50LTIwMjQyNzMxODczNS1qNXQ5bWMyMzZqaG85YXMycWY0dTZxY3NmYW1kaGJ0ci5hcHBzLmdvb2dsZXVzZXJjb250ZW50LmNvbSIsImV4cCI6MTYzMTQ5NDkzMn0.T5_4aOzXTP0ybfBRdUwZi65RLMUmAY3WkHtoqQVspByu8nhnMlhRA8XxMAbii7AZ1YYuDCHl2kjGdtZCzv9wWpITYSe9xP5cQHdUyN2Q-ggG8D7g7uVOC9ecei1lEv-hxmUB3Y4SVZyiTmuna2uFQ1S5PmN0GuIqwJMhv9o1aP5yZgCHrSnJJcoxifHdTbzVn0tgB6wY1-AwvqUv0m4JRovS7qB--ZAg1vtKPclEkwgsnr0BhGfx41ATHTdIvQ7kFKLDnaw4MoUAXhfpUGUptco3S8I2M-FJgXYuZMy2xMr5U1SXpEGqG8R8NTlWSHoy91spNXWESUmtba6g8sS_Bg
2021-09-12 18:00:35 ERROR (MainThread) [homeassistant] Error doing job: Future exception was never retrieved
Traceback (most recent call last):
  File "/usr/local/lib/python3.9/concurrent/futures/thread.py", line 52, in run
    result = self.fn(*self.args, **self.kwargs)
TypeError: update() takes 1 positional argument but 2 were given
2021-09-12 18:05:36 ERROR (MainThread) [homeassistant] Error doing job: Future exception was never retrieved
Traceback (most recent call last):
  File "/usr/local/lib/python3.9/concurrent/futures/thread.py", line 52, in run
    result = self.fn(*self.args, **self.kwargs)
TypeError: update() takes 1 positional argument but 2 were given
2021-09-12 18:10:37 ERROR (MainThread) [homeassistant] Error doing job: Future exception was never retrieved
Traceback (most recent call last):
  File "/usr/local/lib/python3.9/concurrent/futures/thread.py", line 52, in run
    result = self.fn(*self.args, **self.kwargs)
TypeError: update() takes 1 positional argument but 2 were given
2021-09-12 18:15:38 ERROR (MainThread) [homeassistant] Error doing job: Future exception was never retrieved
Traceback (most recent call last):
  File "/usr/local/lib/python3.9/concurrent/futures/thread.py", line 52, in run
    result = self.fn(*self.args, **self.kwargs)
TypeError: update() takes 1 positional argument but 2 were given
2021-09-12 18:15:55 ERROR (stream_worker) [libav.rtsp] method DESCRIBE failed: 404 Not Found
2021-09-12 18:15:55 ERROR (stream_worker) [homeassistant.components.stream.worker] Error opening stream rtsps://stream-uc2-bravo.dropcam.com:443/sdm_live_stream/CiQA2vuxr1SLu8rlYbOHo16R-04X0NNEKfeupmXLad7ICSMu8s8ScQAFjsOTS4_b71We2VG7vYgLakwq7JUxt6NJI0n_4qGM-a8nYLnRqRt-bpKX5HVk56GBFLsegX_YCrq7qGjicjVDCJLw6ikxOmGMNn5FOIzSK0Ae_WFyJ5hjvdjABw-qslkW0czaUaWbWG6Bc1HqAVEU?auth=g.0.eyJraWQiOiIyMzhiNTUxZmMyM2EyM2Y4M2E2ZTE3MmJjZTg0YmU3ZjgxMzAzMmM4IiwiYWxnIjoiUlMyNTYifQ.eyJpc3MiOiJuZXN0LXNlY3VyaXR5LWF1dGhwcm94eSIsInN1YiI6Im5lc3RfaWQ6bmVzdC1waG9lbml4LXByb2Q6MjEyMTgxNDEiLCJwb2wiOiIzcC1vYXV0aC1zY29wZS1BUElfU0RNX1NFUlZJQ0UtY2xpZW50LTIwMjQyNzMxODczNS1qNXQ5bWMyMzZqaG85YXMycWY0dTZxY3NmYW1kaGJ0ci5hcHBzLmdvb2dsZXVzZXJjb250ZW50LmNvbSIsImV4cCI6MTYzMTQ5NjAxNH0.Ol5cAmA8AAwHifzq8pxl_L3eOrG7ppxalouTUJMKiv0tRzHO2CZn4EhOd32ngvOPeGbgkqB6-LgzKxb_u3xmEU4yU1UJyLIDTOlV-SvZg8ljk9aEwamfeCDGQo_tdHqpkWx6_GZpR4VKPfC5hvAncsoP5EO33xSPpgG6xzZd2o0qg5bVeFfKGdlSGdgnp-w7EIqXTQ7is_N7eHu8fhRHbO04eeZYh4BT7Z8Z3CNS9ibsRK1uriuZJFc6QBZA8gQu6QwfsduFOvUOdTqPV19zbEocBp5WBLJQZJ8FHLLm0h0H-O6WJw3u8xVhAwNwlwIU-W2WzHCpk8OxWfqu4yKwRQ
2021-09-12 18:20:39 ERROR (MainThread) [homeassistant] Error doing job: Future exception was never retrieved
Traceback (most recent call last):
  File "/usr/local/lib/python3.9/concurrent/futures/thread.py", line 52, in run
    result = self.fn(*self.args, **self.kwargs)
TypeError: update() takes 1 positional argument but 2 were given
2021-09-12 18:25:40 ERROR (MainThread) [homeassistant] Error doing job: Future exception was never retrieved
Traceback (most recent call last):
  File "/usr/local/lib/python3.9/concurrent/futures/thread.py", line 52, in run
    result = self.fn(*self.args, **self.kwargs)
TypeError: update() takes 1 positional argument but 2 were given
2021-09-12 18:28:58 ERROR (MainThread) [homeassistant.components.websocket_api.http.connection] [23232373330032] Error handling message: Unknown error
Traceback (most recent call last):
  File "/usr/src/homeassistant/homeassistant/components/websocket_api/decorators.py", line 25, in _handle_async_response
    await func(hass, connection, msg)
  File "/usr/src/homeassistant/homeassistant/components/energy/websocket_api.py", line 85, in with_manager
    await result
  File "/usr/src/homeassistant/homeassistant/components/energy/websocket_api.py", line 215, in ws_solar_forecast
    forecast = await forecast_platforms[config_entry.domain](hass, config_entry_id)
  File "/usr/src/homeassistant/homeassistant/components/forecast_solar/energy.py", line 13, in async_get_solar_forecast
    coordinator = hass.data[DOMAIN].get(config_entry_id)
KeyError: 'forecast_solar'
2021-09-12 18:28:58 ERROR (MainThread) [homeassistant.components.websocket_api.http.connection] [23232373330032] Error handling message: Unknown error
Traceback (most recent call last):
  File "/usr/src/homeassistant/homeassistant/components/websocket_api/decorators.py", line 25, in _handle_async_response
    await func(hass, connection, msg)
  File "/usr/src/homeassistant/homeassistant/components/energy/websocket_api.py", line 85, in with_manager
    await result
  File "/usr/src/homeassistant/homeassistant/components/energy/websocket_api.py", line 215, in ws_solar_forecast
    forecast = await forecast_platforms[config_entry.domain](hass, config_entry_id)
  File "/usr/src/homeassistant/homeassistant/components/forecast_solar/energy.py", line 13, in async_get_solar_forecast
    coordinator = hass.data[DOMAIN].get(config_entry_id)
KeyError: 'forecast_solar'
2021-09-12 18:28:58 ERROR (MainThread) [homeassistant.components.websocket_api.http.connection] [23232373330032] Error handling message: Unknown error
Traceback (most recent call last):
  File "/usr/src/homeassistant/homeassistant/components/websocket_api/decorators.py", line 25, in _handle_async_response
    await func(hass, connection, msg)
  File "/usr/src/homeassistant/homeassistant/components/energy/websocket_api.py", line 85, in with_manager
    await result
  File "/usr/src/homeassistant/homeassistant/components/energy/websocket_api.py", line 215, in ws_solar_forecast
    forecast = await forecast_platforms[config_entry.domain](hass, config_entry_id)
  File "/usr/src/homeassistant/homeassistant/components/forecast_solar/energy.py", line 13, in async_get_solar_forecast
    coordinator = hass.data[DOMAIN].get(config_entry_id)
KeyError: 'forecast_solar'
2021-09-12 18:28:58 ERROR (MainThread) [homeassistant.components.websocket_api.http.connection] [23232373330032] Error handling message: Unknown error
Traceback (most recent call last):
  File "/usr/src/homeassistant/homeassistant/components/websocket_api/decorators.py", line 25, in _handle_async_response
    await func(hass, connection, msg)
  File "/usr/src/homeassistant/homeassistant/components/energy/websocket_api.py", line 85, in with_manager
    await result
  File "/usr/src/homeassistant/homeassistant/components/energy/websocket_api.py", line 215, in ws_solar_forecast
    forecast = await forecast_platforms[config_entry.domain](hass, config_entry_id)
  File "/usr/src/homeassistant/homeassistant/components/forecast_solar/energy.py", line 13, in async_get_solar_forecast
    coordinator = hass.data[DOMAIN].get(config_entry_id)
KeyError: 'forecast_solar'
2021-09-12 18:28:58 ERROR (MainThread) [homeassistant.components.websocket_api.http.connection] [23232373330032] Error handling message: Unknown error
Traceback (most recent call last):
  File "/usr/src/homeassistant/homeassistant/components/websocket_api/decorators.py", line 25, in _handle_async_response
    await func(hass, connection, msg)
  File "/usr/src/homeassistant/homeassistant/components/energy/websocket_api.py", line 85, in with_manager
    await result
  File "/usr/src/homeassistant/homeassistant/components/energy/websocket_api.py", line 215, in ws_solar_forecast
    forecast = await forecast_platforms[config_entry.domain](hass, config_entry_id)
  File "/usr/src/homeassistant/homeassistant/components/forecast_solar/energy.py", line 13, in async_get_solar_forecast
    coordinator = hass.data[DOMAIN].get(config_entry_id)
KeyError: 'forecast_solar'
2021-09-12 18:28:58 ERROR (MainThread) [homeassistant.components.websocket_api.http.connection] [23232373330032] Error handling message: Unknown error
Traceback (most recent call last):
  File "/usr/src/homeassistant/homeassistant/components/websocket_api/decorators.py", line 25, in _handle_async_response
    await func(hass, connection, msg)
  File "/usr/src/homeassistant/homeassistant/components/energy/websocket_api.py", line 85, in with_manager
    await result
  File "/usr/src/homeassistant/homeassistant/components/energy/websocket_api.py", line 215, in ws_solar_forecast
    forecast = await forecast_platforms[config_entry.domain](hass, config_entry_id)
  File "/usr/src/homeassistant/homeassistant/components/forecast_solar/energy.py", line 13, in async_get_solar_forecast
    coordinator = hass.data[DOMAIN].get(config_entry_id)
KeyError: 'forecast_solar'
2021-09-12 18:28:58 ERROR (MainThread) [homeassistant.components.websocket_api.http.connection] [23232373330032] Error handling message: Unknown error
Traceback (most recent call last):
  File "/usr/src/homeassistant/homeassistant/components/websocket_api/decorators.py", line 25, in _handle_async_response
    await func(hass, connection, msg)
  File "/usr/src/homeassistant/homeassistant/components/energy/websocket_api.py", line 85, in with_manager
    await result
  File "/usr/src/homeassistant/homeassistant/components/energy/websocket_api.py", line 215, in ws_solar_forecast
    forecast = await forecast_platforms[config_entry.domain](hass, config_entry_id)
  File "/usr/src/homeassistant/homeassistant/components/forecast_solar/energy.py", line 13, in async_get_solar_forecast
    coordinator = hass.data[DOMAIN].get(config_entry_id)
KeyError: 'forecast_solar'
2021-09-12 18:29:15 WARNING (MainThread) [homeassistant.helpers.service] Unable to find referenced entities light.hue_lightstrip_2
2021-09-12 18:29:17 WARNING (MainThread) [homeassistant.helpers.service] Unable to find referenced entities light.hue_lightstrip_2
2021-09-12 18:30:41 ERROR (MainThread) [homeassistant] Error doing job: Future exception was never retrieved
Traceback (most recent call last):
  File "/usr/local/lib/python3.9/concurrent/futures/thread.py", line 52, in run
    result = self.fn(*self.args, **self.kwargs)
TypeError: update() takes 1 positional argument but 2 were given
2021-09-12 18:35:42 ERROR (MainThread) [homeassistant] Error doing job: Future exception was never retrieved
Traceback (most recent call last):
  File "/usr/local/lib/python3.9/concurrent/futures/thread.py", line 52, in run
    result = self.fn(*self.args, **self.kwargs)
TypeError: update() takes 1 positional argument but 2 were given
2021-09-12 18:37:24 ERROR (MainThread) [homeassistant.components.nws] Error requesting NWS observation station SAUC1 data: 503, message='Service Unavailable', url=URL('https://api.weather.gov/stations/SAUC1/observations')
2021-09-12 18:40:43 ERROR (MainThread) [homeassistant] Error doing job: Future exception was never retrieved
Traceback (most recent call last):
  File "/usr/local/lib/python3.9/concurrent/futures/thread.py", line 52, in run
    result = self.fn(*self.args, **self.kwargs)
TypeError: update() takes 1 positional argument but 2 were given
2021-09-12 18:43:09 ERROR (stream_worker) [libav.rtsp] method DESCRIBE failed: 404 Not Found
2021-09-12 18:43:09 ERROR (stream_worker) [homeassistant.components.stream.worker] Error opening stream rtsps://stream-uc2-bravo.dropcam.com:443/sdm_live_stream/CiQA2vuxr1SLu8rlYbOHo16R-04X0NNEKfeupmXLad7ICSMu8s8ScQAFjsOTS4_b71We2VG7vYgLakwq7JUxt6NJI0n_4qGM-a8nYLnRqRt-bpKX5HVk56GBFLsegX_YCrq7qGjicjVDCJLw6ikxOmGMNn5FOIzSK0Ae_WFyJ5hjvdjABw-qslkW0czaUaWbWG6Bc1HqAVEU?auth=g.0.eyJraWQiOiIyMzhiNTUxZmMyM2EyM2Y4M2E2ZTE3MmJjZTg0YmU3ZjgxMzAzMmM4IiwiYWxnIjoiUlMyNTYifQ.eyJpc3MiOiJuZXN0LXNlY3VyaXR5LWF1dGhwcm94eSIsInN1YiI6Im5lc3RfaWQ6bmVzdC1waG9lbml4LXByb2Q6MjEyMTgxNDEiLCJwb2wiOiIzcC1vYXV0aC1zY29wZS1BUElfU0RNX1NFUlZJQ0UtY2xpZW50LTIwMjQyNzMxODczNS1qNXQ5bWMyMzZqaG85YXMycWY0dTZxY3NmYW1kaGJ0ci5hcHBzLmdvb2dsZXVzZXJjb250ZW50LmNvbSIsImV4cCI6MTYzMTQ5NzYzOH0.SNen_CqPkzT2_le-884wNj4QFCq5NhJIUUgXeAL2B3B1leHueWjcKLSLw2p3oifE-cncgDd7SqlyQQxc8HCxkDiuxRmHkvIATgpbbd_Ka4P4IuiaebD7oG1nv8wBaV-u5FQAqg5ar1S9P3AD0yYoN6vPdCMmc_7L3jBRPeHvvWWOSK7xgwLtrXdqxp8mMdH7ANPhuO9eeoj6n0utlWPVyjJz6EQIRWgLFVGf34CzIg8UpsGYNm8WT-BG0vBOUGrepQbMEJHx0Dq4f2E_Xy26X96-dmGuNf2ZN7NnuFO7mtoIUb3xH8WuDpk_0ZTuv90vmKhrJwQUM6LPCxntwtjxWQ
2021-09-12 18:43:23 ERROR (stream_worker) [libav.rtsp] method DESCRIBE failed: 404 Not Found
2021-09-12 18:43:23 ERROR (stream_worker) [homeassistant.components.stream.worker] Error opening stream rtsps://stream-uc2-delta.dropcam.com:443/sdm_live_stream/CiQA2vuxr70CRx2gK8IRmLITNFF032c4dkVUVFEPjSiot_nPtdkScQAFjsOTeLoFyxqJAyv7itMSpamqPm-sOSWbJVUkhKBpkVf4At5KSgRU8_keohbk6Jv-nN1YcRTUbAE8QIYS29993MKo34mCnPbDtaeqsMOxElEcJuWTAQlGp9HPqHLiZJ5JwthadbQD0aS-ZW5Ae7Gv?auth=g.0.eyJraWQiOiIyMzhiNTUxZmMyM2EyM2Y4M2E2ZTE3MmJjZTg0YmU3ZjgxMzAzMmM4IiwiYWxnIjoiUlMyNTYifQ.eyJpc3MiOiJuZXN0LXNlY3VyaXR5LWF1dGhwcm94eSIsInN1YiI6Im5lc3RfaWQ6bmVzdC1waG9lbml4LXByb2Q6MjEyMTgxNDEiLCJwb2wiOiIzcC1vYXV0aC1zY29wZS1BUElfU0RNX1NFUlZJQ0UtY2xpZW50LTIwMjQyNzMxODczNS1qNXQ5bWMyMzZqaG85YXMycWY0dTZxY3NmYW1kaGJ0ci5hcHBzLmdvb2dsZXVzZXJjb250ZW50LmNvbSIsImV4cCI6MTYzMTQ5NzYzOX0.SVPUk6QT-SB7nkn9RSLrmxQsV4g90sCruVEo-M3knHkYNCKh53yi9Z2m6b2cqqFUsWQcWs7R84L7M-6apqceX9zr8RLyE91ANgJ6Peb5_yb84RniijqmBHbxTKk7P-AHegAcF8lBY1r2FAcDx73VHDNm2wx972RT7tygCmkK3K84eQnDQLMzQ38CYzyb1--AVX4zZy5hIp42sIlPNtoZL7dM-yYaON3_l-D69tC7XaG_0zF9FwPaoHu-7G5ay8NzmZkXgMoHNqwIssqexzhpFOw6sLxcMunMT93b8WNb-FGkgwVEE7bWYKeqHtVqXmQX9E6_2oI7xbIqOw_VjFUilA
2021-09-12 18:45:44 ERROR (MainThread) [homeassistant] Error doing job: Future exception was never retrieved
Traceback (most recent call last):
  File "/usr/local/lib/python3.9/concurrent/futures/thread.py", line 52, in run
    result = self.fn(*self.args, **self.kwargs)
TypeError: update() takes 1 positional argument but 2 were given
2021-09-12 18:47:48 ERROR (MainThread) [homeassistant.components.websocket_api.http.connection] [23232364199744] Error handling message: Unknown error
Traceback (most recent call last):
  File "/usr/src/homeassistant/homeassistant/components/websocket_api/decorators.py", line 25, in _handle_async_response
    await func(hass, connection, msg)
  File "/usr/src/homeassistant/homeassistant/components/energy/websocket_api.py", line 85, in with_manager
    await result
  File "/usr/src/homeassistant/homeassistant/components/energy/websocket_api.py", line 215, in ws_solar_forecast
    forecast = await forecast_platforms[config_entry.domain](hass, config_entry_id)
  File "/usr/src/homeassistant/homeassistant/components/forecast_solar/energy.py", line 13, in async_get_solar_forecast
    coordinator = hass.data[DOMAIN].get(config_entry_id)
KeyError: 'forecast_solar'
2021-09-12 18:47:48 ERROR (MainThread) [homeassistant.components.websocket_api.http.connection] [23232364199744] Error handling message: Unknown error
Traceback (most recent call last):
  File "/usr/src/homeassistant/homeassistant/components/websocket_api/decorators.py", line 25, in _handle_async_response
    await func(hass, connection, msg)
  File "/usr/src/homeassistant/homeassistant/components/energy/websocket_api.py", line 85, in with_manager
    await result
  File "/usr/src/homeassistant/homeassistant/components/energy/websocket_api.py", line 215, in ws_solar_forecast
    forecast = await forecast_platforms[config_entry.domain](hass, config_entry_id)
  File "/usr/src/homeassistant/homeassistant/components/forecast_solar/energy.py", line 13, in async_get_solar_forecast
    coordinator = hass.data[DOMAIN].get(config_entry_id)
KeyError: 'forecast_solar'
2021-09-12 18:50:45 ERROR (MainThread) [homeassistant] Error doing job: Future exception was never retrieved
Traceback (most recent call last):
  File "/usr/local/lib/python3.9/concurrent/futures/thread.py", line 52, in run
    result = self.fn(*self.args, **self.kwargs)
TypeError: update() takes 1 positional argument but 2 were given
2021-09-12 18:55:46 ERROR (MainThread) [homeassistant] Error doing job: Future exception was never retrieved
Traceback (most recent call last):
  File "/usr/local/lib/python3.9/concurrent/futures/thread.py", line 52, in run
    result = self.fn(*self.args, **self.kwargs)
TypeError: update() takes 1 positional argument but 2 were given
2021-09-12 18:56:48 WARNING (MainThread) [homeassistant.helpers.service] Unable to find referenced entities light.hue_lightstrip_2
2021-09-12 19:00:47 ERROR (MainThread) [homeassistant] Error doing job: Future exception was never retrieved
Traceback (most recent call last):
  File "/usr/local/lib/python3.9/concurrent/futures/thread.py", line 52, in run
    result = self.fn(*self.args, **self.kwargs)
TypeError: update() takes 1 positional argument but 2 were given
2021-09-12 19:02:12 ERROR (stream_worker) [libav.tls] The specified session has been invalidated for some reason.
2021-09-12 19:02:12 ERROR (stream_worker) [homeassistant.components.stream.worker] Error demuxing stream: 
2021-09-12 19:02:12 ERROR (stream_worker) [libav.tls] The specified session has been invalidated for some reason.
2021-09-12 19:02:33 ERROR (stream_worker) [libav.rtsp] method DESCRIBE failed: 404 Not Found
2021-09-12 19:02:33 ERROR (stream_worker) [homeassistant.components.stream.worker] Error opening stream rtsps://stream-uc2-bravo.dropcam.com:443/sdm_live_stream/CiQA2vuxr1SLu8rlYbOHo16R-04X0NNEKfeupmXLad7ICSMu8s8ScQAFjsOTS4_b71We2VG7vYgLakwq7JUxt6NJI0n_4qGM-a8nYLnRqRt-bpKX5HVk56GBFLsegX_YCrq7qGjicjVDCJLw6ikxOmGMNn5FOIzSK0Ae_WFyJ5hjvdjABw-qslkW0czaUaWbWG6Bc1HqAVEU?auth=g.0.eyJraWQiOiIyMzhiNTUxZmMyM2EyM2Y4M2E2ZTE3MmJjZTg0YmU3ZjgxMzAzMmM4IiwiYWxnIjoiUlMyNTYifQ.eyJpc3MiOiJuZXN0LXNlY3VyaXR5LWF1dGhwcm94eSIsInN1YiI6Im5lc3RfaWQ6bmVzdC1waG9lbml4LXByb2Q6MjEyMTgxNDEiLCJwb2wiOiIzcC1vYXV0aC1zY29wZS1BUElfU0RNX1NFUlZJQ0UtY2xpZW50LTIwMjQyNzMxODczNS1qNXQ5bWMyMzZqaG85YXMycWY0dTZxY3NmYW1kaGJ0ci5hcHBzLmdvb2dsZXVzZXJjb250ZW50LmNvbSIsImV4cCI6MTYzMTQ5ODQ1MH0.tPMv-EG32_XlvIZmCpKyJ12Ozu8zGClYp1WbDrqpdtTyfhR2w_a410FySS2m5ontP4dOlEIuwobL-EtLmC7L-UTsMkZcLFI3pkEY9bzONK24CGe3KJSdpE9hCkdK9L2SM9cAQ87j4pRr9OF5LP7YiLbVPpjZTsW_7ou_Y1g-yu5GA7Fnn5ehSKR-Iwq-ykUciC1-YbZfrAl55FYoBbZRRBiQL8r0leC9RcSSaG73vmI7i-2uemhDzysQlPcXt0nNJ9rzgRpE63NxmMxF4hGNUGOT7BWwoXVVsUJpLHnU-wl5S-jXhZbfS3V3cP9akUTeQF_jgmlWDC06QhKSLnHOKA
2021-09-12 19:03:03 ERROR (stream_worker) [libav.rtsp] method DESCRIBE failed: 404 Not Found
2021-09-12 19:03:03 ERROR (stream_worker) [homeassistant.components.stream.worker] Error opening stream rtsps://stream-uc2-bravo.dropcam.com:443/sdm_live_stream/CiQA2vuxr1SLu8rlYbOHo16R-04X0NNEKfeupmXLad7ICSMu8s8ScQAFjsOTS4_b71We2VG7vYgLakwq7JUxt6NJI0n_4qGM-a8nYLnRqRt-bpKX5HVk56GBFLsegX_YCrq7qGjicjVDCJLw6ikxOmGMNn5FOIzSK0Ae_WFyJ5hjvdjABw-qslkW0czaUaWbWG6Bc1HqAVEU?auth=g.0.eyJraWQiOiIyMzhiNTUxZmMyM2EyM2Y4M2E2ZTE3MmJjZTg0YmU3ZjgxMzAzMmM4IiwiYWxnIjoiUlMyNTYifQ.eyJpc3MiOiJuZXN0LXNlY3VyaXR5LWF1dGhwcm94eSIsInN1YiI6Im5lc3RfaWQ6bmVzdC1waG9lbml4LXByb2Q6MjEyMTgxNDEiLCJwb2wiOiIzcC1vYXV0aC1zY29wZS1BUElfU0RNX1NFUlZJQ0UtY2xpZW50LTIwMjQyNzMxODczNS1qNXQ5bWMyMzZqaG85YXMycWY0dTZxY3NmYW1kaGJ0ci5hcHBzLmdvb2dsZXVzZXJjb250ZW50LmNvbSIsImV4cCI6MTYzMTQ5ODQ1MH0.tPMv-EG32_XlvIZmCpKyJ12Ozu8zGClYp1WbDrqpdtTyfhR2w_a410FySS2m5ontP4dOlEIuwobL-EtLmC7L-UTsMkZcLFI3pkEY9bzONK24CGe3KJSdpE9hCkdK9L2SM9cAQ87j4pRr9OF5LP7YiLbVPpjZTsW_7ou_Y1g-yu5GA7Fnn5ehSKR-Iwq-ykUciC1-YbZfrAl55FYoBbZRRBiQL8r0leC9RcSSaG73vmI7i-2uemhDzysQlPcXt0nNJ9rzgRpE63NxmMxF4hGNUGOT7BWwoXVVsUJpLHnU-wl5S-jXhZbfS3V3cP9akUTeQF_jgmlWDC06QhKSLnHOKA
2021-09-12 19:03:46 ERROR (stream_worker) [libav.rtsp] method DESCRIBE failed: 404 Not Found
2021-09-12 19:03:46 ERROR (stream_worker) [homeassistant.components.stream.worker] Error opening stream rtsps://stream-uc2-bravo.dropcam.com:443/sdm_live_stream/CiQA2vuxr1SLu8rlYbOHo16R-04X0NNEKfeupmXLad7ICSMu8s8ScQAFjsOTS4_b71We2VG7vYgLakwq7JUxt6NJI0n_4qGM-a8nYLnRqRt-bpKX5HVk56GBFLsegX_YCrq7qGjicjVDCJLw6ikxOmGMNn5FOIzSK0Ae_WFyJ5hjvdjABw-qslkW0czaUaWbWG6Bc1HqAVEU?auth=g.0.eyJraWQiOiIyMzhiNTUxZmMyM2EyM2Y4M2E2ZTE3MmJjZTg0YmU3ZjgxMzAzMmM4IiwiYWxnIjoiUlMyNTYifQ.eyJpc3MiOiJuZXN0LXNlY3VyaXR5LWF1dGhwcm94eSIsInN1YiI6Im5lc3RfaWQ6bmVzdC1waG9lbml4LXByb2Q6MjEyMTgxNDEiLCJwb2wiOiIzcC1vYXV0aC1zY29wZS1BUElfU0RNX1NFUlZJQ0UtY2xpZW50LTIwMjQyNzMxODczNS1qNXQ5bWMyMzZqaG85YXMycWY0dTZxY3NmYW1kaGJ0ci5hcHBzLmdvb2dsZXVzZXJjb250ZW50LmNvbSIsImV4cCI6MTYzMTQ5ODQ1MH0.tPMv-EG32_XlvIZmCpKyJ12Ozu8zGClYp1WbDrqpdtTyfhR2w_a410FySS2m5ontP4dOlEIuwobL-EtLmC7L-UTsMkZcLFI3pkEY9bzONK24CGe3KJSdpE9hCkdK9L2SM9cAQ87j4pRr9OF5LP7YiLbVPpjZTsW_7ou_Y1g-yu5GA7Fnn5ehSKR-Iwq-ykUciC1-YbZfrAl55FYoBbZRRBiQL8r0leC9RcSSaG73vmI7i-2uemhDzysQlPcXt0nNJ9rzgRpE63NxmMxF4hGNUGOT7BWwoXVVsUJpLHnU-wl5S-jXhZbfS3V3cP9akUTeQF_jgmlWDC06QhKSLnHOKA
2021-09-12 19:04:19 WARNING (MainThread) [homeassistant.helpers.service] Unable to find referenced entities scene.kitchen_sink_on
2021-09-12 19:04:23 WARNING (MainThread) [homeassistant.helpers.service] Unable to find referenced entities light.hue_lightstrip_2
2021-09-12 19:04:36 ERROR (stream_worker) [libav.rtsp] method DESCRIBE failed: 404 Not Found
2021-09-12 19:04:36 ERROR (stream_worker) [homeassistant.components.stream.worker] Error opening stream rtsps://stream-uc2-bravo.dropcam.com:443/sdm_live_stream/CiQA2vuxr1SLu8rlYbOHo16R-04X0NNEKfeupmXLad7ICSMu8s8ScQAFjsOTS4_b71We2VG7vYgLakwq7JUxt6NJI0n_4qGM-a8nYLnRqRt-bpKX5HVk56GBFLsegX_YCrq7qGjicjVDCJLw6ikxOmGMNn5FOIzSK0Ae_WFyJ5hjvdjABw-qslkW0czaUaWbWG6Bc1HqAVEU?auth=g.0.eyJraWQiOiIyMzhiNTUxZmMyM2EyM2Y4M2E2ZTE3MmJjZTg0YmU3ZjgxMzAzMmM4IiwiYWxnIjoiUlMyNTYifQ.eyJpc3MiOiJuZXN0LXNlY3VyaXR5LWF1dGhwcm94eSIsInN1YiI6Im5lc3RfaWQ6bmVzdC1waG9lbml4LXByb2Q6MjEyMTgxNDEiLCJwb2wiOiIzcC1vYXV0aC1zY29wZS1BUElfU0RNX1NFUlZJQ0UtY2xpZW50LTIwMjQyNzMxODczNS1qNXQ5bWMyMzZqaG85YXMycWY0dTZxY3NmYW1kaGJ0ci5hcHBzLmdvb2dsZXVzZXJjb250ZW50LmNvbSIsImV4cCI6MTYzMTQ5ODQ1MH0.tPMv-EG32_XlvIZmCpKyJ12Ozu8zGClYp1WbDrqpdtTyfhR2w_a410FySS2m5ontP4dOlEIuwobL-EtLmC7L-UTsMkZcLFI3pkEY9bzONK24CGe3KJSdpE9hCkdK9L2SM9cAQ87j4pRr9OF5LP7YiLbVPpjZTsW_7ou_Y1g-yu5GA7Fnn5ehSKR-Iwq-ykUciC1-YbZfrAl55FYoBbZRRBiQL8r0leC9RcSSaG73vmI7i-2uemhDzysQlPcXt0nNJ9rzgRpE63NxmMxF4hGNUGOT7BWwoXVVsUJpLHnU-wl5S-jXhZbfS3V3cP9akUTeQF_jgmlWDC06QhKSLnHOKA
2021-09-12 19:05:37 ERROR (stream_worker) [libav.rtsp] method DESCRIBE failed: 404 Not Found
2021-09-12 19:05:37 ERROR (stream_worker) [homeassistant.components.stream.worker] Error opening stream rtsps://stream-uc2-bravo.dropcam.com:443/sdm_live_stream/CiQA2vuxr1SLu8rlYbOHo16R-04X0NNEKfeupmXLad7ICSMu8s8ScQAFjsOTS4_b71We2VG7vYgLakwq7JUxt6NJI0n_4qGM-a8nYLnRqRt-bpKX5HVk56GBFLsegX_YCrq7qGjicjVDCJLw6ikxOmGMNn5FOIzSK0Ae_WFyJ5hjvdjABw-qslkW0czaUaWbWG6Bc1HqAVEU?auth=g.0.eyJraWQiOiIyMzhiNTUxZmMyM2EyM2Y4M2E2ZTE3MmJjZTg0YmU3ZjgxMzAzMmM4IiwiYWxnIjoiUlMyNTYifQ.eyJpc3MiOiJuZXN0LXNlY3VyaXR5LWF1dGhwcm94eSIsInN1YiI6Im5lc3RfaWQ6bmVzdC1waG9lbml4LXByb2Q6MjEyMTgxNDEiLCJwb2wiOiIzcC1vYXV0aC1zY29wZS1BUElfU0RNX1NFUlZJQ0UtY2xpZW50LTIwMjQyNzMxODczNS1qNXQ5bWMyMzZqaG85YXMycWY0dTZxY3NmYW1kaGJ0ci5hcHBzLmdvb2dsZXVzZXJjb250ZW50LmNvbSIsImV4cCI6MTYzMTQ5ODQ1MH0.tPMv-EG32_XlvIZmCpKyJ12Ozu8zGClYp1WbDrqpdtTyfhR2w_a410FySS2m5ontP4dOlEIuwobL-EtLmC7L-UTsMkZcLFI3pkEY9bzONK24CGe3KJSdpE9hCkdK9L2SM9cAQ87j4pRr9OF5LP7YiLbVPpjZTsW_7ou_Y1g-yu5GA7Fnn5ehSKR-Iwq-ykUciC1-YbZfrAl55FYoBbZRRBiQL8r0leC9RcSSaG73vmI7i-2uemhDzysQlPcXt0nNJ9rzgRpE63NxmMxF4hGNUGOT7BWwoXVVsUJpLHnU-wl5S-jXhZbfS3V3cP9akUTeQF_jgmlWDC06QhKSLnHOKA
2021-09-12 19:05:48 ERROR (MainThread) [homeassistant] Error doing job: Future exception was never retrieved
Traceback (most recent call last):
  File "/usr/local/lib/python3.9/concurrent/futures/thread.py", line 52, in run
    result = self.fn(*self.args, **self.kwargs)
TypeError: update() takes 1 positional argument but 2 were given
2021-09-12 19:06:48 ERROR (stream_worker) [libav.rtsp] method DESCRIBE failed: 404 Not Found
2021-09-12 19:06:48 ERROR (stream_worker) [homeassistant.components.stream.worker] Error opening stream rtsps://stream-uc2-bravo.dropcam.com:443/sdm_live_stream/CiQA2vuxr1SLu8rlYbOHo16R-04X0NNEKfeupmXLad7ICSMu8s8ScQAFjsOTS4_b71We2VG7vYgLakwq7JUxt6NJI0n_4qGM-a8nYLnRqRt-bpKX5HVk56GBFLsegX_YCrq7qGjicjVDCJLw6ikxOmGMNn5FOIzSK0Ae_WFyJ5hjvdjABw-qslkW0czaUaWbWG6Bc1HqAVEU?auth=g.0.eyJraWQiOiIyMzhiNTUxZmMyM2EyM2Y4M2E2ZTE3MmJjZTg0YmU3ZjgxMzAzMmM4IiwiYWxnIjoiUlMyNTYifQ.eyJpc3MiOiJuZXN0LXNlY3VyaXR5LWF1dGhwcm94eSIsInN1YiI6Im5lc3RfaWQ6bmVzdC1waG9lbml4LXByb2Q6MjEyMTgxNDEiLCJwb2wiOiIzcC1vYXV0aC1zY29wZS1BUElfU0RNX1NFUlZJQ0UtY2xpZW50LTIwMjQyNzMxODczNS1qNXQ5bWMyMzZqaG85YXMycWY0dTZxY3NmYW1kaGJ0ci5hcHBzLmdvb2dsZXVzZXJjb250ZW50LmNvbSIsImV4cCI6MTYzMTQ5ODQ1MH0.tPMv-EG32_XlvIZmCpKyJ12Ozu8zGClYp1WbDrqpdtTyfhR2w_a410FySS2m5ontP4dOlEIuwobL-EtLmC7L-UTsMkZcLFI3pkEY9bzONK24CGe3KJSdpE9hCkdK9L2SM9cAQ87j4pRr9OF5LP7YiLbVPpjZTsW_7ou_Y1g-yu5GA7Fnn5ehSKR-Iwq-ykUciC1-YbZfrAl55FYoBbZRRBiQL8r0leC9RcSSaG73vmI7i-2uemhDzysQlPcXt0nNJ9rzgRpE63NxmMxF4hGNUGOT7BWwoXVVsUJpLHnU-wl5S-jXhZbfS3V3cP9akUTeQF_jgmlWDC06QhKSLnHOKA
2021-09-12 19:08:08 ERROR (stream_worker) [libav.rtsp] method DESCRIBE failed: 404 Not Found
2021-09-12 19:08:08 ERROR (stream_worker) [homeassistant.components.stream.worker] Error opening stream rtsps://stream-uc2-bravo.dropcam.com:443/sdm_live_stream/CiQA2vuxr1SLu8rlYbOHo16R-04X0NNEKfeupmXLad7ICSMu8s8ScQAFjsOTS4_b71We2VG7vYgLakwq7JUxt6NJI0n_4qGM-a8nYLnRqRt-bpKX5HVk56GBFLsegX_YCrq7qGjicjVDCJLw6ikxOmGMNn5FOIzSK0Ae_WFyJ5hjvdjABw-qslkW0czaUaWbWG6Bc1HqAVEU?auth=g.0.eyJraWQiOiIyMzhiNTUxZmMyM2EyM2Y4M2E2ZTE3MmJjZTg0YmU3ZjgxMzAzMmM4IiwiYWxnIjoiUlMyNTYifQ.eyJpc3MiOiJuZXN0LXNlY3VyaXR5LWF1dGhwcm94eSIsInN1YiI6Im5lc3RfaWQ6bmVzdC1waG9lbml4LXByb2Q6MjEyMTgxNDEiLCJwb2wiOiIzcC1vYXV0aC1zY29wZS1BUElfU0RNX1NFUlZJQ0UtY2xpZW50LTIwMjQyNzMxODczNS1qNXQ5bWMyMzZqaG85YXMycWY0dTZxY3NmYW1kaGJ0ci5hcHBzLmdvb2dsZXVzZXJjb250ZW50LmNvbSIsImV4cCI6MTYzMTQ5ODQ1MH0.tPMv-EG32_XlvIZmCpKyJ12Ozu8zGClYp1WbDrqpdtTyfhR2w_a410FySS2m5ontP4dOlEIuwobL-EtLmC7L-UTsMkZcLFI3pkEY9bzONK24CGe3KJSdpE9hCkdK9L2SM9cAQ87j4pRr9OF5LP7YiLbVPpjZTsW_7ou_Y1g-yu5GA7Fnn5ehSKR-Iwq-ykUciC1-YbZfrAl55FYoBbZRRBiQL8r0leC9RcSSaG73vmI7i-2uemhDzysQlPcXt0nNJ9rzgRpE63NxmMxF4hGNUGOT7BWwoXVVsUJpLHnU-wl5S-jXhZbfS3V3cP9akUTeQF_jgmlWDC06QhKSLnHOKA
2021-09-12 19:09:39 ERROR (stream_worker) [libav.rtsp] method DESCRIBE failed: 404 Not Found
2021-09-12 19:09:39 ERROR (stream_worker) [homeassistant.components.stream.worker] Error opening stream rtsps://stream-uc2-bravo.dropcam.com:443/sdm_live_stream/CiQA2vuxr1SLu8rlYbOHo16R-04X0NNEKfeupmXLad7ICSMu8s8ScQAFjsOTS4_b71We2VG7vYgLakwq7JUxt6NJI0n_4qGM-a8nYLnRqRt-bpKX5HVk56GBFLsegX_YCrq7qGjicjVDCJLw6ikxOmGMNn5FOIzSK0Ae_WFyJ5hjvdjABw-qslkW0czaUaWbWG6Bc1HqAVEU?auth=g.0.eyJraWQiOiIyMzhiNTUxZmMyM2EyM2Y4M2E2ZTE3MmJjZTg0YmU3ZjgxMzAzMmM4IiwiYWxnIjoiUlMyNTYifQ.eyJpc3MiOiJuZXN0LXNlY3VyaXR5LWF1dGhwcm94eSIsInN1YiI6Im5lc3RfaWQ6bmVzdC1waG9lbml4LXByb2Q6MjEyMTgxNDEiLCJwb2wiOiIzcC1vYXV0aC1zY29wZS1BUElfU0RNX1NFUlZJQ0UtY2xpZW50LTIwMjQyNzMxODczNS1qNXQ5bWMyMzZqaG85YXMycWY0dTZxY3NmYW1kaGJ0ci5hcHBzLmdvb2dsZXVzZXJjb250ZW50LmNvbSIsImV4cCI6MTYzMTQ5ODQ1MH0.tPMv-EG32_XlvIZmCpKyJ12Ozu8zGClYp1WbDrqpdtTyfhR2w_a410FySS2m5ontP4dOlEIuwobL-EtLmC7L-UTsMkZcLFI3pkEY9bzONK24CGe3KJSdpE9hCkdK9L2SM9cAQ87j4pRr9OF5LP7YiLbVPpjZTsW_7ou_Y1g-yu5GA7Fnn5ehSKR-Iwq-ykUciC1-YbZfrAl55FYoBbZRRBiQL8r0leC9RcSSaG73vmI7i-2uemhDzysQlPcXt0nNJ9rzgRpE63NxmMxF4hGNUGOT7BWwoXVVsUJpLHnU-wl5S-jXhZbfS3V3cP9akUTeQF_jgmlWDC06QhKSLnHOKA
2021-09-12 19:10:49 ERROR (MainThread) [homeassistant] Error doing job: Future exception was never retrieved
Traceback (most recent call last):
  File "/usr/local/lib/python3.9/concurrent/futures/thread.py", line 52, in run
    result = self.fn(*self.args, **self.kwargs)
TypeError: update() takes 1 positional argument but 2 were given
2021-09-12 19:11:19 ERROR (stream_worker) [libav.rtsp] method DESCRIBE failed: 404 Not Found
2021-09-12 19:11:19 ERROR (stream_worker) [homeassistant.components.stream.worker] Error opening stream rtsps://stream-uc2-bravo.dropcam.com:443/sdm_live_stream/CiQA2vuxr1SLu8rlYbOHo16R-04X0NNEKfeupmXLad7ICSMu8s8ScQAFjsOTS4_b71We2VG7vYgLakwq7JUxt6NJI0n_4qGM-a8nYLnRqRt-bpKX5HVk56GBFLsegX_YCrq7qGjicjVDCJLw6ikxOmGMNn5FOIzSK0Ae_WFyJ5hjvdjABw-qslkW0czaUaWbWG6Bc1HqAVEU?auth=g.0.eyJraWQiOiIyMzhiNTUxZmMyM2EyM2Y4M2E2ZTE3MmJjZTg0YmU3ZjgxMzAzMmM4IiwiYWxnIjoiUlMyNTYifQ.eyJpc3MiOiJuZXN0LXNlY3VyaXR5LWF1dGhwcm94eSIsInN1YiI6Im5lc3RfaWQ6bmVzdC1waG9lbml4LXByb2Q6MjEyMTgxNDEiLCJwb2wiOiIzcC1vYXV0aC1zY29wZS1BUElfU0RNX1NFUlZJQ0UtY2xpZW50LTIwMjQyNzMxODczNS1qNXQ5bWMyMzZqaG85YXMycWY0dTZxY3NmYW1kaGJ0ci5hcHBzLmdvb2dsZXVzZXJjb250ZW50LmNvbSIsImV4cCI6MTYzMTQ5ODQ1MH0.tPMv-EG32_XlvIZmCpKyJ12Ozu8zGClYp1WbDrqpdtTyfhR2w_a410FySS2m5ontP4dOlEIuwobL-EtLmC7L-UTsMkZcLFI3pkEY9bzONK24CGe3KJSdpE9hCkdK9L2SM9cAQ87j4pRr9OF5LP7YiLbVPpjZTsW_7ou_Y1g-yu5GA7Fnn5ehSKR-Iwq-ykUciC1-YbZfrAl55FYoBbZRRBiQL8r0leC9RcSSaG73vmI7i-2uemhDzysQlPcXt0nNJ9rzgRpE63NxmMxF4hGNUGOT7BWwoXVVsUJpLHnU-wl5S-jXhZbfS3V3cP9akUTeQF_jgmlWDC06QhKSLnHOKA
2021-09-12 19:13:10 ERROR (stream_worker) [libav.rtsp] method DESCRIBE failed: 404 Not Found
2021-09-12 19:13:10 ERROR (stream_worker) [homeassistant.components.stream.worker] Error opening stream rtsps://stream-uc2-bravo.dropcam.com:443/sdm_live_stream/CiQA2vuxr1SLu8rlYbOHo16R-04X0NNEKfeupmXLad7ICSMu8s8ScQAFjsOTS4_b71We2VG7vYgLakwq7JUxt6NJI0n_4qGM-a8nYLnRqRt-bpKX5HVk56GBFLsegX_YCrq7qGjicjVDCJLw6ikxOmGMNn5FOIzSK0Ae_WFyJ5hjvdjABw-qslkW0czaUaWbWG6Bc1HqAVEU?auth=g.0.eyJraWQiOiIyMzhiNTUxZmMyM2EyM2Y4M2E2ZTE3MmJjZTg0YmU3ZjgxMzAzMmM4IiwiYWxnIjoiUlMyNTYifQ.eyJpc3MiOiJuZXN0LXNlY3VyaXR5LWF1dGhwcm94eSIsInN1YiI6Im5lc3RfaWQ6bmVzdC1waG9lbml4LXByb2Q6MjEyMTgxNDEiLCJwb2wiOiIzcC1vYXV0aC1zY29wZS1BUElfU0RNX1NFUlZJQ0UtY2xpZW50LTIwMjQyNzMxODczNS1qNXQ5bWMyMzZqaG85YXMycWY0dTZxY3NmYW1kaGJ0ci5hcHBzLmdvb2dsZXVzZXJjb250ZW50LmNvbSIsImV4cCI6MTYzMTQ5ODQ1MH0.tPMv-EG32_XlvIZmCpKyJ12Ozu8zGClYp1WbDrqpdtTyfhR2w_a410FySS2m5ontP4dOlEIuwobL-EtLmC7L-UTsMkZcLFI3pkEY9bzONK24CGe3KJSdpE9hCkdK9L2SM9cAQ87j4pRr9OF5LP7YiLbVPpjZTsW_7ou_Y1g-yu5GA7Fnn5ehSKR-Iwq-ykUciC1-YbZfrAl55FYoBbZRRBiQL8r0leC9RcSSaG73vmI7i-2uemhDzysQlPcXt0nNJ9rzgRpE63NxmMxF4hGNUGOT7BWwoXVVsUJpLHnU-wl5S-jXhZbfS3V3cP9akUTeQF_jgmlWDC06QhKSLnHOKA
2021-09-12 19:15:10 ERROR (stream_worker) [libav.rtsp] method DESCRIBE failed: 404 Not Found
2021-09-12 19:15:10 ERROR (stream_worker) [homeassistant.components.stream.worker] Error opening stream rtsps://stream-uc2-bravo.dropcam.com:443/sdm_live_stream/CiQA2vuxr1SLu8rlYbOHo16R-04X0NNEKfeupmXLad7ICSMu8s8ScQAFjsOTS4_b71We2VG7vYgLakwq7JUxt6NJI0n_4qGM-a8nYLnRqRt-bpKX5HVk56GBFLsegX_YCrq7qGjicjVDCJLw6ikxOmGMNn5FOIzSK0Ae_WFyJ5hjvdjABw-qslkW0czaUaWbWG6Bc1HqAVEU?auth=g.0.eyJraWQiOiIyMzhiNTUxZmMyM2EyM2Y4M2E2ZTE3MmJjZTg0YmU3ZjgxMzAzMmM4IiwiYWxnIjoiUlMyNTYifQ.eyJpc3MiOiJuZXN0LXNlY3VyaXR5LWF1dGhwcm94eSIsInN1YiI6Im5lc3RfaWQ6bmVzdC1waG9lbml4LXByb2Q6MjEyMTgxNDEiLCJwb2wiOiIzcC1vYXV0aC1zY29wZS1BUElfU0RNX1NFUlZJQ0UtY2xpZW50LTIwMjQyNzMxODczNS1qNXQ5bWMyMzZqaG85YXMycWY0dTZxY3NmYW1kaGJ0ci5hcHBzLmdvb2dsZXVzZXJjb250ZW50LmNvbSIsImV4cCI6MTYzMTQ5ODQ1MH0.tPMv-EG32_XlvIZmCpKyJ12Ozu8zGClYp1WbDrqpdtTyfhR2w_a410FySS2m5ontP4dOlEIuwobL-EtLmC7L-UTsMkZcLFI3pkEY9bzONK24CGe3KJSdpE9hCkdK9L2SM9cAQ87j4pRr9OF5LP7YiLbVPpjZTsW_7ou_Y1g-yu5GA7Fnn5ehSKR-Iwq-ykUciC1-YbZfrAl55FYoBbZRRBiQL8r0leC9RcSSaG73vmI7i-2uemhDzysQlPcXt0nNJ9rzgRpE63NxmMxF4hGNUGOT7BWwoXVVsUJpLHnU-wl5S-jXhZbfS3V3cP9akUTeQF_jgmlWDC06QhKSLnHOKA
2021-09-12 19:15:50 ERROR (MainThread) [homeassistant] Error doing job: Future exception was never retrieved
Traceback (most recent call last):
  File "/usr/local/lib/python3.9/concurrent/futures/thread.py", line 52, in run
    result = self.fn(*self.args, **self.kwargs)
TypeError: update() takes 1 positional argument but 2 were given
2021-09-12 19:17:21 ERROR (stream_worker) [libav.rtsp] method DESCRIBE failed: 404 Not Found
2021-09-12 19:17:21 ERROR (stream_worker) [homeassistant.components.stream.worker] Error opening stream rtsps://stream-uc2-bravo.dropcam.com:443/sdm_live_stream/CiQA2vuxr1SLu8rlYbOHo16R-04X0NNEKfeupmXLad7ICSMu8s8ScQAFjsOTS4_b71We2VG7vYgLakwq7JUxt6NJI0n_4qGM-a8nYLnRqRt-bpKX5HVk56GBFLsegX_YCrq7qGjicjVDCJLw6ikxOmGMNn5FOIzSK0Ae_WFyJ5hjvdjABw-qslkW0czaUaWbWG6Bc1HqAVEU?auth=g.0.eyJraWQiOiIyMzhiNTUxZmMyM2EyM2Y4M2E2ZTE3MmJjZTg0YmU3ZjgxMzAzMmM4IiwiYWxnIjoiUlMyNTYifQ.eyJpc3MiOiJuZXN0LXNlY3VyaXR5LWF1dGhwcm94eSIsInN1YiI6Im5lc3RfaWQ6bmVzdC1waG9lbml4LXByb2Q6MjEyMTgxNDEiLCJwb2wiOiIzcC1vYXV0aC1zY29wZS1BUElfU0RNX1NFUlZJQ0UtY2xpZW50LTIwMjQyNzMxODczNS1qNXQ5bWMyMzZqaG85YXMycWY0dTZxY3NmYW1kaGJ0ci5hcHBzLmdvb2dsZXVzZXJjb250ZW50LmNvbSIsImV4cCI6MTYzMTQ5ODQ1MH0.tPMv-EG32_XlvIZmCpKyJ12Ozu8zGClYp1WbDrqpdtTyfhR2w_a410FySS2m5ontP4dOlEIuwobL-EtLmC7L-UTsMkZcLFI3pkEY9bzONK24CGe3KJSdpE9hCkdK9L2SM9cAQ87j4pRr9OF5LP7YiLbVPpjZTsW_7ou_Y1g-yu5GA7Fnn5ehSKR-Iwq-ykUciC1-YbZfrAl55FYoBbZRRBiQL8r0leC9RcSSaG73vmI7i-2uemhDzysQlPcXt0nNJ9rzgRpE63NxmMxF4hGNUGOT7BWwoXVVsUJpLHnU-wl5S-jXhZbfS3V3cP9akUTeQF_jgmlWDC06QhKSLnHOKA
2021-09-12 19:19:41 ERROR (stream_worker) [libav.rtsp] method DESCRIBE failed: 404 Not Found
2021-09-12 19:19:41 ERROR (stream_worker) [homeassistant.components.stream.worker] Error opening stream rtsps://stream-uc2-bravo.dropcam.com:443/sdm_live_stream/CiQA2vuxr1SLu8rlYbOHo16R-04X0NNEKfeupmXLad7ICSMu8s8ScQAFjsOTS4_b71We2VG7vYgLakwq7JUxt6NJI0n_4qGM-a8nYLnRqRt-bpKX5HVk56GBFLsegX_YCrq7qGjicjVDCJLw6ikxOmGMNn5FOIzSK0Ae_WFyJ5hjvdjABw-qslkW0czaUaWbWG6Bc1HqAVEU?auth=g.0.eyJraWQiOiIyMzhiNTUxZmMyM2EyM2Y4M2E2ZTE3MmJjZTg0YmU3ZjgxMzAzMmM4IiwiYWxnIjoiUlMyNTYifQ.eyJpc3MiOiJuZXN0LXNlY3VyaXR5LWF1dGhwcm94eSIsInN1YiI6Im5lc3RfaWQ6bmVzdC1waG9lbml4LXByb2Q6MjEyMTgxNDEiLCJwb2wiOiIzcC1vYXV0aC1zY29wZS1BUElfU0RNX1NFUlZJQ0UtY2xpZW50LTIwMjQyNzMxODczNS1qNXQ5bWMyMzZqaG85YXMycWY0dTZxY3NmYW1kaGJ0ci5hcHBzLmdvb2dsZXVzZXJjb250ZW50LmNvbSIsImV4cCI6MTYzMTQ5ODQ1MH0.tPMv-EG32_XlvIZmCpKyJ12Ozu8zGClYp1WbDrqpdtTyfhR2w_a410FySS2m5ontP4dOlEIuwobL-EtLmC7L-UTsMkZcLFI3pkEY9bzONK24CGe3KJSdpE9hCkdK9L2SM9cAQ87j4pRr9OF5LP7YiLbVPpjZTsW_7ou_Y1g-yu5GA7Fnn5ehSKR-Iwq-ykUciC1-YbZfrAl55FYoBbZRRBiQL8r0leC9RcSSaG73vmI7i-2uemhDzysQlPcXt0nNJ9rzgRpE63NxmMxF4hGNUGOT7BWwoXVVsUJpLHnU-wl5S-jXhZbfS3V3cP9akUTeQF_jgmlWDC06QhKSLnHOKA
2021-09-12 19:20:51 ERROR (MainThread) [homeassistant] Error doing job: Future exception was never retrieved
Traceback (most recent call last):
  File "/usr/local/lib/python3.9/concurrent/futures/thread.py", line 52, in run
    result = self.fn(*self.args, **self.kwargs)
TypeError: update() takes 1 positional argument but 2 were given
2021-09-12 19:22:12 ERROR (stream_worker) [libav.rtsp] method DESCRIBE failed: 404 Not Found
2021-09-12 19:22:12 ERROR (stream_worker) [homeassistant.components.stream.worker] Error opening stream rtsps://stream-uc2-bravo.dropcam.com:443/sdm_live_stream/CiQA2vuxr1SLu8rlYbOHo16R-04X0NNEKfeupmXLad7ICSMu8s8ScQAFjsOTS4_b71We2VG7vYgLakwq7JUxt6NJI0n_4qGM-a8nYLnRqRt-bpKX5HVk56GBFLsegX_YCrq7qGjicjVDCJLw6ikxOmGMNn5FOIzSK0Ae_WFyJ5hjvdjABw-qslkW0czaUaWbWG6Bc1HqAVEU?auth=g.0.eyJraWQiOiIyMzhiNTUxZmMyM2EyM2Y4M2E2ZTE3MmJjZTg0YmU3ZjgxMzAzMmM4IiwiYWxnIjoiUlMyNTYifQ.eyJpc3MiOiJuZXN0LXNlY3VyaXR5LWF1dGhwcm94eSIsInN1YiI6Im5lc3RfaWQ6bmVzdC1waG9lbml4LXByb2Q6MjEyMTgxNDEiLCJwb2wiOiIzcC1vYXV0aC1zY29wZS1BUElfU0RNX1NFUlZJQ0UtY2xpZW50LTIwMjQyNzMxODczNS1qNXQ5bWMyMzZqaG85YXMycWY0dTZxY3NmYW1kaGJ0ci5hcHBzLmdvb2dsZXVzZXJjb250ZW50LmNvbSIsImV4cCI6MTYzMTQ5ODQ1MH0.tPMv-EG32_XlvIZmCpKyJ12Ozu8zGClYp1WbDrqpdtTyfhR2w_a410FySS2m5ontP4dOlEIuwobL-EtLmC7L-UTsMkZcLFI3pkEY9bzONK24CGe3KJSdpE9hCkdK9L2SM9cAQ87j4pRr9OF5LP7YiLbVPpjZTsW_7ou_Y1g-yu5GA7Fnn5ehSKR-Iwq-ykUciC1-YbZfrAl55FYoBbZRRBiQL8r0leC9RcSSaG73vmI7i-2uemhDzysQlPcXt0nNJ9rzgRpE63NxmMxF4hGNUGOT7BWwoXVVsUJpLHnU-wl5S-jXhZbfS3V3cP9akUTeQF_jgmlWDC06QhKSLnHOKA
2021-09-12 19:24:55 ERROR (stream_worker) [libav.rtsp] method DESCRIBE failed: 404 Not Found
2021-09-12 19:24:55 ERROR (stream_worker) [homeassistant.components.stream.worker] Error opening stream rtsps://stream-uc2-bravo.dropcam.com:443/sdm_live_stream/CiQA2vuxr1SLu8rlYbOHo16R-04X0NNEKfeupmXLad7ICSMu8s8ScQAFjsOTS4_b71We2VG7vYgLakwq7JUxt6NJI0n_4qGM-a8nYLnRqRt-bpKX5HVk56GBFLsegX_YCrq7qGjicjVDCJLw6ikxOmGMNn5FOIzSK0Ae_WFyJ5hjvdjABw-qslkW0czaUaWbWG6Bc1HqAVEU?auth=g.0.eyJraWQiOiIyMzhiNTUxZmMyM2EyM2Y4M2E2ZTE3MmJjZTg0YmU3ZjgxMzAzMmM4IiwiYWxnIjoiUlMyNTYifQ.eyJpc3MiOiJuZXN0LXNlY3VyaXR5LWF1dGhwcm94eSIsInN1YiI6Im5lc3RfaWQ6bmVzdC1waG9lbml4LXByb2Q6MjEyMTgxNDEiLCJwb2wiOiIzcC1vYXV0aC1zY29wZS1BUElfU0RNX1NFUlZJQ0UtY2xpZW50LTIwMjQyNzMxODczNS1qNXQ5bWMyMzZqaG85YXMycWY0dTZxY3NmYW1kaGJ0ci5hcHBzLmdvb2dsZXVzZXJjb250ZW50LmNvbSIsImV4cCI6MTYzMTQ5ODQ1MH0.tPMv-EG32_XlvIZmCpKyJ12Ozu8zGClYp1WbDrqpdtTyfhR2w_a410FySS2m5ontP4dOlEIuwobL-EtLmC7L-UTsMkZcLFI3pkEY9bzONK24CGe3KJSdpE9hCkdK9L2SM9cAQ87j4pRr9OF5LP7YiLbVPpjZTsW_7ou_Y1g-yu5GA7Fnn5ehSKR-Iwq-ykUciC1-YbZfrAl55FYoBbZRRBiQL8r0leC9RcSSaG73vmI7i-2uemhDzysQlPcXt0nNJ9rzgRpE63NxmMxF4hGNUGOT7BWwoXVVsUJpLHnU-wl5S-jXhZbfS3V3cP9akUTeQF_jgmlWDC06QhKSLnHOKA
2021-09-12 19:25:52 ERROR (MainThread) [homeassistant] Error doing job: Future exception was never retrieved
Traceback (most recent call last):
  File "/usr/local/lib/python3.9/concurrent/futures/thread.py", line 52, in run
    result = self.fn(*self.args, **self.kwargs)
TypeError: update() takes 1 positional argument but 2 were given
2021-09-12 19:26:33 ERROR (MainThread) [iotawattpy.connection] Err: 
2021-09-12 19:26:33 ERROR (MainThread) [homeassistant.components.iotawatt.coordinator] Unexpected error fetching 192.168.20.195 data: 'NoneType' object has no attribute 'text'
Traceback (most recent call last):
  File "/usr/src/homeassistant/homeassistant/helpers/update_coordinator.py", line 187, in _async_refresh
    self.data = await self._async_update_data()
  File "/usr/src/homeassistant/homeassistant/components/iotawatt/coordinator.py", line 55, in _async_update_data
    await self.api.update()
  File "/usr/local/lib/python3.9/site-packages/iotawattpy/iotawatt.py", line 66, in update
    await self._refreshSensors(timespan)
  File "/usr/local/lib/python3.9/site-packages/iotawattpy/iotawatt.py", line 100, in _refreshSensors
    results = response.text
AttributeError: 'NoneType' object has no attribute 'text'
2021-09-12 19:27:45 ERROR (stream_worker) [libav.rtsp] method DESCRIBE failed: 404 Not Found
2021-09-12 19:27:45 ERROR (stream_worker) [homeassistant.components.stream.worker] Error opening stream rtsps://stream-uc2-bravo.dropcam.com:443/sdm_live_stream/CiQA2vuxr1SLu8rlYbOHo16R-04X0NNEKfeupmXLad7ICSMu8s8ScQAFjsOTS4_b71We2VG7vYgLakwq7JUxt6NJI0n_4qGM-a8nYLnRqRt-bpKX5HVk56GBFLsegX_YCrq7qGjicjVDCJLw6ikxOmGMNn5FOIzSK0Ae_WFyJ5hjvdjABw-qslkW0czaUaWbWG6Bc1HqAVEU?auth=g.0.eyJraWQiOiIyMzhiNTUxZmMyM2EyM2Y4M2E2ZTE3MmJjZTg0YmU3ZjgxMzAzMmM4IiwiYWxnIjoiUlMyNTYifQ.eyJpc3MiOiJuZXN0LXNlY3VyaXR5LWF1dGhwcm94eSIsInN1YiI6Im5lc3RfaWQ6bmVzdC1waG9lbml4LXByb2Q6MjEyMTgxNDEiLCJwb2wiOiIzcC1vYXV0aC1zY29wZS1BUElfU0RNX1NFUlZJQ0UtY2xpZW50LTIwMjQyNzMxODczNS1qNXQ5bWMyMzZqaG85YXMycWY0dTZxY3NmYW1kaGJ0ci5hcHBzLmdvb2dsZXVzZXJjb250ZW50LmNvbSIsImV4cCI6MTYzMTQ5ODQ1MH0.tPMv-EG32_XlvIZmCpKyJ12Ozu8zGClYp1WbDrqpdtTyfhR2w_a410FySS2m5ontP4dOlEIuwobL-EtLmC7L-UTsMkZcLFI3pkEY9bzONK24CGe3KJSdpE9hCkdK9L2SM9cAQ87j4pRr9OF5LP7YiLbVPpjZTsW_7ou_Y1g-yu5GA7Fnn5ehSKR-Iwq-ykUciC1-YbZfrAl55FYoBbZRRBiQL8r0leC9RcSSaG73vmI7i-2uemhDzysQlPcXt0nNJ9rzgRpE63NxmMxF4hGNUGOT7BWwoXVVsUJpLHnU-wl5S-jXhZbfS3V3cP9akUTeQF_jgmlWDC06QhKSLnHOKA
2021-09-12 19:30:46 ERROR (stream_worker) [libav.rtsp] method DESCRIBE failed: 404 Not Found
2021-09-12 19:30:46 ERROR (stream_worker) [homeassistant.components.stream.worker] Error opening stream rtsps://stream-uc2-bravo.dropcam.com:443/sdm_live_stream/CiQA2vuxr1SLu8rlYbOHo16R-04X0NNEKfeupmXLad7ICSMu8s8ScQAFjsOTS4_b71We2VG7vYgLakwq7JUxt6NJI0n_4qGM-a8nYLnRqRt-bpKX5HVk56GBFLsegX_YCrq7qGjicjVDCJLw6ikxOmGMNn5FOIzSK0Ae_WFyJ5hjvdjABw-qslkW0czaUaWbWG6Bc1HqAVEU?auth=g.0.eyJraWQiOiIyMzhiNTUxZmMyM2EyM2Y4M2E2ZTE3MmJjZTg0YmU3ZjgxMzAzMmM4IiwiYWxnIjoiUlMyNTYifQ.eyJpc3MiOiJuZXN0LXNlY3VyaXR5LWF1dGhwcm94eSIsInN1YiI6Im5lc3RfaWQ6bmVzdC1waG9lbml4LXByb2Q6MjEyMTgxNDEiLCJwb2wiOiIzcC1vYXV0aC1zY29wZS1BUElfU0RNX1NFUlZJQ0UtY2xpZW50LTIwMjQyNzMxODczNS1qNXQ5bWMyMzZqaG85YXMycWY0dTZxY3NmYW1kaGJ0ci5hcHBzLmdvb2dsZXVzZXJjb250ZW50LmNvbSIsImV4cCI6MTYzMTQ5ODQ1MH0.tPMv-EG32_XlvIZmCpKyJ12Ozu8zGClYp1WbDrqpdtTyfhR2w_a410FySS2m5ontP4dOlEIuwobL-EtLmC7L-UTsMkZcLFI3pkEY9bzONK24CGe3KJSdpE9hCkdK9L2SM9cAQ87j4pRr9OF5LP7YiLbVPpjZTsW_7ou_Y1g-yu5GA7Fnn5ehSKR-Iwq-ykUciC1-YbZfrAl55FYoBbZRRBiQL8r0leC9RcSSaG73vmI7i-2uemhDzysQlPcXt0nNJ9rzgRpE63NxmMxF4hGNUGOT7BWwoXVVsUJpLHnU-wl5S-jXhZbfS3V3cP9akUTeQF_jgmlWDC06QhKSLnHOKA
2021-09-12 19:30:53 ERROR (MainThread) [homeassistant] Error doing job: Future exception was never retrieved
Traceback (most recent call last):
  File "/usr/local/lib/python3.9/concurrent/futures/thread.py", line 52, in run
    result = self.fn(*self.args, **self.kwargs)
TypeError: update() takes 1 positional argument but 2 were given
2021-09-12 19:33:56 ERROR (stream_worker) [libav.rtsp] method DESCRIBE failed: 404 Not Found
2021-09-12 19:33:56 ERROR (stream_worker) [homeassistant.components.stream.worker] Error opening stream rtsps://stream-uc2-bravo.dropcam.com:443/sdm_live_stream/CiQA2vuxr1SLu8rlYbOHo16R-04X0NNEKfeupmXLad7ICSMu8s8ScQAFjsOTS4_b71We2VG7vYgLakwq7JUxt6NJI0n_4qGM-a8nYLnRqRt-bpKX5HVk56GBFLsegX_YCrq7qGjicjVDCJLw6ikxOmGMNn5FOIzSK0Ae_WFyJ5hjvdjABw-qslkW0czaUaWbWG6Bc1HqAVEU?auth=g.0.eyJraWQiOiIyMzhiNTUxZmMyM2EyM2Y4M2E2ZTE3MmJjZTg0YmU3ZjgxMzAzMmM4IiwiYWxnIjoiUlMyNTYifQ.eyJpc3MiOiJuZXN0LXNlY3VyaXR5LWF1dGhwcm94eSIsInN1YiI6Im5lc3RfaWQ6bmVzdC1waG9lbml4LXByb2Q6MjEyMTgxNDEiLCJwb2wiOiIzcC1vYXV0aC1zY29wZS1BUElfU0RNX1NFUlZJQ0UtY2xpZW50LTIwMjQyNzMxODczNS1qNXQ5bWMyMzZqaG85YXMycWY0dTZxY3NmYW1kaGJ0ci5hcHBzLmdvb2dsZXVzZXJjb250ZW50LmNvbSIsImV4cCI6MTYzMTQ5ODQ1MH0.tPMv-EG32_XlvIZmCpKyJ12Ozu8zGClYp1WbDrqpdtTyfhR2w_a410FySS2m5ontP4dOlEIuwobL-EtLmC7L-UTsMkZcLFI3pkEY9bzONK24CGe3KJSdpE9hCkdK9L2SM9cAQ87j4pRr9OF5LP7YiLbVPpjZTsW_7ou_Y1g-yu5GA7Fnn5ehSKR-Iwq-ykUciC1-YbZfrAl55FYoBbZRRBiQL8r0leC9RcSSaG73vmI7i-2uemhDzysQlPcXt0nNJ9rzgRpE63NxmMxF4hGNUGOT7BWwoXVVsUJpLHnU-wl5S-jXhZbfS3V3cP9akUTeQF_jgmlWDC06QhKSLnHOKA
2021-09-12 19:35:54 ERROR (MainThread) [homeassistant] Error doing job: Future exception was never retrieved
Traceback (most recent call last):
  File "/usr/local/lib/python3.9/concurrent/futures/thread.py", line 52, in run
    result = self.fn(*self.args, **self.kwargs)
TypeError: update() takes 1 positional argument but 2 were given
2021-09-12 19:37:17 ERROR (stream_worker) [libav.rtsp] method DESCRIBE failed: 404 Not Found
2021-09-12 19:37:17 ERROR (stream_worker) [homeassistant.components.stream.worker] Error opening stream rtsps://stream-uc2-bravo.dropcam.com:443/sdm_live_stream/CiQA2vuxr1SLu8rlYbOHo16R-04X0NNEKfeupmXLad7ICSMu8s8ScQAFjsOTS4_b71We2VG7vYgLakwq7JUxt6NJI0n_4qGM-a8nYLnRqRt-bpKX5HVk56GBFLsegX_YCrq7qGjicjVDCJLw6ikxOmGMNn5FOIzSK0Ae_WFyJ5hjvdjABw-qslkW0czaUaWbWG6Bc1HqAVEU?auth=g.0.eyJraWQiOiIyMzhiNTUxZmMyM2EyM2Y4M2E2ZTE3MmJjZTg0YmU3ZjgxMzAzMmM4IiwiYWxnIjoiUlMyNTYifQ.eyJpc3MiOiJuZXN0LXNlY3VyaXR5LWF1dGhwcm94eSIsInN1YiI6Im5lc3RfaWQ6bmVzdC1waG9lbml4LXByb2Q6MjEyMTgxNDEiLCJwb2wiOiIzcC1vYXV0aC1zY29wZS1BUElfU0RNX1NFUlZJQ0UtY2xpZW50LTIwMjQyNzMxODczNS1qNXQ5bWMyMzZqaG85YXMycWY0dTZxY3NmYW1kaGJ0ci5hcHBzLmdvb2dsZXVzZXJjb250ZW50LmNvbSIsImV4cCI6MTYzMTQ5ODQ1MH0.tPMv-EG32_XlvIZmCpKyJ12Ozu8zGClYp1WbDrqpdtTyfhR2w_a410FySS2m5ontP4dOlEIuwobL-EtLmC7L-UTsMkZcLFI3pkEY9bzONK24CGe3KJSdpE9hCkdK9L2SM9cAQ87j4pRr9OF5LP7YiLbVPpjZTsW_7ou_Y1g-yu5GA7Fnn5ehSKR-Iwq-ykUciC1-YbZfrAl55FYoBbZRRBiQL8r0leC9RcSSaG73vmI7i-2uemhDzysQlPcXt0nNJ9rzgRpE63NxmMxF4hGNUGOT7BWwoXVVsUJpLHnU-wl5S-jXhZbfS3V3cP9akUTeQF_jgmlWDC06QhKSLnHOKA
2021-09-12 19:38:44 ERROR (MainThread) [iotawattpy.connection] Err: 
2021-09-12 19:38:44 ERROR (MainThread) [homeassistant.components.iotawatt.coordinator] Unexpected error fetching 192.168.20.195 data: 'NoneType' object has no attribute 'text'
Traceback (most recent call last):
  File "/usr/src/homeassistant/homeassistant/helpers/update_coordinator.py", line 187, in _async_refresh
    self.data = await self._async_update_data()
  File "/usr/src/homeassistant/homeassistant/components/iotawatt/coordinator.py", line 55, in _async_update_data
    await self.api.update()
  File "/usr/local/lib/python3.9/site-packages/iotawattpy/iotawatt.py", line 66, in update
    await self._refreshSensors(timespan)
  File "/usr/local/lib/python3.9/site-packages/iotawattpy/iotawatt.py", line 100, in _refreshSensors
    results = response.text
AttributeError: 'NoneType' object has no attribute 'text'
2021-09-12 19:40:41 WARNING (MainThread) [bellows.zigbee.application] Watchdog heartbeat timeout: 
2021-09-12 19:40:47 ERROR (stream_worker) [libav.rtsp] method DESCRIBE failed: 404 Not Found
2021-09-12 19:40:47 ERROR (stream_worker) [homeassistant.components.stream.worker] Error opening stream rtsps://stream-uc2-bravo.dropcam.com:443/sdm_live_stream/CiQA2vuxr1SLu8rlYbOHo16R-04X0NNEKfeupmXLad7ICSMu8s8ScQAFjsOTS4_b71We2VG7vYgLakwq7JUxt6NJI0n_4qGM-a8nYLnRqRt-bpKX5HVk56GBFLsegX_YCrq7qGjicjVDCJLw6ikxOmGMNn5FOIzSK0Ae_WFyJ5hjvdjABw-qslkW0czaUaWbWG6Bc1HqAVEU?auth=g.0.eyJraWQiOiIyMzhiNTUxZmMyM2EyM2Y4M2E2ZTE3MmJjZTg0YmU3ZjgxMzAzMmM4IiwiYWxnIjoiUlMyNTYifQ.eyJpc3MiOiJuZXN0LXNlY3VyaXR5LWF1dGhwcm94eSIsInN1YiI6Im5lc3RfaWQ6bmVzdC1waG9lbml4LXByb2Q6MjEyMTgxNDEiLCJwb2wiOiIzcC1vYXV0aC1zY29wZS1BUElfU0RNX1NFUlZJQ0UtY2xpZW50LTIwMjQyNzMxODczNS1qNXQ5bWMyMzZqaG85YXMycWY0dTZxY3NmYW1kaGJ0ci5hcHBzLmdvb2dsZXVzZXJjb250ZW50LmNvbSIsImV4cCI6MTYzMTQ5ODQ1MH0.tPMv-EG32_XlvIZmCpKyJ12Ozu8zGClYp1WbDrqpdtTyfhR2w_a410FySS2m5ontP4dOlEIuwobL-EtLmC7L-UTsMkZcLFI3pkEY9bzONK24CGe3KJSdpE9hCkdK9L2SM9cAQ87j4pRr9OF5LP7YiLbVPpjZTsW_7ou_Y1g-yu5GA7Fnn5ehSKR-Iwq-ykUciC1-YbZfrAl55FYoBbZRRBiQL8r0leC9RcSSaG73vmI7i-2uemhDzysQlPcXt0nNJ9rzgRpE63NxmMxF4hGNUGOT7BWwoXVVsUJpLHnU-wl5S-jXhZbfS3V3cP9akUTeQF_jgmlWDC06QhKSLnHOKA
2021-09-12 19:40:55 ERROR (MainThread) [homeassistant] Error doing job: Future exception was never retrieved
Traceback (most recent call last):
  File "/usr/local/lib/python3.9/concurrent/futures/thread.py", line 52, in run
    result = self.fn(*self.args, **self.kwargs)
TypeError: update() takes 1 positional argument but 2 were given
2021-09-12 19:40:56 WARNING (MainThread) [bellows.zigbee.application] Watchdog heartbeat timeout: 
2021-09-12 19:41:11 WARNING (MainThread) [bellows.zigbee.application] Watchdog heartbeat timeout: 
2021-09-12 19:41:26 WARNING (MainThread) [bellows.zigbee.application] Watchdog heartbeat timeout: 
2021-09-12 19:44:28 ERROR (stream_worker) [libav.rtsp] method DESCRIBE failed: 404 Not Found
2021-09-12 19:44:28 ERROR (stream_worker) [homeassistant.components.stream.worker] Error opening stream rtsps://stream-uc2-bravo.dropcam.com:443/sdm_live_stream/CiQA2vuxr1SLu8rlYbOHo16R-04X0NNEKfeupmXLad7ICSMu8s8ScQAFjsOTS4_b71We2VG7vYgLakwq7JUxt6NJI0n_4qGM-a8nYLnRqRt-bpKX5HVk56GBFLsegX_YCrq7qGjicjVDCJLw6ikxOmGMNn5FOIzSK0Ae_WFyJ5hjvdjABw-qslkW0czaUaWbWG6Bc1HqAVEU?auth=g.0.eyJraWQiOiIyMzhiNTUxZmMyM2EyM2Y4M2E2ZTE3MmJjZTg0YmU3ZjgxMzAzMmM4IiwiYWxnIjoiUlMyNTYifQ.eyJpc3MiOiJuZXN0LXNlY3VyaXR5LWF1dGhwcm94eSIsInN1YiI6Im5lc3RfaWQ6bmVzdC1waG9lbml4LXByb2Q6MjEyMTgxNDEiLCJwb2wiOiIzcC1vYXV0aC1zY29wZS1BUElfU0RNX1NFUlZJQ0UtY2xpZW50LTIwMjQyNzMxODczNS1qNXQ5bWMyMzZqaG85YXMycWY0dTZxY3NmYW1kaGJ0ci5hcHBzLmdvb2dsZXVzZXJjb250ZW50LmNvbSIsImV4cCI6MTYzMTQ5ODQ1MH0.tPMv-EG32_XlvIZmCpKyJ12Ozu8zGClYp1WbDrqpdtTyfhR2w_a410FySS2m5ontP4dOlEIuwobL-EtLmC7L-UTsMkZcLFI3pkEY9bzONK24CGe3KJSdpE9hCkdK9L2SM9cAQ87j4pRr9OF5LP7YiLbVPpjZTsW_7ou_Y1g-yu5GA7Fnn5ehSKR-Iwq-ykUciC1-YbZfrAl55FYoBbZRRBiQL8r0leC9RcSSaG73vmI7i-2uemhDzysQlPcXt0nNJ9rzgRpE63NxmMxF4hGNUGOT7BWwoXVVsUJpLHnU-wl5S-jXhZbfS3V3cP9akUTeQF_jgmlWDC06QhKSLnHOKA
2021-09-12 19:45:56 ERROR (MainThread) [homeassistant] Error doing job: Future exception was never retrieved
Traceback (most recent call last):
  File "/usr/local/lib/python3.9/concurrent/futures/thread.py", line 52, in run
    result = self.fn(*self.args, **self.kwargs)
TypeError: update() takes 1 positional argument but 2 were given
2021-09-12 19:48:18 ERROR (stream_worker) [libav.rtsp] method DESCRIBE failed: 404 Not Found
2021-09-12 19:48:18 ERROR (stream_worker) [homeassistant.components.stream.worker] Error opening stream rtsps://stream-uc2-bravo.dropcam.com:443/sdm_live_stream/CiQA2vuxr1SLu8rlYbOHo16R-04X0NNEKfeupmXLad7ICSMu8s8ScQAFjsOTS4_b71We2VG7vYgLakwq7JUxt6NJI0n_4qGM-a8nYLnRqRt-bpKX5HVk56GBFLsegX_YCrq7qGjicjVDCJLw6ikxOmGMNn5FOIzSK0Ae_WFyJ5hjvdjABw-qslkW0czaUaWbWG6Bc1HqAVEU?auth=g.0.eyJraWQiOiIyMzhiNTUxZmMyM2EyM2Y4M2E2ZTE3MmJjZTg0YmU3ZjgxMzAzMmM4IiwiYWxnIjoiUlMyNTYifQ.eyJpc3MiOiJuZXN0LXNlY3VyaXR5LWF1dGhwcm94eSIsInN1YiI6Im5lc3RfaWQ6bmVzdC1waG9lbml4LXByb2Q6MjEyMTgxNDEiLCJwb2wiOiIzcC1vYXV0aC1zY29wZS1BUElfU0RNX1NFUlZJQ0UtY2xpZW50LTIwMjQyNzMxODczNS1qNXQ5bWMyMzZqaG85YXMycWY0dTZxY3NmYW1kaGJ0ci5hcHBzLmdvb2dsZXVzZXJjb250ZW50LmNvbSIsImV4cCI6MTYzMTQ5ODQ1MH0.tPMv-EG32_XlvIZmCpKyJ12Ozu8zGClYp1WbDrqpdtTyfhR2w_a410FySS2m5ontP4dOlEIuwobL-EtLmC7L-UTsMkZcLFI3pkEY9bzONK24CGe3KJSdpE9hCkdK9L2SM9cAQ87j4pRr9OF5LP7YiLbVPpjZTsW_7ou_Y1g-yu5GA7Fnn5ehSKR-Iwq-ykUciC1-YbZfrAl55FYoBbZRRBiQL8r0leC9RcSSaG73vmI7i-2uemhDzysQlPcXt0nNJ9rzgRpE63NxmMxF4hGNUGOT7BWwoXVVsUJpLHnU-wl5S-jXhZbfS3V3cP9akUTeQF_jgmlWDC06QhKSLnHOKA
2021-09-12 19:50:57 ERROR (MainThread) [homeassistant] Error doing job: Future exception was never retrieved
Traceback (most recent call last):
  File "/usr/local/lib/python3.9/concurrent/futures/thread.py", line 52, in run
    result = self.fn(*self.args, **self.kwargs)
TypeError: update() takes 1 positional argument but 2 were given
2021-09-12 19:52:19 ERROR (stream_worker) [libav.rtsp] method DESCRIBE failed: 404 Not Found
2021-09-12 19:52:19 ERROR (stream_worker) [homeassistant.components.stream.worker] Error opening stream rtsps://stream-uc2-bravo.dropcam.com:443/sdm_live_stream/CiQA2vuxr1SLu8rlYbOHo16R-04X0NNEKfeupmXLad7ICSMu8s8ScQAFjsOTS4_b71We2VG7vYgLakwq7JUxt6NJI0n_4qGM-a8nYLnRqRt-bpKX5HVk56GBFLsegX_YCrq7qGjicjVDCJLw6ikxOmGMNn5FOIzSK0Ae_WFyJ5hjvdjABw-qslkW0czaUaWbWG6Bc1HqAVEU?auth=g.0.eyJraWQiOiIyMzhiNTUxZmMyM2EyM2Y4M2E2ZTE3MmJjZTg0YmU3ZjgxMzAzMmM4IiwiYWxnIjoiUlMyNTYifQ.eyJpc3MiOiJuZXN0LXNlY3VyaXR5LWF1dGhwcm94eSIsInN1YiI6Im5lc3RfaWQ6bmVzdC1waG9lbml4LXByb2Q6MjEyMTgxNDEiLCJwb2wiOiIzcC1vYXV0aC1zY29wZS1BUElfU0RNX1NFUlZJQ0UtY2xpZW50LTIwMjQyNzMxODczNS1qNXQ5bWMyMzZqaG85YXMycWY0dTZxY3NmYW1kaGJ0ci5hcHBzLmdvb2dsZXVzZXJjb250ZW50LmNvbSIsImV4cCI6MTYzMTQ5ODQ1MH0.tPMv-EG32_XlvIZmCpKyJ12Ozu8zGClYp1WbDrqpdtTyfhR2w_a410FySS2m5ontP4dOlEIuwobL-EtLmC7L-UTsMkZcLFI3pkEY9bzONK24CGe3KJSdpE9hCkdK9L2SM9cAQ87j4pRr9OF5LP7YiLbVPpjZTsW_7ou_Y1g-yu5GA7Fnn5ehSKR-Iwq-ykUciC1-YbZfrAl55FYoBbZRRBiQL8r0leC9RcSSaG73vmI7i-2uemhDzysQlPcXt0nNJ9rzgRpE63NxmMxF4hGNUGOT7BWwoXVVsUJpLHnU-wl5S-jXhZbfS3V3cP9akUTeQF_jgmlWDC06QhKSLnHOKA
2021-09-12 19:55:37 WARNING (MainThread) [homeassistant.helpers.service] Unable to find referenced entities light.hue_lightstrip_2
2021-09-12 19:55:58 ERROR (MainThread) [homeassistant] Error doing job: Future exception was never retrieved
Traceback (most recent call last):
  File "/usr/local/lib/python3.9/concurrent/futures/thread.py", line 52, in run
    result = self.fn(*self.args, **self.kwargs)
TypeError: update() takes 1 positional argument but 2 were given
2021-09-12 19:56:22 WARNING (MainThread) [homeassistant.helpers.service] Unable to find referenced entities light.hue_lightstrip_2
2021-09-12 19:56:31 ERROR (stream_worker) [libav.rtsp] method DESCRIBE failed: 404 Not Found
2021-09-12 19:56:31 ERROR (stream_worker) [homeassistant.components.stream.worker] Error opening stream rtsps://stream-uc2-bravo.dropcam.com:443/sdm_live_stream/CiQA2vuxr1SLu8rlYbOHo16R-04X0NNEKfeupmXLad7ICSMu8s8ScQAFjsOTS4_b71We2VG7vYgLakwq7JUxt6NJI0n_4qGM-a8nYLnRqRt-bpKX5HVk56GBFLsegX_YCrq7qGjicjVDCJLw6ikxOmGMNn5FOIzSK0Ae_WFyJ5hjvdjABw-qslkW0czaUaWbWG6Bc1HqAVEU?auth=g.0.eyJraWQiOiIyMzhiNTUxZmMyM2EyM2Y4M2E2ZTE3MmJjZTg0YmU3ZjgxMzAzMmM4IiwiYWxnIjoiUlMyNTYifQ.eyJpc3MiOiJuZXN0LXNlY3VyaXR5LWF1dGhwcm94eSIsInN1YiI6Im5lc3RfaWQ6bmVzdC1waG9lbml4LXByb2Q6MjEyMTgxNDEiLCJwb2wiOiIzcC1vYXV0aC1zY29wZS1BUElfU0RNX1NFUlZJQ0UtY2xpZW50LTIwMjQyNzMxODczNS1qNXQ5bWMyMzZqaG85YXMycWY0dTZxY3NmYW1kaGJ0ci5hcHBzLmdvb2dsZXVzZXJjb250ZW50LmNvbSIsImV4cCI6MTYzMTQ5ODQ1MH0.tPMv-EG32_XlvIZmCpKyJ12Ozu8zGClYp1WbDrqpdtTyfhR2w_a410FySS2m5ontP4dOlEIuwobL-EtLmC7L-UTsMkZcLFI3pkEY9bzONK24CGe3KJSdpE9hCkdK9L2SM9cAQ87j4pRr9OF5LP7YiLbVPpjZTsW_7ou_Y1g-yu5GA7Fnn5ehSKR-Iwq-ykUciC1-YbZfrAl55FYoBbZRRBiQL8r0leC9RcSSaG73vmI7i-2uemhDzysQlPcXt0nNJ9rzgRpE63NxmMxF4hGNUGOT7BWwoXVVsUJpLHnU-wl5S-jXhZbfS3V3cP9akUTeQF_jgmlWDC06QhKSLnHOKA
2021-09-12 20:00:51 ERROR (stream_worker) [libav.rtsp] method DESCRIBE failed: 404 Not Found
2021-09-12 20:00:51 ERROR (stream_worker) [homeassistant.components.stream.worker] Error opening stream rtsps://stream-uc2-bravo.dropcam.com:443/sdm_live_stream/CiQA2vuxr1SLu8rlYbOHo16R-04X0NNEKfeupmXLad7ICSMu8s8ScQAFjsOTS4_b71We2VG7vYgLakwq7JUxt6NJI0n_4qGM-a8nYLnRqRt-bpKX5HVk56GBFLsegX_YCrq7qGjicjVDCJLw6ikxOmGMNn5FOIzSK0Ae_WFyJ5hjvdjABw-qslkW0czaUaWbWG6Bc1HqAVEU?auth=g.0.eyJraWQiOiIyMzhiNTUxZmMyM2EyM2Y4M2E2ZTE3MmJjZTg0YmU3ZjgxMzAzMmM4IiwiYWxnIjoiUlMyNTYifQ.eyJpc3MiOiJuZXN0LXNlY3VyaXR5LWF1dGhwcm94eSIsInN1YiI6Im5lc3RfaWQ6bmVzdC1waG9lbml4LXByb2Q6MjEyMTgxNDEiLCJwb2wiOiIzcC1vYXV0aC1zY29wZS1BUElfU0RNX1NFUlZJQ0UtY2xpZW50LTIwMjQyNzMxODczNS1qNXQ5bWMyMzZqaG85YXMycWY0dTZxY3NmYW1kaGJ0ci5hcHBzLmdvb2dsZXVzZXJjb250ZW50LmNvbSIsImV4cCI6MTYzMTQ5ODQ1MH0.tPMv-EG32_XlvIZmCpKyJ12Ozu8zGClYp1WbDrqpdtTyfhR2w_a410FySS2m5ontP4dOlEIuwobL-EtLmC7L-UTsMkZcLFI3pkEY9bzONK24CGe3KJSdpE9hCkdK9L2SM9cAQ87j4pRr9OF5LP7YiLbVPpjZTsW_7ou_Y1g-yu5GA7Fnn5ehSKR-Iwq-ykUciC1-YbZfrAl55FYoBbZRRBiQL8r0leC9RcSSaG73vmI7i-2uemhDzysQlPcXt0nNJ9rzgRpE63NxmMxF4hGNUGOT7BWwoXVVsUJpLHnU-wl5S-jXhZbfS3V3cP9akUTeQF_jgmlWDC06QhKSLnHOKA
2021-09-12 20:00:59 ERROR (MainThread) [homeassistant] Error doing job: Future exception was never retrieved
Traceback (most recent call last):
  File "/usr/local/lib/python3.9/concurrent/futures/thread.py", line 52, in run
    result = self.fn(*self.args, **self.kwargs)
TypeError: update() takes 1 positional argument but 2 were given
2021-09-12 20:04:42 WARNING (MainThread) [homeassistant.helpers.service] Unable to find referenced entities light.hue_lightstrip_2
2021-09-12 20:05:22 ERROR (stream_worker) [libav.rtsp] method DESCRIBE failed: 404 Not Found
2021-09-12 20:05:22 ERROR (stream_worker) [homeassistant.components.stream.worker] Error opening stream rtsps://stream-uc2-bravo.dropcam.com:443/sdm_live_stream/CiQA2vuxr1SLu8rlYbOHo16R-04X0NNEKfeupmXLad7ICSMu8s8ScQAFjsOTS4_b71We2VG7vYgLakwq7JUxt6NJI0n_4qGM-a8nYLnRqRt-bpKX5HVk56GBFLsegX_YCrq7qGjicjVDCJLw6ikxOmGMNn5FOIzSK0Ae_WFyJ5hjvdjABw-qslkW0czaUaWbWG6Bc1HqAVEU?auth=g.0.eyJraWQiOiIyMzhiNTUxZmMyM2EyM2Y4M2E2ZTE3MmJjZTg0YmU3ZjgxMzAzMmM4IiwiYWxnIjoiUlMyNTYifQ.eyJpc3MiOiJuZXN0LXNlY3VyaXR5LWF1dGhwcm94eSIsInN1YiI6Im5lc3RfaWQ6bmVzdC1waG9lbml4LXByb2Q6MjEyMTgxNDEiLCJwb2wiOiIzcC1vYXV0aC1zY29wZS1BUElfU0RNX1NFUlZJQ0UtY2xpZW50LTIwMjQyNzMxODczNS1qNXQ5bWMyMzZqaG85YXMycWY0dTZxY3NmYW1kaGJ0ci5hcHBzLmdvb2dsZXVzZXJjb250ZW50LmNvbSIsImV4cCI6MTYzMTQ5ODQ1MH0.tPMv-EG32_XlvIZmCpKyJ12Ozu8zGClYp1WbDrqpdtTyfhR2w_a410FySS2m5ontP4dOlEIuwobL-EtLmC7L-UTsMkZcLFI3pkEY9bzONK24CGe3KJSdpE9hCkdK9L2SM9cAQ87j4pRr9OF5LP7YiLbVPpjZTsW_7ou_Y1g-yu5GA7Fnn5ehSKR-Iwq-ykUciC1-YbZfrAl55FYoBbZRRBiQL8r0leC9RcSSaG73vmI7i-2uemhDzysQlPcXt0nNJ9rzgRpE63NxmMxF4hGNUGOT7BWwoXVVsUJpLHnU-wl5S-jXhZbfS3V3cP9akUTeQF_jgmlWDC06QhKSLnHOKA
2021-09-12 20:06:00 ERROR (MainThread) [homeassistant] Error doing job: Future exception was never retrieved
Traceback (most recent call last):
  File "/usr/local/lib/python3.9/concurrent/futures/thread.py", line 52, in run
    result = self.fn(*self.args, **self.kwargs)
TypeError: update() takes 1 positional argument but 2 were given
2021-09-12 20:09:32 ERROR (stream_worker) [homeassistant.components.stream.worker] Error opening stream rtsps://stream-uc2-delta.dropcam.com:443/sdm_live_stream/CiQA2vuxr70CRx2gK8IRmLITNFF032c4dkVUVFEPjSiot_nPtdkScQAFjsOTeLoFyxqJAyv7itMSpamqPm-sOSWbJVUkhKBpkVf4At5KSgRU8_keohbk6Jv-nN1YcRTUbAE8QIYS29993MKo34mCnPbDtaeqsMOxElEcJuWTAQlGp9HPqHLiZJ5JwthadbQD0aS-ZW5Ae7Gv?auth=g.0.eyJraWQiOiIyMzhiNTUxZmMyM2EyM2Y4M2E2ZTE3MmJjZTg0YmU3ZjgxMzAzMmM4IiwiYWxnIjoiUlMyNTYifQ.eyJpc3MiOiJuZXN0LXNlY3VyaXR5LWF1dGhwcm94eSIsInN1YiI6Im5lc3RfaWQ6bmVzdC1waG9lbml4LXByb2Q6MjEyMTgxNDEiLCJwb2wiOiIzcC1vYXV0aC1zY29wZS1BUElfU0RNX1NFUlZJQ0UtY2xpZW50LTIwMjQyNzMxODczNS1qNXQ5bWMyMzZqaG85YXMycWY0dTZxY3NmYW1kaGJ0ci5hcHBzLmdvb2dsZXVzZXJjb250ZW50LmNvbSIsImV4cCI6MTYzMTUwMjc4MX0.d3ofmDY-Ht42tUMq_CTIgwRARAsF5v5PCo1s0xnZe0-q50YGJsAMAStujO5uZdVV-Ygm0iHjGPD3Pk3madk7jid1A6rGJ0xeh4rr3idTbvZKynX3Zq_i0D-_kgBXgs3aCzCzHvpISTPph5i8gWokPx5u0ftIdam3QKBJkFYBtmijsEJ2HSVGySdLeHNuExfPswP8mTs1dGOzvriO9VbS-YpoM6qZIiOta-V5dMZ3dgW7j7oZVi8VTcS-6zqKEiZPEgEYlfYdtkfdMVDvOQPcBoQzgG1zfmvMBDecvChrbwgN_ml8UlBVy36v9Yptq5RmN7i5uNo2L2EgIOGYg6d2Iw
2021-09-12 20:10:03 ERROR (stream_worker) [libav.rtsp] method DESCRIBE failed: 404 Not Found
2021-09-12 20:10:03 ERROR (stream_worker) [homeassistant.components.stream.worker] Error opening stream rtsps://stream-uc2-bravo.dropcam.com:443/sdm_live_stream/CiQA2vuxr1SLu8rlYbOHo16R-04X0NNEKfeupmXLad7ICSMu8s8ScQAFjsOTS4_b71We2VG7vYgLakwq7JUxt6NJI0n_4qGM-a8nYLnRqRt-bpKX5HVk56GBFLsegX_YCrq7qGjicjVDCJLw6ikxOmGMNn5FOIzSK0Ae_WFyJ5hjvdjABw-qslkW0czaUaWbWG6Bc1HqAVEU?auth=g.0.eyJraWQiOiIyMzhiNTUxZmMyM2EyM2Y4M2E2ZTE3MmJjZTg0YmU3ZjgxMzAzMmM4IiwiYWxnIjoiUlMyNTYifQ.eyJpc3MiOiJuZXN0LXNlY3VyaXR5LWF1dGhwcm94eSIsInN1YiI6Im5lc3RfaWQ6bmVzdC1waG9lbml4LXByb2Q6MjEyMTgxNDEiLCJwb2wiOiIzcC1vYXV0aC1zY29wZS1BUElfU0RNX1NFUlZJQ0UtY2xpZW50LTIwMjQyNzMxODczNS1qNXQ5bWMyMzZqaG85YXMycWY0dTZxY3NmYW1kaGJ0ci5hcHBzLmdvb2dsZXVzZXJjb250ZW50LmNvbSIsImV4cCI6MTYzMTQ5ODQ1MH0.tPMv-EG32_XlvIZmCpKyJ12Ozu8zGClYp1WbDrqpdtTyfhR2w_a410FySS2m5ontP4dOlEIuwobL-EtLmC7L-UTsMkZcLFI3pkEY9bzONK24CGe3KJSdpE9hCkdK9L2SM9cAQ87j4pRr9OF5LP7YiLbVPpjZTsW_7ou_Y1g-yu5GA7Fnn5ehSKR-Iwq-ykUciC1-YbZfrAl55FYoBbZRRBiQL8r0leC9RcSSaG73vmI7i-2uemhDzysQlPcXt0nNJ9rzgRpE63NxmMxF4hGNUGOT7BWwoXVVsUJpLHnU-wl5S-jXhZbfS3V3cP9akUTeQF_jgmlWDC06QhKSLnHOKA
2021-09-12 20:11:01 ERROR (MainThread) [homeassistant] Error doing job: Future exception was never retrieved
Traceback (most recent call last):
  File "/usr/local/lib/python3.9/concurrent/futures/thread.py", line 52, in run
    result = self.fn(*self.args, **self.kwargs)
TypeError: update() takes 1 positional argument but 2 were given
2021-09-12 20:14:53 ERROR (stream_worker) [libav.rtsp] method DESCRIBE failed: 404 Not Found
2021-09-12 20:14:53 ERROR (stream_worker) [homeassistant.components.stream.worker] Error opening stream rtsps://stream-uc2-bravo.dropcam.com:443/sdm_live_stream/CiQA2vuxr1SLu8rlYbOHo16R-04X0NNEKfeupmXLad7ICSMu8s8ScQAFjsOTS4_b71We2VG7vYgLakwq7JUxt6NJI0n_4qGM-a8nYLnRqRt-bpKX5HVk56GBFLsegX_YCrq7qGjicjVDCJLw6ikxOmGMNn5FOIzSK0Ae_WFyJ5hjvdjABw-qslkW0czaUaWbWG6Bc1HqAVEU?auth=g.0.eyJraWQiOiIyMzhiNTUxZmMyM2EyM2Y4M2E2ZTE3MmJjZTg0YmU3ZjgxMzAzMmM4IiwiYWxnIjoiUlMyNTYifQ.eyJpc3MiOiJuZXN0LXNlY3VyaXR5LWF1dGhwcm94eSIsInN1YiI6Im5lc3RfaWQ6bmVzdC1waG9lbml4LXByb2Q6MjEyMTgxNDEiLCJwb2wiOiIzcC1vYXV0aC1zY29wZS1BUElfU0RNX1NFUlZJQ0UtY2xpZW50LTIwMjQyNzMxODczNS1qNXQ5bWMyMzZqaG85YXMycWY0dTZxY3NmYW1kaGJ0ci5hcHBzLmdvb2dsZXVzZXJjb250ZW50LmNvbSIsImV4cCI6MTYzMTQ5ODQ1MH0.tPMv-EG32_XlvIZmCpKyJ12Ozu8zGClYp1WbDrqpdtTyfhR2w_a410FySS2m5ontP4dOlEIuwobL-EtLmC7L-UTsMkZcLFI3pkEY9bzONK24CGe3KJSdpE9hCkdK9L2SM9cAQ87j4pRr9OF5LP7YiLbVPpjZTsW_7ou_Y1g-yu5GA7Fnn5ehSKR-Iwq-ykUciC1-YbZfrAl55FYoBbZRRBiQL8r0leC9RcSSaG73vmI7i-2uemhDzysQlPcXt0nNJ9rzgRpE63NxmMxF4hGNUGOT7BWwoXVVsUJpLHnU-wl5S-jXhZbfS3V3cP9akUTeQF_jgmlWDC06QhKSLnHOKA
2021-09-12 20:16:02 ERROR (MainThread) [homeassistant] Error doing job: Future exception was never retrieved
Traceback (most recent call last):
  File "/usr/local/lib/python3.9/concurrent/futures/thread.py", line 52, in run
    result = self.fn(*self.args, **self.kwargs)
TypeError: update() takes 1 positional argument but 2 were given
2021-09-12 20:19:54 ERROR (stream_worker) [libav.rtsp] method DESCRIBE failed: 404 Not Found
2021-09-12 20:19:54 ERROR (stream_worker) [homeassistant.components.stream.worker] Error opening stream rtsps://stream-uc2-bravo.dropcam.com:443/sdm_live_stream/CiQA2vuxr1SLu8rlYbOHo16R-04X0NNEKfeupmXLad7ICSMu8s8ScQAFjsOTS4_b71We2VG7vYgLakwq7JUxt6NJI0n_4qGM-a8nYLnRqRt-bpKX5HVk56GBFLsegX_YCrq7qGjicjVDCJLw6ikxOmGMNn5FOIzSK0Ae_WFyJ5hjvdjABw-qslkW0czaUaWbWG6Bc1HqAVEU?auth=g.0.eyJraWQiOiIyMzhiNTUxZmMyM2EyM2Y4M2E2ZTE3MmJjZTg0YmU3ZjgxMzAzMmM4IiwiYWxnIjoiUlMyNTYifQ.eyJpc3MiOiJuZXN0LXNlY3VyaXR5LWF1dGhwcm94eSIsInN1YiI6Im5lc3RfaWQ6bmVzdC1waG9lbml4LXByb2Q6MjEyMTgxNDEiLCJwb2wiOiIzcC1vYXV0aC1zY29wZS1BUElfU0RNX1NFUlZJQ0UtY2xpZW50LTIwMjQyNzMxODczNS1qNXQ5bWMyMzZqaG85YXMycWY0dTZxY3NmYW1kaGJ0ci5hcHBzLmdvb2dsZXVzZXJjb250ZW50LmNvbSIsImV4cCI6MTYzMTQ5ODQ1MH0.tPMv-EG32_XlvIZmCpKyJ12Ozu8zGClYp1WbDrqpdtTyfhR2w_a410FySS2m5ontP4dOlEIuwobL-EtLmC7L-UTsMkZcLFI3pkEY9bzONK24CGe3KJSdpE9hCkdK9L2SM9cAQ87j4pRr9OF5LP7YiLbVPpjZTsW_7ou_Y1g-yu5GA7Fnn5ehSKR-Iwq-ykUciC1-YbZfrAl55FYoBbZRRBiQL8r0leC9RcSSaG73vmI7i-2uemhDzysQlPcXt0nNJ9rzgRpE63NxmMxF4hGNUGOT7BWwoXVVsUJpLHnU-wl5S-jXhZbfS3V3cP9akUTeQF_jgmlWDC06QhKSLnHOKA
2021-09-12 20:21:03 ERROR (MainThread) [homeassistant] Error doing job: Future exception was never retrieved
Traceback (most recent call last):
  File "/usr/local/lib/python3.9/concurrent/futures/thread.py", line 52, in run
    result = self.fn(*self.args, **self.kwargs)
TypeError: update() takes 1 positional argument but 2 were given
2021-09-12 20:25:05 ERROR (stream_worker) [libav.rtsp] method DESCRIBE failed: 404 Not Found
2021-09-12 20:25:05 ERROR (stream_worker) [homeassistant.components.stream.worker] Error opening stream rtsps://stream-uc2-bravo.dropcam.com:443/sdm_live_stream/CiQA2vuxr1SLu8rlYbOHo16R-04X0NNEKfeupmXLad7ICSMu8s8ScQAFjsOTS4_b71We2VG7vYgLakwq7JUxt6NJI0n_4qGM-a8nYLnRqRt-bpKX5HVk56GBFLsegX_YCrq7qGjicjVDCJLw6ikxOmGMNn5FOIzSK0Ae_WFyJ5hjvdjABw-qslkW0czaUaWbWG6Bc1HqAVEU?auth=g.0.eyJraWQiOiIyMzhiNTUxZmMyM2EyM2Y4M2E2ZTE3MmJjZTg0YmU3ZjgxMzAzMmM4IiwiYWxnIjoiUlMyNTYifQ.eyJpc3MiOiJuZXN0LXNlY3VyaXR5LWF1dGhwcm94eSIsInN1YiI6Im5lc3RfaWQ6bmVzdC1waG9lbml4LXByb2Q6MjEyMTgxNDEiLCJwb2wiOiIzcC1vYXV0aC1zY29wZS1BUElfU0RNX1NFUlZJQ0UtY2xpZW50LTIwMjQyNzMxODczNS1qNXQ5bWMyMzZqaG85YXMycWY0dTZxY3NmYW1kaGJ0ci5hcHBzLmdvb2dsZXVzZXJjb250ZW50LmNvbSIsImV4cCI6MTYzMTQ5ODQ1MH0.tPMv-EG32_XlvIZmCpKyJ12Ozu8zGClYp1WbDrqpdtTyfhR2w_a410FySS2m5ontP4dOlEIuwobL-EtLmC7L-UTsMkZcLFI3pkEY9bzONK24CGe3KJSdpE9hCkdK9L2SM9cAQ87j4pRr9OF5LP7YiLbVPpjZTsW_7ou_Y1g-yu5GA7Fnn5ehSKR-Iwq-ykUciC1-YbZfrAl55FYoBbZRRBiQL8r0leC9RcSSaG73vmI7i-2uemhDzysQlPcXt0nNJ9rzgRpE63NxmMxF4hGNUGOT7BWwoXVVsUJpLHnU-wl5S-jXhZbfS3V3cP9akUTeQF_jgmlWDC06QhKSLnHOKA
2021-09-12 20:26:04 ERROR (MainThread) [homeassistant] Error doing job: Future exception was never retrieved
Traceback (most recent call last):
  File "/usr/local/lib/python3.9/concurrent/futures/thread.py", line 52, in run
    result = self.fn(*self.args, **self.kwargs)
TypeError: update() takes 1 positional argument but 2 were given
2021-09-12 20:30:25 ERROR (stream_worker) [libav.rtsp] method DESCRIBE failed: 404 Not Found
2021-09-12 20:30:25 ERROR (stream_worker) [homeassistant.components.stream.worker] Error opening stream rtsps://stream-uc2-bravo.dropcam.com:443/sdm_live_stream/CiQA2vuxr1SLu8rlYbOHo16R-04X0NNEKfeupmXLad7ICSMu8s8ScQAFjsOTS4_b71We2VG7vYgLakwq7JUxt6NJI0n_4qGM-a8nYLnRqRt-bpKX5HVk56GBFLsegX_YCrq7qGjicjVDCJLw6ikxOmGMNn5FOIzSK0Ae_WFyJ5hjvdjABw-qslkW0czaUaWbWG6Bc1HqAVEU?auth=g.0.eyJraWQiOiIyMzhiNTUxZmMyM2EyM2Y4M2E2ZTE3MmJjZTg0YmU3ZjgxMzAzMmM4IiwiYWxnIjoiUlMyNTYifQ.eyJpc3MiOiJuZXN0LXNlY3VyaXR5LWF1dGhwcm94eSIsInN1YiI6Im5lc3RfaWQ6bmVzdC1waG9lbml4LXByb2Q6MjEyMTgxNDEiLCJwb2wiOiIzcC1vYXV0aC1zY29wZS1BUElfU0RNX1NFUlZJQ0UtY2xpZW50LTIwMjQyNzMxODczNS1qNXQ5bWMyMzZqaG85YXMycWY0dTZxY3NmYW1kaGJ0ci5hcHBzLmdvb2dsZXVzZXJjb250ZW50LmNvbSIsImV4cCI6MTYzMTQ5ODQ1MH0.tPMv-EG32_XlvIZmCpKyJ12Ozu8zGClYp1WbDrqpdtTyfhR2w_a410FySS2m5ontP4dOlEIuwobL-EtLmC7L-UTsMkZcLFI3pkEY9bzONK24CGe3KJSdpE9hCkdK9L2SM9cAQ87j4pRr9OF5LP7YiLbVPpjZTsW_7ou_Y1g-yu5GA7Fnn5ehSKR-Iwq-ykUciC1-YbZfrAl55FYoBbZRRBiQL8r0leC9RcSSaG73vmI7i-2uemhDzysQlPcXt0nNJ9rzgRpE63NxmMxF4hGNUGOT7BWwoXVVsUJpLHnU-wl5S-jXhZbfS3V3cP9akUTeQF_jgmlWDC06QhKSLnHOKA
2021-09-12 20:31:05 ERROR (MainThread) [homeassistant] Error doing job: Future exception was never retrieved
Traceback (most recent call last):
  File "/usr/local/lib/python3.9/concurrent/futures/thread.py", line 52, in run
    result = self.fn(*self.args, **self.kwargs)
TypeError: update() takes 1 positional argument but 2 were given
2021-09-12 20:31:36 ERROR (MainThread) [iotawattpy.connection] Err: 
2021-09-12 20:31:36 ERROR (MainThread) [homeassistant.components.iotawatt.coordinator] Unexpected error fetching 192.168.20.195 data: 'NoneType' object has no attribute 'text'
Traceback (most recent call last):
  File "/usr/src/homeassistant/homeassistant/helpers/update_coordinator.py", line 187, in _async_refresh
    self.data = await self._async_update_data()
  File "/usr/src/homeassistant/homeassistant/components/iotawatt/coordinator.py", line 55, in _async_update_data
    await self.api.update()
  File "/usr/local/lib/python3.9/site-packages/iotawattpy/iotawatt.py", line 66, in update
    await self._refreshSensors(timespan)
  File "/usr/local/lib/python3.9/site-packages/iotawattpy/iotawatt.py", line 100, in _refreshSensors
    results = response.text
AttributeError: 'NoneType' object has no attribute 'text'
2021-09-12 20:35:55 ERROR (stream_worker) [libav.rtsp] method DESCRIBE failed: 404 Not Found
2021-09-12 20:35:55 ERROR (stream_worker) [homeassistant.components.stream.worker] Error opening stream rtsps://stream-uc2-bravo.dropcam.com:443/sdm_live_stream/CiQA2vuxr1SLu8rlYbOHo16R-04X0NNEKfeupmXLad7ICSMu8s8ScQAFjsOTS4_b71We2VG7vYgLakwq7JUxt6NJI0n_4qGM-a8nYLnRqRt-bpKX5HVk56GBFLsegX_YCrq7qGjicjVDCJLw6ikxOmGMNn5FOIzSK0Ae_WFyJ5hjvdjABw-qslkW0czaUaWbWG6Bc1HqAVEU?auth=g.0.eyJraWQiOiIyMzhiNTUxZmMyM2EyM2Y4M2E2ZTE3MmJjZTg0YmU3ZjgxMzAzMmM4IiwiYWxnIjoiUlMyNTYifQ.eyJpc3MiOiJuZXN0LXNlY3VyaXR5LWF1dGhwcm94eSIsInN1YiI6Im5lc3RfaWQ6bmVzdC1waG9lbml4LXByb2Q6MjEyMTgxNDEiLCJwb2wiOiIzcC1vYXV0aC1zY29wZS1BUElfU0RNX1NFUlZJQ0UtY2xpZW50LTIwMjQyNzMxODczNS1qNXQ5bWMyMzZqaG85YXMycWY0dTZxY3NmYW1kaGJ0ci5hcHBzLmdvb2dsZXVzZXJjb250ZW50LmNvbSIsImV4cCI6MTYzMTQ5ODQ1MH0.tPMv-EG32_XlvIZmCpKyJ12Ozu8zGClYp1WbDrqpdtTyfhR2w_a410FySS2m5ontP4dOlEIuwobL-EtLmC7L-UTsMkZcLFI3pkEY9bzONK24CGe3KJSdpE9hCkdK9L2SM9cAQ87j4pRr9OF5LP7YiLbVPpjZTsW_7ou_Y1g-yu5GA7Fnn5ehSKR-Iwq-ykUciC1-YbZfrAl55FYoBbZRRBiQL8r0leC9RcSSaG73vmI7i-2uemhDzysQlPcXt0nNJ9rzgRpE63NxmMxF4hGNUGOT7BWwoXVVsUJpLHnU-wl5S-jXhZbfS3V3cP9akUTeQF_jgmlWDC06QhKSLnHOKA
2021-09-12 20:36:06 ERROR (MainThread) [homeassistant] Error doing job: Future exception was never retrieved
Traceback (most recent call last):
  File "/usr/local/lib/python3.9/concurrent/futures/thread.py", line 52, in run
    result = self.fn(*self.args, **self.kwargs)
TypeError: update() takes 1 positional argument but 2 were given
2021-09-12 20:36:27 ERROR (stream_worker) [libav.rtsp] method DESCRIBE failed: 404 Not Found
2021-09-12 20:36:27 ERROR (stream_worker) [homeassistant.components.stream.worker] Error opening stream rtsps://stream-uc2-delta.dropcam.com:443/sdm_live_stream/CiQA2vuxr70CRx2gK8IRmLITNFF032c4dkVUVFEPjSiot_nPtdkScQAFjsOTeLoFyxqJAyv7itMSpamqPm-sOSWbJVUkhKBpkVf4At5KSgRU8_keohbk6Jv-nN1YcRTUbAE8QIYS29993MKo34mCnPbDtaeqsMOxElEcJuWTAQlGp9HPqHLiZJ5JwthadbQD0aS-ZW5Ae7Gv?auth=g.0.eyJraWQiOiIyMzhiNTUxZmMyM2EyM2Y4M2E2ZTE3MmJjZTg0YmU3ZjgxMzAzMmM4IiwiYWxnIjoiUlMyNTYifQ.eyJpc3MiOiJuZXN0LXNlY3VyaXR5LWF1dGhwcm94eSIsInN1YiI6Im5lc3RfaWQ6bmVzdC1waG9lbml4LXByb2Q6MjEyMTgxNDEiLCJwb2wiOiIzcC1vYXV0aC1zY29wZS1BUElfU0RNX1NFUlZJQ0UtY2xpZW50LTIwMjQyNzMxODczNS1qNXQ5bWMyMzZqaG85YXMycWY0dTZxY3NmYW1kaGJ0ci5hcHBzLmdvb2dsZXVzZXJjb250ZW50LmNvbSIsImV4cCI6MTYzMTUwNDQwNH0.s3xP1pHvFjAk8K6FTQWA155p3_OL9fBEJPa1PVNZmeU3ul1jI2RVKegWhjAxdI7ZYpU5NrR7qr1It88swNZl1hLZSNsWlmoI6h4VFxbmaER0jJ-j1VEX_AvP1oQ1lxfraR5bGKy8eaH3fVRUlJoO22Zici7aY1E4eom-c1w-eQhRYQFxYsP8ucHJQrqfr9qFCgNsQljSbi3vCGfPKeM8vfsoknNfWmhAwwV2IFT2M4FM13N_V1Y8LfdBqGaWTsR7AvmlI7VjgEWSUAcgRhNgadJiCDO1QLSV0zyRbPhyX6be6t_WqWTgbECZZNWccEyXN9yF1Wtjwm2l_lRXOnG5bQ
2021-09-12 20:41:07 ERROR (MainThread) [homeassistant] Error doing job: Future exception was never retrieved
Traceback (most recent call last):
  File "/usr/local/lib/python3.9/concurrent/futures/thread.py", line 52, in run
    result = self.fn(*self.args, **self.kwargs)
TypeError: update() takes 1 positional argument but 2 were given
2021-09-12 20:41:07 ERROR (stream_worker) [libav.rtsp] method DESCRIBE failed: 404 Not Found
2021-09-12 20:41:07 ERROR (stream_worker) [homeassistant.components.stream.worker] Error opening stream rtsps://stream-uc2-delta.dropcam.com:443/sdm_live_stream/CiQA2vuxr70CRx2gK8IRmLITNFF032c4dkVUVFEPjSiot_nPtdkScQAFjsOTeLoFyxqJAyv7itMSpamqPm-sOSWbJVUkhKBpkVf4At5KSgRU8_keohbk6Jv-nN1YcRTUbAE8QIYS29993MKo34mCnPbDtaeqsMOxElEcJuWTAQlGp9HPqHLiZJ5JwthadbQD0aS-ZW5Ae7Gv?auth=g.0.eyJraWQiOiIyMzhiNTUxZmMyM2EyM2Y4M2E2ZTE3MmJjZTg0YmU3ZjgxMzAzMmM4IiwiYWxnIjoiUlMyNTYifQ.eyJpc3MiOiJuZXN0LXNlY3VyaXR5LWF1dGhwcm94eSIsInN1YiI6Im5lc3RfaWQ6bmVzdC1waG9lbml4LXByb2Q6MjEyMTgxNDEiLCJwb2wiOiIzcC1vYXV0aC1zY29wZS1BUElfU0RNX1NFUlZJQ0UtY2xpZW50LTIwMjQyNzMxODczNS1qNXQ5bWMyMzZqaG85YXMycWY0dTZxY3NmYW1kaGJ0ci5hcHBzLmdvb2dsZXVzZXJjb250ZW50LmNvbSIsImV4cCI6MTYzMTUwNDY3NX0.hkjN_yZGRcasQkApFZ8tJMoCAn46MnDAE78GmPmWD4S6d_IZx8cHB1DI9A_chDfqrjjzYl2ukx3Eu9TlFJ7pzziUssYkewaJzCEgyGuCRQbIGQF5JQnvFZSikfQjVgyr8_Tni9i4bkTyKk6eDVHI3bF1x7D4Q7c8v_2F-2PRD2sR-0dWiyMfCYL_5ixM9K1bGyjWPF-CATXbHd3jfEBcjdefMFRqACJGGiXHWmf-3xN-1Bl81PGARYrxrRQ320fOkrkbhWD1BU-8HVTifyTAbxVVS6g0_eZZ2PyWMg2ay9NsMLaQvpuPDehRgZ7gNbCUtobta3AU2gG_YNKL-W2xUg
2021-09-12 20:41:36 ERROR (stream_worker) [libav.rtsp] method DESCRIBE failed: 404 Not Found
2021-09-12 20:41:36 ERROR (stream_worker) [homeassistant.components.stream.worker] Error opening stream rtsps://stream-uc2-bravo.dropcam.com:443/sdm_live_stream/CiQA2vuxr1SLu8rlYbOHo16R-04X0NNEKfeupmXLad7ICSMu8s8ScQAFjsOTS4_b71We2VG7vYgLakwq7JUxt6NJI0n_4qGM-a8nYLnRqRt-bpKX5HVk56GBFLsegX_YCrq7qGjicjVDCJLw6ikxOmGMNn5FOIzSK0Ae_WFyJ5hjvdjABw-qslkW0czaUaWbWG6Bc1HqAVEU?auth=g.0.eyJraWQiOiIyMzhiNTUxZmMyM2EyM2Y4M2E2ZTE3MmJjZTg0YmU3ZjgxMzAzMmM4IiwiYWxnIjoiUlMyNTYifQ.eyJpc3MiOiJuZXN0LXNlY3VyaXR5LWF1dGhwcm94eSIsInN1YiI6Im5lc3RfaWQ6bmVzdC1waG9lbml4LXByb2Q6MjEyMTgxNDEiLCJwb2wiOiIzcC1vYXV0aC1zY29wZS1BUElfU0RNX1NFUlZJQ0UtY2xpZW50LTIwMjQyNzMxODczNS1qNXQ5bWMyMzZqaG85YXMycWY0dTZxY3NmYW1kaGJ0ci5hcHBzLmdvb2dsZXVzZXJjb250ZW50LmNvbSIsImV4cCI6MTYzMTQ5ODQ1MH0.tPMv-EG32_XlvIZmCpKyJ12Ozu8zGClYp1WbDrqpdtTyfhR2w_a410FySS2m5ontP4dOlEIuwobL-EtLmC7L-UTsMkZcLFI3pkEY9bzONK24CGe3KJSdpE9hCkdK9L2SM9cAQ87j4pRr9OF5LP7YiLbVPpjZTsW_7ou_Y1g-yu5GA7Fnn5ehSKR-Iwq-ykUciC1-YbZfrAl55FYoBbZRRBiQL8r0leC9RcSSaG73vmI7i-2uemhDzysQlPcXt0nNJ9rzgRpE63NxmMxF4hGNUGOT7BWwoXVVsUJpLHnU-wl5S-jXhZbfS3V3cP9akUTeQF_jgmlWDC06QhKSLnHOKA
2021-09-12 20:42:48 ERROR (stream_worker) [libav.rtsp] method DESCRIBE failed: 404 Not Found
2021-09-12 20:42:48 ERROR (stream_worker) [homeassistant.components.stream.worker] Error opening stream rtsps://stream-uc2-delta.dropcam.com:443/sdm_live_stream/CiQA2vuxr70CRx2gK8IRmLITNFF032c4dkVUVFEPjSiot_nPtdkScQAFjsOTeLoFyxqJAyv7itMSpamqPm-sOSWbJVUkhKBpkVf4At5KSgRU8_keohbk6Jv-nN1YcRTUbAE8QIYS29993MKo34mCnPbDtaeqsMOxElEcJuWTAQlGp9HPqHLiZJ5JwthadbQD0aS-ZW5Ae7Gv?auth=g.0.eyJraWQiOiIyMzhiNTUxZmMyM2EyM2Y4M2E2ZTE3MmJjZTg0YmU3ZjgxMzAzMmM4IiwiYWxnIjoiUlMyNTYifQ.eyJpc3MiOiJuZXN0LXNlY3VyaXR5LWF1dGhwcm94eSIsInN1YiI6Im5lc3RfaWQ6bmVzdC1waG9lbml4LXByb2Q6MjEyMTgxNDEiLCJwb2wiOiIzcC1vYXV0aC1zY29wZS1BUElfU0RNX1NFUlZJQ0UtY2xpZW50LTIwMjQyNzMxODczNS1qNXQ5bWMyMzZqaG85YXMycWY0dTZxY3NmYW1kaGJ0ci5hcHBzLmdvb2dsZXVzZXJjb250ZW50LmNvbSIsImV4cCI6MTYzMTUwNDY3NX0.hkjN_yZGRcasQkApFZ8tJMoCAn46MnDAE78GmPmWD4S6d_IZx8cHB1DI9A_chDfqrjjzYl2ukx3Eu9TlFJ7pzziUssYkewaJzCEgyGuCRQbIGQF5JQnvFZSikfQjVgyr8_Tni9i4bkTyKk6eDVHI3bF1x7D4Q7c8v_2F-2PRD2sR-0dWiyMfCYL_5ixM9K1bGyjWPF-CATXbHd3jfEBcjdefMFRqACJGGiXHWmf-3xN-1Bl81PGARYrxrRQ320fOkrkbhWD1BU-8HVTifyTAbxVVS6g0_eZZ2PyWMg2ay9NsMLaQvpuPDehRgZ7gNbCUtobta3AU2gG_YNKL-W2xUg
2021-09-12 20:46:08 ERROR (MainThread) [homeassistant] Error doing job: Future exception was never retrieved
Traceback (most recent call last):
  File "/usr/local/lib/python3.9/concurrent/futures/thread.py", line 52, in run
    result = self.fn(*self.args, **self.kwargs)
TypeError: update() takes 1 positional argument but 2 were given
2021-09-12 20:47:26 ERROR (stream_worker) [libav.rtsp] method DESCRIBE failed: 404 Not Found
2021-09-12 20:47:26 ERROR (stream_worker) [homeassistant.components.stream.worker] Error opening stream rtsps://stream-uc2-bravo.dropcam.com:443/sdm_live_stream/CiQA2vuxr1SLu8rlYbOHo16R-04X0NNEKfeupmXLad7ICSMu8s8ScQAFjsOTS4_b71We2VG7vYgLakwq7JUxt6NJI0n_4qGM-a8nYLnRqRt-bpKX5HVk56GBFLsegX_YCrq7qGjicjVDCJLw6ikxOmGMNn5FOIzSK0Ae_WFyJ5hjvdjABw-qslkW0czaUaWbWG6Bc1HqAVEU?auth=g.0.eyJraWQiOiIyMzhiNTUxZmMyM2EyM2Y4M2E2ZTE3MmJjZTg0YmU3ZjgxMzAzMmM4IiwiYWxnIjoiUlMyNTYifQ.eyJpc3MiOiJuZXN0LXNlY3VyaXR5LWF1dGhwcm94eSIsInN1YiI6Im5lc3RfaWQ6bmVzdC1waG9lbml4LXByb2Q6MjEyMTgxNDEiLCJwb2wiOiIzcC1vYXV0aC1zY29wZS1BUElfU0RNX1NFUlZJQ0UtY2xpZW50LTIwMjQyNzMxODczNS1qNXQ5bWMyMzZqaG85YXMycWY0dTZxY3NmYW1kaGJ0ci5hcHBzLmdvb2dsZXVzZXJjb250ZW50LmNvbSIsImV4cCI6MTYzMTQ5ODQ1MH0.tPMv-EG32_XlvIZmCpKyJ12Ozu8zGClYp1WbDrqpdtTyfhR2w_a410FySS2m5ontP4dOlEIuwobL-EtLmC7L-UTsMkZcLFI3pkEY9bzONK24CGe3KJSdpE9hCkdK9L2SM9cAQ87j4pRr9OF5LP7YiLbVPpjZTsW_7ou_Y1g-yu5GA7Fnn5ehSKR-Iwq-ykUciC1-YbZfrAl55FYoBbZRRBiQL8r0leC9RcSSaG73vmI7i-2uemhDzysQlPcXt0nNJ9rzgRpE63NxmMxF4hGNUGOT7BWwoXVVsUJpLHnU-wl5S-jXhZbfS3V3cP9akUTeQF_jgmlWDC06QhKSLnHOKA
2021-09-12 20:51:09 ERROR (MainThread) [homeassistant] Error doing job: Future exception was never retrieved
Traceback (most recent call last):
  File "/usr/local/lib/python3.9/concurrent/futures/thread.py", line 52, in run
    result = self.fn(*self.args, **self.kwargs)
TypeError: update() takes 1 positional argument but 2 were given
2021-09-12 20:53:27 ERROR (stream_worker) [libav.rtsp] method DESCRIBE failed: 404 Not Found
2021-09-12 20:53:27 ERROR (stream_worker) [homeassistant.components.stream.worker] Error opening stream rtsps://stream-uc2-bravo.dropcam.com:443/sdm_live_stream/CiQA2vuxr1SLu8rlYbOHo16R-04X0NNEKfeupmXLad7ICSMu8s8ScQAFjsOTS4_b71We2VG7vYgLakwq7JUxt6NJI0n_4qGM-a8nYLnRqRt-bpKX5HVk56GBFLsegX_YCrq7qGjicjVDCJLw6ikxOmGMNn5FOIzSK0Ae_WFyJ5hjvdjABw-qslkW0czaUaWbWG6Bc1HqAVEU?auth=g.0.eyJraWQiOiIyMzhiNTUxZmMyM2EyM2Y4M2E2ZTE3MmJjZTg0YmU3ZjgxMzAzMmM4IiwiYWxnIjoiUlMyNTYifQ.eyJpc3MiOiJuZXN0LXNlY3VyaXR5LWF1dGhwcm94eSIsInN1YiI6Im5lc3RfaWQ6bmVzdC1waG9lbml4LXByb2Q6MjEyMTgxNDEiLCJwb2wiOiIzcC1vYXV0aC1zY29wZS1BUElfU0RNX1NFUlZJQ0UtY2xpZW50LTIwMjQyNzMxODczNS1qNXQ5bWMyMzZqaG85YXMycWY0dTZxY3NmYW1kaGJ0ci5hcHBzLmdvb2dsZXVzZXJjb250ZW50LmNvbSIsImV4cCI6MTYzMTQ5ODQ1MH0.tPMv-EG32_XlvIZmCpKyJ12Ozu8zGClYp1WbDrqpdtTyfhR2w_a410FySS2m5ontP4dOlEIuwobL-EtLmC7L-UTsMkZcLFI3pkEY9bzONK24CGe3KJSdpE9hCkdK9L2SM9cAQ87j4pRr9OF5LP7YiLbVPpjZTsW_7ou_Y1g-yu5GA7Fnn5ehSKR-Iwq-ykUciC1-YbZfrAl55FYoBbZRRBiQL8r0leC9RcSSaG73vmI7i-2uemhDzysQlPcXt0nNJ9rzgRpE63NxmMxF4hGNUGOT7BWwoXVVsUJpLHnU-wl5S-jXhZbfS3V3cP9akUTeQF_jgmlWDC06QhKSLnHOKA
2021-09-12 20:56:10 ERROR (MainThread) [homeassistant] Error doing job: Future exception was never retrieved
Traceback (most recent call last):
  File "/usr/local/lib/python3.9/concurrent/futures/thread.py", line 52, in run
    result = self.fn(*self.args, **self.kwargs)
TypeError: update() takes 1 positional argument but 2 were given
2021-09-12 20:59:37 ERROR (stream_worker) [libav.rtsp] method DESCRIBE failed: 404 Not Found
2021-09-12 20:59:37 ERROR (stream_worker) [homeassistant.components.stream.worker] Error opening stream rtsps://stream-uc2-bravo.dropcam.com:443/sdm_live_stream/CiQA2vuxr1SLu8rlYbOHo16R-04X0NNEKfeupmXLad7ICSMu8s8ScQAFjsOTS4_b71We2VG7vYgLakwq7JUxt6NJI0n_4qGM-a8nYLnRqRt-bpKX5HVk56GBFLsegX_YCrq7qGjicjVDCJLw6ikxOmGMNn5FOIzSK0Ae_WFyJ5hjvdjABw-qslkW0czaUaWbWG6Bc1HqAVEU?auth=g.0.eyJraWQiOiIyMzhiNTUxZmMyM2EyM2Y4M2E2ZTE3MmJjZTg0YmU3ZjgxMzAzMmM4IiwiYWxnIjoiUlMyNTYifQ.eyJpc3MiOiJuZXN0LXNlY3VyaXR5LWF1dGhwcm94eSIsInN1YiI6Im5lc3RfaWQ6bmVzdC1waG9lbml4LXByb2Q6MjEyMTgxNDEiLCJwb2wiOiIzcC1vYXV0aC1zY29wZS1BUElfU0RNX1NFUlZJQ0UtY2xpZW50LTIwMjQyNzMxODczNS1qNXQ5bWMyMzZqaG85YXMycWY0dTZxY3NmYW1kaGJ0ci5hcHBzLmdvb2dsZXVzZXJjb250ZW50LmNvbSIsImV4cCI6MTYzMTQ5ODQ1MH0.tPMv-EG32_XlvIZmCpKyJ12Ozu8zGClYp1WbDrqpdtTyfhR2w_a410FySS2m5ontP4dOlEIuwobL-EtLmC7L-UTsMkZcLFI3pkEY9bzONK24CGe3KJSdpE9hCkdK9L2SM9cAQ87j4pRr9OF5LP7YiLbVPpjZTsW_7ou_Y1g-yu5GA7Fnn5ehSKR-Iwq-ykUciC1-YbZfrAl55FYoBbZRRBiQL8r0leC9RcSSaG73vmI7i-2uemhDzysQlPcXt0nNJ9rzgRpE63NxmMxF4hGNUGOT7BWwoXVVsUJpLHnU-wl5S-jXhZbfS3V3cP9akUTeQF_jgmlWDC06QhKSLnHOKA
2021-09-12 21:01:11 ERROR (MainThread) [homeassistant] Error doing job: Future exception was never retrieved
Traceback (most recent call last):
  File "/usr/local/lib/python3.9/concurrent/futures/thread.py", line 52, in run
    result = self.fn(*self.args, **self.kwargs)
TypeError: update() takes 1 positional argument but 2 were given
2021-09-12 21:05:59 ERROR (stream_worker) [libav.rtsp] method DESCRIBE failed: 404 Not Found
2021-09-12 21:05:59 ERROR (stream_worker) [homeassistant.components.stream.worker] Error opening stream rtsps://stream-uc2-bravo.dropcam.com:443/sdm_live_stream/CiQA2vuxr1SLu8rlYbOHo16R-04X0NNEKfeupmXLad7ICSMu8s8ScQAFjsOTS4_b71We2VG7vYgLakwq7JUxt6NJI0n_4qGM-a8nYLnRqRt-bpKX5HVk56GBFLsegX_YCrq7qGjicjVDCJLw6ikxOmGMNn5FOIzSK0Ae_WFyJ5hjvdjABw-qslkW0czaUaWbWG6Bc1HqAVEU?auth=g.0.eyJraWQiOiIyMzhiNTUxZmMyM2EyM2Y4M2E2ZTE3MmJjZTg0YmU3ZjgxMzAzMmM4IiwiYWxnIjoiUlMyNTYifQ.eyJpc3MiOiJuZXN0LXNlY3VyaXR5LWF1dGhwcm94eSIsInN1YiI6Im5lc3RfaWQ6bmVzdC1waG9lbml4LXByb2Q6MjEyMTgxNDEiLCJwb2wiOiIzcC1vYXV0aC1zY29wZS1BUElfU0RNX1NFUlZJQ0UtY2xpZW50LTIwMjQyNzMxODczNS1qNXQ5bWMyMzZqaG85YXMycWY0dTZxY3NmYW1kaGJ0ci5hcHBzLmdvb2dsZXVzZXJjb250ZW50LmNvbSIsImV4cCI6MTYzMTQ5ODQ1MH0.tPMv-EG32_XlvIZmCpKyJ12Ozu8zGClYp1WbDrqpdtTyfhR2w_a410FySS2m5ontP4dOlEIuwobL-EtLmC7L-UTsMkZcLFI3pkEY9bzONK24CGe3KJSdpE9hCkdK9L2SM9cAQ87j4pRr9OF5LP7YiLbVPpjZTsW_7ou_Y1g-yu5GA7Fnn5ehSKR-Iwq-ykUciC1-YbZfrAl55FYoBbZRRBiQL8r0leC9RcSSaG73vmI7i-2uemhDzysQlPcXt0nNJ9rzgRpE63NxmMxF4hGNUGOT7BWwoXVVsUJpLHnU-wl5S-jXhZbfS3V3cP9akUTeQF_jgmlWDC06QhKSLnHOKA
2021-09-12 21:06:12 ERROR (MainThread) [homeassistant] Error doing job: Future exception was never retrieved
Traceback (most recent call last):
  File "/usr/local/lib/python3.9/concurrent/futures/thread.py", line 52, in run
    result = self.fn(*self.args, **self.kwargs)
TypeError: update() takes 1 positional argument but 2 were given
2021-09-12 21:09:56 ERROR (MainThread) [homeassistant.components.nws] Error requesting NWS observation station SAUC1 data: 503, message='Service Unavailable', url=URL('https://api.weather.gov/stations/SAUC1/observations')
2021-09-12 21:11:13 ERROR (MainThread) [homeassistant] Error doing job: Future exception was never retrieved
Traceback (most recent call last):
  File "/usr/local/lib/python3.9/concurrent/futures/thread.py", line 52, in run
    result = self.fn(*self.args, **self.kwargs)
TypeError: update() takes 1 positional argument but 2 were given
2021-09-12 21:12:00 WARNING (Recorder) [homeassistant.components.sensor.recorder] sensor.daily_tesla_energy has unknown unit None
2021-09-12 21:12:00 WARNING (Recorder) [homeassistant.components.sensor.recorder] The unit of sensor.daily_tesla_energy (kWh) does not match the unit of already compiled statistics (None). Generation of long term statistics will be suppressed unless the unit changes back to None
2021-09-12 21:12:00 WARNING (Recorder) [homeassistant.components.sensor.recorder] sensor.weekly_tesla_energy has unknown unit None
2021-09-12 21:12:00 WARNING (Recorder) [homeassistant.components.sensor.recorder] The unit of sensor.weekly_tesla_energy (kWh) does not match the unit of already compiled statistics (None). Generation of long term statistics will be suppressed unless the unit changes back to None
2021-09-12 21:12:00 WARNING (Recorder) [homeassistant.components.sensor.recorder] sensor.monthly_tesla_energy has unknown unit None
2021-09-12 21:12:00 WARNING (Recorder) [homeassistant.components.sensor.recorder] The unit of sensor.monthly_tesla_energy (kWh) does not match the unit of already compiled statistics (None). Generation of long term statistics will be suppressed unless the unit changes back to None
2021-09-12 21:12:00 WARNING (Recorder) [homeassistant.components.sensor.recorder] sensor.quarterly_tesla_energy has unknown unit None
2021-09-12 21:12:00 WARNING (Recorder) [homeassistant.components.sensor.recorder] The unit of sensor.quarterly_tesla_energy (kWh) does not match the unit of already compiled statistics (None). Generation of long term statistics will be suppressed unless the unit changes back to None
2021-09-12 21:12:00 WARNING (Recorder) [homeassistant.components.sensor.recorder] sensor.yearly_tesla_energy has unknown unit None
2021-09-12 21:12:00 WARNING (Recorder) [homeassistant.components.sensor.recorder] The unit of sensor.yearly_tesla_energy (kWh) does not match the unit of already compiled statistics (None). Generation of long term statistics will be suppressed unless the unit changes back to None
2021-09-12 21:12:29 ERROR (stream_worker) [libav.rtsp] method DESCRIBE failed: 404 Not Found
2021-09-12 21:12:29 ERROR (stream_worker) [homeassistant.components.stream.worker] Error opening stream rtsps://stream-uc2-bravo.dropcam.com:443/sdm_live_stream/CiQA2vuxr1SLu8rlYbOHo16R-04X0NNEKfeupmXLad7ICSMu8s8ScQAFjsOTS4_b71We2VG7vYgLakwq7JUxt6NJI0n_4qGM-a8nYLnRqRt-bpKX5HVk56GBFLsegX_YCrq7qGjicjVDCJLw6ikxOmGMNn5FOIzSK0Ae_WFyJ5hjvdjABw-qslkW0czaUaWbWG6Bc1HqAVEU?auth=g.0.eyJraWQiOiIyMzhiNTUxZmMyM2EyM2Y4M2E2ZTE3MmJjZTg0YmU3ZjgxMzAzMmM4IiwiYWxnIjoiUlMyNTYifQ.eyJpc3MiOiJuZXN0LXNlY3VyaXR5LWF1dGhwcm94eSIsInN1YiI6Im5lc3RfaWQ6bmVzdC1waG9lbml4LXByb2Q6MjEyMTgxNDEiLCJwb2wiOiIzcC1vYXV0aC1zY29wZS1BUElfU0RNX1NFUlZJQ0UtY2xpZW50LTIwMjQyNzMxODczNS1qNXQ5bWMyMzZqaG85YXMycWY0dTZxY3NmYW1kaGJ0ci5hcHBzLmdvb2dsZXVzZXJjb250ZW50LmNvbSIsImV4cCI6MTYzMTQ5ODQ1MH0.tPMv-EG32_XlvIZmCpKyJ12Ozu8zGClYp1WbDrqpdtTyfhR2w_a410FySS2m5ontP4dOlEIuwobL-EtLmC7L-UTsMkZcLFI3pkEY9bzONK24CGe3KJSdpE9hCkdK9L2SM9cAQ87j4pRr9OF5LP7YiLbVPpjZTsW_7ou_Y1g-yu5GA7Fnn5ehSKR-Iwq-ykUciC1-YbZfrAl55FYoBbZRRBiQL8r0leC9RcSSaG73vmI7i-2uemhDzysQlPcXt0nNJ9rzgRpE63NxmMxF4hGNUGOT7BWwoXVVsUJpLHnU-wl5S-jXhZbfS3V3cP9akUTeQF_jgmlWDC06QhKSLnHOKA
2021-09-12 21:16:14 ERROR (MainThread) [homeassistant] Error doing job: Future exception was never retrieved
Traceback (most recent call last):
  File "/usr/local/lib/python3.9/concurrent/futures/thread.py", line 52, in run
    result = self.fn(*self.args, **self.kwargs)
TypeError: update() takes 1 positional argument but 2 were given
2021-09-12 21:19:10 ERROR (stream_worker) [libav.rtsp] method DESCRIBE failed: 404 Not Found
2021-09-12 21:19:10 ERROR (stream_worker) [homeassistant.components.stream.worker] Error opening stream rtsps://stream-uc2-bravo.dropcam.com:443/sdm_live_stream/CiQA2vuxr1SLu8rlYbOHo16R-04X0NNEKfeupmXLad7ICSMu8s8ScQAFjsOTS4_b71We2VG7vYgLakwq7JUxt6NJI0n_4qGM-a8nYLnRqRt-bpKX5HVk56GBFLsegX_YCrq7qGjicjVDCJLw6ikxOmGMNn5FOIzSK0Ae_WFyJ5hjvdjABw-qslkW0czaUaWbWG6Bc1HqAVEU?auth=g.0.eyJraWQiOiIyMzhiNTUxZmMyM2EyM2Y4M2E2ZTE3MmJjZTg0YmU3ZjgxMzAzMmM4IiwiYWxnIjoiUlMyNTYifQ.eyJpc3MiOiJuZXN0LXNlY3VyaXR5LWF1dGhwcm94eSIsInN1YiI6Im5lc3RfaWQ6bmVzdC1waG9lbml4LXByb2Q6MjEyMTgxNDEiLCJwb2wiOiIzcC1vYXV0aC1zY29wZS1BUElfU0RNX1NFUlZJQ0UtY2xpZW50LTIwMjQyNzMxODczNS1qNXQ5bWMyMzZqaG85YXMycWY0dTZxY3NmYW1kaGJ0ci5hcHBzLmdvb2dsZXVzZXJjb250ZW50LmNvbSIsImV4cCI6MTYzMTQ5ODQ1MH0.tPMv-EG32_XlvIZmCpKyJ12Ozu8zGClYp1WbDrqpdtTyfhR2w_a410FySS2m5ontP4dOlEIuwobL-EtLmC7L-UTsMkZcLFI3pkEY9bzONK24CGe3KJSdpE9hCkdK9L2SM9cAQ87j4pRr9OF5LP7YiLbVPpjZTsW_7ou_Y1g-yu5GA7Fnn5ehSKR-Iwq-ykUciC1-YbZfrAl55FYoBbZRRBiQL8r0leC9RcSSaG73vmI7i-2uemhDzysQlPcXt0nNJ9rzgRpE63NxmMxF4hGNUGOT7BWwoXVVsUJpLHnU-wl5S-jXhZbfS3V3cP9akUTeQF_jgmlWDC06QhKSLnHOKA
2021-09-12 21:21:14 ERROR (MainThread) [homeassistant.components.nws] Error requesting NWS observation station SAUC1 data: 503, message='Service Unavailable', url=URL('https://api.weather.gov/stations/SAUC1/observations')
2021-09-12 21:21:15 ERROR (MainThread) [homeassistant] Error doing job: Future exception was never retrieved
Traceback (most recent call last):
  File "/usr/local/lib/python3.9/concurrent/futures/thread.py", line 52, in run
    result = self.fn(*self.args, **self.kwargs)
TypeError: update() takes 1 positional argument but 2 were given
2021-09-12 21:23:24 WARNING (MainThread) [homeassistant.helpers.service] Unable to find referenced entities light.hue_lightstrip_2
2021-09-12 21:26:00 ERROR (stream_worker) [libav.rtsp] method DESCRIBE failed: 404 Not Found
2021-09-12 21:26:00 ERROR (stream_worker) [homeassistant.components.stream.worker] Error opening stream rtsps://stream-uc2-bravo.dropcam.com:443/sdm_live_stream/CiQA2vuxr1SLu8rlYbOHo16R-04X0NNEKfeupmXLad7ICSMu8s8ScQAFjsOTS4_b71We2VG7vYgLakwq7JUxt6NJI0n_4qGM-a8nYLnRqRt-bpKX5HVk56GBFLsegX_YCrq7qGjicjVDCJLw6ikxOmGMNn5FOIzSK0Ae_WFyJ5hjvdjABw-qslkW0czaUaWbWG6Bc1HqAVEU?auth=g.0.eyJraWQiOiIyMzhiNTUxZmMyM2EyM2Y4M2E2ZTE3MmJjZTg0YmU3ZjgxMzAzMmM4IiwiYWxnIjoiUlMyNTYifQ.eyJpc3MiOiJuZXN0LXNlY3VyaXR5LWF1dGhwcm94eSIsInN1YiI6Im5lc3RfaWQ6bmVzdC1waG9lbml4LXByb2Q6MjEyMTgxNDEiLCJwb2wiOiIzcC1vYXV0aC1zY29wZS1BUElfU0RNX1NFUlZJQ0UtY2xpZW50LTIwMjQyNzMxODczNS1qNXQ5bWMyMzZqaG85YXMycWY0dTZxY3NmYW1kaGJ0ci5hcHBzLmdvb2dsZXVzZXJjb250ZW50LmNvbSIsImV4cCI6MTYzMTQ5ODQ1MH0.tPMv-EG32_XlvIZmCpKyJ12Ozu8zGClYp1WbDrqpdtTyfhR2w_a410FySS2m5ontP4dOlEIuwobL-EtLmC7L-UTsMkZcLFI3pkEY9bzONK24CGe3KJSdpE9hCkdK9L2SM9cAQ87j4pRr9OF5LP7YiLbVPpjZTsW_7ou_Y1g-yu5GA7Fnn5ehSKR-Iwq-ykUciC1-YbZfrAl55FYoBbZRRBiQL8r0leC9RcSSaG73vmI7i-2uemhDzysQlPcXt0nNJ9rzgRpE63NxmMxF4hGNUGOT7BWwoXVVsUJpLHnU-wl5S-jXhZbfS3V3cP9akUTeQF_jgmlWDC06QhKSLnHOKA
2021-09-12 21:26:16 ERROR (MainThread) [homeassistant] Error doing job: Future exception was never retrieved
Traceback (most recent call last):
  File "/usr/local/lib/python3.9/concurrent/futures/thread.py", line 52, in run
    result = self.fn(*self.args, **self.kwargs)
TypeError: update() takes 1 positional argument but 2 were given
2021-09-12 21:31:17 ERROR (MainThread) [homeassistant] Error doing job: Future exception was never retrieved
Traceback (most recent call last):
  File "/usr/local/lib/python3.9/concurrent/futures/thread.py", line 52, in run
    result = self.fn(*self.args, **self.kwargs)
TypeError: update() takes 1 positional argument but 2 were given
2021-09-12 21:33:00 ERROR (stream_worker) [libav.rtsp] method DESCRIBE failed: 404 Not Found
2021-09-12 21:33:00 ERROR (stream_worker) [homeassistant.components.stream.worker] Error opening stream rtsps://stream-uc2-bravo.dropcam.com:443/sdm_live_stream/CiQA2vuxr1SLu8rlYbOHo16R-04X0NNEKfeupmXLad7ICSMu8s8ScQAFjsOTS4_b71We2VG7vYgLakwq7JUxt6NJI0n_4qGM-a8nYLnRqRt-bpKX5HVk56GBFLsegX_YCrq7qGjicjVDCJLw6ikxOmGMNn5FOIzSK0Ae_WFyJ5hjvdjABw-qslkW0czaUaWbWG6Bc1HqAVEU?auth=g.0.eyJraWQiOiIyMzhiNTUxZmMyM2EyM2Y4M2E2ZTE3MmJjZTg0YmU3ZjgxMzAzMmM4IiwiYWxnIjoiUlMyNTYifQ.eyJpc3MiOiJuZXN0LXNlY3VyaXR5LWF1dGhwcm94eSIsInN1YiI6Im5lc3RfaWQ6bmVzdC1waG9lbml4LXByb2Q6MjEyMTgxNDEiLCJwb2wiOiIzcC1vYXV0aC1zY29wZS1BUElfU0RNX1NFUlZJQ0UtY2xpZW50LTIwMjQyNzMxODczNS1qNXQ5bWMyMzZqaG85YXMycWY0dTZxY3NmYW1kaGJ0ci5hcHBzLmdvb2dsZXVzZXJjb250ZW50LmNvbSIsImV4cCI6MTYzMTQ5ODQ1MH0.tPMv-EG32_XlvIZmCpKyJ12Ozu8zGClYp1WbDrqpdtTyfhR2w_a410FySS2m5ontP4dOlEIuwobL-EtLmC7L-UTsMkZcLFI3pkEY9bzONK24CGe3KJSdpE9hCkdK9L2SM9cAQ87j4pRr9OF5LP7YiLbVPpjZTsW_7ou_Y1g-yu5GA7Fnn5ehSKR-Iwq-ykUciC1-YbZfrAl55FYoBbZRRBiQL8r0leC9RcSSaG73vmI7i-2uemhDzysQlPcXt0nNJ9rzgRpE63NxmMxF4hGNUGOT7BWwoXVVsUJpLHnU-wl5S-jXhZbfS3V3cP9akUTeQF_jgmlWDC06QhKSLnHOKA
2021-09-12 21:33:38 ERROR (MainThread) [homeassistant.components.nws] Error requesting NWS observation station SAUC1 data: 503, message='Service Unavailable', url=URL('https://api.weather.gov/stations/SAUC1/observations')
2021-09-12 21:36:18 ERROR (MainThread) [homeassistant] Error doing job: Future exception was never retrieved
Traceback (most recent call last):
  File "/usr/local/lib/python3.9/concurrent/futures/thread.py", line 52, in run
    result = self.fn(*self.args, **self.kwargs)
TypeError: update() takes 1 positional argument but 2 were given
2021-09-12 21:40:11 ERROR (stream_worker) [libav.rtsp] method DESCRIBE failed: 404 Not Found
2021-09-12 21:40:11 ERROR (stream_worker) [homeassistant.components.stream.worker] Error opening stream rtsps://stream-uc2-bravo.dropcam.com:443/sdm_live_stream/CiQA2vuxr1SLu8rlYbOHo16R-04X0NNEKfeupmXLad7ICSMu8s8ScQAFjsOTS4_b71We2VG7vYgLakwq7JUxt6NJI0n_4qGM-a8nYLnRqRt-bpKX5HVk56GBFLsegX_YCrq7qGjicjVDCJLw6ikxOmGMNn5FOIzSK0Ae_WFyJ5hjvdjABw-qslkW0czaUaWbWG6Bc1HqAVEU?auth=g.0.eyJraWQiOiIyMzhiNTUxZmMyM2EyM2Y4M2E2ZTE3MmJjZTg0YmU3ZjgxMzAzMmM4IiwiYWxnIjoiUlMyNTYifQ.eyJpc3MiOiJuZXN0LXNlY3VyaXR5LWF1dGhwcm94eSIsInN1YiI6Im5lc3RfaWQ6bmVzdC1waG9lbml4LXByb2Q6MjEyMTgxNDEiLCJwb2wiOiIzcC1vYXV0aC1zY29wZS1BUElfU0RNX1NFUlZJQ0UtY2xpZW50LTIwMjQyNzMxODczNS1qNXQ5bWMyMzZqaG85YXMycWY0dTZxY3NmYW1kaGJ0ci5hcHBzLmdvb2dsZXVzZXJjb250ZW50LmNvbSIsImV4cCI6MTYzMTQ5ODQ1MH0.tPMv-EG32_XlvIZmCpKyJ12Ozu8zGClYp1WbDrqpdtTyfhR2w_a410FySS2m5ontP4dOlEIuwobL-EtLmC7L-UTsMkZcLFI3pkEY9bzONK24CGe3KJSdpE9hCkdK9L2SM9cAQ87j4pRr9OF5LP7YiLbVPpjZTsW_7ou_Y1g-yu5GA7Fnn5ehSKR-Iwq-ykUciC1-YbZfrAl55FYoBbZRRBiQL8r0leC9RcSSaG73vmI7i-2uemhDzysQlPcXt0nNJ9rzgRpE63NxmMxF4hGNUGOT7BWwoXVVsUJpLHnU-wl5S-jXhZbfS3V3cP9akUTeQF_jgmlWDC06QhKSLnHOKA
2021-09-12 21:41:19 ERROR (MainThread) [homeassistant] Error doing job: Future exception was never retrieved
Traceback (most recent call last):
  File "/usr/local/lib/python3.9/concurrent/futures/thread.py", line 52, in run
    result = self.fn(*self.args, **self.kwargs)
TypeError: update() takes 1 positional argument but 2 were given
2021-09-12 21:46:20 ERROR (MainThread) [homeassistant] Error doing job: Future exception was never retrieved
Traceback (most recent call last):
  File "/usr/local/lib/python3.9/concurrent/futures/thread.py", line 52, in run
    result = self.fn(*self.args, **self.kwargs)
TypeError: update() takes 1 positional argument but 2 were given
2021-09-12 21:47:31 ERROR (stream_worker) [libav.rtsp] method DESCRIBE failed: 404 Not Found
2021-09-12 21:47:31 ERROR (stream_worker) [homeassistant.components.stream.worker] Error opening stream rtsps://stream-uc2-bravo.dropcam.com:443/sdm_live_stream/CiQA2vuxr1SLu8rlYbOHo16R-04X0NNEKfeupmXLad7ICSMu8s8ScQAFjsOTS4_b71We2VG7vYgLakwq7JUxt6NJI0n_4qGM-a8nYLnRqRt-bpKX5HVk56GBFLsegX_YCrq7qGjicjVDCJLw6ikxOmGMNn5FOIzSK0Ae_WFyJ5hjvdjABw-qslkW0czaUaWbWG6Bc1HqAVEU?auth=g.0.eyJraWQiOiIyMzhiNTUxZmMyM2EyM2Y4M2E2ZTE3MmJjZTg0YmU3ZjgxMzAzMmM4IiwiYWxnIjoiUlMyNTYifQ.eyJpc3MiOiJuZXN0LXNlY3VyaXR5LWF1dGhwcm94eSIsInN1YiI6Im5lc3RfaWQ6bmVzdC1waG9lbml4LXByb2Q6MjEyMTgxNDEiLCJwb2wiOiIzcC1vYXV0aC1zY29wZS1BUElfU0RNX1NFUlZJQ0UtY2xpZW50LTIwMjQyNzMxODczNS1qNXQ5bWMyMzZqaG85YXMycWY0dTZxY3NmYW1kaGJ0ci5hcHBzLmdvb2dsZXVzZXJjb250ZW50LmNvbSIsImV4cCI6MTYzMTQ5ODQ1MH0.tPMv-EG32_XlvIZmCpKyJ12Ozu8zGClYp1WbDrqpdtTyfhR2w_a410FySS2m5ontP4dOlEIuwobL-EtLmC7L-UTsMkZcLFI3pkEY9bzONK24CGe3KJSdpE9hCkdK9L2SM9cAQ87j4pRr9OF5LP7YiLbVPpjZTsW_7ou_Y1g-yu5GA7Fnn5ehSKR-Iwq-ykUciC1-YbZfrAl55FYoBbZRRBiQL8r0leC9RcSSaG73vmI7i-2uemhDzysQlPcXt0nNJ9rzgRpE63NxmMxF4hGNUGOT7BWwoXVVsUJpLHnU-wl5S-jXhZbfS3V3cP9akUTeQF_jgmlWDC06QhKSLnHOKA
2021-09-12 21:51:21 ERROR (MainThread) [homeassistant] Error doing job: Future exception was never retrieved
Traceback (most recent call last):
  File "/usr/local/lib/python3.9/concurrent/futures/thread.py", line 52, in run
    result = self.fn(*self.args, **self.kwargs)
TypeError: update() takes 1 positional argument but 2 were given
2021-09-12 21:55:02 ERROR (stream_worker) [libav.rtsp] method DESCRIBE failed: 404 Not Found
2021-09-12 21:55:02 ERROR (stream_worker) [homeassistant.components.stream.worker] Error opening stream rtsps://stream-uc2-bravo.dropcam.com:443/sdm_live_stream/CiQA2vuxr1SLu8rlYbOHo16R-04X0NNEKfeupmXLad7ICSMu8s8ScQAFjsOTS4_b71We2VG7vYgLakwq7JUxt6NJI0n_4qGM-a8nYLnRqRt-bpKX5HVk56GBFLsegX_YCrq7qGjicjVDCJLw6ikxOmGMNn5FOIzSK0Ae_WFyJ5hjvdjABw-qslkW0czaUaWbWG6Bc1HqAVEU?auth=g.0.eyJraWQiOiIyMzhiNTUxZmMyM2EyM2Y4M2E2ZTE3MmJjZTg0YmU3ZjgxMzAzMmM4IiwiYWxnIjoiUlMyNTYifQ.eyJpc3MiOiJuZXN0LXNlY3VyaXR5LWF1dGhwcm94eSIsInN1YiI6Im5lc3RfaWQ6bmVzdC1waG9lbml4LXByb2Q6MjEyMTgxNDEiLCJwb2wiOiIzcC1vYXV0aC1zY29wZS1BUElfU0RNX1NFUlZJQ0UtY2xpZW50LTIwMjQyNzMxODczNS1qNXQ5bWMyMzZqaG85YXMycWY0dTZxY3NmYW1kaGJ0ci5hcHBzLmdvb2dsZXVzZXJjb250ZW50LmNvbSIsImV4cCI6MTYzMTQ5ODQ1MH0.tPMv-EG32_XlvIZmCpKyJ12Ozu8zGClYp1WbDrqpdtTyfhR2w_a410FySS2m5ontP4dOlEIuwobL-EtLmC7L-UTsMkZcLFI3pkEY9bzONK24CGe3KJSdpE9hCkdK9L2SM9cAQ87j4pRr9OF5LP7YiLbVPpjZTsW_7ou_Y1g-yu5GA7Fnn5ehSKR-Iwq-ykUciC1-YbZfrAl55FYoBbZRRBiQL8r0leC9RcSSaG73vmI7i-2uemhDzysQlPcXt0nNJ9rzgRpE63NxmMxF4hGNUGOT7BWwoXVVsUJpLHnU-wl5S-jXhZbfS3V3cP9akUTeQF_jgmlWDC06QhKSLnHOKA
2021-09-12 21:56:22 ERROR (MainThread) [homeassistant] Error doing job: Future exception was never retrieved
Traceback (most recent call last):
  File "/usr/local/lib/python3.9/concurrent/futures/thread.py", line 52, in run
    result = self.fn(*self.args, **self.kwargs)
TypeError: update() takes 1 positional argument but 2 were given
2021-09-12 22:01:23 ERROR (MainThread) [homeassistant] Error doing job: Future exception was never retrieved
Traceback (most recent call last):
  File "/usr/local/lib/python3.9/concurrent/futures/thread.py", line 52, in run
    result = self.fn(*self.args, **self.kwargs)
TypeError: update() takes 1 positional argument but 2 were given
2021-09-12 22:02:42 ERROR (stream_worker) [libav.rtsp] method DESCRIBE failed: 404 Not Found
2021-09-12 22:02:42 ERROR (stream_worker) [homeassistant.components.stream.worker] Error opening stream rtsps://stream-uc2-bravo.dropcam.com:443/sdm_live_stream/CiQA2vuxr1SLu8rlYbOHo16R-04X0NNEKfeupmXLad7ICSMu8s8ScQAFjsOTS4_b71We2VG7vYgLakwq7JUxt6NJI0n_4qGM-a8nYLnRqRt-bpKX5HVk56GBFLsegX_YCrq7qGjicjVDCJLw6ikxOmGMNn5FOIzSK0Ae_WFyJ5hjvdjABw-qslkW0czaUaWbWG6Bc1HqAVEU?auth=g.0.eyJraWQiOiIyMzhiNTUxZmMyM2EyM2Y4M2E2ZTE3MmJjZTg0YmU3ZjgxMzAzMmM4IiwiYWxnIjoiUlMyNTYifQ.eyJpc3MiOiJuZXN0LXNlY3VyaXR5LWF1dGhwcm94eSIsInN1YiI6Im5lc3RfaWQ6bmVzdC1waG9lbml4LXByb2Q6MjEyMTgxNDEiLCJwb2wiOiIzcC1vYXV0aC1zY29wZS1BUElfU0RNX1NFUlZJQ0UtY2xpZW50LTIwMjQyNzMxODczNS1qNXQ5bWMyMzZqaG85YXMycWY0dTZxY3NmYW1kaGJ0ci5hcHBzLmdvb2dsZXVzZXJjb250ZW50LmNvbSIsImV4cCI6MTYzMTQ5ODQ1MH0.tPMv-EG32_XlvIZmCpKyJ12Ozu8zGClYp1WbDrqpdtTyfhR2w_a410FySS2m5ontP4dOlEIuwobL-EtLmC7L-UTsMkZcLFI3pkEY9bzONK24CGe3KJSdpE9hCkdK9L2SM9cAQ87j4pRr9OF5LP7YiLbVPpjZTsW_7ou_Y1g-yu5GA7Fnn5ehSKR-Iwq-ykUciC1-YbZfrAl55FYoBbZRRBiQL8r0leC9RcSSaG73vmI7i-2uemhDzysQlPcXt0nNJ9rzgRpE63NxmMxF4hGNUGOT7BWwoXVVsUJpLHnU-wl5S-jXhZbfS3V3cP9akUTeQF_jgmlWDC06QhKSLnHOKA
2021-09-12 22:05:02 ERROR (MainThread) [homeassistant.components.nws] Error requesting NWS observation station SAUC1 data: 503, message='Service Unavailable', url=URL('https://api.weather.gov/stations/SAUC1/observations')
2021-09-12 22:05:34 WARNING (MainThread) [homeassistant.components.cloud.google_config] Error reporting state - 13: Internal error encountered.
2021-09-12 22:06:24 ERROR (MainThread) [homeassistant] Error doing job: Future exception was never retrieved
Traceback (most recent call last):
  File "/usr/local/lib/python3.9/concurrent/futures/thread.py", line 52, in run
    result = self.fn(*self.args, **self.kwargs)
TypeError: update() takes 1 positional argument but 2 were given
2021-09-12 22:10:33 ERROR (stream_worker) [libav.rtsp] method DESCRIBE failed: 404 Not Found
2021-09-12 22:10:33 ERROR (stream_worker) [homeassistant.components.stream.worker] Error opening stream rtsps://stream-uc2-bravo.dropcam.com:443/sdm_live_stream/CiQA2vuxr1SLu8rlYbOHo16R-04X0NNEKfeupmXLad7ICSMu8s8ScQAFjsOTS4_b71We2VG7vYgLakwq7JUxt6NJI0n_4qGM-a8nYLnRqRt-bpKX5HVk56GBFLsegX_YCrq7qGjicjVDCJLw6ikxOmGMNn5FOIzSK0Ae_WFyJ5hjvdjABw-qslkW0czaUaWbWG6Bc1HqAVEU?auth=g.0.eyJraWQiOiIyMzhiNTUxZmMyM2EyM2Y4M2E2ZTE3MmJjZTg0YmU3ZjgxMzAzMmM4IiwiYWxnIjoiUlMyNTYifQ.eyJpc3MiOiJuZXN0LXNlY3VyaXR5LWF1dGhwcm94eSIsInN1YiI6Im5lc3RfaWQ6bmVzdC1waG9lbml4LXByb2Q6MjEyMTgxNDEiLCJwb2wiOiIzcC1vYXV0aC1zY29wZS1BUElfU0RNX1NFUlZJQ0UtY2xpZW50LTIwMjQyNzMxODczNS1qNXQ5bWMyMzZqaG85YXMycWY0dTZxY3NmYW1kaGJ0ci5hcHBzLmdvb2dsZXVzZXJjb250ZW50LmNvbSIsImV4cCI6MTYzMTQ5ODQ1MH0.tPMv-EG32_XlvIZmCpKyJ12Ozu8zGClYp1WbDrqpdtTyfhR2w_a410FySS2m5ontP4dOlEIuwobL-EtLmC7L-UTsMkZcLFI3pkEY9bzONK24CGe3KJSdpE9hCkdK9L2SM9cAQ87j4pRr9OF5LP7YiLbVPpjZTsW_7ou_Y1g-yu5GA7Fnn5ehSKR-Iwq-ykUciC1-YbZfrAl55FYoBbZRRBiQL8r0leC9RcSSaG73vmI7i-2uemhDzysQlPcXt0nNJ9rzgRpE63NxmMxF4hGNUGOT7BWwoXVVsUJpLHnU-wl5S-jXhZbfS3V3cP9akUTeQF_jgmlWDC06QhKSLnHOKA
2021-09-12 22:11:25 ERROR (MainThread) [homeassistant] Error doing job: Future exception was never retrieved
Traceback (most recent call last):
  File "/usr/local/lib/python3.9/concurrent/futures/thread.py", line 52, in run
    result = self.fn(*self.args, **self.kwargs)
TypeError: update() takes 1 positional argument but 2 were given
2021-09-12 22:16:26 ERROR (MainThread) [homeassistant] Error doing job: Future exception was never retrieved
Traceback (most recent call last):
  File "/usr/local/lib/python3.9/concurrent/futures/thread.py", line 52, in run
    result = self.fn(*self.args, **self.kwargs)
TypeError: update() takes 1 positional argument but 2 were given
2021-09-12 22:18:33 ERROR (stream_worker) [libav.rtsp] method DESCRIBE failed: 404 Not Found
2021-09-12 22:18:33 ERROR (stream_worker) [homeassistant.components.stream.worker] Error opening stream rtsps://stream-uc2-bravo.dropcam.com:443/sdm_live_stream/CiQA2vuxr1SLu8rlYbOHo16R-04X0NNEKfeupmXLad7ICSMu8s8ScQAFjsOTS4_b71We2VG7vYgLakwq7JUxt6NJI0n_4qGM-a8nYLnRqRt-bpKX5HVk56GBFLsegX_YCrq7qGjicjVDCJLw6ikxOmGMNn5FOIzSK0Ae_WFyJ5hjvdjABw-qslkW0czaUaWbWG6Bc1HqAVEU?auth=g.0.eyJraWQiOiIyMzhiNTUxZmMyM2EyM2Y4M2E2ZTE3MmJjZTg0YmU3ZjgxMzAzMmM4IiwiYWxnIjoiUlMyNTYifQ.eyJpc3MiOiJuZXN0LXNlY3VyaXR5LWF1dGhwcm94eSIsInN1YiI6Im5lc3RfaWQ6bmVzdC1waG9lbml4LXByb2Q6MjEyMTgxNDEiLCJwb2wiOiIzcC1vYXV0aC1zY29wZS1BUElfU0RNX1NFUlZJQ0UtY2xpZW50LTIwMjQyNzMxODczNS1qNXQ5bWMyMzZqaG85YXMycWY0dTZxY3NmYW1kaGJ0ci5hcHBzLmdvb2dsZXVzZXJjb250ZW50LmNvbSIsImV4cCI6MTYzMTQ5ODQ1MH0.tPMv-EG32_XlvIZmCpKyJ12Ozu8zGClYp1WbDrqpdtTyfhR2w_a410FySS2m5ontP4dOlEIuwobL-EtLmC7L-UTsMkZcLFI3pkEY9bzONK24CGe3KJSdpE9hCkdK9L2SM9cAQ87j4pRr9OF5LP7YiLbVPpjZTsW_7ou_Y1g-yu5GA7Fnn5ehSKR-Iwq-ykUciC1-YbZfrAl55FYoBbZRRBiQL8r0leC9RcSSaG73vmI7i-2uemhDzysQlPcXt0nNJ9rzgRpE63NxmMxF4hGNUGOT7BWwoXVVsUJpLHnU-wl5S-jXhZbfS3V3cP9akUTeQF_jgmlWDC06QhKSLnHOKA
2021-09-12 22:21:27 ERROR (MainThread) [homeassistant] Error doing job: Future exception was never retrieved
Traceback (most recent call last):
  File "/usr/local/lib/python3.9/concurrent/futures/thread.py", line 52, in run
    result = self.fn(*self.args, **self.kwargs)
TypeError: update() takes 1 positional argument but 2 were given
2021-09-12 22:26:28 ERROR (MainThread) [homeassistant] Error doing job: Future exception was never retrieved
Traceback (most recent call last):
  File "/usr/local/lib/python3.9/concurrent/futures/thread.py", line 52, in run
    result = self.fn(*self.args, **self.kwargs)
TypeError: update() takes 1 positional argument but 2 were given
2021-09-12 22:26:44 ERROR (stream_worker) [libav.rtsp] method DESCRIBE failed: 404 Not Found
2021-09-12 22:26:44 ERROR (stream_worker) [homeassistant.components.stream.worker] Error opening stream rtsps://stream-uc2-bravo.dropcam.com:443/sdm_live_stream/CiQA2vuxr1SLu8rlYbOHo16R-04X0NNEKfeupmXLad7ICSMu8s8ScQAFjsOTS4_b71We2VG7vYgLakwq7JUxt6NJI0n_4qGM-a8nYLnRqRt-bpKX5HVk56GBFLsegX_YCrq7qGjicjVDCJLw6ikxOmGMNn5FOIzSK0Ae_WFyJ5hjvdjABw-qslkW0czaUaWbWG6Bc1HqAVEU?auth=g.0.eyJraWQiOiIyMzhiNTUxZmMyM2EyM2Y4M2E2ZTE3MmJjZTg0YmU3ZjgxMzAzMmM4IiwiYWxnIjoiUlMyNTYifQ.eyJpc3MiOiJuZXN0LXNlY3VyaXR5LWF1dGhwcm94eSIsInN1YiI6Im5lc3RfaWQ6bmVzdC1waG9lbml4LXByb2Q6MjEyMTgxNDEiLCJwb2wiOiIzcC1vYXV0aC1zY29wZS1BUElfU0RNX1NFUlZJQ0UtY2xpZW50LTIwMjQyNzMxODczNS1qNXQ5bWMyMzZqaG85YXMycWY0dTZxY3NmYW1kaGJ0ci5hcHBzLmdvb2dsZXVzZXJjb250ZW50LmNvbSIsImV4cCI6MTYzMTQ5ODQ1MH0.tPMv-EG32_XlvIZmCpKyJ12Ozu8zGClYp1WbDrqpdtTyfhR2w_a410FySS2m5ontP4dOlEIuwobL-EtLmC7L-UTsMkZcLFI3pkEY9bzONK24CGe3KJSdpE9hCkdK9L2SM9cAQ87j4pRr9OF5LP7YiLbVPpjZTsW_7ou_Y1g-yu5GA7Fnn5ehSKR-Iwq-ykUciC1-YbZfrAl55FYoBbZRRBiQL8r0leC9RcSSaG73vmI7i-2uemhDzysQlPcXt0nNJ9rzgRpE63NxmMxF4hGNUGOT7BWwoXVVsUJpLHnU-wl5S-jXhZbfS3V3cP9akUTeQF_jgmlWDC06QhKSLnHOKA
2021-09-12 22:28:06 WARNING (MainThread) [homeassistant.helpers.service] Unable to find referenced entities light.hue_lightstrip_2
2021-09-12 22:31:29 ERROR (MainThread) [homeassistant] Error doing job: Future exception was never retrieved
Traceback (most recent call last):
  File "/usr/local/lib/python3.9/concurrent/futures/thread.py", line 52, in run
    result = self.fn(*self.args, **self.kwargs)
TypeError: update() takes 1 positional argument but 2 were given
2021-09-12 22:35:04 ERROR (stream_worker) [libav.rtsp] method DESCRIBE failed: 404 Not Found
2021-09-12 22:35:04 ERROR (stream_worker) [homeassistant.components.stream.worker] Error opening stream rtsps://stream-uc2-bravo.dropcam.com:443/sdm_live_stream/CiQA2vuxr1SLu8rlYbOHo16R-04X0NNEKfeupmXLad7ICSMu8s8ScQAFjsOTS4_b71We2VG7vYgLakwq7JUxt6NJI0n_4qGM-a8nYLnRqRt-bpKX5HVk56GBFLsegX_YCrq7qGjicjVDCJLw6ikxOmGMNn5FOIzSK0Ae_WFyJ5hjvdjABw-qslkW0czaUaWbWG6Bc1HqAVEU?auth=g.0.eyJraWQiOiIyMzhiNTUxZmMyM2EyM2Y4M2E2ZTE3MmJjZTg0YmU3ZjgxMzAzMmM4IiwiYWxnIjoiUlMyNTYifQ.eyJpc3MiOiJuZXN0LXNlY3VyaXR5LWF1dGhwcm94eSIsInN1YiI6Im5lc3RfaWQ6bmVzdC1waG9lbml4LXByb2Q6MjEyMTgxNDEiLCJwb2wiOiIzcC1vYXV0aC1zY29wZS1BUElfU0RNX1NFUlZJQ0UtY2xpZW50LTIwMjQyNzMxODczNS1qNXQ5bWMyMzZqaG85YXMycWY0dTZxY3NmYW1kaGJ0ci5hcHBzLmdvb2dsZXVzZXJjb250ZW50LmNvbSIsImV4cCI6MTYzMTQ5ODQ1MH0.tPMv-EG32_XlvIZmCpKyJ12Ozu8zGClYp1WbDrqpdtTyfhR2w_a410FySS2m5ontP4dOlEIuwobL-EtLmC7L-UTsMkZcLFI3pkEY9bzONK24CGe3KJSdpE9hCkdK9L2SM9cAQ87j4pRr9OF5LP7YiLbVPpjZTsW_7ou_Y1g-yu5GA7Fnn5ehSKR-Iwq-ykUciC1-YbZfrAl55FYoBbZRRBiQL8r0leC9RcSSaG73vmI7i-2uemhDzysQlPcXt0nNJ9rzgRpE63NxmMxF4hGNUGOT7BWwoXVVsUJpLHnU-wl5S-jXhZbfS3V3cP9akUTeQF_jgmlWDC06QhKSLnHOKA
2021-09-12 22:36:30 ERROR (MainThread) [homeassistant] Error doing job: Future exception was never retrieved
Traceback (most recent call last):
  File "/usr/local/lib/python3.9/concurrent/futures/thread.py", line 52, in run
    result = self.fn(*self.args, **self.kwargs)
TypeError: update() takes 1 positional argument but 2 were given
2021-09-12 22:41:31 ERROR (MainThread) [homeassistant] Error doing job: Future exception was never retrieved
Traceback (most recent call last):
  File "/usr/local/lib/python3.9/concurrent/futures/thread.py", line 52, in run
    result = self.fn(*self.args, **self.kwargs)
TypeError: update() takes 1 positional argument but 2 were given
2021-09-12 22:43:35 ERROR (stream_worker) [libav.rtsp] method DESCRIBE failed: 404 Not Found
2021-09-12 22:43:35 ERROR (stream_worker) [homeassistant.components.stream.worker] Error opening stream rtsps://stream-uc2-bravo.dropcam.com:443/sdm_live_stream/CiQA2vuxr1SLu8rlYbOHo16R-04X0NNEKfeupmXLad7ICSMu8s8ScQAFjsOTS4_b71We2VG7vYgLakwq7JUxt6NJI0n_4qGM-a8nYLnRqRt-bpKX5HVk56GBFLsegX_YCrq7qGjicjVDCJLw6ikxOmGMNn5FOIzSK0Ae_WFyJ5hjvdjABw-qslkW0czaUaWbWG6Bc1HqAVEU?auth=g.0.eyJraWQiOiIyMzhiNTUxZmMyM2EyM2Y4M2E2ZTE3MmJjZTg0YmU3ZjgxMzAzMmM4IiwiYWxnIjoiUlMyNTYifQ.eyJpc3MiOiJuZXN0LXNlY3VyaXR5LWF1dGhwcm94eSIsInN1YiI6Im5lc3RfaWQ6bmVzdC1waG9lbml4LXByb2Q6MjEyMTgxNDEiLCJwb2wiOiIzcC1vYXV0aC1zY29wZS1BUElfU0RNX1NFUlZJQ0UtY2xpZW50LTIwMjQyNzMxODczNS1qNXQ5bWMyMzZqaG85YXMycWY0dTZxY3NmYW1kaGJ0ci5hcHBzLmdvb2dsZXVzZXJjb250ZW50LmNvbSIsImV4cCI6MTYzMTQ5ODQ1MH0.tPMv-EG32_XlvIZmCpKyJ12Ozu8zGClYp1WbDrqpdtTyfhR2w_a410FySS2m5ontP4dOlEIuwobL-EtLmC7L-UTsMkZcLFI3pkEY9bzONK24CGe3KJSdpE9hCkdK9L2SM9cAQ87j4pRr9OF5LP7YiLbVPpjZTsW_7ou_Y1g-yu5GA7Fnn5ehSKR-Iwq-ykUciC1-YbZfrAl55FYoBbZRRBiQL8r0leC9RcSSaG73vmI7i-2uemhDzysQlPcXt0nNJ9rzgRpE63NxmMxF4hGNUGOT7BWwoXVVsUJpLHnU-wl5S-jXhZbfS3V3cP9akUTeQF_jgmlWDC06QhKSLnHOKA
2021-09-12 22:46:32 ERROR (MainThread) [homeassistant] Error doing job: Future exception was never retrieved
Traceback (most recent call last):
  File "/usr/local/lib/python3.9/concurrent/futures/thread.py", line 52, in run
    result = self.fn(*self.args, **self.kwargs)
TypeError: update() takes 1 positional argument but 2 were given
2021-09-12 22:51:33 ERROR (MainThread) [homeassistant] Error doing job: Future exception was never retrieved
Traceback (most recent call last):
  File "/usr/local/lib/python3.9/concurrent/futures/thread.py", line 52, in run
    result = self.fn(*self.args, **self.kwargs)
TypeError: update() takes 1 positional argument but 2 were given
2021-09-12 22:52:16 ERROR (stream_worker) [libav.rtsp] method DESCRIBE failed: 404 Not Found
2021-09-12 22:52:16 ERROR (stream_worker) [homeassistant.components.stream.worker] Error opening stream rtsps://stream-uc2-bravo.dropcam.com:443/sdm_live_stream/CiQA2vuxr1SLu8rlYbOHo16R-04X0NNEKfeupmXLad7ICSMu8s8ScQAFjsOTS4_b71We2VG7vYgLakwq7JUxt6NJI0n_4qGM-a8nYLnRqRt-bpKX5HVk56GBFLsegX_YCrq7qGjicjVDCJLw6ikxOmGMNn5FOIzSK0Ae_WFyJ5hjvdjABw-qslkW0czaUaWbWG6Bc1HqAVEU?auth=g.0.eyJraWQiOiIyMzhiNTUxZmMyM2EyM2Y4M2E2ZTE3MmJjZTg0YmU3ZjgxMzAzMmM4IiwiYWxnIjoiUlMyNTYifQ.eyJpc3MiOiJuZXN0LXNlY3VyaXR5LWF1dGhwcm94eSIsInN1YiI6Im5lc3RfaWQ6bmVzdC1waG9lbml4LXByb2Q6MjEyMTgxNDEiLCJwb2wiOiIzcC1vYXV0aC1zY29wZS1BUElfU0RNX1NFUlZJQ0UtY2xpZW50LTIwMjQyNzMxODczNS1qNXQ5bWMyMzZqaG85YXMycWY0dTZxY3NmYW1kaGJ0ci5hcHBzLmdvb2dsZXVzZXJjb250ZW50LmNvbSIsImV4cCI6MTYzMTQ5ODQ1MH0.tPMv-EG32_XlvIZmCpKyJ12Ozu8zGClYp1WbDrqpdtTyfhR2w_a410FySS2m5ontP4dOlEIuwobL-EtLmC7L-UTsMkZcLFI3pkEY9bzONK24CGe3KJSdpE9hCkdK9L2SM9cAQ87j4pRr9OF5LP7YiLbVPpjZTsW_7ou_Y1g-yu5GA7Fnn5ehSKR-Iwq-ykUciC1-YbZfrAl55FYoBbZRRBiQL8r0leC9RcSSaG73vmI7i-2uemhDzysQlPcXt0nNJ9rzgRpE63NxmMxF4hGNUGOT7BWwoXVVsUJpLHnU-wl5S-jXhZbfS3V3cP9akUTeQF_jgmlWDC06QhKSLnHOKA
2021-09-12 22:56:34 ERROR (MainThread) [homeassistant] Error doing job: Future exception was never retrieved
Traceback (most recent call last):
  File "/usr/local/lib/python3.9/concurrent/futures/thread.py", line 52, in run
    result = self.fn(*self.args, **self.kwargs)
TypeError: update() takes 1 positional argument but 2 were given
2021-09-12 23:00:00 WARNING (MainThread) [homeassistant.helpers.service] Unable to find referenced entities light.sophia_wled
2021-09-12 23:01:07 ERROR (stream_worker) [libav.rtsp] method DESCRIBE failed: 404 Not Found
2021-09-12 23:01:07 ERROR (stream_worker) [homeassistant.components.stream.worker] Error opening stream rtsps://stream-uc2-bravo.dropcam.com:443/sdm_live_stream/CiQA2vuxr1SLu8rlYbOHo16R-04X0NNEKfeupmXLad7ICSMu8s8ScQAFjsOTS4_b71We2VG7vYgLakwq7JUxt6NJI0n_4qGM-a8nYLnRqRt-bpKX5HVk56GBFLsegX_YCrq7qGjicjVDCJLw6ikxOmGMNn5FOIzSK0Ae_WFyJ5hjvdjABw-qslkW0czaUaWbWG6Bc1HqAVEU?auth=g.0.eyJraWQiOiIyMzhiNTUxZmMyM2EyM2Y4M2E2ZTE3MmJjZTg0YmU3ZjgxMzAzMmM4IiwiYWxnIjoiUlMyNTYifQ.eyJpc3MiOiJuZXN0LXNlY3VyaXR5LWF1dGhwcm94eSIsInN1YiI6Im5lc3RfaWQ6bmVzdC1waG9lbml4LXByb2Q6MjEyMTgxNDEiLCJwb2wiOiIzcC1vYXV0aC1zY29wZS1BUElfU0RNX1NFUlZJQ0UtY2xpZW50LTIwMjQyNzMxODczNS1qNXQ5bWMyMzZqaG85YXMycWY0dTZxY3NmYW1kaGJ0ci5hcHBzLmdvb2dsZXVzZXJjb250ZW50LmNvbSIsImV4cCI6MTYzMTQ5ODQ1MH0.tPMv-EG32_XlvIZmCpKyJ12Ozu8zGClYp1WbDrqpdtTyfhR2w_a410FySS2m5ontP4dOlEIuwobL-EtLmC7L-UTsMkZcLFI3pkEY9bzONK24CGe3KJSdpE9hCkdK9L2SM9cAQ87j4pRr9OF5LP7YiLbVPpjZTsW_7ou_Y1g-yu5GA7Fnn5ehSKR-Iwq-ykUciC1-YbZfrAl55FYoBbZRRBiQL8r0leC9RcSSaG73vmI7i-2uemhDzysQlPcXt0nNJ9rzgRpE63NxmMxF4hGNUGOT7BWwoXVVsUJpLHnU-wl5S-jXhZbfS3V3cP9akUTeQF_jgmlWDC06QhKSLnHOKA
2021-09-12 23:01:35 ERROR (MainThread) [homeassistant] Error doing job: Future exception was never retrieved
Traceback (most recent call last):
  File "/usr/local/lib/python3.9/concurrent/futures/thread.py", line 52, in run
    result = self.fn(*self.args, **self.kwargs)
TypeError: update() takes 1 positional argument but 2 were given
2021-09-12 23:06:36 ERROR (MainThread) [homeassistant] Error doing job: Future exception was never retrieved
Traceback (most recent call last):
  File "/usr/local/lib/python3.9/concurrent/futures/thread.py", line 52, in run
    result = self.fn(*self.args, **self.kwargs)
TypeError: update() takes 1 positional argument but 2 were given
2021-09-12 23:10:07 ERROR (stream_worker) [libav.rtsp] method DESCRIBE failed: 404 Not Found
2021-09-12 23:10:07 ERROR (stream_worker) [homeassistant.components.stream.worker] Error opening stream rtsps://stream-uc2-bravo.dropcam.com:443/sdm_live_stream/CiQA2vuxr1SLu8rlYbOHo16R-04X0NNEKfeupmXLad7ICSMu8s8ScQAFjsOTS4_b71We2VG7vYgLakwq7JUxt6NJI0n_4qGM-a8nYLnRqRt-bpKX5HVk56GBFLsegX_YCrq7qGjicjVDCJLw6ikxOmGMNn5FOIzSK0Ae_WFyJ5hjvdjABw-qslkW0czaUaWbWG6Bc1HqAVEU?auth=g.0.eyJraWQiOiIyMzhiNTUxZmMyM2EyM2Y4M2E2ZTE3MmJjZTg0YmU3ZjgxMzAzMmM4IiwiYWxnIjoiUlMyNTYifQ.eyJpc3MiOiJuZXN0LXNlY3VyaXR5LWF1dGhwcm94eSIsInN1YiI6Im5lc3RfaWQ6bmVzdC1waG9lbml4LXByb2Q6MjEyMTgxNDEiLCJwb2wiOiIzcC1vYXV0aC1zY29wZS1BUElfU0RNX1NFUlZJQ0UtY2xpZW50LTIwMjQyNzMxODczNS1qNXQ5bWMyMzZqaG85YXMycWY0dTZxY3NmYW1kaGJ0ci5hcHBzLmdvb2dsZXVzZXJjb250ZW50LmNvbSIsImV4cCI6MTYzMTQ5ODQ1MH0.tPMv-EG32_XlvIZmCpKyJ12Ozu8zGClYp1WbDrqpdtTyfhR2w_a410FySS2m5ontP4dOlEIuwobL-EtLmC7L-UTsMkZcLFI3pkEY9bzONK24CGe3KJSdpE9hCkdK9L2SM9cAQ87j4pRr9OF5LP7YiLbVPpjZTsW_7ou_Y1g-yu5GA7Fnn5ehSKR-Iwq-ykUciC1-YbZfrAl55FYoBbZRRBiQL8r0leC9RcSSaG73vmI7i-2uemhDzysQlPcXt0nNJ9rzgRpE63NxmMxF4hGNUGOT7BWwoXVVsUJpLHnU-wl5S-jXhZbfS3V3cP9akUTeQF_jgmlWDC06QhKSLnHOKA
2021-09-12 23:11:37 ERROR (MainThread) [homeassistant] Error doing job: Future exception was never retrieved
Traceback (most recent call last):
  File "/usr/local/lib/python3.9/concurrent/futures/thread.py", line 52, in run
    result = self.fn(*self.args, **self.kwargs)
TypeError: update() takes 1 positional argument but 2 were given
2021-09-12 23:16:38 ERROR (MainThread) [homeassistant] Error doing job: Future exception was never retrieved
Traceback (most recent call last):
  File "/usr/local/lib/python3.9/concurrent/futures/thread.py", line 52, in run
    result = self.fn(*self.args, **self.kwargs)
TypeError: update() takes 1 positional argument but 2 were given
2021-09-12 23:19:19 ERROR (stream_worker) [libav.rtsp] method DESCRIBE failed: 404 Not Found
2021-09-12 23:19:19 ERROR (stream_worker) [homeassistant.components.stream.worker] Error opening stream rtsps://stream-uc2-bravo.dropcam.com:443/sdm_live_stream/CiQA2vuxr1SLu8rlYbOHo16R-04X0NNEKfeupmXLad7ICSMu8s8ScQAFjsOTS4_b71We2VG7vYgLakwq7JUxt6NJI0n_4qGM-a8nYLnRqRt-bpKX5HVk56GBFLsegX_YCrq7qGjicjVDCJLw6ikxOmGMNn5FOIzSK0Ae_WFyJ5hjvdjABw-qslkW0czaUaWbWG6Bc1HqAVEU?auth=g.0.eyJraWQiOiIyMzhiNTUxZmMyM2EyM2Y4M2E2ZTE3MmJjZTg0YmU3ZjgxMzAzMmM4IiwiYWxnIjoiUlMyNTYifQ.eyJpc3MiOiJuZXN0LXNlY3VyaXR5LWF1dGhwcm94eSIsInN1YiI6Im5lc3RfaWQ6bmVzdC1waG9lbml4LXByb2Q6MjEyMTgxNDEiLCJwb2wiOiIzcC1vYXV0aC1zY29wZS1BUElfU0RNX1NFUlZJQ0UtY2xpZW50LTIwMjQyNzMxODczNS1qNXQ5bWMyMzZqaG85YXMycWY0dTZxY3NmYW1kaGJ0ci5hcHBzLmdvb2dsZXVzZXJjb250ZW50LmNvbSIsImV4cCI6MTYzMTQ5ODQ1MH0.tPMv-EG32_XlvIZmCpKyJ12Ozu8zGClYp1WbDrqpdtTyfhR2w_a410FySS2m5ontP4dOlEIuwobL-EtLmC7L-UTsMkZcLFI3pkEY9bzONK24CGe3KJSdpE9hCkdK9L2SM9cAQ87j4pRr9OF5LP7YiLbVPpjZTsW_7ou_Y1g-yu5GA7Fnn5ehSKR-Iwq-ykUciC1-YbZfrAl55FYoBbZRRBiQL8r0leC9RcSSaG73vmI7i-2uemhDzysQlPcXt0nNJ9rzgRpE63NxmMxF4hGNUGOT7BWwoXVVsUJpLHnU-wl5S-jXhZbfS3V3cP9akUTeQF_jgmlWDC06QhKSLnHOKA
2021-09-12 23:21:39 ERROR (MainThread) [homeassistant] Error doing job: Future exception was never retrieved
Traceback (most recent call last):
  File "/usr/local/lib/python3.9/concurrent/futures/thread.py", line 52, in run
    result = self.fn(*self.args, **self.kwargs)
TypeError: update() takes 1 positional argument but 2 were given
2021-09-12 23:26:40 ERROR (MainThread) [homeassistant] Error doing job: Future exception was never retrieved
Traceback (most recent call last):
  File "/usr/local/lib/python3.9/concurrent/futures/thread.py", line 52, in run
    result = self.fn(*self.args, **self.kwargs)
TypeError: update() takes 1 positional argument but 2 were given
2021-09-12 23:28:40 ERROR (stream_worker) [libav.rtsp] method DESCRIBE failed: 404 Not Found
2021-09-12 23:28:40 ERROR (stream_worker) [homeassistant.components.stream.worker] Error opening stream rtsps://stream-uc2-bravo.dropcam.com:443/sdm_live_stream/CiQA2vuxr1SLu8rlYbOHo16R-04X0NNEKfeupmXLad7ICSMu8s8ScQAFjsOTS4_b71We2VG7vYgLakwq7JUxt6NJI0n_4qGM-a8nYLnRqRt-bpKX5HVk56GBFLsegX_YCrq7qGjicjVDCJLw6ikxOmGMNn5FOIzSK0Ae_WFyJ5hjvdjABw-qslkW0czaUaWbWG6Bc1HqAVEU?auth=g.0.eyJraWQiOiIyMzhiNTUxZmMyM2EyM2Y4M2E2ZTE3MmJjZTg0YmU3ZjgxMzAzMmM4IiwiYWxnIjoiUlMyNTYifQ.eyJpc3MiOiJuZXN0LXNlY3VyaXR5LWF1dGhwcm94eSIsInN1YiI6Im5lc3RfaWQ6bmVzdC1waG9lbml4LXByb2Q6MjEyMTgxNDEiLCJwb2wiOiIzcC1vYXV0aC1zY29wZS1BUElfU0RNX1NFUlZJQ0UtY2xpZW50LTIwMjQyNzMxODczNS1qNXQ5bWMyMzZqaG85YXMycWY0dTZxY3NmYW1kaGJ0ci5hcHBzLmdvb2dsZXVzZXJjb250ZW50LmNvbSIsImV4cCI6MTYzMTQ5ODQ1MH0.tPMv-EG32_XlvIZmCpKyJ12Ozu8zGClYp1WbDrqpdtTyfhR2w_a410FySS2m5ontP4dOlEIuwobL-EtLmC7L-UTsMkZcLFI3pkEY9bzONK24CGe3KJSdpE9hCkdK9L2SM9cAQ87j4pRr9OF5LP7YiLbVPpjZTsW_7ou_Y1g-yu5GA7Fnn5ehSKR-Iwq-ykUciC1-YbZfrAl55FYoBbZRRBiQL8r0leC9RcSSaG73vmI7i-2uemhDzysQlPcXt0nNJ9rzgRpE63NxmMxF4hGNUGOT7BWwoXVVsUJpLHnU-wl5S-jXhZbfS3V3cP9akUTeQF_jgmlWDC06QhKSLnHOKA
2021-09-12 23:31:03 WARNING (MainThread) [bellows.zigbee.application] Watchdog heartbeat timeout: 
2021-09-12 23:31:18 WARNING (MainThread) [bellows.zigbee.application] Watchdog heartbeat timeout: 
2021-09-12 23:31:33 WARNING (MainThread) [bellows.zigbee.application] Watchdog heartbeat timeout: 
2021-09-12 23:31:41 ERROR (MainThread) [homeassistant] Error doing job: Future exception was never retrieved
Traceback (most recent call last):
  File "/usr/local/lib/python3.9/concurrent/futures/thread.py", line 52, in run
    result = self.fn(*self.args, **self.kwargs)
TypeError: update() takes 1 positional argument but 2 were given
2021-09-12 23:31:48 WARNING (MainThread) [bellows.zigbee.application] Watchdog heartbeat timeout: 
2021-09-12 23:31:52 ERROR (MainThread) [bellows.ezsp] NCP entered failed state. Requesting APP controller restart
2021-09-12 23:36:42 ERROR (MainThread) [homeassistant] Error doing job: Future exception was never retrieved
Traceback (most recent call last):
  File "/usr/local/lib/python3.9/concurrent/futures/thread.py", line 52, in run
    result = self.fn(*self.args, **self.kwargs)
TypeError: update() takes 1 positional argument but 2 were given
2021-09-12 23:38:10 ERROR (stream_worker) [libav.rtsp] method DESCRIBE failed: 404 Not Found
2021-09-12 23:38:10 ERROR (stream_worker) [homeassistant.components.stream.worker] Error opening stream rtsps://stream-uc2-bravo.dropcam.com:443/sdm_live_stream/CiQA2vuxr1SLu8rlYbOHo16R-04X0NNEKfeupmXLad7ICSMu8s8ScQAFjsOTS4_b71We2VG7vYgLakwq7JUxt6NJI0n_4qGM-a8nYLnRqRt-bpKX5HVk56GBFLsegX_YCrq7qGjicjVDCJLw6ikxOmGMNn5FOIzSK0Ae_WFyJ5hjvdjABw-qslkW0czaUaWbWG6Bc1HqAVEU?auth=g.0.eyJraWQiOiIyMzhiNTUxZmMyM2EyM2Y4M2E2ZTE3MmJjZTg0YmU3ZjgxMzAzMmM4IiwiYWxnIjoiUlMyNTYifQ.eyJpc3MiOiJuZXN0LXNlY3VyaXR5LWF1dGhwcm94eSIsInN1YiI6Im5lc3RfaWQ6bmVzdC1waG9lbml4LXByb2Q6MjEyMTgxNDEiLCJwb2wiOiIzcC1vYXV0aC1zY29wZS1BUElfU0RNX1NFUlZJQ0UtY2xpZW50LTIwMjQyNzMxODczNS1qNXQ5bWMyMzZqaG85YXMycWY0dTZxY3NmYW1kaGJ0ci5hcHBzLmdvb2dsZXVzZXJjb250ZW50LmNvbSIsImV4cCI6MTYzMTQ5ODQ1MH0.tPMv-EG32_XlvIZmCpKyJ12Ozu8zGClYp1WbDrqpdtTyfhR2w_a410FySS2m5ontP4dOlEIuwobL-EtLmC7L-UTsMkZcLFI3pkEY9bzONK24CGe3KJSdpE9hCkdK9L2SM9cAQ87j4pRr9OF5LP7YiLbVPpjZTsW_7ou_Y1g-yu5GA7Fnn5ehSKR-Iwq-ykUciC1-YbZfrAl55FYoBbZRRBiQL8r0leC9RcSSaG73vmI7i-2uemhDzysQlPcXt0nNJ9rzgRpE63NxmMxF4hGNUGOT7BWwoXVVsUJpLHnU-wl5S-jXhZbfS3V3cP9akUTeQF_jgmlWDC06QhKSLnHOKA
2021-09-12 23:40:45 ERROR (MainThread) [homeassistant] Error doing job: Task was destroyed but it is pending!
2021-09-12 23:41:43 ERROR (MainThread) [homeassistant] Error doing job: Future exception was never retrieved
Traceback (most recent call last):
  File "/usr/local/lib/python3.9/concurrent/futures/thread.py", line 52, in run
    result = self.fn(*self.args, **self.kwargs)
TypeError: update() takes 1 positional argument but 2 were given
2021-09-12 23:46:44 ERROR (MainThread) [homeassistant] Error doing job: Future exception was never retrieved
Traceback (most recent call last):
  File "/usr/local/lib/python3.9/concurrent/futures/thread.py", line 52, in run
    result = self.fn(*self.args, **self.kwargs)
TypeError: update() takes 1 positional argument but 2 were given
2021-09-12 23:47:51 ERROR (stream_worker) [libav.rtsp] method DESCRIBE failed: 404 Not Found
2021-09-12 23:47:51 ERROR (stream_worker) [homeassistant.components.stream.worker] Error opening stream rtsps://stream-uc2-bravo.dropcam.com:443/sdm_live_stream/CiQA2vuxr1SLu8rlYbOHo16R-04X0NNEKfeupmXLad7ICSMu8s8ScQAFjsOTS4_b71We2VG7vYgLakwq7JUxt6NJI0n_4qGM-a8nYLnRqRt-bpKX5HVk56GBFLsegX_YCrq7qGjicjVDCJLw6ikxOmGMNn5FOIzSK0Ae_WFyJ5hjvdjABw-qslkW0czaUaWbWG6Bc1HqAVEU?auth=g.0.eyJraWQiOiIyMzhiNTUxZmMyM2EyM2Y4M2E2ZTE3MmJjZTg0YmU3ZjgxMzAzMmM4IiwiYWxnIjoiUlMyNTYifQ.eyJpc3MiOiJuZXN0LXNlY3VyaXR5LWF1dGhwcm94eSIsInN1YiI6Im5lc3RfaWQ6bmVzdC1waG9lbml4LXByb2Q6MjEyMTgxNDEiLCJwb2wiOiIzcC1vYXV0aC1zY29wZS1BUElfU0RNX1NFUlZJQ0UtY2xpZW50LTIwMjQyNzMxODczNS1qNXQ5bWMyMzZqaG85YXMycWY0dTZxY3NmYW1kaGJ0ci5hcHBzLmdvb2dsZXVzZXJjb250ZW50LmNvbSIsImV4cCI6MTYzMTQ5ODQ1MH0.tPMv-EG32_XlvIZmCpKyJ12Ozu8zGClYp1WbDrqpdtTyfhR2w_a410FySS2m5ontP4dOlEIuwobL-EtLmC7L-UTsMkZcLFI3pkEY9bzONK24CGe3KJSdpE9hCkdK9L2SM9cAQ87j4pRr9OF5LP7YiLbVPpjZTsW_7ou_Y1g-yu5GA7Fnn5ehSKR-Iwq-ykUciC1-YbZfrAl55FYoBbZRRBiQL8r0leC9RcSSaG73vmI7i-2uemhDzysQlPcXt0nNJ9rzgRpE63NxmMxF4hGNUGOT7BWwoXVVsUJpLHnU-wl5S-jXhZbfS3V3cP9akUTeQF_jgmlWDC06QhKSLnHOKA
2021-09-12 23:51:45 ERROR (MainThread) [homeassistant] Error doing job: Future exception was never retrieved
Traceback (most recent call last):
  File "/usr/local/lib/python3.9/concurrent/futures/thread.py", line 52, in run
    result = self.fn(*self.args, **self.kwargs)
TypeError: update() takes 1 positional argument but 2 were given
2021-09-12 23:56:46 ERROR (MainThread) [homeassistant] Error doing job: Future exception was never retrieved
Traceback (most recent call last):
  File "/usr/local/lib/python3.9/concurrent/futures/thread.py", line 52, in run
    result = self.fn(*self.args, **self.kwargs)
TypeError: update() takes 1 positional argument but 2 were given
2021-09-12 23:57:41 ERROR (stream_worker) [libav.rtsp] method DESCRIBE failed: 404 Not Found
2021-09-12 23:57:41 ERROR (stream_worker) [homeassistant.components.stream.worker] Error opening stream rtsps://stream-uc2-bravo.dropcam.com:443/sdm_live_stream/CiQA2vuxr1SLu8rlYbOHo16R-04X0NNEKfeupmXLad7ICSMu8s8ScQAFjsOTS4_b71We2VG7vYgLakwq7JUxt6NJI0n_4qGM-a8nYLnRqRt-bpKX5HVk56GBFLsegX_YCrq7qGjicjVDCJLw6ikxOmGMNn5FOIzSK0Ae_WFyJ5hjvdjABw-qslkW0czaUaWbWG6Bc1HqAVEU?auth=g.0.eyJraWQiOiIyMzhiNTUxZmMyM2EyM2Y4M2E2ZTE3MmJjZTg0YmU3ZjgxMzAzMmM4IiwiYWxnIjoiUlMyNTYifQ.eyJpc3MiOiJuZXN0LXNlY3VyaXR5LWF1dGhwcm94eSIsInN1YiI6Im5lc3RfaWQ6bmVzdC1waG9lbml4LXByb2Q6MjEyMTgxNDEiLCJwb2wiOiIzcC1vYXV0aC1zY29wZS1BUElfU0RNX1NFUlZJQ0UtY2xpZW50LTIwMjQyNzMxODczNS1qNXQ5bWMyMzZqaG85YXMycWY0dTZxY3NmYW1kaGJ0ci5hcHBzLmdvb2dsZXVzZXJjb250ZW50LmNvbSIsImV4cCI6MTYzMTQ5ODQ1MH0.tPMv-EG32_XlvIZmCpKyJ12Ozu8zGClYp1WbDrqpdtTyfhR2w_a410FySS2m5ontP4dOlEIuwobL-EtLmC7L-UTsMkZcLFI3pkEY9bzONK24CGe3KJSdpE9hCkdK9L2SM9cAQ87j4pRr9OF5LP7YiLbVPpjZTsW_7ou_Y1g-yu5GA7Fnn5ehSKR-Iwq-ykUciC1-YbZfrAl55FYoBbZRRBiQL8r0leC9RcSSaG73vmI7i-2uemhDzysQlPcXt0nNJ9rzgRpE63NxmMxF4hGNUGOT7BWwoXVVsUJpLHnU-wl5S-jXhZbfS3V3cP9akUTeQF_jgmlWDC06QhKSLnHOKA
2021-09-13 00:01:47 ERROR (MainThread) [homeassistant] Error doing job: Future exception was never retrieved
Traceback (most recent call last):
  File "/usr/local/lib/python3.9/concurrent/futures/thread.py", line 52, in run
    result = self.fn(*self.args, **self.kwargs)
TypeError: update() takes 1 positional argument but 2 were given
2021-09-13 00:06:48 ERROR (MainThread) [homeassistant] Error doing job: Future exception was never retrieved
Traceback (most recent call last):
  File "/usr/local/lib/python3.9/concurrent/futures/thread.py", line 52, in run
    result = self.fn(*self.args, **self.kwargs)
TypeError: update() takes 1 positional argument but 2 were given
2021-09-13 00:07:42 ERROR (stream_worker) [libav.rtsp] method DESCRIBE failed: 404 Not Found
2021-09-13 00:07:42 ERROR (stream_worker) [homeassistant.components.stream.worker] Error opening stream rtsps://stream-uc2-bravo.dropcam.com:443/sdm_live_stream/CiQA2vuxr1SLu8rlYbOHo16R-04X0NNEKfeupmXLad7ICSMu8s8ScQAFjsOTS4_b71We2VG7vYgLakwq7JUxt6NJI0n_4qGM-a8nYLnRqRt-bpKX5HVk56GBFLsegX_YCrq7qGjicjVDCJLw6ikxOmGMNn5FOIzSK0Ae_WFyJ5hjvdjABw-qslkW0czaUaWbWG6Bc1HqAVEU?auth=g.0.eyJraWQiOiIyMzhiNTUxZmMyM2EyM2Y4M2E2ZTE3MmJjZTg0YmU3ZjgxMzAzMmM4IiwiYWxnIjoiUlMyNTYifQ.eyJpc3MiOiJuZXN0LXNlY3VyaXR5LWF1dGhwcm94eSIsInN1YiI6Im5lc3RfaWQ6bmVzdC1waG9lbml4LXByb2Q6MjEyMTgxNDEiLCJwb2wiOiIzcC1vYXV0aC1zY29wZS1BUElfU0RNX1NFUlZJQ0UtY2xpZW50LTIwMjQyNzMxODczNS1qNXQ5bWMyMzZqaG85YXMycWY0dTZxY3NmYW1kaGJ0ci5hcHBzLmdvb2dsZXVzZXJjb250ZW50LmNvbSIsImV4cCI6MTYzMTQ5ODQ1MH0.tPMv-EG32_XlvIZmCpKyJ12Ozu8zGClYp1WbDrqpdtTyfhR2w_a410FySS2m5ontP4dOlEIuwobL-EtLmC7L-UTsMkZcLFI3pkEY9bzONK24CGe3KJSdpE9hCkdK9L2SM9cAQ87j4pRr9OF5LP7YiLbVPpjZTsW_7ou_Y1g-yu5GA7Fnn5ehSKR-Iwq-ykUciC1-YbZfrAl55FYoBbZRRBiQL8r0leC9RcSSaG73vmI7i-2uemhDzysQlPcXt0nNJ9rzgRpE63NxmMxF4hGNUGOT7BWwoXVVsUJpLHnU-wl5S-jXhZbfS3V3cP9akUTeQF_jgmlWDC06QhKSLnHOKA
2021-09-13 00:11:49 ERROR (MainThread) [homeassistant] Error doing job: Future exception was never retrieved
Traceback (most recent call last):
  File "/usr/local/lib/python3.9/concurrent/futures/thread.py", line 52, in run
    result = self.fn(*self.args, **self.kwargs)
TypeError: update() takes 1 positional argument but 2 were given
2021-09-13 00:16:50 ERROR (MainThread) [homeassistant] Error doing job: Future exception was never retrieved
Traceback (most recent call last):
  File "/usr/local/lib/python3.9/concurrent/futures/thread.py", line 52, in run
    result = self.fn(*self.args, **self.kwargs)
TypeError: update() takes 1 positional argument but 2 were given
2021-09-13 00:17:52 ERROR (stream_worker) [libav.rtsp] method DESCRIBE failed: 404 Not Found
2021-09-13 00:17:52 ERROR (stream_worker) [homeassistant.components.stream.worker] Error opening stream rtsps://stream-uc2-bravo.dropcam.com:443/sdm_live_stream/CiQA2vuxr1SLu8rlYbOHo16R-04X0NNEKfeupmXLad7ICSMu8s8ScQAFjsOTS4_b71We2VG7vYgLakwq7JUxt6NJI0n_4qGM-a8nYLnRqRt-bpKX5HVk56GBFLsegX_YCrq7qGjicjVDCJLw6ikxOmGMNn5FOIzSK0Ae_WFyJ5hjvdjABw-qslkW0czaUaWbWG6Bc1HqAVEU?auth=g.0.eyJraWQiOiIyMzhiNTUxZmMyM2EyM2Y4M2E2ZTE3MmJjZTg0YmU3ZjgxMzAzMmM4IiwiYWxnIjoiUlMyNTYifQ.eyJpc3MiOiJuZXN0LXNlY3VyaXR5LWF1dGhwcm94eSIsInN1YiI6Im5lc3RfaWQ6bmVzdC1waG9lbml4LXByb2Q6MjEyMTgxNDEiLCJwb2wiOiIzcC1vYXV0aC1zY29wZS1BUElfU0RNX1NFUlZJQ0UtY2xpZW50LTIwMjQyNzMxODczNS1qNXQ5bWMyMzZqaG85YXMycWY0dTZxY3NmYW1kaGJ0ci5hcHBzLmdvb2dsZXVzZXJjb250ZW50LmNvbSIsImV4cCI6MTYzMTQ5ODQ1MH0.tPMv-EG32_XlvIZmCpKyJ12Ozu8zGClYp1WbDrqpdtTyfhR2w_a410FySS2m5ontP4dOlEIuwobL-EtLmC7L-UTsMkZcLFI3pkEY9bzONK24CGe3KJSdpE9hCkdK9L2SM9cAQ87j4pRr9OF5LP7YiLbVPpjZTsW_7ou_Y1g-yu5GA7Fnn5ehSKR-Iwq-ykUciC1-YbZfrAl55FYoBbZRRBiQL8r0leC9RcSSaG73vmI7i-2uemhDzysQlPcXt0nNJ9rzgRpE63NxmMxF4hGNUGOT7BWwoXVVsUJpLHnU-wl5S-jXhZbfS3V3cP9akUTeQF_jgmlWDC06QhKSLnHOKA
2021-09-13 00:21:51 ERROR (MainThread) [homeassistant] Error doing job: Future exception was never retrieved
Traceback (most recent call last):
  File "/usr/local/lib/python3.9/concurrent/futures/thread.py", line 52, in run
    result = self.fn(*self.args, **self.kwargs)
TypeError: update() takes 1 positional argument but 2 were given
2021-09-13 00:26:52 ERROR (MainThread) [homeassistant] Error doing job: Future exception was never retrieved
Traceback (most recent call last):
  File "/usr/local/lib/python3.9/concurrent/futures/thread.py", line 52, in run
    result = self.fn(*self.args, **self.kwargs)
TypeError: update() takes 1 positional argument but 2 were given
2021-09-13 00:28:13 ERROR (stream_worker) [libav.rtsp] method DESCRIBE failed: 404 Not Found
2021-09-13 00:28:13 ERROR (stream_worker) [homeassistant.components.stream.worker] Error opening stream rtsps://stream-uc2-bravo.dropcam.com:443/sdm_live_stream/CiQA2vuxr1SLu8rlYbOHo16R-04X0NNEKfeupmXLad7ICSMu8s8ScQAFjsOTS4_b71We2VG7vYgLakwq7JUxt6NJI0n_4qGM-a8nYLnRqRt-bpKX5HVk56GBFLsegX_YCrq7qGjicjVDCJLw6ikxOmGMNn5FOIzSK0Ae_WFyJ5hjvdjABw-qslkW0czaUaWbWG6Bc1HqAVEU?auth=g.0.eyJraWQiOiIyMzhiNTUxZmMyM2EyM2Y4M2E2ZTE3MmJjZTg0YmU3ZjgxMzAzMmM4IiwiYWxnIjoiUlMyNTYifQ.eyJpc3MiOiJuZXN0LXNlY3VyaXR5LWF1dGhwcm94eSIsInN1YiI6Im5lc3RfaWQ6bmVzdC1waG9lbml4LXByb2Q6MjEyMTgxNDEiLCJwb2wiOiIzcC1vYXV0aC1zY29wZS1BUElfU0RNX1NFUlZJQ0UtY2xpZW50LTIwMjQyNzMxODczNS1qNXQ5bWMyMzZqaG85YXMycWY0dTZxY3NmYW1kaGJ0ci5hcHBzLmdvb2dsZXVzZXJjb250ZW50LmNvbSIsImV4cCI6MTYzMTQ5ODQ1MH0.tPMv-EG32_XlvIZmCpKyJ12Ozu8zGClYp1WbDrqpdtTyfhR2w_a410FySS2m5ontP4dOlEIuwobL-EtLmC7L-UTsMkZcLFI3pkEY9bzONK24CGe3KJSdpE9hCkdK9L2SM9cAQ87j4pRr9OF5LP7YiLbVPpjZTsW_7ou_Y1g-yu5GA7Fnn5ehSKR-Iwq-ykUciC1-YbZfrAl55FYoBbZRRBiQL8r0leC9RcSSaG73vmI7i-2uemhDzysQlPcXt0nNJ9rzgRpE63NxmMxF4hGNUGOT7BWwoXVVsUJpLHnU-wl5S-jXhZbfS3V3cP9akUTeQF_jgmlWDC06QhKSLnHOKA
2021-09-13 00:31:53 ERROR (MainThread) [homeassistant] Error doing job: Future exception was never retrieved
Traceback (most recent call last):
  File "/usr/local/lib/python3.9/concurrent/futures/thread.py", line 52, in run
    result = self.fn(*self.args, **self.kwargs)
TypeError: update() takes 1 positional argument but 2 were given
2021-09-13 00:36:54 ERROR (MainThread) [homeassistant] Error doing job: Future exception was never retrieved
Traceback (most recent call last):
  File "/usr/local/lib/python3.9/concurrent/futures/thread.py", line 52, in run
    result = self.fn(*self.args, **self.kwargs)
TypeError: update() takes 1 positional argument but 2 were given
2021-09-13 00:38:43 ERROR (stream_worker) [libav.rtsp] method DESCRIBE failed: 404 Not Found
2021-09-13 00:38:43 ERROR (stream_worker) [homeassistant.components.stream.worker] Error opening stream rtsps://stream-uc2-bravo.dropcam.com:443/sdm_live_stream/CiQA2vuxr1SLu8rlYbOHo16R-04X0NNEKfeupmXLad7ICSMu8s8ScQAFjsOTS4_b71We2VG7vYgLakwq7JUxt6NJI0n_4qGM-a8nYLnRqRt-bpKX5HVk56GBFLsegX_YCrq7qGjicjVDCJLw6ikxOmGMNn5FOIzSK0Ae_WFyJ5hjvdjABw-qslkW0czaUaWbWG6Bc1HqAVEU?auth=g.0.eyJraWQiOiIyMzhiNTUxZmMyM2EyM2Y4M2E2ZTE3MmJjZTg0YmU3ZjgxMzAzMmM4IiwiYWxnIjoiUlMyNTYifQ.eyJpc3MiOiJuZXN0LXNlY3VyaXR5LWF1dGhwcm94eSIsInN1YiI6Im5lc3RfaWQ6bmVzdC1waG9lbml4LXByb2Q6MjEyMTgxNDEiLCJwb2wiOiIzcC1vYXV0aC1zY29wZS1BUElfU0RNX1NFUlZJQ0UtY2xpZW50LTIwMjQyNzMxODczNS1qNXQ5bWMyMzZqaG85YXMycWY0dTZxY3NmYW1kaGJ0ci5hcHBzLmdvb2dsZXVzZXJjb250ZW50LmNvbSIsImV4cCI6MTYzMTQ5ODQ1MH0.tPMv-EG32_XlvIZmCpKyJ12Ozu8zGClYp1WbDrqpdtTyfhR2w_a410FySS2m5ontP4dOlEIuwobL-EtLmC7L-UTsMkZcLFI3pkEY9bzONK24CGe3KJSdpE9hCkdK9L2SM9cAQ87j4pRr9OF5LP7YiLbVPpjZTsW_7ou_Y1g-yu5GA7Fnn5ehSKR-Iwq-ykUciC1-YbZfrAl55FYoBbZRRBiQL8r0leC9RcSSaG73vmI7i-2uemhDzysQlPcXt0nNJ9rzgRpE63NxmMxF4hGNUGOT7BWwoXVVsUJpLHnU-wl5S-jXhZbfS3V3cP9akUTeQF_jgmlWDC06QhKSLnHOKA
2021-09-13 00:41:20 WARNING (MainThread) [homeassistant.helpers.entity] Update of sensor.iss_coordinates is taking over 10 seconds
2021-09-13 00:41:21 WARNING (MainThread) [homeassistant.components.rest.sensor] REST result could not be parsed as JSON
2021-09-13 00:41:21 ERROR (MainThread) [homeassistant.helpers.template] Template variable error: 'mappingproxy object' has no attribute 'iss_position' when rendering '{"longitude": "{{ states.sensor.iss_coordinates.attributes.iss_position.longitude | float }}","latitude": "{{ states.sensor.iss_coordinates.attributes.iss_position.latitude | float }}"}'
2021-09-13 00:41:21 ERROR (MainThread) [homeassistant.components.automation.iss_location_update] ISS Location Update: Error executing script. Error for call_service at pos 1: Error rendering data template: UndefinedError: 'mappingproxy object' has no attribute 'iss_position'
2021-09-13 00:41:21 ERROR (MainThread) [homeassistant.components.automation.iss_location_update] Error while executing automation automation.iss_location_update: Error rendering data template: UndefinedError: 'mappingproxy object' has no attribute 'iss_position'
2021-09-13 00:41:27 WARNING (MainThread) [homeassistant.components.rest.sensor] REST result could not be parsed as JSON
2021-09-13 00:41:28 WARNING (MainThread) [homeassistant.components.rest.sensor] REST result could not be parsed as JSON
2021-09-13 00:41:55 ERROR (MainThread) [homeassistant] Error doing job: Future exception was never retrieved
Traceback (most recent call last):
  File "/usr/local/lib/python3.9/concurrent/futures/thread.py", line 52, in run
    result = self.fn(*self.args, **self.kwargs)
TypeError: update() takes 1 positional argument but 2 were given
2021-09-13 00:41:55 WARNING (MainThread) [homeassistant.components.rest.sensor] REST result could not be parsed as JSON
2021-09-13 00:41:56 WARNING (MainThread) [homeassistant.components.rest.sensor] REST result could not be parsed as JSON
2021-09-13 00:41:56 ERROR (MainThread) [homeassistant.helpers.template] Template variable error: 'mappingproxy object' has no attribute 'iss_position' when rendering '{"longitude": "{{ states.sensor.iss_coordinates.attributes.iss_position.longitude | float }}","latitude": "{{ states.sensor.iss_coordinates.attributes.iss_position.latitude | float }}"}'
2021-09-13 00:41:56 ERROR (MainThread) [homeassistant.components.automation.iss_location_update] ISS Location Update: Error executing script. Error for call_service at pos 1: Error rendering data template: UndefinedError: 'mappingproxy object' has no attribute 'iss_position'
2021-09-13 00:41:56 ERROR (MainThread) [homeassistant.components.automation.iss_location_update] Error while executing automation automation.iss_location_update: Error rendering data template: UndefinedError: 'mappingproxy object' has no attribute 'iss_position'
2021-09-13 00:42:12 WARNING (MainThread) [homeassistant.components.rest.sensor] REST result could not be parsed as JSON
2021-09-13 00:42:27 WARNING (MainThread) [homeassistant.components.rest.sensor] REST result could not be parsed as JSON
2021-09-13 00:42:28 ERROR (MainThread) [homeassistant.helpers.entity] Update for binary_sensor.iss fails
Traceback (most recent call last):
  File "/usr/src/homeassistant/homeassistant/helpers/entity.py", line 446, in async_update_ha_state
    await self.async_device_update()
  File "/usr/src/homeassistant/homeassistant/helpers/entity.py", line 641, in async_device_update
    raise exc
  File "/usr/local/lib/python3.9/concurrent/futures/thread.py", line 52, in run
    result = self.fn(*self.args, **self.kwargs)
  File "/usr/src/homeassistant/homeassistant/components/iss/binary_sensor.py", line 99, in update
    self.iss_data.update()
  File "/usr/src/homeassistant/homeassistant/util/__init__.py", line 277, in wrapper
    result = method(*args, **kwargs)
  File "/usr/src/homeassistant/homeassistant/components/iss/binary_sensor.py", line 119, in update
    self.is_above = iss.is_ISS_above(self.latitude, self.longitude)
  File "/usr/local/lib/python3.9/site-packages/pyiss/__init__.py", line 140, in is_ISS_above
    test = self.pass_times(latitude, longitude, altitude, 2)
  File "/usr/local/lib/python3.9/site-packages/pyiss/__init__.py", line 93, in pass_times
    raise Exception("Error server n {}".format(data.status_code))
Exception: Error server n 500
2021-09-13 00:42:28 WARNING (MainThread) [homeassistant.components.rest.sensor] REST result could not be parsed as JSON
2021-09-13 00:42:44 WARNING (MainThread) [homeassistant.components.rest.sensor] REST result could not be parsed as JSON
2021-09-13 00:43:50 WARNING (MainThread) [homeassistant.helpers.entity] Update of sensor.iss_coordinates is taking over 10 seconds
2021-09-13 00:43:50 ERROR (MainThread) [homeassistant.components.rest.data] Error fetching data: http://api.open-notify.org/iss-now.json failed with 
2021-09-13 00:43:50 WARNING (MainThread) [homeassistant.components.rest.sensor] Empty reply found when expecting JSON data
2021-09-13 00:43:50 ERROR (MainThread) [homeassistant.helpers.template] Template variable error: 'mappingproxy object' has no attribute 'iss_position' when rendering '{"longitude": "{{ states.sensor.iss_coordinates.attributes.iss_position.longitude | float }}","latitude": "{{ states.sensor.iss_coordinates.attributes.iss_position.latitude | float }}"}'
2021-09-13 00:43:50 ERROR (MainThread) [homeassistant.components.automation.iss_location_update] ISS Location Update: Error executing script. Error for call_service at pos 1: Error rendering data template: UndefinedError: 'mappingproxy object' has no attribute 'iss_position'
2021-09-13 00:43:50 ERROR (MainThread) [homeassistant.components.automation.iss_location_update] Error while executing automation automation.iss_location_update: Error rendering data template: UndefinedError: 'mappingproxy object' has no attribute 'iss_position'
2021-09-13 00:44:04 WARNING (MainThread) [homeassistant.components.rest.sensor] REST result could not be parsed as JSON
2021-09-13 00:44:05 WARNING (MainThread) [homeassistant.helpers.entity] Update of sensor.iss_coordinates is taking over 10 seconds
2021-09-13 00:44:05 ERROR (MainThread) [homeassistant.components.rest.data] Error fetching data: http://api.open-notify.org/iss-now.json failed with 
2021-09-13 00:44:05 WARNING (MainThread) [homeassistant.components.rest.sensor] Empty reply found when expecting JSON data
2021-09-13 00:44:20 WARNING (MainThread) [homeassistant.helpers.entity] Update of sensor.iss_coordinates is taking over 10 seconds
2021-09-13 00:44:20 ERROR (MainThread) [homeassistant.components.rest.data] Error fetching data: http://api.open-notify.org/iss-now.json failed with 
2021-09-13 00:44:20 WARNING (MainThread) [homeassistant.components.rest.sensor] Empty reply found when expecting JSON data
2021-09-13 00:44:25 ERROR (MainThread) [homeassistant.helpers.entity] Update for binary_sensor.iss fails
Traceback (most recent call last):
  File "/usr/src/homeassistant/homeassistant/helpers/entity.py", line 446, in async_update_ha_state
    await self.async_device_update()
  File "/usr/src/homeassistant/homeassistant/helpers/entity.py", line 641, in async_device_update
    raise exc
  File "/usr/local/lib/python3.9/concurrent/futures/thread.py", line 52, in run
    result = self.fn(*self.args, **self.kwargs)
  File "/usr/src/homeassistant/homeassistant/components/iss/binary_sensor.py", line 99, in update
    self.iss_data.update()
  File "/usr/src/homeassistant/homeassistant/util/__init__.py", line 277, in wrapper
    result = method(*args, **kwargs)
  File "/usr/src/homeassistant/homeassistant/components/iss/binary_sensor.py", line 119, in update
    self.is_above = iss.is_ISS_above(self.latitude, self.longitude)
  File "/usr/local/lib/python3.9/site-packages/pyiss/__init__.py", line 140, in is_ISS_above
    test = self.pass_times(latitude, longitude, altitude, 2)
  File "/usr/local/lib/python3.9/site-packages/pyiss/__init__.py", line 93, in pass_times
    raise Exception("Error server n {}".format(data.status_code))
Exception: Error server n 500
2021-09-13 00:44:27 WARNING (MainThread) [homeassistant.components.rest.sensor] REST result could not be parsed as JSON
2021-09-13 00:44:27 ERROR (MainThread) [homeassistant.helpers.template] Template variable error: 'mappingproxy object' has no attribute 'iss_position' when rendering '{"longitude": "{{ states.sensor.iss_coordinates.attributes.iss_position.longitude | float }}","latitude": "{{ states.sensor.iss_coordinates.attributes.iss_position.latitude | float }}"}'
2021-09-13 00:44:27 ERROR (MainThread) [homeassistant.components.automation.iss_location_update] ISS Location Update: Error executing script. Error for call_service at pos 1: Error rendering data template: UndefinedError: 'mappingproxy object' has no attribute 'iss_position'
2021-09-13 00:44:27 ERROR (MainThread) [homeassistant.components.automation.iss_location_update] Error while executing automation automation.iss_location_update: Error rendering data template: UndefinedError: 'mappingproxy object' has no attribute 'iss_position'
2021-09-13 00:44:34 WARNING (MainThread) [homeassistant.helpers.entity] Update of sensor.iss_people_in_space is taking over 10 seconds
2021-09-13 00:44:34 ERROR (MainThread) [homeassistant.components.rest.data] Error fetching data: http://api.open-notify.org/astros.json failed with 
2021-09-13 00:44:34 WARNING (MainThread) [homeassistant.components.rest.sensor] Empty reply found when expecting JSON data
2021-09-13 00:44:41 WARNING (MainThread) [homeassistant.components.rest.sensor] REST result could not be parsed as JSON
2021-09-13 00:44:53 ERROR (MainThread) [homeassistant.helpers.entity] Update for binary_sensor.iss fails
Traceback (most recent call last):
  File "/usr/src/homeassistant/homeassistant/helpers/entity.py", line 446, in async_update_ha_state
    await self.async_device_update()
  File "/usr/src/homeassistant/homeassistant/helpers/entity.py", line 641, in async_device_update
    raise exc
  File "/usr/local/lib/python3.9/concurrent/futures/thread.py", line 52, in run
    result = self.fn(*self.args, **self.kwargs)
  File "/usr/src/homeassistant/homeassistant/components/iss/binary_sensor.py", line 99, in update
    self.iss_data.update()
  File "/usr/src/homeassistant/homeassistant/util/__init__.py", line 277, in wrapper
    result = method(*args, **kwargs)
  File "/usr/src/homeassistant/homeassistant/components/iss/binary_sensor.py", line 119, in update
    self.is_above = iss.is_ISS_above(self.latitude, self.longitude)
  File "/usr/local/lib/python3.9/site-packages/pyiss/__init__.py", line 140, in is_ISS_above
    test = self.pass_times(latitude, longitude, altitude, 2)
  File "/usr/local/lib/python3.9/site-packages/pyiss/__init__.py", line 93, in pass_times
    raise Exception("Error server n {}".format(data.status_code))
Exception: Error server n 500
2021-09-13 00:44:56 WARNING (MainThread) [homeassistant.components.rest.sensor] REST result could not be parsed as JSON
2021-09-13 00:44:56 WARNING (MainThread) [homeassistant.components.rest.sensor] REST result could not be parsed as JSON
2021-09-13 00:46:56 ERROR (MainThread) [homeassistant] Error doing job: Future exception was never retrieved
Traceback (most recent call last):
  File "/usr/local/lib/python3.9/concurrent/futures/thread.py", line 52, in run
    result = self.fn(*self.args, **self.kwargs)
TypeError: update() takes 1 positional argument but 2 were given
2021-09-13 00:49:24 ERROR (stream_worker) [libav.rtsp] method DESCRIBE failed: 404 Not Found
2021-09-13 00:49:24 ERROR (stream_worker) [homeassistant.components.stream.worker] Error opening stream rtsps://stream-uc2-bravo.dropcam.com:443/sdm_live_stream/CiQA2vuxr1SLu8rlYbOHo16R-04X0NNEKfeupmXLad7ICSMu8s8ScQAFjsOTS4_b71We2VG7vYgLakwq7JUxt6NJI0n_4qGM-a8nYLnRqRt-bpKX5HVk56GBFLsegX_YCrq7qGjicjVDCJLw6ikxOmGMNn5FOIzSK0Ae_WFyJ5hjvdjABw-qslkW0czaUaWbWG6Bc1HqAVEU?auth=g.0.eyJraWQiOiIyMzhiNTUxZmMyM2EyM2Y4M2E2ZTE3MmJjZTg0YmU3ZjgxMzAzMmM4IiwiYWxnIjoiUlMyNTYifQ.eyJpc3MiOiJuZXN0LXNlY3VyaXR5LWF1dGhwcm94eSIsInN1YiI6Im5lc3RfaWQ6bmVzdC1waG9lbml4LXByb2Q6MjEyMTgxNDEiLCJwb2wiOiIzcC1vYXV0aC1zY29wZS1BUElfU0RNX1NFUlZJQ0UtY2xpZW50LTIwMjQyNzMxODczNS1qNXQ5bWMyMzZqaG85YXMycWY0dTZxY3NmYW1kaGJ0ci5hcHBzLmdvb2dsZXVzZXJjb250ZW50LmNvbSIsImV4cCI6MTYzMTQ5ODQ1MH0.tPMv-EG32_XlvIZmCpKyJ12Ozu8zGClYp1WbDrqpdtTyfhR2w_a410FySS2m5ontP4dOlEIuwobL-EtLmC7L-UTsMkZcLFI3pkEY9bzONK24CGe3KJSdpE9hCkdK9L2SM9cAQ87j4pRr9OF5LP7YiLbVPpjZTsW_7ou_Y1g-yu5GA7Fnn5ehSKR-Iwq-ykUciC1-YbZfrAl55FYoBbZRRBiQL8r0leC9RcSSaG73vmI7i-2uemhDzysQlPcXt0nNJ9rzgRpE63NxmMxF4hGNUGOT7BWwoXVVsUJpLHnU-wl5S-jXhZbfS3V3cP9akUTeQF_jgmlWDC06QhKSLnHOKA
2021-09-13 00:51:57 ERROR (MainThread) [homeassistant] Error doing job: Future exception was never retrieved
Traceback (most recent call last):
  File "/usr/local/lib/python3.9/concurrent/futures/thread.py", line 52, in run
    result = self.fn(*self.args, **self.kwargs)
TypeError: update() takes 1 positional argument but 2 were given
2021-09-13 00:54:20 WARNING (MainThread) [homeassistant.helpers.entity] Update of sensor.iss_coordinates is taking over 10 seconds
2021-09-13 00:54:20 ERROR (MainThread) [homeassistant.components.rest.data] Error fetching data: http://api.open-notify.org/iss-now.json failed with 
2021-09-13 00:54:20 WARNING (MainThread) [homeassistant.components.rest.sensor] Empty reply found when expecting JSON data
2021-09-13 00:54:20 ERROR (MainThread) [homeassistant.helpers.template] Template variable error: 'mappingproxy object' has no attribute 'iss_position' when rendering '{"longitude": "{{ states.sensor.iss_coordinates.attributes.iss_position.longitude | float }}","latitude": "{{ states.sensor.iss_coordinates.attributes.iss_position.latitude | float }}"}'
2021-09-13 00:54:20 ERROR (MainThread) [homeassistant.components.automation.iss_location_update] ISS Location Update: Error executing script. Error for call_service at pos 1: Error rendering data template: UndefinedError: 'mappingproxy object' has no attribute 'iss_position'
2021-09-13 00:54:20 ERROR (MainThread) [homeassistant.components.automation.iss_location_update] Error while executing automation automation.iss_location_update: Error rendering data template: UndefinedError: 'mappingproxy object' has no attribute 'iss_position'
2021-09-13 00:54:28 ERROR (SyncWorker_2) [homeassistant.components.iss.binary_sensor] Unable to retrieve data
2021-09-13 00:54:34 WARNING (MainThread) [homeassistant.helpers.entity] Update of sensor.iss_people_in_space is taking over 10 seconds
2021-09-13 00:54:34 ERROR (MainThread) [homeassistant.components.rest.data] Error fetching data: http://api.open-notify.org/astros.json failed with 
2021-09-13 00:54:34 WARNING (MainThread) [homeassistant.components.rest.sensor] Empty reply found when expecting JSON data
2021-09-13 00:54:35 WARNING (MainThread) [homeassistant.helpers.entity] Update of sensor.iss_coordinates is taking over 10 seconds
2021-09-13 00:54:35 ERROR (MainThread) [homeassistant.components.rest.data] Error fetching data: http://api.open-notify.org/iss-now.json failed with 
2021-09-13 00:54:35 WARNING (MainThread) [homeassistant.components.rest.sensor] Empty reply found when expecting JSON data
2021-09-13 00:54:50 WARNING (MainThread) [homeassistant.helpers.entity] Update of sensor.iss_coordinates is taking over 10 seconds
2021-09-13 00:54:50 ERROR (MainThread) [homeassistant.components.rest.data] Error fetching data: http://api.open-notify.org/iss-now.json failed with 
2021-09-13 00:54:50 WARNING (MainThread) [homeassistant.components.rest.sensor] Empty reply found when expecting JSON data
2021-09-13 00:55:04 WARNING (MainThread) [homeassistant.helpers.entity] Update of sensor.iss_people_in_space is taking over 10 seconds
2021-09-13 00:55:04 ERROR (MainThread) [homeassistant.components.rest.data] Error fetching data: http://api.open-notify.org/astros.json failed with 
2021-09-13 00:55:04 WARNING (MainThread) [homeassistant.components.rest.sensor] Empty reply found when expecting JSON data
2021-09-13 00:55:05 WARNING (MainThread) [homeassistant.helpers.entity] Update of sensor.iss_coordinates is taking over 10 seconds
2021-09-13 00:55:05 ERROR (MainThread) [homeassistant.components.rest.data] Error fetching data: http://api.open-notify.org/iss-now.json failed with 
2021-09-13 00:55:05 WARNING (MainThread) [homeassistant.components.rest.sensor] Empty reply found when expecting JSON data
2021-09-13 00:55:20 WARNING (MainThread) [homeassistant.helpers.entity] Update of sensor.iss_coordinates is taking over 10 seconds
2021-09-13 00:55:20 ERROR (MainThread) [homeassistant.components.rest.data] Error fetching data: http://api.open-notify.org/iss-now.json failed with 
2021-09-13 00:55:20 WARNING (MainThread) [homeassistant.components.rest.sensor] Empty reply found when expecting JSON data
2021-09-13 00:55:34 WARNING (MainThread) [homeassistant.helpers.entity] Update of sensor.iss_pass_times is taking over 10 seconds
2021-09-13 00:55:34 ERROR (MainThread) [homeassistant.components.rest.data] Error fetching data: http://api.open-notify.org/iss-pass.json?lat=34.3769732&lon=-118.5435177 failed with 
2021-09-13 00:55:34 WARNING (MainThread) [homeassistant.components.rest.sensor] Empty reply found when expecting JSON data
2021-09-13 00:55:34 ERROR (MainThread) [homeassistant.components.template.template_entity] TemplateError('UndefinedError: 'mappingproxy object' has no attribute 'response'') while processing template 'Template("{% if states.sensor.iss_pass_times %}{{ states.sensor.iss_pass_times.attributes["response"][0]["risetime"] | timestamp_custom("%a %d %b %Y %H:%M:%S") }}{% endif %}")' for attribute '_attr_native_value' in entity 'sensor.iss_risetime_0'
2021-09-13 00:55:34 ERROR (MainThread) [homeassistant.components.template.template_entity] TemplateError('UndefinedError: 'mappingproxy object' has no attribute 'response'') while processing template 'Template("{% if states.sensor.iss_pass_times %}{{ states.sensor.iss_pass_times.attributes["response"][0]["duration"] }}{% endif %}")' for attribute '_attr_native_value' in entity 'sensor.iss_duration_0'
2021-09-13 00:55:34 ERROR (MainThread) [homeassistant.components.template.template_entity] TemplateError('UndefinedError: 'mappingproxy object' has no attribute 'response'') while processing template 'Template("{% if states.sensor.iss_pass_times %}{{ states.sensor.iss_pass_times.attributes["response"][1]["risetime"] | timestamp_custom("%a %d %b %Y %H:%M:%S") }}{% endif %}")' for attribute '_attr_native_value' in entity 'sensor.iss_risetime_1'
2021-09-13 00:55:34 ERROR (MainThread) [homeassistant.components.template.template_entity] TemplateError('UndefinedError: 'mappingproxy object' has no attribute 'response'') while processing template 'Template("{% if states.sensor.iss_pass_times %}{{ states.sensor.iss_pass_times.attributes["response"][1]["duration"] }}{% endif %}")' for attribute '_attr_native_value' in entity 'sensor.iss_duration_1'
2021-09-13 00:55:34 ERROR (MainThread) [homeassistant.components.template.template_entity] TemplateError('UndefinedError: 'mappingproxy object' has no attribute 'response'') while processing template 'Template("{% if states.sensor.iss_pass_times %}{{ states.sensor.iss_pass_times.attributes["response"][2]["risetime"] | timestamp_custom("%a %d %b %Y %H:%M:%S") }}{% endif %}")' for attribute '_attr_native_value' in entity 'sensor.iss_risetime_2'
2021-09-13 00:55:34 ERROR (MainThread) [homeassistant.components.template.template_entity] TemplateError('UndefinedError: 'mappingproxy object' has no attribute 'response'') while processing template 'Template("{% if states.sensor.iss_pass_times %}{{ states.sensor.iss_pass_times.attributes["response"][2]["duration"] }}{% endif %}")' for attribute '_attr_native_value' in entity 'sensor.iss_duration_2'
2021-09-13 00:55:34 ERROR (MainThread) [homeassistant.components.template.template_entity] TemplateError('UndefinedError: 'mappingproxy object' has no attribute 'response'') while processing template 'Template("{% if states.sensor.iss_pass_times %}{{ states.sensor.iss_pass_times.attributes["response"][3]["risetime"] | timestamp_custom("%a %d %b %Y %H:%M:%S") }}{% endif %}")' for attribute '_attr_native_value' in entity 'sensor.iss_risetime_3'
2021-09-13 00:55:34 ERROR (MainThread) [homeassistant.components.template.template_entity] TemplateError('UndefinedError: 'mappingproxy object' has no attribute 'response'') while processing template 'Template("{% if states.sensor.iss_pass_times %}{{ states.sensor.iss_pass_times.attributes["response"][3]["duration"] }}{% endif %}")' for attribute '_attr_native_value' in entity 'sensor.iss_duration_3'
2021-09-13 00:55:34 ERROR (MainThread) [homeassistant.components.template.template_entity] TemplateError('UndefinedError: 'mappingproxy object' has no attribute 'response'') while processing template 'Template("{% if states.sensor.iss_pass_times %}{{ states.sensor.iss_pass_times.attributes["response"][4]["risetime"] | timestamp_custom("%a %d %b %Y %H:%M:%S") }}{% endif %}")' for attribute '_attr_native_value' in entity 'sensor.iss_risetime_4'
2021-09-13 00:55:34 ERROR (MainThread) [homeassistant.components.template.template_entity] TemplateError('UndefinedError: 'mappingproxy object' has no attribute 'response'') while processing template 'Template("{% if states.sensor.iss_pass_times %}{{ states.sensor.iss_pass_times.attributes["response"][4]["duration"] }}{% endif %}")' for attribute '_attr_native_value' in entity 'sensor.iss_duration_4'
2021-09-13 00:56:58 ERROR (MainThread) [homeassistant] Error doing job: Future exception was never retrieved
Traceback (most recent call last):
  File "/usr/local/lib/python3.9/concurrent/futures/thread.py", line 52, in run
    result = self.fn(*self.args, **self.kwargs)
TypeError: update() takes 1 positional argument but 2 were given
2021-09-13 01:00:14 ERROR (stream_worker) [libav.rtsp] method DESCRIBE failed: 404 Not Found
2021-09-13 01:00:14 ERROR (stream_worker) [homeassistant.components.stream.worker] Error opening stream rtsps://stream-uc2-bravo.dropcam.com:443/sdm_live_stream/CiQA2vuxr1SLu8rlYbOHo16R-04X0NNEKfeupmXLad7ICSMu8s8ScQAFjsOTS4_b71We2VG7vYgLakwq7JUxt6NJI0n_4qGM-a8nYLnRqRt-bpKX5HVk56GBFLsegX_YCrq7qGjicjVDCJLw6ikxOmGMNn5FOIzSK0Ae_WFyJ5hjvdjABw-qslkW0czaUaWbWG6Bc1HqAVEU?auth=g.0.eyJraWQiOiIyMzhiNTUxZmMyM2EyM2Y4M2E2ZTE3MmJjZTg0YmU3ZjgxMzAzMmM4IiwiYWxnIjoiUlMyNTYifQ.eyJpc3MiOiJuZXN0LXNlY3VyaXR5LWF1dGhwcm94eSIsInN1YiI6Im5lc3RfaWQ6bmVzdC1waG9lbml4LXByb2Q6MjEyMTgxNDEiLCJwb2wiOiIzcC1vYXV0aC1zY29wZS1BUElfU0RNX1NFUlZJQ0UtY2xpZW50LTIwMjQyNzMxODczNS1qNXQ5bWMyMzZqaG85YXMycWY0dTZxY3NmYW1kaGJ0ci5hcHBzLmdvb2dsZXVzZXJjb250ZW50LmNvbSIsImV4cCI6MTYzMTQ5ODQ1MH0.tPMv-EG32_XlvIZmCpKyJ12Ozu8zGClYp1WbDrqpdtTyfhR2w_a410FySS2m5ontP4dOlEIuwobL-EtLmC7L-UTsMkZcLFI3pkEY9bzONK24CGe3KJSdpE9hCkdK9L2SM9cAQ87j4pRr9OF5LP7YiLbVPpjZTsW_7ou_Y1g-yu5GA7Fnn5ehSKR-Iwq-ykUciC1-YbZfrAl55FYoBbZRRBiQL8r0leC9RcSSaG73vmI7i-2uemhDzysQlPcXt0nNJ9rzgRpE63NxmMxF4hGNUGOT7BWwoXVVsUJpLHnU-wl5S-jXhZbfS3V3cP9akUTeQF_jgmlWDC06QhKSLnHOKA
2021-09-13 01:01:59 ERROR (MainThread) [homeassistant] Error doing job: Future exception was never retrieved
Traceback (most recent call last):
  File "/usr/local/lib/python3.9/concurrent/futures/thread.py", line 52, in run
    result = self.fn(*self.args, **self.kwargs)
TypeError: update() takes 1 positional argument but 2 were given
2021-09-13 01:07:00 ERROR (MainThread) [homeassistant] Error doing job: Future exception was never retrieved
Traceback (most recent call last):
  File "/usr/local/lib/python3.9/concurrent/futures/thread.py", line 52, in run
    result = self.fn(*self.args, **self.kwargs)
TypeError: update() takes 1 positional argument but 2 were given
2021-09-13 01:11:14 ERROR (stream_worker) [libav.rtsp] method DESCRIBE failed: 404 Not Found
2021-09-13 01:11:14 ERROR (stream_worker) [homeassistant.components.stream.worker] Error opening stream rtsps://stream-uc2-bravo.dropcam.com:443/sdm_live_stream/CiQA2vuxr1SLu8rlYbOHo16R-04X0NNEKfeupmXLad7ICSMu8s8ScQAFjsOTS4_b71We2VG7vYgLakwq7JUxt6NJI0n_4qGM-a8nYLnRqRt-bpKX5HVk56GBFLsegX_YCrq7qGjicjVDCJLw6ikxOmGMNn5FOIzSK0Ae_WFyJ5hjvdjABw-qslkW0czaUaWbWG6Bc1HqAVEU?auth=g.0.eyJraWQiOiIyMzhiNTUxZmMyM2EyM2Y4M2E2ZTE3MmJjZTg0YmU3ZjgxMzAzMmM4IiwiYWxnIjoiUlMyNTYifQ.eyJpc3MiOiJuZXN0LXNlY3VyaXR5LWF1dGhwcm94eSIsInN1YiI6Im5lc3RfaWQ6bmVzdC1waG9lbml4LXByb2Q6MjEyMTgxNDEiLCJwb2wiOiIzcC1vYXV0aC1zY29wZS1BUElfU0RNX1NFUlZJQ0UtY2xpZW50LTIwMjQyNzMxODczNS1qNXQ5bWMyMzZqaG85YXMycWY0dTZxY3NmYW1kaGJ0ci5hcHBzLmdvb2dsZXVzZXJjb250ZW50LmNvbSIsImV4cCI6MTYzMTQ5ODQ1MH0.tPMv-EG32_XlvIZmCpKyJ12Ozu8zGClYp1WbDrqpdtTyfhR2w_a410FySS2m5ontP4dOlEIuwobL-EtLmC7L-UTsMkZcLFI3pkEY9bzONK24CGe3KJSdpE9hCkdK9L2SM9cAQ87j4pRr9OF5LP7YiLbVPpjZTsW_7ou_Y1g-yu5GA7Fnn5ehSKR-Iwq-ykUciC1-YbZfrAl55FYoBbZRRBiQL8r0leC9RcSSaG73vmI7i-2uemhDzysQlPcXt0nNJ9rzgRpE63NxmMxF4hGNUGOT7BWwoXVVsUJpLHnU-wl5S-jXhZbfS3V3cP9akUTeQF_jgmlWDC06QhKSLnHOKA
2021-09-13 01:12:01 ERROR (MainThread) [homeassistant] Error doing job: Future exception was never retrieved
Traceback (most recent call last):
  File "/usr/local/lib/python3.9/concurrent/futures/thread.py", line 52, in run
    result = self.fn(*self.args, **self.kwargs)
TypeError: update() takes 1 positional argument but 2 were given
2021-09-13 01:17:02 ERROR (MainThread) [homeassistant] Error doing job: Future exception was never retrieved
Traceback (most recent call last):
  File "/usr/local/lib/python3.9/concurrent/futures/thread.py", line 52, in run
    result = self.fn(*self.args, **self.kwargs)
TypeError: update() takes 1 positional argument but 2 were given
2021-09-13 01:22:03 ERROR (MainThread) [homeassistant] Error doing job: Future exception was never retrieved
Traceback (most recent call last):
  File "/usr/local/lib/python3.9/concurrent/futures/thread.py", line 52, in run
    result = self.fn(*self.args, **self.kwargs)
TypeError: update() takes 1 positional argument but 2 were given
2021-09-13 01:22:25 ERROR (stream_worker) [libav.rtsp] method DESCRIBE failed: 404 Not Found
2021-09-13 01:22:25 ERROR (stream_worker) [homeassistant.components.stream.worker] Error opening stream rtsps://stream-uc2-bravo.dropcam.com:443/sdm_live_stream/CiQA2vuxr1SLu8rlYbOHo16R-04X0NNEKfeupmXLad7ICSMu8s8ScQAFjsOTS4_b71We2VG7vYgLakwq7JUxt6NJI0n_4qGM-a8nYLnRqRt-bpKX5HVk56GBFLsegX_YCrq7qGjicjVDCJLw6ikxOmGMNn5FOIzSK0Ae_WFyJ5hjvdjABw-qslkW0czaUaWbWG6Bc1HqAVEU?auth=g.0.eyJraWQiOiIyMzhiNTUxZmMyM2EyM2Y4M2E2ZTE3MmJjZTg0YmU3ZjgxMzAzMmM4IiwiYWxnIjoiUlMyNTYifQ.eyJpc3MiOiJuZXN0LXNlY3VyaXR5LWF1dGhwcm94eSIsInN1YiI6Im5lc3RfaWQ6bmVzdC1waG9lbml4LXByb2Q6MjEyMTgxNDEiLCJwb2wiOiIzcC1vYXV0aC1zY29wZS1BUElfU0RNX1NFUlZJQ0UtY2xpZW50LTIwMjQyNzMxODczNS1qNXQ5bWMyMzZqaG85YXMycWY0dTZxY3NmYW1kaGJ0ci5hcHBzLmdvb2dsZXVzZXJjb250ZW50LmNvbSIsImV4cCI6MTYzMTQ5ODQ1MH0.tPMv-EG32_XlvIZmCpKyJ12Ozu8zGClYp1WbDrqpdtTyfhR2w_a410FySS2m5ontP4dOlEIuwobL-EtLmC7L-UTsMkZcLFI3pkEY9bzONK24CGe3KJSdpE9hCkdK9L2SM9cAQ87j4pRr9OF5LP7YiLbVPpjZTsW_7ou_Y1g-yu5GA7Fnn5ehSKR-Iwq-ykUciC1-YbZfrAl55FYoBbZRRBiQL8r0leC9RcSSaG73vmI7i-2uemhDzysQlPcXt0nNJ9rzgRpE63NxmMxF4hGNUGOT7BWwoXVVsUJpLHnU-wl5S-jXhZbfS3V3cP9akUTeQF_jgmlWDC06QhKSLnHOKA
2021-09-13 01:27:04 ERROR (MainThread) [homeassistant] Error doing job: Future exception was never retrieved
Traceback (most recent call last):
  File "/usr/local/lib/python3.9/concurrent/futures/thread.py", line 52, in run
    result = self.fn(*self.args, **self.kwargs)
TypeError: update() takes 1 positional argument but 2 were given
2021-09-13 01:32:05 ERROR (MainThread) [homeassistant] Error doing job: Future exception was never retrieved
Traceback (most recent call last):
  File "/usr/local/lib/python3.9/concurrent/futures/thread.py", line 52, in run
    result = self.fn(*self.args, **self.kwargs)
TypeError: update() takes 1 positional argument but 2 were given
2021-09-13 01:33:45 ERROR (stream_worker) [libav.rtsp] method DESCRIBE failed: 404 Not Found
2021-09-13 01:33:45 ERROR (stream_worker) [homeassistant.components.stream.worker] Error opening stream rtsps://stream-uc2-bravo.dropcam.com:443/sdm_live_stream/CiQA2vuxr1SLu8rlYbOHo16R-04X0NNEKfeupmXLad7ICSMu8s8ScQAFjsOTS4_b71We2VG7vYgLakwq7JUxt6NJI0n_4qGM-a8nYLnRqRt-bpKX5HVk56GBFLsegX_YCrq7qGjicjVDCJLw6ikxOmGMNn5FOIzSK0Ae_WFyJ5hjvdjABw-qslkW0czaUaWbWG6Bc1HqAVEU?auth=g.0.eyJraWQiOiIyMzhiNTUxZmMyM2EyM2Y4M2E2ZTE3MmJjZTg0YmU3ZjgxMzAzMmM4IiwiYWxnIjoiUlMyNTYifQ.eyJpc3MiOiJuZXN0LXNlY3VyaXR5LWF1dGhwcm94eSIsInN1YiI6Im5lc3RfaWQ6bmVzdC1waG9lbml4LXByb2Q6MjEyMTgxNDEiLCJwb2wiOiIzcC1vYXV0aC1zY29wZS1BUElfU0RNX1NFUlZJQ0UtY2xpZW50LTIwMjQyNzMxODczNS1qNXQ5bWMyMzZqaG85YXMycWY0dTZxY3NmYW1kaGJ0ci5hcHBzLmdvb2dsZXVzZXJjb250ZW50LmNvbSIsImV4cCI6MTYzMTQ5ODQ1MH0.tPMv-EG32_XlvIZmCpKyJ12Ozu8zGClYp1WbDrqpdtTyfhR2w_a410FySS2m5ontP4dOlEIuwobL-EtLmC7L-UTsMkZcLFI3pkEY9bzONK24CGe3KJSdpE9hCkdK9L2SM9cAQ87j4pRr9OF5LP7YiLbVPpjZTsW_7ou_Y1g-yu5GA7Fnn5ehSKR-Iwq-ykUciC1-YbZfrAl55FYoBbZRRBiQL8r0leC9RcSSaG73vmI7i-2uemhDzysQlPcXt0nNJ9rzgRpE63NxmMxF4hGNUGOT7BWwoXVVsUJpLHnU-wl5S-jXhZbfS3V3cP9akUTeQF_jgmlWDC06QhKSLnHOKA
2021-09-13 01:37:06 ERROR (MainThread) [homeassistant] Error doing job: Future exception was never retrieved
Traceback (most recent call last):
  File "/usr/local/lib/python3.9/concurrent/futures/thread.py", line 52, in run
    result = self.fn(*self.args, **self.kwargs)
TypeError: update() takes 1 positional argument but 2 were given
2021-09-13 01:42:07 ERROR (MainThread) [homeassistant] Error doing job: Future exception was never retrieved
Traceback (most recent call last):
  File "/usr/local/lib/python3.9/concurrent/futures/thread.py", line 52, in run
    result = self.fn(*self.args, **self.kwargs)
TypeError: update() takes 1 positional argument but 2 were given
2021-09-13 01:45:16 ERROR (stream_worker) [libav.rtsp] method DESCRIBE failed: 404 Not Found
2021-09-13 01:45:16 ERROR (stream_worker) [homeassistant.components.stream.worker] Error opening stream rtsps://stream-uc2-bravo.dropcam.com:443/sdm_live_stream/CiQA2vuxr1SLu8rlYbOHo16R-04X0NNEKfeupmXLad7ICSMu8s8ScQAFjsOTS4_b71We2VG7vYgLakwq7JUxt6NJI0n_4qGM-a8nYLnRqRt-bpKX5HVk56GBFLsegX_YCrq7qGjicjVDCJLw6ikxOmGMNn5FOIzSK0Ae_WFyJ5hjvdjABw-qslkW0czaUaWbWG6Bc1HqAVEU?auth=g.0.eyJraWQiOiIyMzhiNTUxZmMyM2EyM2Y4M2E2ZTE3MmJjZTg0YmU3ZjgxMzAzMmM4IiwiYWxnIjoiUlMyNTYifQ.eyJpc3MiOiJuZXN0LXNlY3VyaXR5LWF1dGhwcm94eSIsInN1YiI6Im5lc3RfaWQ6bmVzdC1waG9lbml4LXByb2Q6MjEyMTgxNDEiLCJwb2wiOiIzcC1vYXV0aC1zY29wZS1BUElfU0RNX1NFUlZJQ0UtY2xpZW50LTIwMjQyNzMxODczNS1qNXQ5bWMyMzZqaG85YXMycWY0dTZxY3NmYW1kaGJ0ci5hcHBzLmdvb2dsZXVzZXJjb250ZW50LmNvbSIsImV4cCI6MTYzMTQ5ODQ1MH0.tPMv-EG32_XlvIZmCpKyJ12Ozu8zGClYp1WbDrqpdtTyfhR2w_a410FySS2m5ontP4dOlEIuwobL-EtLmC7L-UTsMkZcLFI3pkEY9bzONK24CGe3KJSdpE9hCkdK9L2SM9cAQ87j4pRr9OF5LP7YiLbVPpjZTsW_7ou_Y1g-yu5GA7Fnn5ehSKR-Iwq-ykUciC1-YbZfrAl55FYoBbZRRBiQL8r0leC9RcSSaG73vmI7i-2uemhDzysQlPcXt0nNJ9rzgRpE63NxmMxF4hGNUGOT7BWwoXVVsUJpLHnU-wl5S-jXhZbfS3V3cP9akUTeQF_jgmlWDC06QhKSLnHOKA
2021-09-13 01:47:08 ERROR (MainThread) [homeassistant] Error doing job: Future exception was never retrieved
Traceback (most recent call last):
  File "/usr/local/lib/python3.9/concurrent/futures/thread.py", line 52, in run
    result = self.fn(*self.args, **self.kwargs)
TypeError: update() takes 1 positional argument but 2 were given
2021-09-13 01:51:07 ERROR (MainThread) [iotawattpy.connection] Err: 
2021-09-13 01:51:07 ERROR (MainThread) [homeassistant.components.iotawatt.coordinator] Unexpected error fetching 192.168.20.195 data: 'NoneType' object has no attribute 'text'
Traceback (most recent call last):
  File "/usr/src/homeassistant/homeassistant/helpers/update_coordinator.py", line 187, in _async_refresh
    self.data = await self._async_update_data()
  File "/usr/src/homeassistant/homeassistant/components/iotawatt/coordinator.py", line 55, in _async_update_data
    await self.api.update()
  File "/usr/local/lib/python3.9/site-packages/iotawattpy/iotawatt.py", line 66, in update
    await self._refreshSensors(timespan)
  File "/usr/local/lib/python3.9/site-packages/iotawattpy/iotawatt.py", line 100, in _refreshSensors
    results = response.text
AttributeError: 'NoneType' object has no attribute 'text'
2021-09-13 01:52:09 ERROR (MainThread) [homeassistant] Error doing job: Future exception was never retrieved
Traceback (most recent call last):
  File "/usr/local/lib/python3.9/concurrent/futures/thread.py", line 52, in run
    result = self.fn(*self.args, **self.kwargs)
TypeError: update() takes 1 positional argument but 2 were given
2021-09-13 01:56:56 ERROR (stream_worker) [libav.rtsp] method DESCRIBE failed: 404 Not Found
2021-09-13 01:56:56 ERROR (stream_worker) [homeassistant.components.stream.worker] Error opening stream rtsps://stream-uc2-bravo.dropcam.com:443/sdm_live_stream/CiQA2vuxr1SLu8rlYbOHo16R-04X0NNEKfeupmXLad7ICSMu8s8ScQAFjsOTS4_b71We2VG7vYgLakwq7JUxt6NJI0n_4qGM-a8nYLnRqRt-bpKX5HVk56GBFLsegX_YCrq7qGjicjVDCJLw6ikxOmGMNn5FOIzSK0Ae_WFyJ5hjvdjABw-qslkW0czaUaWbWG6Bc1HqAVEU?auth=g.0.eyJraWQiOiIyMzhiNTUxZmMyM2EyM2Y4M2E2ZTE3MmJjZTg0YmU3ZjgxMzAzMmM4IiwiYWxnIjoiUlMyNTYifQ.eyJpc3MiOiJuZXN0LXNlY3VyaXR5LWF1dGhwcm94eSIsInN1YiI6Im5lc3RfaWQ6bmVzdC1waG9lbml4LXByb2Q6MjEyMTgxNDEiLCJwb2wiOiIzcC1vYXV0aC1zY29wZS1BUElfU0RNX1NFUlZJQ0UtY2xpZW50LTIwMjQyNzMxODczNS1qNXQ5bWMyMzZqaG85YXMycWY0dTZxY3NmYW1kaGJ0ci5hcHBzLmdvb2dsZXVzZXJjb250ZW50LmNvbSIsImV4cCI6MTYzMTQ5ODQ1MH0.tPMv-EG32_XlvIZmCpKyJ12Ozu8zGClYp1WbDrqpdtTyfhR2w_a410FySS2m5ontP4dOlEIuwobL-EtLmC7L-UTsMkZcLFI3pkEY9bzONK24CGe3KJSdpE9hCkdK9L2SM9cAQ87j4pRr9OF5LP7YiLbVPpjZTsW_7ou_Y1g-yu5GA7Fnn5ehSKR-Iwq-ykUciC1-YbZfrAl55FYoBbZRRBiQL8r0leC9RcSSaG73vmI7i-2uemhDzysQlPcXt0nNJ9rzgRpE63NxmMxF4hGNUGOT7BWwoXVVsUJpLHnU-wl5S-jXhZbfS3V3cP9akUTeQF_jgmlWDC06QhKSLnHOKA
2021-09-13 01:57:10 ERROR (MainThread) [homeassistant] Error doing job: Future exception was never retrieved
Traceback (most recent call last):
  File "/usr/local/lib/python3.9/concurrent/futures/thread.py", line 52, in run
    result = self.fn(*self.args, **self.kwargs)
TypeError: update() takes 1 positional argument but 2 were given
2021-09-13 02:02:11 ERROR (MainThread) [homeassistant] Error doing job: Future exception was never retrieved
Traceback (most recent call last):
  File "/usr/local/lib/python3.9/concurrent/futures/thread.py", line 52, in run
    result = self.fn(*self.args, **self.kwargs)
TypeError: update() takes 1 positional argument but 2 were given
2021-09-13 02:02:13 ERROR (MainThread) [homeassistant.components.nws] Error requesting NWS observation station SAUC1 data: 504, message='Gateway Time-out', url=URL('https://api.weather.gov/stations/SAUC1/observations')
2021-09-13 02:07:12 ERROR (MainThread) [homeassistant] Error doing job: Future exception was never retrieved
Traceback (most recent call last):
  File "/usr/local/lib/python3.9/concurrent/futures/thread.py", line 52, in run
    result = self.fn(*self.args, **self.kwargs)
TypeError: update() takes 1 positional argument but 2 were given
2021-09-13 02:08:46 ERROR (stream_worker) [libav.rtsp] method DESCRIBE failed: 404 Not Found
2021-09-13 02:08:46 ERROR (stream_worker) [homeassistant.components.stream.worker] Error opening stream rtsps://stream-uc2-bravo.dropcam.com:443/sdm_live_stream/CiQA2vuxr1SLu8rlYbOHo16R-04X0NNEKfeupmXLad7ICSMu8s8ScQAFjsOTS4_b71We2VG7vYgLakwq7JUxt6NJI0n_4qGM-a8nYLnRqRt-bpKX5HVk56GBFLsegX_YCrq7qGjicjVDCJLw6ikxOmGMNn5FOIzSK0Ae_WFyJ5hjvdjABw-qslkW0czaUaWbWG6Bc1HqAVEU?auth=g.0.eyJraWQiOiIyMzhiNTUxZmMyM2EyM2Y4M2E2ZTE3MmJjZTg0YmU3ZjgxMzAzMmM4IiwiYWxnIjoiUlMyNTYifQ.eyJpc3MiOiJuZXN0LXNlY3VyaXR5LWF1dGhwcm94eSIsInN1YiI6Im5lc3RfaWQ6bmVzdC1waG9lbml4LXByb2Q6MjEyMTgxNDEiLCJwb2wiOiIzcC1vYXV0aC1zY29wZS1BUElfU0RNX1NFUlZJQ0UtY2xpZW50LTIwMjQyNzMxODczNS1qNXQ5bWMyMzZqaG85YXMycWY0dTZxY3NmYW1kaGJ0ci5hcHBzLmdvb2dsZXVzZXJjb250ZW50LmNvbSIsImV4cCI6MTYzMTQ5ODQ1MH0.tPMv-EG32_XlvIZmCpKyJ12Ozu8zGClYp1WbDrqpdtTyfhR2w_a410FySS2m5ontP4dOlEIuwobL-EtLmC7L-UTsMkZcLFI3pkEY9bzONK24CGe3KJSdpE9hCkdK9L2SM9cAQ87j4pRr9OF5LP7YiLbVPpjZTsW_7ou_Y1g-yu5GA7Fnn5ehSKR-Iwq-ykUciC1-YbZfrAl55FYoBbZRRBiQL8r0leC9RcSSaG73vmI7i-2uemhDzysQlPcXt0nNJ9rzgRpE63NxmMxF4hGNUGOT7BWwoXVVsUJpLHnU-wl5S-jXhZbfS3V3cP9akUTeQF_jgmlWDC06QhKSLnHOKA
2021-09-13 02:09:50 WARNING (MainThread) [bellows.zigbee.application] Watchdog heartbeat timeout: 
2021-09-13 02:10:05 WARNING (MainThread) [bellows.zigbee.application] Watchdog heartbeat timeout: 
2021-09-13 02:12:13 ERROR (MainThread) [homeassistant] Error doing job: Future exception was never retrieved
Traceback (most recent call last):
  File "/usr/local/lib/python3.9/concurrent/futures/thread.py", line 52, in run
    result = self.fn(*self.args, **self.kwargs)
TypeError: update() takes 1 positional argument but 2 were given
2021-09-13 02:12:20 WARNING (Thread-16) [pychromecast.socket_client] [Aidan Google Home(192.168.6.244):8009] Heartbeat timeout, resetting connection
2021-09-13 02:15:49 ERROR (MainThread) [iotawattpy.connection] Err: 
2021-09-13 02:15:49 ERROR (MainThread) [homeassistant.components.iotawatt.coordinator] Unexpected error fetching 192.168.20.195 data: 'NoneType' object has no attribute 'text'
Traceback (most recent call last):
  File "/usr/src/homeassistant/homeassistant/helpers/update_coordinator.py", line 187, in _async_refresh
    self.data = await self._async_update_data()
  File "/usr/src/homeassistant/homeassistant/components/iotawatt/coordinator.py", line 55, in _async_update_data
    await self.api.update()
  File "/usr/local/lib/python3.9/site-packages/iotawattpy/iotawatt.py", line 66, in update
    await self._refreshSensors(timespan)
  File "/usr/local/lib/python3.9/site-packages/iotawattpy/iotawatt.py", line 100, in _refreshSensors
    results = response.text
AttributeError: 'NoneType' object has no attribute 'text'
2021-09-13 02:17:14 ERROR (MainThread) [homeassistant] Error doing job: Future exception was never retrieved
Traceback (most recent call last):
  File "/usr/local/lib/python3.9/concurrent/futures/thread.py", line 52, in run
    result = self.fn(*self.args, **self.kwargs)
TypeError: update() takes 1 positional argument but 2 were given
2021-09-13 02:20:47 ERROR (stream_worker) [libav.rtsp] method DESCRIBE failed: 404 Not Found
2021-09-13 02:20:47 ERROR (stream_worker) [homeassistant.components.stream.worker] Error opening stream rtsps://stream-uc2-bravo.dropcam.com:443/sdm_live_stream/CiQA2vuxr1SLu8rlYbOHo16R-04X0NNEKfeupmXLad7ICSMu8s8ScQAFjsOTS4_b71We2VG7vYgLakwq7JUxt6NJI0n_4qGM-a8nYLnRqRt-bpKX5HVk56GBFLsegX_YCrq7qGjicjVDCJLw6ikxOmGMNn5FOIzSK0Ae_WFyJ5hjvdjABw-qslkW0czaUaWbWG6Bc1HqAVEU?auth=g.0.eyJraWQiOiIyMzhiNTUxZmMyM2EyM2Y4M2E2ZTE3MmJjZTg0YmU3ZjgxMzAzMmM4IiwiYWxnIjoiUlMyNTYifQ.eyJpc3MiOiJuZXN0LXNlY3VyaXR5LWF1dGhwcm94eSIsInN1YiI6Im5lc3RfaWQ6bmVzdC1waG9lbml4LXByb2Q6MjEyMTgxNDEiLCJwb2wiOiIzcC1vYXV0aC1zY29wZS1BUElfU0RNX1NFUlZJQ0UtY2xpZW50LTIwMjQyNzMxODczNS1qNXQ5bWMyMzZqaG85YXMycWY0dTZxY3NmYW1kaGJ0ci5hcHBzLmdvb2dsZXVzZXJjb250ZW50LmNvbSIsImV4cCI6MTYzMTQ5ODQ1MH0.tPMv-EG32_XlvIZmCpKyJ12Ozu8zGClYp1WbDrqpdtTyfhR2w_a410FySS2m5ontP4dOlEIuwobL-EtLmC7L-UTsMkZcLFI3pkEY9bzONK24CGe3KJSdpE9hCkdK9L2SM9cAQ87j4pRr9OF5LP7YiLbVPpjZTsW_7ou_Y1g-yu5GA7Fnn5ehSKR-Iwq-ykUciC1-YbZfrAl55FYoBbZRRBiQL8r0leC9RcSSaG73vmI7i-2uemhDzysQlPcXt0nNJ9rzgRpE63NxmMxF4hGNUGOT7BWwoXVVsUJpLHnU-wl5S-jXhZbfS3V3cP9akUTeQF_jgmlWDC06QhKSLnHOKA
2021-09-13 02:22:15 ERROR (MainThread) [homeassistant] Error doing job: Future exception was never retrieved
Traceback (most recent call last):
  File "/usr/local/lib/python3.9/concurrent/futures/thread.py", line 52, in run
    result = self.fn(*self.args, **self.kwargs)
TypeError: update() takes 1 positional argument but 2 were given
2021-09-13 02:27:16 ERROR (MainThread) [homeassistant] Error doing job: Future exception was never retrieved
Traceback (most recent call last):
  File "/usr/local/lib/python3.9/concurrent/futures/thread.py", line 52, in run
    result = self.fn(*self.args, **self.kwargs)
TypeError: update() takes 1 positional argument but 2 were given
2021-09-13 02:32:17 ERROR (MainThread) [homeassistant] Error doing job: Future exception was never retrieved
Traceback (most recent call last):
  File "/usr/local/lib/python3.9/concurrent/futures/thread.py", line 52, in run
    result = self.fn(*self.args, **self.kwargs)
TypeError: update() takes 1 positional argument but 2 were given
2021-09-13 02:32:57 ERROR (stream_worker) [libav.rtsp] method DESCRIBE failed: 404 Not Found
2021-09-13 02:32:57 ERROR (stream_worker) [homeassistant.components.stream.worker] Error opening stream rtsps://stream-uc2-bravo.dropcam.com:443/sdm_live_stream/CiQA2vuxr1SLu8rlYbOHo16R-04X0NNEKfeupmXLad7ICSMu8s8ScQAFjsOTS4_b71We2VG7vYgLakwq7JUxt6NJI0n_4qGM-a8nYLnRqRt-bpKX5HVk56GBFLsegX_YCrq7qGjicjVDCJLw6ikxOmGMNn5FOIzSK0Ae_WFyJ5hjvdjABw-qslkW0czaUaWbWG6Bc1HqAVEU?auth=g.0.eyJraWQiOiIyMzhiNTUxZmMyM2EyM2Y4M2E2ZTE3MmJjZTg0YmU3ZjgxMzAzMmM4IiwiYWxnIjoiUlMyNTYifQ.eyJpc3MiOiJuZXN0LXNlY3VyaXR5LWF1dGhwcm94eSIsInN1YiI6Im5lc3RfaWQ6bmVzdC1waG9lbml4LXByb2Q6MjEyMTgxNDEiLCJwb2wiOiIzcC1vYXV0aC1zY29wZS1BUElfU0RNX1NFUlZJQ0UtY2xpZW50LTIwMjQyNzMxODczNS1qNXQ5bWMyMzZqaG85YXMycWY0dTZxY3NmYW1kaGJ0ci5hcHBzLmdvb2dsZXVzZXJjb250ZW50LmNvbSIsImV4cCI6MTYzMTQ5ODQ1MH0.tPMv-EG32_XlvIZmCpKyJ12Ozu8zGClYp1WbDrqpdtTyfhR2w_a410FySS2m5ontP4dOlEIuwobL-EtLmC7L-UTsMkZcLFI3pkEY9bzONK24CGe3KJSdpE9hCkdK9L2SM9cAQ87j4pRr9OF5LP7YiLbVPpjZTsW_7ou_Y1g-yu5GA7Fnn5ehSKR-Iwq-ykUciC1-YbZfrAl55FYoBbZRRBiQL8r0leC9RcSSaG73vmI7i-2uemhDzysQlPcXt0nNJ9rzgRpE63NxmMxF4hGNUGOT7BWwoXVVsUJpLHnU-wl5S-jXhZbfS3V3cP9akUTeQF_jgmlWDC06QhKSLnHOKA
2021-09-13 02:37:18 ERROR (MainThread) [homeassistant] Error doing job: Future exception was never retrieved
Traceback (most recent call last):
  File "/usr/local/lib/python3.9/concurrent/futures/thread.py", line 52, in run
    result = self.fn(*self.args, **self.kwargs)
TypeError: update() takes 1 positional argument but 2 were given
2021-09-13 02:40:55 ERROR (MainThread) [iotawattpy.connection] Err: 
2021-09-13 02:40:55 ERROR (MainThread) [homeassistant.components.iotawatt.coordinator] Unexpected error fetching 192.168.20.195 data: 'NoneType' object has no attribute 'text'
Traceback (most recent call last):
  File "/usr/src/homeassistant/homeassistant/helpers/update_coordinator.py", line 187, in _async_refresh
    self.data = await self._async_update_data()
  File "/usr/src/homeassistant/homeassistant/components/iotawatt/coordinator.py", line 55, in _async_update_data
    await self.api.update()
  File "/usr/local/lib/python3.9/site-packages/iotawattpy/iotawatt.py", line 66, in update
    await self._refreshSensors(timespan)
  File "/usr/local/lib/python3.9/site-packages/iotawattpy/iotawatt.py", line 100, in _refreshSensors
    results = response.text
AttributeError: 'NoneType' object has no attribute 'text'
2021-09-13 02:41:40 WARNING (MainThread) [bellows.zigbee.application] Watchdog heartbeat timeout: 
2021-09-13 02:41:55 WARNING (MainThread) [bellows.zigbee.application] Watchdog heartbeat timeout: 
2021-09-13 02:42:19 ERROR (MainThread) [homeassistant] Error doing job: Future exception was never retrieved
Traceback (most recent call last):
  File "/usr/local/lib/python3.9/concurrent/futures/thread.py", line 52, in run
    result = self.fn(*self.args, **self.kwargs)
TypeError: update() takes 1 positional argument but 2 were given
2021-09-13 02:45:18 ERROR (stream_worker) [libav.rtsp] method DESCRIBE failed: 404 Not Found
2021-09-13 02:45:18 ERROR (stream_worker) [homeassistant.components.stream.worker] Error opening stream rtsps://stream-uc2-bravo.dropcam.com:443/sdm_live_stream/CiQA2vuxr1SLu8rlYbOHo16R-04X0NNEKfeupmXLad7ICSMu8s8ScQAFjsOTS4_b71We2VG7vYgLakwq7JUxt6NJI0n_4qGM-a8nYLnRqRt-bpKX5HVk56GBFLsegX_YCrq7qGjicjVDCJLw6ikxOmGMNn5FOIzSK0Ae_WFyJ5hjvdjABw-qslkW0czaUaWbWG6Bc1HqAVEU?auth=g.0.eyJraWQiOiIyMzhiNTUxZmMyM2EyM2Y4M2E2ZTE3MmJjZTg0YmU3ZjgxMzAzMmM4IiwiYWxnIjoiUlMyNTYifQ.eyJpc3MiOiJuZXN0LXNlY3VyaXR5LWF1dGhwcm94eSIsInN1YiI6Im5lc3RfaWQ6bmVzdC1waG9lbml4LXByb2Q6MjEyMTgxNDEiLCJwb2wiOiIzcC1vYXV0aC1zY29wZS1BUElfU0RNX1NFUlZJQ0UtY2xpZW50LTIwMjQyNzMxODczNS1qNXQ5bWMyMzZqaG85YXMycWY0dTZxY3NmYW1kaGJ0ci5hcHBzLmdvb2dsZXVzZXJjb250ZW50LmNvbSIsImV4cCI6MTYzMTQ5ODQ1MH0.tPMv-EG32_XlvIZmCpKyJ12Ozu8zGClYp1WbDrqpdtTyfhR2w_a410FySS2m5ontP4dOlEIuwobL-EtLmC7L-UTsMkZcLFI3pkEY9bzONK24CGe3KJSdpE9hCkdK9L2SM9cAQ87j4pRr9OF5LP7YiLbVPpjZTsW_7ou_Y1g-yu5GA7Fnn5ehSKR-Iwq-ykUciC1-YbZfrAl55FYoBbZRRBiQL8r0leC9RcSSaG73vmI7i-2uemhDzysQlPcXt0nNJ9rzgRpE63NxmMxF4hGNUGOT7BWwoXVVsUJpLHnU-wl5S-jXhZbfS3V3cP9akUTeQF_jgmlWDC06QhKSLnHOKA
2021-09-13 02:47:20 ERROR (MainThread) [homeassistant] Error doing job: Future exception was never retrieved
Traceback (most recent call last):
  File "/usr/local/lib/python3.9/concurrent/futures/thread.py", line 52, in run
    result = self.fn(*self.args, **self.kwargs)
TypeError: update() takes 1 positional argument but 2 were given
2021-09-13 02:48:19 WARNING (Thread-14) [pychromecast.socket_client] [Kitchen speaker(192.168.20.124):8009] Heartbeat timeout, resetting connection
2021-09-13 02:48:25 ERROR (Thread-14) [pychromecast.socket_client] [Kitchen speaker(192.168.20.124):8009] Failed to connect to service ServiceInfo(type='host', data=('192.168.20.124', 8009)), retrying in 5.0s
2021-09-13 02:52:21 ERROR (MainThread) [homeassistant] Error doing job: Future exception was never retrieved
Traceback (most recent call last):
  File "/usr/local/lib/python3.9/concurrent/futures/thread.py", line 52, in run
    result = self.fn(*self.args, **self.kwargs)
TypeError: update() takes 1 positional argument but 2 were given
2021-09-13 02:57:22 ERROR (MainThread) [homeassistant] Error doing job: Future exception was never retrieved
Traceback (most recent call last):
  File "/usr/local/lib/python3.9/concurrent/futures/thread.py", line 52, in run
    result = self.fn(*self.args, **self.kwargs)
TypeError: update() takes 1 positional argument but 2 were given
2021-09-13 02:57:48 ERROR (stream_worker) [libav.rtsp] method DESCRIBE failed: 404 Not Found
2021-09-13 02:57:48 ERROR (stream_worker) [homeassistant.components.stream.worker] Error opening stream rtsps://stream-uc2-bravo.dropcam.com:443/sdm_live_stream/CiQA2vuxr1SLu8rlYbOHo16R-04X0NNEKfeupmXLad7ICSMu8s8ScQAFjsOTS4_b71We2VG7vYgLakwq7JUxt6NJI0n_4qGM-a8nYLnRqRt-bpKX5HVk56GBFLsegX_YCrq7qGjicjVDCJLw6ikxOmGMNn5FOIzSK0Ae_WFyJ5hjvdjABw-qslkW0czaUaWbWG6Bc1HqAVEU?auth=g.0.eyJraWQiOiIyMzhiNTUxZmMyM2EyM2Y4M2E2ZTE3MmJjZTg0YmU3ZjgxMzAzMmM4IiwiYWxnIjoiUlMyNTYifQ.eyJpc3MiOiJuZXN0LXNlY3VyaXR5LWF1dGhwcm94eSIsInN1YiI6Im5lc3RfaWQ6bmVzdC1waG9lbml4LXByb2Q6MjEyMTgxNDEiLCJwb2wiOiIzcC1vYXV0aC1zY29wZS1BUElfU0RNX1NFUlZJQ0UtY2xpZW50LTIwMjQyNzMxODczNS1qNXQ5bWMyMzZqaG85YXMycWY0dTZxY3NmYW1kaGJ0ci5hcHBzLmdvb2dsZXVzZXJjb250ZW50LmNvbSIsImV4cCI6MTYzMTQ5ODQ1MH0.tPMv-EG32_XlvIZmCpKyJ12Ozu8zGClYp1WbDrqpdtTyfhR2w_a410FySS2m5ontP4dOlEIuwobL-EtLmC7L-UTsMkZcLFI3pkEY9bzONK24CGe3KJSdpE9hCkdK9L2SM9cAQ87j4pRr9OF5LP7YiLbVPpjZTsW_7ou_Y1g-yu5GA7Fnn5ehSKR-Iwq-ykUciC1-YbZfrAl55FYoBbZRRBiQL8r0leC9RcSSaG73vmI7i-2uemhDzysQlPcXt0nNJ9rzgRpE63NxmMxF4hGNUGOT7BWwoXVVsUJpLHnU-wl5S-jXhZbfS3V3cP9akUTeQF_jgmlWDC06QhKSLnHOKA
2021-09-13 03:00:47 WARNING (Thread-18) [pychromecast.socket_client] [Office_Brian speaker(192.168.20.247):8009] Heartbeat timeout, resetting connection
2021-09-13 03:00:54 ERROR (Thread-18) [pychromecast.socket_client] [Office_Brian speaker(192.168.20.247):8009] Failed to connect to service ServiceInfo(type='host', data=('192.168.20.247', 8009)), retrying in 5.0s
2021-09-13 03:01:05 ERROR (Thread-18) [pychromecast.socket_client] [Office_Brian speaker(192.168.20.247):8009] Failed to connect: [Errno 104] Connection reset by peer. aborting due to stop signal.
