2021-09-10 03:17:43 WARNING (SyncWorker_0) [homeassistant.loader] We found a custom integration sun2 which has not been tested by Home Assistant. This component might cause stability problems, be sure to disable it if you experience issues with Home Assistant
2021-09-10 03:17:52 WARNING (Recorder) [homeassistant.components.recorder.util] The system could not validate that the sqlite3 database at //config/home-assistant_v2.db was shutdown cleanly
2021-09-10 03:17:59 ERROR (MainThread) [snitun.client.client_peer] Challenge/Response error with SniTun server
2021-09-10 03:17:59 ERROR (MainThread) [hass_nabucasa.remote] Connection problem to snitun server
2021-09-10 03:18:01 WARNING (MainThread) [homeassistant.components.sensor] Entity sensor.cpu_temp (<class 'homeassistant.components.command_line.sensor.CommandSensor'>) with device_class None reports a temperature in °C which will be converted to °F. Temperature conversion for entities without correct device_class is deprecated and will be removed from Home Assistant Core 2022.3. Please update your configuration if device_class is manually configured, otherwise create a bug report at https://github.com/home-assistant/core/issues?q=is%3Aopen+is%3Aissue+label%3A%22integration%3A+command_line%22
2021-09-10 03:18:02 WARNING (MainThread) [homeassistant.config_entries] Config entry 'Roku Smart Soundbar' for roku integration not ready yet: Invalid response from API: Error occurred while communicating with device; Retrying in background
2021-09-10 03:18:07 WARNING (MainThread) [homeassistant.config_entries] Config entry '192.168.7.195' for wled integration not ready yet: Invalid response from API: Error occurred while communicating with WLED device at 192.168.7.195; Retrying in background
2021-09-10 03:18:55 WARNING (MainThread) [homeassistant.components.sensor] Entity sensor.garagesidedoorsensor_bme280_dewpoint (<class 'homeassistant.components.tasmota.sensor.TasmotaSensor'>) with device_class None reports a temperature in °C which will be converted to °F. Temperature conversion for entities without correct device_class is deprecated and will be removed from Home Assistant Core 2022.3. Please update your configuration if device_class is manually configured, otherwise create a bug report at https://github.com/home-assistant/core/issues?q=is%3Aopen+is%3Aissue+label%3A%22integration%3A+tasmota%22
2021-09-10 03:18:56 WARNING (MainThread) [homeassistant.components.sensor] Entity sensor.attictemp1_bme280_dewpoint (<class 'homeassistant.components.tasmota.sensor.TasmotaSensor'>) with device_class None reports a temperature in °C which will be converted to °F. Temperature conversion for entities without correct device_class is deprecated and will be removed from Home Assistant Core 2022.3. Please update your configuration if device_class is manually configured, otherwise create a bug report at https://github.com/home-assistant/core/issues?q=is%3Aopen+is%3Aissue+label%3A%22integration%3A+tasmota%22
2021-09-10 03:18:57 WARNING (MainThread) [homeassistant.components.template.template_entity] Template loop detected while processing event: <Event state_changed[L]: entity_id=sensor.sensor_count, old_state=<state sensor.sensor_count=315; friendly_name=Number of Sensors @ 2021-09-10T03:18:55.044189-07:00>, new_state=<state sensor.sensor_count=339; friendly_name=Number of Sensors @ 2021-09-10T03:18:56.046438-07:00>>, skipping template render for Template[{{ states.sensor | rejectattr('state', 'eq', 'unavailable') | list | count }}]
2021-09-10 03:20:58 WARNING (MainThread) [homeassistant.components.template.template_entity] Template loop detected while processing event: <Event state_changed[L]: entity_id=sensor.sensor_count, old_state=<state sensor.sensor_count=354; friendly_name=Number of Sensors @ 2021-09-10T03:20:56.139654-07:00>, new_state=<state sensor.sensor_count=362; friendly_name=Number of Sensors @ 2021-09-10T03:20:57.142435-07:00>>, skipping template render for Template[{{ states.sensor | rejectattr('state', 'eq', 'unavailable') | list | count }}]
2021-09-10 03:22:56 ERROR (MainThread) [homeassistant] Error doing job: Future exception was never retrieved
Traceback (most recent call last):
  File "/usr/local/lib/python3.9/concurrent/futures/thread.py", line 52, in run
    result = self.fn(*self.args, **self.kwargs)
TypeError: update() takes 1 positional argument but 2 were given
2021-09-10 03:27:57 ERROR (MainThread) [homeassistant] Error doing job: Future exception was never retrieved
Traceback (most recent call last):
  File "/usr/local/lib/python3.9/concurrent/futures/thread.py", line 52, in run
    result = self.fn(*self.args, **self.kwargs)
TypeError: update() takes 1 positional argument but 2 were given
2021-09-10 03:29:08 WARNING (MainThread) [homeassistant.helpers.service] Unable to find referenced entities light.hue_lightstrip_2
2021-09-10 03:31:32 WARNING (MainThread) [bellows.zigbee.application] Watchdog heartbeat timeout: 
2021-09-10 03:32:58 ERROR (MainThread) [homeassistant] Error doing job: Future exception was never retrieved
Traceback (most recent call last):
  File "/usr/local/lib/python3.9/concurrent/futures/thread.py", line 52, in run
    result = self.fn(*self.args, **self.kwargs)
TypeError: update() takes 1 positional argument but 2 were given
2021-09-10 03:34:39 ERROR (MainThread) [iotawattpy.connection] Err: 
2021-09-10 03:34:39 ERROR (MainThread) [homeassistant.components.iotawatt.coordinator] Unexpected error fetching 192.168.20.195 data: 'NoneType' object has no attribute 'text'
Traceback (most recent call last):
  File "/usr/src/homeassistant/homeassistant/helpers/update_coordinator.py", line 187, in _async_refresh
    self.data = await self._async_update_data()
  File "/usr/src/homeassistant/homeassistant/components/iotawatt/coordinator.py", line 55, in _async_update_data
    await self.api.update()
  File "/usr/local/lib/python3.9/site-packages/iotawattpy/iotawatt.py", line 66, in update
    await self._refreshSensors(timespan)
  File "/usr/local/lib/python3.9/site-packages/iotawattpy/iotawatt.py", line 100, in _refreshSensors
    results = response.text
AttributeError: 'NoneType' object has no attribute 'text'
2021-09-10 03:35:44 WARNING (Thread-8) [pychromecast.socket_client] [Bedroom_Master speaker(192.168.20.77):8009] Heartbeat timeout, resetting connection
2021-09-10 03:35:49 ERROR (Thread-8) [pychromecast.socket_client] [Bedroom_Master speaker(192.168.20.77):8009] Failed to connect to service ServiceInfo(type='host', data=('192.168.20.77', 8009)), retrying in 5.0s
2021-09-10 03:38:00 ERROR (MainThread) [homeassistant] Error doing job: Future exception was never retrieved
Traceback (most recent call last):
  File "/usr/local/lib/python3.9/concurrent/futures/thread.py", line 52, in run
    result = self.fn(*self.args, **self.kwargs)
TypeError: update() takes 1 positional argument but 2 were given
2021-09-10 03:43:01 ERROR (MainThread) [homeassistant] Error doing job: Future exception was never retrieved
Traceback (most recent call last):
  File "/usr/local/lib/python3.9/concurrent/futures/thread.py", line 52, in run
    result = self.fn(*self.args, **self.kwargs)
TypeError: update() takes 1 positional argument but 2 were given
2021-09-10 03:48:02 ERROR (SyncWorker_3) [homeassistant] Error doing job: Future exception was never retrieved
Traceback (most recent call last):
  File "/usr/local/lib/python3.9/concurrent/futures/thread.py", line 52, in run
    result = self.fn(*self.args, **self.kwargs)
TypeError: update() takes 1 positional argument but 2 were given
2021-09-10 03:53:03 ERROR (MainThread) [homeassistant] Error doing job: Future exception was never retrieved
Traceback (most recent call last):
  File "/usr/local/lib/python3.9/concurrent/futures/thread.py", line 52, in run
    result = self.fn(*self.args, **self.kwargs)
TypeError: update() takes 1 positional argument but 2 were given
2021-09-10 03:58:04 ERROR (MainThread) [homeassistant] Error doing job: Future exception was never retrieved
Traceback (most recent call last):
  File "/usr/local/lib/python3.9/concurrent/futures/thread.py", line 52, in run
    result = self.fn(*self.args, **self.kwargs)
TypeError: update() takes 1 positional argument but 2 were given
2021-09-10 04:00:37 WARNING (MainThread) [bellows.zigbee.application] Watchdog heartbeat timeout: 
2021-09-10 04:03:05 ERROR (MainThread) [homeassistant] Error doing job: Future exception was never retrieved
Traceback (most recent call last):
  File "/usr/local/lib/python3.9/concurrent/futures/thread.py", line 52, in run
    result = self.fn(*self.args, **self.kwargs)
TypeError: update() takes 1 positional argument but 2 were given
2021-09-10 04:08:06 ERROR (MainThread) [homeassistant] Error doing job: Future exception was never retrieved
Traceback (most recent call last):
  File "/usr/local/lib/python3.9/concurrent/futures/thread.py", line 52, in run
    result = self.fn(*self.args, **self.kwargs)
TypeError: update() takes 1 positional argument but 2 were given
2021-09-10 04:08:13 ERROR (MainThread) [homeassistant.components.nws] Error requesting NWS observation station SAUC1 data: 503, message='Service Unavailable', url=URL('https://api.weather.gov/stations/SAUC1/observations')
2021-09-10 04:08:17 ERROR (MainThread) [iotawattpy.connection] Err: 
2021-09-10 04:08:17 ERROR (MainThread) [homeassistant.components.iotawatt.coordinator] Unexpected error fetching 192.168.20.195 data: 'NoneType' object has no attribute 'text'
Traceback (most recent call last):
  File "/usr/src/homeassistant/homeassistant/helpers/update_coordinator.py", line 187, in _async_refresh
    self.data = await self._async_update_data()
  File "/usr/src/homeassistant/homeassistant/components/iotawatt/coordinator.py", line 55, in _async_update_data
    await self.api.update()
  File "/usr/local/lib/python3.9/site-packages/iotawattpy/iotawatt.py", line 66, in update
    await self._refreshSensors(timespan)
  File "/usr/local/lib/python3.9/site-packages/iotawattpy/iotawatt.py", line 100, in _refreshSensors
    results = response.text
AttributeError: 'NoneType' object has no attribute 'text'
2021-09-10 04:13:07 ERROR (MainThread) [homeassistant] Error doing job: Future exception was never retrieved
Traceback (most recent call last):
  File "/usr/local/lib/python3.9/concurrent/futures/thread.py", line 52, in run
    result = self.fn(*self.args, **self.kwargs)
TypeError: update() takes 1 positional argument but 2 were given
2021-09-10 04:18:08 ERROR (MainThread) [homeassistant] Error doing job: Future exception was never retrieved
Traceback (most recent call last):
  File "/usr/local/lib/python3.9/concurrent/futures/thread.py", line 52, in run
    result = self.fn(*self.args, **self.kwargs)
TypeError: update() takes 1 positional argument but 2 were given
2021-09-10 04:23:09 ERROR (MainThread) [homeassistant] Error doing job: Future exception was never retrieved
Traceback (most recent call last):
  File "/usr/local/lib/python3.9/concurrent/futures/thread.py", line 52, in run
    result = self.fn(*self.args, **self.kwargs)
TypeError: update() takes 1 positional argument but 2 were given
2021-09-10 04:25:48 WARNING (Thread-14) [pychromecast.socket_client] [Bedroom_Sophia speaker(192.168.20.60):8009] Heartbeat timeout, resetting connection
2021-09-10 04:25:51 ERROR (Thread-14) [pychromecast.socket_client] [Bedroom_Sophia speaker(192.168.20.60):8009] Failed to connect to service ServiceInfo(type='host', data=('192.168.20.60', 8009)), retrying in 5.0s
2021-09-10 04:28:10 ERROR (MainThread) [homeassistant] Error doing job: Future exception was never retrieved
Traceback (most recent call last):
  File "/usr/local/lib/python3.9/concurrent/futures/thread.py", line 52, in run
    result = self.fn(*self.args, **self.kwargs)
TypeError: update() takes 1 positional argument but 2 were given
2021-09-10 04:33:11 ERROR (MainThread) [homeassistant] Error doing job: Future exception was never retrieved
Traceback (most recent call last):
  File "/usr/local/lib/python3.9/concurrent/futures/thread.py", line 52, in run
    result = self.fn(*self.args, **self.kwargs)
TypeError: update() takes 1 positional argument but 2 were given
2021-09-10 04:33:26 ERROR (MainThread) [iotawattpy.connection] Err: 
2021-09-10 04:33:26 ERROR (MainThread) [homeassistant.components.iotawatt.coordinator] Unexpected error fetching 192.168.20.195 data: 'NoneType' object has no attribute 'text'
Traceback (most recent call last):
  File "/usr/src/homeassistant/homeassistant/helpers/update_coordinator.py", line 187, in _async_refresh
    self.data = await self._async_update_data()
  File "/usr/src/homeassistant/homeassistant/components/iotawatt/coordinator.py", line 55, in _async_update_data
    await self.api.update()
  File "/usr/local/lib/python3.9/site-packages/iotawattpy/iotawatt.py", line 66, in update
    await self._refreshSensors(timespan)
  File "/usr/local/lib/python3.9/site-packages/iotawattpy/iotawatt.py", line 100, in _refreshSensors
    results = response.text
AttributeError: 'NoneType' object has no attribute 'text'
2021-09-10 04:35:31 WARNING (Thread-7) [pychromecast.socket_client] [Liam Home Mini(192.168.6.222):8009] Heartbeat timeout, resetting connection
2021-09-10 04:35:47 ERROR (Thread-7) [pychromecast.socket_client] [Liam Home Mini(192.168.6.222):8009] Failed to connect to service ServiceInfo(type='host', data=('192.168.6.222', 8009)), retrying in 5.0s
2021-09-10 04:38:03 ERROR (MainThread) [homeassistant.components.nws] Error requesting NWS forecast station SAUC1 data: 500, message='Internal Server Error', url=URL('https://api.weather.gov/gridpoints/LOX/146,60/forecast')
2021-09-10 04:38:12 ERROR (MainThread) [homeassistant] Error doing job: Future exception was never retrieved
Traceback (most recent call last):
  File "/usr/local/lib/python3.9/concurrent/futures/thread.py", line 52, in run
    result = self.fn(*self.args, **self.kwargs)
TypeError: update() takes 1 positional argument but 2 were given
2021-09-10 04:43:13 ERROR (MainThread) [homeassistant] Error doing job: Future exception was never retrieved
Traceback (most recent call last):
  File "/usr/local/lib/python3.9/concurrent/futures/thread.py", line 52, in run
    result = self.fn(*self.args, **self.kwargs)
TypeError: update() takes 1 positional argument but 2 were given
2021-09-10 04:43:15 WARNING (Thread-13) [pychromecast.socket_client] [Kitchen speaker(192.168.20.124):8009] Heartbeat timeout, resetting connection
2021-09-10 04:43:30 ERROR (Thread-13) [pychromecast.socket_client] [Kitchen speaker(192.168.20.124):8009] Failed to connect to service ServiceInfo(type='host', data=('192.168.20.124', 8009)), retrying in 5.0s
2021-09-10 04:48:14 ERROR (MainThread) [homeassistant] Error doing job: Future exception was never retrieved
Traceback (most recent call last):
  File "/usr/local/lib/python3.9/concurrent/futures/thread.py", line 52, in run
    result = self.fn(*self.args, **self.kwargs)
TypeError: update() takes 1 positional argument but 2 were given
2021-09-10 04:53:15 ERROR (MainThread) [homeassistant] Error doing job: Future exception was never retrieved
Traceback (most recent call last):
  File "/usr/local/lib/python3.9/concurrent/futures/thread.py", line 52, in run
    result = self.fn(*self.args, **self.kwargs)
TypeError: update() takes 1 positional argument but 2 were given
2021-09-10 04:58:16 ERROR (MainThread) [homeassistant] Error doing job: Future exception was never retrieved
Traceback (most recent call last):
  File "/usr/local/lib/python3.9/concurrent/futures/thread.py", line 52, in run
    result = self.fn(*self.args, **self.kwargs)
TypeError: update() takes 1 positional argument but 2 were given
2021-09-10 05:03:17 ERROR (MainThread) [homeassistant] Error doing job: Future exception was never retrieved
Traceback (most recent call last):
  File "/usr/local/lib/python3.9/concurrent/futures/thread.py", line 52, in run
    result = self.fn(*self.args, **self.kwargs)
TypeError: update() takes 1 positional argument but 2 were given
2021-09-10 05:08:18 ERROR (MainThread) [homeassistant] Error doing job: Future exception was never retrieved
Traceback (most recent call last):
  File "/usr/local/lib/python3.9/concurrent/futures/thread.py", line 52, in run
    result = self.fn(*self.args, **self.kwargs)
TypeError: update() takes 1 positional argument but 2 were given
2021-09-10 05:13:19 ERROR (MainThread) [homeassistant] Error doing job: Future exception was never retrieved
Traceback (most recent call last):
  File "/usr/local/lib/python3.9/concurrent/futures/thread.py", line 52, in run
    result = self.fn(*self.args, **self.kwargs)
TypeError: update() takes 1 positional argument but 2 were given
2021-09-10 05:18:20 ERROR (MainThread) [homeassistant] Error doing job: Future exception was never retrieved
Traceback (most recent call last):
  File "/usr/local/lib/python3.9/concurrent/futures/thread.py", line 52, in run
    result = self.fn(*self.args, **self.kwargs)
TypeError: update() takes 1 positional argument but 2 were given
2021-09-10 05:23:21 ERROR (MainThread) [homeassistant] Error doing job: Future exception was never retrieved
Traceback (most recent call last):
  File "/usr/local/lib/python3.9/concurrent/futures/thread.py", line 52, in run
    result = self.fn(*self.args, **self.kwargs)
TypeError: update() takes 1 positional argument but 2 were given
2021-09-10 05:28:22 ERROR (MainThread) [homeassistant] Error doing job: Future exception was never retrieved
Traceback (most recent call last):
  File "/usr/local/lib/python3.9/concurrent/futures/thread.py", line 52, in run
    result = self.fn(*self.args, **self.kwargs)
TypeError: update() takes 1 positional argument but 2 were given
2021-09-10 05:33:23 ERROR (MainThread) [homeassistant] Error doing job: Future exception was never retrieved
Traceback (most recent call last):
  File "/usr/local/lib/python3.9/concurrent/futures/thread.py", line 52, in run
    result = self.fn(*self.args, **self.kwargs)
TypeError: update() takes 1 positional argument but 2 were given
2021-09-10 05:38:24 ERROR (MainThread) [homeassistant] Error doing job: Future exception was never retrieved
Traceback (most recent call last):
  File "/usr/local/lib/python3.9/concurrent/futures/thread.py", line 52, in run
    result = self.fn(*self.args, **self.kwargs)
TypeError: update() takes 1 positional argument but 2 were given
2021-09-10 05:43:25 ERROR (MainThread) [homeassistant] Error doing job: Future exception was never retrieved
Traceback (most recent call last):
  File "/usr/local/lib/python3.9/concurrent/futures/thread.py", line 52, in run
    result = self.fn(*self.args, **self.kwargs)
TypeError: update() takes 1 positional argument but 2 were given
2021-09-10 05:47:28 ERROR (stream_worker) [libav.rtsp] method DESCRIBE failed: 404 Not Found
2021-09-10 05:47:28 ERROR (stream_worker) [homeassistant.components.stream.worker] Error opening stream rtsps://stream-uc2-bravo.dropcam.com:443/sdm_live_stream/CiQA2vuxryuR_Y2Du1lLazI2wVTkRn6yyx5Bz3bJIwL7jh-Ybz0ScQAFjsOTnXrwGRiAaShdp5it8thQUb7ISRu_gcdE35t-E9bXyLnGJ1bOiv0vObCB-SrC49fmUKVhqFlbcUYRnB6qT7edhtcm57TTZqWISxnWKGEoFMfZAHgJeU55nOpYuBvC_Bc3SvurlPuEfKdrhUnT?auth=g.0.eyJraWQiOiIyMzhiNTUxZmMyM2EyM2Y4M2E2ZTE3MmJjZTg0YmU3ZjgxMzAzMmM4IiwiYWxnIjoiUlMyNTYifQ.eyJpc3MiOiJuZXN0LXNlY3VyaXR5LWF1dGhwcm94eSIsInN1YiI6Im5lc3RfaWQ6bmVzdC1waG9lbml4LXByb2Q6MjEyMTgxNDEiLCJwb2wiOiIzcC1vYXV0aC1zY29wZS1BUElfU0RNX1NFUlZJQ0UtY2xpZW50LTIwMjQyNzMxODczNS1qNXQ5bWMyMzZqaG85YXMycWY0dTZxY3NmYW1kaGJ0ci5hcHBzLmdvb2dsZXVzZXJjb250ZW50LmNvbSIsImV4cCI6MTYzMTI3ODMzNn0.gHQSFUW-8x2HU6psU25gDwz-E5d_1NZ7eVBJPnuG8UYlg8qstlvXg2bv80P23EFRigVMXYcHcda2zy5YY7OX3X014Xgw2ug45QA8h6qJK6LzsD-ABdS4C1G-hI-R3EZsmt0LOrngoXCnr5ahYZ8T3VGQVxfooeqCRh0U3xvku2ZSPfPCUQHlXf7by8RIJHLWFpVl1fVeEqoasz6Nfy8f1QbFoKcK07a51Jd4iThaLfXIJfNS8_IJiF25L26VPdDVIaeoOwjgKrt1EqpQ6--Ms62jQdYQoe9EyINBUI8Ol4OjyX9UPf4jKj-fGR9kZ8SoWoqMXR4HUElK7uimG_9o-w
2021-09-10 05:48:26 ERROR (MainThread) [homeassistant] Error doing job: Future exception was never retrieved
Traceback (most recent call last):
  File "/usr/local/lib/python3.9/concurrent/futures/thread.py", line 52, in run
    result = self.fn(*self.args, **self.kwargs)
TypeError: update() takes 1 positional argument but 2 were given
2021-09-10 05:52:09 ERROR (stream_worker) [libav.rtsp] method DESCRIBE failed: 404 Not Found
2021-09-10 05:52:09 ERROR (stream_worker) [homeassistant.components.stream.worker] Error opening stream rtsps://stream-uc2-bravo.dropcam.com:443/sdm_live_stream/CiQA2vuxryuR_Y2Du1lLazI2wVTkRn6yyx5Bz3bJIwL7jh-Ybz0ScQAFjsOTnXrwGRiAaShdp5it8thQUb7ISRu_gcdE35t-E9bXyLnGJ1bOiv0vObCB-SrC49fmUKVhqFlbcUYRnB6qT7edhtcm57TTZqWISxnWKGEoFMfZAHgJeU55nOpYuBvC_Bc3SvurlPuEfKdrhUnT?auth=g.0.eyJraWQiOiIyMzhiNTUxZmMyM2EyM2Y4M2E2ZTE3MmJjZTg0YmU3ZjgxMzAzMmM4IiwiYWxnIjoiUlMyNTYifQ.eyJpc3MiOiJuZXN0LXNlY3VyaXR5LWF1dGhwcm94eSIsInN1YiI6Im5lc3RfaWQ6bmVzdC1waG9lbml4LXByb2Q6MjEyMTgxNDEiLCJwb2wiOiIzcC1vYXV0aC1zY29wZS1BUElfU0RNX1NFUlZJQ0UtY2xpZW50LTIwMjQyNzMxODczNS1qNXQ5bWMyMzZqaG85YXMycWY0dTZxY3NmYW1kaGJ0ci5hcHBzLmdvb2dsZXVzZXJjb250ZW50LmNvbSIsImV4cCI6MTYzMTI3ODYwNn0.eCIpaWrhi-vtUTpyKKA7P5dm3ZUd8yY8zjpLv_my6Ry7oVh0HAgANEpBZiCBLXjwa3U8y3A5c5qI9vNV9Ne_n0hhvZ8EnTqu5niTmo2UVk-cQLNGDonsNaIrtL-DKB_oZ85XE2xzXmF69Abk_YuoJfjm70APXBTqLOxHbT83WAAlo75h39Swye0tB-poRDmxsXIMySBSHLl9w2_8wobklVrt1wOpE3cpTG4HnNZ3kTCrbu-S8jqqfSulxfWF2gU1w99foX9FYRCxJ1xz0u0p9eOLqkl4_GXnPFi3UFv2ISUZFTacrpHgfqFdVdL8bIs-hSqXalTtCjsnGHs_vsdFgQ
2021-09-10 05:53:27 ERROR (MainThread) [homeassistant] Error doing job: Future exception was never retrieved
Traceback (most recent call last):
  File "/usr/local/lib/python3.9/concurrent/futures/thread.py", line 52, in run
    result = self.fn(*self.args, **self.kwargs)
TypeError: update() takes 1 positional argument but 2 were given
2021-09-10 05:56:53 ERROR (stream_worker) [libav.rtsp] method DESCRIBE failed: 404 Not Found
2021-09-10 05:56:53 ERROR (stream_worker) [homeassistant.components.stream.worker] Error opening stream rtsps://stream-uc2-bravo.dropcam.com:443/sdm_live_stream/CiQA2vuxryuR_Y2Du1lLazI2wVTkRn6yyx5Bz3bJIwL7jh-Ybz0ScQAFjsOTnXrwGRiAaShdp5it8thQUb7ISRu_gcdE35t-E9bXyLnGJ1bOiv0vObCB-SrC49fmUKVhqFlbcUYRnB6qT7edhtcm57TTZqWISxnWKGEoFMfZAHgJeU55nOpYuBvC_Bc3SvurlPuEfKdrhUnT?auth=g.0.eyJraWQiOiIyMzhiNTUxZmMyM2EyM2Y4M2E2ZTE3MmJjZTg0YmU3ZjgxMzAzMmM4IiwiYWxnIjoiUlMyNTYifQ.eyJpc3MiOiJuZXN0LXNlY3VyaXR5LWF1dGhwcm94eSIsInN1YiI6Im5lc3RfaWQ6bmVzdC1waG9lbml4LXByb2Q6MjEyMTgxNDEiLCJwb2wiOiIzcC1vYXV0aC1zY29wZS1BUElfU0RNX1NFUlZJQ0UtY2xpZW50LTIwMjQyNzMxODczNS1qNXQ5bWMyMzZqaG85YXMycWY0dTZxY3NmYW1kaGJ0ci5hcHBzLmdvb2dsZXVzZXJjb250ZW50LmNvbSIsImV4cCI6MTYzMTI3ODg3Nn0.m4cCwN4CRyunySGeEVkztoAZh9DnMotnPjoCkxO8hixBr_pARNDHwxBxalMvEXnDV6A1-iOKl3tAFuls3nwUC1zMUu89Xq_MPC426Mt2z3AhFS-fdU5sRkXZZMs5XIanqklb15qdQAkTWBJ2gO4Ho68IBIh75s8nlpXr9S28xX-tRoRtNuDACXeCsoB8whLqHgfb1h6azfFTiSaQleVmOKF5TraYThcM2TA-SVJbjRx3rmkQSLljLK5FJRmqUe3lvwHMhdUVEM3dxivaVlCF4IFaxBRtISovGKdcUeIOGlfzBF8675__TquvVY232HpGeMB9KDdcsLApKjoPUpr5ww
2021-09-10 05:58:28 ERROR (MainThread) [homeassistant] Error doing job: Future exception was never retrieved
Traceback (most recent call last):
  File "/usr/local/lib/python3.9/concurrent/futures/thread.py", line 52, in run
    result = self.fn(*self.args, **self.kwargs)
TypeError: update() takes 1 positional argument but 2 were given
2021-09-10 06:01:32 ERROR (stream_worker) [libav.rtsp] method DESCRIBE failed: 404 Not Found
2021-09-10 06:01:32 ERROR (stream_worker) [homeassistant.components.stream.worker] Error opening stream rtsps://stream-uc2-bravo.dropcam.com:443/sdm_live_stream/CiQA2vuxryuR_Y2Du1lLazI2wVTkRn6yyx5Bz3bJIwL7jh-Ybz0ScQAFjsOTnXrwGRiAaShdp5it8thQUb7ISRu_gcdE35t-E9bXyLnGJ1bOiv0vObCB-SrC49fmUKVhqFlbcUYRnB6qT7edhtcm57TTZqWISxnWKGEoFMfZAHgJeU55nOpYuBvC_Bc3SvurlPuEfKdrhUnT?auth=g.0.eyJraWQiOiIyMzhiNTUxZmMyM2EyM2Y4M2E2ZTE3MmJjZTg0YmU3ZjgxMzAzMmM4IiwiYWxnIjoiUlMyNTYifQ.eyJpc3MiOiJuZXN0LXNlY3VyaXR5LWF1dGhwcm94eSIsInN1YiI6Im5lc3RfaWQ6bmVzdC1waG9lbml4LXByb2Q6MjEyMTgxNDEiLCJwb2wiOiIzcC1vYXV0aC1zY29wZS1BUElfU0RNX1NFUlZJQ0UtY2xpZW50LTIwMjQyNzMxODczNS1qNXQ5bWMyMzZqaG85YXMycWY0dTZxY3NmYW1kaGJ0ci5hcHBzLmdvb2dsZXVzZXJjb250ZW50LmNvbSIsImV4cCI6MTYzMTI3OTE0N30.X60n8xGM5n9QPM_RK5wYLCGbnrVKY_ufnCDquV0EqxVw1Ec9XwJMBKqPeJlBR1_V6mVPQ0aSYn3WxYPxYQULTP28NLTWjDM5_WdwodePKEQGP5I4y-XjtFalQR315BIAZLUm02vaJiiP8BO1B0D_EAFJ42kJh62EyxdVPzEqQWNL7IUq3maDGHMb1PqzPvtnQI93hCPwZ41QfjHOVLo66oUsQ29xetgMXhfO1ynCo4gXVynlq0hV1baD5hF2LV0kD8eqmPNzq4k0VQ7JBD91XqLq-dLRVBm4wAUmVd4GhSEYGHPaT3nj9alOB4JGuaaZ-_sQv3-9E2yYU3qpbj40LA
2021-09-10 06:02:23 ERROR (stream_worker) [libav.rtsp] method DESCRIBE failed: 404 Not Found
2021-09-10 06:02:23 ERROR (stream_worker) [homeassistant.components.stream.worker] Error opening stream rtsps://stream-uc2-bravo.dropcam.com:443/sdm_live_stream/CiQA2vuxryuR_Y2Du1lLazI2wVTkRn6yyx5Bz3bJIwL7jh-Ybz0ScQAFjsOTnXrwGRiAaShdp5it8thQUb7ISRu_gcdE35t-E9bXyLnGJ1bOiv0vObCB-SrC49fmUKVhqFlbcUYRnB6qT7edhtcm57TTZqWISxnWKGEoFMfZAHgJeU55nOpYuBvC_Bc3SvurlPuEfKdrhUnT?auth=g.0.eyJraWQiOiIyMzhiNTUxZmMyM2EyM2Y4M2E2ZTE3MmJjZTg0YmU3ZjgxMzAzMmM4IiwiYWxnIjoiUlMyNTYifQ.eyJpc3MiOiJuZXN0LXNlY3VyaXR5LWF1dGhwcm94eSIsInN1YiI6Im5lc3RfaWQ6bmVzdC1waG9lbml4LXByb2Q6MjEyMTgxNDEiLCJwb2wiOiIzcC1vYXV0aC1zY29wZS1BUElfU0RNX1NFUlZJQ0UtY2xpZW50LTIwMjQyNzMxODczNS1qNXQ5bWMyMzZqaG85YXMycWY0dTZxY3NmYW1kaGJ0ci5hcHBzLmdvb2dsZXVzZXJjb250ZW50LmNvbSIsImV4cCI6MTYzMTI3OTE0N30.X60n8xGM5n9QPM_RK5wYLCGbnrVKY_ufnCDquV0EqxVw1Ec9XwJMBKqPeJlBR1_V6mVPQ0aSYn3WxYPxYQULTP28NLTWjDM5_WdwodePKEQGP5I4y-XjtFalQR315BIAZLUm02vaJiiP8BO1B0D_EAFJ42kJh62EyxdVPzEqQWNL7IUq3maDGHMb1PqzPvtnQI93hCPwZ41QfjHOVLo66oUsQ29xetgMXhfO1ynCo4gXVynlq0hV1baD5hF2LV0kD8eqmPNzq4k0VQ7JBD91XqLq-dLRVBm4wAUmVd4GhSEYGHPaT3nj9alOB4JGuaaZ-_sQv3-9E2yYU3qpbj40LA
2021-09-10 06:03:27 ERROR (stream_worker) [libav.rtsp] method DESCRIBE failed: 404 Not Found
2021-09-10 06:03:27 ERROR (stream_worker) [homeassistant.components.stream.worker] Error opening stream rtsps://stream-uc2-bravo.dropcam.com:443/sdm_live_stream/CiQA2vuxryuR_Y2Du1lLazI2wVTkRn6yyx5Bz3bJIwL7jh-Ybz0ScQAFjsOTnXrwGRiAaShdp5it8thQUb7ISRu_gcdE35t-E9bXyLnGJ1bOiv0vObCB-SrC49fmUKVhqFlbcUYRnB6qT7edhtcm57TTZqWISxnWKGEoFMfZAHgJeU55nOpYuBvC_Bc3SvurlPuEfKdrhUnT?auth=g.0.eyJraWQiOiIyMzhiNTUxZmMyM2EyM2Y4M2E2ZTE3MmJjZTg0YmU3ZjgxMzAzMmM4IiwiYWxnIjoiUlMyNTYifQ.eyJpc3MiOiJuZXN0LXNlY3VyaXR5LWF1dGhwcm94eSIsInN1YiI6Im5lc3RfaWQ6bmVzdC1waG9lbml4LXByb2Q6MjEyMTgxNDEiLCJwb2wiOiIzcC1vYXV0aC1zY29wZS1BUElfU0RNX1NFUlZJQ0UtY2xpZW50LTIwMjQyNzMxODczNS1qNXQ5bWMyMzZqaG85YXMycWY0dTZxY3NmYW1kaGJ0ci5hcHBzLmdvb2dsZXVzZXJjb250ZW50LmNvbSIsImV4cCI6MTYzMTI3OTE0N30.X60n8xGM5n9QPM_RK5wYLCGbnrVKY_ufnCDquV0EqxVw1Ec9XwJMBKqPeJlBR1_V6mVPQ0aSYn3WxYPxYQULTP28NLTWjDM5_WdwodePKEQGP5I4y-XjtFalQR315BIAZLUm02vaJiiP8BO1B0D_EAFJ42kJh62EyxdVPzEqQWNL7IUq3maDGHMb1PqzPvtnQI93hCPwZ41QfjHOVLo66oUsQ29xetgMXhfO1ynCo4gXVynlq0hV1baD5hF2LV0kD8eqmPNzq4k0VQ7JBD91XqLq-dLRVBm4wAUmVd4GhSEYGHPaT3nj9alOB4JGuaaZ-_sQv3-9E2yYU3qpbj40LA
2021-09-10 06:03:29 ERROR (MainThread) [homeassistant] Error doing job: Future exception was never retrieved
Traceback (most recent call last):
  File "/usr/local/lib/python3.9/concurrent/futures/thread.py", line 52, in run
    result = self.fn(*self.args, **self.kwargs)
TypeError: update() takes 1 positional argument but 2 were given
2021-09-10 06:08:30 ERROR (MainThread) [homeassistant] Error doing job: Future exception was never retrieved
Traceback (most recent call last):
  File "/usr/local/lib/python3.9/concurrent/futures/thread.py", line 52, in run
    result = self.fn(*self.args, **self.kwargs)
TypeError: update() takes 1 positional argument but 2 were given
2021-09-10 06:13:31 ERROR (MainThread) [homeassistant] Error doing job: Future exception was never retrieved
Traceback (most recent call last):
  File "/usr/local/lib/python3.9/concurrent/futures/thread.py", line 52, in run
    result = self.fn(*self.args, **self.kwargs)
TypeError: update() takes 1 positional argument but 2 were given
2021-09-10 06:18:32 ERROR (MainThread) [homeassistant] Error doing job: Future exception was never retrieved
Traceback (most recent call last):
  File "/usr/local/lib/python3.9/concurrent/futures/thread.py", line 52, in run
    result = self.fn(*self.args, **self.kwargs)
TypeError: update() takes 1 positional argument but 2 were given
2021-09-10 06:20:03 ERROR (stream_worker) [libav.rtsp] method DESCRIBE failed: 404 Not Found
2021-09-10 06:20:03 ERROR (stream_worker) [homeassistant.components.stream.worker] Error opening stream rtsps://stream-uc2-bravo.dropcam.com:443/sdm_live_stream/CiQA2vuxryuR_Y2Du1lLazI2wVTkRn6yyx5Bz3bJIwL7jh-Ybz0ScQAFjsOTnXrwGRiAaShdp5it8thQUb7ISRu_gcdE35t-E9bXyLnGJ1bOiv0vObCB-SrC49fmUKVhqFlbcUYRnB6qT7edhtcm57TTZqWISxnWKGEoFMfZAHgJeU55nOpYuBvC_Bc3SvurlPuEfKdrhUnT?auth=g.0.eyJraWQiOiIyMzhiNTUxZmMyM2EyM2Y4M2E2ZTE3MmJjZTg0YmU3ZjgxMzAzMmM4IiwiYWxnIjoiUlMyNTYifQ.eyJpc3MiOiJuZXN0LXNlY3VyaXR5LWF1dGhwcm94eSIsInN1YiI6Im5lc3RfaWQ6bmVzdC1waG9lbml4LXByb2Q6MjEyMTgxNDEiLCJwb2wiOiIzcC1vYXV0aC1zY29wZS1BUElfU0RNX1NFUlZJQ0UtY2xpZW50LTIwMjQyNzMxODczNS1qNXQ5bWMyMzZqaG85YXMycWY0dTZxY3NmYW1kaGJ0ci5hcHBzLmdvb2dsZXVzZXJjb250ZW50LmNvbSIsImV4cCI6MTYzMTI4MDIzMH0.eZ6k3DPT9CU7FBZhgpTSS8X5WC3ViVUTeT7SNNhn1bQTUAAF-FjsAOjBPzvqHJVoEJM37DOcY4gePmDD0XsZT0_u81NlnJTAwiY9TsscX3H0elfXR4ij6lYelYdRPZcozTZ6YINhjNn58COUHuZ7eIpES1jVPkuE0Xe-L1Lg8K6VRn1cRdcTR4jTgtrm96PaQWmDa6aeN577d400qpl32A3EQylvePi8YcDelbJ5JpkfzsW4vNhOfFJeA8Mrbf0IYcyAb6DLVpzkPmWPP1v3vDNtzdNMvA_r8e3Flvw844NIwT56jL48Cz5gXzpwqRpg66meuy6CzAFkWsNGK9Ei1g
2021-09-10 06:21:26 ERROR (stream_worker) [libav.rtsp] method DESCRIBE failed: 404 Not Found
2021-09-10 06:21:26 ERROR (stream_worker) [homeassistant.components.stream.worker] Error opening stream rtsps://stream-uc2-bravo.dropcam.com:443/sdm_live_stream/CiQA2vuxryuR_Y2Du1lLazI2wVTkRn6yyx5Bz3bJIwL7jh-Ybz0ScQAFjsOTnXrwGRiAaShdp5it8thQUb7ISRu_gcdE35t-E9bXyLnGJ1bOiv0vObCB-SrC49fmUKVhqFlbcUYRnB6qT7edhtcm57TTZqWISxnWKGEoFMfZAHgJeU55nOpYuBvC_Bc3SvurlPuEfKdrhUnT?auth=g.0.eyJraWQiOiIyMzhiNTUxZmMyM2EyM2Y4M2E2ZTE3MmJjZTg0YmU3ZjgxMzAzMmM4IiwiYWxnIjoiUlMyNTYifQ.eyJpc3MiOiJuZXN0LXNlY3VyaXR5LWF1dGhwcm94eSIsInN1YiI6Im5lc3RfaWQ6bmVzdC1waG9lbml4LXByb2Q6MjEyMTgxNDEiLCJwb2wiOiIzcC1vYXV0aC1zY29wZS1BUElfU0RNX1NFUlZJQ0UtY2xpZW50LTIwMjQyNzMxODczNS1qNXQ5bWMyMzZqaG85YXMycWY0dTZxY3NmYW1kaGJ0ci5hcHBzLmdvb2dsZXVzZXJjb250ZW50LmNvbSIsImV4cCI6MTYzMTI4MDIzMH0.eZ6k3DPT9CU7FBZhgpTSS8X5WC3ViVUTeT7SNNhn1bQTUAAF-FjsAOjBPzvqHJVoEJM37DOcY4gePmDD0XsZT0_u81NlnJTAwiY9TsscX3H0elfXR4ij6lYelYdRPZcozTZ6YINhjNn58COUHuZ7eIpES1jVPkuE0Xe-L1Lg8K6VRn1cRdcTR4jTgtrm96PaQWmDa6aeN577d400qpl32A3EQylvePi8YcDelbJ5JpkfzsW4vNhOfFJeA8Mrbf0IYcyAb6DLVpzkPmWPP1v3vDNtzdNMvA_r8e3Flvw844NIwT56jL48Cz5gXzpwqRpg66meuy6CzAFkWsNGK9Ei1g
2021-09-10 06:22:58 ERROR (stream_worker) [libav.rtsp] method DESCRIBE failed: 404 Not Found
2021-09-10 06:22:58 ERROR (stream_worker) [homeassistant.components.stream.worker] Error opening stream rtsps://stream-uc2-bravo.dropcam.com:443/sdm_live_stream/CiQA2vuxryuR_Y2Du1lLazI2wVTkRn6yyx5Bz3bJIwL7jh-Ybz0ScQAFjsOTnXrwGRiAaShdp5it8thQUb7ISRu_gcdE35t-E9bXyLnGJ1bOiv0vObCB-SrC49fmUKVhqFlbcUYRnB6qT7edhtcm57TTZqWISxnWKGEoFMfZAHgJeU55nOpYuBvC_Bc3SvurlPuEfKdrhUnT?auth=g.0.eyJraWQiOiIyMzhiNTUxZmMyM2EyM2Y4M2E2ZTE3MmJjZTg0YmU3ZjgxMzAzMmM4IiwiYWxnIjoiUlMyNTYifQ.eyJpc3MiOiJuZXN0LXNlY3VyaXR5LWF1dGhwcm94eSIsInN1YiI6Im5lc3RfaWQ6bmVzdC1waG9lbml4LXByb2Q6MjEyMTgxNDEiLCJwb2wiOiIzcC1vYXV0aC1zY29wZS1BUElfU0RNX1NFUlZJQ0UtY2xpZW50LTIwMjQyNzMxODczNS1qNXQ5bWMyMzZqaG85YXMycWY0dTZxY3NmYW1kaGJ0ci5hcHBzLmdvb2dsZXVzZXJjb250ZW50LmNvbSIsImV4cCI6MTYzMTI4MDIzMH0.eZ6k3DPT9CU7FBZhgpTSS8X5WC3ViVUTeT7SNNhn1bQTUAAF-FjsAOjBPzvqHJVoEJM37DOcY4gePmDD0XsZT0_u81NlnJTAwiY9TsscX3H0elfXR4ij6lYelYdRPZcozTZ6YINhjNn58COUHuZ7eIpES1jVPkuE0Xe-L1Lg8K6VRn1cRdcTR4jTgtrm96PaQWmDa6aeN577d400qpl32A3EQylvePi8YcDelbJ5JpkfzsW4vNhOfFJeA8Mrbf0IYcyAb6DLVpzkPmWPP1v3vDNtzdNMvA_r8e3Flvw844NIwT56jL48Cz5gXzpwqRpg66meuy6CzAFkWsNGK9Ei1g
2021-09-10 06:23:33 ERROR (MainThread) [homeassistant] Error doing job: Future exception was never retrieved
Traceback (most recent call last):
  File "/usr/local/lib/python3.9/concurrent/futures/thread.py", line 52, in run
    result = self.fn(*self.args, **self.kwargs)
TypeError: update() takes 1 positional argument but 2 were given
2021-09-10 06:28:34 ERROR (MainThread) [homeassistant] Error doing job: Future exception was never retrieved
Traceback (most recent call last):
  File "/usr/local/lib/python3.9/concurrent/futures/thread.py", line 52, in run
    result = self.fn(*self.args, **self.kwargs)
TypeError: update() takes 1 positional argument but 2 were given
2021-09-10 06:31:04 WARNING (MainThread) [bellows.zigbee.application] Watchdog heartbeat timeout: 
2021-09-10 06:32:35 ERROR (stream_worker) [libav.rtsp] method DESCRIBE failed: 404 Not Found
2021-09-10 06:32:35 ERROR (stream_worker) [homeassistant.components.stream.worker] Error opening stream rtsps://stream-uc2-delta.dropcam.com:443/sdm_live_stream/CiQA2vuxr0cz3uGK6pdk-GsmixwGlQ4I9ToMkWcbvV56BPnmuAsScQAFjsOTKzsUJlNkyY9WR6m24tCzh8uaBGheYK5uf1zJOzubLn9Xaj1xIryiaENBviH9g_u3T0X72rHGt94eqSypb31ZFgJ3YinxoxJNRZceJrz0QNo_NmpISS-CSOH-tlaSBPX7t2zYQ9fgwFinYW_Z?auth=g.0.eyJraWQiOiIyMzhiNTUxZmMyM2EyM2Y4M2E2ZTE3MmJjZTg0YmU3ZjgxMzAzMmM4IiwiYWxnIjoiUlMyNTYifQ.eyJpc3MiOiJuZXN0LXNlY3VyaXR5LWF1dGhwcm94eSIsInN1YiI6Im5lc3RfaWQ6bmVzdC1waG9lbml4LXByb2Q6MjEyMTgxNDEiLCJwb2wiOiIzcC1vYXV0aC1zY29wZS1BUElfU0RNX1NFUlZJQ0UtY2xpZW50LTIwMjQyNzMxODczNS1qNXQ5bWMyMzZqaG85YXMycWY0dTZxY3NmYW1kaGJ0ci5hcHBzLmdvb2dsZXVzZXJjb250ZW50LmNvbSIsImV4cCI6MTYzMTI4MTA0MX0.p2fuMqPdhWiRgcTF_p4WpE8We3cdprqUI55wRi9TBcXS7k-ul-NgUWkhbzbB7e17S40x6ooDOL1jukCHrkAAqgHqiyPh3DJGfk7CM0woY7uDFIrQTdZU0xDHRFHgu4oyMNQzzG3fqr5qi6TkC_Zg_EuDbtObobTkf19LxM-Q5Ny-6Abl1jY1bW3x6wf_pc0Dg37YogMY70XTMLEeTjYueYR4dis5DvfcuoW_WPkeTeuwvJOJXOUEIN_TNiJvY6zME-Mf7upu7r619AWsQOYpKS3Qz0I3_zhQdp_XNByvRtJL50iZhSdnkSHi7gwxSfg96B1UUntIgKwO9m5Dw-indQ
2021-09-10 06:33:35 ERROR (MainThread) [homeassistant] Error doing job: Future exception was never retrieved
Traceback (most recent call last):
  File "/usr/local/lib/python3.9/concurrent/futures/thread.py", line 52, in run
    result = self.fn(*self.args, **self.kwargs)
TypeError: update() takes 1 positional argument but 2 were given
2021-09-10 06:34:16 WARNING (MainThread) [homeassistant.helpers.service] Unable to find referenced entities scene.kitchen_sink_off
2021-09-10 06:35:40 ERROR (stream_worker) [libav.tls] The specified session has been invalidated for some reason.
2021-09-10 06:35:40 ERROR (stream_worker) [homeassistant.components.stream.worker] Error demuxing stream: 
2021-09-10 06:36:00 ERROR (stream_worker) [libav.tls] The specified session has been invalidated for some reason.
2021-09-10 06:36:10 ERROR (stream_worker) [libav.rtsp] method DESCRIBE failed: 404 Not Found
2021-09-10 06:36:10 ERROR (stream_worker) [homeassistant.components.stream.worker] Error opening stream rtsps://stream-uc2-delta.dropcam.com:443/sdm_live_stream/CiQA2vuxr0cz3uGK6pdk-GsmixwGlQ4I9ToMkWcbvV56BPnmuAsScQAFjsOTKzsUJlNkyY9WR6m24tCzh8uaBGheYK5uf1zJOzubLn9Xaj1xIryiaENBviH9g_u3T0X72rHGt94eqSypb31ZFgJ3YinxoxJNRZceJrz0QNo_NmpISS-CSOH-tlaSBPX7t2zYQ9fgwFinYW_Z?auth=g.0.eyJraWQiOiIyMzhiNTUxZmMyM2EyM2Y4M2E2ZTE3MmJjZTg0YmU3ZjgxMzAzMmM4IiwiYWxnIjoiUlMyNTYifQ.eyJpc3MiOiJuZXN0LXNlY3VyaXR5LWF1dGhwcm94eSIsInN1YiI6Im5lc3RfaWQ6bmVzdC1waG9lbml4LXByb2Q6MjEyMTgxNDEiLCJwb2wiOiIzcC1vYXV0aC1zY29wZS1BUElfU0RNX1NFUlZJQ0UtY2xpZW50LTIwMjQyNzMxODczNS1qNXQ5bWMyMzZqaG85YXMycWY0dTZxY3NmYW1kaGJ0ci5hcHBzLmdvb2dsZXVzZXJjb250ZW50LmNvbSIsImV4cCI6MTYzMTI4MTA0MX0.p2fuMqPdhWiRgcTF_p4WpE8We3cdprqUI55wRi9TBcXS7k-ul-NgUWkhbzbB7e17S40x6ooDOL1jukCHrkAAqgHqiyPh3DJGfk7CM0woY7uDFIrQTdZU0xDHRFHgu4oyMNQzzG3fqr5qi6TkC_Zg_EuDbtObobTkf19LxM-Q5Ny-6Abl1jY1bW3x6wf_pc0Dg37YogMY70XTMLEeTjYueYR4dis5DvfcuoW_WPkeTeuwvJOJXOUEIN_TNiJvY6zME-Mf7upu7r619AWsQOYpKS3Qz0I3_zhQdp_XNByvRtJL50iZhSdnkSHi7gwxSfg96B1UUntIgKwO9m5Dw-indQ
2021-09-10 06:37:36 ERROR (stream_worker) [libav.rtsp] method DESCRIBE failed: 404 Not Found
2021-09-10 06:37:36 ERROR (stream_worker) [homeassistant.components.stream.worker] Error opening stream rtsps://stream-uc2-delta.dropcam.com:443/sdm_live_stream/CiQA2vuxr0cz3uGK6pdk-GsmixwGlQ4I9ToMkWcbvV56BPnmuAsScQAFjsOTKzsUJlNkyY9WR6m24tCzh8uaBGheYK5uf1zJOzubLn9Xaj1xIryiaENBviH9g_u3T0X72rHGt94eqSypb31ZFgJ3YinxoxJNRZceJrz0QNo_NmpISS-CSOH-tlaSBPX7t2zYQ9fgwFinYW_Z?auth=g.0.eyJraWQiOiIyMzhiNTUxZmMyM2EyM2Y4M2E2ZTE3MmJjZTg0YmU3ZjgxMzAzMmM4IiwiYWxnIjoiUlMyNTYifQ.eyJpc3MiOiJuZXN0LXNlY3VyaXR5LWF1dGhwcm94eSIsInN1YiI6Im5lc3RfaWQ6bmVzdC1waG9lbml4LXByb2Q6MjEyMTgxNDEiLCJwb2wiOiIzcC1vYXV0aC1zY29wZS1BUElfU0RNX1NFUlZJQ0UtY2xpZW50LTIwMjQyNzMxODczNS1qNXQ5bWMyMzZqaG85YXMycWY0dTZxY3NmYW1kaGJ0ci5hcHBzLmdvb2dsZXVzZXJjb250ZW50LmNvbSIsImV4cCI6MTYzMTI4MTMxMn0.KMsi2x2eltanzHsfE5zV6rT8EVPWOCmLPUPXw1-gAYf_Ls96PhVevjQtrDQRQXnA0_AJZ4a9VuDuUpFPrU0FdA6OHOEg3JVYL9aCMdEIL-n2izuNLNSJu2rU0fjeGHpBaeKjiTMwZlA2B9KSyV2mdYWambIJZrEYVkIJPRocmPelKOyPW64eYIi3LDzcZgPr1P5XXvWky8aJwt88mCd02wymQBsW-8XWL1rza5iARsdwzq0Gl_x6YCr8-CgQeJp-xIRZ5uVSBugiI6wzEBczDFCElFSxyNjlsGoOj2BLqAPOnMNuHjuGcrbj91d_TkfS5Rgc2K0xhhkg34D4NImkPQ
2021-09-10 06:38:36 ERROR (MainThread) [homeassistant] Error doing job: Future exception was never retrieved
Traceback (most recent call last):
  File "/usr/local/lib/python3.9/concurrent/futures/thread.py", line 52, in run
    result = self.fn(*self.args, **self.kwargs)
TypeError: update() takes 1 positional argument but 2 were given
2021-09-10 06:42:18 ERROR (stream_worker) [libav.rtsp] method DESCRIBE failed: 404 Not Found
2021-09-10 06:42:18 ERROR (stream_worker) [homeassistant.components.stream.worker] Error opening stream rtsps://stream-uc2-delta.dropcam.com:443/sdm_live_stream/CiQA2vuxr0cz3uGK6pdk-GsmixwGlQ4I9ToMkWcbvV56BPnmuAsScQAFjsOTKzsUJlNkyY9WR6m24tCzh8uaBGheYK5uf1zJOzubLn9Xaj1xIryiaENBviH9g_u3T0X72rHGt94eqSypb31ZFgJ3YinxoxJNRZceJrz0QNo_NmpISS-CSOH-tlaSBPX7t2zYQ9fgwFinYW_Z?auth=g.0.eyJraWQiOiIyMzhiNTUxZmMyM2EyM2Y4M2E2ZTE3MmJjZTg0YmU3ZjgxMzAzMmM4IiwiYWxnIjoiUlMyNTYifQ.eyJpc3MiOiJuZXN0LXNlY3VyaXR5LWF1dGhwcm94eSIsInN1YiI6Im5lc3RfaWQ6bmVzdC1waG9lbml4LXByb2Q6MjEyMTgxNDEiLCJwb2wiOiIzcC1vYXV0aC1zY29wZS1BUElfU0RNX1NFUlZJQ0UtY2xpZW50LTIwMjQyNzMxODczNS1qNXQ5bWMyMzZqaG85YXMycWY0dTZxY3NmYW1kaGJ0ci5hcHBzLmdvb2dsZXVzZXJjb250ZW50LmNvbSIsImV4cCI6MTYzMTI4MTU4M30.EJ_rh4-ZO96zNV67pjWPa-YVWfcawdFOV0OXGt96TFEcGRZuVBQ7Njp1kvSNMRzIGvMLWgQFvP1V29v-PFRzI0gmiA_EPE-HH3HAXvEE2osyHd6QCusIxEBKeT0DzcqgeoeO6vKbSBnHKuJepiERq6WMVfSMwBB5esnKb-4Psh3drrUT5pPIFj63F9xzx6DHy69InTSBRQ38XJ1X_okq0axeITEeNYC1uWdBJJa_FOsdWs_ZiWZhM67OlDyJB95shWr-kJPc8AYiNPaAb4ML9NAajTbsxoXL6ySztT1oGx458-ZbL6v3-TS-PPetE9VjshrsKdhuhLypBZfAmxG98A
2021-09-10 06:43:37 ERROR (MainThread) [homeassistant] Error doing job: Future exception was never retrieved
Traceback (most recent call last):
  File "/usr/local/lib/python3.9/concurrent/futures/thread.py", line 52, in run
    result = self.fn(*self.args, **self.kwargs)
TypeError: update() takes 1 positional argument but 2 were given
2021-09-10 06:46:55 ERROR (stream_worker) [libav.rtsp] method DESCRIBE failed: 404 Not Found
2021-09-10 06:46:55 ERROR (stream_worker) [homeassistant.components.stream.worker] Error opening stream rtsps://stream-uc2-delta.dropcam.com:443/sdm_live_stream/CiQA2vuxr0cz3uGK6pdk-GsmixwGlQ4I9ToMkWcbvV56BPnmuAsScQAFjsOTKzsUJlNkyY9WR6m24tCzh8uaBGheYK5uf1zJOzubLn9Xaj1xIryiaENBviH9g_u3T0X72rHGt94eqSypb31ZFgJ3YinxoxJNRZceJrz0QNo_NmpISS-CSOH-tlaSBPX7t2zYQ9fgwFinYW_Z?auth=g.0.eyJraWQiOiIyMzhiNTUxZmMyM2EyM2Y4M2E2ZTE3MmJjZTg0YmU3ZjgxMzAzMmM4IiwiYWxnIjoiUlMyNTYifQ.eyJpc3MiOiJuZXN0LXNlY3VyaXR5LWF1dGhwcm94eSIsInN1YiI6Im5lc3RfaWQ6bmVzdC1waG9lbml4LXByb2Q6MjEyMTgxNDEiLCJwb2wiOiIzcC1vYXV0aC1zY29wZS1BUElfU0RNX1NFUlZJQ0UtY2xpZW50LTIwMjQyNzMxODczNS1qNXQ5bWMyMzZqaG85YXMycWY0dTZxY3NmYW1kaGJ0ci5hcHBzLmdvb2dsZXVzZXJjb250ZW50LmNvbSIsImV4cCI6MTYzMTI4MTg1M30.G6xMnq8Lpo6NsRlMOV1XOPQpDfGl6egOWesGP1nQkKEQnZHpRnTjhzUNHeTt5E4GCfSqCbuKvMuhHpKW9vwVLR1E3f1pqz5wzeEEzL28bLSQt-GzAWZktNfHPi6mfJZcOhtGm9tH11cYPSbVFPhXVSeYGIOXCry9hACez3WrfY4E5GbO2yCZL2Lpvv7OifblgZPPNCugVV77N3JZF6k4VRrv69Rsu5b46NEg5iRgCfaVRncVtlV238WNchuxPeIPelmUDiKsggjG0R5pLNMXfBxh_iR0eonJzQdA20TgKyNi2sob8vW4i7EXJjbsDBnT8tKBcyYSqxAV7YVgZPbZSQ
2021-09-10 06:48:38 ERROR (MainThread) [homeassistant] Error doing job: Future exception was never retrieved
Traceback (most recent call last):
  File "/usr/local/lib/python3.9/concurrent/futures/thread.py", line 52, in run
    result = self.fn(*self.args, **self.kwargs)
TypeError: update() takes 1 positional argument but 2 were given
2021-09-10 06:51:36 ERROR (stream_worker) [libav.rtsp] method DESCRIBE failed: 404 Not Found
2021-09-10 06:51:36 ERROR (stream_worker) [homeassistant.components.stream.worker] Error opening stream rtsps://stream-uc2-delta.dropcam.com:443/sdm_live_stream/CiQA2vuxr0cz3uGK6pdk-GsmixwGlQ4I9ToMkWcbvV56BPnmuAsScQAFjsOTKzsUJlNkyY9WR6m24tCzh8uaBGheYK5uf1zJOzubLn9Xaj1xIryiaENBviH9g_u3T0X72rHGt94eqSypb31ZFgJ3YinxoxJNRZceJrz0QNo_NmpISS-CSOH-tlaSBPX7t2zYQ9fgwFinYW_Z?auth=g.0.eyJraWQiOiIyMzhiNTUxZmMyM2EyM2Y4M2E2ZTE3MmJjZTg0YmU3ZjgxMzAzMmM4IiwiYWxnIjoiUlMyNTYifQ.eyJpc3MiOiJuZXN0LXNlY3VyaXR5LWF1dGhwcm94eSIsInN1YiI6Im5lc3RfaWQ6bmVzdC1waG9lbml4LXByb2Q6MjEyMTgxNDEiLCJwb2wiOiIzcC1vYXV0aC1zY29wZS1BUElfU0RNX1NFUlZJQ0UtY2xpZW50LTIwMjQyNzMxODczNS1qNXQ5bWMyMzZqaG85YXMycWY0dTZxY3NmYW1kaGJ0ci5hcHBzLmdvb2dsZXVzZXJjb250ZW50LmNvbSIsImV4cCI6MTYzMTI4MjEyNH0.qvfY8700lyB90mHrzg8ECZGRoDBRDE7VBZGHhnAKbCdBOZfDqN7PV5N_rFc0S0Wt9JgcIopEsWMxinlh-BJ_HIaluiafBGvHizhmH25xZeq8o1J_lXEnr0Aj3nwMMFvVXkMustdT2Rp5Gz91T0Cf-bIDtcrBXVY3G57_prZIrDBjjPQcsxGpLZNEQ-Z3Pn7olPgdk5EVc6X1TcbkfK0MvnW337XTc-IKKTQXZxRDljIlDfsEHvmMkSeILwKzkKOGp7rzFWxJmnyLFR5wg0KiDvfceKTnn7X5vAQlxeuw-g0o4cXcZQomvtwYfTB8evX9XoMqZhX9meAzSNf13Bo1iA
2021-09-10 06:53:39 ERROR (MainThread) [homeassistant] Error doing job: Future exception was never retrieved
Traceback (most recent call last):
  File "/usr/local/lib/python3.9/concurrent/futures/thread.py", line 52, in run
    result = self.fn(*self.args, **self.kwargs)
TypeError: update() takes 1 positional argument but 2 were given
2021-09-10 06:56:35 ERROR (stream_worker) [homeassistant.components.stream.worker] Error opening stream rtsps://stream-uc2-delta.dropcam.com:443/sdm_live_stream/CiQA2vuxr0cz3uGK6pdk-GsmixwGlQ4I9ToMkWcbvV56BPnmuAsScQAFjsOTKzsUJlNkyY9WR6m24tCzh8uaBGheYK5uf1zJOzubLn9Xaj1xIryiaENBviH9g_u3T0X72rHGt94eqSypb31ZFgJ3YinxoxJNRZceJrz0QNo_NmpISS-CSOH-tlaSBPX7t2zYQ9fgwFinYW_Z?auth=g.0.eyJraWQiOiIyMzhiNTUxZmMyM2EyM2Y4M2E2ZTE3MmJjZTg0YmU3ZjgxMzAzMmM4IiwiYWxnIjoiUlMyNTYifQ.eyJpc3MiOiJuZXN0LXNlY3VyaXR5LWF1dGhwcm94eSIsInN1YiI6Im5lc3RfaWQ6bmVzdC1waG9lbml4LXByb2Q6MjEyMTgxNDEiLCJwb2wiOiIzcC1vYXV0aC1zY29wZS1BUElfU0RNX1NFUlZJQ0UtY2xpZW50LTIwMjQyNzMxODczNS1qNXQ5bWMyMzZqaG85YXMycWY0dTZxY3NmYW1kaGJ0ci5hcHBzLmdvb2dsZXVzZXJjb250ZW50LmNvbSIsImV4cCI6MTYzMTI4MjM5NH0.kybHk2Y2TReY-xeQzuK_QQYHip_rJp5wYVwMrwUYn0XU_JPSjwS8H3HfYgMTzsOZCh_xEKA1PhXXnyR9qdUaQqPR4hvfSlae_gkSh606GZeH5YXFQH9u3pBB9EdxvTvBGuawKo_UyF2pU7yLcNrz64ZSRbfyZd6NeKYdxN5RHN-irzEwNVpViVVc8_XCwV1cre-BBL1QnmOlwwyeerwLZw1bqlwrn3M6QxjR-w-FeXT5NxURadn1AF1d5Y661HrqGlWWoxHdWaeJLNTN-ZfPUvh6BSWL_v0XuSa66xvXK1JR1B3XMoweV1mKXrfSp4fg7bBdn9kgG2HiuyScK81gsw
2021-09-10 06:58:40 ERROR (MainThread) [homeassistant] Error doing job: Future exception was never retrieved
Traceback (most recent call last):
  File "/usr/local/lib/python3.9/concurrent/futures/thread.py", line 52, in run
    result = self.fn(*self.args, **self.kwargs)
TypeError: update() takes 1 positional argument but 2 were given
2021-09-10 07:03:41 ERROR (MainThread) [homeassistant] Error doing job: Future exception was never retrieved
Traceback (most recent call last):
  File "/usr/local/lib/python3.9/concurrent/futures/thread.py", line 52, in run
    result = self.fn(*self.args, **self.kwargs)
TypeError: update() takes 1 positional argument but 2 were given
2021-09-10 07:05:27 ERROR (stream_worker) [libav.rtsp] method DESCRIBE failed: 404 Not Found
2021-09-10 07:05:27 ERROR (stream_worker) [homeassistant.components.stream.worker] Error opening stream rtsps://stream-uc2-delta.dropcam.com:443/sdm_live_stream/CiQA2vuxr0cz3uGK6pdk-GsmixwGlQ4I9ToMkWcbvV56BPnmuAsScQAFjsOTKzsUJlNkyY9WR6m24tCzh8uaBGheYK5uf1zJOzubLn9Xaj1xIryiaENBviH9g_u3T0X72rHGt94eqSypb31ZFgJ3YinxoxJNRZceJrz0QNo_NmpISS-CSOH-tlaSBPX7t2zYQ9fgwFinYW_Z?auth=g.0.eyJraWQiOiIyMzhiNTUxZmMyM2EyM2Y4M2E2ZTE3MmJjZTg0YmU3ZjgxMzAzMmM4IiwiYWxnIjoiUlMyNTYifQ.eyJpc3MiOiJuZXN0LXNlY3VyaXR5LWF1dGhwcm94eSIsInN1YiI6Im5lc3RfaWQ6bmVzdC1waG9lbml4LXByb2Q6MjEyMTgxNDEiLCJwb2wiOiIzcC1vYXV0aC1zY29wZS1BUElfU0RNX1NFUlZJQ0UtY2xpZW50LTIwMjQyNzMxODczNS1qNXQ5bWMyMzZqaG85YXMycWY0dTZxY3NmYW1kaGJ0ci5hcHBzLmdvb2dsZXVzZXJjb250ZW50LmNvbSIsImV4cCI6MTYzMTI4MjkzNn0.ZOVIX3oT_CauauJh40qd9E_F86kaG9VHh8HuKq1TcGafldoViAK6cTGSrNFjClDaw2Kc4_KiADwB8p4y8cEhwRO5gl-WOL8Umuqx582JFNYR6Amuy1SQYGQJ3TPY2jl2Li3AU8qHSkdZRrOVVpIAzKdhcXF9O-IFI69KwMFm0CJJcv_7cuPBkGDAwn3pNLx5UU4GUNUJPV73Za52Nqwa_da-ROYFQEMBwXFpPejSFXWN54FCUCuczg1SWvjPGreqpCU6PubqOylnalmygTprQEnuJ4Z3NrghupLN1zuoGGDSWHk80q0K6Q_gcr7BAXAmfNY-4JOe0Nogho1fu9yyoA
2021-09-10 07:07:27 ERROR (stream_worker) [homeassistant.components.stream.worker] Error opening stream rtsps://stream-uc2-delta.dropcam.com:443/sdm_live_stream/CiQA2vuxr0cz3uGK6pdk-GsmixwGlQ4I9ToMkWcbvV56BPnmuAsScQAFjsOTKzsUJlNkyY9WR6m24tCzh8uaBGheYK5uf1zJOzubLn9Xaj1xIryiaENBviH9g_u3T0X72rHGt94eqSypb31ZFgJ3YinxoxJNRZceJrz0QNo_NmpISS-CSOH-tlaSBPX7t2zYQ9fgwFinYW_Z?auth=g.0.eyJraWQiOiIyMzhiNTUxZmMyM2EyM2Y4M2E2ZTE3MmJjZTg0YmU3ZjgxMzAzMmM4IiwiYWxnIjoiUlMyNTYifQ.eyJpc3MiOiJuZXN0LXNlY3VyaXR5LWF1dGhwcm94eSIsInN1YiI6Im5lc3RfaWQ6bmVzdC1waG9lbml4LXByb2Q6MjEyMTgxNDEiLCJwb2wiOiIzcC1vYXV0aC1zY29wZS1BUElfU0RNX1NFUlZJQ0UtY2xpZW50LTIwMjQyNzMxODczNS1qNXQ5bWMyMzZqaG85YXMycWY0dTZxY3NmYW1kaGJ0ci5hcHBzLmdvb2dsZXVzZXJjb250ZW50LmNvbSIsImV4cCI6MTYzMTI4MjkzNn0.ZOVIX3oT_CauauJh40qd9E_F86kaG9VHh8HuKq1TcGafldoViAK6cTGSrNFjClDaw2Kc4_KiADwB8p4y8cEhwRO5gl-WOL8Umuqx582JFNYR6Amuy1SQYGQJ3TPY2jl2Li3AU8qHSkdZRrOVVpIAzKdhcXF9O-IFI69KwMFm0CJJcv_7cuPBkGDAwn3pNLx5UU4GUNUJPV73Za52Nqwa_da-ROYFQEMBwXFpPejSFXWN54FCUCuczg1SWvjPGreqpCU6PubqOylnalmygTprQEnuJ4Z3NrghupLN1zuoGGDSWHk80q0K6Q_gcr7BAXAmfNY-4JOe0Nogho1fu9yyoA
2021-09-10 07:08:42 ERROR (MainThread) [homeassistant] Error doing job: Future exception was never retrieved
Traceback (most recent call last):
  File "/usr/local/lib/python3.9/concurrent/futures/thread.py", line 52, in run
    result = self.fn(*self.args, **self.kwargs)
TypeError: update() takes 1 positional argument but 2 were given
2021-09-10 07:13:43 ERROR (MainThread) [homeassistant] Error doing job: Future exception was never retrieved
Traceback (most recent call last):
  File "/usr/local/lib/python3.9/concurrent/futures/thread.py", line 52, in run
    result = self.fn(*self.args, **self.kwargs)
TypeError: update() takes 1 positional argument but 2 were given
2021-09-10 07:18:44 ERROR (MainThread) [homeassistant] Error doing job: Future exception was never retrieved
Traceback (most recent call last):
  File "/usr/local/lib/python3.9/concurrent/futures/thread.py", line 52, in run
    result = self.fn(*self.args, **self.kwargs)
TypeError: update() takes 1 positional argument but 2 were given
2021-09-10 07:23:45 ERROR (MainThread) [homeassistant] Error doing job: Future exception was never retrieved
Traceback (most recent call last):
  File "/usr/local/lib/python3.9/concurrent/futures/thread.py", line 52, in run
    result = self.fn(*self.args, **self.kwargs)
TypeError: update() takes 1 positional argument but 2 were given
2021-09-10 07:28:46 ERROR (MainThread) [homeassistant] Error doing job: Future exception was never retrieved
Traceback (most recent call last):
  File "/usr/local/lib/python3.9/concurrent/futures/thread.py", line 52, in run
    result = self.fn(*self.args, **self.kwargs)
TypeError: update() takes 1 positional argument but 2 were given
2021-09-10 07:33:47 ERROR (MainThread) [homeassistant] Error doing job: Future exception was never retrieved
Traceback (most recent call last):
  File "/usr/local/lib/python3.9/concurrent/futures/thread.py", line 52, in run
    result = self.fn(*self.args, **self.kwargs)
TypeError: update() takes 1 positional argument but 2 were given
2021-09-10 07:38:48 ERROR (MainThread) [homeassistant] Error doing job: Future exception was never retrieved
Traceback (most recent call last):
  File "/usr/local/lib/python3.9/concurrent/futures/thread.py", line 52, in run
    result = self.fn(*self.args, **self.kwargs)
TypeError: update() takes 1 positional argument but 2 were given
2021-09-10 07:43:49 ERROR (MainThread) [homeassistant] Error doing job: Future exception was never retrieved
Traceback (most recent call last):
  File "/usr/local/lib/python3.9/concurrent/futures/thread.py", line 52, in run
    result = self.fn(*self.args, **self.kwargs)
TypeError: update() takes 1 positional argument but 2 were given
2021-09-10 07:48:50 ERROR (MainThread) [homeassistant] Error doing job: Future exception was never retrieved
Traceback (most recent call last):
  File "/usr/local/lib/python3.9/concurrent/futures/thread.py", line 52, in run
    result = self.fn(*self.args, **self.kwargs)
TypeError: update() takes 1 positional argument but 2 were given
2021-09-10 07:53:51 ERROR (MainThread) [homeassistant] Error doing job: Future exception was never retrieved
Traceback (most recent call last):
  File "/usr/local/lib/python3.9/concurrent/futures/thread.py", line 52, in run
    result = self.fn(*self.args, **self.kwargs)
TypeError: update() takes 1 positional argument but 2 were given
2021-09-10 07:58:52 ERROR (MainThread) [homeassistant] Error doing job: Future exception was never retrieved
Traceback (most recent call last):
  File "/usr/local/lib/python3.9/concurrent/futures/thread.py", line 52, in run
    result = self.fn(*self.args, **self.kwargs)
TypeError: update() takes 1 positional argument but 2 were given
2021-09-10 08:00:32 ERROR (MainThread) [homeassistant.components.nws] Error requesting NWS observation station SAUC1 data: 503, message='Service Unavailable', url=URL('https://api.weather.gov/stations/SAUC1/observations')
2021-09-10 08:03:53 ERROR (MainThread) [homeassistant] Error doing job: Future exception was never retrieved
Traceback (most recent call last):
  File "/usr/local/lib/python3.9/concurrent/futures/thread.py", line 52, in run
    result = self.fn(*self.args, **self.kwargs)
TypeError: update() takes 1 positional argument but 2 were given
2021-09-10 08:07:55 WARNING (MainThread) [bellows.zigbee.application] Watchdog heartbeat timeout: 
2021-09-10 08:08:54 ERROR (MainThread) [homeassistant] Error doing job: Future exception was never retrieved
Traceback (most recent call last):
  File "/usr/local/lib/python3.9/concurrent/futures/thread.py", line 52, in run
    result = self.fn(*self.args, **self.kwargs)
TypeError: update() takes 1 positional argument but 2 were given
2021-09-10 08:13:55 ERROR (MainThread) [homeassistant] Error doing job: Future exception was never retrieved
Traceback (most recent call last):
  File "/usr/local/lib/python3.9/concurrent/futures/thread.py", line 52, in run
    result = self.fn(*self.args, **self.kwargs)
TypeError: update() takes 1 positional argument but 2 were given
2021-09-10 08:18:56 ERROR (MainThread) [homeassistant] Error doing job: Future exception was never retrieved
Traceback (most recent call last):
  File "/usr/local/lib/python3.9/concurrent/futures/thread.py", line 52, in run
    result = self.fn(*self.args, **self.kwargs)
TypeError: update() takes 1 positional argument but 2 were given
2021-09-10 08:23:57 ERROR (MainThread) [homeassistant] Error doing job: Future exception was never retrieved
Traceback (most recent call last):
  File "/usr/local/lib/python3.9/concurrent/futures/thread.py", line 52, in run
    result = self.fn(*self.args, **self.kwargs)
TypeError: update() takes 1 positional argument but 2 were given
2021-09-10 08:28:58 ERROR (MainThread) [homeassistant] Error doing job: Future exception was never retrieved
Traceback (most recent call last):
  File "/usr/local/lib/python3.9/concurrent/futures/thread.py", line 52, in run
    result = self.fn(*self.args, **self.kwargs)
TypeError: update() takes 1 positional argument but 2 were given
2021-09-10 08:33:59 ERROR (MainThread) [homeassistant] Error doing job: Future exception was never retrieved
Traceback (most recent call last):
  File "/usr/local/lib/python3.9/concurrent/futures/thread.py", line 52, in run
    result = self.fn(*self.args, **self.kwargs)
TypeError: update() takes 1 positional argument but 2 were given
2021-09-10 08:39:00 ERROR (MainThread) [homeassistant] Error doing job: Future exception was never retrieved
Traceback (most recent call last):
  File "/usr/local/lib/python3.9/concurrent/futures/thread.py", line 52, in run
    result = self.fn(*self.args, **self.kwargs)
TypeError: update() takes 1 positional argument but 2 were given
2021-09-10 08:44:01 ERROR (MainThread) [homeassistant] Error doing job: Future exception was never retrieved
Traceback (most recent call last):
  File "/usr/local/lib/python3.9/concurrent/futures/thread.py", line 52, in run
    result = self.fn(*self.args, **self.kwargs)
TypeError: update() takes 1 positional argument but 2 were given
2021-09-10 08:49:02 ERROR (MainThread) [homeassistant] Error doing job: Future exception was never retrieved
Traceback (most recent call last):
  File "/usr/local/lib/python3.9/concurrent/futures/thread.py", line 52, in run
    result = self.fn(*self.args, **self.kwargs)
TypeError: update() takes 1 positional argument but 2 were given
2021-09-10 08:54:03 ERROR (MainThread) [homeassistant] Error doing job: Future exception was never retrieved
Traceback (most recent call last):
  File "/usr/local/lib/python3.9/concurrent/futures/thread.py", line 52, in run
    result = self.fn(*self.args, **self.kwargs)
TypeError: update() takes 1 positional argument but 2 were given
2021-09-10 08:59:04 ERROR (MainThread) [homeassistant] Error doing job: Future exception was never retrieved
Traceback (most recent call last):
  File "/usr/local/lib/python3.9/concurrent/futures/thread.py", line 52, in run
    result = self.fn(*self.args, **self.kwargs)
TypeError: update() takes 1 positional argument but 2 were given
2021-09-10 09:01:55 ERROR (MainThread) [homeassistant.components.nws] Error requesting NWS observation station SAUC1 data: 503, message='Service Unavailable', url=URL('https://api.weather.gov/stations/SAUC1/observations')
2021-09-10 09:04:05 ERROR (MainThread) [homeassistant] Error doing job: Future exception was never retrieved
Traceback (most recent call last):
  File "/usr/local/lib/python3.9/concurrent/futures/thread.py", line 52, in run
    result = self.fn(*self.args, **self.kwargs)
TypeError: update() takes 1 positional argument but 2 were given
2021-09-10 09:09:06 ERROR (MainThread) [homeassistant] Error doing job: Future exception was never retrieved
Traceback (most recent call last):
  File "/usr/local/lib/python3.9/concurrent/futures/thread.py", line 52, in run
    result = self.fn(*self.args, **self.kwargs)
TypeError: update() takes 1 positional argument but 2 were given
2021-09-10 09:14:07 ERROR (MainThread) [homeassistant] Error doing job: Future exception was never retrieved
Traceback (most recent call last):
  File "/usr/local/lib/python3.9/concurrent/futures/thread.py", line 52, in run
    result = self.fn(*self.args, **self.kwargs)
TypeError: update() takes 1 positional argument but 2 were given
2021-09-10 09:16:35 ERROR (MainThread) [homeassistant.components.nws] Error requesting NWS observation station SAUC1 data: 503, message='Service Unavailable', url=URL('https://api.weather.gov/stations/SAUC1/observations')
2021-09-10 09:19:08 ERROR (MainThread) [homeassistant] Error doing job: Future exception was never retrieved
Traceback (most recent call last):
  File "/usr/local/lib/python3.9/concurrent/futures/thread.py", line 52, in run
    result = self.fn(*self.args, **self.kwargs)
TypeError: update() takes 1 positional argument but 2 were given
2021-09-10 09:24:09 ERROR (MainThread) [homeassistant] Error doing job: Future exception was never retrieved
Traceback (most recent call last):
  File "/usr/local/lib/python3.9/concurrent/futures/thread.py", line 52, in run
    result = self.fn(*self.args, **self.kwargs)
TypeError: update() takes 1 positional argument but 2 were given
2021-09-10 09:29:10 ERROR (MainThread) [homeassistant] Error doing job: Future exception was never retrieved
Traceback (most recent call last):
  File "/usr/local/lib/python3.9/concurrent/futures/thread.py", line 52, in run
    result = self.fn(*self.args, **self.kwargs)
TypeError: update() takes 1 positional argument but 2 were given
2021-09-10 09:34:11 ERROR (MainThread) [homeassistant] Error doing job: Future exception was never retrieved
Traceback (most recent call last):
  File "/usr/local/lib/python3.9/concurrent/futures/thread.py", line 52, in run
    result = self.fn(*self.args, **self.kwargs)
TypeError: update() takes 1 positional argument but 2 were given
2021-09-10 09:39:12 ERROR (MainThread) [homeassistant] Error doing job: Future exception was never retrieved
Traceback (most recent call last):
  File "/usr/local/lib/python3.9/concurrent/futures/thread.py", line 52, in run
    result = self.fn(*self.args, **self.kwargs)
TypeError: update() takes 1 positional argument but 2 were given
2021-09-10 09:44:13 ERROR (MainThread) [homeassistant] Error doing job: Future exception was never retrieved
Traceback (most recent call last):
  File "/usr/local/lib/python3.9/concurrent/futures/thread.py", line 52, in run
    result = self.fn(*self.args, **self.kwargs)
TypeError: update() takes 1 positional argument but 2 were given
2021-09-10 09:49:14 ERROR (MainThread) [homeassistant] Error doing job: Future exception was never retrieved
Traceback (most recent call last):
  File "/usr/local/lib/python3.9/concurrent/futures/thread.py", line 52, in run
    result = self.fn(*self.args, **self.kwargs)
TypeError: update() takes 1 positional argument but 2 were given
2021-09-10 09:54:15 ERROR (MainThread) [homeassistant] Error doing job: Future exception was never retrieved
Traceback (most recent call last):
  File "/usr/local/lib/python3.9/concurrent/futures/thread.py", line 52, in run
    result = self.fn(*self.args, **self.kwargs)
TypeError: update() takes 1 positional argument but 2 were given
2021-09-10 09:59:16 ERROR (MainThread) [homeassistant] Error doing job: Future exception was never retrieved
Traceback (most recent call last):
  File "/usr/local/lib/python3.9/concurrent/futures/thread.py", line 52, in run
    result = self.fn(*self.args, **self.kwargs)
TypeError: update() takes 1 positional argument but 2 were given
2021-09-10 10:01:11 ERROR (MainThread) [homeassistant.helpers.event] Error while processing state change for sensor.simexport
Traceback (most recent call last):
  File "/usr/src/homeassistant/homeassistant/helpers/event.py", line 272, in _async_state_change_dispatcher
    hass.async_run_hass_job(job, event)
  File "/usr/src/homeassistant/homeassistant/core.py", line 433, in async_run_hass_job
    hassjob.target(*args)
  File "/usr/src/homeassistant/homeassistant/components/integration/sensor.py", line 157, in calc_integration
    or new_state.state in (STATE_UNKNOWN, STATE_UNAVAILABLE)
AttributeError: 'NoneType' object has no attribute 'state'
2021-09-10 10:04:17 ERROR (MainThread) [homeassistant] Error doing job: Future exception was never retrieved
Traceback (most recent call last):
  File "/usr/local/lib/python3.9/concurrent/futures/thread.py", line 52, in run
    result = self.fn(*self.args, **self.kwargs)
TypeError: update() takes 1 positional argument but 2 were given
2021-09-10 10:09:18 ERROR (MainThread) [homeassistant] Error doing job: Future exception was never retrieved
Traceback (most recent call last):
  File "/usr/local/lib/python3.9/concurrent/futures/thread.py", line 52, in run
    result = self.fn(*self.args, **self.kwargs)
TypeError: update() takes 1 positional argument but 2 were given
2021-09-10 10:14:19 ERROR (MainThread) [homeassistant] Error doing job: Future exception was never retrieved
Traceback (most recent call last):
  File "/usr/local/lib/python3.9/concurrent/futures/thread.py", line 52, in run
    result = self.fn(*self.args, **self.kwargs)
TypeError: update() takes 1 positional argument but 2 were given
2021-09-10 10:18:11 ERROR (MainThread) [homeassistant.components.nws] Error requesting NWS observation station SAUC1 data: 503, message='Service Unavailable', url=URL('https://api.weather.gov/stations/SAUC1/observations')
2021-09-10 10:18:19 WARNING (MainThread) [bellows.zigbee.application] Watchdog heartbeat timeout: 
2021-09-10 10:18:34 WARNING (MainThread) [bellows.zigbee.application] Watchdog heartbeat timeout: 
2021-09-10 10:18:46 ERROR (bellows.thread_0) [bellows.uart] CRC error in frame b'784cb1a9112a15b658944f24ab5593499c29571340669874f4df9289fcc20251a8bd7e' (b'a8bd' != b'8c3f')
2021-09-10 10:18:46 ERROR (MainThread) [bellows.ezsp] NCP entered failed state. Requesting APP controller restart
2021-09-10 10:18:46 ERROR (MainThread) [bellows.ezsp] NCP entered failed state. Requesting APP controller restart
2021-09-10 10:19:20 ERROR (MainThread) [homeassistant] Error doing job: Future exception was never retrieved
Traceback (most recent call last):
  File "/usr/local/lib/python3.9/concurrent/futures/thread.py", line 52, in run
    result = self.fn(*self.args, **self.kwargs)
TypeError: update() takes 1 positional argument but 2 were given
2021-09-10 10:24:21 ERROR (MainThread) [homeassistant] Error doing job: Future exception was never retrieved
Traceback (most recent call last):
  File "/usr/local/lib/python3.9/concurrent/futures/thread.py", line 52, in run
    result = self.fn(*self.args, **self.kwargs)
TypeError: update() takes 1 positional argument but 2 were given
2021-09-10 10:29:22 ERROR (MainThread) [homeassistant] Error doing job: Future exception was never retrieved
Traceback (most recent call last):
  File "/usr/local/lib/python3.9/concurrent/futures/thread.py", line 52, in run
    result = self.fn(*self.args, **self.kwargs)
TypeError: update() takes 1 positional argument but 2 were given
2021-09-10 10:30:14 ERROR (MainThread) [homeassistant] Error doing job: Task was destroyed but it is pending!
2021-09-10 10:31:00 ERROR (MainThread) [iotawattpy.connection] Err: 
2021-09-10 10:31:00 ERROR (MainThread) [homeassistant.components.iotawatt.coordinator] Unexpected error fetching 192.168.20.195 data: 'NoneType' object has no attribute 'text'
Traceback (most recent call last):
  File "/usr/src/homeassistant/homeassistant/helpers/update_coordinator.py", line 187, in _async_refresh
    self.data = await self._async_update_data()
  File "/usr/src/homeassistant/homeassistant/components/iotawatt/coordinator.py", line 55, in _async_update_data
    await self.api.update()
  File "/usr/local/lib/python3.9/site-packages/iotawattpy/iotawatt.py", line 66, in update
    await self._refreshSensors(timespan)
  File "/usr/local/lib/python3.9/site-packages/iotawattpy/iotawatt.py", line 100, in _refreshSensors
    results = response.text
AttributeError: 'NoneType' object has no attribute 'text'
2021-09-10 10:34:23 ERROR (MainThread) [homeassistant] Error doing job: Future exception was never retrieved
Traceback (most recent call last):
  File "/usr/local/lib/python3.9/concurrent/futures/thread.py", line 52, in run
    result = self.fn(*self.args, **self.kwargs)
TypeError: update() takes 1 positional argument but 2 were given
2021-09-10 10:39:24 ERROR (MainThread) [homeassistant] Error doing job: Future exception was never retrieved
Traceback (most recent call last):
  File "/usr/local/lib/python3.9/concurrent/futures/thread.py", line 52, in run
    result = self.fn(*self.args, **self.kwargs)
TypeError: update() takes 1 positional argument but 2 were given
2021-09-10 10:44:25 ERROR (MainThread) [homeassistant] Error doing job: Future exception was never retrieved
Traceback (most recent call last):
  File "/usr/local/lib/python3.9/concurrent/futures/thread.py", line 52, in run
    result = self.fn(*self.args, **self.kwargs)
TypeError: update() takes 1 positional argument but 2 were given
2021-09-10 10:48:41 WARNING (MainThread) [bellows.zigbee.application] Watchdog heartbeat timeout: 
2021-09-10 10:48:56 WARNING (MainThread) [bellows.zigbee.application] Watchdog heartbeat timeout: 
2021-09-10 10:49:11 WARNING (MainThread) [bellows.zigbee.application] Watchdog heartbeat timeout: 
2021-09-10 10:49:26 ERROR (MainThread) [homeassistant] Error doing job: Future exception was never retrieved
Traceback (most recent call last):
  File "/usr/local/lib/python3.9/concurrent/futures/thread.py", line 52, in run
    result = self.fn(*self.args, **self.kwargs)
TypeError: update() takes 1 positional argument but 2 were given
2021-09-10 10:54:27 ERROR (MainThread) [homeassistant] Error doing job: Future exception was never retrieved
Traceback (most recent call last):
  File "/usr/local/lib/python3.9/concurrent/futures/thread.py", line 52, in run
    result = self.fn(*self.args, **self.kwargs)
TypeError: update() takes 1 positional argument but 2 were given
2021-09-10 10:57:25 ERROR (MainThread) [homeassistant.components.roku.coordinator] Error fetching roku data: Invalid response from API: Timeout occurred while connecting to device
2021-09-10 10:58:20 ERROR (MainThread) [homeassistant.components.roku.coordinator] Error fetching roku data: Invalid response from API: Timeout occurred while connecting to device
2021-09-10 10:59:28 ERROR (MainThread) [homeassistant] Error doing job: Future exception was never retrieved
Traceback (most recent call last):
  File "/usr/local/lib/python3.9/concurrent/futures/thread.py", line 52, in run
    result = self.fn(*self.args, **self.kwargs)
TypeError: update() takes 1 positional argument but 2 were given
2021-09-10 11:03:27 ERROR (MainThread) [homeassistant.components.roku.coordinator] Error fetching roku data: Invalid response from API: Timeout occurred while connecting to device
2021-09-10 11:04:29 ERROR (MainThread) [homeassistant] Error doing job: Future exception was never retrieved
Traceback (most recent call last):
  File "/usr/local/lib/python3.9/concurrent/futures/thread.py", line 52, in run
    result = self.fn(*self.args, **self.kwargs)
TypeError: update() takes 1 positional argument but 2 were given
2021-09-10 11:09:30 ERROR (MainThread) [homeassistant] Error doing job: Future exception was never retrieved
Traceback (most recent call last):
  File "/usr/local/lib/python3.9/concurrent/futures/thread.py", line 52, in run
    result = self.fn(*self.args, **self.kwargs)
TypeError: update() takes 1 positional argument but 2 were given
2021-09-10 11:11:27 ERROR (MainThread) [homeassistant.components.roku.coordinator] Error fetching roku data: Invalid response from API: Timeout occurred while connecting to device
2021-09-10 11:14:31 ERROR (MainThread) [homeassistant] Error doing job: Future exception was never retrieved
Traceback (most recent call last):
  File "/usr/local/lib/python3.9/concurrent/futures/thread.py", line 52, in run
    result = self.fn(*self.args, **self.kwargs)
TypeError: update() takes 1 positional argument but 2 were given
2021-09-10 11:15:54 ERROR (MainThread) [homeassistant.components.roku.coordinator] Error fetching roku data: Invalid response from API: Timeout occurred while connecting to device
2021-09-10 11:19:32 ERROR (MainThread) [homeassistant] Error doing job: Future exception was never retrieved
Traceback (most recent call last):
  File "/usr/local/lib/python3.9/concurrent/futures/thread.py", line 52, in run
    result = self.fn(*self.args, **self.kwargs)
TypeError: update() takes 1 positional argument but 2 were given
2021-09-10 11:19:43 WARNING (MainThread) [bellows.zigbee.application] Watchdog heartbeat timeout: 
2021-09-10 11:19:58 WARNING (MainThread) [bellows.zigbee.application] Watchdog heartbeat timeout: 
2021-09-10 11:20:13 WARNING (MainThread) [bellows.zigbee.application] Watchdog heartbeat timeout: 
2021-09-10 11:23:05 ERROR (MainThread) [homeassistant.components.roku.coordinator] Error fetching roku data: Invalid response from API: Timeout occurred while connecting to device
2021-09-10 11:24:33 ERROR (MainThread) [homeassistant] Error doing job: Future exception was never retrieved
Traceback (most recent call last):
  File "/usr/local/lib/python3.9/concurrent/futures/thread.py", line 52, in run
    result = self.fn(*self.args, **self.kwargs)
TypeError: update() takes 1 positional argument but 2 were given
2021-09-10 11:29:34 ERROR (MainThread) [homeassistant] Error doing job: Future exception was never retrieved
Traceback (most recent call last):
  File "/usr/local/lib/python3.9/concurrent/futures/thread.py", line 52, in run
    result = self.fn(*self.args, **self.kwargs)
TypeError: update() takes 1 positional argument but 2 were given
2021-09-10 11:34:35 ERROR (MainThread) [homeassistant] Error doing job: Future exception was never retrieved
Traceback (most recent call last):
  File "/usr/local/lib/python3.9/concurrent/futures/thread.py", line 52, in run
    result = self.fn(*self.args, **self.kwargs)
TypeError: update() takes 1 positional argument but 2 were given
2021-09-10 11:39:36 ERROR (MainThread) [homeassistant] Error doing job: Future exception was never retrieved
Traceback (most recent call last):
  File "/usr/local/lib/python3.9/concurrent/futures/thread.py", line 52, in run
    result = self.fn(*self.args, **self.kwargs)
TypeError: update() takes 1 positional argument but 2 were given
2021-09-10 11:44:37 ERROR (MainThread) [homeassistant] Error doing job: Future exception was never retrieved
Traceback (most recent call last):
  File "/usr/local/lib/python3.9/concurrent/futures/thread.py", line 52, in run
    result = self.fn(*self.args, **self.kwargs)
TypeError: update() takes 1 positional argument but 2 were given
2021-09-10 11:49:38 ERROR (MainThread) [homeassistant] Error doing job: Future exception was never retrieved
Traceback (most recent call last):
  File "/usr/local/lib/python3.9/concurrent/futures/thread.py", line 52, in run
    result = self.fn(*self.args, **self.kwargs)
TypeError: update() takes 1 positional argument but 2 were given
2021-09-10 11:50:23 ERROR (MainThread) [iotawattpy.connection] Err: 
2021-09-10 11:50:23 ERROR (MainThread) [homeassistant.components.iotawatt.coordinator] Unexpected error fetching 192.168.20.195 data: 'NoneType' object has no attribute 'text'
Traceback (most recent call last):
  File "/usr/src/homeassistant/homeassistant/helpers/update_coordinator.py", line 187, in _async_refresh
    self.data = await self._async_update_data()
  File "/usr/src/homeassistant/homeassistant/components/iotawatt/coordinator.py", line 55, in _async_update_data
    await self.api.update()
  File "/usr/local/lib/python3.9/site-packages/iotawattpy/iotawatt.py", line 66, in update
    await self._refreshSensors(timespan)
  File "/usr/local/lib/python3.9/site-packages/iotawattpy/iotawatt.py", line 107, in _refreshSensors
    query = query.text
AttributeError: 'NoneType' object has no attribute 'text'
2021-09-10 11:54:39 ERROR (MainThread) [homeassistant] Error doing job: Future exception was never retrieved
Traceback (most recent call last):
  File "/usr/local/lib/python3.9/concurrent/futures/thread.py", line 52, in run
    result = self.fn(*self.args, **self.kwargs)
TypeError: update() takes 1 positional argument but 2 were given
2021-09-10 11:56:58 ERROR (MainThread) [iotawattpy.connection] Err: 
2021-09-10 11:56:58 ERROR (MainThread) [homeassistant.components.iotawatt.coordinator] Unexpected error fetching 192.168.20.195 data: 'NoneType' object has no attribute 'text'
Traceback (most recent call last):
  File "/usr/src/homeassistant/homeassistant/helpers/update_coordinator.py", line 187, in _async_refresh
    self.data = await self._async_update_data()
  File "/usr/src/homeassistant/homeassistant/components/iotawatt/coordinator.py", line 55, in _async_update_data
    await self.api.update()
  File "/usr/local/lib/python3.9/site-packages/iotawattpy/iotawatt.py", line 66, in update
    await self._refreshSensors(timespan)
  File "/usr/local/lib/python3.9/site-packages/iotawattpy/iotawatt.py", line 100, in _refreshSensors
    results = response.text
AttributeError: 'NoneType' object has no attribute 'text'
2021-09-10 11:59:40 ERROR (MainThread) [homeassistant] Error doing job: Future exception was never retrieved
Traceback (most recent call last):
  File "/usr/local/lib/python3.9/concurrent/futures/thread.py", line 52, in run
    result = self.fn(*self.args, **self.kwargs)
TypeError: update() takes 1 positional argument but 2 were given
2021-09-10 12:04:41 ERROR (MainThread) [homeassistant] Error doing job: Future exception was never retrieved
Traceback (most recent call last):
  File "/usr/local/lib/python3.9/concurrent/futures/thread.py", line 52, in run
    result = self.fn(*self.args, **self.kwargs)
TypeError: update() takes 1 positional argument but 2 were given
2021-09-10 12:08:15 WARNING (Thread-15) [pychromecast.socket_client] [Office_Brian speaker(192.168.20.247):8009] Heartbeat timeout, resetting connection
2021-09-10 12:08:25 ERROR (Thread-15) [pychromecast.socket_client] [Office_Brian speaker(192.168.20.247):8009] Failed to connect to service ServiceInfo(type='host', data=('192.168.20.247', 8009)), retrying in 5.0s
2021-09-10 12:09:42 ERROR (MainThread) [homeassistant] Error doing job: Future exception was never retrieved
Traceback (most recent call last):
  File "/usr/local/lib/python3.9/concurrent/futures/thread.py", line 52, in run
    result = self.fn(*self.args, **self.kwargs)
TypeError: update() takes 1 positional argument but 2 were given
2021-09-10 12:13:12 WARNING (Thread-15) [pychromecast.socket_client] [Office_Brian speaker(192.168.20.247):8009] Heartbeat timeout, resetting connection
2021-09-10 12:13:18 ERROR (Thread-15) [pychromecast.socket_client] [Office_Brian speaker(192.168.20.247):8009] Failed to connect to service ServiceInfo(type='host', data=('192.168.20.247', 8009)), retrying in 5.0s
2021-09-10 12:14:16 WARNING (Thread-15) [pychromecast.socket_client] [Office_Brian speaker(192.168.20.247):8009] Heartbeat timeout, resetting connection
2021-09-10 12:14:19 ERROR (Thread-15) [pychromecast.socket_client] [Office_Brian speaker(192.168.20.247):8009] Failed to connect to service ServiceInfo(type='host', data=('192.168.20.247', 8009)), retrying in 5.0s
2021-09-10 12:14:43 ERROR (MainThread) [homeassistant] Error doing job: Future exception was never retrieved
Traceback (most recent call last):
  File "/usr/local/lib/python3.9/concurrent/futures/thread.py", line 52, in run
    result = self.fn(*self.args, **self.kwargs)
TypeError: update() takes 1 positional argument but 2 were given
2021-09-10 12:16:42 WARNING (MainThread) [bellows.zigbee.application] Watchdog heartbeat timeout: 
2021-09-10 12:16:57 WARNING (MainThread) [bellows.zigbee.application] Watchdog heartbeat timeout: 
2021-09-10 12:17:12 WARNING (MainThread) [bellows.zigbee.application] Watchdog heartbeat timeout: 
2021-09-10 12:17:27 WARNING (MainThread) [bellows.zigbee.application] Watchdog heartbeat timeout: 
2021-09-10 12:17:42 WARNING (MainThread) [bellows.zigbee.application] Watchdog heartbeat timeout: 
2021-09-10 12:19:44 ERROR (MainThread) [homeassistant] Error doing job: Future exception was never retrieved
Traceback (most recent call last):
  File "/usr/local/lib/python3.9/concurrent/futures/thread.py", line 52, in run
    result = self.fn(*self.args, **self.kwargs)
TypeError: update() takes 1 positional argument but 2 were given
2021-09-10 12:23:59 ERROR (SyncWorker_18) [homeassistant] Error doing job: Task was destroyed but it is pending!
2021-09-10 12:24:23 WARNING (MainThread) [bellows.zigbee.application] Watchdog heartbeat timeout: 
2021-09-10 12:24:45 ERROR (MainThread) [homeassistant] Error doing job: Future exception was never retrieved
Traceback (most recent call last):
  File "/usr/local/lib/python3.9/concurrent/futures/thread.py", line 52, in run
    result = self.fn(*self.args, **self.kwargs)
TypeError: update() takes 1 positional argument but 2 were given
2021-09-10 12:29:46 ERROR (MainThread) [homeassistant] Error doing job: Future exception was never retrieved
Traceback (most recent call last):
  File "/usr/local/lib/python3.9/concurrent/futures/thread.py", line 52, in run
    result = self.fn(*self.args, **self.kwargs)
TypeError: update() takes 1 positional argument but 2 were given
2021-09-10 12:34:00 ERROR (MainThread) [homeassistant.components.roku.coordinator] Error fetching roku data: Invalid response from API: Timeout occurred while connecting to device
2021-09-10 12:34:10 ERROR (MainThread) [iotawattpy.connection] Err: 
2021-09-10 12:34:10 ERROR (MainThread) [homeassistant.components.iotawatt.coordinator] Unexpected error fetching 192.168.20.195 data: 'NoneType' object has no attribute 'text'
Traceback (most recent call last):
  File "/usr/src/homeassistant/homeassistant/helpers/update_coordinator.py", line 187, in _async_refresh
    self.data = await self._async_update_data()
  File "/usr/src/homeassistant/homeassistant/components/iotawatt/coordinator.py", line 55, in _async_update_data
    await self.api.update()
  File "/usr/local/lib/python3.9/site-packages/iotawattpy/iotawatt.py", line 66, in update
    await self._refreshSensors(timespan)
  File "/usr/local/lib/python3.9/site-packages/iotawattpy/iotawatt.py", line 100, in _refreshSensors
    results = response.text
AttributeError: 'NoneType' object has no attribute 'text'
2021-09-10 12:34:47 ERROR (MainThread) [homeassistant] Error doing job: Future exception was never retrieved
Traceback (most recent call last):
  File "/usr/local/lib/python3.9/concurrent/futures/thread.py", line 52, in run
    result = self.fn(*self.args, **self.kwargs)
TypeError: update() takes 1 positional argument but 2 were given
2021-09-10 12:39:48 ERROR (MainThread) [homeassistant] Error doing job: Future exception was never retrieved
Traceback (most recent call last):
  File "/usr/local/lib/python3.9/concurrent/futures/thread.py", line 52, in run
    result = self.fn(*self.args, **self.kwargs)
TypeError: update() takes 1 positional argument but 2 were given
2021-09-10 12:44:49 ERROR (MainThread) [homeassistant] Error doing job: Future exception was never retrieved
Traceback (most recent call last):
  File "/usr/local/lib/python3.9/concurrent/futures/thread.py", line 52, in run
    result = self.fn(*self.args, **self.kwargs)
TypeError: update() takes 1 positional argument but 2 were given
2021-09-10 12:48:02 ERROR (MainThread) [homeassistant.components.roku.coordinator] Error fetching roku data: Invalid response from API: Timeout occurred while connecting to device
2021-09-10 12:49:22 ERROR (MainThread) [homeassistant.components.roku.coordinator] Error fetching roku data: Invalid response from API: Timeout occurred while connecting to device
2021-09-10 12:49:50 ERROR (MainThread) [homeassistant] Error doing job: Future exception was never retrieved
Traceback (most recent call last):
  File "/usr/local/lib/python3.9/concurrent/futures/thread.py", line 52, in run
    result = self.fn(*self.args, **self.kwargs)
TypeError: update() takes 1 positional argument but 2 were given
2021-09-10 12:53:13 ERROR (MainThread) [homeassistant.components.roku.coordinator] Error fetching roku data: Invalid response from API: Timeout occurred while connecting to device
2021-09-10 12:54:51 ERROR (MainThread) [homeassistant] Error doing job: Future exception was never retrieved
Traceback (most recent call last):
  File "/usr/local/lib/python3.9/concurrent/futures/thread.py", line 52, in run
    result = self.fn(*self.args, **self.kwargs)
TypeError: update() takes 1 positional argument but 2 were given
2021-09-10 12:59:52 ERROR (MainThread) [homeassistant] Error doing job: Future exception was never retrieved
Traceback (most recent call last):
  File "/usr/local/lib/python3.9/concurrent/futures/thread.py", line 52, in run
    result = self.fn(*self.args, **self.kwargs)
TypeError: update() takes 1 positional argument but 2 were given
2021-09-10 13:04:53 ERROR (MainThread) [homeassistant] Error doing job: Future exception was never retrieved
Traceback (most recent call last):
  File "/usr/local/lib/python3.9/concurrent/futures/thread.py", line 52, in run
    result = self.fn(*self.args, **self.kwargs)
TypeError: update() takes 1 positional argument but 2 were given
2021-09-10 13:09:54 ERROR (MainThread) [homeassistant] Error doing job: Future exception was never retrieved
Traceback (most recent call last):
  File "/usr/local/lib/python3.9/concurrent/futures/thread.py", line 52, in run
    result = self.fn(*self.args, **self.kwargs)
TypeError: update() takes 1 positional argument but 2 were given
2021-09-10 13:10:27 ERROR (MainThread) [homeassistant.components.nws] Error requesting NWS observation station SAUC1 data: 503, message='Service Unavailable', url=URL('https://api.weather.gov/stations/SAUC1/observations')
2021-09-10 13:14:55 ERROR (MainThread) [homeassistant] Error doing job: Future exception was never retrieved
Traceback (most recent call last):
  File "/usr/local/lib/python3.9/concurrent/futures/thread.py", line 52, in run
    result = self.fn(*self.args, **self.kwargs)
TypeError: update() takes 1 positional argument but 2 were given
2021-09-10 13:15:30 ERROR (MainThread) [homeassistant] Error doing job: Task exception was never retrieved
Traceback (most recent call last):
  File "/usr/local/lib/python3.9/site-packages/zigpy/device.py", line 287, in request
    raise zigpy.exceptions.DeliveryError(
zigpy.exceptions.DeliveryError: [0xa8ad:1:0x0500]: Message send failure
2021-09-10 13:19:56 ERROR (MainThread) [homeassistant] Error doing job: Future exception was never retrieved
Traceback (most recent call last):
  File "/usr/local/lib/python3.9/concurrent/futures/thread.py", line 52, in run
    result = self.fn(*self.args, **self.kwargs)
TypeError: update() takes 1 positional argument but 2 were given
2021-09-10 13:24:57 ERROR (MainThread) [homeassistant] Error doing job: Future exception was never retrieved
Traceback (most recent call last):
  File "/usr/local/lib/python3.9/concurrent/futures/thread.py", line 52, in run
    result = self.fn(*self.args, **self.kwargs)
TypeError: update() takes 1 positional argument but 2 were given
2021-09-10 13:29:58 ERROR (MainThread) [homeassistant] Error doing job: Future exception was never retrieved
Traceback (most recent call last):
  File "/usr/local/lib/python3.9/concurrent/futures/thread.py", line 52, in run
    result = self.fn(*self.args, **self.kwargs)
TypeError: update() takes 1 positional argument but 2 were given
2021-09-10 13:34:59 ERROR (MainThread) [homeassistant] Error doing job: Future exception was never retrieved
Traceback (most recent call last):
  File "/usr/local/lib/python3.9/concurrent/futures/thread.py", line 52, in run
    result = self.fn(*self.args, **self.kwargs)
TypeError: update() takes 1 positional argument but 2 were given
2021-09-10 13:40:00 ERROR (MainThread) [homeassistant] Error doing job: Future exception was never retrieved
Traceback (most recent call last):
  File "/usr/local/lib/python3.9/concurrent/futures/thread.py", line 52, in run
    result = self.fn(*self.args, **self.kwargs)
TypeError: update() takes 1 positional argument but 2 were given
2021-09-10 13:45:01 ERROR (MainThread) [homeassistant] Error doing job: Future exception was never retrieved
Traceback (most recent call last):
  File "/usr/local/lib/python3.9/concurrent/futures/thread.py", line 52, in run
    result = self.fn(*self.args, **self.kwargs)
TypeError: update() takes 1 positional argument but 2 were given
2021-09-10 13:45:27 ERROR (MainThread) [iotawattpy.connection] Err: 
2021-09-10 13:45:27 ERROR (MainThread) [homeassistant.components.iotawatt.coordinator] Unexpected error fetching 192.168.20.195 data: 'NoneType' object has no attribute 'text'
Traceback (most recent call last):
  File "/usr/src/homeassistant/homeassistant/helpers/update_coordinator.py", line 187, in _async_refresh
    self.data = await self._async_update_data()
  File "/usr/src/homeassistant/homeassistant/components/iotawatt/coordinator.py", line 55, in _async_update_data
    await self.api.update()
  File "/usr/local/lib/python3.9/site-packages/iotawattpy/iotawatt.py", line 66, in update
    await self._refreshSensors(timespan)
  File "/usr/local/lib/python3.9/site-packages/iotawattpy/iotawatt.py", line 107, in _refreshSensors
    query = query.text
AttributeError: 'NoneType' object has no attribute 'text'
2021-09-10 13:47:04 ERROR (MainThread) [homeassistant.components.roku.coordinator] Error fetching roku data: Invalid response from API: Timeout occurred while connecting to device
2021-09-10 13:50:02 ERROR (MainThread) [homeassistant] Error doing job: Future exception was never retrieved
Traceback (most recent call last):
  File "/usr/local/lib/python3.9/concurrent/futures/thread.py", line 52, in run
    result = self.fn(*self.args, **self.kwargs)
TypeError: update() takes 1 positional argument but 2 were given
2021-09-10 13:55:03 ERROR (MainThread) [homeassistant] Error doing job: Future exception was never retrieved
Traceback (most recent call last):
  File "/usr/local/lib/python3.9/concurrent/futures/thread.py", line 52, in run
    result = self.fn(*self.args, **self.kwargs)
TypeError: update() takes 1 positional argument but 2 were given
2021-09-10 14:00:04 ERROR (MainThread) [homeassistant] Error doing job: Future exception was never retrieved
Traceback (most recent call last):
  File "/usr/local/lib/python3.9/concurrent/futures/thread.py", line 52, in run
    result = self.fn(*self.args, **self.kwargs)
TypeError: update() takes 1 positional argument but 2 were given
2021-09-10 14:05:05 ERROR (MainThread) [homeassistant] Error doing job: Future exception was never retrieved
Traceback (most recent call last):
  File "/usr/local/lib/python3.9/concurrent/futures/thread.py", line 52, in run
    result = self.fn(*self.args, **self.kwargs)
TypeError: update() takes 1 positional argument but 2 were given
2021-09-10 14:10:06 ERROR (MainThread) [homeassistant] Error doing job: Future exception was never retrieved
Traceback (most recent call last):
  File "/usr/local/lib/python3.9/concurrent/futures/thread.py", line 52, in run
    result = self.fn(*self.args, **self.kwargs)
TypeError: update() takes 1 positional argument but 2 were given
2021-09-10 14:15:07 ERROR (MainThread) [homeassistant] Error doing job: Future exception was never retrieved
Traceback (most recent call last):
  File "/usr/local/lib/python3.9/concurrent/futures/thread.py", line 52, in run
    result = self.fn(*self.args, **self.kwargs)
TypeError: update() takes 1 positional argument but 2 were given
2021-09-10 14:20:08 ERROR (MainThread) [homeassistant] Error doing job: Future exception was never retrieved
Traceback (most recent call last):
  File "/usr/local/lib/python3.9/concurrent/futures/thread.py", line 52, in run
    result = self.fn(*self.args, **self.kwargs)
TypeError: update() takes 1 positional argument but 2 were given
2021-09-10 14:25:09 ERROR (MainThread) [homeassistant] Error doing job: Future exception was never retrieved
Traceback (most recent call last):
  File "/usr/local/lib/python3.9/concurrent/futures/thread.py", line 52, in run
    result = self.fn(*self.args, **self.kwargs)
TypeError: update() takes 1 positional argument but 2 were given
2021-09-10 14:30:10 ERROR (MainThread) [homeassistant] Error doing job: Future exception was never retrieved
Traceback (most recent call last):
  File "/usr/local/lib/python3.9/concurrent/futures/thread.py", line 52, in run
    result = self.fn(*self.args, **self.kwargs)
TypeError: update() takes 1 positional argument but 2 were given
2021-09-10 14:32:48 ERROR (MainThread) [iotawattpy.connection] Err: 
2021-09-10 14:32:48 ERROR (MainThread) [homeassistant.components.iotawatt.coordinator] Unexpected error fetching 192.168.20.195 data: 'NoneType' object has no attribute 'text'
Traceback (most recent call last):
  File "/usr/src/homeassistant/homeassistant/helpers/update_coordinator.py", line 187, in _async_refresh
    self.data = await self._async_update_data()
  File "/usr/src/homeassistant/homeassistant/components/iotawatt/coordinator.py", line 55, in _async_update_data
    await self.api.update()
  File "/usr/local/lib/python3.9/site-packages/iotawattpy/iotawatt.py", line 66, in update
    await self._refreshSensors(timespan)
  File "/usr/local/lib/python3.9/site-packages/iotawattpy/iotawatt.py", line 100, in _refreshSensors
    results = response.text
AttributeError: 'NoneType' object has no attribute 'text'
2021-09-10 14:33:58 WARNING (MainThread) [bellows.zigbee.application] Watchdog heartbeat timeout: 
2021-09-10 14:34:13 WARNING (MainThread) [bellows.zigbee.application] Watchdog heartbeat timeout: 
2021-09-10 14:35:11 ERROR (MainThread) [homeassistant] Error doing job: Future exception was never retrieved
Traceback (most recent call last):
  File "/usr/local/lib/python3.9/concurrent/futures/thread.py", line 52, in run
    result = self.fn(*self.args, **self.kwargs)
TypeError: update() takes 1 positional argument but 2 were given
2021-09-10 14:40:12 ERROR (MainThread) [homeassistant] Error doing job: Future exception was never retrieved
Traceback (most recent call last):
  File "/usr/local/lib/python3.9/concurrent/futures/thread.py", line 52, in run
    result = self.fn(*self.args, **self.kwargs)
TypeError: update() takes 1 positional argument but 2 were given
2021-09-10 14:42:33 WARNING (MainThread) [bellows.zigbee.application] Watchdog heartbeat timeout: 
2021-09-10 14:42:41 ERROR (bellows.thread_0) [bellows.uart] CRC error in frame b'6aeaa1a9a52a52b2df946125a15590499c4e27abedce6f8bfec66389fc7e3fa7ebcdde6f8fffc7dbd5d2698c4623a9ec763ba5ea758241984c2613b1e070381c0e07bbe5ca658a459a4d9e4f9ff7c3d9d46a35a25190486aeaa1a9a52a52b2df946125a15590499c4e27abedce6f8bfec66389fc7e3fa7ebcdde6f8fffc7dbd5d2698c4623a9ec763ba5ea758241984c2613b1e070381c0e07bbe5ca658a459a4d9e4f9ff7c3d9d46a35a251904824bec57e' (b'bec5' != b'2bd2')
2021-09-10 14:42:41 ERROR (MainThread) [bellows.ezsp] NCP entered failed state. Requesting APP controller restart
2021-09-10 14:45:13 ERROR (MainThread) [homeassistant] Error doing job: Future exception was never retrieved
Traceback (most recent call last):
  File "/usr/local/lib/python3.9/concurrent/futures/thread.py", line 52, in run
    result = self.fn(*self.args, **self.kwargs)
TypeError: update() takes 1 positional argument but 2 were given
2021-09-10 14:46:02 ERROR (MainThread) [iotawattpy.connection] Err: 
2021-09-10 14:46:02 ERROR (MainThread) [homeassistant.components.iotawatt.coordinator] Unexpected error fetching 192.168.20.195 data: 'NoneType' object has no attribute 'text'
Traceback (most recent call last):
  File "/usr/src/homeassistant/homeassistant/helpers/update_coordinator.py", line 187, in _async_refresh
    self.data = await self._async_update_data()
  File "/usr/src/homeassistant/homeassistant/components/iotawatt/coordinator.py", line 55, in _async_update_data
    await self.api.update()
  File "/usr/local/lib/python3.9/site-packages/iotawattpy/iotawatt.py", line 66, in update
    await self._refreshSensors(timespan)
  File "/usr/local/lib/python3.9/site-packages/iotawattpy/iotawatt.py", line 100, in _refreshSensors
    results = response.text
AttributeError: 'NoneType' object has no attribute 'text'
2021-09-10 14:46:37 ERROR (MainThread) [iotawattpy.connection] Err: 
2021-09-10 14:46:37 ERROR (MainThread) [homeassistant.components.iotawatt.coordinator] Unexpected error fetching 192.168.20.195 data: 'NoneType' object has no attribute 'text'
Traceback (most recent call last):
  File "/usr/src/homeassistant/homeassistant/helpers/update_coordinator.py", line 187, in _async_refresh
    self.data = await self._async_update_data()
  File "/usr/src/homeassistant/homeassistant/components/iotawatt/coordinator.py", line 55, in _async_update_data
    await self.api.update()
  File "/usr/local/lib/python3.9/site-packages/iotawattpy/iotawatt.py", line 66, in update
    await self._refreshSensors(timespan)
  File "/usr/local/lib/python3.9/site-packages/iotawattpy/iotawatt.py", line 100, in _refreshSensors
    results = response.text
AttributeError: 'NoneType' object has no attribute 'text'
2021-09-10 14:47:12 ERROR (MainThread) [iotawattpy.connection] Err: 
2021-09-10 14:47:12 ERROR (MainThread) [homeassistant.components.iotawatt.coordinator] Unexpected error fetching 192.168.20.195 data: 'NoneType' object has no attribute 'text'
Traceback (most recent call last):
  File "/usr/src/homeassistant/homeassistant/helpers/update_coordinator.py", line 187, in _async_refresh
    self.data = await self._async_update_data()
  File "/usr/src/homeassistant/homeassistant/components/iotawatt/coordinator.py", line 55, in _async_update_data
    await self.api.update()
  File "/usr/local/lib/python3.9/site-packages/iotawattpy/iotawatt.py", line 66, in update
    await self._refreshSensors(timespan)
  File "/usr/local/lib/python3.9/site-packages/iotawattpy/iotawatt.py", line 100, in _refreshSensors
    results = response.text
AttributeError: 'NoneType' object has no attribute 'text'
2021-09-10 14:48:02 ERROR (MainThread) [homeassistant] Error doing job: Task was destroyed but it is pending!
2021-09-10 14:50:14 ERROR (MainThread) [homeassistant] Error doing job: Future exception was never retrieved
Traceback (most recent call last):
  File "/usr/local/lib/python3.9/concurrent/futures/thread.py", line 52, in run
    result = self.fn(*self.args, **self.kwargs)
TypeError: update() takes 1 positional argument but 2 were given
2021-09-10 14:55:15 ERROR (MainThread) [homeassistant] Error doing job: Future exception was never retrieved
Traceback (most recent call last):
  File "/usr/local/lib/python3.9/concurrent/futures/thread.py", line 52, in run
    result = self.fn(*self.args, **self.kwargs)
TypeError: update() takes 1 positional argument but 2 were given
2021-09-10 15:00:16 ERROR (MainThread) [homeassistant] Error doing job: Future exception was never retrieved
Traceback (most recent call last):
  File "/usr/local/lib/python3.9/concurrent/futures/thread.py", line 52, in run
    result = self.fn(*self.args, **self.kwargs)
TypeError: update() takes 1 positional argument but 2 were given
2021-09-10 15:05:17 ERROR (MainThread) [homeassistant] Error doing job: Future exception was never retrieved
Traceback (most recent call last):
  File "/usr/local/lib/python3.9/concurrent/futures/thread.py", line 52, in run
    result = self.fn(*self.args, **self.kwargs)
TypeError: update() takes 1 positional argument but 2 were given
2021-09-10 15:10:18 ERROR (MainThread) [homeassistant] Error doing job: Future exception was never retrieved
Traceback (most recent call last):
  File "/usr/local/lib/python3.9/concurrent/futures/thread.py", line 52, in run
    result = self.fn(*self.args, **self.kwargs)
TypeError: update() takes 1 positional argument but 2 were given
2021-09-10 15:15:19 ERROR (MainThread) [homeassistant] Error doing job: Future exception was never retrieved
Traceback (most recent call last):
  File "/usr/local/lib/python3.9/concurrent/futures/thread.py", line 52, in run
    result = self.fn(*self.args, **self.kwargs)
TypeError: update() takes 1 positional argument but 2 were given
2021-09-10 15:18:06 ERROR (MainThread) [homeassistant.components.forecast_solar] Unexpected error fetching forecast_solar data: The Forecast.Solar API is unreachable, 
Traceback (most recent call last):
  File "/usr/src/homeassistant/homeassistant/helpers/update_coordinator.py", line 187, in _async_refresh
    self.data = await self._async_update_data()
  File "/usr/src/homeassistant/homeassistant/helpers/update_coordinator.py", line 147, in _async_update_data
    return await self.update_method()
  File "/usr/local/lib/python3.9/site-packages/forecast_solar/__init__.py", line 138, in estimate
    data = await self._request(
  File "/usr/local/lib/python3.9/site-packages/forecast_solar/__init__.py", line 105, in _request
    raise ForecastSolarConnectionError(
forecast_solar.exceptions.ForecastSolarConnectionError: The Forecast.Solar API is unreachable, 
2021-09-10 15:20:20 ERROR (MainThread) [homeassistant] Error doing job: Future exception was never retrieved
Traceback (most recent call last):
  File "/usr/local/lib/python3.9/concurrent/futures/thread.py", line 52, in run
    result = self.fn(*self.args, **self.kwargs)
TypeError: update() takes 1 positional argument but 2 were given
2021-09-10 15:25:21 ERROR (MainThread) [homeassistant] Error doing job: Future exception was never retrieved
Traceback (most recent call last):
  File "/usr/local/lib/python3.9/concurrent/futures/thread.py", line 52, in run
    result = self.fn(*self.args, **self.kwargs)
TypeError: update() takes 1 positional argument but 2 were given
2021-09-10 15:30:22 ERROR (MainThread) [homeassistant] Error doing job: Future exception was never retrieved
Traceback (most recent call last):
  File "/usr/local/lib/python3.9/concurrent/futures/thread.py", line 52, in run
    result = self.fn(*self.args, **self.kwargs)
TypeError: update() takes 1 positional argument but 2 were given
2021-09-10 15:35:23 ERROR (MainThread) [homeassistant] Error doing job: Future exception was never retrieved
Traceback (most recent call last):
  File "/usr/local/lib/python3.9/concurrent/futures/thread.py", line 52, in run
    result = self.fn(*self.args, **self.kwargs)
TypeError: update() takes 1 positional argument but 2 were given
2021-09-10 15:40:24 ERROR (MainThread) [homeassistant] Error doing job: Future exception was never retrieved
Traceback (most recent call last):
  File "/usr/local/lib/python3.9/concurrent/futures/thread.py", line 52, in run
    result = self.fn(*self.args, **self.kwargs)
TypeError: update() takes 1 positional argument but 2 were given
2021-09-10 15:45:25 ERROR (MainThread) [homeassistant] Error doing job: Future exception was never retrieved
Traceback (most recent call last):
  File "/usr/local/lib/python3.9/concurrent/futures/thread.py", line 52, in run
    result = self.fn(*self.args, **self.kwargs)
TypeError: update() takes 1 positional argument but 2 were given
2021-09-10 15:50:26 ERROR (MainThread) [homeassistant] Error doing job: Future exception was never retrieved
Traceback (most recent call last):
  File "/usr/local/lib/python3.9/concurrent/futures/thread.py", line 52, in run
    result = self.fn(*self.args, **self.kwargs)
TypeError: update() takes 1 positional argument but 2 were given
2021-09-10 15:55:27 ERROR (MainThread) [homeassistant] Error doing job: Future exception was never retrieved
Traceback (most recent call last):
  File "/usr/local/lib/python3.9/concurrent/futures/thread.py", line 52, in run
    result = self.fn(*self.args, **self.kwargs)
TypeError: update() takes 1 positional argument but 2 were given
2021-09-10 16:00:28 ERROR (MainThread) [homeassistant] Error doing job: Future exception was never retrieved
Traceback (most recent call last):
  File "/usr/local/lib/python3.9/concurrent/futures/thread.py", line 52, in run
    result = self.fn(*self.args, **self.kwargs)
TypeError: update() takes 1 positional argument but 2 were given
2021-09-10 16:02:27 ERROR (MainThread) [homeassistant.components.nws] Error requesting NWS observation station SAUC1 data: 503, message='Service Unavailable', url=URL('https://api.weather.gov/stations/SAUC1/observations')
2021-09-10 16:05:29 ERROR (MainThread) [homeassistant] Error doing job: Future exception was never retrieved
Traceback (most recent call last):
  File "/usr/local/lib/python3.9/concurrent/futures/thread.py", line 52, in run
    result = self.fn(*self.args, **self.kwargs)
TypeError: update() takes 1 positional argument but 2 were given
2021-09-10 16:10:30 ERROR (MainThread) [homeassistant] Error doing job: Future exception was never retrieved
Traceback (most recent call last):
  File "/usr/local/lib/python3.9/concurrent/futures/thread.py", line 52, in run
    result = self.fn(*self.args, **self.kwargs)
TypeError: update() takes 1 positional argument but 2 were given
2021-09-10 16:15:31 ERROR (MainThread) [homeassistant] Error doing job: Future exception was never retrieved
Traceback (most recent call last):
  File "/usr/local/lib/python3.9/concurrent/futures/thread.py", line 52, in run
    result = self.fn(*self.args, **self.kwargs)
TypeError: update() takes 1 positional argument but 2 were given
2021-09-10 16:20:32 ERROR (MainThread) [homeassistant] Error doing job: Future exception was never retrieved
Traceback (most recent call last):
  File "/usr/local/lib/python3.9/concurrent/futures/thread.py", line 52, in run
    result = self.fn(*self.args, **self.kwargs)
TypeError: update() takes 1 positional argument but 2 were given
2021-09-10 16:25:33 ERROR (MainThread) [homeassistant] Error doing job: Future exception was never retrieved
Traceback (most recent call last):
  File "/usr/local/lib/python3.9/concurrent/futures/thread.py", line 52, in run
    result = self.fn(*self.args, **self.kwargs)
TypeError: update() takes 1 positional argument but 2 were given
2021-09-10 16:30:34 ERROR (MainThread) [homeassistant] Error doing job: Future exception was never retrieved
Traceback (most recent call last):
  File "/usr/local/lib/python3.9/concurrent/futures/thread.py", line 52, in run
    result = self.fn(*self.args, **self.kwargs)
TypeError: update() takes 1 positional argument but 2 were given
2021-09-10 16:35:35 ERROR (MainThread) [homeassistant] Error doing job: Future exception was never retrieved
Traceback (most recent call last):
  File "/usr/local/lib/python3.9/concurrent/futures/thread.py", line 52, in run
    result = self.fn(*self.args, **self.kwargs)
TypeError: update() takes 1 positional argument but 2 were given
2021-09-10 16:38:44 WARNING (MainThread) [homeassistant.helpers.entity] Update of sensor.seventeentrack_packages_delivered is taking over 10 seconds
2021-09-10 16:40:36 ERROR (MainThread) [homeassistant] Error doing job: Future exception was never retrieved
Traceback (most recent call last):
  File "/usr/local/lib/python3.9/concurrent/futures/thread.py", line 52, in run
    result = self.fn(*self.args, **self.kwargs)
TypeError: update() takes 1 positional argument but 2 were given
2021-09-10 16:45:37 ERROR (MainThread) [homeassistant] Error doing job: Future exception was never retrieved
Traceback (most recent call last):
  File "/usr/local/lib/python3.9/concurrent/futures/thread.py", line 52, in run
    result = self.fn(*self.args, **self.kwargs)
TypeError: update() takes 1 positional argument but 2 were given
2021-09-10 16:50:38 ERROR (MainThread) [homeassistant] Error doing job: Future exception was never retrieved
Traceback (most recent call last):
  File "/usr/local/lib/python3.9/concurrent/futures/thread.py", line 52, in run
    result = self.fn(*self.args, **self.kwargs)
TypeError: update() takes 1 positional argument but 2 were given
2021-09-10 16:53:15 ERROR (MainThread) [iotawattpy.connection] Err: 
2021-09-10 16:53:15 ERROR (MainThread) [homeassistant.components.iotawatt.coordinator] Unexpected error fetching 192.168.20.195 data: 'NoneType' object has no attribute 'text'
Traceback (most recent call last):
  File "/usr/src/homeassistant/homeassistant/helpers/update_coordinator.py", line 187, in _async_refresh
    self.data = await self._async_update_data()
  File "/usr/src/homeassistant/homeassistant/components/iotawatt/coordinator.py", line 55, in _async_update_data
    await self.api.update()
  File "/usr/local/lib/python3.9/site-packages/iotawattpy/iotawatt.py", line 66, in update
    await self._refreshSensors(timespan)
  File "/usr/local/lib/python3.9/site-packages/iotawattpy/iotawatt.py", line 107, in _refreshSensors
    query = query.text
AttributeError: 'NoneType' object has no attribute 'text'
2021-09-10 16:55:39 ERROR (MainThread) [homeassistant] Error doing job: Future exception was never retrieved
Traceback (most recent call last):
  File "/usr/local/lib/python3.9/concurrent/futures/thread.py", line 52, in run
    result = self.fn(*self.args, **self.kwargs)
TypeError: update() takes 1 positional argument but 2 were given
2021-09-10 16:57:00 DEBUG (MainThread) [bellows.ezsp.protocol] Send command sendBroadcast: (<BroadcastAddress.ALL_ROUTERS_AND_COORDINATOR: 65532>, EmberApsFrame(profileId=0, clusterId=54, sourceEndpoint=0, destinationEndpoint=0, options=<EmberApsOption.APS_OPTION_NONE: 0>, groupId=0, sequence=10), 0, 11, b'\n<\x00')
2021-09-10 16:57:00 DEBUG (MainThread) [bellows.ezsp.protocol] Send command addTransientLinkKey: (ff:ff:ff:ff:ff:ff:ff:ff, [90, 105, 103, 66, 101, 101, 65, 108, 108, 105, 97, 110, 99, 101, 48, 57])
2021-09-10 16:57:00 DEBUG (bellows.thread_0) [bellows.uart] Sending: b'627721a9622ae94d59947c25aa5592499c4e2dabe6cd6db7fd648f7e'
2021-09-10 16:57:00 DEBUG (bellows.thread_0) [bellows.uart] Data frame: b'2777a1a9622a15a4caae7e'
2021-09-10 16:57:00 DEBUG (bellows.thread_0) [bellows.uart] Sending: b'83401b7e'
2021-09-10 16:57:00 DEBUG (bellows.thread_0) [bellows.uart] Sending: b'737421a9fb2aea4da66bb5da55aac820fb0c42ceaca20be29ca800eccc4702ca7e'
2021-09-10 16:57:00 DEBUG (MainThread) [bellows.ezsp.protocol] Application frame 54 (sendBroadcast) received: b'0016'
2021-09-10 16:57:00 DEBUG (bellows.thread_0) [bellows.uart] Data frame: b'3777b1a9112a10b259a24a25aa5592499c58d8abedce9874fecc5f89186c7e'
2021-09-10 16:57:00 DEBUG (bellows.thread_0) [bellows.uart] Sending: b'8430fc7e'
2021-09-10 16:57:00 DEBUG (MainThread) [bellows.ezsp.protocol] Application frame 69 (incomingMessageHandler) received: b'050000360000000000000016ff000000ffff030a3c00'
2021-09-10 16:57:00 DEBUG (MainThread) [bellows.zigbee.application] Received incomingMessageHandler frame with [<EmberIncomingMessageType.INCOMING_BROADCAST_LOOPBACK: 5>, EmberApsFrame(profileId=0, clusterId=54, sourceEndpoint=0, destinationEndpoint=0, options=<EmberApsOption.APS_OPTION_NONE: 0>, groupId=0, sequence=22), 255, 0, 0x0000, 255, 255, b'\n<\x00']
2021-09-10 16:57:00 DEBUG (MainThread) [zigpy.zdo] [0x0000:zdo] ZDO request ZDOCmd.Mgmt_Permit_Joining_req: [60, <Bool.false: 0>]
2021-09-10 16:57:00 DEBUG (bellows.thread_0) [bellows.uart] Data frame: b'4074a1a9fb2a154e317e'
2021-09-10 16:57:00 DEBUG (bellows.thread_0) [bellows.uart] Sending: b'8520dd7e'
2021-09-10 16:57:00 DEBUG (MainThread) [bellows.ezsp.protocol] Application frame 175 (addTransientLinkKey) received: b'00'
2021-09-10 16:57:00 DEBUG (MainThread) [bellows.ezsp.protocol] Send command setPolicy: (<EzspPolicyId.TRUST_CENTER_POLICY: 0>, <EzspDecisionBitmask.ALLOW_UNSECURED_REJOINS|ALLOW_JOINS: 3>)
2021-09-10 16:57:00 DEBUG (bellows.thread_0) [bellows.uart] Sending: b'057521a9012a15b15953967e'
2021-09-10 16:57:01 DEBUG (bellows.thread_0) [bellows.uart] Data frame: b'5175a1a9012a15a0187e'
2021-09-10 16:57:01 DEBUG (bellows.thread_0) [bellows.uart] Sending: b'8610be7e'
2021-09-10 16:57:01 DEBUG (MainThread) [bellows.ezsp.protocol] Application frame 85 (setPolicy) received: b'00'
2021-09-10 16:57:01 DEBUG (bellows.thread_0) [bellows.uart] Data frame: b'6175b1a96b2a134ea6944a13aa5592499c4e27bde6ce67f98f7e'
2021-09-10 16:57:01 DEBUG (bellows.thread_0) [bellows.uart] Sending: b'87009f7e'
2021-09-10 16:57:01 DEBUG (MainThread) [bellows.ezsp.protocol] Application frame 63 (messageSentHandler) received: b'06fcff00003600000000000000160b0000'
2021-09-10 16:57:01 DEBUG (MainThread) [bellows.zigbee.application] Received messageSentHandler frame with [<EmberOutgoingMessageType.OUTGOING_BROADCAST: 6>, 65532, EmberApsFrame(profileId=0, clusterId=54, sourceEndpoint=0, destinationEndpoint=0, options=<EmberApsOption.APS_OPTION_NONE: 0>, groupId=0, sequence=22), 11, <EmberStatus.SUCCESS: 0>, b'']
2021-09-10 16:57:01 DEBUG (MainThread) [bellows.ezsp.protocol] Send command permitJoining: (60,)
2021-09-10 16:57:01 DEBUG (bellows.thread_0) [bellows.uart] Sending: b'177a21a9762a2991457e'
2021-09-10 16:57:01 DEBUG (bellows.thread_0) [bellows.uart] Data frame: b'727aa1a9762a158ef77e'
2021-09-10 16:57:01 DEBUG (bellows.thread_0) [bellows.uart] Sending: b'8070787e'
2021-09-10 16:57:01 DEBUG (MainThread) [bellows.ezsp.protocol] Application frame 34 (permitJoining) received: b'00'
2021-09-10 16:57:03 DEBUG (MainThread) [bellows.ezsp.protocol] Send command readCounters: ()
2021-09-10 16:57:03 DEBUG (bellows.thread_0) [bellows.uart] Sending: b'207b21a9a52acf357e'
2021-09-10 16:57:03 DEBUG (bellows.thread_0) [bellows.uart] Data frame: b'037ba1a9a52a08b26e945c25a15590499c4e26abecce6f8bfec66389fc7e3fa7ebcdde6f8fffc7dbd5d2698c4623a9ec763ba5ea758241984c2613b1e070381c0e07bbe5ca658a459a4d9e4f9ff7c3d9d46a35a25190482472117e'
2021-09-10 16:57:03 DEBUG (bellows.thread_0) [bellows.uart] Sending: b'8160597e'
2021-09-10 16:57:03 DEBUG (MainThread) [bellows.ezsp.protocol] Application frame 241 (readCounters) received: b'1d00370016000b000200000001000100080003000000000000000000000000000000000000000000000000000000000000000000000000000000000000000000000000000000000000000000000000000000'
2021-09-10 16:57:03 DEBUG (MainThread) [bellows.ezsp.protocol] Send command getValue: (<EzspValueId.VALUE_FREE_BUFFERS: 3>,)
2021-09-10 16:57:03 DEBUG (bellows.thread_0) [bellows.uart] Sending: b'317821a9fe2a1680917e'
2021-09-10 16:57:04 DEBUG (bellows.thread_0) [bellows.uart] Data frame: b'1478a1a9fe2a15b3aaf5677e'
2021-09-10 16:57:04 DEBUG (bellows.thread_0) [bellows.uart] Sending: b'82503a7e'
2021-09-10 16:57:04 DEBUG (MainThread) [bellows.ezsp.protocol] Application frame 170 (getValue) received: b'0001f3'
2021-09-10 16:57:04 DEBUG (MainThread) [bellows.zigbee.application] Free buffers status EzspStatus.SUCCESS, value: 243
2021-09-10 16:57:04 DEBUG (MainThread) [bellows.zigbee.application] ezsp_counters: [MAC_RX_BROADCAST = 3600, MAC_TX_BROADCAST = 6732, MAC_RX_UNICAST = 2295, MAC_TX_UNICAST_SUCCESS = 525, MAC_TX_UNICAST_RETRY = 743, MAC_TX_UNICAST_FAILED = 197, APS_DATA_RX_BROADCAST = 12, APS_DATA_TX_BROADCAST = 12, APS_DATA_RX_UNICAST = 478, APS_DATA_TX_UNICAST_SUCCESS = 128, APS_DATA_TX_UNICAST_RETRY = 39, APS_DATA_TX_UNICAST_FAILED = 19, ROUTE_DISCOVERY_INITIATED = 6, NEIGHBOR_ADDED = 0, NEIGHBOR_REMOVED = 0, NEIGHBOR_STALE = 0, JOIN_INDICATION = 1, CHILD_REMOVED = 2, ASH_OVERFLOW_ERROR = 0, ASH_FRAMING_ERROR = 0, ASH_OVERRUN_ERROR = 0, NWK_FRAME_COUNTER_FAILURE = 0, APS_FRAME_COUNTER_FAILURE = 0, UTILITY = 0, APS_LINK_KEY_NOT_AUTHORIZED = 0, NWK_DECRYPTION_FAILURE = 0, APS_DECRYPTION_FAILURE = 0, ALLOCATE_PACKET_BUFFER_FAILURE = 0, RELAYED_UNICAST = 0, PHY_TO_MAC_QUEUE_LIMIT_REACHED = 0, PACKET_VALIDATE_LIBRARY_DROPPED_COUNT = 0, TYPE_NWK_RETRY_OVERFLOW = 0, PHY_CCA_FAIL_COUNT = 4, BROADCAST_TABLE_FULL = 0, PTA_LO_PRI_REQUESTED = 0, PTA_HI_PRI_REQUESTED = 0, PTA_LO_PRI_DENIED = 0, PTA_HI_PRI_DENIED = 0, PTA_LO_PRI_TX_ABORTED = 0, PTA_HI_PRI_TX_ABORTED = 0, ADDRESS_CONFLICT_SENT = 0, EZSP_FREE_BUFFERS = 243]
2021-09-10 16:57:14 DEBUG (MainThread) [bellows.ezsp.protocol] Send command readCounters: ()
2021-09-10 16:57:14 DEBUG (bellows.thread_0) [bellows.uart] Sending: b'427921a9a52a5fee7e'
2021-09-10 16:57:14 DEBUG (bellows.thread_0) [bellows.uart] Data frame: b'2579a1a9a52a0ab260945d25a15590499c4e26abecce6f8bfec66389fc7e3fa7ebcdde6f8fffc7dbd5d2698c4623a9ec763ba5ea758241984c2613b1e070381c0e07bbe5ca658a459a4d9e4f9ff7c3d9d46a35a2519048245b247e'
2021-09-10 16:57:14 DEBUG (bellows.thread_0) [bellows.uart] Sending: b'83401b7e'
2021-09-10 16:57:14 DEBUG (MainThread) [bellows.ezsp.protocol] Application frame 241 (readCounters) received: b'1f00390017000b000200000001000100080003000000000000000000000000000000000000000000000000000000000000000000000000000000000000000000000000000000000000000000000000000000'
2021-09-10 16:57:14 DEBUG (MainThread) [bellows.ezsp.protocol] Send command getValue: (<EzspValueId.VALUE_FREE_BUFFERS: 3>,)
2021-09-10 16:57:14 DEBUG (bellows.thread_0) [bellows.uart] Sending: b'537d5e21a9fe2a16de897e'
2021-09-10 16:57:14 DEBUG (bellows.thread_0) [bellows.uart] Data frame: b'367ea1a9fe2a15b3aa14377e'
2021-09-10 16:57:14 DEBUG (bellows.thread_0) [bellows.uart] Sending: b'8430fc7e'
2021-09-10 16:57:14 DEBUG (MainThread) [bellows.ezsp.protocol] Application frame 170 (getValue) received: b'0001f3'
2021-09-10 16:57:14 DEBUG (MainThread) [bellows.zigbee.application] Free buffers status EzspStatus.SUCCESS, value: 243
2021-09-10 16:57:14 DEBUG (MainThread) [bellows.zigbee.application] ezsp_counters: [MAC_RX_BROADCAST = 3602, MAC_TX_BROADCAST = 6734, MAC_RX_UNICAST = 2296, MAC_TX_UNICAST_SUCCESS = 525, MAC_TX_UNICAST_RETRY = 743, MAC_TX_UNICAST_FAILED = 197, APS_DATA_RX_BROADCAST = 12, APS_DATA_TX_BROADCAST = 12, APS_DATA_RX_UNICAST = 478, APS_DATA_TX_UNICAST_SUCCESS = 128, APS_DATA_TX_UNICAST_RETRY = 39, APS_DATA_TX_UNICAST_FAILED = 19, ROUTE_DISCOVERY_INITIATED = 6, NEIGHBOR_ADDED = 0, NEIGHBOR_REMOVED = 0, NEIGHBOR_STALE = 0, JOIN_INDICATION = 1, CHILD_REMOVED = 2, ASH_OVERFLOW_ERROR = 0, ASH_FRAMING_ERROR = 0, ASH_OVERRUN_ERROR = 0, NWK_FRAME_COUNTER_FAILURE = 0, APS_FRAME_COUNTER_FAILURE = 0, UTILITY = 0, APS_LINK_KEY_NOT_AUTHORIZED = 0, NWK_DECRYPTION_FAILURE = 0, APS_DECRYPTION_FAILURE = 0, ALLOCATE_PACKET_BUFFER_FAILURE = 0, RELAYED_UNICAST = 0, PHY_TO_MAC_QUEUE_LIMIT_REACHED = 0, PACKET_VALIDATE_LIBRARY_DROPPED_COUNT = 0, TYPE_NWK_RETRY_OVERFLOW = 0, PHY_CCA_FAIL_COUNT = 4, BROADCAST_TABLE_FULL = 0, PTA_LO_PRI_REQUESTED = 0, PTA_HI_PRI_REQUESTED = 0, PTA_LO_PRI_DENIED = 0, PTA_HI_PRI_DENIED = 0, PTA_LO_PRI_TX_ABORTED = 0, PTA_HI_PRI_TX_ABORTED = 0, ADDRESS_CONFLICT_SENT = 0, EZSP_FREE_BUFFERS = 243]
2021-09-10 16:57:24 DEBUG (MainThread) [bellows.ezsp.protocol] Send command readCounters: ()
2021-09-10 16:57:24 DEBUG (bellows.thread_0) [bellows.uart] Sending: b'647f21a9a52a2a827e'
2021-09-10 16:57:25 DEBUG (bellows.thread_0) [bellows.uart] Data frame: b'477fa1a9a52a37b264945d25a15590499c4e26abecce6f8bfec66389fc7e3fa7ebcdde6f8fffc7dbd5d2698c4623a9ec763ba5ea758241984c2613b1e070381c0e07bbe5ca658a459a4d9e4f9ff7c3d9d46a35a2519048243a057e'
2021-09-10 16:57:25 DEBUG (bellows.thread_0) [bellows.uart] Sending: b'8520dd7e'
2021-09-10 16:57:25 DEBUG (MainThread) [bellows.ezsp.protocol] Application frame 241 (readCounters) received: b'22003d0017000b000200000001000100080003000000000000000000000000000000000000000000000000000000000000000000000000000000000000000000000000000000000000000000000000000000'
2021-09-10 16:57:25 DEBUG (MainThread) [bellows.ezsp.protocol] Send command getValue: (<EzspValueId.VALUE_FREE_BUFFERS: 3>,)
2021-09-10 16:57:25 DEBUG (bellows.thread_0) [bellows.uart] Sending: b'757c21a9fe2a169a7d3a7e'
2021-09-10 16:57:25 DEBUG (bellows.thread_0) [bellows.uart] Data frame: b'507ca1a9fe2a15b3aa393c7e'
2021-09-10 16:57:25 DEBUG (bellows.thread_0) [bellows.uart] Sending: b'8610be7e'
2021-09-10 16:57:25 DEBUG (MainThread) [bellows.ezsp.protocol] Application frame 170 (getValue) received: b'0001f3'
2021-09-10 16:57:25 DEBUG (MainThread) [bellows.zigbee.application] Free buffers status EzspStatus.SUCCESS, value: 243
2021-09-10 16:57:25 DEBUG (MainThread) [bellows.zigbee.application] ezsp_counters: [MAC_RX_BROADCAST = 3605, MAC_TX_BROADCAST = 6738, MAC_RX_UNICAST = 2296, MAC_TX_UNICAST_SUCCESS = 525, MAC_TX_UNICAST_RETRY = 743, MAC_TX_UNICAST_FAILED = 197, APS_DATA_RX_BROADCAST = 12, APS_DATA_TX_BROADCAST = 12, APS_DATA_RX_UNICAST = 478, APS_DATA_TX_UNICAST_SUCCESS = 128, APS_DATA_TX_UNICAST_RETRY = 39, APS_DATA_TX_UNICAST_FAILED = 19, ROUTE_DISCOVERY_INITIATED = 6, NEIGHBOR_ADDED = 0, NEIGHBOR_REMOVED = 0, NEIGHBOR_STALE = 0, JOIN_INDICATION = 1, CHILD_REMOVED = 2, ASH_OVERFLOW_ERROR = 0, ASH_FRAMING_ERROR = 0, ASH_OVERRUN_ERROR = 0, NWK_FRAME_COUNTER_FAILURE = 0, APS_FRAME_COUNTER_FAILURE = 0, UTILITY = 0, APS_LINK_KEY_NOT_AUTHORIZED = 0, NWK_DECRYPTION_FAILURE = 0, APS_DECRYPTION_FAILURE = 0, ALLOCATE_PACKET_BUFFER_FAILURE = 0, RELAYED_UNICAST = 0, PHY_TO_MAC_QUEUE_LIMIT_REACHED = 0, PACKET_VALIDATE_LIBRARY_DROPPED_COUNT = 0, TYPE_NWK_RETRY_OVERFLOW = 0, PHY_CCA_FAIL_COUNT = 4, BROADCAST_TABLE_FULL = 0, PTA_LO_PRI_REQUESTED = 0, PTA_HI_PRI_REQUESTED = 0, PTA_LO_PRI_DENIED = 0, PTA_HI_PRI_DENIED = 0, PTA_LO_PRI_TX_ABORTED = 0, PTA_HI_PRI_TX_ABORTED = 0, ADDRESS_CONFLICT_SENT = 0, EZSP_FREE_BUFFERS = 243]
2021-09-10 16:57:35 DEBUG (MainThread) [bellows.ezsp.protocol] Send command readCounters: ()
2021-09-10 16:57:35 DEBUG (bellows.thread_0) [bellows.uart] Sending: b'067d5d21a9a52aba597e'
2021-09-10 16:57:35 DEBUG (bellows.thread_0) [bellows.uart] Data frame: b'617da1a9a52a36b267945d25a15590499c4e26abecce6f8bfec66389fc7e3fa7ebcdde6f8fffc7dbd5d2698c4623a9ec763ba5ea758241984c2613b1e070381c0e07bbe5ca658a459a4d9e4f9ff7c3d9d46a35a2519048248dc77e'
2021-09-10 16:57:35 DEBUG (bellows.thread_0) [bellows.uart] Sending: b'87009f7e'
2021-09-10 16:57:35 DEBUG (MainThread) [bellows.ezsp.protocol] Application frame 241 (readCounters) received: b'23003e0017000b000200000001000100080003000000000000000000000000000000000000000000000000000000000000000000000000000000000000000000000000000000000000000000000000000000'
2021-09-10 16:57:35 DEBUG (MainThread) [bellows.ezsp.protocol] Send command getValue: (<EzspValueId.VALUE_FREE_BUFFERS: 3>,)
2021-09-10 16:57:35 DEBUG (bellows.thread_0) [bellows.uart] Sending: b'170221a9fe2a168cdc7e'
2021-09-10 16:57:35 DEBUG (bellows.thread_0) [bellows.uart] Data frame: b'7202a1a9fe2a15b3aa76ba7e'
2021-09-10 16:57:35 DEBUG (bellows.thread_0) [bellows.uart] Sending: b'8070787e'
2021-09-10 16:57:35 DEBUG (MainThread) [bellows.ezsp.protocol] Application frame 170 (getValue) received: b'0001f3'
2021-09-10 16:57:35 DEBUG (MainThread) [bellows.zigbee.application] Free buffers status EzspStatus.SUCCESS, value: 243
2021-09-10 16:57:35 DEBUG (MainThread) [bellows.zigbee.application] ezsp_counters: [MAC_RX_BROADCAST = 3606, MAC_TX_BROADCAST = 6739, MAC_RX_UNICAST = 2296, MAC_TX_UNICAST_SUCCESS = 525, MAC_TX_UNICAST_RETRY = 743, MAC_TX_UNICAST_FAILED = 197, APS_DATA_RX_BROADCAST = 12, APS_DATA_TX_BROADCAST = 12, APS_DATA_RX_UNICAST = 478, APS_DATA_TX_UNICAST_SUCCESS = 128, APS_DATA_TX_UNICAST_RETRY = 39, APS_DATA_TX_UNICAST_FAILED = 19, ROUTE_DISCOVERY_INITIATED = 6, NEIGHBOR_ADDED = 0, NEIGHBOR_REMOVED = 0, NEIGHBOR_STALE = 0, JOIN_INDICATION = 1, CHILD_REMOVED = 2, ASH_OVERFLOW_ERROR = 0, ASH_FRAMING_ERROR = 0, ASH_OVERRUN_ERROR = 0, NWK_FRAME_COUNTER_FAILURE = 0, APS_FRAME_COUNTER_FAILURE = 0, UTILITY = 0, APS_LINK_KEY_NOT_AUTHORIZED = 0, NWK_DECRYPTION_FAILURE = 0, APS_DECRYPTION_FAILURE = 0, ALLOCATE_PACKET_BUFFER_FAILURE = 0, RELAYED_UNICAST = 0, PHY_TO_MAC_QUEUE_LIMIT_REACHED = 0, PACKET_VALIDATE_LIBRARY_DROPPED_COUNT = 0, TYPE_NWK_RETRY_OVERFLOW = 0, PHY_CCA_FAIL_COUNT = 4, BROADCAST_TABLE_FULL = 0, PTA_LO_PRI_REQUESTED = 0, PTA_HI_PRI_REQUESTED = 0, PTA_LO_PRI_DENIED = 0, PTA_HI_PRI_DENIED = 0, PTA_LO_PRI_TX_ABORTED = 0, PTA_HI_PRI_TX_ABORTED = 0, ADDRESS_CONFLICT_SENT = 0, EZSP_FREE_BUFFERS = 243]
2021-09-10 16:57:45 DEBUG (MainThread) [bellows.ezsp.protocol] Send command readCounters: ()
2021-09-10 16:57:45 DEBUG (bellows.thread_0) [bellows.uart] Sending: b'200321a9a52ad09e7e'
2021-09-10 16:57:45 DEBUG (bellows.thread_0) [bellows.uart] Data frame: b'0303a1a9a52a33b21b945225a15590499c4e26abecce6f8bfec66389fc7e3fa7ebcdde6f8fffc7dbd5d2698c4623a9ec763ba5ea758241984c2613b1e070381c0e07bbe5ca658a459a4d9e4f9ff7c3d9d46a35a25190482413997e'
2021-09-10 16:57:45 DEBUG (bellows.thread_0) [bellows.uart] Sending: b'8160597e'
2021-09-10 16:57:45 DEBUG (MainThread) [bellows.ezsp.protocol] Application frame 241 (readCounters) received: b'2600420018000b000200000001000100080003000000000000000000000000000000000000000000000000000000000000000000000000000000000000000000000000000000000000000000000000000000'
2021-09-10 16:57:45 DEBUG (MainThread) [bellows.ezsp.protocol] Send command getValue: (<EzspValueId.VALUE_FREE_BUFFERS: 3>,)
2021-09-10 16:57:45 DEBUG (bellows.thread_0) [bellows.uart] Sending: b'310021a9fe2a16c84f7e'
2021-09-10 16:57:45 DEBUG (bellows.thread_0) [bellows.uart] Data frame: b'1400a1a9fe2a15b3aa5bb17e'
2021-09-10 16:57:45 DEBUG (bellows.thread_0) [bellows.uart] Sending: b'82503a7e'
2021-09-10 16:57:45 DEBUG (MainThread) [bellows.ezsp.protocol] Application frame 170 (getValue) received: b'0001f3'
2021-09-10 16:57:45 DEBUG (MainThread) [bellows.zigbee.application] Free buffers status EzspStatus.SUCCESS, value: 243
2021-09-10 16:57:45 DEBUG (MainThread) [bellows.zigbee.application] ezsp_counters: [MAC_RX_BROADCAST = 3609, MAC_TX_BROADCAST = 6743, MAC_RX_UNICAST = 2297, MAC_TX_UNICAST_SUCCESS = 525, MAC_TX_UNICAST_RETRY = 743, MAC_TX_UNICAST_FAILED = 197, APS_DATA_RX_BROADCAST = 12, APS_DATA_TX_BROADCAST = 12, APS_DATA_RX_UNICAST = 478, APS_DATA_TX_UNICAST_SUCCESS = 128, APS_DATA_TX_UNICAST_RETRY = 39, APS_DATA_TX_UNICAST_FAILED = 19, ROUTE_DISCOVERY_INITIATED = 6, NEIGHBOR_ADDED = 0, NEIGHBOR_REMOVED = 0, NEIGHBOR_STALE = 0, JOIN_INDICATION = 1, CHILD_REMOVED = 2, ASH_OVERFLOW_ERROR = 0, ASH_FRAMING_ERROR = 0, ASH_OVERRUN_ERROR = 0, NWK_FRAME_COUNTER_FAILURE = 0, APS_FRAME_COUNTER_FAILURE = 0, UTILITY = 0, APS_LINK_KEY_NOT_AUTHORIZED = 0, NWK_DECRYPTION_FAILURE = 0, APS_DECRYPTION_FAILURE = 0, ALLOCATE_PACKET_BUFFER_FAILURE = 0, RELAYED_UNICAST = 0, PHY_TO_MAC_QUEUE_LIMIT_REACHED = 0, PACKET_VALIDATE_LIBRARY_DROPPED_COUNT = 0, TYPE_NWK_RETRY_OVERFLOW = 0, PHY_CCA_FAIL_COUNT = 4, BROADCAST_TABLE_FULL = 0, PTA_LO_PRI_REQUESTED = 0, PTA_HI_PRI_REQUESTED = 0, PTA_LO_PRI_DENIED = 0, PTA_HI_PRI_DENIED = 0, PTA_LO_PRI_TX_ABORTED = 0, PTA_HI_PRI_TX_ABORTED = 0, ADDRESS_CONFLICT_SENT = 0, EZSP_FREE_BUFFERS = 243]
2021-09-10 16:57:55 DEBUG (MainThread) [bellows.ezsp.protocol] Send command readCounters: ()
2021-09-10 16:57:55 DEBUG (bellows.thread_0) [bellows.uart] Sending: b'420121a9a52a40457e'
2021-09-10 16:57:56 DEBUG (bellows.thread_0) [bellows.uart] Data frame: b'2501a1a9a52a3db21c945225a15590499c4e26abecce6f8bfec66389fc7e3fa7ebcdde6f8fffc7dbd5d2698c4623a9ec763ba5ea758241984c2613b1e070381c0e07bbe5ca658a459a4d9e4f9ff7c3d9d46a35a251904824b1e67e'
2021-09-10 16:57:56 DEBUG (bellows.thread_0) [bellows.uart] Sending: b'83401b7e'
2021-09-10 16:57:56 DEBUG (MainThread) [bellows.ezsp.protocol] Application frame 241 (readCounters) received: b'2800450018000b000200000001000100080003000000000000000000000000000000000000000000000000000000000000000000000000000000000000000000000000000000000000000000000000000000'
2021-09-10 16:57:56 DEBUG (MainThread) [bellows.ezsp.protocol] Send command getValue: (<EzspValueId.VALUE_FREE_BUFFERS: 3>,)
2021-09-10 16:57:56 DEBUG (bellows.thread_0) [bellows.uart] Sending: b'530621a9fe2a1696577e'
2021-09-10 16:57:56 DEBUG (bellows.thread_0) [bellows.uart] Data frame: b'3606a1a9fe2a15b3aabae17e'
2021-09-10 16:57:56 DEBUG (bellows.thread_0) [bellows.uart] Sending: b'8430fc7e'
2021-09-10 16:57:56 DEBUG (MainThread) [bellows.ezsp.protocol] Application frame 170 (getValue) received: b'0001f3'
2021-09-10 16:57:56 DEBUG (MainThread) [bellows.zigbee.application] Free buffers status EzspStatus.SUCCESS, value: 243
2021-09-10 16:57:56 DEBUG (MainThread) [bellows.zigbee.application] ezsp_counters: [MAC_RX_BROADCAST = 3611, MAC_TX_BROADCAST = 6746, MAC_RX_UNICAST = 2297, MAC_TX_UNICAST_SUCCESS = 525, MAC_TX_UNICAST_RETRY = 743, MAC_TX_UNICAST_FAILED = 197, APS_DATA_RX_BROADCAST = 12, APS_DATA_TX_BROADCAST = 12, APS_DATA_RX_UNICAST = 478, APS_DATA_TX_UNICAST_SUCCESS = 128, APS_DATA_TX_UNICAST_RETRY = 39, APS_DATA_TX_UNICAST_FAILED = 19, ROUTE_DISCOVERY_INITIATED = 6, NEIGHBOR_ADDED = 0, NEIGHBOR_REMOVED = 0, NEIGHBOR_STALE = 0, JOIN_INDICATION = 1, CHILD_REMOVED = 2, ASH_OVERFLOW_ERROR = 0, ASH_FRAMING_ERROR = 0, ASH_OVERRUN_ERROR = 0, NWK_FRAME_COUNTER_FAILURE = 0, APS_FRAME_COUNTER_FAILURE = 0, UTILITY = 0, APS_LINK_KEY_NOT_AUTHORIZED = 0, NWK_DECRYPTION_FAILURE = 0, APS_DECRYPTION_FAILURE = 0, ALLOCATE_PACKET_BUFFER_FAILURE = 0, RELAYED_UNICAST = 0, PHY_TO_MAC_QUEUE_LIMIT_REACHED = 0, PACKET_VALIDATE_LIBRARY_DROPPED_COUNT = 0, TYPE_NWK_RETRY_OVERFLOW = 0, PHY_CCA_FAIL_COUNT = 4, BROADCAST_TABLE_FULL = 0, PTA_LO_PRI_REQUESTED = 0, PTA_HI_PRI_REQUESTED = 0, PTA_LO_PRI_DENIED = 0, PTA_HI_PRI_DENIED = 0, PTA_LO_PRI_TX_ABORTED = 0, PTA_HI_PRI_TX_ABORTED = 0, ADDRESS_CONFLICT_SENT = 0, EZSP_FREE_BUFFERS = 243]
2021-09-10 16:58:03 DEBUG (MainThread) [bellows.ezsp.protocol] Send command setPolicy: (<EzspPolicyId.TRUST_CENTER_POLICY: 0>, <EzspDecisionBitmask.IGNORE_UNSECURED_REJOINS|ALLOW_JOINS: 9>)
2021-09-10 16:58:03 DEBUG (bellows.thread_0) [bellows.uart] Sending: b'640721a9012a15bb5990f17e'
2021-09-10 16:58:03 DEBUG (bellows.thread_0) [bellows.uart] Data frame: b'4707a1a9012a15f89a7e'
2021-09-10 16:58:03 DEBUG (bellows.thread_0) [bellows.uart] Sending: b'8520dd7e'
2021-09-10 16:58:03 DEBUG (MainThread) [bellows.ezsp.protocol] Application frame 85 (setPolicy) received: b'00'
2021-09-10 16:58:06 DEBUG (MainThread) [bellows.ezsp.protocol] Send command readCounters: ()
2021-09-10 16:58:06 DEBUG (bellows.thread_0) [bellows.uart] Sending: b'750421a9a52a84df7e'
2021-09-10 16:58:06 DEBUG (bellows.thread_0) [bellows.uart] Data frame: b'5004a1a9a52a3fb21e945225a15590499c4e26abecce6f8bfec66389fc7e3fa7ebcdde6f8fffc7dbd5d2698c4623a9ec763ba5ea758241984c2613b1e070381c0e07bbe5ca658a459a4d9e4f9ff7c3d9d46a35a2519048245ea77e'
2021-09-10 16:58:06 DEBUG (bellows.thread_0) [bellows.uart] Sending: b'8610be7e'
2021-09-10 16:58:06 DEBUG (MainThread) [bellows.ezsp.protocol] Application frame 241 (readCounters) received: b'2a00470018000b000200000001000100080003000000000000000000000000000000000000000000000000000000000000000000000000000000000000000000000000000000000000000000000000000000'
2021-09-10 16:58:06 DEBUG (MainThread) [bellows.ezsp.protocol] Send command getValue: (<EzspValueId.VALUE_FREE_BUFFERS: 3>,)
2021-09-10 16:58:06 DEBUG (bellows.thread_0) [bellows.uart] Sending: b'060521a9fe2a16cb877e'
2021-09-10 16:58:06 DEBUG (bellows.thread_0) [bellows.uart] Data frame: b'6105a1a9fe2a15b3aacf187e'
2021-09-10 16:58:06 DEBUG (bellows.thread_0) [bellows.uart] Sending: b'87009f7e'
2021-09-10 16:58:06 DEBUG (MainThread) [bellows.ezsp.protocol] Application frame 170 (getValue) received: b'0001f3'
2021-09-10 16:58:06 DEBUG (MainThread) [bellows.zigbee.application] Free buffers status EzspStatus.SUCCESS, value: 243
2021-09-10 16:58:06 DEBUG (MainThread) [bellows.zigbee.application] ezsp_counters: [MAC_RX_BROADCAST = 3613, MAC_TX_BROADCAST = 6748, MAC_RX_UNICAST = 2297, MAC_TX_UNICAST_SUCCESS = 525, MAC_TX_UNICAST_RETRY = 743, MAC_TX_UNICAST_FAILED = 197, APS_DATA_RX_BROADCAST = 12, APS_DATA_TX_BROADCAST = 12, APS_DATA_RX_UNICAST = 478, APS_DATA_TX_UNICAST_SUCCESS = 128, APS_DATA_TX_UNICAST_RETRY = 39, APS_DATA_TX_UNICAST_FAILED = 19, ROUTE_DISCOVERY_INITIATED = 6, NEIGHBOR_ADDED = 0, NEIGHBOR_REMOVED = 0, NEIGHBOR_STALE = 0, JOIN_INDICATION = 1, CHILD_REMOVED = 2, ASH_OVERFLOW_ERROR = 0, ASH_FRAMING_ERROR = 0, ASH_OVERRUN_ERROR = 0, NWK_FRAME_COUNTER_FAILURE = 0, APS_FRAME_COUNTER_FAILURE = 0, UTILITY = 0, APS_LINK_KEY_NOT_AUTHORIZED = 0, NWK_DECRYPTION_FAILURE = 0, APS_DECRYPTION_FAILURE = 0, ALLOCATE_PACKET_BUFFER_FAILURE = 0, RELAYED_UNICAST = 0, PHY_TO_MAC_QUEUE_LIMIT_REACHED = 0, PACKET_VALIDATE_LIBRARY_DROPPED_COUNT = 0, TYPE_NWK_RETRY_OVERFLOW = 0, PHY_CCA_FAIL_COUNT = 4, BROADCAST_TABLE_FULL = 0, PTA_LO_PRI_REQUESTED = 0, PTA_HI_PRI_REQUESTED = 0, PTA_LO_PRI_DENIED = 0, PTA_HI_PRI_DENIED = 0, PTA_LO_PRI_TX_ABORTED = 0, PTA_HI_PRI_TX_ABORTED = 0, ADDRESS_CONFLICT_SENT = 0, EZSP_FREE_BUFFERS = 243]
2021-09-10 16:58:16 DEBUG (MainThread) [bellows.ezsp.protocol] Send command readCounters: ()
2021-09-10 16:58:16 DEBUG (bellows.thread_0) [bellows.uart] Sending: b'170a21a9a52a9f2f7e'
2021-09-10 16:58:17 DEBUG (bellows.thread_0) [bellows.uart] Data frame: b'720aa1a9a52a3fb211945325a15590499c4e26abecce6f8bfec66389fc7e3fa7ebcdde6f8fffc7dbd5d2698c4623a9ec763ba5ea758241984c2613b1e070381c0e07bbe5ca658a459a4d9e4f9ff7c3d9d46a35a25190482482c07e'
2021-09-10 16:58:17 DEBUG (bellows.thread_0) [bellows.uart] Sending: b'8070787e'
2021-09-10 16:58:17 DEBUG (MainThread) [bellows.ezsp.protocol] Application frame 241 (readCounters) received: b'2a00480019000b000200000001000100080003000000000000000000000000000000000000000000000000000000000000000000000000000000000000000000000000000000000000000000000000000000'
2021-09-10 16:58:17 DEBUG (MainThread) [bellows.ezsp.protocol] Send command getValue: (<EzspValueId.VALUE_FREE_BUFFERS: 3>,)
2021-09-10 16:58:17 DEBUG (bellows.thread_0) [bellows.uart] Sending: b'200b21a9fe2a1684f77e'
2021-09-10 16:58:17 DEBUG (bellows.thread_0) [bellows.uart] Data frame: b'7a0aa1a9a52a3fb211945325a15590499c4e26abecce6f8bfec66389fc7e3fa7ebcdde6f8fffc7dbd5d2698c4623a9ec763ba5ea758241984c2613b1e070381c0e07bbe5ca658a459a4d9e4f9ff7c3d9d46a35a25190482431fa7e'
2021-09-10 16:58:17 DEBUG (bellows.thread_0) [bellows.uart] Sending: b'8070787e'
2021-09-10 16:58:17 DEBUG (MainThread) [bellows.ezsp.protocol] Application frame 241 (readCounters) received: b'2a00480019000b000200000001000100080003000000000000000000000000000000000000000000000000000000000000000000000000000000000000000000000000000000000000000000000000000000'
2021-09-10 16:58:17 DEBUG (MainThread) [bellows.zigbee.application] Received readCounters frame with [[42, 72, 25, 11, 2, 0, 1, 1, 8, 3, 0, 0, 0, 0, 0, 0, 0, 0, 0, 0, 0, 0, 0, 0, 0, 0, 0, 0, 0, 0, 0, 0, 0, 0, 0, 0, 0, 0, 0, 0, 0]]
2021-09-10 16:58:18 DEBUG (bellows.thread_0) [bellows.uart] Data frame: b'030ba1a9fe2a15b3aa6f4b7e'
2021-09-10 16:58:18 DEBUG (bellows.thread_0) [bellows.uart] Sending: b'8160597e'
2021-09-10 16:58:18 DEBUG (MainThread) [bellows.ezsp.protocol] Application frame 170 (getValue) received: b'0001f3'
2021-09-10 16:58:18 DEBUG (MainThread) [bellows.zigbee.application] Free buffers status EzspStatus.SUCCESS, value: 243
2021-09-10 16:58:18 DEBUG (MainThread) [bellows.zigbee.application] ezsp_counters: [MAC_RX_BROADCAST = 3613, MAC_TX_BROADCAST = 6749, MAC_RX_UNICAST = 2298, MAC_TX_UNICAST_SUCCESS = 525, MAC_TX_UNICAST_RETRY = 743, MAC_TX_UNICAST_FAILED = 197, APS_DATA_RX_BROADCAST = 12, APS_DATA_TX_BROADCAST = 12, APS_DATA_RX_UNICAST = 478, APS_DATA_TX_UNICAST_SUCCESS = 128, APS_DATA_TX_UNICAST_RETRY = 39, APS_DATA_TX_UNICAST_FAILED = 19, ROUTE_DISCOVERY_INITIATED = 6, NEIGHBOR_ADDED = 0, NEIGHBOR_REMOVED = 0, NEIGHBOR_STALE = 0, JOIN_INDICATION = 1, CHILD_REMOVED = 2, ASH_OVERFLOW_ERROR = 0, ASH_FRAMING_ERROR = 0, ASH_OVERRUN_ERROR = 0, NWK_FRAME_COUNTER_FAILURE = 0, APS_FRAME_COUNTER_FAILURE = 0, UTILITY = 0, APS_LINK_KEY_NOT_AUTHORIZED = 0, NWK_DECRYPTION_FAILURE = 0, APS_DECRYPTION_FAILURE = 0, ALLOCATE_PACKET_BUFFER_FAILURE = 0, RELAYED_UNICAST = 0, PHY_TO_MAC_QUEUE_LIMIT_REACHED = 0, PACKET_VALIDATE_LIBRARY_DROPPED_COUNT = 0, TYPE_NWK_RETRY_OVERFLOW = 0, PHY_CCA_FAIL_COUNT = 4, BROADCAST_TABLE_FULL = 0, PTA_LO_PRI_REQUESTED = 0, PTA_HI_PRI_REQUESTED = 0, PTA_LO_PRI_DENIED = 0, PTA_HI_PRI_DENIED = 0, PTA_LO_PRI_TX_ABORTED = 0, PTA_HI_PRI_TX_ABORTED = 0, ADDRESS_CONFLICT_SENT = 0, EZSP_FREE_BUFFERS = 243]
2021-09-10 16:58:28 DEBUG (MainThread) [bellows.ezsp.protocol] Send command readCounters: ()
2021-09-10 16:58:28 DEBUG (bellows.thread_0) [bellows.uart] Sending: b'310821a9a52a63457e'
2021-09-10 16:58:28 DEBUG (bellows.thread_0) [bellows.uart] Data frame: b'1408a1a9a52a38b215945325a15590499c4e26abecce6f8bfec66389fc7e3fa7ebcdde6f8fffc7dbd5d2698c4623a9ec763ba5ea758241984c2613b1e070381c0e07bbe5ca658a459a4d9e4f9ff7c3d9d46a35a251904824b14c7e'
2021-09-10 16:58:28 DEBUG (bellows.thread_0) [bellows.uart] Sending: b'82503a7e'
2021-09-10 16:58:28 DEBUG (MainThread) [bellows.ezsp.protocol] Application frame 241 (readCounters) received: b'2d004c0019000b000200000001000100080003000000000000000000000000000000000000000000000000000000000000000000000000000000000000000000000000000000000000000000000000000000'
2021-09-10 16:58:28 DEBUG (MainThread) [bellows.ezsp.protocol] Send command getValue: (<EzspValueId.VALUE_FREE_BUFFERS: 3>,)
2021-09-10 16:58:28 DEBUG (bellows.thread_0) [bellows.uart] Sending: b'420921a9fe2a16dc4e7e'
2021-09-10 16:58:28 DEBUG (bellows.thread_0) [bellows.uart] Data frame: b'2509a1a9fe2a15b3aa1d997e'
2021-09-10 16:58:28 DEBUG (bellows.thread_0) [bellows.uart] Sending: b'83401b7e'
2021-09-10 16:58:28 DEBUG (MainThread) [bellows.ezsp.protocol] Application frame 170 (getValue) received: b'0001f3'
2021-09-10 16:58:28 DEBUG (MainThread) [bellows.zigbee.application] Free buffers status EzspStatus.SUCCESS, value: 243
2021-09-10 16:58:28 DEBUG (MainThread) [bellows.zigbee.application] ezsp_counters: [MAC_RX_BROADCAST = 3616, MAC_TX_BROADCAST = 6753, MAC_RX_UNICAST = 2298, MAC_TX_UNICAST_SUCCESS = 525, MAC_TX_UNICAST_RETRY = 743, MAC_TX_UNICAST_FAILED = 197, APS_DATA_RX_BROADCAST = 12, APS_DATA_TX_BROADCAST = 12, APS_DATA_RX_UNICAST = 478, APS_DATA_TX_UNICAST_SUCCESS = 128, APS_DATA_TX_UNICAST_RETRY = 39, APS_DATA_TX_UNICAST_FAILED = 19, ROUTE_DISCOVERY_INITIATED = 6, NEIGHBOR_ADDED = 0, NEIGHBOR_REMOVED = 0, NEIGHBOR_STALE = 0, JOIN_INDICATION = 1, CHILD_REMOVED = 2, ASH_OVERFLOW_ERROR = 0, ASH_FRAMING_ERROR = 0, ASH_OVERRUN_ERROR = 0, NWK_FRAME_COUNTER_FAILURE = 0, APS_FRAME_COUNTER_FAILURE = 0, UTILITY = 0, APS_LINK_KEY_NOT_AUTHORIZED = 0, NWK_DECRYPTION_FAILURE = 0, APS_DECRYPTION_FAILURE = 0, ALLOCATE_PACKET_BUFFER_FAILURE = 0, RELAYED_UNICAST = 0, PHY_TO_MAC_QUEUE_LIMIT_REACHED = 0, PACKET_VALIDATE_LIBRARY_DROPPED_COUNT = 0, TYPE_NWK_RETRY_OVERFLOW = 0, PHY_CCA_FAIL_COUNT = 4, BROADCAST_TABLE_FULL = 0, PTA_LO_PRI_REQUESTED = 0, PTA_HI_PRI_REQUESTED = 0, PTA_LO_PRI_DENIED = 0, PTA_HI_PRI_DENIED = 0, PTA_LO_PRI_TX_ABORTED = 0, PTA_HI_PRI_TX_ABORTED = 0, ADDRESS_CONFLICT_SENT = 0, EZSP_FREE_BUFFERS = 243]
2021-09-10 16:58:38 DEBUG (MainThread) [bellows.ezsp.protocol] Send command readCounters: ()
2021-09-10 16:58:38 DEBUG (bellows.thread_0) [bellows.uart] Sending: b'530e21a9a52a7a987e'
2021-09-10 16:58:39 DEBUG (bellows.thread_0) [bellows.uart] Data frame: b'360ea1a9a52a38b214945325a15590499c4e26abecce6f8bfec66389fc7e3fa7ebcdde6f8fffc7dbd5d2698c4623a9ec763ba5ea758241984c2613b1e070381c0e07bbe5ca658a459a4d9e4f9ff7c3d9d46a35a25190482487c67e'
2021-09-10 16:58:39 DEBUG (bellows.thread_0) [bellows.uart] Sending: b'8430fc7e'
2021-09-10 16:58:39 DEBUG (MainThread) [bellows.ezsp.protocol] Application frame 241 (readCounters) received: b'2d004d0019000b000200000001000100080003000000000000000000000000000000000000000000000000000000000000000000000000000000000000000000000000000000000000000000000000000000'
2021-09-10 16:58:39 DEBUG (MainThread) [bellows.ezsp.protocol] Send command getValue: (<EzspValueId.VALUE_FREE_BUFFERS: 3>,)
2021-09-10 16:58:39 DEBUG (bellows.thread_0) [bellows.uart] Sending: b'640f21a9fe2a169e7c7e'
2021-09-10 16:58:39 DEBUG (bellows.thread_0) [bellows.uart] Data frame: b'470fa1a9fe2a15b3aaa3107e'
2021-09-10 16:58:39 DEBUG (bellows.thread_0) [bellows.uart] Sending: b'8520dd7e'
2021-09-10 16:58:39 DEBUG (MainThread) [bellows.ezsp.protocol] Application frame 170 (getValue) received: b'0001f3'
2021-09-10 16:58:39 DEBUG (MainThread) [bellows.zigbee.application] Free buffers status EzspStatus.SUCCESS, value: 243
2021-09-10 16:58:39 DEBUG (MainThread) [bellows.zigbee.application] ezsp_counters: [MAC_RX_BROADCAST = 3616, MAC_TX_BROADCAST = 6754, MAC_RX_UNICAST = 2298, MAC_TX_UNICAST_SUCCESS = 525, MAC_TX_UNICAST_RETRY = 743, MAC_TX_UNICAST_FAILED = 197, APS_DATA_RX_BROADCAST = 12, APS_DATA_TX_BROADCAST = 12, APS_DATA_RX_UNICAST = 478, APS_DATA_TX_UNICAST_SUCCESS = 128, APS_DATA_TX_UNICAST_RETRY = 39, APS_DATA_TX_UNICAST_FAILED = 19, ROUTE_DISCOVERY_INITIATED = 6, NEIGHBOR_ADDED = 0, NEIGHBOR_REMOVED = 0, NEIGHBOR_STALE = 0, JOIN_INDICATION = 1, CHILD_REMOVED = 2, ASH_OVERFLOW_ERROR = 0, ASH_FRAMING_ERROR = 0, ASH_OVERRUN_ERROR = 0, NWK_FRAME_COUNTER_FAILURE = 0, APS_FRAME_COUNTER_FAILURE = 0, UTILITY = 0, APS_LINK_KEY_NOT_AUTHORIZED = 0, NWK_DECRYPTION_FAILURE = 0, APS_DECRYPTION_FAILURE = 0, ALLOCATE_PACKET_BUFFER_FAILURE = 0, RELAYED_UNICAST = 0, PHY_TO_MAC_QUEUE_LIMIT_REACHED = 0, PACKET_VALIDATE_LIBRARY_DROPPED_COUNT = 0, TYPE_NWK_RETRY_OVERFLOW = 0, PHY_CCA_FAIL_COUNT = 4, BROADCAST_TABLE_FULL = 0, PTA_LO_PRI_REQUESTED = 0, PTA_HI_PRI_REQUESTED = 0, PTA_LO_PRI_DENIED = 0, PTA_HI_PRI_DENIED = 0, PTA_LO_PRI_TX_ABORTED = 0, PTA_HI_PRI_TX_ABORTED = 0, ADDRESS_CONFLICT_SENT = 0, EZSP_FREE_BUFFERS = 243]
2021-09-10 16:58:49 DEBUG (MainThread) [bellows.ezsp.protocol] Send command readCounters: ()
2021-09-10 16:58:49 DEBUG (bellows.thread_0) [bellows.uart] Sending: b'750c21a9a52a86f27e'
2021-09-10 16:58:50 DEBUG (bellows.thread_0) [bellows.uart] Data frame: b'500ca1a9a52a3bb217945025a15590499c4e26abecce6f8bfec66389fc7e3fa7ebcdde6f8fffc7dbd5d2698c4623a9ec763ba5ea758241984c2613b1e070381c0e07bbe5ca658a459a4d9e4f9ff7c3d9d46a35a251904824fc927e'
2021-09-10 16:58:50 DEBUG (bellows.thread_0) [bellows.uart] Sending: b'8610be7e'
2021-09-10 16:58:50 DEBUG (MainThread) [bellows.ezsp.protocol] Application frame 241 (readCounters) received: b'2e004e001a000b000200000001000100080003000000000000000000000000000000000000000000000000000000000000000000000000000000000000000000000000000000000000000000000000000000'
2021-09-10 16:58:50 DEBUG (MainThread) [bellows.ezsp.protocol] Send command getValue: (<EzspValueId.VALUE_FREE_BUFFERS: 3>,)
2021-09-10 16:58:50 DEBUG (bellows.thread_0) [bellows.uart] Sending: b'060d21a9fe2a16c6c57e'
2021-09-10 16:58:50 DEBUG (bellows.thread_0) [bellows.uart] Data frame: b'610da1a9fe2a15b3aad1c27e'
2021-09-10 16:58:50 DEBUG (bellows.thread_0) [bellows.uart] Sending: b'87009f7e'
2021-09-10 16:58:50 DEBUG (MainThread) [bellows.ezsp.protocol] Application frame 170 (getValue) received: b'0001f3'
2021-09-10 16:58:50 DEBUG (MainThread) [bellows.zigbee.application] Free buffers status EzspStatus.SUCCESS, value: 243
2021-09-10 16:58:50 DEBUG (MainThread) [bellows.zigbee.application] ezsp_counters: [MAC_RX_BROADCAST = 3617, MAC_TX_BROADCAST = 6755, MAC_RX_UNICAST = 2299, MAC_TX_UNICAST_SUCCESS = 525, MAC_TX_UNICAST_RETRY = 743, MAC_TX_UNICAST_FAILED = 197, APS_DATA_RX_BROADCAST = 12, APS_DATA_TX_BROADCAST = 12, APS_DATA_RX_UNICAST = 478, APS_DATA_TX_UNICAST_SUCCESS = 128, APS_DATA_TX_UNICAST_RETRY = 39, APS_DATA_TX_UNICAST_FAILED = 19, ROUTE_DISCOVERY_INITIATED = 6, NEIGHBOR_ADDED = 0, NEIGHBOR_REMOVED = 0, NEIGHBOR_STALE = 0, JOIN_INDICATION = 1, CHILD_REMOVED = 2, ASH_OVERFLOW_ERROR = 0, ASH_FRAMING_ERROR = 0, ASH_OVERRUN_ERROR = 0, NWK_FRAME_COUNTER_FAILURE = 0, APS_FRAME_COUNTER_FAILURE = 0, UTILITY = 0, APS_LINK_KEY_NOT_AUTHORIZED = 0, NWK_DECRYPTION_FAILURE = 0, APS_DECRYPTION_FAILURE = 0, ALLOCATE_PACKET_BUFFER_FAILURE = 0, RELAYED_UNICAST = 0, PHY_TO_MAC_QUEUE_LIMIT_REACHED = 0, PACKET_VALIDATE_LIBRARY_DROPPED_COUNT = 0, TYPE_NWK_RETRY_OVERFLOW = 0, PHY_CCA_FAIL_COUNT = 4, BROADCAST_TABLE_FULL = 0, PTA_LO_PRI_REQUESTED = 0, PTA_HI_PRI_REQUESTED = 0, PTA_LO_PRI_DENIED = 0, PTA_HI_PRI_DENIED = 0, PTA_LO_PRI_TX_ABORTED = 0, PTA_HI_PRI_TX_ABORTED = 0, ADDRESS_CONFLICT_SENT = 0, EZSP_FREE_BUFFERS = 243]
2021-09-10 16:59:00 DEBUG (MainThread) [bellows.ezsp.protocol] Send command readCounters: ()
2021-09-10 16:59:00 DEBUG (bellows.thread_0) [bellows.uart] Sending: b'171221a9a52a99587e'
2021-09-10 17:00:40 ERROR (MainThread) [homeassistant] Error doing job: Future exception was never retrieved
Traceback (most recent call last):
  File "/usr/local/lib/python3.9/concurrent/futures/thread.py", line 52, in run
    result = self.fn(*self.args, **self.kwargs)
TypeError: update() takes 1 positional argument but 2 were given
2021-09-10 17:05:41 ERROR (MainThread) [homeassistant] Error doing job: Future exception was never retrieved
Traceback (most recent call last):
  File "/usr/local/lib/python3.9/concurrent/futures/thread.py", line 52, in run
    result = self.fn(*self.args, **self.kwargs)
TypeError: update() takes 1 positional argument but 2 were given
2021-09-10 17:10:42 ERROR (MainThread) [homeassistant] Error doing job: Future exception was never retrieved
Traceback (most recent call last):
  File "/usr/local/lib/python3.9/concurrent/futures/thread.py", line 52, in run
    result = self.fn(*self.args, **self.kwargs)
TypeError: update() takes 1 positional argument but 2 were given
2021-09-10 17:15:16 ERROR (MainThread) [homeassistant.components.nws] Error requesting NWS observation station SAUC1 data: 503, message='Service Unavailable', url=URL('https://api.weather.gov/stations/SAUC1/observations')
2021-09-10 17:15:43 ERROR (MainThread) [homeassistant] Error doing job: Future exception was never retrieved
Traceback (most recent call last):
  File "/usr/local/lib/python3.9/concurrent/futures/thread.py", line 52, in run
    result = self.fn(*self.args, **self.kwargs)
TypeError: update() takes 1 positional argument but 2 were given
2021-09-10 17:20:44 ERROR (MainThread) [homeassistant] Error doing job: Future exception was never retrieved
Traceback (most recent call last):
  File "/usr/local/lib/python3.9/concurrent/futures/thread.py", line 52, in run
    result = self.fn(*self.args, **self.kwargs)
TypeError: update() takes 1 positional argument but 2 were given
2021-09-10 17:25:28 ERROR (MainThread) [iotawattpy.connection] Err: 
2021-09-10 17:25:28 ERROR (MainThread) [homeassistant.components.iotawatt.coordinator] Unexpected error fetching 192.168.20.195 data: 'NoneType' object has no attribute 'text'
Traceback (most recent call last):
  File "/usr/src/homeassistant/homeassistant/helpers/update_coordinator.py", line 187, in _async_refresh
    self.data = await self._async_update_data()
  File "/usr/src/homeassistant/homeassistant/components/iotawatt/coordinator.py", line 55, in _async_update_data
    await self.api.update()
  File "/usr/local/lib/python3.9/site-packages/iotawattpy/iotawatt.py", line 66, in update
    await self._refreshSensors(timespan)
  File "/usr/local/lib/python3.9/site-packages/iotawattpy/iotawatt.py", line 100, in _refreshSensors
    results = response.text
AttributeError: 'NoneType' object has no attribute 'text'
2021-09-10 17:25:45 ERROR (MainThread) [homeassistant] Error doing job: Future exception was never retrieved
Traceback (most recent call last):
  File "/usr/local/lib/python3.9/concurrent/futures/thread.py", line 52, in run
    result = self.fn(*self.args, **self.kwargs)
TypeError: update() takes 1 positional argument but 2 were given
2021-09-10 17:30:46 ERROR (MainThread) [homeassistant] Error doing job: Future exception was never retrieved
Traceback (most recent call last):
  File "/usr/local/lib/python3.9/concurrent/futures/thread.py", line 52, in run
    result = self.fn(*self.args, **self.kwargs)
TypeError: update() takes 1 positional argument but 2 were given
2021-09-10 17:35:47 ERROR (MainThread) [homeassistant] Error doing job: Future exception was never retrieved
Traceback (most recent call last):
  File "/usr/local/lib/python3.9/concurrent/futures/thread.py", line 52, in run
    result = self.fn(*self.args, **self.kwargs)
TypeError: update() takes 1 positional argument but 2 were given
2021-09-10 17:38:57 WARNING (MainThread) [bellows.zigbee.application] Watchdog heartbeat timeout: 
2021-09-10 17:40:48 ERROR (MainThread) [homeassistant] Error doing job: Future exception was never retrieved
Traceback (most recent call last):
  File "/usr/local/lib/python3.9/concurrent/futures/thread.py", line 52, in run
    result = self.fn(*self.args, **self.kwargs)
TypeError: update() takes 1 positional argument but 2 were given
2021-09-10 17:45:49 ERROR (MainThread) [homeassistant] Error doing job: Future exception was never retrieved
Traceback (most recent call last):
  File "/usr/local/lib/python3.9/concurrent/futures/thread.py", line 52, in run
    result = self.fn(*self.args, **self.kwargs)
TypeError: update() takes 1 positional argument but 2 were given
2021-09-10 17:50:50 ERROR (MainThread) [homeassistant] Error doing job: Future exception was never retrieved
Traceback (most recent call last):
  File "/usr/local/lib/python3.9/concurrent/futures/thread.py", line 52, in run
    result = self.fn(*self.args, **self.kwargs)
TypeError: update() takes 1 positional argument but 2 were given
2021-09-10 17:50:59 ERROR (MainThread) [frontend.js.latest.202108300] http://192.168.7.12:8123/frontend_latest/bbfe5c61.js:235:519 Uncaught TypeError: Cannot read properties of undefined (reading 'get')
2021-09-10 17:51:04 ERROR (MainThread) [frontend.js.latest.202108300] http://192.168.7.12:8123/frontend_latest/bbfe5c61.js:235:519 Uncaught TypeError: Cannot read properties of undefined (reading 'get')
2021-09-10 17:51:09 ERROR (MainThread) [frontend.js.latest.202108300] http://192.168.7.12:8123/frontend_latest/bbfe5c61.js:235:519 Uncaught TypeError: Cannot read properties of undefined (reading 'get')
2021-09-10 17:51:16 ERROR (MainThread) [frontend.js.latest.202108300] http://192.168.7.12:8123/frontend_latest/bbfe5c61.js:235:519 Uncaught TypeError: Cannot read properties of undefined (reading 'get')
2021-09-10 17:55:51 ERROR (MainThread) [homeassistant] Error doing job: Future exception was never retrieved
Traceback (most recent call last):
  File "/usr/local/lib/python3.9/concurrent/futures/thread.py", line 52, in run
    result = self.fn(*self.args, **self.kwargs)
TypeError: update() takes 1 positional argument but 2 were given
2021-09-10 18:00:52 ERROR (MainThread) [homeassistant] Error doing job: Future exception was never retrieved
Traceback (most recent call last):
  File "/usr/local/lib/python3.9/concurrent/futures/thread.py", line 52, in run
    result = self.fn(*self.args, **self.kwargs)
TypeError: update() takes 1 positional argument but 2 were given
2021-09-10 18:02:02 WARNING (MainThread) [bellows.zigbee.application] Watchdog heartbeat timeout: 
2021-09-10 18:02:17 WARNING (MainThread) [bellows.zigbee.application] Watchdog heartbeat timeout: 
2021-09-10 18:02:32 WARNING (MainThread) [bellows.zigbee.application] Watchdog heartbeat timeout: 
2021-09-10 18:02:47 WARNING (MainThread) [bellows.zigbee.application] Watchdog heartbeat timeout: 
2021-09-10 18:03:02 WARNING (MainThread) [bellows.zigbee.application] Watchdog heartbeat timeout: 
2021-09-10 18:05:53 ERROR (MainThread) [homeassistant] Error doing job: Future exception was never retrieved
Traceback (most recent call last):
  File "/usr/local/lib/python3.9/concurrent/futures/thread.py", line 52, in run
    result = self.fn(*self.args, **self.kwargs)
TypeError: update() takes 1 positional argument but 2 were given
2021-09-10 18:07:04 ERROR (MainThread) [homeassistant] Error doing job: Task was destroyed but it is pending!
2021-09-10 18:10:54 ERROR (MainThread) [homeassistant] Error doing job: Future exception was never retrieved
Traceback (most recent call last):
  File "/usr/local/lib/python3.9/concurrent/futures/thread.py", line 52, in run
    result = self.fn(*self.args, **self.kwargs)
TypeError: update() takes 1 positional argument but 2 were given
2021-09-10 18:15:55 ERROR (MainThread) [homeassistant] Error doing job: Future exception was never retrieved
Traceback (most recent call last):
  File "/usr/local/lib/python3.9/concurrent/futures/thread.py", line 52, in run
    result = self.fn(*self.args, **self.kwargs)
TypeError: update() takes 1 positional argument but 2 were given
2021-09-10 18:20:56 ERROR (MainThread) [homeassistant] Error doing job: Future exception was never retrieved
Traceback (most recent call last):
  File "/usr/local/lib/python3.9/concurrent/futures/thread.py", line 52, in run
    result = self.fn(*self.args, **self.kwargs)
TypeError: update() takes 1 positional argument but 2 were given
2021-09-10 18:21:48 ERROR (Thread-1607) [homeassistant.helpers.template] Template variable error: 'sensor' is undefined when rendering '{{ sensor.daily_solar_energy }}


{## Imitate available variables: ##}
{% set my_test_json = {
  "temperature": 25,
  "unit": "°C"
} %}

{% if (is_state("person.brian_mccarty", "home")) 
   or (is_state("person.amber_mccarty", "home"))  
   or (is_state("person.liam_mccarty", "home"))  
   or (is_state("person.aidan_mccarty", "home"))  
   or (is_state("person.sophia_mccarty", "home")) -%}
  Occupied
{%- else -%}
  Unoccupied
{%- endif %}

{{ states.sensor.iss_people_in_space.attributes["people"][0]["name"] }}


The temperature is {{ my_test_json.temperature }} {{ my_test_json.unit }}.

{% if is_state("sun.sun", "above_horizon") -%}
  The sun rose {{ relative_time(states.sun.sun.last_changed) }} ago.
{%- else -%}
  The sun will rise at {{ as_timestamp(strptime(state_attr("sun.sun", "next_rising"), "")) | timestamp_local }}.
{%- endif %}

For loop example getting entity values in the weather domain:

{% for state in states.weather -%}
  {%- if loop.first %}The {% elif loop.last %} and the {% else %}, the {% endif -%}
  {{ state.name | lower }} is {{state.state_with_unit}}
{%- endfor %}.'
2021-09-10 18:21:54 ERROR (Thread-1608) [homeassistant.helpers.template] Template variable error: 'statessensor' is undefined when rendering '{{ statessensor.daily_solar_energy }}


{## Imitate available variables: ##}
{% set my_test_json = {
  "temperature": 25,
  "unit": "°C"
} %}

{% if (is_state("person.brian_mccarty", "home")) 
   or (is_state("person.amber_mccarty", "home"))  
   or (is_state("person.liam_mccarty", "home"))  
   or (is_state("person.aidan_mccarty", "home"))  
   or (is_state("person.sophia_mccarty", "home")) -%}
  Occupied
{%- else -%}
  Unoccupied
{%- endif %}

{{ states.sensor.iss_people_in_space.attributes["people"][0]["name"] }}


The temperature is {{ my_test_json.temperature }} {{ my_test_json.unit }}.

{% if is_state("sun.sun", "above_horizon") -%}
  The sun rose {{ relative_time(states.sun.sun.last_changed) }} ago.
{%- else -%}
  The sun will rise at {{ as_timestamp(strptime(state_attr("sun.sun", "next_rising"), "")) | timestamp_local }}.
{%- endif %}

For loop example getting entity values in the weather domain:

{% for state in states.weather -%}
  {%- if loop.first %}The {% elif loop.last %} and the {% else %}, the {% endif -%}
  {{ state.name | lower }} is {{state.state_with_unit}}
{%- endfor %}.'
2021-09-10 18:21:55 ERROR (Thread-1609) [homeassistant.helpers.template] Template variable error: 'sensor' is undefined when rendering '{{ states,sensor.daily_solar_energy }}


{## Imitate available variables: ##}
{% set my_test_json = {
  "temperature": 25,
  "unit": "°C"
} %}

{% if (is_state("person.brian_mccarty", "home")) 
   or (is_state("person.amber_mccarty", "home"))  
   or (is_state("person.liam_mccarty", "home"))  
   or (is_state("person.aidan_mccarty", "home"))  
   or (is_state("person.sophia_mccarty", "home")) -%}
  Occupied
{%- else -%}
  Unoccupied
{%- endif %}

{{ states.sensor.iss_people_in_space.attributes["people"][0]["name"] }}


The temperature is {{ my_test_json.temperature }} {{ my_test_json.unit }}.

{% if is_state("sun.sun", "above_horizon") -%}
  The sun rose {{ relative_time(states.sun.sun.last_changed) }} ago.
{%- else -%}
  The sun will rise at {{ as_timestamp(strptime(state_attr("sun.sun", "next_rising"), "")) | timestamp_local }}.
{%- endif %}

For loop example getting entity values in the weather domain:

{% for state in states.weather -%}
  {%- if loop.first %}The {% elif loop.last %} and the {% else %}, the {% endif -%}
  {{ state.name | lower }} is {{state.state_with_unit}}
{%- endfor %}.'
2021-09-10 18:22:35 WARNING (Thread-1611) [homeassistant.helpers.template] Template variable warning: 'homeassistant.helpers.template.TemplateState object' has no attribute 'stat' when rendering '{{ states.sensor.daily_solar_energy.stat }}


{## Imitate available variables: ##}
{% set my_test_json = {
  "temperature": 25,
  "unit": "°C"
} %}

{% if (is_state("person.brian_mccarty", "home")) 
   or (is_state("person.amber_mccarty", "home"))  
   or (is_state("person.liam_mccarty", "home"))  
   or (is_state("person.aidan_mccarty", "home"))  
   or (is_state("person.sophia_mccarty", "home")) -%}
  Occupied
{%- else -%}
  Unoccupied
{%- endif %}

{{ states.sensor.iss_people_in_space.attributes["people"][0]["name"] }}


The temperature is {{ my_test_json.temperature }} {{ my_test_json.unit }}.

{% if is_state("sun.sun", "above_horizon") -%}
  The sun rose {{ relative_time(states.sun.sun.last_changed) }} ago.
{%- else -%}
  The sun will rise at {{ as_timestamp(strptime(state_attr("sun.sun", "next_rising"), "")) | timestamp_local }}.
{%- endif %}

For loop example getting entity values in the weather domain:

{% for state in states.weather -%}
  {%- if loop.first %}The {% elif loop.last %} and the {% else %}, the {% endif -%}
  {{ state.name | lower }} is {{state.state_with_unit}}
{%- endfor %}.'
2021-09-10 18:22:35 WARNING (MainThread) [homeassistant.helpers.template] Template variable warning: 'homeassistant.helpers.template.TemplateState object' has no attribute 'stat' when rendering '{{ states.sensor.daily_solar_energy.stat }}


{## Imitate available variables: ##}
{% set my_test_json = {
  "temperature": 25,
  "unit": "°C"
} %}

{% if (is_state("person.brian_mccarty", "home")) 
   or (is_state("person.amber_mccarty", "home"))  
   or (is_state("person.liam_mccarty", "home"))  
   or (is_state("person.aidan_mccarty", "home"))  
   or (is_state("person.sophia_mccarty", "home")) -%}
  Occupied
{%- else -%}
  Unoccupied
{%- endif %}

{{ states.sensor.iss_people_in_space.attributes["people"][0]["name"] }}


The temperature is {{ my_test_json.temperature }} {{ my_test_json.unit }}.

{% if is_state("sun.sun", "above_horizon") -%}
  The sun rose {{ relative_time(states.sun.sun.last_changed) }} ago.
{%- else -%}
  The sun will rise at {{ as_timestamp(strptime(state_attr("sun.sun", "next_rising"), "")) | timestamp_local }}.
{%- endif %}

For loop example getting entity values in the weather domain:

{% for state in states.weather -%}
  {%- if loop.first %}The {% elif loop.last %} and the {% else %}, the {% endif -%}
  {{ state.name | lower }} is {{state.state_with_unit}}
{%- endfor %}.'
2021-09-10 18:22:35 WARNING (MainThread) [homeassistant.helpers.template] Template variable warning: 'homeassistant.helpers.template.TemplateState object' has no attribute 'stat' when rendering '{{ states.sensor.daily_solar_energy.stat }}


{## Imitate available variables: ##}
{% set my_test_json = {
  "temperature": 25,
  "unit": "°C"
} %}

{% if (is_state("person.brian_mccarty", "home")) 
   or (is_state("person.amber_mccarty", "home"))  
   or (is_state("person.liam_mccarty", "home"))  
   or (is_state("person.aidan_mccarty", "home"))  
   or (is_state("person.sophia_mccarty", "home")) -%}
  Occupied
{%- else -%}
  Unoccupied
{%- endif %}

{{ states.sensor.iss_people_in_space.attributes["people"][0]["name"] }}


The temperature is {{ my_test_json.temperature }} {{ my_test_json.unit }}.

{% if is_state("sun.sun", "above_horizon") -%}
  The sun rose {{ relative_time(states.sun.sun.last_changed) }} ago.
{%- else -%}
  The sun will rise at {{ as_timestamp(strptime(state_attr("sun.sun", "next_rising"), "")) | timestamp_local }}.
{%- endif %}

For loop example getting entity values in the weather domain:

{% for state in states.weather -%}
  {%- if loop.first %}The {% elif loop.last %} and the {% else %}, the {% endif -%}
  {{ state.name | lower }} is {{state.state_with_unit}}
{%- endfor %}.'
2021-09-10 18:22:35 WARNING (Thread-1612) [homeassistant.helpers.template] Template variable warning: 'homeassistant.helpers.template.TemplateState object' has no attribute 'stats' when rendering '{{ states.sensor.daily_solar_energy.stats }}


{## Imitate available variables: ##}
{% set my_test_json = {
  "temperature": 25,
  "unit": "°C"
} %}

{% if (is_state("person.brian_mccarty", "home")) 
   or (is_state("person.amber_mccarty", "home"))  
   or (is_state("person.liam_mccarty", "home"))  
   or (is_state("person.aidan_mccarty", "home"))  
   or (is_state("person.sophia_mccarty", "home")) -%}
  Occupied
{%- else -%}
  Unoccupied
{%- endif %}

{{ states.sensor.iss_people_in_space.attributes["people"][0]["name"] }}


The temperature is {{ my_test_json.temperature }} {{ my_test_json.unit }}.

{% if is_state("sun.sun", "above_horizon") -%}
  The sun rose {{ relative_time(states.sun.sun.last_changed) }} ago.
{%- else -%}
  The sun will rise at {{ as_timestamp(strptime(state_attr("sun.sun", "next_rising"), "")) | timestamp_local }}.
{%- endif %}

For loop example getting entity values in the weather domain:

{% for state in states.weather -%}
  {%- if loop.first %}The {% elif loop.last %} and the {% else %}, the {% endif -%}
  {{ state.name | lower }} is {{state.state_with_unit}}
{%- endfor %}.'
2021-09-10 18:22:35 WARNING (MainThread) [homeassistant.helpers.template] Template variable warning: 'homeassistant.helpers.template.TemplateState object' has no attribute 'stats' when rendering '{{ states.sensor.daily_solar_energy.stats }}


{## Imitate available variables: ##}
{% set my_test_json = {
  "temperature": 25,
  "unit": "°C"
} %}

{% if (is_state("person.brian_mccarty", "home")) 
   or (is_state("person.amber_mccarty", "home"))  
   or (is_state("person.liam_mccarty", "home"))  
   or (is_state("person.aidan_mccarty", "home"))  
   or (is_state("person.sophia_mccarty", "home")) -%}
  Occupied
{%- else -%}
  Unoccupied
{%- endif %}

{{ states.sensor.iss_people_in_space.attributes["people"][0]["name"] }}


The temperature is {{ my_test_json.temperature }} {{ my_test_json.unit }}.

{% if is_state("sun.sun", "above_horizon") -%}
  The sun rose {{ relative_time(states.sun.sun.last_changed) }} ago.
{%- else -%}
  The sun will rise at {{ as_timestamp(strptime(state_attr("sun.sun", "next_rising"), "")) | timestamp_local }}.
{%- endif %}

For loop example getting entity values in the weather domain:

{% for state in states.weather -%}
  {%- if loop.first %}The {% elif loop.last %} and the {% else %}, the {% endif -%}
  {{ state.name | lower }} is {{state.state_with_unit}}
{%- endfor %}.'
2021-09-10 18:22:35 WARNING (MainThread) [homeassistant.helpers.template] Template variable warning: 'homeassistant.helpers.template.TemplateState object' has no attribute 'stats' when rendering '{{ states.sensor.daily_solar_energy.stats }}


{## Imitate available variables: ##}
{% set my_test_json = {
  "temperature": 25,
  "unit": "°C"
} %}

{% if (is_state("person.brian_mccarty", "home")) 
   or (is_state("person.amber_mccarty", "home"))  
   or (is_state("person.liam_mccarty", "home"))  
   or (is_state("person.aidan_mccarty", "home"))  
   or (is_state("person.sophia_mccarty", "home")) -%}
  Occupied
{%- else -%}
  Unoccupied
{%- endif %}

{{ states.sensor.iss_people_in_space.attributes["people"][0]["name"] }}


The temperature is {{ my_test_json.temperature }} {{ my_test_json.unit }}.

{% if is_state("sun.sun", "above_horizon") -%}
  The sun rose {{ relative_time(states.sun.sun.last_changed) }} ago.
{%- else -%}
  The sun will rise at {{ as_timestamp(strptime(state_attr("sun.sun", "next_rising"), "")) | timestamp_local }}.
{%- endif %}

For loop example getting entity values in the weather domain:

{% for state in states.weather -%}
  {%- if loop.first %}The {% elif loop.last %} and the {% else %}, the {% endif -%}
  {{ state.name | lower }} is {{state.state_with_unit}}
{%- endfor %}.'
2021-09-10 18:25:57 ERROR (MainThread) [homeassistant] Error doing job: Future exception was never retrieved
Traceback (most recent call last):
  File "/usr/local/lib/python3.9/concurrent/futures/thread.py", line 52, in run
    result = self.fn(*self.args, **self.kwargs)
TypeError: update() takes 1 positional argument but 2 were given
2021-09-10 18:30:58 ERROR (MainThread) [homeassistant] Error doing job: Future exception was never retrieved
Traceback (most recent call last):
  File "/usr/local/lib/python3.9/concurrent/futures/thread.py", line 52, in run
    result = self.fn(*self.args, **self.kwargs)
TypeError: update() takes 1 positional argument but 2 were given
2021-09-10 18:31:41 WARNING (MainThread) [homeassistant.components.template.template_entity] Template loop detected while processing event: <Event state_changed[L]: entity_id=sensor.sensor_count, old_state=<state sensor.sensor_count=447; friendly_name=Number of Sensors @ 2021-09-10T18:31:39.337526-07:00>, new_state=<state sensor.sensor_count=472; friendly_name=Number of Sensors @ 2021-09-10T18:31:40.660282-07:00>>, skipping template render for Template[{{ states.sensor | rejectattr('state', 'eq', 'unavailable') | list | count }}]
2021-09-10 18:33:13 WARNING (MainThread) [homeassistant.helpers.service] Unable to find referenced entities light.hue_lightstrip_2
2021-09-10 18:35:59 ERROR (MainThread) [homeassistant] Error doing job: Future exception was never retrieved
Traceback (most recent call last):
  File "/usr/local/lib/python3.9/concurrent/futures/thread.py", line 52, in run
    result = self.fn(*self.args, **self.kwargs)
TypeError: update() takes 1 positional argument but 2 were given
2021-09-10 18:41:00 ERROR (MainThread) [homeassistant] Error doing job: Future exception was never retrieved
Traceback (most recent call last):
  File "/usr/local/lib/python3.9/concurrent/futures/thread.py", line 52, in run
    result = self.fn(*self.args, **self.kwargs)
TypeError: update() takes 1 positional argument but 2 were given
2021-09-10 18:46:01 ERROR (MainThread) [homeassistant] Error doing job: Future exception was never retrieved
Traceback (most recent call last):
  File "/usr/local/lib/python3.9/concurrent/futures/thread.py", line 52, in run
    result = self.fn(*self.args, **self.kwargs)
TypeError: update() takes 1 positional argument but 2 were given
2021-09-10 18:47:03 ERROR (MainThread) [homeassistant] Error doing job: Task exception was never retrieved
Traceback (most recent call last):
  File "/usr/local/lib/python3.9/site-packages/zigpy/device.py", line 287, in request
    raise zigpy.exceptions.DeliveryError(
zigpy.exceptions.DeliveryError: [0xa8ad:1:0x0500]: Message send failure
2021-09-10 18:51:02 ERROR (MainThread) [homeassistant] Error doing job: Future exception was never retrieved
Traceback (most recent call last):
  File "/usr/local/lib/python3.9/concurrent/futures/thread.py", line 52, in run
    result = self.fn(*self.args, **self.kwargs)
TypeError: update() takes 1 positional argument but 2 were given
2021-09-10 18:51:29 WARNING (MainThread) [bellows.zigbee.application] Watchdog heartbeat timeout: 
2021-09-10 18:56:03 ERROR (MainThread) [homeassistant] Error doing job: Future exception was never retrieved
Traceback (most recent call last):
  File "/usr/local/lib/python3.9/concurrent/futures/thread.py", line 52, in run
    result = self.fn(*self.args, **self.kwargs)
TypeError: update() takes 1 positional argument but 2 were given
2021-09-10 19:01:04 ERROR (MainThread) [homeassistant] Error doing job: Future exception was never retrieved
Traceback (most recent call last):
  File "/usr/local/lib/python3.9/concurrent/futures/thread.py", line 52, in run
    result = self.fn(*self.args, **self.kwargs)
TypeError: update() takes 1 positional argument but 2 were given
2021-09-10 19:02:46 WARNING (MainThread) [homeassistant.components.cloud.google_config] Error reporting state - 5: Requested entity was not found.
2021-09-10 19:05:44 ERROR (MainThread) [frontend.js.latest.202108300] http://192.168.7.12:8123/frontend_latest/bbfe5c61.js:235:519 Uncaught TypeError: Cannot read properties of undefined (reading 'get')
2021-09-10 19:05:51 ERROR (MainThread) [frontend.js.latest.202108300] http://192.168.7.12:8123/frontend_latest/bbfe5c61.js:235:519 Uncaught TypeError: Cannot read properties of undefined (reading 'get')
2021-09-10 19:05:56 ERROR (MainThread) [frontend.js.latest.202108300] http://192.168.7.12:8123/frontend_latest/bbfe5c61.js:235:519 Uncaught TypeError: Cannot read properties of undefined (reading 'get')
2021-09-10 19:06:03 ERROR (MainThread) [frontend.js.latest.202108300] http://192.168.7.12:8123/frontend_latest/bbfe5c61.js:235:519 Uncaught TypeError: Cannot read properties of undefined (reading 'get')
2021-09-10 19:06:05 ERROR (MainThread) [homeassistant] Error doing job: Future exception was never retrieved
Traceback (most recent call last):
  File "/usr/local/lib/python3.9/concurrent/futures/thread.py", line 52, in run
    result = self.fn(*self.args, **self.kwargs)
TypeError: update() takes 1 positional argument but 2 were given
2021-09-10 19:07:08 WARNING (MainThread) [homeassistant.helpers.service] Unable to find referenced entities scene.kitchen_sink_on
2021-09-10 19:07:09 WARNING (MainThread) [homeassistant.helpers.service] Unable to find referenced entities light.hue_lightstrip_2
2021-09-10 19:11:06 ERROR (MainThread) [homeassistant] Error doing job: Future exception was never retrieved
Traceback (most recent call last):
  File "/usr/local/lib/python3.9/concurrent/futures/thread.py", line 52, in run
    result = self.fn(*self.args, **self.kwargs)
TypeError: update() takes 1 positional argument but 2 were given
2021-09-10 19:16:07 ERROR (MainThread) [homeassistant] Error doing job: Future exception was never retrieved
Traceback (most recent call last):
  File "/usr/local/lib/python3.9/concurrent/futures/thread.py", line 52, in run
    result = self.fn(*self.args, **self.kwargs)
TypeError: update() takes 1 positional argument but 2 were given
2021-09-10 19:21:08 ERROR (MainThread) [homeassistant] Error doing job: Future exception was never retrieved
Traceback (most recent call last):
  File "/usr/local/lib/python3.9/concurrent/futures/thread.py", line 52, in run
    result = self.fn(*self.args, **self.kwargs)
TypeError: update() takes 1 positional argument but 2 were given
2021-09-10 19:26:09 ERROR (MainThread) [homeassistant] Error doing job: Future exception was never retrieved
Traceback (most recent call last):
  File "/usr/local/lib/python3.9/concurrent/futures/thread.py", line 52, in run
    result = self.fn(*self.args, **self.kwargs)
TypeError: update() takes 1 positional argument but 2 were given
2021-09-10 19:31:10 ERROR (MainThread) [homeassistant] Error doing job: Future exception was never retrieved
Traceback (most recent call last):
  File "/usr/local/lib/python3.9/concurrent/futures/thread.py", line 52, in run
    result = self.fn(*self.args, **self.kwargs)
TypeError: update() takes 1 positional argument but 2 were given
2021-09-10 19:36:11 ERROR (MainThread) [homeassistant] Error doing job: Future exception was never retrieved
Traceback (most recent call last):
  File "/usr/local/lib/python3.9/concurrent/futures/thread.py", line 52, in run
    result = self.fn(*self.args, **self.kwargs)
TypeError: update() takes 1 positional argument but 2 were given
2021-09-10 19:38:56 WARNING (MainThread) [homeassistant.components.cloud.google_config] Error reporting state - 5: Requested entity was not found.
2021-09-10 19:41:12 ERROR (MainThread) [homeassistant] Error doing job: Future exception was never retrieved
Traceback (most recent call last):
  File "/usr/local/lib/python3.9/concurrent/futures/thread.py", line 52, in run
    result = self.fn(*self.args, **self.kwargs)
TypeError: update() takes 1 positional argument but 2 were given
2021-09-10 19:42:27 ERROR (MainThread) [homeassistant.components.shelly] Timeout fetching shellyem-B05A54 data
2021-09-10 19:44:40 WARNING (MainThread) [homeassistant.components.template.template_entity] Template loop detected while processing event: <Event state_changed[L]: entity_id=sensor.entities_count, old_state=<state sensor.entities_count=751; friendly_name=Number of Entities @ 2021-09-10T19:42:40.237009-07:00>, new_state=<state sensor.entities_count=728; friendly_name=Number of Entities @ 2021-09-10T19:43:40.248500-07:00>>, skipping template render for Template[{{ states | rejectattr('state', 'eq', 'unavailable') | list | count}}]
2021-09-10 19:44:41 ERROR (MainThread) [homeassistant.components.shelly] Timeout fetching shellyem-B05A54 data
2021-09-10 19:46:13 ERROR (MainThread) [homeassistant] Error doing job: Future exception was never retrieved
Traceback (most recent call last):
  File "/usr/local/lib/python3.9/concurrent/futures/thread.py", line 52, in run
    result = self.fn(*self.args, **self.kwargs)
TypeError: update() takes 1 positional argument but 2 were given
2021-09-10 19:48:27 ERROR (MainThread) [frontend.js.latest.202108300] http://192.168.7.12:8123/frontend_latest/bbfe5c61.js:235:519 Uncaught TypeError: Cannot read properties of undefined (reading 'get')
2021-09-10 19:48:33 ERROR (MainThread) [frontend.js.latest.202108300] http://192.168.7.12:8123/frontend_latest/bbfe5c61.js:235:519 Uncaught TypeError: Cannot read properties of undefined (reading 'get')
2021-09-10 19:48:38 ERROR (MainThread) [frontend.js.latest.202108300] http://192.168.7.12:8123/frontend_latest/bbfe5c61.js:235:519 Uncaught TypeError: Cannot read properties of undefined (reading 'get')
2021-09-10 19:48:45 ERROR (MainThread) [frontend.js.latest.202108300] http://192.168.7.12:8123/frontend_latest/bbfe5c61.js:235:519 Uncaught TypeError: Cannot read properties of undefined (reading 'get')
2021-09-10 19:48:47 WARNING (MainThread) [homeassistant.components.cloud.google_config] Error reporting state - 5: Requested entity was not found.
2021-09-10 19:51:14 ERROR (MainThread) [homeassistant] Error doing job: Future exception was never retrieved
Traceback (most recent call last):
  File "/usr/local/lib/python3.9/concurrent/futures/thread.py", line 52, in run
    result = self.fn(*self.args, **self.kwargs)
TypeError: update() takes 1 positional argument but 2 were given
2021-09-10 19:54:28 ERROR (MainThread) [homeassistant.components.template.cover] Received invalid cover is_on state: unavailable. Expected: open, opening, closed, closing, true, false
2021-09-10 19:54:31 WARNING (MainThread) [homeassistant.components.sensor] Entity sensor.cpu_temp (<class 'homeassistant.components.command_line.sensor.CommandSensor'>) with device_class None reports a temperature in °C which will be converted to °F. Temperature conversion for entities without correct device_class is deprecated and will be removed from Home Assistant Core 2022.3. Please update your configuration if device_class is manually configured, otherwise create a bug report at https://github.com/home-assistant/core/issues?q=is%3Aopen+is%3Aissue+label%3A%22integration%3A+command_line%22
2021-09-10 19:54:31 WARNING (MainThread) [homeassistant.components.template.template_entity] Template loop detected while processing event: <Event state_changed[L]: entity_id=sensor.sensor_count, old_state=<state sensor.sensor_count=470; friendly_name=Number of Sensors @ 2021-09-10T19:54:28.763399-07:00>, new_state=<state sensor.sensor_count=495; friendly_name=Number of Sensors @ 2021-09-10T19:54:30.565816-07:00>>, skipping template render for Template[{{ states.sensor | rejectattr('state', 'eq', 'unavailable') | list | count }}]
2021-09-10 19:56:15 ERROR (MainThread) [homeassistant] Error doing job: Future exception was never retrieved
Traceback (most recent call last):
  File "/usr/local/lib/python3.9/concurrent/futures/thread.py", line 52, in run
    result = self.fn(*self.args, **self.kwargs)
TypeError: update() takes 1 positional argument but 2 were given
2021-09-10 19:56:25 ERROR (MainThread) [homeassistant.components.template.cover] Received invalid cover is_on state: unavailable. Expected: open, opening, closed, closing, true, false
2021-09-10 19:56:27 WARNING (MainThread) [homeassistant.components.template.template_entity] Template loop detected while processing event: <Event state_changed[L]: entity_id=sensor.sensor_count, old_state=<state sensor.sensor_count=477; friendly_name=Number of Sensors @ 2021-09-10T19:56:23.442435-07:00>, new_state=<state sensor.sensor_count=502; friendly_name=Number of Sensors @ 2021-09-10T19:56:25.211797-07:00>>, skipping template render for Template[{{ states.sensor | rejectattr('state', 'eq', 'unavailable') | list | count }}]
2021-09-10 19:56:29 WARNING (MainThread) [homeassistant.components.sensor] Entity sensor.cpu_temp (<class 'homeassistant.components.command_line.sensor.CommandSensor'>) with device_class None reports a temperature in °C which will be converted to °F. Temperature conversion for entities without correct device_class is deprecated and will be removed from Home Assistant Core 2022.3. Please update your configuration if device_class is manually configured, otherwise create a bug report at https://github.com/home-assistant/core/issues?q=is%3Aopen+is%3Aissue+label%3A%22integration%3A+command_line%22
2021-09-10 19:56:30 WARNING (MainThread) [homeassistant.components.template.template_entity] Template loop detected while processing event: <Event state_changed[L]: entity_id=sensor.sensor_count, old_state=<state sensor.sensor_count=491; friendly_name=Number of Sensors @ 2021-09-10T19:56:28.536045-07:00>, new_state=<state sensor.sensor_count=489; friendly_name=Number of Sensors @ 2021-09-10T19:56:29.749726-07:00>>, skipping template render for Template[{{ states.sensor | rejectattr('state', 'eq', 'unavailable') | list | count }}]
2021-09-10 19:56:58 ERROR (MainThread) [homeassistant.components.roku.coordinator] Unexpected error fetching roku data: Session is closed
Traceback (most recent call last):
  File "/usr/src/homeassistant/homeassistant/helpers/update_coordinator.py", line 187, in _async_refresh
    self.data = await self._async_update_data()
  File "/usr/src/homeassistant/homeassistant/components/roku/coordinator.py", line 53, in _async_update_data
    data = await self.roku.update(full_update=full_update)
  File "/usr/local/lib/python3.9/site-packages/rokuecp/rokuecp.py", line 70, in update
    updates["info"] = info = await self._get_device_info()
  File "/usr/local/lib/python3.9/site-packages/rokuecp/rokuecp.py", line 179, in _get_device_info
    res = await self._request("/query/device-info")
  File "/usr/local/lib/python3.9/site-packages/rokuecp/client.py", line 65, in _request
    response = await self._session.request(
  File "/usr/local/lib/python3.9/site-packages/aiohttp/client.py", line 381, in _request
    raise RuntimeError("Session is closed")
RuntimeError: Session is closed
2021-09-10 19:56:58 ERROR (MainThread) [hass_nabucasa.google_report_state] Unexpected error
Traceback (most recent call last):
  File "/usr/local/lib/python3.9/site-packages/hass_nabucasa/iot_base.py", line 108, in connect
    await self._handle_connection()
  File "/usr/local/lib/python3.9/site-packages/hass_nabucasa/iot_base.py", line 165, in _handle_connection
    self.client = client = await self.cloud.websession.ws_connect(
  File "/usr/local/lib/python3.9/site-packages/aiohttp/client.py", line 754, in _ws_connect
    resp = await self.request(
  File "/usr/local/lib/python3.9/site-packages/aiohttp/client.py", line 381, in _request
    raise RuntimeError("Session is closed")
RuntimeError: Session is closed
2021-09-10 19:57:03 ERROR (MainThread) [hass_nabucasa.google_report_state] Unexpected error
Traceback (most recent call last):
  File "/usr/local/lib/python3.9/site-packages/hass_nabucasa/iot_base.py", line 108, in connect
    await self._handle_connection()
  File "/usr/local/lib/python3.9/site-packages/hass_nabucasa/iot_base.py", line 165, in _handle_connection
    self.client = client = await self.cloud.websession.ws_connect(
  File "/usr/local/lib/python3.9/site-packages/aiohttp/client.py", line 754, in _ws_connect
    resp = await self.request(
  File "/usr/local/lib/python3.9/site-packages/aiohttp/client.py", line 381, in _request
    raise RuntimeError("Session is closed")
RuntimeError: Session is closed
2021-09-10 19:57:13 ERROR (MainThread) [homeassistant.components.roku.coordinator] Unexpected error fetching roku data: Session is closed
Traceback (most recent call last):
  File "/usr/src/homeassistant/homeassistant/helpers/update_coordinator.py", line 187, in _async_refresh
    self.data = await self._async_update_data()
  File "/usr/src/homeassistant/homeassistant/components/roku/coordinator.py", line 53, in _async_update_data
    data = await self.roku.update(full_update=full_update)
  File "/usr/local/lib/python3.9/site-packages/rokuecp/rokuecp.py", line 70, in update
    updates["info"] = info = await self._get_device_info()
  File "/usr/local/lib/python3.9/site-packages/rokuecp/rokuecp.py", line 179, in _get_device_info
    res = await self._request("/query/device-info")
  File "/usr/local/lib/python3.9/site-packages/rokuecp/client.py", line 65, in _request
    response = await self._session.request(
  File "/usr/local/lib/python3.9/site-packages/aiohttp/client.py", line 381, in _request
    raise RuntimeError("Session is closed")
RuntimeError: Session is closed
2021-09-10 19:57:15 ERROR (MainThread) [homeassistant.components.shelly] Unexpected error fetching shellyem-B05A54 data: 'NoneType' object has no attribute 'update'
Traceback (most recent call last):
  File "/usr/src/homeassistant/homeassistant/helpers/update_coordinator.py", line 187, in _async_refresh
    self.data = await self._async_update_data()
  File "/usr/src/homeassistant/homeassistant/components/shelly/__init__.py", line 276, in _async_update_data
    await self.device.update()
AttributeError: 'NoneType' object has no attribute 'update'
2021-09-10 19:57:17 ERROR (MainThread) [homeassistant.components.iotawatt.coordinator] Unexpected error fetching 192.168.20.195 data: Cannot send a request, as the client has been closed.
Traceback (most recent call last):
  File "/usr/src/homeassistant/homeassistant/helpers/update_coordinator.py", line 187, in _async_refresh
    self.data = await self._async_update_data()
  File "/usr/src/homeassistant/homeassistant/components/iotawatt/coordinator.py", line 55, in _async_update_data
    await self.api.update()
  File "/usr/local/lib/python3.9/site-packages/iotawattpy/iotawatt.py", line 66, in update
    await self._refreshSensors(timespan)
  File "/usr/local/lib/python3.9/site-packages/iotawattpy/iotawatt.py", line 99, in _refreshSensors
    response = await self._getInputsandOutputs()
  File "/usr/local/lib/python3.9/site-packages/iotawattpy/iotawatt.py", line 74, in _getInputsandOutputs
    return await self._connection.get(url, self._username, self._password)
  File "/usr/local/lib/python3.9/site-packages/iotawattpy/connection.py", line 18, in get
    return await self.__open(url, username=username, password=password)
  File "/usr/local/lib/python3.9/site-packages/iotawattpy/connection.py", line 37, in __open
    resp = await getattr(self._websession, method)(
  File "/usr/local/lib/python3.9/site-packages/httpx/_client.py", line 1740, in get
    return await self.request(
  File "/usr/local/lib/python3.9/site-packages/httpx/_client.py", line 1494, in request
    response = await self.send(
  File "/usr/local/lib/python3.9/site-packages/httpx/_client.py", line 1572, in send
    raise RuntimeError("Cannot send a request, as the client has been closed.")
RuntimeError: Cannot send a request, as the client has been closed.
2021-09-10 19:57:18 ERROR (MainThread) [hass_nabucasa.google_report_state] Unexpected error
Traceback (most recent call last):
  File "/usr/local/lib/python3.9/site-packages/hass_nabucasa/iot_base.py", line 108, in connect
    await self._handle_connection()
  File "/usr/local/lib/python3.9/site-packages/hass_nabucasa/iot_base.py", line 165, in _handle_connection
    self.client = client = await self.cloud.websession.ws_connect(
  File "/usr/local/lib/python3.9/site-packages/aiohttp/client.py", line 754, in _ws_connect
    resp = await self.request(
  File "/usr/local/lib/python3.9/site-packages/aiohttp/client.py", line 381, in _request
    raise RuntimeError("Session is closed")
RuntimeError: Session is closed
2021-09-10 19:57:28 ERROR (MainThread) [homeassistant.components.roku.coordinator] Unexpected error fetching roku data: Session is closed
Traceback (most recent call last):
  File "/usr/src/homeassistant/homeassistant/helpers/update_coordinator.py", line 187, in _async_refresh
    self.data = await self._async_update_data()
  File "/usr/src/homeassistant/homeassistant/components/roku/coordinator.py", line 53, in _async_update_data
    data = await self.roku.update(full_update=full_update)
  File "/usr/local/lib/python3.9/site-packages/rokuecp/rokuecp.py", line 70, in update
    updates["info"] = info = await self._get_device_info()
  File "/usr/local/lib/python3.9/site-packages/rokuecp/rokuecp.py", line 179, in _get_device_info
    res = await self._request("/query/device-info")
  File "/usr/local/lib/python3.9/site-packages/rokuecp/client.py", line 65, in _request
    response = await self._session.request(
  File "/usr/local/lib/python3.9/site-packages/aiohttp/client.py", line 381, in _request
    raise RuntimeError("Session is closed")
RuntimeError: Session is closed
2021-09-10 19:57:38 ERROR (MainThread) [hass_nabucasa.google_report_state] Unexpected error
Traceback (most recent call last):
  File "/usr/local/lib/python3.9/site-packages/hass_nabucasa/iot_base.py", line 108, in connect
    await self._handle_connection()
  File "/usr/local/lib/python3.9/site-packages/hass_nabucasa/iot_base.py", line 165, in _handle_connection
    self.client = client = await self.cloud.websession.ws_connect(
  File "/usr/local/lib/python3.9/site-packages/aiohttp/client.py", line 754, in _ws_connect
    resp = await self.request(
  File "/usr/local/lib/python3.9/site-packages/aiohttp/client.py", line 381, in _request
    raise RuntimeError("Session is closed")
RuntimeError: Session is closed
2021-09-10 19:57:43 ERROR (MainThread) [homeassistant.components.roku.coordinator] Unexpected error fetching roku data: Session is closed
Traceback (most recent call last):
  File "/usr/src/homeassistant/homeassistant/helpers/update_coordinator.py", line 187, in _async_refresh
    self.data = await self._async_update_data()
  File "/usr/src/homeassistant/homeassistant/components/roku/coordinator.py", line 53, in _async_update_data
    data = await self.roku.update(full_update=full_update)
  File "/usr/local/lib/python3.9/site-packages/rokuecp/rokuecp.py", line 70, in update
    updates["info"] = info = await self._get_device_info()
  File "/usr/local/lib/python3.9/site-packages/rokuecp/rokuecp.py", line 179, in _get_device_info
    res = await self._request("/query/device-info")
  File "/usr/local/lib/python3.9/site-packages/rokuecp/client.py", line 65, in _request
    response = await self._session.request(
  File "/usr/local/lib/python3.9/site-packages/aiohttp/client.py", line 381, in _request
    raise RuntimeError("Session is closed")
RuntimeError: Session is closed
2021-09-10 19:57:47 ERROR (MainThread) [homeassistant.components.iotawatt.coordinator] Unexpected error fetching 192.168.20.195 data: Cannot send a request, as the client has been closed.
Traceback (most recent call last):
  File "/usr/src/homeassistant/homeassistant/helpers/update_coordinator.py", line 187, in _async_refresh
    self.data = await self._async_update_data()
  File "/usr/src/homeassistant/homeassistant/components/iotawatt/coordinator.py", line 55, in _async_update_data
    await self.api.update()
  File "/usr/local/lib/python3.9/site-packages/iotawattpy/iotawatt.py", line 66, in update
    await self._refreshSensors(timespan)
  File "/usr/local/lib/python3.9/site-packages/iotawattpy/iotawatt.py", line 99, in _refreshSensors
    response = await self._getInputsandOutputs()
  File "/usr/local/lib/python3.9/site-packages/iotawattpy/iotawatt.py", line 74, in _getInputsandOutputs
    return await self._connection.get(url, self._username, self._password)
  File "/usr/local/lib/python3.9/site-packages/iotawattpy/connection.py", line 18, in get
    return await self.__open(url, username=username, password=password)
  File "/usr/local/lib/python3.9/site-packages/iotawattpy/connection.py", line 37, in __open
    resp = await getattr(self._websession, method)(
  File "/usr/local/lib/python3.9/site-packages/httpx/_client.py", line 1740, in get
    return await self.request(
  File "/usr/local/lib/python3.9/site-packages/httpx/_client.py", line 1494, in request
    response = await self.send(
  File "/usr/local/lib/python3.9/site-packages/httpx/_client.py", line 1572, in send
    raise RuntimeError("Cannot send a request, as the client has been closed.")
RuntimeError: Cannot send a request, as the client has been closed.
2021-09-10 19:57:48 ERROR (MainThread) [homeassistant.components.shelly] Unexpected error fetching shellyem-B05A54 data: 'NoneType' object has no attribute 'update'
Traceback (most recent call last):
  File "/usr/src/homeassistant/homeassistant/helpers/update_coordinator.py", line 187, in _async_refresh
    self.data = await self._async_update_data()
  File "/usr/src/homeassistant/homeassistant/components/shelly/__init__.py", line 276, in _async_update_data
    await self.device.update()
AttributeError: 'NoneType' object has no attribute 'update'
2021-09-10 19:57:50 ERROR (MainThread) [homeassistant] Error doing job: Task exception was never retrieved
Traceback (most recent call last):
  File "/usr/local/lib/python3.9/site-packages/aiohttp/http_websocket.py", line 673, in ping
    await self._send_frame(message, WSMsgType.PING)
  File "/usr/local/lib/python3.9/site-packages/aiohttp/http_websocket.py", line 643, in _send_frame
    self._write(header + mask + message)
  File "/usr/local/lib/python3.9/site-packages/aiohttp/http_websocket.py", line 660, in _write
    raise ConnectionResetError("Cannot write to closing transport")
ConnectionResetError: Cannot write to closing transport
2021-09-10 19:57:58 ERROR (MainThread) [homeassistant.components.roku.coordinator] Unexpected error fetching roku data: Session is closed
Traceback (most recent call last):
  File "/usr/src/homeassistant/homeassistant/helpers/update_coordinator.py", line 187, in _async_refresh
    self.data = await self._async_update_data()
  File "/usr/src/homeassistant/homeassistant/components/roku/coordinator.py", line 53, in _async_update_data
    data = await self.roku.update(full_update=full_update)
  File "/usr/local/lib/python3.9/site-packages/rokuecp/rokuecp.py", line 70, in update
    updates["info"] = info = await self._get_device_info()
  File "/usr/local/lib/python3.9/site-packages/rokuecp/rokuecp.py", line 179, in _get_device_info
    res = await self._request("/query/device-info")
  File "/usr/local/lib/python3.9/site-packages/rokuecp/client.py", line 65, in _request
    response = await self._session.request(
  File "/usr/local/lib/python3.9/site-packages/aiohttp/client.py", line 381, in _request
    raise RuntimeError("Session is closed")
RuntimeError: Session is closed
2021-09-10 19:58:13 ERROR (MainThread) [homeassistant.components.roku.coordinator] Unexpected error fetching roku data: Session is closed
Traceback (most recent call last):
  File "/usr/src/homeassistant/homeassistant/helpers/update_coordinator.py", line 187, in _async_refresh
    self.data = await self._async_update_data()
  File "/usr/src/homeassistant/homeassistant/components/roku/coordinator.py", line 53, in _async_update_data
    data = await self.roku.update(full_update=full_update)
  File "/usr/local/lib/python3.9/site-packages/rokuecp/rokuecp.py", line 70, in update
    updates["info"] = info = await self._get_device_info()
  File "/usr/local/lib/python3.9/site-packages/rokuecp/rokuecp.py", line 179, in _get_device_info
    res = await self._request("/query/device-info")
  File "/usr/local/lib/python3.9/site-packages/rokuecp/client.py", line 65, in _request
    response = await self._session.request(
  File "/usr/local/lib/python3.9/site-packages/aiohttp/client.py", line 381, in _request
    raise RuntimeError("Session is closed")
RuntimeError: Session is closed
2021-09-10 19:58:17 ERROR (MainThread) [homeassistant.components.iotawatt.coordinator] Unexpected error fetching 192.168.20.195 data: Cannot send a request, as the client has been closed.
Traceback (most recent call last):
  File "/usr/src/homeassistant/homeassistant/helpers/update_coordinator.py", line 187, in _async_refresh
    self.data = await self._async_update_data()
  File "/usr/src/homeassistant/homeassistant/components/iotawatt/coordinator.py", line 55, in _async_update_data
    await self.api.update()
  File "/usr/local/lib/python3.9/site-packages/iotawattpy/iotawatt.py", line 66, in update
    await self._refreshSensors(timespan)
  File "/usr/local/lib/python3.9/site-packages/iotawattpy/iotawatt.py", line 99, in _refreshSensors
    response = await self._getInputsandOutputs()
  File "/usr/local/lib/python3.9/site-packages/iotawattpy/iotawatt.py", line 74, in _getInputsandOutputs
    return await self._connection.get(url, self._username, self._password)
  File "/usr/local/lib/python3.9/site-packages/iotawattpy/connection.py", line 18, in get
    return await self.__open(url, username=username, password=password)
  File "/usr/local/lib/python3.9/site-packages/iotawattpy/connection.py", line 37, in __open
    resp = await getattr(self._websession, method)(
  File "/usr/local/lib/python3.9/site-packages/httpx/_client.py", line 1740, in get
    return await self.request(
  File "/usr/local/lib/python3.9/site-packages/httpx/_client.py", line 1494, in request
    response = await self.send(
  File "/usr/local/lib/python3.9/site-packages/httpx/_client.py", line 1572, in send
    raise RuntimeError("Cannot send a request, as the client has been closed.")
RuntimeError: Cannot send a request, as the client has been closed.
2021-09-10 19:58:20 ERROR (MainThread) [hass_nabucasa.google_report_state] Unexpected error
Traceback (most recent call last):
  File "/usr/local/lib/python3.9/site-packages/hass_nabucasa/iot_base.py", line 108, in connect
    await self._handle_connection()
  File "/usr/local/lib/python3.9/site-packages/hass_nabucasa/iot_base.py", line 165, in _handle_connection
    self.client = client = await self.cloud.websession.ws_connect(
  File "/usr/local/lib/python3.9/site-packages/aiohttp/client.py", line 754, in _ws_connect
    resp = await self.request(
  File "/usr/local/lib/python3.9/site-packages/aiohttp/client.py", line 381, in _request
    raise RuntimeError("Session is closed")
RuntimeError: Session is closed
2021-09-10 19:58:21 ERROR (MainThread) [homeassistant.components.shelly] Unexpected error fetching shellyem-B05A54 data: 'NoneType' object has no attribute 'update'
Traceback (most recent call last):
  File "/usr/src/homeassistant/homeassistant/helpers/update_coordinator.py", line 187, in _async_refresh
    self.data = await self._async_update_data()
  File "/usr/src/homeassistant/homeassistant/components/shelly/__init__.py", line 276, in _async_update_data
    await self.device.update()
AttributeError: 'NoneType' object has no attribute 'update'
2021-09-10 19:58:28 ERROR (MainThread) [homeassistant.components.roku.coordinator] Unexpected error fetching roku data: Session is closed
Traceback (most recent call last):
  File "/usr/src/homeassistant/homeassistant/helpers/update_coordinator.py", line 187, in _async_refresh
    self.data = await self._async_update_data()
  File "/usr/src/homeassistant/homeassistant/components/roku/coordinator.py", line 53, in _async_update_data
    data = await self.roku.update(full_update=full_update)
  File "/usr/local/lib/python3.9/site-packages/rokuecp/rokuecp.py", line 70, in update
    updates["info"] = info = await self._get_device_info()
  File "/usr/local/lib/python3.9/site-packages/rokuecp/rokuecp.py", line 179, in _get_device_info
    res = await self._request("/query/device-info")
  File "/usr/local/lib/python3.9/site-packages/rokuecp/client.py", line 65, in _request
    response = await self._session.request(
  File "/usr/local/lib/python3.9/site-packages/aiohttp/client.py", line 381, in _request
    raise RuntimeError("Session is closed")
RuntimeError: Session is closed
2021-09-10 19:58:43 ERROR (MainThread) [homeassistant.components.roku.coordinator] Unexpected error fetching roku data: Session is closed
Traceback (most recent call last):
  File "/usr/src/homeassistant/homeassistant/helpers/update_coordinator.py", line 187, in _async_refresh
    self.data = await self._async_update_data()
  File "/usr/src/homeassistant/homeassistant/components/roku/coordinator.py", line 53, in _async_update_data
    data = await self.roku.update(full_update=full_update)
  File "/usr/local/lib/python3.9/site-packages/rokuecp/rokuecp.py", line 70, in update
    updates["info"] = info = await self._get_device_info()
  File "/usr/local/lib/python3.9/site-packages/rokuecp/rokuecp.py", line 179, in _get_device_info
    res = await self._request("/query/device-info")
  File "/usr/local/lib/python3.9/site-packages/rokuecp/client.py", line 65, in _request
    response = await self._session.request(
  File "/usr/local/lib/python3.9/site-packages/aiohttp/client.py", line 381, in _request
    raise RuntimeError("Session is closed")
RuntimeError: Session is closed
2021-09-10 19:58:47 ERROR (MainThread) [homeassistant.components.iotawatt.coordinator] Unexpected error fetching 192.168.20.195 data: Cannot send a request, as the client has been closed.
Traceback (most recent call last):
  File "/usr/src/homeassistant/homeassistant/helpers/update_coordinator.py", line 187, in _async_refresh
    self.data = await self._async_update_data()
  File "/usr/src/homeassistant/homeassistant/components/iotawatt/coordinator.py", line 55, in _async_update_data
    await self.api.update()
  File "/usr/local/lib/python3.9/site-packages/iotawattpy/iotawatt.py", line 66, in update
    await self._refreshSensors(timespan)
  File "/usr/local/lib/python3.9/site-packages/iotawattpy/iotawatt.py", line 99, in _refreshSensors
    response = await self._getInputsandOutputs()
  File "/usr/local/lib/python3.9/site-packages/iotawattpy/iotawatt.py", line 74, in _getInputsandOutputs
    return await self._connection.get(url, self._username, self._password)
  File "/usr/local/lib/python3.9/site-packages/iotawattpy/connection.py", line 18, in get
    return await self.__open(url, username=username, password=password)
  File "/usr/local/lib/python3.9/site-packages/iotawattpy/connection.py", line 37, in __open
    resp = await getattr(self._websession, method)(
  File "/usr/local/lib/python3.9/site-packages/httpx/_client.py", line 1740, in get
    return await self.request(
  File "/usr/local/lib/python3.9/site-packages/httpx/_client.py", line 1494, in request
    response = await self.send(
  File "/usr/local/lib/python3.9/site-packages/httpx/_client.py", line 1572, in send
    raise RuntimeError("Cannot send a request, as the client has been closed.")
RuntimeError: Cannot send a request, as the client has been closed.
2021-09-10 19:58:54 ERROR (MainThread) [homeassistant.components.shelly] Unexpected error fetching shellyem-B05A54 data: 'NoneType' object has no attribute 'update'
Traceback (most recent call last):
  File "/usr/src/homeassistant/homeassistant/helpers/update_coordinator.py", line 187, in _async_refresh
    self.data = await self._async_update_data()
  File "/usr/src/homeassistant/homeassistant/components/shelly/__init__.py", line 276, in _async_update_data
    await self.device.update()
AttributeError: 'NoneType' object has no attribute 'update'
2021-09-10 19:58:58 ERROR (MainThread) [homeassistant.components.roku.coordinator] Unexpected error fetching roku data: Session is closed
Traceback (most recent call last):
  File "/usr/src/homeassistant/homeassistant/helpers/update_coordinator.py", line 187, in _async_refresh
    self.data = await self._async_update_data()
  File "/usr/src/homeassistant/homeassistant/components/roku/coordinator.py", line 53, in _async_update_data
    data = await self.roku.update(full_update=full_update)
  File "/usr/local/lib/python3.9/site-packages/rokuecp/rokuecp.py", line 70, in update
    updates["info"] = info = await self._get_device_info()
  File "/usr/local/lib/python3.9/site-packages/rokuecp/rokuecp.py", line 179, in _get_device_info
    res = await self._request("/query/device-info")
  File "/usr/local/lib/python3.9/site-packages/rokuecp/client.py", line 65, in _request
    response = await self._session.request(
  File "/usr/local/lib/python3.9/site-packages/aiohttp/client.py", line 381, in _request
    raise RuntimeError("Session is closed")
RuntimeError: Session is closed
2021-09-10 19:59:09 ERROR (MainThread) [homeassistant] Error doing job: Task exception was never retrieved
Traceback (most recent call last):
  File "/usr/src/homeassistant/homeassistant/components/nest/camera_sdm.py", line 151, in _handle_stream_refresh
    self._stream = await self._stream.extend_rtsp_stream()
  File "/usr/local/lib/python3.9/site-packages/google_nest_sdm/camera_traits.py", line 96, in extend_rtsp_stream
    resp = await self._cmd.execute(data)
  File "/usr/local/lib/python3.9/site-packages/google_nest_sdm/traits.py", line 26, in execute
    return await self._auth.post(f"{self._device_id}:executeCommand", json=data)
  File "/usr/local/lib/python3.9/site-packages/google_nest_sdm/auth.py", line 76, in post
    resp = await self.request("post", url, **kwargs)
  File "/usr/local/lib/python3.9/site-packages/google_nest_sdm/auth.py", line 59, in request
    return await self._websession.request(method, url, **kwargs, headers=headers)
  File "/usr/local/lib/python3.9/site-packages/aiohttp/client.py", line 381, in _request
    raise RuntimeError("Session is closed")
RuntimeError: Session is closed
2021-09-10 19:59:09 ERROR (MainThread) [homeassistant] Error doing job: Task exception was never retrieved
Traceback (most recent call last):
  File "/usr/src/homeassistant/homeassistant/components/nest/camera_sdm.py", line 151, in _handle_stream_refresh
    self._stream = await self._stream.extend_rtsp_stream()
  File "/usr/local/lib/python3.9/site-packages/google_nest_sdm/camera_traits.py", line 96, in extend_rtsp_stream
    resp = await self._cmd.execute(data)
  File "/usr/local/lib/python3.9/site-packages/google_nest_sdm/traits.py", line 26, in execute
    return await self._auth.post(f"{self._device_id}:executeCommand", json=data)
  File "/usr/local/lib/python3.9/site-packages/google_nest_sdm/auth.py", line 76, in post
    resp = await self.request("post", url, **kwargs)
  File "/usr/local/lib/python3.9/site-packages/google_nest_sdm/auth.py", line 59, in request
    return await self._websession.request(method, url, **kwargs, headers=headers)
  File "/usr/local/lib/python3.9/site-packages/aiohttp/client.py", line 381, in _request
    raise RuntimeError("Session is closed")
RuntimeError: Session is closed
