2021-09-01 15:09:03 WARNING (SyncWorker_0) [homeassistant.loader] We found a custom integration sun2 which has not been tested by Home Assistant. This component might cause stability problems, be sure to disable it if you experience issues with Home Assistant
2021-09-01 15:09:17 WARNING (MainThread) [homeassistant.components.sensor] Entity sensor.cpu_temp (<class 'homeassistant.components.command_line.sensor.CommandSensor'>) with device_class None reports a temperature in °C which will be converted to °F. Temperature conversion for entities without correct device_class is deprecated and will be removed from Home Assistant Core 2022.3. Please update your configuration if device_class is manually configured, otherwise create a bug report at https://github.com/home-assistant/core/issues?q=is%3Aopen+is%3Aissue+label%3A%22integration%3A+command_line%22
2021-09-01 15:09:17 ERROR (MainThread) [snitun.client.client_peer] Challenge/Response error with SniTun server
2021-09-01 15:09:17 ERROR (MainThread) [hass_nabucasa.remote] Connection problem to snitun server
2021-09-01 15:09:19 WARNING (MainThread) [homeassistant.config_entries] Config entry 'Roku Smart Soundbar' for roku integration not ready yet: Invalid response from API: Error occurred while communicating with device; Retrying in background
2021-09-01 15:09:23 WARNING (MainThread) [homeassistant.components.sensor] Entity sensor.attictemp1_bme280_dewpoint (<class 'homeassistant.components.tasmota.sensor.TasmotaSensor'>) with device_class None reports a temperature in °C which will be converted to °F. Temperature conversion for entities without correct device_class is deprecated and will be removed from Home Assistant Core 2022.3. Please update your configuration if device_class is manually configured, otherwise create a bug report at https://github.com/home-assistant/core/issues?q=is%3Aopen+is%3Aissue+label%3A%22integration%3A+tasmota%22
2021-09-01 15:09:23 WARNING (MainThread) [homeassistant.components.sensor] Entity sensor.garagesidedoorsensor_bme280_dewpoint (<class 'homeassistant.components.tasmota.sensor.TasmotaSensor'>) with device_class None reports a temperature in °C which will be converted to °F. Temperature conversion for entities without correct device_class is deprecated and will be removed from Home Assistant Core 2022.3. Please update your configuration if device_class is manually configured, otherwise create a bug report at https://github.com/home-assistant/core/issues?q=is%3Aopen+is%3Aissue+label%3A%22integration%3A+tasmota%22
2021-09-01 15:09:24 WARNING (MainThread) [homeassistant.components.sensor] Setup of sensor platform snmp is taking over 10 seconds.
2021-09-01 15:09:24 WARNING (MainThread) [homeassistant.components.sensor] Setup of sensor platform snmp is taking over 10 seconds.
2021-09-01 15:09:24 WARNING (MainThread) [homeassistant.components.sensor] Setup of sensor platform snmp is taking over 10 seconds.
2021-09-01 15:09:24 WARNING (MainThread) [homeassistant.components.sensor] Setup of sensor platform snmp is taking over 10 seconds.
2021-09-01 15:09:24 WARNING (MainThread) [homeassistant.components.sensor] Setup of sensor platform snmp is taking over 10 seconds.
2021-09-01 15:09:25 ERROR (MainThread) [homeassistant.components.snmp.sensor] Please check the details in the configuration file
2021-09-01 15:09:25 ERROR (MainThread) [homeassistant.components.snmp.sensor] Please check the details in the configuration file
2021-09-01 15:09:25 ERROR (MainThread) [homeassistant.components.snmp.sensor] Please check the details in the configuration file
2021-09-01 15:09:25 ERROR (MainThread) [homeassistant.components.snmp.sensor] Please check the details in the configuration file
2021-09-01 15:09:25 ERROR (MainThread) [homeassistant.components.snmp.sensor] Please check the details in the configuration file
2021-09-01 15:09:25 WARNING (MainThread) [homeassistant.config_entries] Config entry '192.168.7.195' for wled integration not ready yet: Invalid response from API: Error occurred while communicating with WLED device at 192.168.7.195; Retrying in background
2021-09-01 15:09:28 ERROR (MainThread) [homeassistant.components.nws] Error requesting NWS observation station SAUC1 data: 503, message='Service Unavailable', url=URL('https://api.weather.gov/stations/SAUC1/observations')
2021-09-01 15:10:13 WARNING (MainThread) [homeassistant.bootstrap] Waiting on integrations to complete setup: forecast_solar
2021-09-01 15:11:13 WARNING (MainThread) [homeassistant.bootstrap] Waiting on integrations to complete setup: forecast_solar
2021-09-01 15:11:22 WARNING (MainThread) [homeassistant.config_entries] Config entry 'Cerezo House HA' for forecast_solar integration not ready yet: Cannot connect to host 91.228.53.233:443 ssl:False [Connect call failed ('91.228.53.233', 443)]; Retrying in background
2021-09-01 15:11:23 WARNING (Recorder) [homeassistant.components.recorder.migration] Database is about to upgrade. Schema version: 18
2021-09-01 15:13:23 WARNING (MainThread) [homeassistant.components.template.template_entity] Template loop detected while processing event: <Event state_changed[L]: entity_id=sensor.entities_count, old_state=<state sensor.entities_count=819; friendly_name=Number of Entities @ 2021-09-01T15:11:23.008243-07:00>, new_state=<state sensor.entities_count=865; friendly_name=Number of Entities @ 2021-09-01T15:12:23.028756-07:00>>, skipping template render for Template[{{ states | rejectattr('state', 'eq', 'unavailable') | list | count}}]
2021-09-01 15:14:11 ERROR (MainThread) [homeassistant] Error doing job: Future exception was never retrieved
Traceback (most recent call last):
  File "/usr/local/lib/python3.9/concurrent/futures/thread.py", line 52, in run
    result = self.fn(*self.args, **self.kwargs)
TypeError: update() takes 1 positional argument but 2 were given
2021-09-01 15:19:12 ERROR (MainThread) [homeassistant] Error doing job: Future exception was never retrieved
Traceback (most recent call last):
  File "/usr/local/lib/python3.9/concurrent/futures/thread.py", line 52, in run
    result = self.fn(*self.args, **self.kwargs)
TypeError: update() takes 1 positional argument but 2 were given
2021-09-01 15:20:41 ERROR (stream_worker) [libav.rtsp] method DESCRIBE failed: 404 Not Found
2021-09-01 15:20:41 ERROR (stream_worker) [homeassistant.components.stream.worker] Error opening stream rtsps://stream-uc2-delta.dropcam.com:443/sdm_live_stream/CiQA2vuxr78j7c5P9HWw124G6Ni7awY_aM0OSh9LOuJzPSL-NJQScABQBG8tLmoZV4IRRVg1cIhOuT_RrvHzJBhOBJOx6w5v-nNDykd2JFTZFPeevFG7YiBW81o93-Xg7DjO3RQqv2-azIbMI01XY-zj1iuvbO7erqeDNtYVGMFUnt5EvnZyyBt4lDJZ_cN2G19vwwjB4PQ?auth=g.0.eyJraWQiOiIyMzhiNTUxZmMyM2EyM2Y4M2E2ZTE3MmJjZTg0YmU3ZjgxMzAzMmM4IiwiYWxnIjoiUlMyNTYifQ.eyJpc3MiOiJuZXN0LXNlY3VyaXR5LWF1dGhwcm94eSIsInN1YiI6Im5lc3RfaWQ6bmVzdC1waG9lbml4LXByb2Q6MjEyMTgxNDEiLCJwb2wiOiIzcC1vYXV0aC1zY29wZS1BUElfU0RNX1NFUlZJQ0UtY2xpZW50LTIwMjQyNzMxODczNS1qNXQ5bWMyMzZqaG85YXMycWY0dTZxY3NmYW1kaGJ0ci5hcHBzLmdvb2dsZXVzZXJjb250ZW50LmNvbSIsImV4cCI6MTYzMDUzNTEyNn0.prZ0P8WOZ9BD2qyZjj0ui8Amv18Y87JAHWm1O7ZBCYCAnEQgdnrUXWjU905IRKm8ZqtYXHyMJ5OiXKhw0Q2OMT0Xlm2s9oj-uVH-nKpz6gQ0O77Op-M9Nru6JsdZbfK0DpHTsIDgrGqjqWAW_1sy400KXfMrg6Xv2ZeDGTy1oXtJ6FqWA1cUPYe1mgJu1cevEcW82aVzdR6uvuCleCliuT0bhSybTCDy0O5J0VsN_jY5OUKyGM-OcclP1wZmEjfDXRqc_KAVoLh13fh5orKVWUbNA8xSSZqQ6BrlUTxhOuAh4fYbJNQtsmLXRnlcca6iVKC4jvUhA-jhxai3O03yFg
2021-09-01 15:23:01 ERROR (MainThread) [homeassistant.components.nws] Error requesting NWS observation station SAUC1 data: 503, message='Service Unavailable', url=URL('https://api.weather.gov/stations/SAUC1/observations')
2021-09-01 15:24:13 ERROR (MainThread) [homeassistant] Error doing job: Future exception was never retrieved
Traceback (most recent call last):
  File "/usr/local/lib/python3.9/concurrent/futures/thread.py", line 52, in run
    result = self.fn(*self.args, **self.kwargs)
TypeError: update() takes 1 positional argument but 2 were given
2021-09-01 15:29:14 ERROR (MainThread) [homeassistant] Error doing job: Future exception was never retrieved
Traceback (most recent call last):
  File "/usr/local/lib/python3.9/concurrent/futures/thread.py", line 52, in run
    result = self.fn(*self.args, **self.kwargs)
TypeError: update() takes 1 positional argument but 2 were given
2021-09-01 15:34:15 ERROR (MainThread) [homeassistant] Error doing job: Future exception was never retrieved
Traceback (most recent call last):
  File "/usr/local/lib/python3.9/concurrent/futures/thread.py", line 52, in run
    result = self.fn(*self.args, **self.kwargs)
TypeError: update() takes 1 positional argument but 2 were given
2021-09-01 15:39:16 ERROR (SyncWorker_7) [homeassistant] Error doing job: Future exception was never retrieved
Traceback (most recent call last):
  File "/usr/local/lib/python3.9/concurrent/futures/thread.py", line 52, in run
    result = self.fn(*self.args, **self.kwargs)
TypeError: update() takes 1 positional argument but 2 were given
2021-09-01 15:44:17 ERROR (MainThread) [homeassistant] Error doing job: Future exception was never retrieved
Traceback (most recent call last):
  File "/usr/local/lib/python3.9/concurrent/futures/thread.py", line 52, in run
    result = self.fn(*self.args, **self.kwargs)
TypeError: update() takes 1 positional argument but 2 were given
2021-09-01 15:49:18 ERROR (SyncWorker_1) [homeassistant] Error doing job: Future exception was never retrieved
Traceback (most recent call last):
  File "/usr/local/lib/python3.9/concurrent/futures/thread.py", line 52, in run
    result = self.fn(*self.args, **self.kwargs)
TypeError: update() takes 1 positional argument but 2 were given
2021-09-01 15:54:19 ERROR (MainThread) [homeassistant] Error doing job: Future exception was never retrieved
Traceback (most recent call last):
  File "/usr/local/lib/python3.9/concurrent/futures/thread.py", line 52, in run
    result = self.fn(*self.args, **self.kwargs)
TypeError: update() takes 1 positional argument but 2 were given
2021-09-01 15:59:20 ERROR (MainThread) [homeassistant] Error doing job: Future exception was never retrieved
Traceback (most recent call last):
  File "/usr/local/lib/python3.9/concurrent/futures/thread.py", line 52, in run
    result = self.fn(*self.args, **self.kwargs)
TypeError: update() takes 1 positional argument but 2 were given
2021-09-01 16:01:14 ERROR (stream_worker) [homeassistant.components.stream.worker] Stream has no video
2021-09-01 16:04:21 ERROR (MainThread) [homeassistant] Error doing job: Future exception was never retrieved
Traceback (most recent call last):
  File "/usr/local/lib/python3.9/concurrent/futures/thread.py", line 52, in run
    result = self.fn(*self.args, **self.kwargs)
TypeError: update() takes 1 positional argument but 2 were given
2021-09-01 16:05:52 WARNING (stream_worker) [homeassistant.components.stream.worker] Audio stream not found
2021-09-01 16:09:22 ERROR (MainThread) [homeassistant] Error doing job: Future exception was never retrieved
Traceback (most recent call last):
  File "/usr/local/lib/python3.9/concurrent/futures/thread.py", line 52, in run
    result = self.fn(*self.args, **self.kwargs)
TypeError: update() takes 1 positional argument but 2 were given
2021-09-01 16:14:23 ERROR (MainThread) [homeassistant] Error doing job: Future exception was never retrieved
Traceback (most recent call last):
  File "/usr/local/lib/python3.9/concurrent/futures/thread.py", line 52, in run
    result = self.fn(*self.args, **self.kwargs)
TypeError: update() takes 1 positional argument but 2 were given
2021-09-01 16:19:24 ERROR (MainThread) [homeassistant] Error doing job: Future exception was never retrieved
Traceback (most recent call last):
  File "/usr/local/lib/python3.9/concurrent/futures/thread.py", line 52, in run
    result = self.fn(*self.args, **self.kwargs)
TypeError: update() takes 1 positional argument but 2 were given
2021-09-01 16:24:25 ERROR (MainThread) [homeassistant] Error doing job: Future exception was never retrieved
Traceback (most recent call last):
  File "/usr/local/lib/python3.9/concurrent/futures/thread.py", line 52, in run
    result = self.fn(*self.args, **self.kwargs)
TypeError: update() takes 1 positional argument but 2 were given
2021-09-01 16:29:26 ERROR (MainThread) [homeassistant] Error doing job: Future exception was never retrieved
Traceback (most recent call last):
  File "/usr/local/lib/python3.9/concurrent/futures/thread.py", line 52, in run
    result = self.fn(*self.args, **self.kwargs)
TypeError: update() takes 1 positional argument but 2 were given
2021-09-01 16:34:27 ERROR (MainThread) [homeassistant] Error doing job: Future exception was never retrieved
Traceback (most recent call last):
  File "/usr/local/lib/python3.9/concurrent/futures/thread.py", line 52, in run
    result = self.fn(*self.args, **self.kwargs)
TypeError: update() takes 1 positional argument but 2 were given
2021-09-01 16:37:34 ERROR (stream_worker) [libav.rtsp] method DESCRIBE failed: 404 Not Found
2021-09-01 16:37:34 ERROR (stream_worker) [homeassistant.components.stream.worker] Error opening stream rtsps://stream-uc2-bravo.dropcam.com:443/sdm_live_stream/CiQA2vuxrzSUh11qjH4VUWPmcl-T_VLGPcYlKSjUB70U1J8uImAScQBQBG8ti0c5BZeoDdrlgvTR6cbln82NpgmPIkrBweSWJE_YORFUFD6G-BLEW_hy_CZW-jWyIZQf_nUc94jL8tWgXEGOYuBVQ-SnC3kcTgJDh953WnzeTA2L7J99QxP3hFizjljV82XyLDH4IjoabngB?auth=g.0.eyJraWQiOiIyMzhiNTUxZmMyM2EyM2Y4M2E2ZTE3MmJjZTg0YmU3ZjgxMzAzMmM4IiwiYWxnIjoiUlMyNTYifQ.eyJpc3MiOiJuZXN0LXNlY3VyaXR5LWF1dGhwcm94eSIsInN1YiI6Im5lc3RfaWQ6bmVzdC1waG9lbml4LXByb2Q6MjEyMTgxNDEiLCJwb2wiOiIzcC1vYXV0aC1zY29wZS1BUElfU0RNX1NFUlZJQ0UtY2xpZW50LTIwMjQyNzMxODczNS1qNXQ5bWMyMzZqaG85YXMycWY0dTZxY3NmYW1kaGJ0ci5hcHBzLmdvb2dsZXVzZXJjb250ZW50LmNvbSIsImV4cCI6MTYzMDUzOTczMX0.HNwbIMwNo22Uw6D7pM737_CEMRsG7zWJjwWGYdO84m1f4t2lg9fjBuZf6Y37yywh2Nu-lW0BJNUb1XpSVSF7cjlzxwnkdvwKFPCCBnHh4znl5wfGY9h1XkT2m47xbSi5CJmxfTizFhbR_N4PtKXTS4tw5cT-rZFRC5xRbGkZ3IBhbrUQcHYCUKVgD4MwVaLsyXGyhptwMSA7W21lSXroZ17NxPNZ86jxgigOt3g-WSmFahNXbtt7J31tVd0Ud8UrcJGh-DlF_lAH_Qf2YoS-pOR2cemkgklZgfBDOlX0qacgwNeRcfS4-Y3Ii-QmM9KLO40lb4CyaBDZqrMXYqK58Q
2021-09-01 16:39:28 ERROR (MainThread) [homeassistant] Error doing job: Future exception was never retrieved
Traceback (most recent call last):
  File "/usr/local/lib/python3.9/concurrent/futures/thread.py", line 52, in run
    result = self.fn(*self.args, **self.kwargs)
TypeError: update() takes 1 positional argument but 2 were given
2021-09-01 16:44:29 ERROR (MainThread) [homeassistant] Error doing job: Future exception was never retrieved
Traceback (most recent call last):
  File "/usr/local/lib/python3.9/concurrent/futures/thread.py", line 52, in run
    result = self.fn(*self.args, **self.kwargs)
TypeError: update() takes 1 positional argument but 2 were given
2021-09-01 16:49:30 ERROR (MainThread) [homeassistant] Error doing job: Future exception was never retrieved
Traceback (most recent call last):
  File "/usr/local/lib/python3.9/concurrent/futures/thread.py", line 52, in run
    result = self.fn(*self.args, **self.kwargs)
TypeError: update() takes 1 positional argument but 2 were given
2021-09-01 16:54:31 ERROR (MainThread) [homeassistant] Error doing job: Future exception was never retrieved
Traceback (most recent call last):
  File "/usr/local/lib/python3.9/concurrent/futures/thread.py", line 52, in run
    result = self.fn(*self.args, **self.kwargs)
TypeError: update() takes 1 positional argument but 2 were given
2021-09-01 16:59:32 ERROR (MainThread) [homeassistant] Error doing job: Future exception was never retrieved
Traceback (most recent call last):
  File "/usr/local/lib/python3.9/concurrent/futures/thread.py", line 52, in run
    result = self.fn(*self.args, **self.kwargs)
TypeError: update() takes 1 positional argument but 2 were given
2021-09-01 17:04:33 ERROR (MainThread) [homeassistant] Error doing job: Future exception was never retrieved
Traceback (most recent call last):
  File "/usr/local/lib/python3.9/concurrent/futures/thread.py", line 52, in run
    result = self.fn(*self.args, **self.kwargs)
TypeError: update() takes 1 positional argument but 2 were given
2021-09-01 17:09:25 ERROR (stream_worker) [libav.rtsp] method DESCRIBE failed: 404 Not Found
2021-09-01 17:09:25 ERROR (stream_worker) [homeassistant.components.stream.worker] Error opening stream rtsps://stream-uc2-bravo.dropcam.com:443/sdm_live_stream/CiQA2vuxrzSUh11qjH4VUWPmcl-T_VLGPcYlKSjUB70U1J8uImAScQBQBG8ti0c5BZeoDdrlgvTR6cbln82NpgmPIkrBweSWJE_YORFUFD6G-BLEW_hy_CZW-jWyIZQf_nUc94jL8tWgXEGOYuBVQ-SnC3kcTgJDh953WnzeTA2L7J99QxP3hFizjljV82XyLDH4IjoabngB?auth=g.0.eyJraWQiOiIyMzhiNTUxZmMyM2EyM2Y4M2E2ZTE3MmJjZTg0YmU3ZjgxMzAzMmM4IiwiYWxnIjoiUlMyNTYifQ.eyJpc3MiOiJuZXN0LXNlY3VyaXR5LWF1dGhwcm94eSIsInN1YiI6Im5lc3RfaWQ6bmVzdC1waG9lbml4LXByb2Q6MjEyMTgxNDEiLCJwb2wiOiIzcC1vYXV0aC1zY29wZS1BUElfU0RNX1NFUlZJQ0UtY2xpZW50LTIwMjQyNzMxODczNS1qNXQ5bWMyMzZqaG85YXMycWY0dTZxY3NmYW1kaGJ0ci5hcHBzLmdvb2dsZXVzZXJjb250ZW50LmNvbSIsImV4cCI6MTYzMDU0MTYyOX0.uPDb2-AqSfpGsrKtaRu32qwdFAfBmqHZqhgzC5LydNgywHGPWheSTNcK6ZCqISdEM_q243yDbvy4-PzAbpTJz-1gO8PdKpurDIl7QriFXvYYV9ZwKjZo2BvDBOAFBOLK8w7KUfNzvqHaFAZluunue0JHQRl0Zavp1DnC4JlnpjBAXtEnJ0ZMkvi4pE5PFgjvKjMZklZ4g_p7HtFa-ZtECjbVJLD9sgSWNwyDsbLFbfmY9vufQDoUTMiCJbbWIIp2Mm5WScVDUm2j1GGe0Zf79NK3bdkmHiY7poxe2fGxxEt6WoVQR2lPUGzY82JWhoxMGbWBKF9ry12uwxkvLLFLSQ
2021-09-01 17:09:34 ERROR (MainThread) [homeassistant] Error doing job: Future exception was never retrieved
Traceback (most recent call last):
  File "/usr/local/lib/python3.9/concurrent/futures/thread.py", line 52, in run
    result = self.fn(*self.args, **self.kwargs)
TypeError: update() takes 1 positional argument but 2 were given
2021-09-01 17:10:11 ERROR (stream_worker) [libav.rtsp] method DESCRIBE failed: 404 Not Found
2021-09-01 17:10:11 ERROR (stream_worker) [homeassistant.components.stream.worker] Error opening stream rtsps://stream-uc2-bravo.dropcam.com:443/sdm_live_stream/CiQA2vuxrzSUh11qjH4VUWPmcl-T_VLGPcYlKSjUB70U1J8uImAScQBQBG8ti0c5BZeoDdrlgvTR6cbln82NpgmPIkrBweSWJE_YORFUFD6G-BLEW_hy_CZW-jWyIZQf_nUc94jL8tWgXEGOYuBVQ-SnC3kcTgJDh953WnzeTA2L7J99QxP3hFizjljV82XyLDH4IjoabngB?auth=g.0.eyJraWQiOiIyMzhiNTUxZmMyM2EyM2Y4M2E2ZTE3MmJjZTg0YmU3ZjgxMzAzMmM4IiwiYWxnIjoiUlMyNTYifQ.eyJpc3MiOiJuZXN0LXNlY3VyaXR5LWF1dGhwcm94eSIsInN1YiI6Im5lc3RfaWQ6bmVzdC1waG9lbml4LXByb2Q6MjEyMTgxNDEiLCJwb2wiOiIzcC1vYXV0aC1zY29wZS1BUElfU0RNX1NFUlZJQ0UtY2xpZW50LTIwMjQyNzMxODczNS1qNXQ5bWMyMzZqaG85YXMycWY0dTZxY3NmYW1kaGJ0ci5hcHBzLmdvb2dsZXVzZXJjb250ZW50LmNvbSIsImV4cCI6MTYzMDU0MTYyOX0.uPDb2-AqSfpGsrKtaRu32qwdFAfBmqHZqhgzC5LydNgywHGPWheSTNcK6ZCqISdEM_q243yDbvy4-PzAbpTJz-1gO8PdKpurDIl7QriFXvYYV9ZwKjZo2BvDBOAFBOLK8w7KUfNzvqHaFAZluunue0JHQRl0Zavp1DnC4JlnpjBAXtEnJ0ZMkvi4pE5PFgjvKjMZklZ4g_p7HtFa-ZtECjbVJLD9sgSWNwyDsbLFbfmY9vufQDoUTMiCJbbWIIp2Mm5WScVDUm2j1GGe0Zf79NK3bdkmHiY7poxe2fGxxEt6WoVQR2lPUGzY82JWhoxMGbWBKF9ry12uwxkvLLFLSQ
2021-09-01 17:14:35 ERROR (MainThread) [homeassistant] Error doing job: Future exception was never retrieved
Traceback (most recent call last):
  File "/usr/local/lib/python3.9/concurrent/futures/thread.py", line 52, in run
    result = self.fn(*self.args, **self.kwargs)
TypeError: update() takes 1 positional argument but 2 were given
2021-09-01 17:19:36 ERROR (MainThread) [homeassistant] Error doing job: Future exception was never retrieved
Traceback (most recent call last):
  File "/usr/local/lib/python3.9/concurrent/futures/thread.py", line 52, in run
    result = self.fn(*self.args, **self.kwargs)
TypeError: update() takes 1 positional argument but 2 were given
2021-09-01 17:24:37 ERROR (MainThread) [homeassistant] Error doing job: Future exception was never retrieved
Traceback (most recent call last):
  File "/usr/local/lib/python3.9/concurrent/futures/thread.py", line 52, in run
    result = self.fn(*self.args, **self.kwargs)
TypeError: update() takes 1 positional argument but 2 were given
2021-09-01 17:27:16 ERROR (stream_worker) [libav.rtsp] method DESCRIBE failed: 404 Not Found
2021-09-01 17:27:16 ERROR (stream_worker) [homeassistant.components.stream.worker] Error opening stream rtsps://stream-uc2-delta.dropcam.com:443/sdm_live_stream/CiQA2vuxr78j7c5P9HWw124G6Ni7awY_aM0OSh9LOuJzPSL-NJQScABQBG8tLmoZV4IRRVg1cIhOuT_RrvHzJBhOBJOx6w5v-nNDykd2JFTZFPeevFG7YiBW81o93-Xg7DjO3RQqv2-azIbMI01XY-zj1iuvbO7erqeDNtYVGMFUnt5EvnZyyBt4lDJZ_cN2G19vwwjB4PQ?auth=g.0.eyJraWQiOiIyMzhiNTUxZmMyM2EyM2Y4M2E2ZTE3MmJjZTg0YmU3ZjgxMzAzMmM4IiwiYWxnIjoiUlMyNTYifQ.eyJpc3MiOiJuZXN0LXNlY3VyaXR5LWF1dGhwcm94eSIsInN1YiI6Im5lc3RfaWQ6bmVzdC1waG9lbml4LXByb2Q6MjEyMTgxNDEiLCJwb2wiOiIzcC1vYXV0aC1zY29wZS1BUElfU0RNX1NFUlZJQ0UtY2xpZW50LTIwMjQyNzMxODczNS1qNXQ5bWMyMzZqaG85YXMycWY0dTZxY3NmYW1kaGJ0ci5hcHBzLmdvb2dsZXVzZXJjb250ZW50LmNvbSIsImV4cCI6MTYzMDU0MjcxNX0.ZBId2M1mwLVNVUSTH2wofasI9lplfvkw3Mxl1y4biKSrmFzH1_H0ZzN0335Y_O94TGzGjtfPf2B4KhikcHypcSfVl7ayVq9cPSdiA5Wx0_jU1UjOhXls00NNVEl-Q_pQt8WgLm-bqaV30Aaji5kA1WGrFAkosodAohuLU8j4ciywo7LAHKMML0CwEVK_X-jqfqGncSUpPeluSB4xwUIE2XBfF-wFOZCyBRwi4S4gXdiCIrPAyC2lXoeOpcct1h2D95LGFKHQm1rG9FqXkZfMHQkV3Tt5uwH8BHjSO2Buy122tZQAKN_x2a44LpTTHHZ2YrDhUfXsHih208s_P_XywA
2021-09-01 17:29:38 ERROR (MainThread) [homeassistant] Error doing job: Future exception was never retrieved
Traceback (most recent call last):
  File "/usr/local/lib/python3.9/concurrent/futures/thread.py", line 52, in run
    result = self.fn(*self.args, **self.kwargs)
TypeError: update() takes 1 positional argument but 2 were given
2021-09-01 17:34:39 ERROR (MainThread) [homeassistant] Error doing job: Future exception was never retrieved
Traceback (most recent call last):
  File "/usr/local/lib/python3.9/concurrent/futures/thread.py", line 52, in run
    result = self.fn(*self.args, **self.kwargs)
TypeError: update() takes 1 positional argument but 2 were given
2021-09-01 17:39:40 ERROR (MainThread) [homeassistant] Error doing job: Future exception was never retrieved
Traceback (most recent call last):
  File "/usr/local/lib/python3.9/concurrent/futures/thread.py", line 52, in run
    result = self.fn(*self.args, **self.kwargs)
TypeError: update() takes 1 positional argument but 2 were given
2021-09-01 17:44:41 ERROR (MainThread) [homeassistant] Error doing job: Future exception was never retrieved
Traceback (most recent call last):
  File "/usr/local/lib/python3.9/concurrent/futures/thread.py", line 52, in run
    result = self.fn(*self.args, **self.kwargs)
TypeError: update() takes 1 positional argument but 2 were given
2021-09-01 17:49:42 ERROR (MainThread) [homeassistant] Error doing job: Future exception was never retrieved
Traceback (most recent call last):
  File "/usr/local/lib/python3.9/concurrent/futures/thread.py", line 52, in run
    result = self.fn(*self.args, **self.kwargs)
TypeError: update() takes 1 positional argument but 2 were given
2021-09-01 17:54:43 ERROR (MainThread) [homeassistant] Error doing job: Future exception was never retrieved
Traceback (most recent call last):
  File "/usr/local/lib/python3.9/concurrent/futures/thread.py", line 52, in run
    result = self.fn(*self.args, **self.kwargs)
TypeError: update() takes 1 positional argument but 2 were given
2021-09-01 17:59:44 ERROR (MainThread) [homeassistant] Error doing job: Future exception was never retrieved
Traceback (most recent call last):
  File "/usr/local/lib/python3.9/concurrent/futures/thread.py", line 52, in run
    result = self.fn(*self.args, **self.kwargs)
TypeError: update() takes 1 positional argument but 2 were given
2021-09-01 18:04:45 ERROR (MainThread) [homeassistant] Error doing job: Future exception was never retrieved
Traceback (most recent call last):
  File "/usr/local/lib/python3.9/concurrent/futures/thread.py", line 52, in run
    result = self.fn(*self.args, **self.kwargs)
TypeError: update() takes 1 positional argument but 2 were given
2021-09-01 18:08:24 ERROR (stream_worker) [homeassistant.components.stream.worker] Stream has no video
2021-09-01 18:09:46 ERROR (MainThread) [homeassistant] Error doing job: Future exception was never retrieved
Traceback (most recent call last):
  File "/usr/local/lib/python3.9/concurrent/futures/thread.py", line 52, in run
    result = self.fn(*self.args, **self.kwargs)
TypeError: update() takes 1 positional argument but 2 were given
2021-09-01 18:14:47 ERROR (MainThread) [homeassistant] Error doing job: Future exception was never retrieved
Traceback (most recent call last):
  File "/usr/local/lib/python3.9/concurrent/futures/thread.py", line 52, in run
    result = self.fn(*self.args, **self.kwargs)
TypeError: update() takes 1 positional argument but 2 were given
2021-09-01 18:19:48 ERROR (MainThread) [homeassistant] Error doing job: Future exception was never retrieved
Traceback (most recent call last):
  File "/usr/local/lib/python3.9/concurrent/futures/thread.py", line 52, in run
    result = self.fn(*self.args, **self.kwargs)
TypeError: update() takes 1 positional argument but 2 were given
2021-09-01 18:24:49 ERROR (MainThread) [homeassistant] Error doing job: Future exception was never retrieved
Traceback (most recent call last):
  File "/usr/local/lib/python3.9/concurrent/futures/thread.py", line 52, in run
    result = self.fn(*self.args, **self.kwargs)
TypeError: update() takes 1 positional argument but 2 were given
2021-09-01 18:29:50 ERROR (MainThread) [homeassistant] Error doing job: Future exception was never retrieved
Traceback (most recent call last):
  File "/usr/local/lib/python3.9/concurrent/futures/thread.py", line 52, in run
    result = self.fn(*self.args, **self.kwargs)
TypeError: update() takes 1 positional argument but 2 were given
2021-09-01 18:34:38 ERROR (MainThread) [homeassistant.components.nws] Error requesting NWS observation station SAUC1 data: 503, message='Service Unavailable', url=URL('https://api.weather.gov/stations/SAUC1/observations')
2021-09-01 18:34:51 ERROR (MainThread) [homeassistant] Error doing job: Future exception was never retrieved
Traceback (most recent call last):
  File "/usr/local/lib/python3.9/concurrent/futures/thread.py", line 52, in run
    result = self.fn(*self.args, **self.kwargs)
TypeError: update() takes 1 positional argument but 2 were given
2021-09-01 18:35:44 ERROR (stream_worker) [libav.rtsp] method DESCRIBE failed: 404 Not Found
2021-09-01 18:35:44 ERROR (stream_worker) [homeassistant.components.stream.worker] Error opening stream rtsps://stream-uc2-bravo.dropcam.com:443/sdm_live_stream/CiQA2vuxrzSUh11qjH4VUWPmcl-T_VLGPcYlKSjUB70U1J8uImAScQBQBG8ti0c5BZeoDdrlgvTR6cbln82NpgmPIkrBweSWJE_YORFUFD6G-BLEW_hy_CZW-jWyIZQf_nUc94jL8tWgXEGOYuBVQ-SnC3kcTgJDh953WnzeTA2L7J99QxP3hFizjljV82XyLDH4IjoabngB?auth=g.0.eyJraWQiOiIyMzhiNTUxZmMyM2EyM2Y4M2E2ZTE3MmJjZTg0YmU3ZjgxMzAzMmM4IiwiYWxnIjoiUlMyNTYifQ.eyJpc3MiOiJuZXN0LXNlY3VyaXR5LWF1dGhwcm94eSIsInN1YiI6Im5lc3RfaWQ6bmVzdC1waG9lbml4LXByb2Q6MjEyMTgxNDEiLCJwb2wiOiIzcC1vYXV0aC1zY29wZS1BUElfU0RNX1NFUlZJQ0UtY2xpZW50LTIwMjQyNzMxODczNS1qNXQ5bWMyMzZqaG85YXMycWY0dTZxY3NmYW1kaGJ0ci5hcHBzLmdvb2dsZXVzZXJjb250ZW50LmNvbSIsImV4cCI6MTYzMDU0Njc4MH0.emYaBBQKvVr8e0bRYBJbttngMtI3EqeZpYPyFPb9nQs-EDnKNG8I3VvVW1GNMk9omSQZN_k0CVYJvh6sbMtb9ZcJRz5QuSZZJhTEiyNTwmwOeH3m9RD-g5a9lbLZZrAKRGB_YQibMPIFVXn3QJAnZ4EMi9gm_15AIK1hGe_N1TrIxEYQ0F-NZF3Ve_yg839d2-Hf2Vfo3PGvNqZ_5jcV1j0sZCOOX2CiX4kOtgdR4UOQJKUVRZVYdoHqbzEWLAUKde0hFXI_vg6yKOj8MiidfUDXEUNDfZZmifw0Xrvk6XhwBHiZMEdPs9qHWdqnr4SwkRpE-rLEZlZ6e-zQqg21pg
2021-09-01 18:36:54 ERROR (stream_worker) [libav.rtsp] method DESCRIBE failed: 404 Not Found
2021-09-01 18:36:54 ERROR (stream_worker) [homeassistant.components.stream.worker] Error opening stream rtsps://stream-uc2-bravo.dropcam.com:443/sdm_live_stream/CiQA2vuxrzSUh11qjH4VUWPmcl-T_VLGPcYlKSjUB70U1J8uImAScQBQBG8ti0c5BZeoDdrlgvTR6cbln82NpgmPIkrBweSWJE_YORFUFD6G-BLEW_hy_CZW-jWyIZQf_nUc94jL8tWgXEGOYuBVQ-SnC3kcTgJDh953WnzeTA2L7J99QxP3hFizjljV82XyLDH4IjoabngB?auth=g.0.eyJraWQiOiIyMzhiNTUxZmMyM2EyM2Y4M2E2ZTE3MmJjZTg0YmU3ZjgxMzAzMmM4IiwiYWxnIjoiUlMyNTYifQ.eyJpc3MiOiJuZXN0LXNlY3VyaXR5LWF1dGhwcm94eSIsInN1YiI6Im5lc3RfaWQ6bmVzdC1waG9lbml4LXByb2Q6MjEyMTgxNDEiLCJwb2wiOiIzcC1vYXV0aC1zY29wZS1BUElfU0RNX1NFUlZJQ0UtY2xpZW50LTIwMjQyNzMxODczNS1qNXQ5bWMyMzZqaG85YXMycWY0dTZxY3NmYW1kaGJ0ci5hcHBzLmdvb2dsZXVzZXJjb250ZW50LmNvbSIsImV4cCI6MTYzMDU0Njc4MH0.emYaBBQKvVr8e0bRYBJbttngMtI3EqeZpYPyFPb9nQs-EDnKNG8I3VvVW1GNMk9omSQZN_k0CVYJvh6sbMtb9ZcJRz5QuSZZJhTEiyNTwmwOeH3m9RD-g5a9lbLZZrAKRGB_YQibMPIFVXn3QJAnZ4EMi9gm_15AIK1hGe_N1TrIxEYQ0F-NZF3Ve_yg839d2-Hf2Vfo3PGvNqZ_5jcV1j0sZCOOX2CiX4kOtgdR4UOQJKUVRZVYdoHqbzEWLAUKde0hFXI_vg6yKOj8MiidfUDXEUNDfZZmifw0Xrvk6XhwBHiZMEdPs9qHWdqnr4SwkRpE-rLEZlZ6e-zQqg21pg
2021-09-01 18:38:17 ERROR (stream_worker) [libav.rtsp] method DESCRIBE failed: 404 Not Found
2021-09-01 18:38:17 ERROR (stream_worker) [homeassistant.components.stream.worker] Error opening stream rtsps://stream-uc2-bravo.dropcam.com:443/sdm_live_stream/CiQA2vuxrzSUh11qjH4VUWPmcl-T_VLGPcYlKSjUB70U1J8uImAScQBQBG8ti0c5BZeoDdrlgvTR6cbln82NpgmPIkrBweSWJE_YORFUFD6G-BLEW_hy_CZW-jWyIZQf_nUc94jL8tWgXEGOYuBVQ-SnC3kcTgJDh953WnzeTA2L7J99QxP3hFizjljV82XyLDH4IjoabngB?auth=g.0.eyJraWQiOiIyMzhiNTUxZmMyM2EyM2Y4M2E2ZTE3MmJjZTg0YmU3ZjgxMzAzMmM4IiwiYWxnIjoiUlMyNTYifQ.eyJpc3MiOiJuZXN0LXNlY3VyaXR5LWF1dGhwcm94eSIsInN1YiI6Im5lc3RfaWQ6bmVzdC1waG9lbml4LXByb2Q6MjEyMTgxNDEiLCJwb2wiOiIzcC1vYXV0aC1zY29wZS1BUElfU0RNX1NFUlZJQ0UtY2xpZW50LTIwMjQyNzMxODczNS1qNXQ5bWMyMzZqaG85YXMycWY0dTZxY3NmYW1kaGJ0ci5hcHBzLmdvb2dsZXVzZXJjb250ZW50LmNvbSIsImV4cCI6MTYzMDU0Njc4MH0.emYaBBQKvVr8e0bRYBJbttngMtI3EqeZpYPyFPb9nQs-EDnKNG8I3VvVW1GNMk9omSQZN_k0CVYJvh6sbMtb9ZcJRz5QuSZZJhTEiyNTwmwOeH3m9RD-g5a9lbLZZrAKRGB_YQibMPIFVXn3QJAnZ4EMi9gm_15AIK1hGe_N1TrIxEYQ0F-NZF3Ve_yg839d2-Hf2Vfo3PGvNqZ_5jcV1j0sZCOOX2CiX4kOtgdR4UOQJKUVRZVYdoHqbzEWLAUKde0hFXI_vg6yKOj8MiidfUDXEUNDfZZmifw0Xrvk6XhwBHiZMEdPs9qHWdqnr4SwkRpE-rLEZlZ6e-zQqg21pg
2021-09-01 18:39:31 ERROR (MainThread) [homeassistant.components.nws] Error requesting NWS forecast station SAUC1 data: 500, message='Internal Server Error', url=URL('https://api.weather.gov/gridpoints/LOX/146,60/forecast')
2021-09-01 18:39:52 ERROR (MainThread) [homeassistant] Error doing job: Future exception was never retrieved
Traceback (most recent call last):
  File "/usr/local/lib/python3.9/concurrent/futures/thread.py", line 52, in run
    result = self.fn(*self.args, **self.kwargs)
TypeError: update() takes 1 positional argument but 2 were given
2021-09-01 18:44:53 ERROR (MainThread) [homeassistant] Error doing job: Future exception was never retrieved
Traceback (most recent call last):
  File "/usr/local/lib/python3.9/concurrent/futures/thread.py", line 52, in run
    result = self.fn(*self.args, **self.kwargs)
TypeError: update() takes 1 positional argument but 2 were given
2021-09-01 18:49:54 ERROR (MainThread) [homeassistant] Error doing job: Future exception was never retrieved
Traceback (most recent call last):
  File "/usr/local/lib/python3.9/concurrent/futures/thread.py", line 52, in run
    result = self.fn(*self.args, **self.kwargs)
TypeError: update() takes 1 positional argument but 2 were given
2021-09-01 18:54:55 ERROR (MainThread) [homeassistant] Error doing job: Future exception was never retrieved
Traceback (most recent call last):
  File "/usr/local/lib/python3.9/concurrent/futures/thread.py", line 52, in run
    result = self.fn(*self.args, **self.kwargs)
TypeError: update() takes 1 positional argument but 2 were given
2021-09-01 18:59:56 ERROR (MainThread) [homeassistant] Error doing job: Future exception was never retrieved
Traceback (most recent call last):
  File "/usr/local/lib/python3.9/concurrent/futures/thread.py", line 52, in run
    result = self.fn(*self.args, **self.kwargs)
TypeError: update() takes 1 positional argument but 2 were given
2021-09-01 19:04:57 ERROR (MainThread) [homeassistant] Error doing job: Future exception was never retrieved
Traceback (most recent call last):
  File "/usr/local/lib/python3.9/concurrent/futures/thread.py", line 52, in run
    result = self.fn(*self.args, **self.kwargs)
TypeError: update() takes 1 positional argument but 2 were given
2021-09-01 19:09:58 ERROR (MainThread) [homeassistant] Error doing job: Future exception was never retrieved
Traceback (most recent call last):
  File "/usr/local/lib/python3.9/concurrent/futures/thread.py", line 52, in run
    result = self.fn(*self.args, **self.kwargs)
TypeError: update() takes 1 positional argument but 2 were given
2021-09-01 19:14:59 ERROR (MainThread) [homeassistant] Error doing job: Future exception was never retrieved
Traceback (most recent call last):
  File "/usr/local/lib/python3.9/concurrent/futures/thread.py", line 52, in run
    result = self.fn(*self.args, **self.kwargs)
TypeError: update() takes 1 positional argument but 2 were given
2021-09-01 19:19:32 WARNING (MainThread) [homeassistant.helpers.service] Unable to find referenced entities scene.kitchen_sink_on
2021-09-01 19:19:32 WARNING (MainThread) [homeassistant.helpers.service] Unable to find referenced entities light.hue_lightstrip_2
2021-09-01 19:20:00 ERROR (MainThread) [homeassistant] Error doing job: Future exception was never retrieved
Traceback (most recent call last):
  File "/usr/local/lib/python3.9/concurrent/futures/thread.py", line 52, in run
    result = self.fn(*self.args, **self.kwargs)
TypeError: update() takes 1 positional argument but 2 were given
2021-09-01 19:25:01 ERROR (MainThread) [homeassistant] Error doing job: Future exception was never retrieved
Traceback (most recent call last):
  File "/usr/local/lib/python3.9/concurrent/futures/thread.py", line 52, in run
    result = self.fn(*self.args, **self.kwargs)
TypeError: update() takes 1 positional argument but 2 were given
2021-09-01 19:30:02 ERROR (MainThread) [homeassistant] Error doing job: Future exception was never retrieved
Traceback (most recent call last):
  File "/usr/local/lib/python3.9/concurrent/futures/thread.py", line 52, in run
    result = self.fn(*self.args, **self.kwargs)
TypeError: update() takes 1 positional argument but 2 were given
2021-09-01 19:35:03 ERROR (MainThread) [homeassistant] Error doing job: Future exception was never retrieved
Traceback (most recent call last):
  File "/usr/local/lib/python3.9/concurrent/futures/thread.py", line 52, in run
    result = self.fn(*self.args, **self.kwargs)
TypeError: update() takes 1 positional argument but 2 were given
2021-09-01 19:40:04 ERROR (MainThread) [homeassistant] Error doing job: Future exception was never retrieved
Traceback (most recent call last):
  File "/usr/local/lib/python3.9/concurrent/futures/thread.py", line 52, in run
    result = self.fn(*self.args, **self.kwargs)
TypeError: update() takes 1 positional argument but 2 were given
2021-09-01 19:45:05 ERROR (MainThread) [homeassistant] Error doing job: Future exception was never retrieved
Traceback (most recent call last):
  File "/usr/local/lib/python3.9/concurrent/futures/thread.py", line 52, in run
    result = self.fn(*self.args, **self.kwargs)
TypeError: update() takes 1 positional argument but 2 were given
2021-09-01 19:50:06 ERROR (MainThread) [homeassistant] Error doing job: Future exception was never retrieved
Traceback (most recent call last):
  File "/usr/local/lib/python3.9/concurrent/futures/thread.py", line 52, in run
    result = self.fn(*self.args, **self.kwargs)
TypeError: update() takes 1 positional argument but 2 were given
2021-09-01 19:55:07 ERROR (MainThread) [homeassistant] Error doing job: Future exception was never retrieved
Traceback (most recent call last):
  File "/usr/local/lib/python3.9/concurrent/futures/thread.py", line 52, in run
    result = self.fn(*self.args, **self.kwargs)
TypeError: update() takes 1 positional argument but 2 were given
2021-09-01 20:00:08 ERROR (MainThread) [homeassistant] Error doing job: Future exception was never retrieved
Traceback (most recent call last):
  File "/usr/local/lib/python3.9/concurrent/futures/thread.py", line 52, in run
    result = self.fn(*self.args, **self.kwargs)
TypeError: update() takes 1 positional argument but 2 were given
2021-09-01 20:05:09 ERROR (MainThread) [homeassistant] Error doing job: Future exception was never retrieved
Traceback (most recent call last):
  File "/usr/local/lib/python3.9/concurrent/futures/thread.py", line 52, in run
    result = self.fn(*self.args, **self.kwargs)
TypeError: update() takes 1 positional argument but 2 were given
2021-09-01 20:10:10 ERROR (MainThread) [homeassistant] Error doing job: Future exception was never retrieved
Traceback (most recent call last):
  File "/usr/local/lib/python3.9/concurrent/futures/thread.py", line 52, in run
    result = self.fn(*self.args, **self.kwargs)
TypeError: update() takes 1 positional argument but 2 were given
2021-09-01 20:15:11 ERROR (MainThread) [homeassistant] Error doing job: Future exception was never retrieved
Traceback (most recent call last):
  File "/usr/local/lib/python3.9/concurrent/futures/thread.py", line 52, in run
    result = self.fn(*self.args, **self.kwargs)
TypeError: update() takes 1 positional argument but 2 were given
2021-09-01 20:20:12 ERROR (MainThread) [homeassistant] Error doing job: Future exception was never retrieved
Traceback (most recent call last):
  File "/usr/local/lib/python3.9/concurrent/futures/thread.py", line 52, in run
    result = self.fn(*self.args, **self.kwargs)
TypeError: update() takes 1 positional argument but 2 were given
2021-09-01 20:25:13 ERROR (MainThread) [homeassistant] Error doing job: Future exception was never retrieved
Traceback (most recent call last):
  File "/usr/local/lib/python3.9/concurrent/futures/thread.py", line 52, in run
    result = self.fn(*self.args, **self.kwargs)
TypeError: update() takes 1 positional argument but 2 were given
2021-09-01 20:30:14 ERROR (MainThread) [homeassistant] Error doing job: Future exception was never retrieved
Traceback (most recent call last):
  File "/usr/local/lib/python3.9/concurrent/futures/thread.py", line 52, in run
    result = self.fn(*self.args, **self.kwargs)
TypeError: update() takes 1 positional argument but 2 were given
2021-09-01 20:35:15 ERROR (MainThread) [homeassistant] Error doing job: Future exception was never retrieved
Traceback (most recent call last):
  File "/usr/local/lib/python3.9/concurrent/futures/thread.py", line 52, in run
    result = self.fn(*self.args, **self.kwargs)
TypeError: update() takes 1 positional argument but 2 were given
2021-09-01 20:40:16 ERROR (MainThread) [homeassistant] Error doing job: Future exception was never retrieved
Traceback (most recent call last):
  File "/usr/local/lib/python3.9/concurrent/futures/thread.py", line 52, in run
    result = self.fn(*self.args, **self.kwargs)
TypeError: update() takes 1 positional argument but 2 were given
2021-09-01 20:45:17 ERROR (MainThread) [homeassistant] Error doing job: Future exception was never retrieved
Traceback (most recent call last):
  File "/usr/local/lib/python3.9/concurrent/futures/thread.py", line 52, in run
    result = self.fn(*self.args, **self.kwargs)
TypeError: update() takes 1 positional argument but 2 were given
2021-09-01 20:50:18 ERROR (MainThread) [homeassistant] Error doing job: Future exception was never retrieved
Traceback (most recent call last):
  File "/usr/local/lib/python3.9/concurrent/futures/thread.py", line 52, in run
    result = self.fn(*self.args, **self.kwargs)
TypeError: update() takes 1 positional argument but 2 were given
2021-09-01 20:55:19 ERROR (MainThread) [homeassistant] Error doing job: Future exception was never retrieved
Traceback (most recent call last):
  File "/usr/local/lib/python3.9/concurrent/futures/thread.py", line 52, in run
    result = self.fn(*self.args, **self.kwargs)
TypeError: update() takes 1 positional argument but 2 were given
2021-09-01 21:00:20 ERROR (MainThread) [homeassistant] Error doing job: Future exception was never retrieved
Traceback (most recent call last):
  File "/usr/local/lib/python3.9/concurrent/futures/thread.py", line 52, in run
    result = self.fn(*self.args, **self.kwargs)
TypeError: update() takes 1 positional argument but 2 were given
2021-09-01 21:05:21 ERROR (MainThread) [homeassistant] Error doing job: Future exception was never retrieved
Traceback (most recent call last):
  File "/usr/local/lib/python3.9/concurrent/futures/thread.py", line 52, in run
    result = self.fn(*self.args, **self.kwargs)
TypeError: update() takes 1 positional argument but 2 were given
2021-09-01 21:10:22 ERROR (MainThread) [homeassistant] Error doing job: Future exception was never retrieved
Traceback (most recent call last):
  File "/usr/local/lib/python3.9/concurrent/futures/thread.py", line 52, in run
    result = self.fn(*self.args, **self.kwargs)
TypeError: update() takes 1 positional argument but 2 were given
2021-09-01 21:15:23 ERROR (MainThread) [homeassistant] Error doing job: Future exception was never retrieved
Traceback (most recent call last):
  File "/usr/local/lib/python3.9/concurrent/futures/thread.py", line 52, in run
    result = self.fn(*self.args, **self.kwargs)
TypeError: update() takes 1 positional argument but 2 were given
2021-09-01 21:20:24 ERROR (MainThread) [homeassistant] Error doing job: Future exception was never retrieved
Traceback (most recent call last):
  File "/usr/local/lib/python3.9/concurrent/futures/thread.py", line 52, in run
    result = self.fn(*self.args, **self.kwargs)
TypeError: update() takes 1 positional argument but 2 were given
2021-09-01 21:25:25 ERROR (MainThread) [homeassistant] Error doing job: Future exception was never retrieved
Traceback (most recent call last):
  File "/usr/local/lib/python3.9/concurrent/futures/thread.py", line 52, in run
    result = self.fn(*self.args, **self.kwargs)
TypeError: update() takes 1 positional argument but 2 were given
2021-09-01 21:30:26 ERROR (MainThread) [homeassistant] Error doing job: Future exception was never retrieved
Traceback (most recent call last):
  File "/usr/local/lib/python3.9/concurrent/futures/thread.py", line 52, in run
    result = self.fn(*self.args, **self.kwargs)
TypeError: update() takes 1 positional argument but 2 were given
2021-09-01 21:35:27 ERROR (MainThread) [homeassistant] Error doing job: Future exception was never retrieved
Traceback (most recent call last):
  File "/usr/local/lib/python3.9/concurrent/futures/thread.py", line 52, in run
    result = self.fn(*self.args, **self.kwargs)
TypeError: update() takes 1 positional argument but 2 were given
2021-09-01 21:38:35 WARNING (MainThread) [bellows.zigbee.application] Watchdog heartbeat timeout: 
2021-09-01 21:38:50 WARNING (MainThread) [bellows.zigbee.application] Watchdog heartbeat timeout: 
2021-09-01 21:38:57 ERROR (bellows.thread_0) [bellows.uart] CRC error in frame b'189c1f27aa5a7e' (b'aa5a' != b'5034')
2021-09-01 21:38:57 ERROR (MainThread) [bellows.ezsp] NCP entered failed state. Requesting APP controller restart
2021-09-01 21:39:41 ERROR (MainThread) [homeassistant] Error doing job: Task was destroyed but it is pending!
2021-09-01 21:40:28 ERROR (MainThread) [homeassistant] Error doing job: Future exception was never retrieved
Traceback (most recent call last):
  File "/usr/local/lib/python3.9/concurrent/futures/thread.py", line 52, in run
    result = self.fn(*self.args, **self.kwargs)
TypeError: update() takes 1 positional argument but 2 were given
2021-09-01 21:45:29 ERROR (MainThread) [homeassistant] Error doing job: Future exception was never retrieved
Traceback (most recent call last):
  File "/usr/local/lib/python3.9/concurrent/futures/thread.py", line 52, in run
    result = self.fn(*self.args, **self.kwargs)
TypeError: update() takes 1 positional argument but 2 were given
2021-09-01 21:50:30 ERROR (MainThread) [homeassistant] Error doing job: Future exception was never retrieved
Traceback (most recent call last):
  File "/usr/local/lib/python3.9/concurrent/futures/thread.py", line 52, in run
    result = self.fn(*self.args, **self.kwargs)
TypeError: update() takes 1 positional argument but 2 were given
2021-09-01 21:55:31 ERROR (MainThread) [homeassistant] Error doing job: Future exception was never retrieved
Traceback (most recent call last):
  File "/usr/local/lib/python3.9/concurrent/futures/thread.py", line 52, in run
    result = self.fn(*self.args, **self.kwargs)
TypeError: update() takes 1 positional argument but 2 were given
2021-09-01 22:00:32 ERROR (MainThread) [homeassistant] Error doing job: Future exception was never retrieved
Traceback (most recent call last):
  File "/usr/local/lib/python3.9/concurrent/futures/thread.py", line 52, in run
    result = self.fn(*self.args, **self.kwargs)
TypeError: update() takes 1 positional argument but 2 were given
2021-09-01 22:00:47 ERROR (stream_worker) [libav.tls] The specified session has been invalidated for some reason.
2021-09-01 22:00:47 ERROR (stream_worker) [homeassistant.components.stream.worker] Error demuxing stream: 
2021-09-01 22:01:17 ERROR (stream_worker) [libav.tls] The specified session has been invalidated for some reason.
2021-09-01 22:01:19 ERROR (stream_worker) [libav.rtsp] method DESCRIBE failed: 403 Forbidden
2021-09-01 22:01:19 ERROR (stream_worker) [homeassistant.components.stream.worker] Error opening stream rtsps://stream-uc2-delta.dropcam.com:443/sdm_live_stream/CiQA2vuxr78j7c5P9HWw124G6Ni7awY_aM0OSh9LOuJzPSL-NJQScABQBG8tLmoZV4IRRVg1cIhOuT_RrvHzJBhOBJOx6w5v-nNDykd2JFTZFPeevFG7YiBW81o93-Xg7DjO3RQqv2-azIbMI01XY-zj1iuvbO7erqeDNtYVGMFUnt5EvnZyyBt4lDJZ_cN2G19vwwjB4PQ?auth=g.0.eyJraWQiOiIyMzhiNTUxZmMyM2EyM2Y4M2E2ZTE3MmJjZTg0YmU3ZjgxMzAzMmM4IiwiYWxnIjoiUlMyNTYifQ.eyJpc3MiOiJuZXN0LXNlY3VyaXR5LWF1dGhwcm94eSIsInN1YiI6Im5lc3RfaWQ6bmVzdC1waG9lbml4LXByb2Q6MjEyMTgxNDEiLCJwb2wiOiIzcC1vYXV0aC1zY29wZS1BUElfU0RNX1NFUlZJQ0UtY2xpZW50LTIwMjQyNzMxODczNS1qNXQ5bWMyMzZqaG85YXMycWY0dTZxY3NmYW1kaGJ0ci5hcHBzLmdvb2dsZXVzZXJjb250ZW50LmNvbSIsImV4cCI6MTYzMDU1ODk4M30.RrBhXjoiajZMF2NDOIfRPPqSGExv4QVAKulRFmYPQCcF-den5H1bR5_0pktxG8QHNewRfRZHWvyWhY5NI7U1RTZ2PyAjcG8rk7OkuPvTaanvbMzOIBeSbvOPYKmihXwknPLJjRsXIbBBQEJEjFHA5Wf6gpdl48ZzDt9UT-MAkLZgvlkA76SoEfMaDKJqBA8b7xNxt72rTY2z5F4vUD9bnol56ADg-88mMhIKmp44QPvu5VfdrzxzCuZl0nrEcDzmpjihK5REHqEDlf_cQKYvTVwjVNg6xiaVzIUdEmVXfhsC7gXwI6qktUM2AwpowezdDK1IF4YrS_X9W7sceFhoLw
2021-09-01 22:01:59 ERROR (stream_worker) [libav.rtsp] method DESCRIBE failed: 403 Forbidden
2021-09-01 22:01:59 ERROR (stream_worker) [homeassistant.components.stream.worker] Error opening stream rtsps://stream-uc2-delta.dropcam.com:443/sdm_live_stream/CiQA2vuxr78j7c5P9HWw124G6Ni7awY_aM0OSh9LOuJzPSL-NJQScABQBG8tLmoZV4IRRVg1cIhOuT_RrvHzJBhOBJOx6w5v-nNDykd2JFTZFPeevFG7YiBW81o93-Xg7DjO3RQqv2-azIbMI01XY-zj1iuvbO7erqeDNtYVGMFUnt5EvnZyyBt4lDJZ_cN2G19vwwjB4PQ?auth=g.0.eyJraWQiOiIyMzhiNTUxZmMyM2EyM2Y4M2E2ZTE3MmJjZTg0YmU3ZjgxMzAzMmM4IiwiYWxnIjoiUlMyNTYifQ.eyJpc3MiOiJuZXN0LXNlY3VyaXR5LWF1dGhwcm94eSIsInN1YiI6Im5lc3RfaWQ6bmVzdC1waG9lbml4LXByb2Q6MjEyMTgxNDEiLCJwb2wiOiIzcC1vYXV0aC1zY29wZS1BUElfU0RNX1NFUlZJQ0UtY2xpZW50LTIwMjQyNzMxODczNS1qNXQ5bWMyMzZqaG85YXMycWY0dTZxY3NmYW1kaGJ0ci5hcHBzLmdvb2dsZXVzZXJjb250ZW50LmNvbSIsImV4cCI6MTYzMDU1ODk4M30.RrBhXjoiajZMF2NDOIfRPPqSGExv4QVAKulRFmYPQCcF-den5H1bR5_0pktxG8QHNewRfRZHWvyWhY5NI7U1RTZ2PyAjcG8rk7OkuPvTaanvbMzOIBeSbvOPYKmihXwknPLJjRsXIbBBQEJEjFHA5Wf6gpdl48ZzDt9UT-MAkLZgvlkA76SoEfMaDKJqBA8b7xNxt72rTY2z5F4vUD9bnol56ADg-88mMhIKmp44QPvu5VfdrzxzCuZl0nrEcDzmpjihK5REHqEDlf_cQKYvTVwjVNg6xiaVzIUdEmVXfhsC7gXwI6qktUM2AwpowezdDK1IF4YrS_X9W7sceFhoLw
2021-09-01 22:05:33 ERROR (MainThread) [homeassistant] Error doing job: Future exception was never retrieved
Traceback (most recent call last):
  File "/usr/local/lib/python3.9/concurrent/futures/thread.py", line 52, in run
    result = self.fn(*self.args, **self.kwargs)
TypeError: update() takes 1 positional argument but 2 were given
2021-09-01 22:10:34 ERROR (MainThread) [homeassistant] Error doing job: Future exception was never retrieved
Traceback (most recent call last):
  File "/usr/local/lib/python3.9/concurrent/futures/thread.py", line 52, in run
    result = self.fn(*self.args, **self.kwargs)
TypeError: update() takes 1 positional argument but 2 were given
2021-09-01 22:15:35 ERROR (MainThread) [homeassistant] Error doing job: Future exception was never retrieved
Traceback (most recent call last):
  File "/usr/local/lib/python3.9/concurrent/futures/thread.py", line 52, in run
    result = self.fn(*self.args, **self.kwargs)
TypeError: update() takes 1 positional argument but 2 were given
2021-09-01 22:20:36 ERROR (MainThread) [homeassistant] Error doing job: Future exception was never retrieved
Traceback (most recent call last):
  File "/usr/local/lib/python3.9/concurrent/futures/thread.py", line 52, in run
    result = self.fn(*self.args, **self.kwargs)
TypeError: update() takes 1 positional argument but 2 were given
2021-09-01 22:25:37 ERROR (MainThread) [homeassistant] Error doing job: Future exception was never retrieved
Traceback (most recent call last):
  File "/usr/local/lib/python3.9/concurrent/futures/thread.py", line 52, in run
    result = self.fn(*self.args, **self.kwargs)
TypeError: update() takes 1 positional argument but 2 were given
2021-09-01 22:30:38 ERROR (MainThread) [homeassistant] Error doing job: Future exception was never retrieved
Traceback (most recent call last):
  File "/usr/local/lib/python3.9/concurrent/futures/thread.py", line 52, in run
    result = self.fn(*self.args, **self.kwargs)
TypeError: update() takes 1 positional argument but 2 were given
2021-09-01 22:35:39 ERROR (MainThread) [homeassistant] Error doing job: Future exception was never retrieved
Traceback (most recent call last):
  File "/usr/local/lib/python3.9/concurrent/futures/thread.py", line 52, in run
    result = self.fn(*self.args, **self.kwargs)
TypeError: update() takes 1 positional argument but 2 were given
2021-09-01 22:40:40 ERROR (MainThread) [homeassistant] Error doing job: Future exception was never retrieved
Traceback (most recent call last):
  File "/usr/local/lib/python3.9/concurrent/futures/thread.py", line 52, in run
    result = self.fn(*self.args, **self.kwargs)
TypeError: update() takes 1 positional argument but 2 were given
2021-09-01 22:45:41 ERROR (MainThread) [homeassistant] Error doing job: Future exception was never retrieved
Traceback (most recent call last):
  File "/usr/local/lib/python3.9/concurrent/futures/thread.py", line 52, in run
    result = self.fn(*self.args, **self.kwargs)
TypeError: update() takes 1 positional argument but 2 were given
2021-09-01 22:50:42 ERROR (MainThread) [homeassistant] Error doing job: Future exception was never retrieved
Traceback (most recent call last):
  File "/usr/local/lib/python3.9/concurrent/futures/thread.py", line 52, in run
    result = self.fn(*self.args, **self.kwargs)
TypeError: update() takes 1 positional argument but 2 were given
2021-09-01 22:55:43 ERROR (MainThread) [homeassistant] Error doing job: Future exception was never retrieved
Traceback (most recent call last):
  File "/usr/local/lib/python3.9/concurrent/futures/thread.py", line 52, in run
    result = self.fn(*self.args, **self.kwargs)
TypeError: update() takes 1 positional argument but 2 were given
2021-09-01 23:00:00 WARNING (MainThread) [homeassistant.helpers.service] Unable to find referenced entities light.sophia_wled
2021-09-01 23:00:44 ERROR (MainThread) [homeassistant] Error doing job: Future exception was never retrieved
Traceback (most recent call last):
  File "/usr/local/lib/python3.9/concurrent/futures/thread.py", line 52, in run
    result = self.fn(*self.args, **self.kwargs)
TypeError: update() takes 1 positional argument but 2 were given
2021-09-01 23:05:45 ERROR (MainThread) [homeassistant] Error doing job: Future exception was never retrieved
Traceback (most recent call last):
  File "/usr/local/lib/python3.9/concurrent/futures/thread.py", line 52, in run
    result = self.fn(*self.args, **self.kwargs)
TypeError: update() takes 1 positional argument but 2 were given
2021-09-01 23:10:46 ERROR (MainThread) [homeassistant] Error doing job: Future exception was never retrieved
Traceback (most recent call last):
  File "/usr/local/lib/python3.9/concurrent/futures/thread.py", line 52, in run
    result = self.fn(*self.args, **self.kwargs)
TypeError: update() takes 1 positional argument but 2 were given
2021-09-01 23:12:00 WARNING (Recorder) [homeassistant.components.sensor.recorder] Entity sensor.solar_energy from integration integration has state class total_increasing, but its state is not strictly increasing. Please create a bug report at https://github.com/home-assistant/core/issues?q=is%3Aopen+is%3Aissue+label%3A%22integration%3A+recorder%22
2021-09-01 23:15:47 ERROR (MainThread) [homeassistant] Error doing job: Future exception was never retrieved
Traceback (most recent call last):
  File "/usr/local/lib/python3.9/concurrent/futures/thread.py", line 52, in run
    result = self.fn(*self.args, **self.kwargs)
TypeError: update() takes 1 positional argument but 2 were given
2021-09-01 23:20:48 ERROR (MainThread) [homeassistant] Error doing job: Future exception was never retrieved
Traceback (most recent call last):
  File "/usr/local/lib/python3.9/concurrent/futures/thread.py", line 52, in run
    result = self.fn(*self.args, **self.kwargs)
TypeError: update() takes 1 positional argument but 2 were given
2021-09-01 23:25:49 ERROR (MainThread) [homeassistant] Error doing job: Future exception was never retrieved
Traceback (most recent call last):
  File "/usr/local/lib/python3.9/concurrent/futures/thread.py", line 52, in run
    result = self.fn(*self.args, **self.kwargs)
TypeError: update() takes 1 positional argument but 2 were given
2021-09-01 23:30:50 ERROR (MainThread) [homeassistant] Error doing job: Future exception was never retrieved
Traceback (most recent call last):
  File "/usr/local/lib/python3.9/concurrent/futures/thread.py", line 52, in run
    result = self.fn(*self.args, **self.kwargs)
TypeError: update() takes 1 positional argument but 2 were given
2021-09-01 23:35:51 ERROR (MainThread) [homeassistant] Error doing job: Future exception was never retrieved
Traceback (most recent call last):
  File "/usr/local/lib/python3.9/concurrent/futures/thread.py", line 52, in run
    result = self.fn(*self.args, **self.kwargs)
TypeError: update() takes 1 positional argument but 2 were given
2021-09-01 23:40:52 ERROR (MainThread) [homeassistant] Error doing job: Future exception was never retrieved
Traceback (most recent call last):
  File "/usr/local/lib/python3.9/concurrent/futures/thread.py", line 52, in run
    result = self.fn(*self.args, **self.kwargs)
TypeError: update() takes 1 positional argument but 2 were given
2021-09-01 23:45:53 ERROR (MainThread) [homeassistant] Error doing job: Future exception was never retrieved
Traceback (most recent call last):
  File "/usr/local/lib/python3.9/concurrent/futures/thread.py", line 52, in run
    result = self.fn(*self.args, **self.kwargs)
TypeError: update() takes 1 positional argument but 2 were given
2021-09-01 23:50:54 ERROR (MainThread) [homeassistant] Error doing job: Future exception was never retrieved
Traceback (most recent call last):
  File "/usr/local/lib/python3.9/concurrent/futures/thread.py", line 52, in run
    result = self.fn(*self.args, **self.kwargs)
TypeError: update() takes 1 positional argument but 2 were given
2021-09-01 23:55:55 ERROR (MainThread) [homeassistant] Error doing job: Future exception was never retrieved
Traceback (most recent call last):
  File "/usr/local/lib/python3.9/concurrent/futures/thread.py", line 52, in run
    result = self.fn(*self.args, **self.kwargs)
TypeError: update() takes 1 positional argument but 2 were given
2021-09-02 00:00:56 ERROR (MainThread) [homeassistant] Error doing job: Future exception was never retrieved
Traceback (most recent call last):
  File "/usr/local/lib/python3.9/concurrent/futures/thread.py", line 52, in run
    result = self.fn(*self.args, **self.kwargs)
TypeError: update() takes 1 positional argument but 2 were given
2021-09-02 00:05:57 ERROR (MainThread) [homeassistant] Error doing job: Future exception was never retrieved
Traceback (most recent call last):
  File "/usr/local/lib/python3.9/concurrent/futures/thread.py", line 52, in run
    result = self.fn(*self.args, **self.kwargs)
TypeError: update() takes 1 positional argument but 2 were given
2021-09-02 00:10:04 WARNING (MainThread) [bellows.zigbee.application] Watchdog heartbeat timeout: 
2021-09-02 00:10:05 ERROR (bellows.thread_0) [bellows.uart] CRC error in frame b'5c48a1a9a52a25b2d9942d258b5582499d4e27abedce7b8bf8c66389fc7e3fa7ebcdde6f8f4c2613b1e070381c0e07bbe5ca658a459a4d9e4f9ff7c3d9d46a35a2519048247ce97e' (b'7ce9' != b'b50c')
2021-09-02 00:10:05 ERROR (MainThread) [bellows.ezsp] NCP entered failed state. Requesting APP controller restart
2021-09-02 00:10:21 ERROR (MainThread) [homeassistant] Error doing job: Task was destroyed but it is pending!
2021-09-02 00:10:58 ERROR (MainThread) [homeassistant] Error doing job: Future exception was never retrieved
Traceback (most recent call last):
  File "/usr/local/lib/python3.9/concurrent/futures/thread.py", line 52, in run
    result = self.fn(*self.args, **self.kwargs)
TypeError: update() takes 1 positional argument but 2 were given
2021-09-02 00:15:59 ERROR (MainThread) [homeassistant] Error doing job: Future exception was never retrieved
Traceback (most recent call last):
  File "/usr/local/lib/python3.9/concurrent/futures/thread.py", line 52, in run
    result = self.fn(*self.args, **self.kwargs)
TypeError: update() takes 1 positional argument but 2 were given
2021-09-02 00:21:00 ERROR (MainThread) [homeassistant] Error doing job: Future exception was never retrieved
Traceback (most recent call last):
  File "/usr/local/lib/python3.9/concurrent/futures/thread.py", line 52, in run
    result = self.fn(*self.args, **self.kwargs)
TypeError: update() takes 1 positional argument but 2 were given
2021-09-02 00:26:01 ERROR (MainThread) [homeassistant] Error doing job: Future exception was never retrieved
Traceback (most recent call last):
  File "/usr/local/lib/python3.9/concurrent/futures/thread.py", line 52, in run
    result = self.fn(*self.args, **self.kwargs)
TypeError: update() takes 1 positional argument but 2 were given
2021-09-02 00:31:02 ERROR (MainThread) [homeassistant] Error doing job: Future exception was never retrieved
Traceback (most recent call last):
  File "/usr/local/lib/python3.9/concurrent/futures/thread.py", line 52, in run
    result = self.fn(*self.args, **self.kwargs)
TypeError: update() takes 1 positional argument but 2 were given
2021-09-02 00:36:03 ERROR (MainThread) [homeassistant] Error doing job: Future exception was never retrieved
Traceback (most recent call last):
  File "/usr/local/lib/python3.9/concurrent/futures/thread.py", line 52, in run
    result = self.fn(*self.args, **self.kwargs)
TypeError: update() takes 1 positional argument but 2 were given
2021-09-02 00:41:04 ERROR (MainThread) [homeassistant] Error doing job: Future exception was never retrieved
Traceback (most recent call last):
  File "/usr/local/lib/python3.9/concurrent/futures/thread.py", line 52, in run
    result = self.fn(*self.args, **self.kwargs)
TypeError: update() takes 1 positional argument but 2 were given
2021-09-02 00:46:05 ERROR (MainThread) [homeassistant] Error doing job: Future exception was never retrieved
Traceback (most recent call last):
  File "/usr/local/lib/python3.9/concurrent/futures/thread.py", line 52, in run
    result = self.fn(*self.args, **self.kwargs)
TypeError: update() takes 1 positional argument but 2 were given
2021-09-02 00:51:06 ERROR (MainThread) [homeassistant] Error doing job: Future exception was never retrieved
Traceback (most recent call last):
  File "/usr/local/lib/python3.9/concurrent/futures/thread.py", line 52, in run
    result = self.fn(*self.args, **self.kwargs)
TypeError: update() takes 1 positional argument but 2 were given
2021-09-02 00:54:19 ERROR (MainThread) [homeassistant.components.template.template_entity] TemplateError('UndefinedError: list object has no element 4') while processing template 'Template("{% if states.sensor.iss_pass_times %}{{ states.sensor.iss_pass_times.attributes["response"][4]["risetime"] | timestamp_custom("%a %d %b %Y %H:%M:%S") }}{% endif %}")' for attribute '_attr_native_value' in entity 'sensor.iss_risetime_4'
2021-09-02 00:54:19 ERROR (MainThread) [homeassistant.components.template.template_entity] TemplateError('UndefinedError: list object has no element 4') while processing template 'Template("{% if states.sensor.iss_pass_times %}{{ states.sensor.iss_pass_times.attributes["response"][4]["duration"] }}{% endif %}")' for attribute '_attr_native_value' in entity 'sensor.iss_duration_4'
2021-09-02 00:56:07 ERROR (MainThread) [homeassistant] Error doing job: Future exception was never retrieved
Traceback (most recent call last):
  File "/usr/local/lib/python3.9/concurrent/futures/thread.py", line 52, in run
    result = self.fn(*self.args, **self.kwargs)
TypeError: update() takes 1 positional argument but 2 were given
2021-09-02 01:01:08 ERROR (MainThread) [homeassistant] Error doing job: Future exception was never retrieved
Traceback (most recent call last):
  File "/usr/local/lib/python3.9/concurrent/futures/thread.py", line 52, in run
    result = self.fn(*self.args, **self.kwargs)
TypeError: update() takes 1 positional argument but 2 were given
2021-09-02 01:06:09 ERROR (MainThread) [homeassistant] Error doing job: Future exception was never retrieved
Traceback (most recent call last):
  File "/usr/local/lib/python3.9/concurrent/futures/thread.py", line 52, in run
    result = self.fn(*self.args, **self.kwargs)
TypeError: update() takes 1 positional argument but 2 were given
2021-09-02 01:11:10 ERROR (MainThread) [homeassistant] Error doing job: Future exception was never retrieved
Traceback (most recent call last):
  File "/usr/local/lib/python3.9/concurrent/futures/thread.py", line 52, in run
    result = self.fn(*self.args, **self.kwargs)
TypeError: update() takes 1 positional argument but 2 were given
2021-09-02 01:16:11 ERROR (MainThread) [homeassistant] Error doing job: Future exception was never retrieved
Traceback (most recent call last):
  File "/usr/local/lib/python3.9/concurrent/futures/thread.py", line 52, in run
    result = self.fn(*self.args, **self.kwargs)
TypeError: update() takes 1 positional argument but 2 were given
2021-09-02 01:21:12 ERROR (MainThread) [homeassistant] Error doing job: Future exception was never retrieved
Traceback (most recent call last):
  File "/usr/local/lib/python3.9/concurrent/futures/thread.py", line 52, in run
    result = self.fn(*self.args, **self.kwargs)
TypeError: update() takes 1 positional argument but 2 were given
2021-09-02 01:26:13 ERROR (MainThread) [homeassistant] Error doing job: Future exception was never retrieved
Traceback (most recent call last):
  File "/usr/local/lib/python3.9/concurrent/futures/thread.py", line 52, in run
    result = self.fn(*self.args, **self.kwargs)
TypeError: update() takes 1 positional argument but 2 were given
2021-09-02 01:31:14 ERROR (MainThread) [homeassistant] Error doing job: Future exception was never retrieved
Traceback (most recent call last):
  File "/usr/local/lib/python3.9/concurrent/futures/thread.py", line 52, in run
    result = self.fn(*self.args, **self.kwargs)
TypeError: update() takes 1 positional argument but 2 were given
2021-09-02 01:36:15 ERROR (MainThread) [homeassistant] Error doing job: Future exception was never retrieved
Traceback (most recent call last):
  File "/usr/local/lib/python3.9/concurrent/futures/thread.py", line 52, in run
    result = self.fn(*self.args, **self.kwargs)
TypeError: update() takes 1 positional argument but 2 were given
2021-09-02 01:41:16 ERROR (MainThread) [homeassistant] Error doing job: Future exception was never retrieved
Traceback (most recent call last):
  File "/usr/local/lib/python3.9/concurrent/futures/thread.py", line 52, in run
    result = self.fn(*self.args, **self.kwargs)
TypeError: update() takes 1 positional argument but 2 were given
2021-09-02 01:46:17 ERROR (MainThread) [homeassistant] Error doing job: Future exception was never retrieved
Traceback (most recent call last):
  File "/usr/local/lib/python3.9/concurrent/futures/thread.py", line 52, in run
    result = self.fn(*self.args, **self.kwargs)
TypeError: update() takes 1 positional argument but 2 were given
2021-09-02 01:51:18 ERROR (MainThread) [homeassistant] Error doing job: Future exception was never retrieved
Traceback (most recent call last):
  File "/usr/local/lib/python3.9/concurrent/futures/thread.py", line 52, in run
    result = self.fn(*self.args, **self.kwargs)
TypeError: update() takes 1 positional argument but 2 were given
2021-09-02 01:56:19 ERROR (MainThread) [homeassistant] Error doing job: Future exception was never retrieved
Traceback (most recent call last):
  File "/usr/local/lib/python3.9/concurrent/futures/thread.py", line 52, in run
    result = self.fn(*self.args, **self.kwargs)
TypeError: update() takes 1 positional argument but 2 were given
2021-09-02 02:01:20 ERROR (MainThread) [homeassistant] Error doing job: Future exception was never retrieved
Traceback (most recent call last):
  File "/usr/local/lib/python3.9/concurrent/futures/thread.py", line 52, in run
    result = self.fn(*self.args, **self.kwargs)
TypeError: update() takes 1 positional argument but 2 were given
2021-09-02 02:06:21 ERROR (MainThread) [homeassistant] Error doing job: Future exception was never retrieved
Traceback (most recent call last):
  File "/usr/local/lib/python3.9/concurrent/futures/thread.py", line 52, in run
    result = self.fn(*self.args, **self.kwargs)
TypeError: update() takes 1 positional argument but 2 were given
2021-09-02 02:07:13 ERROR (MainThread) [homeassistant.components.nws] Error requesting NWS observation station SAUC1 data: 503, message='Service Unavailable', url=URL('https://api.weather.gov/stations/SAUC1/observations')
2021-09-02 02:11:22 ERROR (MainThread) [homeassistant] Error doing job: Future exception was never retrieved
Traceback (most recent call last):
  File "/usr/local/lib/python3.9/concurrent/futures/thread.py", line 52, in run
    result = self.fn(*self.args, **self.kwargs)
TypeError: update() takes 1 positional argument but 2 were given
2021-09-02 02:16:23 ERROR (MainThread) [homeassistant] Error doing job: Future exception was never retrieved
Traceback (most recent call last):
  File "/usr/local/lib/python3.9/concurrent/futures/thread.py", line 52, in run
    result = self.fn(*self.args, **self.kwargs)
TypeError: update() takes 1 positional argument but 2 were given
2021-09-02 02:21:24 ERROR (MainThread) [homeassistant] Error doing job: Future exception was never retrieved
Traceback (most recent call last):
  File "/usr/local/lib/python3.9/concurrent/futures/thread.py", line 52, in run
    result = self.fn(*self.args, **self.kwargs)
TypeError: update() takes 1 positional argument but 2 were given
2021-09-02 02:23:09 WARNING (Thread-15) [pychromecast.socket_client] [Bedroom_Sophia speaker(192.168.20.60):8009] Heartbeat timeout, resetting connection
2021-09-02 02:23:27 ERROR (Thread-15) [pychromecast.socket_client] [Bedroom_Sophia speaker(192.168.20.60):8009] Failed to connect to service ServiceInfo(type='host', data=('192.168.20.60', 8009)), retrying in 5.0s
2021-09-02 02:26:25 ERROR (MainThread) [homeassistant] Error doing job: Future exception was never retrieved
Traceback (most recent call last):
  File "/usr/local/lib/python3.9/concurrent/futures/thread.py", line 52, in run
    result = self.fn(*self.args, **self.kwargs)
TypeError: update() takes 1 positional argument but 2 were given
2021-09-02 02:31:26 ERROR (MainThread) [homeassistant] Error doing job: Future exception was never retrieved
Traceback (most recent call last):
  File "/usr/local/lib/python3.9/concurrent/futures/thread.py", line 52, in run
    result = self.fn(*self.args, **self.kwargs)
TypeError: update() takes 1 positional argument but 2 were given
2021-09-02 02:36:27 ERROR (MainThread) [homeassistant] Error doing job: Future exception was never retrieved
Traceback (most recent call last):
  File "/usr/local/lib/python3.9/concurrent/futures/thread.py", line 52, in run
    result = self.fn(*self.args, **self.kwargs)
TypeError: update() takes 1 positional argument but 2 were given
2021-09-02 02:41:28 ERROR (MainThread) [homeassistant] Error doing job: Future exception was never retrieved
Traceback (most recent call last):
  File "/usr/local/lib/python3.9/concurrent/futures/thread.py", line 52, in run
    result = self.fn(*self.args, **self.kwargs)
TypeError: update() takes 1 positional argument but 2 were given
2021-09-02 02:46:29 ERROR (MainThread) [homeassistant] Error doing job: Future exception was never retrieved
Traceback (most recent call last):
  File "/usr/local/lib/python3.9/concurrent/futures/thread.py", line 52, in run
    result = self.fn(*self.args, **self.kwargs)
TypeError: update() takes 1 positional argument but 2 were given
2021-09-02 02:51:30 ERROR (MainThread) [homeassistant] Error doing job: Future exception was never retrieved
Traceback (most recent call last):
  File "/usr/local/lib/python3.9/concurrent/futures/thread.py", line 52, in run
    result = self.fn(*self.args, **self.kwargs)
TypeError: update() takes 1 positional argument but 2 were given
2021-09-02 02:56:31 ERROR (MainThread) [homeassistant] Error doing job: Future exception was never retrieved
Traceback (most recent call last):
  File "/usr/local/lib/python3.9/concurrent/futures/thread.py", line 52, in run
    result = self.fn(*self.args, **self.kwargs)
TypeError: update() takes 1 positional argument but 2 were given
2021-09-02 03:01:06 WARNING (Thread-837) [homeassistant.util.executor] Thread[SyncWorker_5] is still running at shutdown: File "/usr/local/lib/python3.9/threading.py", line 930, in _bootstrap
    self._bootstrap_inner()
  File "/usr/local/lib/python3.9/threading.py", line 973, in _bootstrap_inner
    self.run()
  File "/usr/local/lib/python3.9/threading.py", line 910, in run
    self._target(*self._args, **self._kwargs)
  File "/usr/local/lib/python3.9/concurrent/futures/thread.py", line 77, in _worker
    work_item.run()
  File "/usr/local/lib/python3.9/concurrent/futures/thread.py", line 52, in run
    result = self.fn(*self.args, **self.kwargs)
  File "/usr/src/homeassistant/homeassistant/components/discovery/__init__.py", line 225, in _discover
    for disc in netdisco.discover():
  File "/usr/local/lib/python3.9/site-packages/netdisco/discovery.py", line 103, in discover
    return [dis for dis, checker in self.discoverables.items()
  File "/usr/local/lib/python3.9/site-packages/netdisco/discovery.py", line 104, in <listcomp>
    if checker.is_discovered()]
  File "/usr/local/lib/python3.9/site-packages/netdisco/discoverables/__init__.py", line 21, in is_discovered
    return len(self.get_entries()) > 0
  File "/usr/local/lib/python3.9/site-packages/netdisco/discoverables/plex_mediaserver.py", line 21, in get_entries
    return self.find_by_data({'Content-Type': 'plex/media-server'})
  File "/usr/local/lib/python3.9/site-packages/netdisco/discoverables/__init__.py", line 159, in find_by_data
    return self.netdis.gdm.find_by_data(values)
  File "/usr/local/lib/python3.9/site-packages/netdisco/gdm.py", line 41, in find_by_data
    self.scan()
  File "/usr/local/lib/python3.9/site-packages/netdisco/gdm.py", line 23, in scan
    self.update()
  File "/usr/local/lib/python3.9/site-packages/netdisco/gdm.py", line 85, in update
    bdata, server = sock.recvfrom(1024)
