2021-09-10 19:59:19 WARNING (SyncWorker_0) [homeassistant.loader] We found a custom integration sun2 which has not been tested by Home Assistant. This component might cause stability problems, be sure to disable it if you experience issues with Home Assistant
2021-09-10 19:59:29 ERROR (MainThread) [snitun.client.client_peer] Challenge/Response error with SniTun server
2021-09-10 19:59:29 ERROR (MainThread) [hass_nabucasa.remote] Connection problem to snitun server
2021-09-10 19:59:31 WARNING (MainThread) [homeassistant.components.sensor] Entity sensor.cpu_temp (<class 'homeassistant.components.command_line.sensor.CommandSensor'>) with device_class None reports a temperature in °C which will be converted to °F. Temperature conversion for entities without correct device_class is deprecated and will be removed from Home Assistant Core 2022.3. Please update your configuration if device_class is manually configured, otherwise create a bug report at https://github.com/home-assistant/core/issues?q=is%3Aopen+is%3Aissue+label%3A%22integration%3A+command_line%22
2021-09-10 19:59:31 WARNING (MainThread) [homeassistant.components.sensor] Entity sensor.iotawatt_total_sce_kwh_cost (<class 'homeassistant.components.energy.sensor.EnergyCostSensor'>) with state_class measurement has set last_reset. Setting last_reset is deprecated and will be unsupported from Home Assistant Core 2021.11. Please update your configuration if state_class is manually configured, otherwise create a bug report at https://github.com/home-assistant/core/issues?q=is%3Aopen+is%3Aissue+label%3A%22integration%3A+energy%22
2021-09-10 19:59:31 WARNING (MainThread) [homeassistant.components.sensor] Entity sensor.iotawatt_gridexport_compensation (<class 'homeassistant.components.energy.sensor.EnergyCostSensor'>) with state_class measurement has set last_reset. Setting last_reset is deprecated and will be unsupported from Home Assistant Core 2021.11. Please update your configuration if state_class is manually configured, otherwise create a bug report at https://github.com/home-assistant/core/issues?q=is%3Aopen+is%3Aissue+label%3A%22integration%3A+energy%22
2021-09-10 19:59:33 WARNING (MainThread) [homeassistant.config_entries] Config entry 'Roku Smart Soundbar' for roku integration not ready yet: Invalid response from API: Error occurred while communicating with device; Retrying in background
2021-09-10 19:59:36 WARNING (MainThread) [homeassistant.components.sensor] Entity sensor.attictemp1_bme280_dewpoint (<class 'homeassistant.components.tasmota.sensor.TasmotaSensor'>) with device_class None reports a temperature in °C which will be converted to °F. Temperature conversion for entities without correct device_class is deprecated and will be removed from Home Assistant Core 2022.3. Please update your configuration if device_class is manually configured, otherwise create a bug report at https://github.com/home-assistant/core/issues?q=is%3Aopen+is%3Aissue+label%3A%22integration%3A+tasmota%22
2021-09-10 19:59:36 WARNING (MainThread) [homeassistant.components.sensor] Entity sensor.garagesidedoorsensor_bme280_dewpoint (<class 'homeassistant.components.tasmota.sensor.TasmotaSensor'>) with device_class None reports a temperature in °C which will be converted to °F. Temperature conversion for entities without correct device_class is deprecated and will be removed from Home Assistant Core 2022.3. Please update your configuration if device_class is manually configured, otherwise create a bug report at https://github.com/home-assistant/core/issues?q=is%3Aopen+is%3Aissue+label%3A%22integration%3A+tasmota%22
2021-09-10 19:59:39 WARNING (MainThread) [homeassistant.config_entries] Config entry '192.168.7.195' for wled integration not ready yet: Invalid response from API: Error occurred while communicating with WLED device at 192.168.7.195; Retrying in background
2021-09-10 20:04:28 ERROR (MainThread) [homeassistant] Error doing job: Future exception was never retrieved
Traceback (most recent call last):
  File "/usr/local/lib/python3.9/concurrent/futures/thread.py", line 52, in run
    result = self.fn(*self.args, **self.kwargs)
TypeError: update() takes 1 positional argument but 2 were given
2021-09-10 20:09:29 ERROR (MainThread) [homeassistant] Error doing job: Future exception was never retrieved
Traceback (most recent call last):
  File "/usr/local/lib/python3.9/concurrent/futures/thread.py", line 52, in run
    result = self.fn(*self.args, **self.kwargs)
TypeError: update() takes 1 positional argument but 2 were given
2021-09-10 20:11:25 WARNING (MainThread) [haffmpeg.tools] Timeout reading image.
2021-09-10 20:14:30 ERROR (MainThread) [homeassistant] Error doing job: Future exception was never retrieved
Traceback (most recent call last):
  File "/usr/local/lib/python3.9/concurrent/futures/thread.py", line 52, in run
    result = self.fn(*self.args, **self.kwargs)
TypeError: update() takes 1 positional argument but 2 were given
2021-09-10 20:17:49 ERROR (stream_worker) [libav.rtsp] method DESCRIBE failed: 404 Not Found
2021-09-10 20:17:49 ERROR (stream_worker) [homeassistant.components.stream.worker] Error opening stream rtsps://stream-uc2-bravo.dropcam.com:443/sdm_live_stream/CiQA2vuxrz2sgA8iUhOEUMVn4NQgm_HYKff_nrs-qDJnCB_sv6wScQAFjsOTIkRzKZ_vho6bYL13N3HzZ-jDdcKomoh6mO_z_hty8c0rvqFmrH4mwLmhLf8GfYBHbDSkZUQpw_TeljlcYITQ9fxiHLLt_eu4aRDsDNrLYWIQDkbVT9St8D7k55HVh4B8VaTrdTYun28tu1_3?auth=g.0.eyJraWQiOiIyMzhiNTUxZmMyM2EyM2Y4M2E2ZTE3MmJjZTg0YmU3ZjgxMzAzMmM4IiwiYWxnIjoiUlMyNTYifQ.eyJpc3MiOiJuZXN0LXNlY3VyaXR5LWF1dGhwcm94eSIsInN1YiI6Im5lc3RfaWQ6bmVzdC1waG9lbml4LXByb2Q6MjEyMTgxNDEiLCJwb2wiOiIzcC1vYXV0aC1zY29wZS1BUElfU0RNX1NFUlZJQ0UtY2xpZW50LTIwMjQyNzMxODczNS1qNXQ5bWMyMzZqaG85YXMycWY0dTZxY3NmYW1kaGJ0ci5hcHBzLmdvb2dsZXVzZXJjb250ZW50LmNvbSIsImV4cCI6MTYzMTMzMDU1OH0.DHFOxMWHiTTP8AwHroyp_ykY1i5HBGcTEvORetsgPU-BCANpxFQ_2w2zbkvMzJrg5FsHphM9qzh1FtPcNh-XwzMv282uQKW1p9EnbdVoLciErz9W0-nPmJw3BDD9JUiVjVQH_udbtU_mzVFQDknOKF0mCo4H5EmgacPS-l1-dJbxMeNDNYFUI5czUnKEut6ayTWW5JOOtJLjSh8XVKvkAyEasd9-8Yvl5HYOlFLVEL2o76VGs3mK1l_SgIvWtUeKDv6x9ul7pqhpxJeFeSbhg9A5VkRbrwNsCPz8W2EUKJ_BJ3R-8-CjqJpgTQfttMdhq9z6_Lk_4fbh5nE1NNkkTA
2021-09-10 20:19:31 ERROR (MainThread) [homeassistant] Error doing job: Future exception was never retrieved
Traceback (most recent call last):
  File "/usr/local/lib/python3.9/concurrent/futures/thread.py", line 52, in run
    result = self.fn(*self.args, **self.kwargs)
TypeError: update() takes 1 positional argument but 2 were given
2021-09-10 20:24:32 ERROR (MainThread) [homeassistant] Error doing job: Future exception was never retrieved
Traceback (most recent call last):
  File "/usr/local/lib/python3.9/concurrent/futures/thread.py", line 52, in run
    result = self.fn(*self.args, **self.kwargs)
TypeError: update() takes 1 positional argument but 2 were given
2021-09-10 20:26:58 WARNING (stream_worker) [homeassistant.components.stream.worker] Audio stream not found
2021-09-10 20:29:33 ERROR (MainThread) [homeassistant] Error doing job: Future exception was never retrieved
Traceback (most recent call last):
  File "/usr/local/lib/python3.9/concurrent/futures/thread.py", line 52, in run
    result = self.fn(*self.args, **self.kwargs)
TypeError: update() takes 1 positional argument but 2 were given
2021-09-10 20:34:34 ERROR (MainThread) [homeassistant] Error doing job: Future exception was never retrieved
Traceback (most recent call last):
  File "/usr/local/lib/python3.9/concurrent/futures/thread.py", line 52, in run
    result = self.fn(*self.args, **self.kwargs)
TypeError: update() takes 1 positional argument but 2 were given
2021-09-10 20:39:35 ERROR (MainThread) [homeassistant] Error doing job: Future exception was never retrieved
Traceback (most recent call last):
  File "/usr/local/lib/python3.9/concurrent/futures/thread.py", line 52, in run
    result = self.fn(*self.args, **self.kwargs)
TypeError: update() takes 1 positional argument but 2 were given
2021-09-10 20:44:36 ERROR (MainThread) [homeassistant] Error doing job: Future exception was never retrieved
Traceback (most recent call last):
  File "/usr/local/lib/python3.9/concurrent/futures/thread.py", line 52, in run
    result = self.fn(*self.args, **self.kwargs)
TypeError: update() takes 1 positional argument but 2 were given
2021-09-10 20:49:23 ERROR (stream_worker) [libav.rtsp] method DESCRIBE failed: 404 Not Found
2021-09-10 20:49:23 ERROR (stream_worker) [homeassistant.components.stream.worker] Error opening stream rtsps://stream-uc2-delta.dropcam.com:443/sdm_live_stream/CiQA2vuxr6WY2VVedou9hCPV4sChWuwav6uqKwarBLcDdUJw5ygScQAFjsOTdMTBcJ5ngrsiGYZQdfooLrM0HYjFspm2C-SwCNwhlLKpupV7KeB2M56AYcCfF8V3QMDOBWB4TEIZZUDwgXZDMA09EkbrBwdJG51LWeBgadzWgeg3bwqaBlq7BMCRC9TIIAd9ukTyjXKTocHX?auth=g.0.eyJraWQiOiIyMzhiNTUxZmMyM2EyM2Y4M2E2ZTE3MmJjZTg0YmU3ZjgxMzAzMmM4IiwiYWxnIjoiUlMyNTYifQ.eyJpc3MiOiJuZXN0LXNlY3VyaXR5LWF1dGhwcm94eSIsInN1YiI6Im5lc3RfaWQ6bmVzdC1waG9lbml4LXByb2Q6MjEyMTgxNDEiLCJwb2wiOiIzcC1vYXV0aC1zY29wZS1BUElfU0RNX1NFUlZJQ0UtY2xpZW50LTIwMjQyNzMxODczNS1qNXQ5bWMyMzZqaG85YXMycWY0dTZxY3NmYW1kaGJ0ci5hcHBzLmdvb2dsZXVzZXJjb250ZW50LmNvbSIsImV4cCI6MTYzMTMzMjQ1Mn0.Nn4lIA09uLSWX_vpFP0vAZkFv-a_U2U_HRMOGopuYkaqnhzSN2GC0CeSnpDR7PVVax09itjImi9EYBxGqgExUUTTcTKPSd4Qba8iZLpcLpaQlGqkJ2X-mX-nLZ7O8SCSnAbNmbBWpukb_Z857ZxYxIhdIDQyzd9UMGN7LP0npQ0jM86yF1CFwgu5hWs2Kt2nAX-U41EBaVkOBAlOxxhTAPDhlt-GepPy0PxCQ4a2sxf8-APatm3T_ghLH3t0tBDzPR-3gzzVz6Nf5XAxzqQi2itm4-5K-AwpaULTLOPH4x7_CSf8zMiiCdPyXFfnvUZsHug99vaoGxR9eB_vT-eO4g
2021-09-10 20:49:37 ERROR (MainThread) [homeassistant] Error doing job: Future exception was never retrieved
Traceback (most recent call last):
  File "/usr/local/lib/python3.9/concurrent/futures/thread.py", line 52, in run
    result = self.fn(*self.args, **self.kwargs)
TypeError: update() takes 1 positional argument but 2 were given
2021-09-10 20:49:46 ERROR (stream_worker) [libav.rtsp] method DESCRIBE failed: 404 Not Found
2021-09-10 20:49:46 ERROR (stream_worker) [homeassistant.components.stream.worker] Error opening stream rtsps://stream-uc2-delta.dropcam.com:443/sdm_live_stream/CiQA2vuxr6WY2VVedou9hCPV4sChWuwav6uqKwarBLcDdUJw5ygScQAFjsOTdMTBcJ5ngrsiGYZQdfooLrM0HYjFspm2C-SwCNwhlLKpupV7KeB2M56AYcCfF8V3QMDOBWB4TEIZZUDwgXZDMA09EkbrBwdJG51LWeBgadzWgeg3bwqaBlq7BMCRC9TIIAd9ukTyjXKTocHX?auth=g.0.eyJraWQiOiIyMzhiNTUxZmMyM2EyM2Y4M2E2ZTE3MmJjZTg0YmU3ZjgxMzAzMmM4IiwiYWxnIjoiUlMyNTYifQ.eyJpc3MiOiJuZXN0LXNlY3VyaXR5LWF1dGhwcm94eSIsInN1YiI6Im5lc3RfaWQ6bmVzdC1waG9lbml4LXByb2Q6MjEyMTgxNDEiLCJwb2wiOiIzcC1vYXV0aC1zY29wZS1BUElfU0RNX1NFUlZJQ0UtY2xpZW50LTIwMjQyNzMxODczNS1qNXQ5bWMyMzZqaG85YXMycWY0dTZxY3NmYW1kaGJ0ci5hcHBzLmdvb2dsZXVzZXJjb250ZW50LmNvbSIsImV4cCI6MTYzMTMzMjQ1Mn0.Nn4lIA09uLSWX_vpFP0vAZkFv-a_U2U_HRMOGopuYkaqnhzSN2GC0CeSnpDR7PVVax09itjImi9EYBxGqgExUUTTcTKPSd4Qba8iZLpcLpaQlGqkJ2X-mX-nLZ7O8SCSnAbNmbBWpukb_Z857ZxYxIhdIDQyzd9UMGN7LP0npQ0jM86yF1CFwgu5hWs2Kt2nAX-U41EBaVkOBAlOxxhTAPDhlt-GepPy0PxCQ4a2sxf8-APatm3T_ghLH3t0tBDzPR-3gzzVz6Nf5XAxzqQi2itm4-5K-AwpaULTLOPH4x7_CSf8zMiiCdPyXFfnvUZsHug99vaoGxR9eB_vT-eO4g
2021-09-10 20:50:19 ERROR (stream_worker) [libav.rtsp] method DESCRIBE failed: 404 Not Found
2021-09-10 20:50:19 ERROR (stream_worker) [homeassistant.components.stream.worker] Error opening stream rtsps://stream-uc2-delta.dropcam.com:443/sdm_live_stream/CiQA2vuxr6WY2VVedou9hCPV4sChWuwav6uqKwarBLcDdUJw5ygScQAFjsOTdMTBcJ5ngrsiGYZQdfooLrM0HYjFspm2C-SwCNwhlLKpupV7KeB2M56AYcCfF8V3QMDOBWB4TEIZZUDwgXZDMA09EkbrBwdJG51LWeBgadzWgeg3bwqaBlq7BMCRC9TIIAd9ukTyjXKTocHX?auth=g.0.eyJraWQiOiIyMzhiNTUxZmMyM2EyM2Y4M2E2ZTE3MmJjZTg0YmU3ZjgxMzAzMmM4IiwiYWxnIjoiUlMyNTYifQ.eyJpc3MiOiJuZXN0LXNlY3VyaXR5LWF1dGhwcm94eSIsInN1YiI6Im5lc3RfaWQ6bmVzdC1waG9lbml4LXByb2Q6MjEyMTgxNDEiLCJwb2wiOiIzcC1vYXV0aC1zY29wZS1BUElfU0RNX1NFUlZJQ0UtY2xpZW50LTIwMjQyNzMxODczNS1qNXQ5bWMyMzZqaG85YXMycWY0dTZxY3NmYW1kaGJ0ci5hcHBzLmdvb2dsZXVzZXJjb250ZW50LmNvbSIsImV4cCI6MTYzMTMzMjQ1Mn0.Nn4lIA09uLSWX_vpFP0vAZkFv-a_U2U_HRMOGopuYkaqnhzSN2GC0CeSnpDR7PVVax09itjImi9EYBxGqgExUUTTcTKPSd4Qba8iZLpcLpaQlGqkJ2X-mX-nLZ7O8SCSnAbNmbBWpukb_Z857ZxYxIhdIDQyzd9UMGN7LP0npQ0jM86yF1CFwgu5hWs2Kt2nAX-U41EBaVkOBAlOxxhTAPDhlt-GepPy0PxCQ4a2sxf8-APatm3T_ghLH3t0tBDzPR-3gzzVz6Nf5XAxzqQi2itm4-5K-AwpaULTLOPH4x7_CSf8zMiiCdPyXFfnvUZsHug99vaoGxR9eB_vT-eO4g
2021-09-10 20:51:01 ERROR (stream_worker) [libav.rtsp] method DESCRIBE failed: 404 Not Found
2021-09-10 20:51:01 ERROR (stream_worker) [homeassistant.components.stream.worker] Error opening stream rtsps://stream-uc2-delta.dropcam.com:443/sdm_live_stream/CiQA2vuxr6WY2VVedou9hCPV4sChWuwav6uqKwarBLcDdUJw5ygScQAFjsOTdMTBcJ5ngrsiGYZQdfooLrM0HYjFspm2C-SwCNwhlLKpupV7KeB2M56AYcCfF8V3QMDOBWB4TEIZZUDwgXZDMA09EkbrBwdJG51LWeBgadzWgeg3bwqaBlq7BMCRC9TIIAd9ukTyjXKTocHX?auth=g.0.eyJraWQiOiIyMzhiNTUxZmMyM2EyM2Y4M2E2ZTE3MmJjZTg0YmU3ZjgxMzAzMmM4IiwiYWxnIjoiUlMyNTYifQ.eyJpc3MiOiJuZXN0LXNlY3VyaXR5LWF1dGhwcm94eSIsInN1YiI6Im5lc3RfaWQ6bmVzdC1waG9lbml4LXByb2Q6MjEyMTgxNDEiLCJwb2wiOiIzcC1vYXV0aC1zY29wZS1BUElfU0RNX1NFUlZJQ0UtY2xpZW50LTIwMjQyNzMxODczNS1qNXQ5bWMyMzZqaG85YXMycWY0dTZxY3NmYW1kaGJ0ci5hcHBzLmdvb2dsZXVzZXJjb250ZW50LmNvbSIsImV4cCI6MTYzMTMzMjQ1Mn0.Nn4lIA09uLSWX_vpFP0vAZkFv-a_U2U_HRMOGopuYkaqnhzSN2GC0CeSnpDR7PVVax09itjImi9EYBxGqgExUUTTcTKPSd4Qba8iZLpcLpaQlGqkJ2X-mX-nLZ7O8SCSnAbNmbBWpukb_Z857ZxYxIhdIDQyzd9UMGN7LP0npQ0jM86yF1CFwgu5hWs2Kt2nAX-U41EBaVkOBAlOxxhTAPDhlt-GepPy0PxCQ4a2sxf8-APatm3T_ghLH3t0tBDzPR-3gzzVz6Nf5XAxzqQi2itm4-5K-AwpaULTLOPH4x7_CSf8zMiiCdPyXFfnvUZsHug99vaoGxR9eB_vT-eO4g
2021-09-10 20:54:38 ERROR (MainThread) [homeassistant] Error doing job: Future exception was never retrieved
Traceback (most recent call last):
  File "/usr/local/lib/python3.9/concurrent/futures/thread.py", line 52, in run
    result = self.fn(*self.args, **self.kwargs)
TypeError: update() takes 1 positional argument but 2 were given
2021-09-10 20:59:39 ERROR (MainThread) [homeassistant] Error doing job: Future exception was never retrieved
Traceback (most recent call last):
  File "/usr/local/lib/python3.9/concurrent/futures/thread.py", line 52, in run
    result = self.fn(*self.args, **self.kwargs)
TypeError: update() takes 1 positional argument but 2 were given
2021-09-10 21:04:40 ERROR (MainThread) [homeassistant] Error doing job: Future exception was never retrieved
Traceback (most recent call last):
  File "/usr/local/lib/python3.9/concurrent/futures/thread.py", line 52, in run
    result = self.fn(*self.args, **self.kwargs)
TypeError: update() takes 1 positional argument but 2 were given
2021-09-10 21:09:41 ERROR (MainThread) [homeassistant] Error doing job: Future exception was never retrieved
Traceback (most recent call last):
  File "/usr/local/lib/python3.9/concurrent/futures/thread.py", line 52, in run
    result = self.fn(*self.args, **self.kwargs)
TypeError: update() takes 1 positional argument but 2 were given
2021-09-10 21:09:43 ERROR (MainThread) [homeassistant.components.nws] Error requesting NWS observation station SAUC1 data: 503, message='Service Unavailable', url=URL('https://api.weather.gov/stations/SAUC1/observations')
2021-09-10 21:14:42 ERROR (MainThread) [homeassistant] Error doing job: Future exception was never retrieved
Traceback (most recent call last):
  File "/usr/local/lib/python3.9/concurrent/futures/thread.py", line 52, in run
    result = self.fn(*self.args, **self.kwargs)
TypeError: update() takes 1 positional argument but 2 were given
2021-09-10 21:16:36 ERROR (stream_worker) [libav.rtsp] method DESCRIBE failed: 404 Not Found
2021-09-10 21:16:36 ERROR (stream_worker) [homeassistant.components.stream.worker] Error opening stream rtsps://stream-uc2-bravo.dropcam.com:443/sdm_live_stream/CiQA2vuxrz2sgA8iUhOEUMVn4NQgm_HYKff_nrs-qDJnCB_sv6wScQAFjsOTIkRzKZ_vho6bYL13N3HzZ-jDdcKomoh6mO_z_hty8c0rvqFmrH4mwLmhLf8GfYBHbDSkZUQpw_TeljlcYITQ9fxiHLLt_eu4aRDsDNrLYWIQDkbVT9St8D7k55HVh4B8VaTrdTYun28tu1_3?auth=g.0.eyJraWQiOiIyMzhiNTUxZmMyM2EyM2Y4M2E2ZTE3MmJjZTg0YmU3ZjgxMzAzMmM4IiwiYWxnIjoiUlMyNTYifQ.eyJpc3MiOiJuZXN0LXNlY3VyaXR5LWF1dGhwcm94eSIsInN1YiI6Im5lc3RfaWQ6bmVzdC1waG9lbml4LXByb2Q6MjEyMTgxNDEiLCJwb2wiOiIzcC1vYXV0aC1zY29wZS1BUElfU0RNX1NFUlZJQ0UtY2xpZW50LTIwMjQyNzMxODczNS1qNXQ5bWMyMzZqaG85YXMycWY0dTZxY3NmYW1kaGJ0ci5hcHBzLmdvb2dsZXVzZXJjb250ZW50LmNvbSIsImV4cCI6MTYzMTMzNDA3NX0.Y2exBw8U8kq6N70cYhf5Uy5qz84M4VYWeer46f4KTUCEfH_lS2vzOU9ciXuHtJ4KnLwyAS86GJvsQ2W8FX5XyI_XgRIyvQEeiDLzV2nJLS1_FLugl2f8TiV3qc0_PfwKkfDwp5yjFMHNz06kJ9eLx1ONkYYJMfK3Lm_KccdknEKHv-VVN5XPOZAwIp6Q3mCLhkfS_YlyLrX-UA3y--jCo37IYn68CMvjsnoGxq8ZHYWe-HhbuBWD07pnDe4pYKXKHi_gFBjtXG6A04seHP4gtS9msGvhWIgCWA5Xx3MUiu1z5HeQ0X8bdY_I5gHJgLnG8HdwdLBMmZmJJni7tZznMQ
2021-09-10 21:19:43 ERROR (SyncWorker_2) [homeassistant] Error doing job: Future exception was never retrieved
Traceback (most recent call last):
  File "/usr/local/lib/python3.9/concurrent/futures/thread.py", line 52, in run
    result = self.fn(*self.args, **self.kwargs)
TypeError: update() takes 1 positional argument but 2 were given
2021-09-10 21:20:54 ERROR (MainThread) [homeassistant.components.nws] Error requesting NWS observation station SAUC1 data: 503, message='Service Unavailable', url=URL('https://api.weather.gov/stations/SAUC1/observations')
2021-09-10 21:24:44 ERROR (MainThread) [homeassistant] Error doing job: Future exception was never retrieved
Traceback (most recent call last):
  File "/usr/local/lib/python3.9/concurrent/futures/thread.py", line 52, in run
    result = self.fn(*self.args, **self.kwargs)
TypeError: update() takes 1 positional argument but 2 were given
2021-09-10 21:25:55 ERROR (stream_worker) [libav.rtsp] method DESCRIBE failed: 404 Not Found
2021-09-10 21:25:55 ERROR (stream_worker) [homeassistant.components.stream.worker] Error opening stream rtsps://stream-uc2-bravo.dropcam.com:443/sdm_live_stream/CiQA2vuxrz2sgA8iUhOEUMVn4NQgm_HYKff_nrs-qDJnCB_sv6wScQAFjsOTIkRzKZ_vho6bYL13N3HzZ-jDdcKomoh6mO_z_hty8c0rvqFmrH4mwLmhLf8GfYBHbDSkZUQpw_TeljlcYITQ9fxiHLLt_eu4aRDsDNrLYWIQDkbVT9St8D7k55HVh4B8VaTrdTYun28tu1_3?auth=g.0.eyJraWQiOiIyMzhiNTUxZmMyM2EyM2Y4M2E2ZTE3MmJjZTg0YmU3ZjgxMzAzMmM4IiwiYWxnIjoiUlMyNTYifQ.eyJpc3MiOiJuZXN0LXNlY3VyaXR5LWF1dGhwcm94eSIsInN1YiI6Im5lc3RfaWQ6bmVzdC1waG9lbml4LXByb2Q6MjEyMTgxNDEiLCJwb2wiOiIzcC1vYXV0aC1zY29wZS1BUElfU0RNX1NFUlZJQ0UtY2xpZW50LTIwMjQyNzMxODczNS1qNXQ5bWMyMzZqaG85YXMycWY0dTZxY3NmYW1kaGJ0ci5hcHBzLmdvb2dsZXVzZXJjb250ZW50LmNvbSIsImV4cCI6MTYzMTMzNDYxNn0.Ha-aC7e8Ri7inzWXYnLDZWmSKnBYYfsVwfg2l-xnmpOPpmoiOSNrdEb603cRmAiNud7c_UTDwuT2C1ds6b4BTDY5fBrRf14tZsvzxp61t_cCKeYpTtNadn3BAyPubr69aYLqeHwsgu6HkLFvPoGJrRQ01c6mdebzJom_Y0_mnMdTbpYt_B5PPuN3teUJa1annmyfPC89OpCtAsJ_Z13pJjFARruq-dVR6cBwZmyrxoUQkBNxLwfrg-uqLNQYSf3c7Q9DZhamk27XHiEVBaD19dxs850jYpMYAmuBDzV6tPfv-CXiyhKzpyD87Yu1dotHcWcx50PeKaS3gruO5ex4Lw
2021-09-10 21:29:45 ERROR (MainThread) [homeassistant] Error doing job: Future exception was never retrieved
Traceback (most recent call last):
  File "/usr/local/lib/python3.9/concurrent/futures/thread.py", line 52, in run
    result = self.fn(*self.args, **self.kwargs)
TypeError: update() takes 1 positional argument but 2 were given
2021-09-10 21:32:04 ERROR (MainThread) [homeassistant.components.nws] Error requesting NWS observation station SAUC1 data: 503, message='Service Unavailable', url=URL('https://api.weather.gov/stations/SAUC1/observations')
2021-09-10 21:34:46 ERROR (MainThread) [homeassistant] Error doing job: Future exception was never retrieved
Traceback (most recent call last):
  File "/usr/local/lib/python3.9/concurrent/futures/thread.py", line 52, in run
    result = self.fn(*self.args, **self.kwargs)
TypeError: update() takes 1 positional argument but 2 were given
2021-09-10 21:39:47 ERROR (MainThread) [homeassistant] Error doing job: Future exception was never retrieved
Traceback (most recent call last):
  File "/usr/local/lib/python3.9/concurrent/futures/thread.py", line 52, in run
    result = self.fn(*self.args, **self.kwargs)
TypeError: update() takes 1 positional argument but 2 were given
2021-09-10 21:44:48 ERROR (MainThread) [homeassistant] Error doing job: Future exception was never retrieved
Traceback (most recent call last):
  File "/usr/local/lib/python3.9/concurrent/futures/thread.py", line 52, in run
    result = self.fn(*self.args, **self.kwargs)
TypeError: update() takes 1 positional argument but 2 were given
2021-09-10 21:49:49 ERROR (MainThread) [homeassistant] Error doing job: Future exception was never retrieved
Traceback (most recent call last):
  File "/usr/local/lib/python3.9/concurrent/futures/thread.py", line 52, in run
    result = self.fn(*self.args, **self.kwargs)
TypeError: update() takes 1 positional argument but 2 were given
2021-09-10 21:54:50 ERROR (MainThread) [homeassistant] Error doing job: Future exception was never retrieved
Traceback (most recent call last):
  File "/usr/local/lib/python3.9/concurrent/futures/thread.py", line 52, in run
    result = self.fn(*self.args, **self.kwargs)
TypeError: update() takes 1 positional argument but 2 were given
2021-09-10 21:59:51 ERROR (MainThread) [homeassistant] Error doing job: Future exception was never retrieved
Traceback (most recent call last):
  File "/usr/local/lib/python3.9/concurrent/futures/thread.py", line 52, in run
    result = self.fn(*self.args, **self.kwargs)
TypeError: update() takes 1 positional argument but 2 were given
2021-09-10 22:03:15 ERROR (MainThread) [homeassistant.components.nws] Error requesting NWS observation station SAUC1 data: 503, message='Service Unavailable', url=URL('https://api.weather.gov/stations/SAUC1/observations')
2021-09-10 22:04:52 ERROR (MainThread) [homeassistant] Error doing job: Future exception was never retrieved
Traceback (most recent call last):
  File "/usr/local/lib/python3.9/concurrent/futures/thread.py", line 52, in run
    result = self.fn(*self.args, **self.kwargs)
TypeError: update() takes 1 positional argument but 2 were given
2021-09-10 22:09:53 ERROR (MainThread) [homeassistant] Error doing job: Future exception was never retrieved
Traceback (most recent call last):
  File "/usr/local/lib/python3.9/concurrent/futures/thread.py", line 52, in run
    result = self.fn(*self.args, **self.kwargs)
TypeError: update() takes 1 positional argument but 2 were given
2021-09-10 22:14:54 ERROR (MainThread) [homeassistant] Error doing job: Future exception was never retrieved
Traceback (most recent call last):
  File "/usr/local/lib/python3.9/concurrent/futures/thread.py", line 52, in run
    result = self.fn(*self.args, **self.kwargs)
TypeError: update() takes 1 positional argument but 2 were given
2021-09-10 22:19:55 ERROR (MainThread) [homeassistant] Error doing job: Future exception was never retrieved
Traceback (most recent call last):
  File "/usr/local/lib/python3.9/concurrent/futures/thread.py", line 52, in run
    result = self.fn(*self.args, **self.kwargs)
TypeError: update() takes 1 positional argument but 2 were given
2021-09-10 22:22:30 ERROR (MainThread) [iotawattpy.connection] Err: 
2021-09-10 22:22:30 ERROR (MainThread) [homeassistant.components.iotawatt.coordinator] Unexpected error fetching 192.168.20.195 data: 'NoneType' object has no attribute 'text'
Traceback (most recent call last):
  File "/usr/src/homeassistant/homeassistant/helpers/update_coordinator.py", line 187, in _async_refresh
    self.data = await self._async_update_data()
  File "/usr/src/homeassistant/homeassistant/components/iotawatt/coordinator.py", line 55, in _async_update_data
    await self.api.update()
  File "/usr/local/lib/python3.9/site-packages/iotawattpy/iotawatt.py", line 66, in update
    await self._refreshSensors(timespan)
  File "/usr/local/lib/python3.9/site-packages/iotawattpy/iotawatt.py", line 100, in _refreshSensors
    results = response.text
AttributeError: 'NoneType' object has no attribute 'text'
2021-09-10 22:24:46 ERROR (stream_worker) [libav.rtsp] method DESCRIBE failed: 404 Not Found
2021-09-10 22:24:46 ERROR (stream_worker) [homeassistant.components.stream.worker] Error opening stream rtsps://stream-uc2-delta.dropcam.com:443/sdm_live_stream/CiQA2vuxr6WY2VVedou9hCPV4sChWuwav6uqKwarBLcDdUJw5ygScQAFjsOTdMTBcJ5ngrsiGYZQdfooLrM0HYjFspm2C-SwCNwhlLKpupV7KeB2M56AYcCfF8V3QMDOBWB4TEIZZUDwgXZDMA09EkbrBwdJG51LWeBgadzWgeg3bwqaBlq7BMCRC9TIIAd9ukTyjXKTocHX?auth=g.0.eyJraWQiOiIyMzhiNTUxZmMyM2EyM2Y4M2E2ZTE3MmJjZTg0YmU3ZjgxMzAzMmM4IiwiYWxnIjoiUlMyNTYifQ.eyJpc3MiOiJuZXN0LXNlY3VyaXR5LWF1dGhwcm94eSIsInN1YiI6Im5lc3RfaWQ6bmVzdC1waG9lbml4LXByb2Q6MjEyMTgxNDEiLCJwb2wiOiIzcC1vYXV0aC1zY29wZS1BUElfU0RNX1NFUlZJQ0UtY2xpZW50LTIwMjQyNzMxODczNS1qNXQ5bWMyMzZqaG85YXMycWY0dTZxY3NmYW1kaGJ0ci5hcHBzLmdvb2dsZXVzZXJjb250ZW50LmNvbSIsImV4cCI6MTYzMTMzODEzNH0.DrNHWRFXqdh73Z-AEDPWno87WDD-S65qUwGP8jJtz1WJXFjVtCMU1gT4d1rhIt71-G5cyOHns8667wiAUDQCllYrkyR-JMY8_AcMGOWRga9lRhYbnEEGYOUl3cvzZlyUJzMwjWB7Nzfpn7MEw5p9Z0Hmp9g_S9T7_IiRwibjLvsvt9eLnUDu1Cvq7h0oH8_dybLGmd4R1cUz7evXgXDuAhpUIzgOFPdbrzYjV6BoAeuQ9GfUQjFo674ViQ2RxDdGk6qhmiRJTRSiy3W29HmUXMoZdtMnaXNbt__yXV19-vqt8M1larHgAL4RDNZ3ne5ks-_Bg5Aaa6zyB9cj9suspg
2021-09-10 22:24:56 ERROR (MainThread) [homeassistant] Error doing job: Future exception was never retrieved
Traceback (most recent call last):
  File "/usr/local/lib/python3.9/concurrent/futures/thread.py", line 52, in run
    result = self.fn(*self.args, **self.kwargs)
TypeError: update() takes 1 positional argument but 2 were given
2021-09-10 22:29:57 ERROR (MainThread) [homeassistant] Error doing job: Future exception was never retrieved
Traceback (most recent call last):
  File "/usr/local/lib/python3.9/concurrent/futures/thread.py", line 52, in run
    result = self.fn(*self.args, **self.kwargs)
TypeError: update() takes 1 positional argument but 2 were given
2021-09-10 22:34:58 ERROR (MainThread) [homeassistant] Error doing job: Future exception was never retrieved
Traceback (most recent call last):
  File "/usr/local/lib/python3.9/concurrent/futures/thread.py", line 52, in run
    result = self.fn(*self.args, **self.kwargs)
TypeError: update() takes 1 positional argument but 2 were given
2021-09-10 22:39:59 ERROR (MainThread) [homeassistant] Error doing job: Future exception was never retrieved
Traceback (most recent call last):
  File "/usr/local/lib/python3.9/concurrent/futures/thread.py", line 52, in run
    result = self.fn(*self.args, **self.kwargs)
TypeError: update() takes 1 positional argument but 2 were given
2021-09-10 22:42:36 ERROR (stream_worker) [libav.rtsp] method DESCRIBE failed: 404 Not Found
2021-09-10 22:42:36 ERROR (stream_worker) [homeassistant.components.stream.worker] Error opening stream rtsps://stream-uc2-bravo.dropcam.com:443/sdm_live_stream/CiQA2vuxrz2sgA8iUhOEUMVn4NQgm_HYKff_nrs-qDJnCB_sv6wScQAFjsOTIkRzKZ_vho6bYL13N3HzZ-jDdcKomoh6mO_z_hty8c0rvqFmrH4mwLmhLf8GfYBHbDSkZUQpw_TeljlcYITQ9fxiHLLt_eu4aRDsDNrLYWIQDkbVT9St8D7k55HVh4B8VaTrdTYun28tu1_3?auth=g.0.eyJraWQiOiIyMzhiNTUxZmMyM2EyM2Y4M2E2ZTE3MmJjZTg0YmU3ZjgxMzAzMmM4IiwiYWxnIjoiUlMyNTYifQ.eyJpc3MiOiJuZXN0LXNlY3VyaXR5LWF1dGhwcm94eSIsInN1YiI6Im5lc3RfaWQ6bmVzdC1waG9lbml4LXByb2Q6MjEyMTgxNDEiLCJwb2wiOiIzcC1vYXV0aC1zY29wZS1BUElfU0RNX1NFUlZJQ0UtY2xpZW50LTIwMjQyNzMxODczNS1qNXQ5bWMyMzZqaG85YXMycWY0dTZxY3NmYW1kaGJ0ci5hcHBzLmdvb2dsZXVzZXJjb250ZW50LmNvbSIsImV4cCI6MTYzMTMzOTIxNX0.MG1Jz3hmDbrQSE_h4nT45jdSIiNDryIiELMCNq8HoV1xk3yzotvt9DghSxvldyUqz_AQEYdne_9hSyYB7z_JC8w4Kv4I0wRs1RqRPH-fiORz69u5mN1D7CKXdOEcDGy5S0fQVRAWkRYmKCIh8ykdoviTk4_ehLf4uXSYbsvTUn6VKSBaF9cZhNXHRHisb-fUH8TmV3vzsqirWC46E6-ENR4rko8-U01t1K59uwV-2lwY-FtsSPX0DY1EbyRCvcbjT9d-KfK2VEOuoXyMare2V1rgS4WTgo_BlAiwkLUKScKVNzpswLTTYng3_vs-D3GVUo9YxeyNBPUZC2vV7r4oEg
2021-09-10 22:45:00 ERROR (MainThread) [homeassistant] Error doing job: Future exception was never retrieved
Traceback (most recent call last):
  File "/usr/local/lib/python3.9/concurrent/futures/thread.py", line 52, in run
    result = self.fn(*self.args, **self.kwargs)
TypeError: update() takes 1 positional argument but 2 were given
2021-09-10 22:50:01 ERROR (MainThread) [homeassistant] Error doing job: Future exception was never retrieved
Traceback (most recent call last):
  File "/usr/local/lib/python3.9/concurrent/futures/thread.py", line 52, in run
    result = self.fn(*self.args, **self.kwargs)
TypeError: update() takes 1 positional argument but 2 were given
2021-09-10 22:55:02 ERROR (MainThread) [homeassistant] Error doing job: Future exception was never retrieved
Traceback (most recent call last):
  File "/usr/local/lib/python3.9/concurrent/futures/thread.py", line 52, in run
    result = self.fn(*self.args, **self.kwargs)
TypeError: update() takes 1 positional argument but 2 were given
2021-09-10 22:56:29 ERROR (stream_worker) [libav.rtsp] method DESCRIBE failed: 404 Not Found
2021-09-10 22:56:29 ERROR (stream_worker) [homeassistant.components.stream.worker] Error opening stream rtsps://stream-uc2-delta.dropcam.com:443/sdm_live_stream/CiQA2vuxr6WY2VVedou9hCPV4sChWuwav6uqKwarBLcDdUJw5ygScQAFjsOTdMTBcJ5ngrsiGYZQdfooLrM0HYjFspm2C-SwCNwhlLKpupV7KeB2M56AYcCfF8V3QMDOBWB4TEIZZUDwgXZDMA09EkbrBwdJG51LWeBgadzWgeg3bwqaBlq7BMCRC9TIIAd9ukTyjXKTocHX?auth=g.0.eyJraWQiOiIyMzhiNTUxZmMyM2EyM2Y4M2E2ZTE3MmJjZTg0YmU3ZjgxMzAzMmM4IiwiYWxnIjoiUlMyNTYifQ.eyJpc3MiOiJuZXN0LXNlY3VyaXR5LWF1dGhwcm94eSIsInN1YiI6Im5lc3RfaWQ6bmVzdC1waG9lbml4LXByb2Q6MjEyMTgxNDEiLCJwb2wiOiIzcC1vYXV0aC1zY29wZS1BUElfU0RNX1NFUlZJQ0UtY2xpZW50LTIwMjQyNzMxODczNS1qNXQ5bWMyMzZqaG85YXMycWY0dTZxY3NmYW1kaGJ0ci5hcHBzLmdvb2dsZXVzZXJjb250ZW50LmNvbSIsImV4cCI6MTYzMTM0MDAyN30.lY1RvqCKd6oZ6_qs868Zzw-J9s_rzBTaUODTwjE9nr_StI0bnJhlm0d287DA1dlouQ6unuPo2wDbqRZgEjnSgsmi5vXwZhlrnIx99a2KJ-yQQ9YkNSltumucvrqC24TCAeV3ol-jk3Qqd-laE6Sr0fhtmdxHzSgA_8aJQFF5XQ9gTxyfzarRblkvBbIyyQ-x4cbYi376A8nDKsjKY93HOLdKnzw_QgjhNrQn1yY4LWzP3JxVsN9j9PPsaUj6ZhskzQ8o4HC1BFvf4yr5z-6i0uKxDNwHIKs_ytqMBYu8U2XpedOP0HYwQQb0m0-yUXwqwUyIfQb-y6WZ4MBxqrOLtg
2021-09-10 23:00:00 WARNING (MainThread) [homeassistant.helpers.service] Unable to find referenced entities light.sophia_wled
2021-09-10 23:00:03 ERROR (MainThread) [homeassistant] Error doing job: Future exception was never retrieved
Traceback (most recent call last):
  File "/usr/local/lib/python3.9/concurrent/futures/thread.py", line 52, in run
    result = self.fn(*self.args, **self.kwargs)
TypeError: update() takes 1 positional argument but 2 were given
2021-09-10 23:05:04 ERROR (MainThread) [homeassistant] Error doing job: Future exception was never retrieved
Traceback (most recent call last):
  File "/usr/local/lib/python3.9/concurrent/futures/thread.py", line 52, in run
    result = self.fn(*self.args, **self.kwargs)
TypeError: update() takes 1 positional argument but 2 were given
2021-09-10 23:10:05 ERROR (MainThread) [homeassistant] Error doing job: Future exception was never retrieved
Traceback (most recent call last):
  File "/usr/local/lib/python3.9/concurrent/futures/thread.py", line 52, in run
    result = self.fn(*self.args, **self.kwargs)
TypeError: update() takes 1 positional argument but 2 were given
2021-09-10 23:13:59 ERROR (MainThread) [iotawattpy.connection] Err: 
2021-09-10 23:13:59 ERROR (MainThread) [homeassistant.components.iotawatt.coordinator] Unexpected error fetching 192.168.20.195 data: 'NoneType' object has no attribute 'text'
Traceback (most recent call last):
  File "/usr/src/homeassistant/homeassistant/helpers/update_coordinator.py", line 187, in _async_refresh
    self.data = await self._async_update_data()
  File "/usr/src/homeassistant/homeassistant/components/iotawatt/coordinator.py", line 55, in _async_update_data
    await self.api.update()
  File "/usr/local/lib/python3.9/site-packages/iotawattpy/iotawatt.py", line 66, in update
    await self._refreshSensors(timespan)
  File "/usr/local/lib/python3.9/site-packages/iotawattpy/iotawatt.py", line 100, in _refreshSensors
    results = response.text
AttributeError: 'NoneType' object has no attribute 'text'
2021-09-10 23:14:26 ERROR (stream_worker) [libav.rtsp] method DESCRIBE failed: 404 Not Found
2021-09-10 23:14:26 ERROR (stream_worker) [homeassistant.components.stream.worker] Error opening stream rtsps://stream-uc2-bravo.dropcam.com:443/sdm_live_stream/CiQA2vuxrz2sgA8iUhOEUMVn4NQgm_HYKff_nrs-qDJnCB_sv6wScQAFjsOTIkRzKZ_vho6bYL13N3HzZ-jDdcKomoh6mO_z_hty8c0rvqFmrH4mwLmhLf8GfYBHbDSkZUQpw_TeljlcYITQ9fxiHLLt_eu4aRDsDNrLYWIQDkbVT9St8D7k55HVh4B8VaTrdTYun28tu1_3?auth=g.0.eyJraWQiOiIyMzhiNTUxZmMyM2EyM2Y4M2E2ZTE3MmJjZTg0YmU3ZjgxMzAzMmM4IiwiYWxnIjoiUlMyNTYifQ.eyJpc3MiOiJuZXN0LXNlY3VyaXR5LWF1dGhwcm94eSIsInN1YiI6Im5lc3RfaWQ6bmVzdC1waG9lbml4LXByb2Q6MjEyMTgxNDEiLCJwb2wiOiIzcC1vYXV0aC1zY29wZS1BUElfU0RNX1NFUlZJQ0UtY2xpZW50LTIwMjQyNzMxODczNS1qNXQ5bWMyMzZqaG85YXMycWY0dTZxY3NmYW1kaGJ0ci5hcHBzLmdvb2dsZXVzZXJjb250ZW50LmNvbSIsImV4cCI6MTYzMTM0MTEwOH0.sH0XCuEQNM_LoNCEu539s0Bvffk-b3vrkn8QlN3DDjKjvd6KSdvz0c8DTIROZbTayAtZNM-5L2XC3fDqvaos7Ulnm22pbIGw_9hEXxAWoci0dYYLcMffXaft0SyQqXKwbyaOPywmrS7G3J8WX7HINs7sKKL-2eTuZ4MS5wylPp5ycNSArgxXYjt24vZ9THZvEehRGia6aSCROFR7iWDzrIVL6VMdFiwTn53HGoQvstiAQpqhf0UDS-6wh7MGEDutUNUgZDvWzjOZz-hAaFdIR-Ixwo495ypR1LqjBWuTRkLLIPRImiIgCqvc_v7hopIWxU-MWJNav7Tbkoe1ZWafag
2021-09-10 23:15:06 ERROR (MainThread) [homeassistant] Error doing job: Future exception was never retrieved
Traceback (most recent call last):
  File "/usr/local/lib/python3.9/concurrent/futures/thread.py", line 52, in run
    result = self.fn(*self.args, **self.kwargs)
TypeError: update() takes 1 positional argument but 2 were given
2021-09-10 23:19:00 ERROR (stream_worker) [libav.rtsp] method DESCRIBE failed: 404 Not Found
2021-09-10 23:19:00 ERROR (stream_worker) [homeassistant.components.stream.worker] Error opening stream rtsps://stream-uc2-bravo.dropcam.com:443/sdm_live_stream/CiQA2vuxrz2sgA8iUhOEUMVn4NQgm_HYKff_nrs-qDJnCB_sv6wScQAFjsOTIkRzKZ_vho6bYL13N3HzZ-jDdcKomoh6mO_z_hty8c0rvqFmrH4mwLmhLf8GfYBHbDSkZUQpw_TeljlcYITQ9fxiHLLt_eu4aRDsDNrLYWIQDkbVT9St8D7k55HVh4B8VaTrdTYun28tu1_3?auth=g.0.eyJraWQiOiIyMzhiNTUxZmMyM2EyM2Y4M2E2ZTE3MmJjZTg0YmU3ZjgxMzAzMmM4IiwiYWxnIjoiUlMyNTYifQ.eyJpc3MiOiJuZXN0LXNlY3VyaXR5LWF1dGhwcm94eSIsInN1YiI6Im5lc3RfaWQ6bmVzdC1waG9lbml4LXByb2Q6MjEyMTgxNDEiLCJwb2wiOiIzcC1vYXV0aC1zY29wZS1BUElfU0RNX1NFUlZJQ0UtY2xpZW50LTIwMjQyNzMxODczNS1qNXQ5bWMyMzZqaG85YXMycWY0dTZxY3NmYW1kaGJ0ci5hcHBzLmdvb2dsZXVzZXJjb250ZW50LmNvbSIsImV4cCI6MTYzMTM0MTM3OX0.rcVDjI3JCiqLl7ZNlOcUrktglJbP1V32gwPVylaPIZGROM4Y3DJu85VsZ3pEnIuW4Xax4VNHPQrrkNFAht-7SFhyDR4ugoOFNzMdaPnOZq5ZriyKlj-kmkq7gxgQzwhtuf_P05WH07sF_M5v-VucgYM6ssK6IuWXmW-YUCLApyFhqGxlBlXM0nRoDC_6Cjl7iSoUttwTZXhTWNVWLV2DtuwPsswGlv9Aj40zcaB7cTeqOv3tLUAtntUY3mQ7kZOfKTjTZGtuhrk8X7gIi3lJgdBPSGuhHcOHoC6KqXgFpEYHNd9pzDKQ-ZDhKFWdaKSEdl22Bvqve_qJU5rmsAFQTg
2021-09-10 23:20:07 ERROR (MainThread) [homeassistant] Error doing job: Future exception was never retrieved
Traceback (most recent call last):
  File "/usr/local/lib/python3.9/concurrent/futures/thread.py", line 52, in run
    result = self.fn(*self.args, **self.kwargs)
TypeError: update() takes 1 positional argument but 2 were given
2021-09-10 23:25:08 ERROR (MainThread) [homeassistant] Error doing job: Future exception was never retrieved
Traceback (most recent call last):
  File "/usr/local/lib/python3.9/concurrent/futures/thread.py", line 52, in run
    result = self.fn(*self.args, **self.kwargs)
TypeError: update() takes 1 positional argument but 2 were given
2021-09-10 23:30:09 ERROR (MainThread) [homeassistant] Error doing job: Future exception was never retrieved
Traceback (most recent call last):
  File "/usr/local/lib/python3.9/concurrent/futures/thread.py", line 52, in run
    result = self.fn(*self.args, **self.kwargs)
TypeError: update() takes 1 positional argument but 2 were given
2021-09-10 23:35:10 ERROR (MainThread) [homeassistant] Error doing job: Future exception was never retrieved
Traceback (most recent call last):
  File "/usr/local/lib/python3.9/concurrent/futures/thread.py", line 52, in run
    result = self.fn(*self.args, **self.kwargs)
TypeError: update() takes 1 positional argument but 2 were given
2021-09-10 23:40:11 ERROR (MainThread) [homeassistant] Error doing job: Future exception was never retrieved
Traceback (most recent call last):
  File "/usr/local/lib/python3.9/concurrent/futures/thread.py", line 52, in run
    result = self.fn(*self.args, **self.kwargs)
TypeError: update() takes 1 positional argument but 2 were given
2021-09-10 23:45:12 ERROR (MainThread) [homeassistant] Error doing job: Future exception was never retrieved
Traceback (most recent call last):
  File "/usr/local/lib/python3.9/concurrent/futures/thread.py", line 52, in run
    result = self.fn(*self.args, **self.kwargs)
TypeError: update() takes 1 positional argument but 2 were given
2021-09-10 23:50:13 ERROR (MainThread) [homeassistant] Error doing job: Future exception was never retrieved
Traceback (most recent call last):
  File "/usr/local/lib/python3.9/concurrent/futures/thread.py", line 52, in run
    result = self.fn(*self.args, **self.kwargs)
TypeError: update() takes 1 positional argument but 2 were given
2021-09-10 23:55:14 ERROR (MainThread) [homeassistant] Error doing job: Future exception was never retrieved
Traceback (most recent call last):
  File "/usr/local/lib/python3.9/concurrent/futures/thread.py", line 52, in run
    result = self.fn(*self.args, **self.kwargs)
TypeError: update() takes 1 positional argument but 2 were given
2021-09-11 00:00:15 ERROR (MainThread) [homeassistant] Error doing job: Future exception was never retrieved
Traceback (most recent call last):
  File "/usr/local/lib/python3.9/concurrent/futures/thread.py", line 52, in run
    result = self.fn(*self.args, **self.kwargs)
TypeError: update() takes 1 positional argument but 2 were given
2021-09-11 00:04:16 ERROR (stream_worker) [libav.rtsp] method DESCRIBE failed: 404 Not Found
2021-09-11 00:04:16 ERROR (stream_worker) [homeassistant.components.stream.worker] Error opening stream rtsps://stream-uc2-bravo.dropcam.com:443/sdm_live_stream/CiQA2vuxrz2sgA8iUhOEUMVn4NQgm_HYKff_nrs-qDJnCB_sv6wScQAFjsOTIkRzKZ_vho6bYL13N3HzZ-jDdcKomoh6mO_z_hty8c0rvqFmrH4mwLmhLf8GfYBHbDSkZUQpw_TeljlcYITQ9fxiHLLt_eu4aRDsDNrLYWIQDkbVT9St8D7k55HVh4B8VaTrdTYun28tu1_3?auth=g.0.eyJraWQiOiIyMzhiNTUxZmMyM2EyM2Y4M2E2ZTE3MmJjZTg0YmU3ZjgxMzAzMmM4IiwiYWxnIjoiUlMyNTYifQ.eyJpc3MiOiJuZXN0LXNlY3VyaXR5LWF1dGhwcm94eSIsInN1YiI6Im5lc3RfaWQ6bmVzdC1waG9lbml4LXByb2Q6MjEyMTgxNDEiLCJwb2wiOiIzcC1vYXV0aC1zY29wZS1BUElfU0RNX1NFUlZJQ0UtY2xpZW50LTIwMjQyNzMxODczNS1qNXQ5bWMyMzZqaG85YXMycWY0dTZxY3NmYW1kaGJ0ci5hcHBzLmdvb2dsZXVzZXJjb250ZW50LmNvbSIsImV4cCI6MTYzMTM0NDA4NH0.cJOU58B6AKh0lDikGCCTKWltDAeXnwK9G5DRfjB8-3-9FhqiSZAaqpnsnCc1jSgGS-DR86eLE8KHJBAVKAsXT88o2WDLRqFNet6LrTq-Eg6FxaVJ0M-arVH-E2p7UEncDbKkP5xI103JMeK4gfUuxeDFQpMsmd5t6hDOZg2tSgcQUjicT0guW0t9R8LDcaMawp4tB09N0DylBlKh--orYUxp2XyVvUHKKj_8dBjg44imJq1koTLepgdw1mEvRDP2kSyEVF6qjm6xiI9D2Wqau8iga6ZD7MgHOKD1Suk_Twko0Or5TopsOrIkA4fwGseMyiGF9i0CMdAs_BH3p-Tu1A
2021-09-11 00:05:16 ERROR (MainThread) [homeassistant] Error doing job: Future exception was never retrieved
Traceback (most recent call last):
  File "/usr/local/lib/python3.9/concurrent/futures/thread.py", line 52, in run
    result = self.fn(*self.args, **self.kwargs)
TypeError: update() takes 1 positional argument but 2 were given
2021-09-11 00:10:17 ERROR (MainThread) [homeassistant] Error doing job: Future exception was never retrieved
Traceback (most recent call last):
  File "/usr/local/lib/python3.9/concurrent/futures/thread.py", line 52, in run
    result = self.fn(*self.args, **self.kwargs)
TypeError: update() takes 1 positional argument but 2 were given
2021-09-11 00:13:17 ERROR (stream_worker) [libav.rtsp] method DESCRIBE failed: 404 Not Found
2021-09-11 00:13:17 ERROR (stream_worker) [homeassistant.components.stream.worker] Error opening stream rtsps://stream-uc2-delta.dropcam.com:443/sdm_live_stream/CiQA2vuxr6WY2VVedou9hCPV4sChWuwav6uqKwarBLcDdUJw5ygScQAFjsOTdMTBcJ5ngrsiGYZQdfooLrM0HYjFspm2C-SwCNwhlLKpupV7KeB2M56AYcCfF8V3QMDOBWB4TEIZZUDwgXZDMA09EkbrBwdJG51LWeBgadzWgeg3bwqaBlq7BMCRC9TIIAd9ukTyjXKTocHX?auth=g.0.eyJraWQiOiIyMzhiNTUxZmMyM2EyM2Y4M2E2ZTE3MmJjZTg0YmU3ZjgxMzAzMmM4IiwiYWxnIjoiUlMyNTYifQ.eyJpc3MiOiJuZXN0LXNlY3VyaXR5LWF1dGhwcm94eSIsInN1YiI6Im5lc3RfaWQ6bmVzdC1waG9lbml4LXByb2Q6MjEyMTgxNDEiLCJwb2wiOiIzcC1vYXV0aC1zY29wZS1BUElfU0RNX1NFUlZJQ0UtY2xpZW50LTIwMjQyNzMxODczNS1qNXQ5bWMyMzZqaG85YXMycWY0dTZxY3NmYW1kaGJ0ci5hcHBzLmdvb2dsZXVzZXJjb250ZW50LmNvbSIsImV4cCI6MTYzMTM0NDYyNn0.VPsfr_GEkc43YDXuP1QdhGhFYFhGAx35Idn1rmbOFK2sZk1gx5cYA16J7pm_4WWQhlTzoh0QJkPETDt52XVp9tiAd9UUUljYtGXlmGq2TXAVZdoHVRW911PwDOqG8TQcABE1sRDZlqViSCx3KDQCKiOPHLKZQBbqNliVRk2JuH_inogo6l1MqFxJsjbHZiOw1NJ_bc1J7GPoAatwWQmxG0PaG9gzbSzMQt62ZahaVJxn3hTvGHJU9fG2yxjpn0nkEEz2pvhuH5Irmt33fcSXB2uzNfUOAeiyAGiWticll-6BDd-nz-suJYuuM5AuU5vkIQWP1-Ynbmadzn1ft1o6MQ
2021-09-11 00:15:12 ERROR (stream_worker) [libav.tls] Error in the pull function.
2021-09-11 00:15:12 ERROR (stream_worker) [libav.tls] The specified session has been invalidated for some reason.
2021-09-11 00:15:12 ERROR (stream_worker) [homeassistant.components.stream.worker] Error demuxing stream: 
2021-09-11 00:15:12 ERROR (stream_worker) [libav.tls] The specified session has been invalidated for some reason.
2021-09-11 00:15:18 ERROR (MainThread) [homeassistant] Error doing job: Future exception was never retrieved
Traceback (most recent call last):
  File "/usr/local/lib/python3.9/concurrent/futures/thread.py", line 52, in run
    result = self.fn(*self.args, **self.kwargs)
TypeError: update() takes 1 positional argument but 2 were given
2021-09-11 00:20:19 ERROR (MainThread) [homeassistant] Error doing job: Future exception was never retrieved
Traceback (most recent call last):
  File "/usr/local/lib/python3.9/concurrent/futures/thread.py", line 52, in run
    result = self.fn(*self.args, **self.kwargs)
TypeError: update() takes 1 positional argument but 2 were given
2021-09-11 00:22:27 ERROR (stream_worker) [libav.rtsp] method DESCRIBE failed: 404 Not Found
2021-09-11 00:22:27 ERROR (stream_worker) [homeassistant.components.stream.worker] Error opening stream rtsps://stream-uc2-bravo.dropcam.com:443/sdm_live_stream/CiQA2vuxrz2sgA8iUhOEUMVn4NQgm_HYKff_nrs-qDJnCB_sv6wScQAFjsOTIkRzKZ_vho6bYL13N3HzZ-jDdcKomoh6mO_z_hty8c0rvqFmrH4mwLmhLf8GfYBHbDSkZUQpw_TeljlcYITQ9fxiHLLt_eu4aRDsDNrLYWIQDkbVT9St8D7k55HVh4B8VaTrdTYun28tu1_3?auth=g.0.eyJraWQiOiIyMzhiNTUxZmMyM2EyM2Y4M2E2ZTE3MmJjZTg0YmU3ZjgxMzAzMmM4IiwiYWxnIjoiUlMyNTYifQ.eyJpc3MiOiJuZXN0LXNlY3VyaXR5LWF1dGhwcm94eSIsInN1YiI6Im5lc3RfaWQ6bmVzdC1waG9lbml4LXByb2Q6MjEyMTgxNDEiLCJwb2wiOiIzcC1vYXV0aC1zY29wZS1BUElfU0RNX1NFUlZJQ0UtY2xpZW50LTIwMjQyNzMxODczNS1qNXQ5bWMyMzZqaG85YXMycWY0dTZxY3NmYW1kaGJ0ci5hcHBzLmdvb2dsZXVzZXJjb250ZW50LmNvbSIsImV4cCI6MTYzMTM0NTE2Nn0.CZiV7Qx4mTD3Q3l2cuY5cIwZfJS2O4s1ZeFK0lA5yJ_Dyi4UJEe6E7SlwESQR3tzxWWsHycqvQIcyUX1XlBnsUI10hxnn2Tv2QQWeJaa4PfQCE64KcHpU-pnl8L3-5sGWCiBdoxlJFilxz9Ft2mq_BGNacGqDuK2npmEaixq1LSmyUaU1Ij3UF7GyEBhZScUZ2gZlcXobDO4uCOcALdSryVP1KDu6voqusdfO9aY6pvrC5P4JPSpznXIoWaK8wBr6y9EY3jhRZgcmeLavmgm9nJCpikm4JoVh2dJcAn6FXsOIP29m7jOypUq2sIQ7I_30odUDZ8jDMC8Cb-Hbp9BXw
2021-09-11 00:25:20 ERROR (MainThread) [homeassistant] Error doing job: Future exception was never retrieved
Traceback (most recent call last):
  File "/usr/local/lib/python3.9/concurrent/futures/thread.py", line 52, in run
    result = self.fn(*self.args, **self.kwargs)
TypeError: update() takes 1 positional argument but 2 were given
2021-09-11 00:30:21 ERROR (MainThread) [homeassistant] Error doing job: Future exception was never retrieved
Traceback (most recent call last):
  File "/usr/local/lib/python3.9/concurrent/futures/thread.py", line 52, in run
    result = self.fn(*self.args, **self.kwargs)
TypeError: update() takes 1 positional argument but 2 were given
2021-09-11 00:32:18 WARNING (MainThread) [bellows.zigbee.application] Watchdog heartbeat timeout: 
2021-09-11 00:32:33 WARNING (MainThread) [bellows.zigbee.application] Watchdog heartbeat timeout: 
2021-09-11 00:32:48 WARNING (MainThread) [bellows.zigbee.application] Watchdog heartbeat timeout: 
2021-09-11 00:33:03 WARNING (MainThread) [bellows.zigbee.application] Watchdog heartbeat timeout: 
2021-09-11 00:33:18 WARNING (MainThread) [bellows.zigbee.application] Watchdog heartbeat timeout: 
2021-09-11 00:34:17 WARNING (MainThread) [homeassistant.helpers.service] Unable to find referenced entities light.hue_lightstrip_2
2021-09-11 00:35:22 ERROR (MainThread) [homeassistant] Error doing job: Future exception was never retrieved
Traceback (most recent call last):
  File "/usr/local/lib/python3.9/concurrent/futures/thread.py", line 52, in run
    result = self.fn(*self.args, **self.kwargs)
TypeError: update() takes 1 positional argument but 2 were given
2021-09-11 00:37:35 ERROR (MainThread) [homeassistant] Error doing job: Task was destroyed but it is pending!
2021-09-11 00:39:33 ERROR (MainThread) [homeassistant.components.openweathermap.weather_update_coordinator] Error fetching openweathermap data: HTTPSConnectionPool(host='api.openweathermap.org', port=443): Max retries exceeded with url: /data/2.5/onecall?APPID=2f25f55c59e31d8ff0bc160dd5b080b4&lang=en&lon=-118.5447782&lat=34.3703751 (Caused by SSLError(SSLEOFError(8, 'EOF occurred in violation of protocol (_ssl.c:1129)')))
2021-09-11 00:40:23 ERROR (MainThread) [homeassistant] Error doing job: Future exception was never retrieved
Traceback (most recent call last):
  File "/usr/local/lib/python3.9/concurrent/futures/thread.py", line 52, in run
    result = self.fn(*self.args, **self.kwargs)
TypeError: update() takes 1 positional argument but 2 were given
2021-09-11 00:41:38 WARNING (MainThread) [bellows.zigbee.application] Watchdog heartbeat timeout: 
2021-09-11 00:45:24 ERROR (MainThread) [homeassistant] Error doing job: Future exception was never retrieved
Traceback (most recent call last):
  File "/usr/local/lib/python3.9/concurrent/futures/thread.py", line 52, in run
    result = self.fn(*self.args, **self.kwargs)
TypeError: update() takes 1 positional argument but 2 were given
2021-09-11 00:50:25 ERROR (MainThread) [homeassistant] Error doing job: Future exception was never retrieved
Traceback (most recent call last):
  File "/usr/local/lib/python3.9/concurrent/futures/thread.py", line 52, in run
    result = self.fn(*self.args, **self.kwargs)
TypeError: update() takes 1 positional argument but 2 were given
2021-09-11 00:55:26 ERROR (MainThread) [homeassistant] Error doing job: Future exception was never retrieved
Traceback (most recent call last):
  File "/usr/local/lib/python3.9/concurrent/futures/thread.py", line 52, in run
    result = self.fn(*self.args, **self.kwargs)
TypeError: update() takes 1 positional argument but 2 were given
2021-09-11 01:00:27 ERROR (MainThread) [homeassistant] Error doing job: Future exception was never retrieved
Traceback (most recent call last):
  File "/usr/local/lib/python3.9/concurrent/futures/thread.py", line 52, in run
    result = self.fn(*self.args, **self.kwargs)
TypeError: update() takes 1 positional argument but 2 were given
2021-09-11 01:05:28 ERROR (MainThread) [homeassistant] Error doing job: Future exception was never retrieved
Traceback (most recent call last):
  File "/usr/local/lib/python3.9/concurrent/futures/thread.py", line 52, in run
    result = self.fn(*self.args, **self.kwargs)
TypeError: update() takes 1 positional argument but 2 were given
2021-09-11 01:10:29 ERROR (MainThread) [homeassistant] Error doing job: Future exception was never retrieved
Traceback (most recent call last):
  File "/usr/local/lib/python3.9/concurrent/futures/thread.py", line 52, in run
    result = self.fn(*self.args, **self.kwargs)
TypeError: update() takes 1 positional argument but 2 were given
2021-09-11 01:15:30 ERROR (MainThread) [homeassistant] Error doing job: Future exception was never retrieved
Traceback (most recent call last):
  File "/usr/local/lib/python3.9/concurrent/futures/thread.py", line 52, in run
    result = self.fn(*self.args, **self.kwargs)
TypeError: update() takes 1 positional argument but 2 were given
2021-09-11 01:20:31 ERROR (MainThread) [homeassistant] Error doing job: Future exception was never retrieved
Traceback (most recent call last):
  File "/usr/local/lib/python3.9/concurrent/futures/thread.py", line 52, in run
    result = self.fn(*self.args, **self.kwargs)
TypeError: update() takes 1 positional argument but 2 were given
2021-09-11 01:25:32 ERROR (MainThread) [homeassistant] Error doing job: Future exception was never retrieved
Traceback (most recent call last):
  File "/usr/local/lib/python3.9/concurrent/futures/thread.py", line 52, in run
    result = self.fn(*self.args, **self.kwargs)
TypeError: update() takes 1 positional argument but 2 were given
2021-09-11 01:30:33 ERROR (MainThread) [homeassistant] Error doing job: Future exception was never retrieved
Traceback (most recent call last):
  File "/usr/local/lib/python3.9/concurrent/futures/thread.py", line 52, in run
    result = self.fn(*self.args, **self.kwargs)
TypeError: update() takes 1 positional argument but 2 were given
2021-09-11 01:35:34 ERROR (MainThread) [homeassistant] Error doing job: Future exception was never retrieved
Traceback (most recent call last):
  File "/usr/local/lib/python3.9/concurrent/futures/thread.py", line 52, in run
    result = self.fn(*self.args, **self.kwargs)
TypeError: update() takes 1 positional argument but 2 were given
2021-09-11 01:40:35 ERROR (MainThread) [homeassistant] Error doing job: Future exception was never retrieved
Traceback (most recent call last):
  File "/usr/local/lib/python3.9/concurrent/futures/thread.py", line 52, in run
    result = self.fn(*self.args, **self.kwargs)
TypeError: update() takes 1 positional argument but 2 were given
2021-09-11 01:45:36 ERROR (MainThread) [homeassistant] Error doing job: Future exception was never retrieved
Traceback (most recent call last):
  File "/usr/local/lib/python3.9/concurrent/futures/thread.py", line 52, in run
    result = self.fn(*self.args, **self.kwargs)
TypeError: update() takes 1 positional argument but 2 were given
2021-09-11 01:50:37 ERROR (MainThread) [homeassistant] Error doing job: Future exception was never retrieved
Traceback (most recent call last):
  File "/usr/local/lib/python3.9/concurrent/futures/thread.py", line 52, in run
    result = self.fn(*self.args, **self.kwargs)
TypeError: update() takes 1 positional argument but 2 were given
2021-09-11 01:55:38 ERROR (MainThread) [homeassistant] Error doing job: Future exception was never retrieved
Traceback (most recent call last):
  File "/usr/local/lib/python3.9/concurrent/futures/thread.py", line 52, in run
    result = self.fn(*self.args, **self.kwargs)
TypeError: update() takes 1 positional argument but 2 were given
2021-09-11 02:00:39 ERROR (MainThread) [homeassistant] Error doing job: Future exception was never retrieved
Traceback (most recent call last):
  File "/usr/local/lib/python3.9/concurrent/futures/thread.py", line 52, in run
    result = self.fn(*self.args, **self.kwargs)
TypeError: update() takes 1 positional argument but 2 were given
2021-09-11 02:05:40 ERROR (MainThread) [homeassistant] Error doing job: Future exception was never retrieved
Traceback (most recent call last):
  File "/usr/local/lib/python3.9/concurrent/futures/thread.py", line 52, in run
    result = self.fn(*self.args, **self.kwargs)
TypeError: update() takes 1 positional argument but 2 were given
2021-09-11 02:06:00 WARNING (Thread-8) [pychromecast.socket_client] [Kitchen speaker(192.168.20.124):8009] Heartbeat timeout, resetting connection
2021-09-11 02:06:15 ERROR (Thread-8) [pychromecast.socket_client] [Kitchen speaker(192.168.20.124):8009] Failed to connect to service ServiceInfo(type='host', data=('192.168.20.124', 8009)), retrying in 5.0s
2021-09-11 02:06:18 ERROR (MainThread) [homeassistant.components.nws] Error requesting NWS observation station SAUC1 data: 503, message='Service Unavailable', url=URL('https://api.weather.gov/stations/SAUC1/observations')
2021-09-11 02:10:41 ERROR (MainThread) [homeassistant] Error doing job: Future exception was never retrieved
Traceback (most recent call last):
  File "/usr/local/lib/python3.9/concurrent/futures/thread.py", line 52, in run
    result = self.fn(*self.args, **self.kwargs)
TypeError: update() takes 1 positional argument but 2 were given
2021-09-11 02:15:42 ERROR (MainThread) [homeassistant] Error doing job: Future exception was never retrieved
Traceback (most recent call last):
  File "/usr/local/lib/python3.9/concurrent/futures/thread.py", line 52, in run
    result = self.fn(*self.args, **self.kwargs)
TypeError: update() takes 1 positional argument but 2 were given
2021-09-11 02:16:01 WARNING (MainThread) [bellows.zigbee.application] Watchdog heartbeat timeout: 
2021-09-11 02:20:43 ERROR (MainThread) [homeassistant] Error doing job: Future exception was never retrieved
Traceback (most recent call last):
  File "/usr/local/lib/python3.9/concurrent/futures/thread.py", line 52, in run
    result = self.fn(*self.args, **self.kwargs)
TypeError: update() takes 1 positional argument but 2 were given
2021-09-11 02:25:44 ERROR (MainThread) [homeassistant] Error doing job: Future exception was never retrieved
Traceback (most recent call last):
  File "/usr/local/lib/python3.9/concurrent/futures/thread.py", line 52, in run
    result = self.fn(*self.args, **self.kwargs)
TypeError: update() takes 1 positional argument but 2 were given
2021-09-11 02:27:19 WARNING (Thread-9) [pychromecast.socket_client] [Liam Home Mini(192.168.6.222):8009] Heartbeat timeout, resetting connection
2021-09-11 02:27:49 ERROR (Thread-9) [pychromecast.socket_client] [Liam Home Mini(192.168.6.222):8009] Failed to connect to service ServiceInfo(type='host', data=('192.168.6.222', 8009)), retrying in 5.0s
2021-09-11 02:30:45 ERROR (MainThread) [homeassistant] Error doing job: Future exception was never retrieved
Traceback (most recent call last):
  File "/usr/local/lib/python3.9/concurrent/futures/thread.py", line 52, in run
    result = self.fn(*self.args, **self.kwargs)
TypeError: update() takes 1 positional argument but 2 were given
2021-09-11 02:35:46 ERROR (MainThread) [homeassistant] Error doing job: Future exception was never retrieved
Traceback (most recent call last):
  File "/usr/local/lib/python3.9/concurrent/futures/thread.py", line 52, in run
    result = self.fn(*self.args, **self.kwargs)
TypeError: update() takes 1 positional argument but 2 were given
2021-09-11 02:40:43 WARNING (Thread-11) [pychromecast.socket_client] [Aidan Google Home(192.168.6.244):8009] Heartbeat timeout, resetting connection
2021-09-11 02:40:47 ERROR (MainThread) [homeassistant] Error doing job: Future exception was never retrieved
Traceback (most recent call last):
  File "/usr/local/lib/python3.9/concurrent/futures/thread.py", line 52, in run
    result = self.fn(*self.args, **self.kwargs)
TypeError: update() takes 1 positional argument but 2 were given
2021-09-11 02:40:50 ERROR (Thread-11) [pychromecast.socket_client] [Aidan Google Home(192.168.6.244):8009] Failed to connect to service ServiceInfo(type='host', data=('192.168.6.244', 8009)), retrying in 5.0s
2021-09-11 02:42:39 WARNING (Thread-14) [pychromecast.socket_client] [Office_Brian speaker(192.168.20.247):8009] Heartbeat timeout, resetting connection
2021-09-11 02:42:56 WARNING (MainThread) [homeassistant.components.template.template_entity] Template loop detected while processing event: <Event state_changed[L]: entity_id=sensor.entities_count, old_state=<state sensor.entities_count=765; friendly_name=Number of Entities @ 2021-09-11T02:40:56.680977-07:00>, new_state=<state sensor.entities_count=766; friendly_name=Number of Entities @ 2021-09-11T02:41:56.682390-07:00>>, skipping template render for Template[{{ states | rejectattr('state', 'eq', 'unavailable') | list | count}}]
2021-09-11 02:45:48 ERROR (MainThread) [homeassistant] Error doing job: Future exception was never retrieved
Traceback (most recent call last):
  File "/usr/local/lib/python3.9/concurrent/futures/thread.py", line 52, in run
    result = self.fn(*self.args, **self.kwargs)
TypeError: update() takes 1 positional argument but 2 were given
2021-09-11 02:50:49 ERROR (MainThread) [homeassistant] Error doing job: Future exception was never retrieved
Traceback (most recent call last):
  File "/usr/local/lib/python3.9/concurrent/futures/thread.py", line 52, in run
    result = self.fn(*self.args, **self.kwargs)
TypeError: update() takes 1 positional argument but 2 were given
2021-09-11 02:55:50 ERROR (MainThread) [homeassistant] Error doing job: Future exception was never retrieved
Traceback (most recent call last):
  File "/usr/local/lib/python3.9/concurrent/futures/thread.py", line 52, in run
    result = self.fn(*self.args, **self.kwargs)
TypeError: update() takes 1 positional argument but 2 were given
2021-09-11 03:00:51 ERROR (MainThread) [homeassistant] Error doing job: Future exception was never retrieved
Traceback (most recent call last):
  File "/usr/local/lib/python3.9/concurrent/futures/thread.py", line 52, in run
    result = self.fn(*self.args, **self.kwargs)
TypeError: update() takes 1 positional argument but 2 were given
