2021-09-03 03:16:57 WARNING (SyncWorker_1) [homeassistant.loader] We found a custom integration sun2 which has not been tested by Home Assistant. This component might cause stability problems, be sure to disable it if you experience issues with Home Assistant
2021-09-03 03:17:05 WARNING (Recorder) [homeassistant.components.recorder.util] The system could not validate that the sqlite3 database at //config/home-assistant_v2.db was shutdown cleanly
2021-09-03 03:17:14 WARNING (MainThread) [homeassistant.components.sensor] Entity sensor.cpu_temp (<class 'homeassistant.components.command_line.sensor.CommandSensor'>) with device_class None reports a temperature in °C which will be converted to °F. Temperature conversion for entities without correct device_class is deprecated and will be removed from Home Assistant Core 2022.3. Please update your configuration if device_class is manually configured, otherwise create a bug report at https://github.com/home-assistant/core/issues?q=is%3Aopen+is%3Aissue+label%3A%22integration%3A+command_line%22
2021-09-03 03:17:14 WARNING (MainThread) [homeassistant.config_entries] Config entry 'Roku Smart Soundbar' for roku integration not ready yet: Invalid response from API: Error occurred while communicating with device; Retrying in background
2021-09-03 03:17:20 WARNING (MainThread) [homeassistant.config_entries] Config entry '192.168.7.195' for wled integration not ready yet: Invalid response from API: Error occurred while communicating with WLED device at 192.168.7.195; Retrying in background
2021-09-03 03:17:21 ERROR (MainThread) [homeassistant.components.snmp.sensor] Please check the details in the configuration file
2021-09-03 03:17:21 ERROR (MainThread) [homeassistant.components.snmp.sensor] Please check the details in the configuration file
2021-09-03 03:17:21 ERROR (MainThread) [homeassistant.components.snmp.sensor] Please check the details in the configuration file
2021-09-03 03:17:21 ERROR (MainThread) [homeassistant.components.snmp.sensor] Please check the details in the configuration file
2021-09-03 03:17:21 ERROR (MainThread) [homeassistant.components.snmp.sensor] Please check the details in the configuration file
2021-09-03 03:18:09 WARNING (MainThread) [homeassistant.bootstrap] Waiting on integrations to complete setup: forecast_solar
2021-09-03 03:18:10 ERROR (bellows.thread_0) [bellows.uart] CRC error in frame b'24ab5593499c554f1d5d4c9874facfec88f17e3fa7e990ca7e' (b'90ca' != b'aa2b')
2021-09-03 03:18:39 ERROR (MainThread) [homeassistant] Error doing job: Task exception was never retrieved
Traceback (most recent call last):
  File "/usr/local/lib/python3.9/site-packages/zigpy/device.py", line 287, in request
    raise zigpy.exceptions.DeliveryError(
zigpy.exceptions.DeliveryError: [0x82b0:1:0x0500]: Message send failure
2021-09-03 03:18:40 ERROR (MainThread) [homeassistant] Error doing job: Task exception was never retrieved
Traceback (most recent call last):
  File "/usr/local/lib/python3.9/site-packages/zigpy/device.py", line 287, in request
    raise zigpy.exceptions.DeliveryError(
zigpy.exceptions.DeliveryError: [0x82b0:1:0x0500]: Message send failure
2021-09-03 03:18:46 WARNING (MainThread) [homeassistant.components.sensor] Entity sensor.garagesidedoorsensor_bme280_dewpoint (<class 'homeassistant.components.tasmota.sensor.TasmotaSensor'>) with device_class None reports a temperature in °C which will be converted to °F. Temperature conversion for entities without correct device_class is deprecated and will be removed from Home Assistant Core 2022.3. Please update your configuration if device_class is manually configured, otherwise create a bug report at https://github.com/home-assistant/core/issues?q=is%3Aopen+is%3Aissue+label%3A%22integration%3A+tasmota%22
2021-09-03 03:19:09 WARNING (MainThread) [homeassistant.bootstrap] Waiting on integrations to complete setup: forecast_solar
2021-09-03 03:19:19 WARNING (MainThread) [homeassistant.config_entries] Config entry 'Cerezo House HA' for forecast_solar integration not ready yet: Cannot connect to host 91.228.53.233:443 ssl:False [Connect call failed ('91.228.53.233', 443)]; Retrying in background
2021-09-03 03:19:19 WARNING (MainThread) [homeassistant.config_entries] Config entry 'Cerezo House HA' for forecast_solar integration not ready yet: Cannot connect to host 91.228.53.233:443 ssl:False [Connect call failed ('91.228.53.233', 443)]; Retrying in background
2021-09-03 03:19:19 ERROR (MainThread) [homeassistant.helpers.event] Error while processing template: Template("{% if states.sensor.iss_pass_times %}{{ states.sensor.iss_pass_times.attributes["response"][4]["risetime"] | timestamp_custom("%a %d %b %Y %H:%M:%S") }}{% endif %}")
Traceback (most recent call last):
  File "/usr/src/homeassistant/homeassistant/helpers/template.py", line 394, in async_render
    render_result = _render_with_context(self.template, compiled, **kwargs)
  File "/usr/src/homeassistant/homeassistant/helpers/template.py", line 1477, in _render_with_context
    return template.render(**kwargs)
  File "/usr/local/lib/python3.9/site-packages/jinja2/environment.py", line 1304, in render
    self.environment.handle_exception()
  File "/usr/local/lib/python3.9/site-packages/jinja2/environment.py", line 925, in handle_exception
    raise rewrite_traceback_stack(source=source)
  File "<template>", line 1, in top-level template code
  File "/usr/local/lib/python3.9/site-packages/jinja2/sandbox.py", line 303, in getitem
    return obj[argument]
jinja2.exceptions.UndefinedError: list object has no element 4

The above exception was the direct cause of the following exception:

Traceback (most recent call last):
  File "/usr/src/homeassistant/homeassistant/helpers/template.py", line 510, in async_render_to_info
    render_info._result = self.async_render(variables, strict=strict, **kwargs)
  File "/usr/src/homeassistant/homeassistant/helpers/template.py", line 396, in async_render
    raise TemplateError(err) from err
homeassistant.exceptions.TemplateError: UndefinedError: list object has no element 4
2021-09-03 03:19:19 ERROR (MainThread) [homeassistant.components.template.template_entity] TemplateError('UndefinedError: list object has no element 4') while processing template 'Template("{% if states.sensor.iss_pass_times %}{{ states.sensor.iss_pass_times.attributes["response"][4]["risetime"] | timestamp_custom("%a %d %b %Y %H:%M:%S") }}{% endif %}")' for attribute '_attr_native_value' in entity 'sensor.iss_risetime_4'
2021-09-03 03:19:19 ERROR (MainThread) [homeassistant.helpers.event] Error while processing template: Template("{% if states.sensor.iss_pass_times %}{{ states.sensor.iss_pass_times.attributes["response"][4]["duration"] }}{% endif %}")
Traceback (most recent call last):
  File "/usr/src/homeassistant/homeassistant/helpers/template.py", line 394, in async_render
    render_result = _render_with_context(self.template, compiled, **kwargs)
  File "/usr/src/homeassistant/homeassistant/helpers/template.py", line 1477, in _render_with_context
    return template.render(**kwargs)
  File "/usr/local/lib/python3.9/site-packages/jinja2/environment.py", line 1304, in render
    self.environment.handle_exception()
  File "/usr/local/lib/python3.9/site-packages/jinja2/environment.py", line 925, in handle_exception
    raise rewrite_traceback_stack(source=source)
  File "<template>", line 1, in top-level template code
  File "/usr/local/lib/python3.9/site-packages/jinja2/sandbox.py", line 303, in getitem
    return obj[argument]
jinja2.exceptions.UndefinedError: list object has no element 4

The above exception was the direct cause of the following exception:

Traceback (most recent call last):
  File "/usr/src/homeassistant/homeassistant/helpers/template.py", line 510, in async_render_to_info
    render_info._result = self.async_render(variables, strict=strict, **kwargs)
  File "/usr/src/homeassistant/homeassistant/helpers/template.py", line 396, in async_render
    raise TemplateError(err) from err
homeassistant.exceptions.TemplateError: UndefinedError: list object has no element 4
2021-09-03 03:19:19 ERROR (MainThread) [homeassistant.components.template.template_entity] TemplateError('UndefinedError: list object has no element 4') while processing template 'Template("{% if states.sensor.iss_pass_times %}{{ states.sensor.iss_pass_times.attributes["response"][4]["duration"] }}{% endif %}")' for attribute '_attr_native_value' in entity 'sensor.iss_duration_4'
2021-09-03 03:20:49 WARNING (MainThread) [homeassistant.helpers.service] Unable to find referenced entities light.hue_lightstrip_2
2021-09-03 03:20:50 WARNING (MainThread) [homeassistant.components.sensor] Entity sensor.attictemp1_bme280_dewpoint (<class 'homeassistant.components.tasmota.sensor.TasmotaSensor'>) with device_class None reports a temperature in °C which will be converted to °F. Temperature conversion for entities without correct device_class is deprecated and will be removed from Home Assistant Core 2022.3. Please update your configuration if device_class is manually configured, otherwise create a bug report at https://github.com/home-assistant/core/issues?q=is%3Aopen+is%3Aissue+label%3A%22integration%3A+tasmota%22
2021-09-03 03:20:50 WARNING (MainThread) [homeassistant.components.template.template_entity] Template loop detected while processing event: <Event state_changed[L]: entity_id=sensor.sensor_count, old_state=<state sensor.sensor_count=416; friendly_name=Number of Sensors @ 2021-09-03T03:20:48.163502-07:00>, new_state=<state sensor.sensor_count=462; friendly_name=Number of Sensors @ 2021-09-03T03:20:49.165728-07:00>>, skipping template render for Template[{{ states.sensor | rejectattr('state', 'eq', 'unavailable') | list | count }}]
2021-09-03 03:21:19 WARNING (MainThread) [homeassistant.components.template.template_entity] Template loop detected while processing event: <Event state_changed[L]: entity_id=sensor.entities_count, old_state=<state sensor.entities_count=733; friendly_name=Number of Entities @ 2021-09-03T03:19:19.652404-07:00>, new_state=<state sensor.entities_count=754; friendly_name=Number of Entities @ 2021-09-03T03:20:19.704283-07:00>>, skipping template render for Template[{{ states | rejectattr('state', 'eq', 'unavailable') | list | count}}]
2021-09-03 03:22:09 ERROR (MainThread) [homeassistant] Error doing job: Future exception was never retrieved
Traceback (most recent call last):
  File "/usr/local/lib/python3.9/concurrent/futures/thread.py", line 52, in run
    result = self.fn(*self.args, **self.kwargs)
TypeError: update() takes 1 positional argument but 2 were given
2021-09-03 03:27:10 ERROR (MainThread) [homeassistant] Error doing job: Future exception was never retrieved
Traceback (most recent call last):
  File "/usr/local/lib/python3.9/concurrent/futures/thread.py", line 52, in run
    result = self.fn(*self.args, **self.kwargs)
TypeError: update() takes 1 positional argument but 2 were given
2021-09-03 03:32:11 ERROR (MainThread) [homeassistant] Error doing job: Future exception was never retrieved
Traceback (most recent call last):
  File "/usr/local/lib/python3.9/concurrent/futures/thread.py", line 52, in run
    result = self.fn(*self.args, **self.kwargs)
TypeError: update() takes 1 positional argument but 2 were given
2021-09-03 03:37:12 ERROR (MainThread) [homeassistant] Error doing job: Future exception was never retrieved
Traceback (most recent call last):
  File "/usr/local/lib/python3.9/concurrent/futures/thread.py", line 52, in run
    result = self.fn(*self.args, **self.kwargs)
TypeError: update() takes 1 positional argument but 2 were given
2021-09-03 03:40:17 WARNING (MainThread) [bellows.zigbee.application] Watchdog heartbeat timeout: 
2021-09-03 03:42:13 ERROR (MainThread) [homeassistant] Error doing job: Future exception was never retrieved
Traceback (most recent call last):
  File "/usr/local/lib/python3.9/concurrent/futures/thread.py", line 52, in run
    result = self.fn(*self.args, **self.kwargs)
TypeError: update() takes 1 positional argument but 2 were given
2021-09-03 03:47:14 ERROR (MainThread) [homeassistant] Error doing job: Future exception was never retrieved
Traceback (most recent call last):
  File "/usr/local/lib/python3.9/concurrent/futures/thread.py", line 52, in run
    result = self.fn(*self.args, **self.kwargs)
TypeError: update() takes 1 positional argument but 2 were given
2021-09-03 03:52:15 ERROR (MainThread) [homeassistant] Error doing job: Future exception was never retrieved
Traceback (most recent call last):
  File "/usr/local/lib/python3.9/concurrent/futures/thread.py", line 52, in run
    result = self.fn(*self.args, **self.kwargs)
TypeError: update() takes 1 positional argument but 2 were given
2021-09-03 03:55:36 ERROR (stream_worker) [homeassistant.components.stream.worker] Stream has no video
2021-09-03 03:57:16 ERROR (MainThread) [homeassistant] Error doing job: Future exception was never retrieved
Traceback (most recent call last):
  File "/usr/local/lib/python3.9/concurrent/futures/thread.py", line 52, in run
    result = self.fn(*self.args, **self.kwargs)
TypeError: update() takes 1 positional argument but 2 were given
2021-09-03 04:02:17 ERROR (MainThread) [homeassistant] Error doing job: Future exception was never retrieved
Traceback (most recent call last):
  File "/usr/local/lib/python3.9/concurrent/futures/thread.py", line 52, in run
    result = self.fn(*self.args, **self.kwargs)
TypeError: update() takes 1 positional argument but 2 were given
2021-09-03 04:02:23 WARNING (Thread-15) [pychromecast.socket_client] [Office_Brian speaker(192.168.20.247):8009] Heartbeat timeout, resetting connection
2021-09-03 04:02:29 ERROR (Thread-15) [pychromecast.socket_client] [Office_Brian speaker(192.168.20.247):8009] Failed to connect to service ServiceInfo(type='host', data=('192.168.20.247', 8009)), retrying in 5.0s
2021-09-03 04:07:18 ERROR (MainThread) [homeassistant] Error doing job: Future exception was never retrieved
Traceback (most recent call last):
  File "/usr/local/lib/python3.9/concurrent/futures/thread.py", line 52, in run
    result = self.fn(*self.args, **self.kwargs)
TypeError: update() takes 1 positional argument but 2 were given
2021-09-03 04:09:21 ERROR (stream_worker) [libav.rtsp] method DESCRIBE failed: 404 Not Found
2021-09-03 04:09:21 ERROR (stream_worker) [homeassistant.components.stream.worker] Error opening stream rtsps://stream-uc2-bravo.dropcam.com:443/sdm_live_stream/CiQA2vuxr-LP01PGJcHMj2yZQZFZPWWB9gxlAEX36ndGpkLPgSgScQBQBG8tsduigF-pY7oW2muqz1xbBJ_UgxAwAW_-MMLZV12LJ73G-OLNVsOhEGUNMU6oubYsuvUqgXfX06GwD6bGvl7LUiEzXVBOkFMhd8hQ48NXaT0qjNpZHcrWyNl90m2gBjD5bOBLR8OvR3cHJt1j?auth=g.0.eyJraWQiOiIyMzhiNTUxZmMyM2EyM2Y4M2E2ZTE3MmJjZTg0YmU3ZjgxMzAzMmM4IiwiYWxnIjoiUlMyNTYifQ.eyJpc3MiOiJuZXN0LXNlY3VyaXR5LWF1dGhwcm94eSIsInN1YiI6Im5lc3RfaWQ6bmVzdC1waG9lbml4LXByb2Q6MjEyMTgxNDEiLCJwb2wiOiIzcC1vYXV0aC1zY29wZS1BUElfU0RNX1NFUlZJQ0UtY2xpZW50LTIwMjQyNzMxODczNS1qNXQ5bWMyMzZqaG85YXMycWY0dTZxY3NmYW1kaGJ0ci5hcHBzLmdvb2dsZXVzZXJjb250ZW50LmNvbSIsImV4cCI6MTYzMDY2NzYzNn0.SZNM2zaEU_QqWVSXvX407qIIacoi956Q4YZ06C3u015GolT6C_ZYsAS94jaISI6nLjgqTl-oUSjoUhxFi3r5m68g48aaUTjH5sBxPlXPjKjAzkxJBDxUHG5iGgKNnDxxqXWddjVh5sR_b_z1fiSoLnR55flolmthPzN9qL1stU8ccVuOTZJ5Ik0CoMlew2p7_TuuEQOFaAWAeTScnt-CLr7FX192Frgxp6DnVt0NAvBEWVykc0YbOCAeGFGVFgnUpwmZ5MO2NN0jycX8KoXb5VEykgDPpRL-JBJV5LZJKr3bKTXs3O4cAl3zxfNe1o3DX525ToWNcbjWUYnx2lT7BA
2021-09-03 04:09:56 ERROR (stream_worker) [libav.rtsp] method DESCRIBE failed: 404 Not Found
2021-09-03 04:09:56 ERROR (stream_worker) [homeassistant.components.stream.worker] Error opening stream rtsps://stream-uc2-bravo.dropcam.com:443/sdm_live_stream/CiQA2vuxr-LP01PGJcHMj2yZQZFZPWWB9gxlAEX36ndGpkLPgSgScQBQBG8tsduigF-pY7oW2muqz1xbBJ_UgxAwAW_-MMLZV12LJ73G-OLNVsOhEGUNMU6oubYsuvUqgXfX06GwD6bGvl7LUiEzXVBOkFMhd8hQ48NXaT0qjNpZHcrWyNl90m2gBjD5bOBLR8OvR3cHJt1j?auth=g.0.eyJraWQiOiIyMzhiNTUxZmMyM2EyM2Y4M2E2ZTE3MmJjZTg0YmU3ZjgxMzAzMmM4IiwiYWxnIjoiUlMyNTYifQ.eyJpc3MiOiJuZXN0LXNlY3VyaXR5LWF1dGhwcm94eSIsInN1YiI6Im5lc3RfaWQ6bmVzdC1waG9lbml4LXByb2Q6MjEyMTgxNDEiLCJwb2wiOiIzcC1vYXV0aC1zY29wZS1BUElfU0RNX1NFUlZJQ0UtY2xpZW50LTIwMjQyNzMxODczNS1qNXQ5bWMyMzZqaG85YXMycWY0dTZxY3NmYW1kaGJ0ci5hcHBzLmdvb2dsZXVzZXJjb250ZW50LmNvbSIsImV4cCI6MTYzMDY2NzYzNn0.SZNM2zaEU_QqWVSXvX407qIIacoi956Q4YZ06C3u015GolT6C_ZYsAS94jaISI6nLjgqTl-oUSjoUhxFi3r5m68g48aaUTjH5sBxPlXPjKjAzkxJBDxUHG5iGgKNnDxxqXWddjVh5sR_b_z1fiSoLnR55flolmthPzN9qL1stU8ccVuOTZJ5Ik0CoMlew2p7_TuuEQOFaAWAeTScnt-CLr7FX192Frgxp6DnVt0NAvBEWVykc0YbOCAeGFGVFgnUpwmZ5MO2NN0jycX8KoXb5VEykgDPpRL-JBJV5LZJKr3bKTXs3O4cAl3zxfNe1o3DX525ToWNcbjWUYnx2lT7BA
2021-09-03 04:12:19 ERROR (MainThread) [homeassistant] Error doing job: Future exception was never retrieved
Traceback (most recent call last):
  File "/usr/local/lib/python3.9/concurrent/futures/thread.py", line 52, in run
    result = self.fn(*self.args, **self.kwargs)
TypeError: update() takes 1 positional argument but 2 were given
2021-09-03 04:17:20 ERROR (MainThread) [homeassistant] Error doing job: Future exception was never retrieved
Traceback (most recent call last):
  File "/usr/local/lib/python3.9/concurrent/futures/thread.py", line 52, in run
    result = self.fn(*self.args, **self.kwargs)
TypeError: update() takes 1 positional argument but 2 were given
2021-09-03 04:22:21 ERROR (MainThread) [homeassistant] Error doing job: Future exception was never retrieved
Traceback (most recent call last):
  File "/usr/local/lib/python3.9/concurrent/futures/thread.py", line 52, in run
    result = self.fn(*self.args, **self.kwargs)
TypeError: update() takes 1 positional argument but 2 were given
2021-09-03 04:23:09 ERROR (stream_worker) [homeassistant.components.stream.worker] Stream has no video
2021-09-03 04:23:59 ERROR (stream_worker) [libav.rtsp] method DESCRIBE failed: 404 Not Found
2021-09-03 04:23:59 ERROR (stream_worker) [homeassistant.components.stream.worker] Error opening stream rtsps://stream-uc2-bravo.dropcam.com:443/sdm_live_stream/CiQA2vuxr-LP01PGJcHMj2yZQZFZPWWB9gxlAEX36ndGpkLPgSgScQBQBG8tsduigF-pY7oW2muqz1xbBJ_UgxAwAW_-MMLZV12LJ73G-OLNVsOhEGUNMU6oubYsuvUqgXfX06GwD6bGvl7LUiEzXVBOkFMhd8hQ48NXaT0qjNpZHcrWyNl90m2gBjD5bOBLR8OvR3cHJt1j?auth=g.0.eyJraWQiOiIyMzhiNTUxZmMyM2EyM2Y4M2E2ZTE3MmJjZTg0YmU3ZjgxMzAzMmM4IiwiYWxnIjoiUlMyNTYifQ.eyJpc3MiOiJuZXN0LXNlY3VyaXR5LWF1dGhwcm94eSIsInN1YiI6Im5lc3RfaWQ6bmVzdC1waG9lbml4LXByb2Q6MjEyMTgxNDEiLCJwb2wiOiIzcC1vYXV0aC1zY29wZS1BUElfU0RNX1NFUlZJQ0UtY2xpZW50LTIwMjQyNzMxODczNS1qNXQ5bWMyMzZqaG85YXMycWY0dTZxY3NmYW1kaGJ0ci5hcHBzLmdvb2dsZXVzZXJjb250ZW50LmNvbSIsImV4cCI6MTYzMDY2ODQ0OH0.nHoxX43BUOOw8sD2N5VRmn5z7yoYbJSAt7F-20rDGj0rTa2riGKRVLpbdtrgY5IvHaYPsoNZlhBCYrD31j1AWVFBMUtuM43yERoOcs9_CbPqc66jCfQ7FOZ9SL_8APCAaY5lcs185C1mFhIYsBUFHdiU4ZWxEcZBgmTop5TbjWpc9TDoEBjESGUImfG1UZ-JeVamzydeZzhsOWVPskdMXtWUhiJAlDg3Whl5A1e-JCc0SeRvK8S1-7n_TAg9awDEIf1GGZeDzDvMgb9fErkcSkTk8BnaUrHm8XPGgcCHXjQoxIpeCK14u05oiD0lm1_YoBeFx-J-FKDphNSOoshXwg
2021-09-03 04:27:22 ERROR (MainThread) [homeassistant] Error doing job: Future exception was never retrieved
Traceback (most recent call last):
  File "/usr/local/lib/python3.9/concurrent/futures/thread.py", line 52, in run
    result = self.fn(*self.args, **self.kwargs)
TypeError: update() takes 1 positional argument but 2 were given
2021-09-03 04:32:23 ERROR (MainThread) [homeassistant] Error doing job: Future exception was never retrieved
Traceback (most recent call last):
  File "/usr/local/lib/python3.9/concurrent/futures/thread.py", line 52, in run
    result = self.fn(*self.args, **self.kwargs)
TypeError: update() takes 1 positional argument but 2 were given
2021-09-03 04:32:32 ERROR (stream_worker) [libav.rtsp] method DESCRIBE failed: 404 Not Found
2021-09-03 04:32:32 ERROR (stream_worker) [homeassistant.components.stream.worker] Error opening stream rtsps://stream-uc2-bravo.dropcam.com:443/sdm_live_stream/CiQA2vuxr-LP01PGJcHMj2yZQZFZPWWB9gxlAEX36ndGpkLPgSgScQBQBG8tsduigF-pY7oW2muqz1xbBJ_UgxAwAW_-MMLZV12LJ73G-OLNVsOhEGUNMU6oubYsuvUqgXfX06GwD6bGvl7LUiEzXVBOkFMhd8hQ48NXaT0qjNpZHcrWyNl90m2gBjD5bOBLR8OvR3cHJt1j?auth=g.0.eyJraWQiOiIyMzhiNTUxZmMyM2EyM2Y4M2E2ZTE3MmJjZTg0YmU3ZjgxMzAzMmM4IiwiYWxnIjoiUlMyNTYifQ.eyJpc3MiOiJuZXN0LXNlY3VyaXR5LWF1dGhwcm94eSIsInN1YiI6Im5lc3RfaWQ6bmVzdC1waG9lbml4LXByb2Q6MjEyMTgxNDEiLCJwb2wiOiIzcC1vYXV0aC1zY29wZS1BUElfU0RNX1NFUlZJQ0UtY2xpZW50LTIwMjQyNzMxODczNS1qNXQ5bWMyMzZqaG85YXMycWY0dTZxY3NmYW1kaGJ0ci5hcHBzLmdvb2dsZXVzZXJjb250ZW50LmNvbSIsImV4cCI6MTYzMDY2ODk4OX0.l6XrH3KphJuSiRAEq4_BFVI2BE_pnEGKbITaFIgYl7xnBpsWzwR28d-IZbGvxIqNLy9i7Rv_k3tQg7jg2knZjim87hjpsKGWxacfUVkWMhlTxC7qN2WRWFnrjuYdcnuasEUM_LneNHWGZ_l3zVjA_lnxNxL2St9vtQOOSvze5T3kTOxCT5DTAIxRC7B_xLldU1E4hltaIqKnfnUwvDqGe54savdumOoqoSfrDGTVC3x9Kq28HAAkrSnygfLTxv8QtPYePkeVKLC2frPbIp1V4qbAWGpVR9gOQdfR1EPQshwuQgtdfymRZjQ8pWyIZmD97mrS_eVbmjaZMw4kfnOndg
2021-09-03 04:37:17 ERROR (stream_worker) [libav.rtsp] method DESCRIBE failed: 404 Not Found
2021-09-03 04:37:17 ERROR (stream_worker) [homeassistant.components.stream.worker] Error opening stream rtsps://stream-uc2-bravo.dropcam.com:443/sdm_live_stream/CiQA2vuxr-LP01PGJcHMj2yZQZFZPWWB9gxlAEX36ndGpkLPgSgScQBQBG8tsduigF-pY7oW2muqz1xbBJ_UgxAwAW_-MMLZV12LJ73G-OLNVsOhEGUNMU6oubYsuvUqgXfX06GwD6bGvl7LUiEzXVBOkFMhd8hQ48NXaT0qjNpZHcrWyNl90m2gBjD5bOBLR8OvR3cHJt1j?auth=g.0.eyJraWQiOiIyMzhiNTUxZmMyM2EyM2Y4M2E2ZTE3MmJjZTg0YmU3ZjgxMzAzMmM4IiwiYWxnIjoiUlMyNTYifQ.eyJpc3MiOiJuZXN0LXNlY3VyaXR5LWF1dGhwcm94eSIsInN1YiI6Im5lc3RfaWQ6bmVzdC1waG9lbml4LXByb2Q6MjEyMTgxNDEiLCJwb2wiOiIzcC1vYXV0aC1zY29wZS1BUElfU0RNX1NFUlZJQ0UtY2xpZW50LTIwMjQyNzMxODczNS1qNXQ5bWMyMzZqaG85YXMycWY0dTZxY3NmYW1kaGJ0ci5hcHBzLmdvb2dsZXVzZXJjb250ZW50LmNvbSIsImV4cCI6MTYzMDY2OTI2MH0.YX2iSC1fPGqRtTCTN9D8TMMNMy1I0eUhvL8JE1ArSRVM6sJvX5KtWcFwSWYS6_vpnk6UGRaBw9F2p10-Mpe8l0JJhEiD1p9MEJxp8X1YY8q8dcTGftb4TJ38kfwTS08TVm9l39XyllTCXn72iZ1yMdINj_UJVkvPDojEoOPyl4An8qf6ihGPDSyHw6vBsYhhV2FqQyWRFzYjlzhhPIdqwmi5mdNIEHwW8U_D3MdvxkB74x8FaaXNAaSp3E-AlUae0NupsHKMBYB-2iyWKpdI5Lziz2dHJeLDNvYqKEJ4nPJ33iMqlXT0H78UHgSOxuETZImmUcLB5DCYCDr7REbegw
2021-09-03 04:37:24 ERROR (MainThread) [homeassistant] Error doing job: Future exception was never retrieved
Traceback (most recent call last):
  File "/usr/local/lib/python3.9/concurrent/futures/thread.py", line 52, in run
    result = self.fn(*self.args, **self.kwargs)
TypeError: update() takes 1 positional argument but 2 were given
2021-09-03 04:38:38 ERROR (stream_worker) [libav.rtsp] method DESCRIBE failed: 404 Not Found
2021-09-03 04:38:38 ERROR (stream_worker) [homeassistant.components.stream.worker] Error opening stream rtsps://stream-uc2-bravo.dropcam.com:443/sdm_live_stream/CiQA2vuxr-LP01PGJcHMj2yZQZFZPWWB9gxlAEX36ndGpkLPgSgScQBQBG8tsduigF-pY7oW2muqz1xbBJ_UgxAwAW_-MMLZV12LJ73G-OLNVsOhEGUNMU6oubYsuvUqgXfX06GwD6bGvl7LUiEzXVBOkFMhd8hQ48NXaT0qjNpZHcrWyNl90m2gBjD5bOBLR8OvR3cHJt1j?auth=g.0.eyJraWQiOiIyMzhiNTUxZmMyM2EyM2Y4M2E2ZTE3MmJjZTg0YmU3ZjgxMzAzMmM4IiwiYWxnIjoiUlMyNTYifQ.eyJpc3MiOiJuZXN0LXNlY3VyaXR5LWF1dGhwcm94eSIsInN1YiI6Im5lc3RfaWQ6bmVzdC1waG9lbml4LXByb2Q6MjEyMTgxNDEiLCJwb2wiOiIzcC1vYXV0aC1zY29wZS1BUElfU0RNX1NFUlZJQ0UtY2xpZW50LTIwMjQyNzMxODczNS1qNXQ5bWMyMzZqaG85YXMycWY0dTZxY3NmYW1kaGJ0ci5hcHBzLmdvb2dsZXVzZXJjb250ZW50LmNvbSIsImV4cCI6MTYzMDY2OTI2MH0.YX2iSC1fPGqRtTCTN9D8TMMNMy1I0eUhvL8JE1ArSRVM6sJvX5KtWcFwSWYS6_vpnk6UGRaBw9F2p10-Mpe8l0JJhEiD1p9MEJxp8X1YY8q8dcTGftb4TJ38kfwTS08TVm9l39XyllTCXn72iZ1yMdINj_UJVkvPDojEoOPyl4An8qf6ihGPDSyHw6vBsYhhV2FqQyWRFzYjlzhhPIdqwmi5mdNIEHwW8U_D3MdvxkB74x8FaaXNAaSp3E-AlUae0NupsHKMBYB-2iyWKpdI5Lziz2dHJeLDNvYqKEJ4nPJ33iMqlXT0H78UHgSOxuETZImmUcLB5DCYCDr7REbegw
2021-09-03 04:42:21 ERROR (stream_worker) [homeassistant.components.stream.worker] Error opening stream rtsps://stream-uc2-bravo.dropcam.com:443/sdm_live_stream/CiQA2vuxr-LP01PGJcHMj2yZQZFZPWWB9gxlAEX36ndGpkLPgSgScQBQBG8tsduigF-pY7oW2muqz1xbBJ_UgxAwAW_-MMLZV12LJ73G-OLNVsOhEGUNMU6oubYsuvUqgXfX06GwD6bGvl7LUiEzXVBOkFMhd8hQ48NXaT0qjNpZHcrWyNl90m2gBjD5bOBLR8OvR3cHJt1j?auth=g.0.eyJraWQiOiIyMzhiNTUxZmMyM2EyM2Y4M2E2ZTE3MmJjZTg0YmU3ZjgxMzAzMmM4IiwiYWxnIjoiUlMyNTYifQ.eyJpc3MiOiJuZXN0LXNlY3VyaXR5LWF1dGhwcm94eSIsInN1YiI6Im5lc3RfaWQ6bmVzdC1waG9lbml4LXByb2Q6MjEyMTgxNDEiLCJwb2wiOiIzcC1vYXV0aC1zY29wZS1BUElfU0RNX1NFUlZJQ0UtY2xpZW50LTIwMjQyNzMxODczNS1qNXQ5bWMyMzZqaG85YXMycWY0dTZxY3NmYW1kaGJ0ci5hcHBzLmdvb2dsZXVzZXJjb250ZW50LmNvbSIsImV4cCI6MTYzMDY2OTUzMH0.Mv1YBGgzAwRuhqyOT4uujXXMrbCWzywuxFUElmyTCyN6f4lRYe3W-s2jqCX26mtWNMCuLCpBwEHTA3v0CPWcXjjSOwFXd7WbBjJ0vw2d6_Nf_qyqJ9sE8s0vxnVBNKf9zgw8pAuimPCM9lfcdiwQiFzNAX6Xo7zM6yP7_zA50k9ocv-5_hb6t1wHxpfn5whHcQZm15YDoYEH03Zqi1EzaDH7-d6L0gu2F4CLxKawOrZjghH6919PqxmKr-dgHa76_Kt29BLdZCpISYckbGNIZ1H2H4oCJsx-amcSpqtrUWCXpb8GXzNXYoPEVNRNw26LOMz-agPcoEyGWIAZMAuNdA
2021-09-03 04:42:25 ERROR (MainThread) [homeassistant] Error doing job: Future exception was never retrieved
Traceback (most recent call last):
  File "/usr/local/lib/python3.9/concurrent/futures/thread.py", line 52, in run
    result = self.fn(*self.args, **self.kwargs)
TypeError: update() takes 1 positional argument but 2 were given
2021-09-03 04:44:02 ERROR (stream_worker) [libav.rtsp] method DESCRIBE failed: 404 Not Found
2021-09-03 04:44:02 ERROR (stream_worker) [homeassistant.components.stream.worker] Error opening stream rtsps://stream-uc2-bravo.dropcam.com:443/sdm_live_stream/CiQA2vuxr-LP01PGJcHMj2yZQZFZPWWB9gxlAEX36ndGpkLPgSgScQBQBG8tsduigF-pY7oW2muqz1xbBJ_UgxAwAW_-MMLZV12LJ73G-OLNVsOhEGUNMU6oubYsuvUqgXfX06GwD6bGvl7LUiEzXVBOkFMhd8hQ48NXaT0qjNpZHcrWyNl90m2gBjD5bOBLR8OvR3cHJt1j?auth=g.0.eyJraWQiOiIyMzhiNTUxZmMyM2EyM2Y4M2E2ZTE3MmJjZTg0YmU3ZjgxMzAzMmM4IiwiYWxnIjoiUlMyNTYifQ.eyJpc3MiOiJuZXN0LXNlY3VyaXR5LWF1dGhwcm94eSIsInN1YiI6Im5lc3RfaWQ6bmVzdC1waG9lbml4LXByb2Q6MjEyMTgxNDEiLCJwb2wiOiIzcC1vYXV0aC1zY29wZS1BUElfU0RNX1NFUlZJQ0UtY2xpZW50LTIwMjQyNzMxODczNS1qNXQ5bWMyMzZqaG85YXMycWY0dTZxY3NmYW1kaGJ0ci5hcHBzLmdvb2dsZXVzZXJjb250ZW50LmNvbSIsImV4cCI6MTYzMDY2OTUzMH0.Mv1YBGgzAwRuhqyOT4uujXXMrbCWzywuxFUElmyTCyN6f4lRYe3W-s2jqCX26mtWNMCuLCpBwEHTA3v0CPWcXjjSOwFXd7WbBjJ0vw2d6_Nf_qyqJ9sE8s0vxnVBNKf9zgw8pAuimPCM9lfcdiwQiFzNAX6Xo7zM6yP7_zA50k9ocv-5_hb6t1wHxpfn5whHcQZm15YDoYEH03Zqi1EzaDH7-d6L0gu2F4CLxKawOrZjghH6919PqxmKr-dgHa76_Kt29BLdZCpISYckbGNIZ1H2H4oCJsx-amcSpqtrUWCXpb8GXzNXYoPEVNRNw26LOMz-agPcoEyGWIAZMAuNdA
2021-09-03 04:47:26 ERROR (MainThread) [homeassistant] Error doing job: Future exception was never retrieved
Traceback (most recent call last):
  File "/usr/local/lib/python3.9/concurrent/futures/thread.py", line 52, in run
    result = self.fn(*self.args, **self.kwargs)
TypeError: update() takes 1 positional argument but 2 were given
2021-09-03 04:52:27 ERROR (MainThread) [homeassistant] Error doing job: Future exception was never retrieved
Traceback (most recent call last):
  File "/usr/local/lib/python3.9/concurrent/futures/thread.py", line 52, in run
    result = self.fn(*self.args, **self.kwargs)
TypeError: update() takes 1 positional argument but 2 were given
2021-09-03 04:57:28 ERROR (MainThread) [homeassistant] Error doing job: Future exception was never retrieved
Traceback (most recent call last):
  File "/usr/local/lib/python3.9/concurrent/futures/thread.py", line 52, in run
    result = self.fn(*self.args, **self.kwargs)
TypeError: update() takes 1 positional argument but 2 were given
2021-09-03 05:02:29 ERROR (MainThread) [homeassistant] Error doing job: Future exception was never retrieved
Traceback (most recent call last):
  File "/usr/local/lib/python3.9/concurrent/futures/thread.py", line 52, in run
    result = self.fn(*self.args, **self.kwargs)
TypeError: update() takes 1 positional argument but 2 were given
2021-09-03 05:07:30 ERROR (MainThread) [homeassistant] Error doing job: Future exception was never retrieved
Traceback (most recent call last):
  File "/usr/local/lib/python3.9/concurrent/futures/thread.py", line 52, in run
    result = self.fn(*self.args, **self.kwargs)
TypeError: update() takes 1 positional argument but 2 were given
2021-09-03 05:12:31 ERROR (MainThread) [homeassistant] Error doing job: Future exception was never retrieved
Traceback (most recent call last):
  File "/usr/local/lib/python3.9/concurrent/futures/thread.py", line 52, in run
    result = self.fn(*self.args, **self.kwargs)
TypeError: update() takes 1 positional argument but 2 were given
2021-09-03 05:17:32 ERROR (MainThread) [homeassistant] Error doing job: Future exception was never retrieved
Traceback (most recent call last):
  File "/usr/local/lib/python3.9/concurrent/futures/thread.py", line 52, in run
    result = self.fn(*self.args, **self.kwargs)
TypeError: update() takes 1 positional argument but 2 were given
2021-09-03 05:22:33 ERROR (MainThread) [homeassistant] Error doing job: Future exception was never retrieved
Traceback (most recent call last):
  File "/usr/local/lib/python3.9/concurrent/futures/thread.py", line 52, in run
    result = self.fn(*self.args, **self.kwargs)
TypeError: update() takes 1 positional argument but 2 were given
2021-09-03 05:27:34 ERROR (MainThread) [homeassistant] Error doing job: Future exception was never retrieved
Traceback (most recent call last):
  File "/usr/local/lib/python3.9/concurrent/futures/thread.py", line 52, in run
    result = self.fn(*self.args, **self.kwargs)
TypeError: update() takes 1 positional argument but 2 were given
2021-09-03 05:32:35 ERROR (MainThread) [homeassistant] Error doing job: Future exception was never retrieved
Traceback (most recent call last):
  File "/usr/local/lib/python3.9/concurrent/futures/thread.py", line 52, in run
    result = self.fn(*self.args, **self.kwargs)
TypeError: update() takes 1 positional argument but 2 were given
2021-09-03 05:34:49 ERROR (stream_worker) [homeassistant.components.stream.worker] Stream has no video
2021-09-03 05:35:11 ERROR (stream_worker) [libav.rtsp] method DESCRIBE failed: 404 Not Found
2021-09-03 05:35:11 ERROR (stream_worker) [homeassistant.components.stream.worker] Error opening stream rtsps://stream-uc2-delta.dropcam.com:443/sdm_live_stream/CiQA2vuxr6cbojJeifHgZXMjs5h47y1p9HklYimuklKRPudP28wScQBQBG8tCrSUglQ-TD8Xw2O1QZAfWSpPIjoWpFeNMXB0Snsv7397ntSB1zgckl3Kf-D5lMjabmgCOE73qdTKNHRX7SP5OJwets0z2HeNjmtrOonf8RDdu5DvUlec4p5ZqicB8pPZRpXnkFQPLs3_oT_H?auth=g.0.eyJraWQiOiIyMzhiNTUxZmMyM2EyM2Y4M2E2ZTE3MmJjZTg0YmU3ZjgxMzAzMmM4IiwiYWxnIjoiUlMyNTYifQ.eyJpc3MiOiJuZXN0LXNlY3VyaXR5LWF1dGhwcm94eSIsInN1YiI6Im5lc3RfaWQ6bmVzdC1waG9lbml4LXByb2Q6MjEyMTgxNDEiLCJwb2wiOiIzcC1vYXV0aC1zY29wZS1BUElfU0RNX1NFUlZJQ0UtY2xpZW50LTIwMjQyNzMxODczNS1qNXQ5bWMyMzZqaG85YXMycWY0dTZxY3NmYW1kaGJ0ci5hcHBzLmdvb2dsZXVzZXJjb250ZW50LmNvbSIsImV4cCI6MTYzMDY3Mjc3N30.NRjBlc5B6j1sF5SucduPmU6pYt72i7EAebZ38tVepeUR6XsptmrwRPnpl8aU8S8Hj1HZKUMq50OqxSTFsE0CJB_WuvzS22ULKwDPwk7MaFOlhj42J671OWxKu3h4NB65khnsYkT14n8jO8CnQRUb_c6_Vb8MQ2vKvvKvdRTPewQoVBRH2pP749456vVHRAyft-Ddw9pF6wQ3x7XdM_3EG7HYrkuqk7DsjbD76P4-9LV5vp41c7f4vG2LSJTFpKE3v2Fr8X9qij4--B8-cgnb1x-KbjHNMbLuft1j-pQkbvHDCHKfCWbIBRxEY8-Dm7HxmYFtlpxPocrTuL2eIw-hIg
2021-09-03 05:37:36 ERROR (MainThread) [homeassistant] Error doing job: Future exception was never retrieved
Traceback (most recent call last):
  File "/usr/local/lib/python3.9/concurrent/futures/thread.py", line 52, in run
    result = self.fn(*self.args, **self.kwargs)
TypeError: update() takes 1 positional argument but 2 were given
2021-09-03 05:42:37 ERROR (MainThread) [homeassistant] Error doing job: Future exception was never retrieved
Traceback (most recent call last):
  File "/usr/local/lib/python3.9/concurrent/futures/thread.py", line 52, in run
    result = self.fn(*self.args, **self.kwargs)
TypeError: update() takes 1 positional argument but 2 were given
2021-09-03 05:44:12 ERROR (stream_worker) [homeassistant.components.stream.worker] Stream has no video
2021-09-03 05:44:57 ERROR (stream_worker) [libav.rtsp] method DESCRIBE failed: 404 Not Found
2021-09-03 05:44:57 ERROR (stream_worker) [homeassistant.components.stream.worker] Error opening stream rtsps://stream-uc2-delta.dropcam.com:443/sdm_live_stream/CiQA2vuxr6cbojJeifHgZXMjs5h47y1p9HklYimuklKRPudP28wScQBQBG8tCrSUglQ-TD8Xw2O1QZAfWSpPIjoWpFeNMXB0Snsv7397ntSB1zgckl3Kf-D5lMjabmgCOE73qdTKNHRX7SP5OJwets0z2HeNjmtrOonf8RDdu5DvUlec4p5ZqicB8pPZRpXnkFQPLs3_oT_H?auth=g.0.eyJraWQiOiIyMzhiNTUxZmMyM2EyM2Y4M2E2ZTE3MmJjZTg0YmU3ZjgxMzAzMmM4IiwiYWxnIjoiUlMyNTYifQ.eyJpc3MiOiJuZXN0LXNlY3VyaXR5LWF1dGhwcm94eSIsInN1YiI6Im5lc3RfaWQ6bmVzdC1waG9lbml4LXByb2Q6MjEyMTgxNDEiLCJwb2wiOiIzcC1vYXV0aC1zY29wZS1BUElfU0RNX1NFUlZJQ0UtY2xpZW50LTIwMjQyNzMxODczNS1qNXQ5bWMyMzZqaG85YXMycWY0dTZxY3NmYW1kaGJ0ci5hcHBzLmdvb2dsZXVzZXJjb250ZW50LmNvbSIsImV4cCI6MTYzMDY3MzMxOH0.qT2ZtXanfCOW8dhw5DJ4xHiRi3TGFt93nPKgNYVxvkLsvB_XGpyOzCootwZ3aVteinpVngHVwjlgk2vM240mq7GUWTh83LJe-sNuN4hS8J-6_L56Sq_63juTkvaIebwkruyOV8N1AdalqjXrfBbBPkKj5xMjTKqOucEaQlSUkLd288j2QgI8zG7gsBqieA0pAKWZxkZnE8Sdb1bfbJOoRDQKwzIlvM-Q_yciAS24SWfnI7CvHu_Xinr840H2NSjnJ9T_B8w54a35qlbqTqW6s3giBNwZJrJ4mhW_7faTlcsLxcagBm4u--HsTLHokdXC50_H7OR5o7mLDZpnZ5NOlw
2021-09-03 05:47:38 ERROR (MainThread) [homeassistant] Error doing job: Future exception was never retrieved
Traceback (most recent call last):
  File "/usr/local/lib/python3.9/concurrent/futures/thread.py", line 52, in run
    result = self.fn(*self.args, **self.kwargs)
TypeError: update() takes 1 positional argument but 2 were given
2021-09-03 05:49:20 ERROR (stream_worker) [homeassistant.components.stream.worker] Error opening stream rtsps://stream-uc2-delta.dropcam.com:443/sdm_live_stream/CiQA2vuxr6cbojJeifHgZXMjs5h47y1p9HklYimuklKRPudP28wScQBQBG8tCrSUglQ-TD8Xw2O1QZAfWSpPIjoWpFeNMXB0Snsv7397ntSB1zgckl3Kf-D5lMjabmgCOE73qdTKNHRX7SP5OJwets0z2HeNjmtrOonf8RDdu5DvUlec4p5ZqicB8pPZRpXnkFQPLs3_oT_H?auth=g.0.eyJraWQiOiIyMzhiNTUxZmMyM2EyM2Y4M2E2ZTE3MmJjZTg0YmU3ZjgxMzAzMmM4IiwiYWxnIjoiUlMyNTYifQ.eyJpc3MiOiJuZXN0LXNlY3VyaXR5LWF1dGhwcm94eSIsInN1YiI6Im5lc3RfaWQ6bmVzdC1waG9lbml4LXByb2Q6MjEyMTgxNDEiLCJwb2wiOiIzcC1vYXV0aC1zY29wZS1BUElfU0RNX1NFUlZJQ0UtY2xpZW50LTIwMjQyNzMxODczNS1qNXQ5bWMyMzZqaG85YXMycWY0dTZxY3NmYW1kaGJ0ci5hcHBzLmdvb2dsZXVzZXJjb250ZW50LmNvbSIsImV4cCI6MTYzMDY3MzU4OX0.W19iWdZiQhQuNgG7KAGxeA0vsYcT9EaWTo-9vEIWI-i4RDeKAC38D5gJEMl-Sm2tFIhmrkUi8Nj2KEqUJa6ICghzHltrAp--pjEi6HU37y6Q89SJKBFzlaPjuur-Lw8Tt8nNoVcj_dW5Je_RNie2PCRBux2eUx3J8CDQCaulWxszbdEq8yim5MWvtYfE5vkco_UwL-pXzBtNMncKKVgBIwg1fVBsW-JGE3klYOx4QSjlW_hj5ht3tj-hsJwaT32Y86KUcmjSZLWRi9bpMimO0s-_fgX1Lht-nK-OM5vnsWNLWzVlT6XdocK2m5ofZz2Xd-dl_WfvyTsXHbPjWKupxQ
2021-09-03 05:50:40 ERROR (stream_worker) [homeassistant.components.stream.worker] Error opening stream rtsps://stream-uc2-delta.dropcam.com:443/sdm_live_stream/CiQA2vuxr6cbojJeifHgZXMjs5h47y1p9HklYimuklKRPudP28wScQBQBG8tCrSUglQ-TD8Xw2O1QZAfWSpPIjoWpFeNMXB0Snsv7397ntSB1zgckl3Kf-D5lMjabmgCOE73qdTKNHRX7SP5OJwets0z2HeNjmtrOonf8RDdu5DvUlec4p5ZqicB8pPZRpXnkFQPLs3_oT_H?auth=g.0.eyJraWQiOiIyMzhiNTUxZmMyM2EyM2Y4M2E2ZTE3MmJjZTg0YmU3ZjgxMzAzMmM4IiwiYWxnIjoiUlMyNTYifQ.eyJpc3MiOiJuZXN0LXNlY3VyaXR5LWF1dGhwcm94eSIsInN1YiI6Im5lc3RfaWQ6bmVzdC1waG9lbml4LXByb2Q6MjEyMTgxNDEiLCJwb2wiOiIzcC1vYXV0aC1zY29wZS1BUElfU0RNX1NFUlZJQ0UtY2xpZW50LTIwMjQyNzMxODczNS1qNXQ5bWMyMzZqaG85YXMycWY0dTZxY3NmYW1kaGJ0ci5hcHBzLmdvb2dsZXVzZXJjb250ZW50LmNvbSIsImV4cCI6MTYzMDY3MzU4OX0.W19iWdZiQhQuNgG7KAGxeA0vsYcT9EaWTo-9vEIWI-i4RDeKAC38D5gJEMl-Sm2tFIhmrkUi8Nj2KEqUJa6ICghzHltrAp--pjEi6HU37y6Q89SJKBFzlaPjuur-Lw8Tt8nNoVcj_dW5Je_RNie2PCRBux2eUx3J8CDQCaulWxszbdEq8yim5MWvtYfE5vkco_UwL-pXzBtNMncKKVgBIwg1fVBsW-JGE3klYOx4QSjlW_hj5ht3tj-hsJwaT32Y86KUcmjSZLWRi9bpMimO0s-_fgX1Lht-nK-OM5vnsWNLWzVlT6XdocK2m5ofZz2Xd-dl_WfvyTsXHbPjWKupxQ
2021-09-03 05:51:51 ERROR (stream_worker) [libav.rtsp] method DESCRIBE failed: 404 Not Found
2021-09-03 05:51:51 ERROR (stream_worker) [homeassistant.components.stream.worker] Error opening stream rtsps://stream-uc2-delta.dropcam.com:443/sdm_live_stream/CiQA2vuxr6cbojJeifHgZXMjs5h47y1p9HklYimuklKRPudP28wScQBQBG8tCrSUglQ-TD8Xw2O1QZAfWSpPIjoWpFeNMXB0Snsv7397ntSB1zgckl3Kf-D5lMjabmgCOE73qdTKNHRX7SP5OJwets0z2HeNjmtrOonf8RDdu5DvUlec4p5ZqicB8pPZRpXnkFQPLs3_oT_H?auth=g.0.eyJraWQiOiIyMzhiNTUxZmMyM2EyM2Y4M2E2ZTE3MmJjZTg0YmU3ZjgxMzAzMmM4IiwiYWxnIjoiUlMyNTYifQ.eyJpc3MiOiJuZXN0LXNlY3VyaXR5LWF1dGhwcm94eSIsInN1YiI6Im5lc3RfaWQ6bmVzdC1waG9lbml4LXByb2Q6MjEyMTgxNDEiLCJwb2wiOiIzcC1vYXV0aC1zY29wZS1BUElfU0RNX1NFUlZJQ0UtY2xpZW50LTIwMjQyNzMxODczNS1qNXQ5bWMyMzZqaG85YXMycWY0dTZxY3NmYW1kaGJ0ci5hcHBzLmdvb2dsZXVzZXJjb250ZW50LmNvbSIsImV4cCI6MTYzMDY3MzU4OX0.W19iWdZiQhQuNgG7KAGxeA0vsYcT9EaWTo-9vEIWI-i4RDeKAC38D5gJEMl-Sm2tFIhmrkUi8Nj2KEqUJa6ICghzHltrAp--pjEi6HU37y6Q89SJKBFzlaPjuur-Lw8Tt8nNoVcj_dW5Je_RNie2PCRBux2eUx3J8CDQCaulWxszbdEq8yim5MWvtYfE5vkco_UwL-pXzBtNMncKKVgBIwg1fVBsW-JGE3klYOx4QSjlW_hj5ht3tj-hsJwaT32Y86KUcmjSZLWRi9bpMimO0s-_fgX1Lht-nK-OM5vnsWNLWzVlT6XdocK2m5ofZz2Xd-dl_WfvyTsXHbPjWKupxQ
2021-09-03 05:52:39 ERROR (MainThread) [homeassistant] Error doing job: Future exception was never retrieved
Traceback (most recent call last):
  File "/usr/local/lib/python3.9/concurrent/futures/thread.py", line 52, in run
    result = self.fn(*self.args, **self.kwargs)
TypeError: update() takes 1 positional argument but 2 were given
2021-09-03 05:57:40 ERROR (MainThread) [homeassistant] Error doing job: Future exception was never retrieved
Traceback (most recent call last):
  File "/usr/local/lib/python3.9/concurrent/futures/thread.py", line 52, in run
    result = self.fn(*self.args, **self.kwargs)
TypeError: update() takes 1 positional argument but 2 were given
2021-09-03 06:02:41 ERROR (MainThread) [homeassistant] Error doing job: Future exception was never retrieved
Traceback (most recent call last):
  File "/usr/local/lib/python3.9/concurrent/futures/thread.py", line 52, in run
    result = self.fn(*self.args, **self.kwargs)
TypeError: update() takes 1 positional argument but 2 were given
2021-09-03 06:07:42 ERROR (MainThread) [homeassistant] Error doing job: Future exception was never retrieved
Traceback (most recent call last):
  File "/usr/local/lib/python3.9/concurrent/futures/thread.py", line 52, in run
    result = self.fn(*self.args, **self.kwargs)
TypeError: update() takes 1 positional argument but 2 were given
2021-09-03 06:08:11 ERROR (MainThread) [homeassistant.components.nws] Error requesting NWS observation station SAUC1 data: 503, message='Service Unavailable', url=URL('https://api.weather.gov/stations/SAUC1/observations')
2021-09-03 06:12:00 WARNING (Recorder) [homeassistant.components.sensor.recorder] Entity sensor.solar_energy from integration integration has state class total_increasing, but its state is not strictly increasing. Please create a bug report at https://github.com/home-assistant/core/issues?q=is%3Aopen+is%3Aissue+label%3A%22integration%3A+recorder%22
2021-09-03 06:12:43 ERROR (MainThread) [homeassistant] Error doing job: Future exception was never retrieved
Traceback (most recent call last):
  File "/usr/local/lib/python3.9/concurrent/futures/thread.py", line 52, in run
    result = self.fn(*self.args, **self.kwargs)
TypeError: update() takes 1 positional argument but 2 were given
2021-09-03 06:17:44 ERROR (MainThread) [homeassistant] Error doing job: Future exception was never retrieved
Traceback (most recent call last):
  File "/usr/local/lib/python3.9/concurrent/futures/thread.py", line 52, in run
    result = self.fn(*self.args, **self.kwargs)
TypeError: update() takes 1 positional argument but 2 were given
2021-09-03 06:22:45 ERROR (MainThread) [homeassistant] Error doing job: Future exception was never retrieved
Traceback (most recent call last):
  File "/usr/local/lib/python3.9/concurrent/futures/thread.py", line 52, in run
    result = self.fn(*self.args, **self.kwargs)
TypeError: update() takes 1 positional argument but 2 were given
2021-09-03 06:27:46 ERROR (MainThread) [homeassistant] Error doing job: Future exception was never retrieved
Traceback (most recent call last):
  File "/usr/local/lib/python3.9/concurrent/futures/thread.py", line 52, in run
    result = self.fn(*self.args, **self.kwargs)
TypeError: update() takes 1 positional argument but 2 were given
2021-09-03 06:29:21 WARNING (MainThread) [homeassistant.helpers.service] Unable to find referenced entities scene.kitchen_sink_off
2021-09-03 06:32:15 ERROR (MainThread) [homeassistant.components.template.template_entity] TemplateError('UndefinedError: list object has no element 4') while processing template 'Template("{% if states.sensor.iss_pass_times %}{{ states.sensor.iss_pass_times.attributes["response"][4]["risetime"] | timestamp_custom("%a %d %b %Y %H:%M:%S") }}{% endif %}")' for attribute '_attr_native_value' in entity 'sensor.iss_risetime_4'
2021-09-03 06:32:15 ERROR (MainThread) [homeassistant.components.template.template_entity] TemplateError('UndefinedError: list object has no element 4') while processing template 'Template("{% if states.sensor.iss_pass_times %}{{ states.sensor.iss_pass_times.attributes["response"][4]["duration"] }}{% endif %}")' for attribute '_attr_native_value' in entity 'sensor.iss_duration_4'
2021-09-03 06:32:47 ERROR (MainThread) [homeassistant] Error doing job: Future exception was never retrieved
Traceback (most recent call last):
  File "/usr/local/lib/python3.9/concurrent/futures/thread.py", line 52, in run
    result = self.fn(*self.args, **self.kwargs)
TypeError: update() takes 1 positional argument but 2 were given
2021-09-03 06:37:48 ERROR (MainThread) [homeassistant] Error doing job: Future exception was never retrieved
Traceback (most recent call last):
  File "/usr/local/lib/python3.9/concurrent/futures/thread.py", line 52, in run
    result = self.fn(*self.args, **self.kwargs)
TypeError: update() takes 1 positional argument but 2 were given
2021-09-03 06:42:49 ERROR (MainThread) [homeassistant] Error doing job: Future exception was never retrieved
Traceback (most recent call last):
  File "/usr/local/lib/python3.9/concurrent/futures/thread.py", line 52, in run
    result = self.fn(*self.args, **self.kwargs)
TypeError: update() takes 1 positional argument but 2 were given
2021-09-03 06:47:50 ERROR (MainThread) [homeassistant] Error doing job: Future exception was never retrieved
Traceback (most recent call last):
  File "/usr/local/lib/python3.9/concurrent/futures/thread.py", line 52, in run
    result = self.fn(*self.args, **self.kwargs)
TypeError: update() takes 1 positional argument but 2 were given
2021-09-03 06:52:51 ERROR (MainThread) [homeassistant] Error doing job: Future exception was never retrieved
Traceback (most recent call last):
  File "/usr/local/lib/python3.9/concurrent/futures/thread.py", line 52, in run
    result = self.fn(*self.args, **self.kwargs)
TypeError: update() takes 1 positional argument but 2 were given
2021-09-03 06:57:52 ERROR (MainThread) [homeassistant] Error doing job: Future exception was never retrieved
Traceback (most recent call last):
  File "/usr/local/lib/python3.9/concurrent/futures/thread.py", line 52, in run
    result = self.fn(*self.args, **self.kwargs)
TypeError: update() takes 1 positional argument but 2 were given
2021-09-03 07:02:53 ERROR (MainThread) [homeassistant] Error doing job: Future exception was never retrieved
Traceback (most recent call last):
  File "/usr/local/lib/python3.9/concurrent/futures/thread.py", line 52, in run
    result = self.fn(*self.args, **self.kwargs)
TypeError: update() takes 1 positional argument but 2 were given
2021-09-03 07:07:54 ERROR (MainThread) [homeassistant] Error doing job: Future exception was never retrieved
Traceback (most recent call last):
  File "/usr/local/lib/python3.9/concurrent/futures/thread.py", line 52, in run
    result = self.fn(*self.args, **self.kwargs)
TypeError: update() takes 1 positional argument but 2 were given
2021-09-03 07:12:55 ERROR (MainThread) [homeassistant] Error doing job: Future exception was never retrieved
Traceback (most recent call last):
  File "/usr/local/lib/python3.9/concurrent/futures/thread.py", line 52, in run
    result = self.fn(*self.args, **self.kwargs)
TypeError: update() takes 1 positional argument but 2 were given
2021-09-03 07:17:56 ERROR (MainThread) [homeassistant] Error doing job: Future exception was never retrieved
Traceback (most recent call last):
  File "/usr/local/lib/python3.9/concurrent/futures/thread.py", line 52, in run
    result = self.fn(*self.args, **self.kwargs)
TypeError: update() takes 1 positional argument but 2 were given
2021-09-03 07:22:57 ERROR (MainThread) [homeassistant] Error doing job: Future exception was never retrieved
Traceback (most recent call last):
  File "/usr/local/lib/python3.9/concurrent/futures/thread.py", line 52, in run
    result = self.fn(*self.args, **self.kwargs)
TypeError: update() takes 1 positional argument but 2 were given
2021-09-03 07:27:58 ERROR (MainThread) [homeassistant] Error doing job: Future exception was never retrieved
Traceback (most recent call last):
  File "/usr/local/lib/python3.9/concurrent/futures/thread.py", line 52, in run
    result = self.fn(*self.args, **self.kwargs)
TypeError: update() takes 1 positional argument but 2 were given
2021-09-03 07:32:59 ERROR (MainThread) [homeassistant] Error doing job: Future exception was never retrieved
Traceback (most recent call last):
  File "/usr/local/lib/python3.9/concurrent/futures/thread.py", line 52, in run
    result = self.fn(*self.args, **self.kwargs)
TypeError: update() takes 1 positional argument but 2 were given
2021-09-03 07:38:00 ERROR (MainThread) [homeassistant] Error doing job: Future exception was never retrieved
Traceback (most recent call last):
  File "/usr/local/lib/python3.9/concurrent/futures/thread.py", line 52, in run
    result = self.fn(*self.args, **self.kwargs)
TypeError: update() takes 1 positional argument but 2 were given
2021-09-03 07:43:01 ERROR (MainThread) [homeassistant] Error doing job: Future exception was never retrieved
Traceback (most recent call last):
  File "/usr/local/lib/python3.9/concurrent/futures/thread.py", line 52, in run
    result = self.fn(*self.args, **self.kwargs)
TypeError: update() takes 1 positional argument but 2 were given
2021-09-03 07:48:02 ERROR (MainThread) [homeassistant] Error doing job: Future exception was never retrieved
Traceback (most recent call last):
  File "/usr/local/lib/python3.9/concurrent/futures/thread.py", line 52, in run
    result = self.fn(*self.args, **self.kwargs)
TypeError: update() takes 1 positional argument but 2 were given
2021-09-03 07:53:03 ERROR (MainThread) [homeassistant] Error doing job: Future exception was never retrieved
Traceback (most recent call last):
  File "/usr/local/lib/python3.9/concurrent/futures/thread.py", line 52, in run
    result = self.fn(*self.args, **self.kwargs)
TypeError: update() takes 1 positional argument but 2 were given
2021-09-03 07:58:04 ERROR (MainThread) [homeassistant] Error doing job: Future exception was never retrieved
Traceback (most recent call last):
  File "/usr/local/lib/python3.9/concurrent/futures/thread.py", line 52, in run
    result = self.fn(*self.args, **self.kwargs)
TypeError: update() takes 1 positional argument but 2 were given
2021-09-03 08:03:05 ERROR (MainThread) [homeassistant] Error doing job: Future exception was never retrieved
Traceback (most recent call last):
  File "/usr/local/lib/python3.9/concurrent/futures/thread.py", line 52, in run
    result = self.fn(*self.args, **self.kwargs)
TypeError: update() takes 1 positional argument but 2 were given
2021-09-03 08:08:06 ERROR (MainThread) [homeassistant] Error doing job: Future exception was never retrieved
Traceback (most recent call last):
  File "/usr/local/lib/python3.9/concurrent/futures/thread.py", line 52, in run
    result = self.fn(*self.args, **self.kwargs)
TypeError: update() takes 1 positional argument but 2 were given
2021-09-03 08:13:07 ERROR (MainThread) [homeassistant] Error doing job: Future exception was never retrieved
Traceback (most recent call last):
  File "/usr/local/lib/python3.9/concurrent/futures/thread.py", line 52, in run
    result = self.fn(*self.args, **self.kwargs)
TypeError: update() takes 1 positional argument but 2 were given
2021-09-03 08:18:08 ERROR (MainThread) [homeassistant] Error doing job: Future exception was never retrieved
Traceback (most recent call last):
  File "/usr/local/lib/python3.9/concurrent/futures/thread.py", line 52, in run
    result = self.fn(*self.args, **self.kwargs)
TypeError: update() takes 1 positional argument but 2 were given
2021-09-03 08:23:09 ERROR (MainThread) [homeassistant] Error doing job: Future exception was never retrieved
Traceback (most recent call last):
  File "/usr/local/lib/python3.9/concurrent/futures/thread.py", line 52, in run
    result = self.fn(*self.args, **self.kwargs)
TypeError: update() takes 1 positional argument but 2 were given
2021-09-03 08:28:10 ERROR (MainThread) [homeassistant] Error doing job: Future exception was never retrieved
Traceback (most recent call last):
  File "/usr/local/lib/python3.9/concurrent/futures/thread.py", line 52, in run
    result = self.fn(*self.args, **self.kwargs)
TypeError: update() takes 1 positional argument but 2 were given
2021-09-03 08:33:11 ERROR (MainThread) [homeassistant] Error doing job: Future exception was never retrieved
Traceback (most recent call last):
  File "/usr/local/lib/python3.9/concurrent/futures/thread.py", line 52, in run
    result = self.fn(*self.args, **self.kwargs)
TypeError: update() takes 1 positional argument but 2 were given
2021-09-03 08:38:12 ERROR (MainThread) [homeassistant] Error doing job: Future exception was never retrieved
Traceback (most recent call last):
  File "/usr/local/lib/python3.9/concurrent/futures/thread.py", line 52, in run
    result = self.fn(*self.args, **self.kwargs)
TypeError: update() takes 1 positional argument but 2 were given
2021-09-03 08:43:13 ERROR (MainThread) [homeassistant] Error doing job: Future exception was never retrieved
Traceback (most recent call last):
  File "/usr/local/lib/python3.9/concurrent/futures/thread.py", line 52, in run
    result = self.fn(*self.args, **self.kwargs)
TypeError: update() takes 1 positional argument but 2 were given
2021-09-03 08:48:14 ERROR (MainThread) [homeassistant] Error doing job: Future exception was never retrieved
Traceback (most recent call last):
  File "/usr/local/lib/python3.9/concurrent/futures/thread.py", line 52, in run
    result = self.fn(*self.args, **self.kwargs)
TypeError: update() takes 1 positional argument but 2 were given
2021-09-03 08:53:15 ERROR (MainThread) [homeassistant] Error doing job: Future exception was never retrieved
Traceback (most recent call last):
  File "/usr/local/lib/python3.9/concurrent/futures/thread.py", line 52, in run
    result = self.fn(*self.args, **self.kwargs)
TypeError: update() takes 1 positional argument but 2 were given
2021-09-03 08:58:16 ERROR (MainThread) [homeassistant] Error doing job: Future exception was never retrieved
Traceback (most recent call last):
  File "/usr/local/lib/python3.9/concurrent/futures/thread.py", line 52, in run
    result = self.fn(*self.args, **self.kwargs)
TypeError: update() takes 1 positional argument but 2 were given
2021-09-03 09:03:17 ERROR (MainThread) [homeassistant] Error doing job: Future exception was never retrieved
Traceback (most recent call last):
  File "/usr/local/lib/python3.9/concurrent/futures/thread.py", line 52, in run
    result = self.fn(*self.args, **self.kwargs)
TypeError: update() takes 1 positional argument but 2 were given
2021-09-03 09:08:18 ERROR (MainThread) [homeassistant] Error doing job: Future exception was never retrieved
Traceback (most recent call last):
  File "/usr/local/lib/python3.9/concurrent/futures/thread.py", line 52, in run
    result = self.fn(*self.args, **self.kwargs)
TypeError: update() takes 1 positional argument but 2 were given
2021-09-03 09:13:19 ERROR (MainThread) [homeassistant] Error doing job: Future exception was never retrieved
Traceback (most recent call last):
  File "/usr/local/lib/python3.9/concurrent/futures/thread.py", line 52, in run
    result = self.fn(*self.args, **self.kwargs)
TypeError: update() takes 1 positional argument but 2 were given
2021-09-03 09:18:20 ERROR (MainThread) [homeassistant] Error doing job: Future exception was never retrieved
Traceback (most recent call last):
  File "/usr/local/lib/python3.9/concurrent/futures/thread.py", line 52, in run
    result = self.fn(*self.args, **self.kwargs)
TypeError: update() takes 1 positional argument but 2 were given
2021-09-03 09:23:21 ERROR (MainThread) [homeassistant] Error doing job: Future exception was never retrieved
Traceback (most recent call last):
  File "/usr/local/lib/python3.9/concurrent/futures/thread.py", line 52, in run
    result = self.fn(*self.args, **self.kwargs)
TypeError: update() takes 1 positional argument but 2 were given
2021-09-03 09:28:22 ERROR (MainThread) [homeassistant] Error doing job: Future exception was never retrieved
Traceback (most recent call last):
  File "/usr/local/lib/python3.9/concurrent/futures/thread.py", line 52, in run
    result = self.fn(*self.args, **self.kwargs)
TypeError: update() takes 1 positional argument but 2 were given
2021-09-03 09:33:23 ERROR (MainThread) [homeassistant] Error doing job: Future exception was never retrieved
Traceback (most recent call last):
  File "/usr/local/lib/python3.9/concurrent/futures/thread.py", line 52, in run
    result = self.fn(*self.args, **self.kwargs)
TypeError: update() takes 1 positional argument but 2 were given
2021-09-03 09:38:24 ERROR (MainThread) [homeassistant] Error doing job: Future exception was never retrieved
Traceback (most recent call last):
  File "/usr/local/lib/python3.9/concurrent/futures/thread.py", line 52, in run
    result = self.fn(*self.args, **self.kwargs)
TypeError: update() takes 1 positional argument but 2 were given
2021-09-03 09:43:25 ERROR (MainThread) [homeassistant] Error doing job: Future exception was never retrieved
Traceback (most recent call last):
  File "/usr/local/lib/python3.9/concurrent/futures/thread.py", line 52, in run
    result = self.fn(*self.args, **self.kwargs)
TypeError: update() takes 1 positional argument but 2 were given
2021-09-03 09:47:15 ERROR (MainThread) [homeassistant.components.template.template_entity] TemplateError('UndefinedError: list object has no element 4') while processing template 'Template("{% if states.sensor.iss_pass_times %}{{ states.sensor.iss_pass_times.attributes["response"][4]["risetime"] | timestamp_custom("%a %d %b %Y %H:%M:%S") }}{% endif %}")' for attribute '_attr_native_value' in entity 'sensor.iss_risetime_4'
2021-09-03 09:47:15 ERROR (MainThread) [homeassistant.components.template.template_entity] TemplateError('UndefinedError: list object has no element 4') while processing template 'Template("{% if states.sensor.iss_pass_times %}{{ states.sensor.iss_pass_times.attributes["response"][4]["duration"] }}{% endif %}")' for attribute '_attr_native_value' in entity 'sensor.iss_duration_4'
2021-09-03 09:48:26 ERROR (MainThread) [homeassistant] Error doing job: Future exception was never retrieved
Traceback (most recent call last):
  File "/usr/local/lib/python3.9/concurrent/futures/thread.py", line 52, in run
    result = self.fn(*self.args, **self.kwargs)
TypeError: update() takes 1 positional argument but 2 were given
2021-09-03 09:53:27 ERROR (MainThread) [homeassistant] Error doing job: Future exception was never retrieved
Traceback (most recent call last):
  File "/usr/local/lib/python3.9/concurrent/futures/thread.py", line 52, in run
    result = self.fn(*self.args, **self.kwargs)
TypeError: update() takes 1 positional argument but 2 were given
2021-09-03 09:58:28 ERROR (MainThread) [homeassistant] Error doing job: Future exception was never retrieved
Traceback (most recent call last):
  File "/usr/local/lib/python3.9/concurrent/futures/thread.py", line 52, in run
    result = self.fn(*self.args, **self.kwargs)
TypeError: update() takes 1 positional argument but 2 were given
2021-09-03 10:01:11 ERROR (MainThread) [homeassistant.components.nws] Error requesting NWS observation station SAUC1 data: 503, message='Service Unavailable', url=URL('https://api.weather.gov/stations/SAUC1/observations')
2021-09-03 10:03:29 ERROR (MainThread) [homeassistant] Error doing job: Future exception was never retrieved
Traceback (most recent call last):
  File "/usr/local/lib/python3.9/concurrent/futures/thread.py", line 52, in run
    result = self.fn(*self.args, **self.kwargs)
TypeError: update() takes 1 positional argument but 2 were given
2021-09-03 10:08:30 ERROR (MainThread) [homeassistant] Error doing job: Future exception was never retrieved
Traceback (most recent call last):
  File "/usr/local/lib/python3.9/concurrent/futures/thread.py", line 52, in run
    result = self.fn(*self.args, **self.kwargs)
TypeError: update() takes 1 positional argument but 2 were given
2021-09-03 10:12:21 ERROR (MainThread) [homeassistant.components.nws] Error requesting NWS observation station SAUC1 data: 503, message='Service Unavailable', url=URL('https://api.weather.gov/stations/SAUC1/observations')
2021-09-03 10:13:31 ERROR (MainThread) [homeassistant] Error doing job: Future exception was never retrieved
Traceback (most recent call last):
  File "/usr/local/lib/python3.9/concurrent/futures/thread.py", line 52, in run
    result = self.fn(*self.args, **self.kwargs)
TypeError: update() takes 1 positional argument but 2 were given
2021-09-03 10:17:42 WARNING (MainThread) [haffmpeg.tools] Timeout reading image.
2021-09-03 10:18:32 ERROR (MainThread) [homeassistant] Error doing job: Future exception was never retrieved
Traceback (most recent call last):
  File "/usr/local/lib/python3.9/concurrent/futures/thread.py", line 52, in run
    result = self.fn(*self.args, **self.kwargs)
TypeError: update() takes 1 positional argument but 2 were given
2021-09-03 10:23:33 ERROR (MainThread) [homeassistant] Error doing job: Future exception was never retrieved
Traceback (most recent call last):
  File "/usr/local/lib/python3.9/concurrent/futures/thread.py", line 52, in run
    result = self.fn(*self.args, **self.kwargs)
TypeError: update() takes 1 positional argument but 2 were given
2021-09-03 10:28:34 ERROR (MainThread) [homeassistant] Error doing job: Future exception was never retrieved
Traceback (most recent call last):
  File "/usr/local/lib/python3.9/concurrent/futures/thread.py", line 52, in run
    result = self.fn(*self.args, **self.kwargs)
TypeError: update() takes 1 positional argument but 2 were given
2021-09-03 10:33:35 ERROR (MainThread) [homeassistant] Error doing job: Future exception was never retrieved
Traceback (most recent call last):
  File "/usr/local/lib/python3.9/concurrent/futures/thread.py", line 52, in run
    result = self.fn(*self.args, **self.kwargs)
TypeError: update() takes 1 positional argument but 2 were given
2021-09-03 10:38:36 ERROR (MainThread) [homeassistant] Error doing job: Future exception was never retrieved
Traceback (most recent call last):
  File "/usr/local/lib/python3.9/concurrent/futures/thread.py", line 52, in run
    result = self.fn(*self.args, **self.kwargs)
TypeError: update() takes 1 positional argument but 2 were given
2021-09-03 10:43:37 ERROR (MainThread) [homeassistant] Error doing job: Future exception was never retrieved
Traceback (most recent call last):
  File "/usr/local/lib/python3.9/concurrent/futures/thread.py", line 52, in run
    result = self.fn(*self.args, **self.kwargs)
TypeError: update() takes 1 positional argument but 2 were given
2021-09-03 10:48:38 ERROR (MainThread) [homeassistant] Error doing job: Future exception was never retrieved
Traceback (most recent call last):
  File "/usr/local/lib/python3.9/concurrent/futures/thread.py", line 52, in run
    result = self.fn(*self.args, **self.kwargs)
TypeError: update() takes 1 positional argument but 2 were given
2021-09-03 10:49:46 WARNING (MainThread) [haffmpeg.tools] Timeout reading image.
